Workbook

Sheet 共通処理概要(全判変換)
A1: =[1]表紙!A54 -> Webシステム | K1: 文書名 | U1: モジュールID | Z1: =[1]表紙!$AJ$63 -> MS | AE1: モジュール名 | AJ1: =[1]表紙!$AX$63 -> Webシステム | AS1: 文書番号 | AZ1: Version | BF1: Rev.
K2: =[1]表紙!O64 -> アドオン設計書 | U2: ｻﾌﾞﾓｼﾞｭｰﾙID | Z2: =[1]表紙!$AJ$64 -> MSBB | AE2: ｻﾌﾞﾓｼﾞｭｰﾙ名 | AJ2: =[1]表紙!$AX$64 -> 販売Webシステム | AS2: =[1]表紙!$BL$64 -> M7-US-1140 | AZ2: =[1]表紙!$BU$64 -> 7.0.2 | BF2: =[1]表紙!$CB$64 -> 2
K3: =RIGHT(CELL("filename",$A$1),LEN(CELL("filename",$A$1))-FIND("]",CELL("filename",$A$1))) -> 共通処理概要(全判変換) | U3: 表題 | Z3: =[1]表紙!$AJ$65 -> MSBBPACOM | AE3: =[1]表紙!$AQ$65 -> Web共通ロジック
A5: 全判変換サブルーチン(スリッタ巾→全般巾計算)
A6: No | B6: 入力 | J6: 処理 | BD6: 出力
A7: 1 | B7: 初期処理
B9: 入力(引数) | K9: 処理項目 | S9: 処理内容 | BD9: 出力
C10: 最終工程WG | S10: 1. | T10: WK事業所CD、WK受注巾、WK数量を設定 | BE10: 巾（表） | BI10: ※表巾 | BM10: ※参考資料：受注全判変換サブルーチン_20220808_v01.xlsx
C11: 号機 | K11: WK事業所CD | T11: WK事業所CD = 最終工程WG | BE11: 全判巾
C12: 製品区分 | K12: WK受注巾 | T12: WK受注巾 = スリッター１巾 + スリッター2巾 | BE12: 全判流れ
C13: 段 | K13: WK数量 | T13: WK数量 = 受注数量 | BE13: 全判数量
C14: 表原紙 | BE14: コルスリ区分
C15: 表印刷CD | S15: 2. | T15: WKフィールド 初期化 | BE15: 割数
C16: 表エンボスCD | T16: WK倍数巾 ＝ ０ | BE16: 最大割数
C17: 中原紙 | T17: WK１巾１ ＝ ０
C18: 中印刷CD | T18: WK１巾２ ＝ ０
C19: 中エンボスCD | T19: WK巾Ａ ＝ “ ”
C20: 裏原紙 | T20: WK巾Ｂ ＝ “ ”
C21: 裏印刷CD | T21: WK２巾１ ＝ ０
C22: 裏エンボスCD | T22: WK原紙巾 ＝ ０
C23: スリッター１巾 | T23: WK全判流れ ＝ ０
C24: スリッター1流れ | T24: WK最小流れコルスリ ＝ ０
C25: 受注数量
C26: スリッター2巾 | S26: 3. | T26: 最大巾取得
C27: スリッター2流れ | T27: 3-1.最終工程WG と 段 より 汎用マスタ（段）参照して
C28: コルスリ区分 | K28: WK巾大 | U28: ・WK巾大を設定
V29: 製品区分 １３（Ｇプリント） 以下 ならば WK巾大 ＝ 受注両面最大巾
V30: 製品区分 １３（Ｇプリント） より大 ならば WK巾大 ＝ 受注片面最大巾
K31: WK最大巾 | U31: ・WK最大巾を設定
V32: WK巾大 ≠ ０ ならば WK最大巾 ＝ WK巾大
V33: WK巾大 ＝ ０ ならば 拠点別に次の通り
W34: WK事業所CDより判定
X35: WK事業所CD ＝ 名古屋 ならば WK最大巾 ＝ １３５０
X36: WK事業所CD ＝ 神奈川 ならば WK最大巾 ＝ １４００
X37: WK事業所CD ＝ 仙台 ならば WK最大巾 ＝ １３５０
X38: WK事業所CD 上記以外 ならば WK最大巾 ＝ １６００
T39: 3-2.汎用マスタ（段） 該当 なければ 全判変換サブルーチン 処理終了
S41: 4. | T41: 大阪ローカル
K42: WKローカル区分 | T42: WK事業所CD ＝ 大阪 ならば
U43: 製品区分： 21（巻ボール）、22（片面シート）、23（片面加工）、31（プリフル）、32（刷本支給）のとき
...

Sheet 処理詳細
A1: =[1]表紙!A54 -> Webシステム | K1: 文書名 | U1: モジュールID | Z1: =[1]表紙!$AJ$63 -> MS | AE1: モジュール名 | AJ1: =[1]表紙!$AX$63 -> Webシステム | AS1: 文書番号 | AZ1: Version | BF1: Rev.
K2: =[1]表紙!O64 -> アドオン設計書 | U2: ｻﾌﾞﾓｼﾞｭｰﾙID | Z2: =[1]表紙!$AJ$64 -> MSBB | AE2: ｻﾌﾞﾓｼﾞｭｰﾙ名 | AJ2: =[1]表紙!$AX$64 -> 販売Webシステム | AS2: =[1]表紙!$BL$64 -> M7-US-1140 | AZ2: =[1]表紙!$BU$64 -> 7.0.2 | BF2: =[1]表紙!$CB$64 -> 2
K3: =RIGHT(CELL("filename",$A$1),LEN(CELL("filename",$A$1))-FIND("]",CELL("filename",$A$1))) -> 処理詳細 | U3: 表題 | Z3: =[1]表紙!$AJ$65 -> MSBBPACOM | AE3: =[1]表紙!$AQ$65 -> Web共通ロジック
