Workbook
Name Rev.: 表紙!$U$22
Name Ver.: 表紙!$AE$26
Name ご確認者: 表紙!$AG$40
Name ご確認日: 表紙!$AG$42
Name サブシステム名: 表紙!$U$28
Name システム名: 表紙!$U$26
Name プロジェクト名: 表紙!$U$18
Name 開発区分: 表紙!$U$36
Name 機能ＩＤ: 表紙!$U$32
Name 機能区分: 表紙!$U$34
Name 機能名称: 表紙!$U$30
Name 顧客名: 表紙!$U$16
Name 最終更新者: 表紙!$AB$40
Name 最終更新日: 表紙!$AB$42
Name 作成者: 表紙!$W$40
Name 作成日: 表紙!$W$42
Name 章: 表紙!$M$10
Name 文書名: 表紙!$M$10

Sheet 目次
A1: アドオン設計書作成ガイド
C3: ■アドオン設計と成果物について
D4: ・システム設計フェーズとソフトウェア設計フェーズでアドオンの処理仕様を定義する
D5: ・システム設計フェーズとソフトウェア設計フェーズの成果物がアドオン設計書であり、ソフトウェア製作フェーズのインプットとなる
C7: ■各設計フェーズ毎のアドオン設計書作成範囲
D8: ・システム設計フェーズ：他機能との関連を定義するとともに、画面や帳票、ファイル入出力を中心とした外部入出力の設計を行う
D9: ・ソフトウェア設計フェーズ：内部処理を中心とした設計を行う
U11: ◎ | W11: … | X11: システム設計フェーズで作成
U12: ○ | W12: … | X12: システム設計フェーズで基本仕様を定義して、ソフトウェア設計フェーズで詳細化する
U13: △ | W13: … | X13: 必要に応じて（例えば標準仕様から変更がない場合は不要）
U14: ‐ | W14: … | X14: 不要
W15: … | X15: ソフトウェア設計フェーズで作成
D17: 各設計書と作成対象シートのマトリックス | S17: ※カスタマイズ：標準機能に機能を追加する アドオン：新規で機能を開発する
D18: EXCELシート | N18: 画面設計書 | W18: バッチ設計書 | AF18: 帳票設計書 | AO18: ＢＩ設計書 | AT18: .Net設計書 | BB18: EXCELシート | BL18: WebDB設計書 | BR18: 帳票設計書 | BX18: 汎用申請設計書
N19: カスタマイズ | S19: アドオン | W19: カスタマイズ | AB19: アドオン | AF19: カスタマイズ | AK19: アドオン | AO19: アドオン | AT19: アドオン | BL19: アドオン | BR19: アドオン | BX19: アドオン
D20: 概要 | N20: ◎ | O20: ※1 | S20: ◎ | W20: ◎ | X20: ※1 | AB20: ◎ | AF20: ◎ | AG20: ※1 | AK20: ◎ | AO20: ◎ | AT20: ◎ | BB20: 機能概要 | BL20: ◎ | BR20: ◎ | BX20: ◎
D21: レイアウト | N21: ◎ | O21: ※2 | S21: ◎ | W21: ‐ | AB21: ‐ | AF21: ◎ | AG21: ※2 | AK21: ◎ | AO21: ◎ | AT21: ◎ | BB21: アプリケーションフロー | BL21: ◎ | BR21: ー | BX21: ◎
D22: 項目説明 | N22: △ | S22: ○ | W22: ‐ | AB22: ‐ | AF22: △ | AK22: ○ | AO22: ○ | AT22: ○ | BB22: データベース設定 | BL22: ◎ | BR22: ー | BX22: ◎
D23: 引数説明 | N23: ‐ | S23: ‐ | W23: △ | AB23: ◎ | AF23: ‐ | AK23: ‐ | AO23: ‐ | AT23: ◎ | BB23: フィールド設定 | BL23: ◎ | BR23: ー | BX23: ◎
D24: 処理概要 | N24: ◎ | S24: ◎ | W24: ◎ | AB24: ◎ | AF24: ◎ | AK24: ◎ | AO24: ◎ | AT24: ◎ | BB24: 一覧表示画面設定 | BL24: ◎ | BR24: ー | BX24: ◎
D25: 処理詳細 | BB25: 表示編集画面設定 | BL25: ◎ | BR25: ー | BX25: ◎
D26: 処理・サービス関連図 | N26: △ | S26: ◎ | W26: △ | AB26: ◎ | AF26: ‐ | AK26: ‐ | AO26: ‐ | AT26: ◎ | BB26: 明細画面設定 | BL26: △ | BN26: ※3 | BR26: ー | BX26: △ | BZ26: ※3
D27: 検索入出力仕様 | N27: △ | S27: ○ | W27: △ | AB27: ○ | AF27: ‐ | AK27: ‐ | AO27: ‐ | AT27: ○ | BB27: 集計表示設定 | BL27: △ | BN27: ※4 | BR27: ー | BX27: △ | BZ27: ※4
D28: 更新入出力仕様 | N28: △ | S28: ○ | W28: △ | AB28: ○ | AF28: ‐ | AK28: ‐ | AO28: ‐ | AT28: ○ | BB28: 絞り込み条件設定 | BL28: △ | BN28: ※5 | BR28: ー | BX28: △ | BZ28: ※5
D29: ファイル入出力仕様 | N29: △ | S29: △ | W29: ‐ | AB29: ‐ | AF29: ‐ | AK29: ‐ | AO29: ‐ | AT29: △ | BB29: その他設定 | BR29: ー
D30: 画面遷移 | N30: △ | S30: ◎ | W30: ‐ | AB30: ‐ | AF30: ‐ | AK30: ‐ | AO30: ‐ | AT30: ◎ | BB30: 帳票イメージ | BL30: ー | BR30: ◎ | BX30: ー
D31: メッセージ一覧 | N31: △ | S31: △ | W31: △ | AB31: △ | AF31: ‐ | AK31: ‐ | AO31: ‐ | AT31: △ | BB31: 項目設計 | BL31: ー | BR31: ◎ | BX31: ー
D32: 補足説明 | N32: △ | S32: △ | W32: △ | AB32: △ | AF32: △ | AK32: △ | AO32: △ | AT32: △ | BB32: 補足説明 | BL32: △ | BR32: △ | BX32: △
D33: サービス呼出編集仕様 | N33: - | S33: - | W33: - | AB33: - | AF33: - | AK33: - | AO33: - | AT33: - | BB33: 補足説明(詳細)
D35: ※1 | G35: 別シートでカスタマイズ内容を記載する | BB35: ※3 | BE35: 単票画面は記載しない
D36: ※2 | G36: 吹き出しでカスタマイズ内容を記載する | BB36: ※4 | BE36: 集計・グラフ機能を使用する場合に記載する
BB37: ※5 | BE37: 共通設定のみ記載する(個別設定は、記載しない)

Sheet 表紙
AW2: サブモジュール
AW3: MA_マスタ管理
AW4: MB_業務共通
AW5: MG_原価管理
AW6: MSBA_需給管理
M7: 基本設計 | AW7: MSBB_販売管理
AW8: MSBC_生産管理
AW9: MSBD_購買管理
M10: アドオン設計書 | AW10: MSBE_在庫物流管理
AW11: MSBF_品質管理
AW12: MSBG_債権管理
AW13: MSBH_債務管理
AW14: MSBI_締処理
AW15: MSUA_リスト・入力補助
M16: 顧客 | U16: 株式会社クラウン・パッケージ | AW16: PF_ESBアダプタ
M18: プロジェクト名 | U18: 基幹システム刷新PJ | AW18: 機能区分
AW19: 画面
M20: 文書番号 | AW20: 帳票
AW21: バッチ
M22: Ｒｅｖ． | U22: {=MAX(_xlfn.NUMBERVALUE(改訂!A7:E48))} -> 1 | AW22: マスタ
M24: 機密性区分 | U24: 取扱注意（Ｃ） | AW24: 開発区分
AW25: カスタマイズ
M26: システム名 | U26: mcframe7 | AC26: Ver. | AE26: 7.0.2 | AW26: アドオン
AW27: －
M28: サブモジュール | U28: MSBB_販売管理
M30: 機能名 | U30: =M50 -> 取引先マスタ連携
M32: 機能ID | U32: =G50 -> MSBBBA020
M34: 機能区分 | U34: バッチ
M36: 開発区分 | U36: アドオン
W39: 作成 | AB39: 最終更新 | AG39: ご確認
W40: MDSOL
W42: 44824
A48: 文書番号 | G48: 画面ID | M48: 画面名 | V48: Version | AB48: Revision
A50: M7-US-1140 | G50: MSBBBA020 | M50: 取引先マスタ連携 | V50: 1.0.0 | AB50: r01.00
A53: 共通（元データ）
A54: Webシステム・mcframe7 | K54: 文書名 | U54: モジュールID | Z54: MS | AE54: モジュール名 | AJ54: Webシステム | AS54: 文書番号 | AZ54: Version | BF54: Rev.
K55: 画面説明書 | U55: ｻﾌﾞﾓｼﾞｭｰﾙID | Z55: MSBB | AE55: ｻﾌﾞﾓｼﾞｭｰﾙ名 | AJ55: 販売Webシステム | AS55: M7-US-1140 | AZ55: 1.0.0 | BF55: r00.00
K56: 表紙 | U56: 表題 | Z56: MSBBBA020 | AE56: 取引先マスタ連携
A57: 共通（リンク用）
A58: =A54 -> Webシステム・mcframe7 | K58: 文書名 | U58: モジュールID | Z58: =Z54 -> MS | AE58: モジュール名 | AJ58: =AJ54 -> Webシステム | AS58: 文書番号 | AZ58: Version | BF58: Rev.
...

Sheet 改訂
A1: 第7章 | K1: 改訂 | AU1: 作成者 | AZ1: MDSOL | BE1: 作成日 | BJ1: =表紙!W42 -> 44824 | BP1: Rev.
AU2: 修正者 | BE2: 改訂日 | BP2: =表紙!CB64 -> 1
A5: Rev. | F5: 改定内容 | BC5: 頁 | BM5: 変更日 変更者 | BR5: 確認日 確認者
A7: 1 | F7: 新規作成

Sheet 概要
A1: =表紙!A54 -> Webシステム・mcframe7 | O1: 文書名 | AC1: モジュールID | AJ1: =表紙!AJ63 -> MS | AQ1: モジュール名 | AX1: =表紙!AX63 -> Webシステム | BL1: 文書番号 | BU1: Version | CB1: Rev.
O2: =表紙!O64 -> アドオン設計書 | AC2: サブモジュールID | AJ2: =表紙!AJ64 -> MSBB | AQ2: サブモジュール名 | AX2: =表紙!AX64 -> 販売Webシステム | BL2: =表紙!BL64 -> M7-US-1140 | BU2: =表紙!BU64 -> 7.0.2 | CB2: =表紙!CB64 -> 1
O3: =RIGHT(CELL("filename",$A$1),LEN(CELL("filename",$A$1))-FIND("]",CELL("filename",$A$1))) -> 概要 | AC3: 表題 | AJ3: =表紙!AJ65 -> MSBBBA020 | AQ3: =表紙!AQ65 -> 取引先マスタ連携
AO5: 概要
B7: 【業務要件】
C8: カスタマイズ | G8: 内容
C9: No.
C10: 4 | G10: 見積Webシステムを構築する
H11: 主要機能
H12: ⑦得意先マスタ | M12: ・・・＞ | O12: システム設計フェーズ変更点：得意先→取引先
C14: 35 | G14: 消込条件追加
H15: ①取引先の口座を管理する(得意先マスタ項目追加:得意先マスタのアドオンに含む)
C17: 75 | G17: 取引先マスタのmcframeへの連携
H18: Webにて取引先マスタ(得意先マスタ)を実装する
C20: 40 | G20: 発注一覧登録、発注登録 共通帳票印刷共通ロジック
H21: 発注先のFSC認証番号(取引先マスタ 発注先タブのメモ３)の取得、出力 | AD21: ・・・＞mcframe7 メモ3に連携する
B24: 【機能概要】
C25: Web取引先の情報をmcframe7取引先マスタへ転送する
C26: web取引先マスタから取引先マスタ、得意先担当マスタ、口座マスタへデータ転送する
B28: 【前提条件】
C29: 1. | D29: ジョブスケジューラにより実行する
C30: 2. | D30: 与信限度額マスタへの連携は実施しない
D31: →mcframe7の機能にて登録する
C32: 3. | D32: 削除連携は、論理削除の連携とする
B34: 【説明】
C35: Web取引先マスタ情報をmcframe7の取引先マスタに連携する。
C36: ※得意先→取引先(買い側)含めた連携となった
C40: 新規時
C54: 更新時
C64: 削除時
B74: 【目的】
C75: Web取引先マスタ情報をmcframe7の取引先マスタに連携する
B77: 【処理関連図/サービス関連図】
C78: ※処理・サービス関連図シートに詳細記載
B80: 【自由記述】
C81: なし

Sheet IF概要
A1: =表紙!A54 -> Webシステム・mcframe7 | K1: 文書名 | U1: モジュールID | Z1: =表紙!$AJ$63 -> MS | AE1: モジュール名 | AJ1: =表紙!$AX$63 -> Webシステム | AS1: 文書番号 | AZ1: Version | BF1: Rev.
K2: =表紙!O64 -> アドオン設計書 | U2: ｻﾌﾞﾓｼﾞｭｰﾙID | Z2: =表紙!$AJ$64 -> MSBB | AE2: ｻﾌﾞﾓｼﾞｭｰﾙ名 | AJ2: =表紙!$AX$64 -> 販売Webシステム | AS2: =表紙!$BL$64 -> M7-US-1140 | AZ2: =表紙!$BU$64 -> 7.0.2 | BF2: =表紙!$CB$64 -> 1
K3: =RIGHT(CELL("filename",$A$1),LEN(CELL("filename",$A$1))-FIND("]",CELL("filename",$A$1))) -> IF概要 | U3: 表題 | Z3: =表紙!$AJ$65 -> MSBBBA020 | AE3: =表紙!$AQ$65 -> 取引先マスタ連携

Sheet 処理・サービス関連図
A1: =表紙!A54 -> Webシステム・mcframe7 | K1: 文書名 | U1: モジュールID | Z1: =表紙!$AJ$63 -> MS | AE1: モジュール名 | AJ1: =表紙!$AX$63 -> Webシステム | AS1: 文書番号 | AZ1: Version | BF1: Rev.
K2: =表紙!O64 -> アドオン設計書 | U2: ｻﾌﾞﾓｼﾞｭｰﾙID | Z2: =表紙!$AJ$64 -> MSBB | AE2: ｻﾌﾞﾓｼﾞｭｰﾙ名 | AJ2: =表紙!$AX$64 -> 販売Webシステム | AS2: =表紙!$BL$64 -> M7-US-1140 | AZ2: =表紙!$BU$64 -> 7.0.2 | BF2: =表紙!$CB$64 -> 1
K3: =RIGHT(CELL("filename",$A$1),LEN(CELL("filename",$A$1))-FIND("]",CELL("filename",$A$1))) -> 処理・サービス関連図 | U3: 表題 | Z3: =表紙!$AJ$65 -> MSBBBA020 | AE3: =表紙!$AQ$65 -> 取引先マスタ連携
C7: 検索処理
C21: 登録・更新処理

Sheet 処理概要
A1: =表紙!A54 -> Webシステム・mcframe7 | K1: 文書名 | U1: モジュールID | Z1: =表紙!$AJ$63 -> MS | AE1: モジュール名 | AJ1: =表紙!$AX$63 -> Webシステム | AS1: 文書番号 | AZ1: Version | BF1: Rev.
K2: =表紙!O64 -> アドオン設計書 | U2: ｻﾌﾞﾓｼﾞｭｰﾙID | Z2: =表紙!$AJ$64 -> MSBB | AE2: ｻﾌﾞﾓｼﾞｭｰﾙ名 | AJ2: =表紙!$AX$64 -> 販売Webシステム | AS2: =表紙!$BL$64 -> M7-US-1140 | AZ2: =表紙!$BU$64 -> 7.0.2 | BF2: =表紙!$CB$64 -> 1
K3: =RIGHT(CELL("filename",$A$1),LEN(CELL("filename",$A$1))-FIND("]",CELL("filename",$A$1))) -> 処理概要 | U3: 表題 | Z3: =表紙!$AJ$65 -> MSBBBA020 | AE3: =表紙!$AQ$65 -> 取引先マスタ連携
A5: No | B5: 入力 | J5: 処理（取引先マスタ連携） | AZ5: 出力
A6: 1 | B6: 初期処理
K8: １．処理開始メッセージをログに出力する。 | AZ8: サーバログ
K9: ２．WEB取引先マスタのmcframe7転送FLG=0 ANDのデータを抽出する。 | AZ9: 内部ワーク
A12: 2 | B12: データ出力
K14: １．取引先出力定義.txtを読込み、転送定義を取得する
K15: ２．初期処理で抽出したWEB取引先マスタから各マスタへデータを転送する | AZ15: 取引先マスタ入出力仕様.NO1
M16: 取引先マスタ、得意先担当マスタ、口座マスタ | AZ16: 得意先担当マスタ入出力仕様.NO1
AZ17: 口座マスタ入出力仕様.NO1
L19: 取引先マスタ連携は、固定値の転送項目があるため、取引先出力定義.txtを用意し、固定値を設定できるようにする
M20: →DB項目と固定値項目に関して：取引先出力定義.txtを読込み設定する
AB22: 例：マスタ入力定義 住所１、通貨項目
AC23: 取引先出力定義テキストに下記のように定義しDB項目、固定値を取得する
AC24: 取引先出力定義.txt
AD25: # 転送項目
AD26: 通貨=JPY | AL26: …固定値の場合
AD27: 住所１=@都道府県@ | AL27: …DB項目の場合
AD28: 固定値は、値を記述、DB項目は、@[DB名]@で指定する
A48: 2 | B48: テーブル更新
K50: １．初期処理で抽出したデータのmcframe7転送FLG、mcframe7転送日時を更新する | AZ50: 更新入出力仕様.NO1
K51: (抽出したWEB取引先マスタの取引先CDをキーに更新する)
A53: 3 | B53: 終了処理
K55: １．出力したデータ件数をログに出力する。 | AZ55: サーバログ
M56: 取引先IFデータ出力件数：nnn件
K58: ２．処理終了メッセージをログに出力する。 | AZ58: サーバログ

Sheet 引数説明
A1: =表紙!A54 -> Webシステム・mcframe7 | K1: 文書名 | U1: モジュールID | Z1: =表紙!$AJ$63 -> MS | AE1: モジュール名 | AJ1: =表紙!$AX$63 -> Webシステム | AS1: 文書番号 | AZ1: Version | BF1: Rev.
K2: =表紙!O64 -> アドオン設計書 | U2: ｻﾌﾞﾓｼﾞｭｰﾙID | Z2: =表紙!$AJ$64 -> MSBB | AE2: ｻﾌﾞﾓｼﾞｭｰﾙ名 | AJ2: =表紙!$AX$64 -> 販売Webシステム | AS2: =表紙!$BL$64 -> M7-US-1140 | AZ2: =表紙!$BU$64 -> 7.0.2 | BF2: =表紙!$CB$64 -> 1
K3: =RIGHT(CELL("filename",$A$1),LEN(CELL("filename",$A$1))-FIND("]",CELL("filename",$A$1))) -> 引数説明 | U3: 表題 | Z3: =表紙!$AJ$65 -> MSBBBA020 | AE3: =表紙!$AQ$65 -> 取引先マスタ連携
B5: オペレーションＩＤ/名称：取引先マスタ連携/取込
A6: 必 | B6: 項目名 | N6: 説明 | AS6: 未設定時の振る舞い
C7: 引数無し

Sheet 取引先マスタ入出力仕様
A1: =表紙!A54 -> Webシステム・mcframe7 | K1: 文書名 | U1: モジュールID | Z1: =表紙!$AJ$63 -> MS | AE1: モジュール名 | AJ1: =表紙!$AX$63 -> Webシステム | AS1: 文書番号 | AZ1: Version | BF1: Rev.
K2: =表紙!O64 -> アドオン設計書 | U2: ｻﾌﾞﾓｼﾞｭｰﾙID | Z2: =表紙!$AJ$64 -> MSBB | AE2: ｻﾌﾞﾓｼﾞｭｰﾙ名 | AJ2: =表紙!$AX$64 -> 販売Webシステム | AS2: =表紙!$BL$64 -> M7-US-1140 | AZ2: =表紙!$BU$64 -> 7.0.2 | BF2: =表紙!$CB$64 -> 1
K3: =RIGHT(CELL("filename",$A$1),LEN(CELL("filename",$A$1))-FIND("]",CELL("filename",$A$1))) -> 取引先マスタ入出力仕様 | U3: 表題 | Z3: =表紙!$AJ$65 -> MSBBBA020 | AE3: =表紙!$AQ$65 -> 取引先マスタ連携
A5: No | G5: 1 | S5: ロジック名称 | AH5: 備考 | BM5: CP指摘 2022/11/1 本多 新シート単価適用基準（0：受注日 1：納入日）を項目追加 願います。 | BX5: MDSOL回答 2022/11/04 MCF側からの参照は、VIEW参照となります。(MCFには項目追加せずに、VIEW参照する) | DG5: 2022/11/07 落合 問題なし。当該機能には不要と認識しました。
A6: 処理分類 | E6: 更新 | BM6: 説明 1：納入日基準の場合、日次処理日にて新単価適用日に該当した場合、特値扱いされていない、かつ売上確定していない、受注データ、出荷データの単価を新単価へ更新する。 | BX6: WEB取引先マスタには、項目追加しました。
A7: No | C7: 転送先 | V7: 転送元 | AQ7: 備考
C8: 種 | D8: オブジェクト | K8: 項目名 | V8: 種 | W8: オブジェクト | AF8: 項目名 | BM8: 説明 | BN8: 値の制限 | BO8: 設定仕様 | BP8: 未設定時の振る舞い | BR8: 区
A9: 1 | C9: T | D9: 取引先マスタ（共通） | K9: 取引先ＣＤ | V9: T | W9: WEB取引先マスタ | AF9: 取引先ＣＤ | BM9: 取引先を表すＣＤ
A10: 2 | C10: T | D10: 取引先マスタ（共通） | K10: 取引先名 | V10: T | W10: WEB取引先マスタ | AF10: 取引先略称 | BM10: 取引先に対する名称
A11: 3 | C11: T | D11: 取引先マスタ（共通） | K11: 取引先別名１ | V11: T | W11: WEB取引先マスタ | AF11: 取引先名 | BM11: 取引先に対する別名 標準機能ではマスタに登録できるだけで、設定した値が使用される機能はない ※会計Link機能によっては会計システムに連携される
A12: 4 | C12: T | D12: 取引先マスタ（共通） | K12: 取引先別名２ | V12: T | W12: WEB取引先マスタ | AF12: 取引先別名２ | AQ12: 使用しない | BM12: 取引先に対する別名 標準機能ではマスタに登録できるだけで、設定した値が使用される機能はない ※会計Link機能によっては会計システムに連携される
A13: 5 | C13: T | D13: 取引先マスタ（共通） | K13: 取引先別名３ | V13: T | W13: WEB取引先マスタ | AF13: 取引先別名３ | AQ13: 使用しない | BM13: 取引先に対する別名 標準機能ではマスタに登録できるだけで、設定した値が使用される機能はない ※会計Link機能によっては会計システムに連携される
A14: 6 | C14: T | D14: 取引先マスタ（共通） | K14: 取引先別名４ | V14: T | W14: WEB取引先マスタ | AF14: 取引先別名４ | AQ14: 使用しない | BM14: 取引先に対する別名 標準機能ではマスタに登録できるだけで、設定した値が使用される機能はない ※会計Link機能によっては会計システムに連携される
A15: 7 | C15: T | D15: 取引先マスタ（共通） | K15: 郵便番号 | V15: T | W15: WEB取引先マスタ | AF15: 郵便番号 | AQ15: 画面 | AS15: 郵便番号 | BM15: 取引先に対する郵便番号 帳票に表示する値を設定する | BN15: 半角大文字アルファベット、半角数字、半角スペース、「-」から成り立つ文字列
A16: 8 | C16: T | D16: 取引先マスタ（共通） | K16: 住所１ | V16: T | W16: WEB取引先マスタ | AF16: 都道府県 | AQ16: 画面 | AS16: 都道府県 | BM16: 取引先に対する住所 帳票に表示する値を設定する
A17: 9 | C17: T | D17: 取引先マスタ（共通） | K17: 住所２ | V17: T | W17: WEB取引先マスタ | AF17: 市区町村 | AQ17: 画面 | AS17: 市区町村 | BM17: 取引先に対する住所 帳票に表示する値を設定する
A18: 10 | C18: T | D18: 取引先マスタ（共通） | K18: 住所３ | V18: T | W18: WEB取引先マスタ | AF18: 町域・番地 | AQ18: 画面 | AS18: 町域・番地 | BM18: 取引先に対する住所 帳票に表示する値を設定する
A19: 11 | C19: T | D19: 取引先マスタ（共通） | K19: 住所４ | V19: T | W19: WEB取引先マスタ | AF19: 建物など | AQ19: 画面 | AS19: 建物など | BM19: 取引先に対する住所 帳票に表示する値を設定する
A20: 12 | C20: T | D20: 取引先マスタ（共通） | K20: ＴＥＬ | V20: T | W20: WEB取引先マスタ | AF20: ＴＥＬ | AQ20: 画面 | AS20: ＴＥＬ | BM20: 取引先に対する電話番号 帳票に表示する値を設定する | BN20: 「+」、「-」、半角スペース、「(」、「)」、半角数字から成り立つ文字列
A21: 13 | C21: T | D21: 取引先マスタ（共通） | K21: ＦＡＸ | V21: T | W21: WEB取引先マスタ | AF21: ＦＡＸ | AQ21: 画面 | AS21: ＦＡＸ | BM21: 取引先に対するＦＡＸ番号 帳票に表示する値を設定する | BN21: 「+」、「-」、半角スペース、「(」、「)」、半角数字から成り立つ文字列
A22: 14 | C22: T | D22: 取引先マスタ（共通） | K22: 法人番号 | V22: T | W22: WEB取引先マスタ | AF22: 法人番号 | AQ22: 画面 | AS22: 法人番号 | BM22: 取引先に対する法人番号
A23: 15 | C23: T | D23: 取引先マスタ（共通） | K23: 標準企業コード | V23: T | W23: WEB取引先マスタ | AF23: 標準企業コード | AQ23: 画面 | AS23: 標準企業コード | BM23: 各種業界における統一された企業コード 納品書など社外帳票に出力する際に使用することを想定している
A24: 16 | C24: T | D24: 取引先マスタ（共通） | K24: 国ＣＤ | AF24: 固定：JP | AQ24: ※国内取引 | BM24: 取引先に対する国ＣＤ | BN24: 国マスタに登録されている国ＣＤ
A25: 17 | C25: T | D25: 取引先マスタ（共通） | K25: 地域ＣＤ | V25: T | W25: WEB取引先マスタ | AF25: 地域ＣＤ | AQ25: 画面 | AS25: 地域ＣＤ | BM25: 取引先に対する地域ＣＤ 集計処理や検索条件として使用される | BN25: 地域マスタに登録されている地域ＣＤ
A26: 18 | C26: T | D26: 取引先マスタ（共通） | K26: 通貨ＣＤ | AF26: 固定：JPY | AQ26: ※国内取引 | BM26: 取引先に対する基準通貨ＣＤ | BN26: 通貨マスタに登録されている通貨ＣＤ
A27: 19 | C27: T | D27: 取引先マスタ（共通） | K27: 帳票出力ロケールＣＤ | AF27: 固定：ja_jp | BM27: 注文書や見積書など社外帳票を出力する際に使用するロケールＣＤ ※ロケールＣＤに対する名称が表示される ※指定しない場合はトリガで会社基本マスタ（FrameManager)の標準ロケールＣ Ｄが設定される | BN27: MCConfigのロケールエントリーに存在するロケールＣＤ
A28: 20 | C28: T | D28: 取引先マスタ（共通） | K28: 取引先分類ＣＤ１ | V28: T | W28: WEB取引先マスタ | AF28: 取引先分類ＣＤ１ | AQ28: 画面 | AS28: 取引先分類ＣＤ１ | BM28: 取引先対する取引先分類ＣＤ１ | BN28: 取引先分類マスタに取引先分類区分が1で登録されている取引先分類ＣＤ
A29: 21 | C29: T | D29: 取引先マスタ（共通） | K29: 取引先分類ＣＤ２ | V29: T | W29: WEB取引先マスタ | AF29: 取引先分類ＣＤ２ | AQ29: 画面 | AS29: 取引先分類ＣＤ２ | BM29: 取引先対する取引先分類ＣＤ２ | BN29: 取引先分類マスタに取引先分類区分が2で登録されている取引先分類ＣＤ
A30: 22 | C30: T | D30: 取引先マスタ（共通） | K30: 取引先分類ＣＤ３ | V30: T | W30: WEB取引先マスタ | AF30: 取引先分類ＣＤ３ | AQ30: 画面 | AS30: 取引先分類ＣＤ３ | BM30: 取引先対する取引先分類ＣＤ３ | BN30: 取引先分類マスタに取引先分類区分が3で登録されている取引先分類ＣＤ
A31: 23 | C31: T | D31: 取引先マスタ（共通） | K31: 取引先分類ＣＤ４ | V31: T | W31: WEB取引先マスタ | AF31: 取引先分類ＣＤ４ | AQ31: 画面 | AS31: 取引先分類ＣＤ４ | BM31: 取引先対する取引先分類ＣＤ４ | BN31: 取引先分類マスタに取引先分類区分が4で登録されている取引先分類ＣＤ
A32: 24 | C32: T | D32: 取引先マスタ（共通） | K32: 取引先分類ＣＤ５ | V32: T | W32: WEB取引先マスタ | AF32: 取引先分類ＣＤ５ | AQ32: 画面 | AS32: 取引先分類ＣＤ５ | BM32: 取引先対する取引先分類ＣＤ５ | BN32: 取引先分類マスタに取引先分類区分が5で登録されている取引先分類ＣＤ
A33: 25 | C33: T | D33: 取引先マスタ（共通） | K33: 取引先分類ＣＤ６ | V33: T | W33: WEB取引先マスタ | AF33: 取引先分類ＣＤ６ | AQ33: 画面 | AS33: 取引先分類ＣＤ６ | BM33: 取引先対する取引先分類ＣＤ６ | BN33: 取引先分類マスタに取引先分類区分が6で登録されている取引先分類ＣＤ
A34: 26 | C34: T | D34: 取引先マスタ（共通） | K34: 取引先分類ＣＤ７ | V34: T | W34: WEB取引先マスタ | AF34: 取引先分類ＣＤ７ | AQ34: 画面 | AS34: 取引先分類ＣＤ７ | BM34: 取引先対する取引先分類ＣＤ７ | BN34: 取引先分類マスタに取引先分類区分が7で登録されている取引先分類ＣＤ
A35: 27 | C35: T | D35: 取引先マスタ（共通） | K35: 取引先分類ＣＤ８ | V35: T | W35: WEB取引先マスタ | AF35: 取引先分類ＣＤ８ | AQ35: 画面 | AS35: 取引先分類ＣＤ８ | BM35: 取引先対する取引先分類ＣＤ８ | BN35: 取引先分類マスタに取引先分類区分が8で登録されている取引先分類ＣＤ
A36: 28 | C36: T | D36: 取引先マスタ（共通） | K36: 取引先分類ＣＤ９ | V36: T | W36: WEB取引先マスタ | AF36: 取引先分類ＣＤ９ | AQ36: 画面 | AS36: 取引先分類ＣＤ９ | BM36: 取引先対する取引先分類ＣＤ９ | BN36: 取引先分類マスタに取引先分類区分が9で登録されている取引先分類ＣＤ
A37: 29 | C37: T | D37: 取引先マスタ（共通） | K37: 取引先分類ＣＤ１０ | V37: T | W37: WEB取引先マスタ | AF37: 取引先分類ＣＤ１０ | AQ37: 画面 | AS37: 取引先分類ＣＤ１０ | BM37: 取引先対する取引先分類ＣＤ１０ | BN37: 取引先分類マスタに取引先分類区分が10で登録されている取引先分類ＣＤ
A38: 30 | C38: T | D38: 取引先マスタ（共通） | K38: 取引先配賦グループ | AF38: NULL | BM38: 取引先に対する配賦グループ | BO38: 原価管理で取引先別に費用情報が登録される場合に使用される 取引先１及び取引先２の費用は数量配賦、取引先３の費用は金額配賦など、取引先別に配賦方法（配賦パタン）が異なる場合に、取引先ごとに異なる値を設定する ※同じ配賦方法（配賦パタン）となる取引先に対しては同じ値を設定する ※上記では取引先１と取引先２に同じ値を設定する | BP38: 取引先ごとに配賦パタンを決定しない
A39: 31 | C39: T | D39: 取引先マスタ（共通） | K39: 得意先ＦＬＧ | V39: T | W39: WEB取引先マスタ | AF39: 得意先ＦＬＧ
A40: 32 | C40: T | D40: 取引先マスタ（共通） | K40: 売掛先ＦＬＧ | V40: T | W40: WEB取引先マスタ | AF40: 売掛先ＦＬＧ
A41: 33 | C41: T | D41: 取引先マスタ（共通） | K41: 請求先ＦＬＧ | V41: T | W41: WEB取引先マスタ | AF41: 請求先ＦＬＧ
...

Sheet 得意先担当マスタ入出力仕様
A1: =表紙!A54 -> Webシステム・mcframe7 | K1: 文書名 | U1: モジュールID | Z1: =表紙!$AJ$63 -> MS | AE1: モジュール名 | AJ1: =表紙!$AX$63 -> Webシステム | AS1: 文書番号 | AZ1: Version | BF1: Rev.
K2: =表紙!O64 -> アドオン設計書 | U2: ｻﾌﾞﾓｼﾞｭｰﾙID | Z2: =表紙!$AJ$64 -> MSBB | AE2: ｻﾌﾞﾓｼﾞｭｰﾙ名 | AJ2: =表紙!$AX$64 -> 販売Webシステム | AS2: =表紙!$BL$64 -> M7-US-1140 | AZ2: =表紙!$BU$64 -> 7.0.2 | BF2: =表紙!$CB$64 -> 1
K3: =RIGHT(CELL("filename",$A$1),LEN(CELL("filename",$A$1))-FIND("]",CELL("filename",$A$1))) -> 得意先担当マスタ入出力仕様 | U3: 表題 | Z3: =表紙!$AJ$65 -> MSBBBA020 | AE3: =表紙!$AQ$65 -> 取引先マスタ連携
A5: No | G5: 1 | S5: ロジック名称 | AH5: 備考
A6: 処理分類 | E6: 更新
A7: No | C7: 転送先 | V7: 転送元 | AQ7: 備考
C8: 種 | D8: オブジェクト | K8: 項目名 | V8: 種 | W8: オブジェクト | AF8: 項目名 | BM8: 説明 | BN8: 値の制限 | BO8: 設定仕様 | BP8: 未設定時の振る舞い
A9: 1 | C9: T | D9: 得意先担当マスタ | K9: 得意先ＣＤ | V9: T | W9: WEB取引先マスタ | AF9: 取引先ＣＤ | AQ9: 画面 | AS9: 取引先ＣＤ | BM9: 得意先ＣＤ | BN9: 取引先マスタで得意先ＦＬＧが設定されている取引先ＣＤ
A10: 2 | C10: T | D10: 得意先担当マスタ | K10: 適用開始日 | AF10: 登録日時 | BM10: 当該レコードを有効にする日 | BN10: 適用開始日≦適用終了日 適用開始日以外のキー項目が同一となる場合に、期間が重なるようなデータは登録できない
A11: 3 | C11: T | D11: 得意先担当マスタ | K11: 会社ＣＤ | AF11: (システム自動)
A12: 4 | C12: T | D12: 得意先担当マスタ | K12: 適用終了日 | AF12: 固定：2099/12/31 | BM12: 当該レコードが有効となる最終日 | BN12: 適用開始日≦適用終了日 適用開始日以外のキー項目が同一となる場合に、期間が重なるようなデータは登録できない
A13: 5 | C13: T | D13: 得意先担当マスタ | K13: 担当者ＣＤ | V13: T | W13: WEB取引先マスタ | AF13: 営業担当CD | AQ13: 画面 | AS13: 営業担当 | BM13: 得意先を担当する担当者ＣＤ 担当者ＣＤを設定した場合は担当者に対して担当者権限マスタに登録されている主部門が売上部門として連携される | BN13: 担当者マスタに登録されている担当者ＣＤ 部門ＣＤが設定されている場合は設定不可 担当者ＣＤもしくは部門ＣＤのどちらかは必須
A14: 6 | C14: T | D14: 得意先担当マスタ | K14: 部門ＣＤ | AF14: NULL | BM14: 得意先を担当する部門ＣＤ | BN14: 部門マスタで営業部門ＦＬＧが設定されている部門ＣＤ 担当者ＣＤが設定されている場合は設定不可 担当者ＣＤもしくは部門ＣＤのどちらかは必須
A15: 7 | C15: T | D15: 得意先担当マスタ | K15: メモ１
A16: 8 | C16: T | D16: 得意先担当マスタ | K16: メモ２
A17: 9 | C17: T | D17: 得意先担当マスタ | K17: メモ３
A18: 10 | C18: T | D18: 得意先担当マスタ | K18: 論理削除ＦＬＧ
A19: 11 | C19: T | D19: 得意先担当マスタ | K19: 論理削除ユーザＩＤ
A20: 12 | C20: T | D20: 得意先担当マスタ | K20: 論理削除ユーザ名
A21: 13 | C21: T | D21: 得意先担当マスタ | K21: 論理削除日時
A22: 14 | C22: T | D22: 得意先担当マスタ | K22: 登録ユーザＩＤ
A23: 15 | C23: T | D23: 得意先担当マスタ | K23: 登録ユーザ名
A24: 16 | C24: T | D24: 得意先担当マスタ | K24: 登録日時
A25: 17 | C25: T | D25: 得意先担当マスタ | K25: 登録機能ＩＤ
A26: 18 | C26: T | D26: 得意先担当マスタ | K26: 更新カウンタ
... A31: 23 | C31: T | D31: 得意先担当マスタ | K31: 更新リクエストＮＯ

Sheet 口座マスタ入出力仕様
A1: =表紙!A54 -> Webシステム・mcframe7 | K1: 文書名 | U1: モジュールID | Z1: =表紙!$AJ$63 -> MS | AE1: モジュール名 | AJ1: =表紙!$AX$63 -> Webシステム | AS1: 文書番号 | AZ1: Version | BF1: Rev.
K2: =表紙!O64 -> アドオン設計書 | U2: ｻﾌﾞﾓｼﾞｭｰﾙID | Z2: =表紙!$AJ$64 -> MSBB | AE2: ｻﾌﾞﾓｼﾞｭｰﾙ名 | AJ2: =表紙!$AX$64 -> 販売Webシステム | AS2: =表紙!$BL$64 -> M7-US-1140 | AZ2: =表紙!$BU$64 -> 7.0.2 | BF2: =表紙!$CB$64 -> 1
K3: =RIGHT(CELL("filename",$A$1),LEN(CELL("filename",$A$1))-FIND("]",CELL("filename",$A$1))) -> 口座マスタ入出力仕様 | U3: 表題 | Z3: =表紙!$AJ$65 -> MSBBBA020 | AE3: =表紙!$AQ$65 -> 取引先マスタ連携
A5: No | G5: 1 | S5: ロジック名称 | AH5: 備考
A6: 処理分類 | E6: 更新
A7: No | C7: 転送先 | V7: 転送元 | AQ7: 備考
C8: 種 | D8: オブジェクト | K8: 項目名 | V8: 種 | W8: オブジェクト | AF8: 項目名 | BM8: 説明 | BN8: 値の制限 | BO8: 設定仕様 | BP8: 未設定時の振る舞い
A9: 1 | C9: T | D9: 口座マスタ | K9: 口座ＣＤ | V9: T | W9: WEB取引先マスタ | AF9: 取引先ＣＤ | AQ9: 画面 | AS9: 取引先ＣＤ | BM9: 口座を表すＣＤ
A10: 2 | C10: T | D10: 口座マスタ | K10: 口座名 | V10: T | W10: WEB取引先マスタ | AF10: 取引先略称 | AQ10: 取引先略称 + 固定：口座 | BM10: 口座ＣＤに対する名称
A11: 3 | C11: T | D11: 口座マスタ | K11: 社外ＦＬＧ | AF11: 固定：1 | AQ11: チェック有り固定 | BM11: 社内口座か社外口座（振込先口座）かどうかを制御するフラグ | BO11: 支払先の口座として利用する場合に設定する フラグを設定した場合は社内用の口座としては利用できない
A12: 4 | C12: T | D12: 口座マスタ | K12: 銀行ＣＤ | V12: T | W12: WEB取引先マスタ | AF12: 銀行(支払予定管理先) | AQ12: 画面 | AS12: 銀行(支払予定管理先) | BM12: 口座ＣＤに対する銀行ＣＤ | BN12: 銀行マスタに登録されている銀行ＣＤ
A13: 5 | C13: T | D13: 口座マスタ | K13: 支店ＣＤ | V13: T | W13: WEB取引先マスタ | AF13: 銀行支店(支払予定管理先) | AQ13: 画面 | AS13: 銀行支店(支払予定管理先) | BM13: 口座ＣＤに対する支店ＣＤ | BN13: 銀行ＣＤに対して銀行支店マスタに登録されている支店ＣＤ
A14: 6 | C14: T | D14: 口座マスタ | K14: 口座番号 | V14: T | W14: WEB取引先マスタ | AF14: 支払口座 | AQ14: 画面 | AS14: 支払口座 | BM14: 口座ＣＤに対する口座番号
A15: 7 | C15: T | D15: 口座マスタ | K15: 口座区分 | V15: T | W15: WEB取引先マスタ | AF15: 支払口座区分 | AQ15: 画面 | AS15: 支払口座区分 | BM15: 口座ＣＤに対する口座区分 | BN15: 定数：口座区分 1：普通 2：当座 3：その他
A16: 8 | C16: T | D16: 口座マスタ | K16: 口座名義 | AF16: NULL | BM16: 口座ＣＤに対する口座名義
A17: 9 | C17: T | D17: 口座マスタ | K17: 口座名義別名 | V17: T | W17: WEB取引先マスタ | AF17: 口座名義(カナ) | AQ17: 画面 | AS17: 口座名義(カナ) | BM17: 口座名義に対する別名（口座名義に対するカナ名など）
A18: 10 | C18: T | D18: 口座マスタ | K18: メモ１
A19: 11 | C19: T | D19: 口座マスタ | K19: メモ２
A20: 12 | C20: T | D20: 口座マスタ | K20: メモ３
A21: 13 | C21: T | D21: 口座マスタ | K21: 論理削除ＦＬＧ
A22: 14 | C22: T | D22: 口座マスタ | K22: 論理削除ユーザＩＤ
A23: 15 | C23: T | D23: 口座マスタ | K23: 論理削除ユーザ名
A24: 16 | C24: T | D24: 口座マスタ | K24: 論理削除日時
A25: 17 | C25: T | D25: 口座マスタ | K25: 登録ユーザＩＤ
A26: 18 | C26: T | D26: 口座マスタ | K26: 登録ユーザ名
A27: 19 | C27: T | D27: 口座マスタ | K27: 登録日時
A28: 20 | C28: T | D28: 口座マスタ | K28: 登録機能ＩＤ
A29: 21 | C29: T | D29: 口座マスタ | K29: 更新カウンタ
... A34: 26 | C34: T | D34: 口座マスタ | K34: 更新リクエストＮＯ

Sheet 更新入出力仕様
A1: =表紙!A54 -> Webシステム・mcframe7 | K1: 文書名 | U1: モジュールID | Z1: =表紙!$AJ$63 -> MS | AE1: モジュール名 | AJ1: =表紙!$AX$63 -> Webシステム | AS1: 文書番号 | AZ1: Version | BF1: Rev.
K2: =表紙!O64 -> アドオン設計書 | U2: ｻﾌﾞﾓｼﾞｭｰﾙID | Z2: =表紙!$AJ$64 -> MSBB | AE2: ｻﾌﾞﾓｼﾞｭｰﾙ名 | AJ2: =表紙!$AX$64 -> 販売Webシステム | AS2: =表紙!$BL$64 -> M7-US-1140 | AZ2: =表紙!$BU$64 -> 7.0.2 | BF2: =表紙!$CB$64 -> 1
K3: =RIGHT(CELL("filename",$A$1),LEN(CELL("filename",$A$1))-FIND("]",CELL("filename",$A$1))) -> 更新入出力仕様 | U3: 表題 | Z3: =表紙!$AJ$65 -> MSBBBA020 | AE3: =表紙!$AQ$65 -> 取引先マスタ連携
A5: No | G5: 1 | S5: ロジック名称 | AH5: 備考
A6: 処理分類 | E6: 更新
A7: No | C7: 転送先 | V7: 転送元 | AQ7: 説明
C8: 種 | D8: オブジェクト | K8: 項目名 | V8: 種 | W8: オブジェクト | AF8: 項目名
C9: T | D9: WEB取引先マスタ | K9: mcframe7転送FLG | AF9: 1
C10: T | D10: WEB取引先マスタ | K10: mcframe7転送日時 | AF10: 処理日時
A12: 更新条件
C13: T | D13: WEB取引先マスタ | K13: 取引先CD | V13: T | W13: WEB取引先マスタ | AF13: 取引先CD | AQ13: 抽出したWEB取引先マスタの取引先CDをキーに更新する

Sheet 補足説明資料
A1: =表紙!A54 -> Webシステム・mcframe7 | O1: 文書名 | AC1: モジュールID | AJ1: =表紙!AJ63 -> MS | AQ1: モジュール名 | AX1: =表紙!AX63 -> Webシステム | BL1: 文書番号 | BU1: Version | CB1: Rev.
O2: =表紙!O64 -> アドオン設計書 | AC2: サブモジュールID | AJ2: =表紙!AJ64 -> MSBB | AQ2: サブモジュール名 | AX2: =表紙!AX64 -> 販売Webシステム | BL2: =表紙!BL64 -> M7-US-1140 | BU2: =表紙!BU64 -> 7.0.2 | CB2: =表紙!CB64 -> 1
O3: =RIGHT(CELL("filename",$A$1),LEN(CELL("filename",$A$1))-FIND("]",CELL("filename",$A$1))) -> 補足説明資料 | AC3: 表題 | AJ3: =表紙!AJ65 -> MSBBBA020 | AQ3: =表紙!AQ65 -> 取引先マスタ連携
AO5: 補足説明
D7: 「取引先出力定義.txt」定義に関して
E8: 概要：取引先マスタ連携のDB項目・固定項目を定義する
D10: 取引先出力定義.txt イメージ
D11: # 転送項目
D12: 取引先ＣＤ | N12: = | P12: @取引先ＣＤ@
D13: 取引先名 | N13: = | P13: @取引先略称@
D14: 取引先別名１ | N14: = | P14: @取引先名@
D15: 取引先別名２ | N15: = | P15: @取引先別名２@
D16: 取引先別名３ | N16: = | P16: @取引先別名３@
D17: 取引先別名４ | N17: = | P17: @取引先別名４@
D18: 郵便番号 | N18: = | P18: @郵便番号@
D19: 住所１ | N19: = | P19: @都道府県@
D20: 住所２ | N20: = | P20: @市区町村@
D21: 住所３ | N21: = | P21: @町域・番地@
D22: 住所４ | N22: = | P22: @建物など@
D23: ＴＥＬ | N23: = | P23: @ＴＥＬ@
... D209: 買戻義務ＦＬＧ | N209: = | P209: @買戻義務ＦＬＧ@

Sheet |→補足シート

Sheet マスタ入力定義
A1: mcframe 7 | K1: 文書名 | U1: モジュールID | Z1: MA | AE1: モジュール名 | AJ1: マスタ管理 | AS1: 文書番号 | AZ1: Version | BF1: Rev.
K2: 文書名 | U2: ｻﾌﾞﾓｼﾞｭｰﾙID | Z2: MABC | AE2: ｻﾌﾞﾓｼﾞｭｰﾙ名 | AJ2: マスタ（共通） | AS2: M7-US-1140 | AZ2: 7.0.2 | BF2: 1
K3: マスタ入力定義 | U3: 表題 | Z3: MABCP0510 | AE3: 取引先マスタ登録
A5: CP項目 要否 | E5: 画面名 | L5: タブ名 (タブ無画面は-) | S5: データ項目名 | Z5: 必須 項目 | AD5: 備考１ | AN5: メモ | AT5: 入力パターン１ | BL5: 入力パターン２ | CF5: 入力パターン3
AT6: 得意先関連 | BL6: 発注先(原材料、資材、副資材、購買品、他)関連 | CF6: 発注先(外注品)関連
AT7: 設定値 | BA7: 担当 | BF7: 登録方法 | BL7: 設定値 | BT7: 担当 | BZ7: 登録方法 | CF7: 設定値 | CN7: 担当 | CS7: 登録方法
L8: 共通１ | S8: 取引先 | Z8: 〇 | AT8: 事業所＋取引先 | BA8: システム | BF8: WEB→mcframe | BL8: 事業所＋取引先 | BT8: 業務or総務 | BZ8: 画面 | CF8: 事業所＋取引先 | CN8: 業務 | CS8: 画面
L9: 共通１ | S9: 標準取引先名 | Z9: 〇 | AT9: 得意先略称 | BA9: 営業 | BF9: WEB→mcframe | BL9: 発注先略称 | BT9: 業務or総務 | BZ9: 画面 | CF9: 発注先略称 | CN9: 業務 | CS9: 画面
L10: 共通１ | S10: 取引先別名１ | AT10: 得意先正式名称 | BA10: 営業 | BF10: WEB→mcframe | BL10: 発注先正式名称 | BT10: 業務or総務 | BZ10: 画面 | CF10: 発注先正式名称 | CN10: 業務 | CS10: 画面
A11: X | L11: 共通１ | S11: 取引先別名２ | AT11: 使用しない | BA11: システム | BF11: WEB→mcframe | BL11: 使用しない | CF11: 使用しない
A12: X | L12: 共通１ | S12: 取引先別名３ | AT12: 使用しない | BA12: システム | BF12: WEB→mcframe | BL12: 使用しない | CF12: 使用しない
A13: X | L13: 共通１ | S13: 取引先別名４ | AT13: 使用しない | BA13: システム | BF13: WEB→mcframe | BL13: 使用しない | CF13: 使用しない
L14: 共通１ | S14: 通貨 | AT14: 固定：JPY | BA14: システム | BF14: WEB→mcframe | BL14: JPY | BT14: 業務or総務 | BZ14: 画面 | CF14: JPY | CN14: 業務 | CS14: 画面
L15: 共通１ | S15: 通貨名 | AT15: 円 | BA15: システム | BF15: WEB→mcframe | BL15: 円 | CF15: 円
L16: 共通１ | S16: 国 | Z16: 〇 | AT16: 固定：JPY | BA16: システム | BF16: WEB→mcframe | BL16: JPN | BT16: 業務or総務 | BZ16: 画面 | CF16: JPN | CN16: 業務 | CS16: 画面
L17: 共通１ | S17: 国名 | AT17: 日本 | BA17: システム | BF17: WEB→mcframe | BL17: 日本 | CF17: 日本
L18: 共通１ | S18: 地域 | AT18: 都道府県 | BA18: 営業 | BF18: WEB→mcframe | BL18: 都道府県 | BT18: 業務or総務 | BZ18: 画面 | CF18: 都道府県 | CN18: 業務 | CS18: 画面
L19: 共通１ | S19: 地域名 | AT19: 都道府県名 | BA19: システム | BF19: WEB→mcframe | BL19: 都道府県名 | CF19: 都道府県名
L20: 共通２ | S20: 法人番号 | AT20: 法人番号 | BA20: 営業 | BF20: WEB→mcframe | BL20: 法人番号 | BT20: 業務or総務 | BZ20: 画面 | CF20: 法人番号 | CN20: 業務 | CS20: 画面
L21: 共通２ | S21: 標準企業コード | AT21: 標準企業コード | BA21: 営業 | BF21: WEB→mcframe | BL21: 標準企業コード | BT21: 業務or総務 | BZ21: 画面 | CF21: 標準企業コード | CN21: 業務 | CS21: 画面
L22: 共通２ | S22: 郵便番号 | AT22: 郵便番号 | BA22: 営業 | BF22: WEB→mcframe | BL22: 郵便番号 | BT22: 業務or総務 | BZ22: 画面 | CF22: 郵便番号 | CN22: 業務 | CS22: 画面
L23: 共通２ | S23: 住所１ | AT23: 住所 | BA23: 営業 | BF23: WEB→mcframe | BL23: 住所 | BT23: 業務or総務 | BZ23: 画面 | CF23: 住所 | CN23: 業務 | CS23: 画面
L24: 共通２ | S24: 住所２ | AT24: 使用しない | BA24: システム | BF24: WEB→mcframe | BT24: 業務or総務 | BZ24: 画面 | CN24: 業務 | CS24: 画面
L25: 共通２ | S25: 住所３ | AT25: 使用しない | BA25: システム | BF25: WEB→mcframe | BT25: 業務or総務 | BZ25: 画面 | CN25: 業務 | CS25: 画面
L26: 共通２ | S26: 住所４ | AT26: 使用しない | BA26: システム | BF26: WEB→mcframe | BT26: 業務or総務 | BZ26: 画面 | CN26: 業務 | CS26: 画面
L27: 共通２ | S27: ＴＥＬ | AT27: ＴＥＬ | BA27: 営業 | BF27: WEB→mcframe | BL27: ＴＥＬ | BT27: 業務or総務 | BZ27: 画面 | CF27: ＴＥＬ | CN27: 業務 | CS27: 画面
L28: 共通２ | S28: ＦＡＸ | AT28: ＦＡＸ | BA28: 営業 | BF28: WEB→mcframe | BL28: ＦＡＸ | BT28: 業務or総務 | BZ28: 画面 | CF28: ＦＡＸ | CN28: 業務 | CS28: 画面
L29: 共通２ | S29: 帳票出力ロケール | AT29: ja_jp | BA29: 営業 | BF29: WEB→mcframe | BL29: ja_jp | BT29: 業務or総務 | BZ29: 画面 | CF29: ja_jp | CN29: 業務 | CS29: 画面
L30: 共通２ | S30: 帳票出力ロケール名 | AT30: 日本語出力 | BA30: 営業 | BF30: WEB→mcframe | BL30: 日本語出力 | CF30: 日本語出力
L31: 共通２ | S31: 取引先配賦Ｇ | AT31: 原価で決定 | BA31: システム | BF31: WEB→mcframe | BL31: 原価で決定 | BT31: 業務or総務 | BZ31: 画面 | CF31: 原価で決定 | CN31: 業務 | CS31: 画面
L32: 共通２ | S32: メモ１ | AT32: 使用しない | BA32: システム | BF32: WEB→mcframe | BT32: 業務or総務 | BZ32: 画面 | CN32: 業務 | CS32: 画面
L33: 共通２ | S33: メモ２ | AT33: 使用しない | BA33: システム | BF33: WEB→mcframe | BT33: 業務or総務 | BZ33: 画面 | CN33: 業務 | CS33: 画面
L34: 共通２ | S34: メモ３ | AT34: 使用しない | BA34: システム | BF34: WEB→mcframe | BT34: 業務or総務 | BZ34: 画面 | CN34: 業務 | CS34: 画面
L35: 取引先分類 | S35: 取引先分類１ | AT35: 締め日 | BA35: 営業 | BF35: WEB→mcframe
L36: 取引先分類 | S36: 取引先分類名１ | AT36: 締め日 | BA36: 営業 | BF36: WEB→mcframe
L37: 取引先分類 | S37: 取引先分類２ | BF37: WEB→mcframe
L38: 取引先分類 | S38: 取引先分類名２ | BF38: WEB→mcframe
L39: 取引先分類 | S39: 取引先分類３ | BF39: WEB→mcframe
L40: 取引先分類 | S40: 取引先分類名３ | BF40: WEB→mcframe
L41: 取引先分類 | S41: 取引先分類４ | BF41: WEB→mcframe
...

Sheet 補足説明資料(OLD)
A1: =表紙!A54 -> Webシステム・mcframe7 | O1: 文書名 | AC1: モジュールID | AJ1: =表紙!AJ64 -> MSBB | AQ1: モジュール名 | AX1: =表紙!AX64 -> 販売Webシステム | BL1: 文書番号 | BU1: Version | CB1: Rev.
O2: =表紙!O65 -> 表紙 | AC2: サブモジュールID | AJ2: =表紙!AJ65 -> MSBBBA020 | AQ2: サブモジュール名 | AX2: =表紙!AX65 -> 0 | BL2: =表紙!BL65 -> 0 | BU2: =表紙!BU65 -> 0 | CB2: =表紙!CB65 -> 0
O3: =RIGHT(CELL("filename",$A$1),LEN(CELL("filename",$A$1))-FIND("]",CELL("filename",$A$1))) -> 補足説明資料(OLD) | AC3: 表題 | AJ3: =表紙!AJ66 -> 0 | AQ3: =表紙!AQ66 -> 0
AO5: 補足説明
C33: 図 7-1 取引先場所系マスタ関連図
C53: 図 15-1 販売系マスタ関連図
B89: 固定値に関して
B91: 外部ファイルの読込みやワークテーブルで管理する。
B119: 得意先担当マスタ オペレーション案
B121: ① | C121: 現行データ：解除
B149: ② | C149: 新規データ：取込
F162: EXCEL加工し、インポート
