Workbook
Name Rev.: 表紙!$U$22
Name Ver.: 表紙!$AE$26
Name ご確認者: 表紙!$AG$40
Name ご確認日: 表紙!$AG$42
Name サブシステム名: 表紙!$U$28
Name システム名: 表紙!$U$26
Name プロジェクト名: 表紙!$U$18
Name 開発区分: 表紙!$U$36
Name 機能ＩＤ: 表紙!$U$32
Name 機能区分: 表紙!$U$34
Name 機能名称: 表紙!$U$30
Name 顧客名: 表紙!$U$16
Name 最終更新者: 表紙!$AB$40
Name 最終更新日: 表紙!$AB$42
Name 作成者: 表紙!$W$40
Name 作成日: 表紙!$W$42
Name 章: 表紙!$M$10
Name 文書名: 表紙!$M$10

Sheet 目次
A1: アドオン設計書作成ガイド
C3: ■アドオン設計と成果物について
D4: ・システム設計フェーズとソフトウェア設計フェーズでアドオンの処理仕様を定義する
D5: ・システム設計フェーズとソフトウェア設計フェーズの成果物がアドオン設計書であり、ソフトウェア製作フェーズのインプットとなる
C7: ■各設計フェーズ毎のアドオン設計書作成範囲
D8: ・システム設計フェーズ：他機能との関連を定義するとともに、画面や帳票、ファイル入出力を中心とした外部入出力の設計を行う
D9: ・ソフトウェア設計フェーズ：内部処理を中心とした設計を行う
U11: ◎ | W11: … | X11: システム設計フェーズで作成
U12: ○ | W12: … | X12: システム設計フェーズで基本仕様を定義して、ソフトウェア設計フェーズで詳細化する
U13: △ | W13: … | X13: 必要に応じて（例えば標準仕様から変更がない場合は不要）
U14: ‐ | W14: … | X14: 不要
W15: … | X15: ソフトウェア設計フェーズで作成
D17: 各設計書と作成対象シートのマトリックス | S17: ※カスタマイズ：標準機能に機能を追加する アドオン：新規で機能を開発する
D18: EXCELシート | N18: 画面設計書 | W18: バッチ設計書 | AF18: 帳票設計書 | AO18: ＢＩ設計書 | AT18: .Net設計書 | BB18: EXCELシート | BL18: WebDB設計書 | BR18: 帳票設計書 | BX18: 汎用申請設計書
N19: カスタマイズ | S19: アドオン | W19: カスタマイズ | AB19: アドオン | AF19: カスタマイズ | AK19: アドオン | AO19: アドオン | AT19: アドオン | BL19: アドオン | BR19: アドオン | BX19: アドオン
D20: 概要 | N20: ◎ | O20: ※1 | S20: ◎ | W20: ◎ | X20: ※1 | AB20: ◎ | AF20: ◎ | AG20: ※1 | AK20: ◎ | AO20: ◎ | AT20: ◎ | BB20: 機能概要 | BL20: ◎ | BR20: ◎ | BX20: ◎
D21: レイアウト | N21: ◎ | O21: ※2 | S21: ◎ | W21: ‐ | AB21: ‐ | AF21: ◎ | AG21: ※2 | AK21: ◎ | AO21: ◎ | AT21: ◎ | BB21: アプリケーションフロー | BL21: ◎ | BR21: ー | BX21: ◎
D22: 項目説明 | N22: △ | S22: ○ | W22: ‐ | AB22: ‐ | AF22: △ | AK22: ○ | AO22: ○ | AT22: ○ | BB22: データベース設定 | BL22: ◎ | BR22: ー | BX22: ◎
D23: 引数説明 | N23: ‐ | S23: ‐ | W23: △ | AB23: ◎ | AF23: ‐ | AK23: ‐ | AO23: ‐ | AT23: ◎ | BB23: フィールド設定 | BL23: ◎ | BR23: ー | BX23: ◎
D24: 処理概要 | N24: ◎ | S24: ◎ | W24: ◎ | AB24: ◎ | AF24: ◎ | AK24: ◎ | AO24: ◎ | AT24: ◎ | BB24: 一覧表示画面設定 | BL24: ◎ | BR24: ー | BX24: ◎
D25: 処理詳細 | BB25: 表示編集画面設定 | BL25: ◎ | BR25: ー | BX25: ◎
D26: 処理・サービス関連図 | N26: △ | S26: ◎ | W26: △ | AB26: ◎ | AF26: ‐ | AK26: ‐ | AO26: ‐ | AT26: ◎ | BB26: 明細画面設定 | BL26: △ | BN26: ※3 | BR26: ー | BX26: △ | BZ26: ※3
D27: 検索入出力仕様 | N27: △ | S27: ○ | W27: △ | AB27: ○ | AF27: ‐ | AK27: ‐ | AO27: ‐ | AT27: ○ | BB27: 集計表示設定 | BL27: △ | BN27: ※4 | BR27: ー | BX27: △ | BZ27: ※4
D28: 更新入出力仕様 | N28: △ | S28: ○ | W28: △ | AB28: ○ | AF28: ‐ | AK28: ‐ | AO28: ‐ | AT28: ○ | BB28: 絞り込み条件設定 | BL28: △ | BN28: ※5 | BR28: ー | BX28: △ | BZ28: ※5
D29: ファイル入出力仕様 | N29: △ | S29: △ | W29: ‐ | AB29: ‐ | AF29: ‐ | AK29: ‐ | AO29: ‐ | AT29: △ | BB29: その他設定 | BR29: ー
D30: 画面遷移 | N30: △ | S30: ◎ | W30: ‐ | AB30: ‐ | AF30: ‐ | AK30: ‐ | AO30: ‐ | AT30: ◎ | BB30: 帳票イメージ | BL30: ー | BR30: ◎ | BX30: ー
D31: メッセージ一覧 | N31: △ | S31: △ | W31: △ | AB31: △ | AF31: ‐ | AK31: ‐ | AO31: ‐ | AT31: △ | BB31: 項目設計 | BL31: ー | BR31: ◎ | BX31: ー
D32: 補足説明 | N32: △ | S32: △ | W32: △ | AB32: △ | AF32: △ | AK32: △ | AO32: △ | AT32: △ | BB32: 補足説明 | BL32: △ | BR32: △ | BX32: △
D33: サービス呼出編集仕様 | N33: - | S33: - | W33: - | AB33: - | AF33: - | AK33: - | AO33: - | AT33: - | BB33: 補足説明(詳細)
D35: ※1 | G35: 別シートでカスタマイズ内容を記載する | BB35: ※3 | BE35: 単票画面は記載しない
D36: ※2 | G36: 吹き出しでカスタマイズ内容を記載する | BB36: ※4 | BE36: 集計・グラフ機能を使用する場合に記載する
BB37: ※5 | BE37: 共通設定のみ記載する(個別設定は、記載しない)

Sheet 表紙
AW2: サブモジュール
AW3: MA_マスタ管理
AW4: MB_業務共通
AW5: MG_原価管理
AW6: MSBA_需給管理
M7: 基本設計 | AW7: MSBB_販売管理
AW8: MSBC_生産管理
AW9: MSBD_購買管理
M10: アドオン設計書 | AW10: MSBE_在庫物流管理
AW11: MSBF_品質管理
AW12: MSBG_債権管理
AW13: MSBH_債務管理
AW14: MSBI_締処理
AW15: MSUA_リスト・入力補助
M16: 顧客 | U16: 株式会社クラウン・パッケージ | AW16: PF_ESBアダプタ
M18: プロジェクト名 | U18: 基幹システム刷新PJ | AW18: 機能区分
AW19: 画面
M20: 文書番号 | AW20: 帳票
AW21: バッチ
M22: Ｒｅｖ． | U22: {=MAX(_xlfn.NUMBERVALUE(改訂!A7:E48))} -> 2 | AW22: マスタ
M24: 機密性区分 | U24: 取扱注意（Ｃ） | AW24: 開発区分
AW25: カスタマイズ
M26: システム名 | U26: Webシステム | AC26: Ver. | AE26: 1.0.0 | AW26: アドオン
AW27: －
M28: サブモジュール | U28: MSBB_販売管理
M30: 機能名 | U30: =M50 -> Webシステム(共通概要)
M32: 機能ID | U32: =G50 -> MSBBPA000
M34: 機能区分 | U34: 画面
M36: 開発区分 | U36: アドオン
W39: 作成 | AB39: 最終更新 | AG39: ご確認
W40: MDSOL | AB40: MDSOL 石田
W42: 44806 | AB42: 44994
A48: 文書番号 | G48: 画面ID | M48: 画面名 | V48: Version | AB48: Revision
A50: M7-US-1140 | G50: MSBBPA000 | M50: Webシステム(共通概要) | V50: 1.0.0 | AB50: r01.00
A53: 共通（元データ）
A54: Webシステム | K54: 文書名 | U54: モジュールID | Z54: MS | AE54: モジュール名 | AJ54: Webシステム | AS54: 文書番号 | AZ54: Version | BF54: Rev.
K55: 画面説明書 | U55: ｻﾌﾞﾓｼﾞｭｰﾙID | Z55: MSBB | AE55: ｻﾌﾞﾓｼﾞｭｰﾙ名 | AJ55: Webシステム | AS55: M7-US-1140 | AZ55: 1.0.0 | BF55: r00.00
K56: 表紙 | U56: 表題 | Z56: MSBBPA000 | AE56: Webシステム(共通概要)
A57: 共通（リンク用）
A58: =A54 -> Webシステム | K58: 文書名 | U58: モジュールID | Z58: =Z54 -> MS | AE58: モジュール名 | AJ58: =AJ54 -> Webシステム | AS58: 文書番号 | AZ58: Version | BF58: Rev.
...

Sheet 改訂
A1: 第7章 | K1: 改訂 | AU1: 作成者 | AZ1: MDSOL | BE1: 作成日 | BJ1: =表紙!W42 -> 44806 | BP1: Rev.
AU2: 修正者 | AZ2: =BM10 -> MDSOL石田 | BE2: 改訂日 | BJ2: =MAX(改訂!BM7:BQ52) -> 44994 | BP2: =表紙!CB64 -> 2
A5: Rev. | F5: 改定内容 | BC5: 頁 | BM5: 変更日 変更者 | BR5: 確認日 確認者
A7: 1 | F7: 新規作成
A9: 2 | F9: RCS-1229:原紙コード、コード名称部品の取得方法変更 | BC9: 汎用検索(共通検索) | BM9: 44994 | BR9: 44995
BM10: MDSOL石田 | BR10: MDSOL奥本

Sheet 概要
A1: Webシステム | O1: 文書名 | AC1: モジュールID | AJ1: =表紙!AJ63 -> MS | AQ1: モジュール名 | AX1: =表紙!AX63 -> Webシステム | BL1: 文書番号 | BU1: Version | CB1: Rev.
O2: =表紙!O64 -> アドオン設計書 | AC2: サブモジュールID | AJ2: =表紙!AJ64 -> MSBB | AQ2: サブモジュール名 | AX2: =表紙!AX64 -> Webシステム | BL2: =表紙!BL64 -> M7-US-1140 | BU2: =表紙!BU64 -> 1.0.0 | CB2: =表紙!CB64 -> 2
O3: =RIGHT(CELL("filename",$A$1),LEN(CELL("filename",$A$1))-FIND("]",CELL("filename",$A$1))) -> 概要 | AC3: 表題 | AJ3: =表紙!AJ65 -> MSBBPA000 | AQ3: =表紙!AQ65 -> Webシステム(共通概要)
AO5: 概要
B7: 【説明】
B8: 目的：Webシステムを構築する。
B9: 背景：見積業務は、機能要求レベルが高く、UIに機能制限があるPOWER EGGでの実現が難しく、Webシステム(スクラッチ開発)を新規に構築する。
D10: →難易度の高い：見積入力・製品マスタ・受注入力もWebシステムにて構築する。
B12: 【前提条件】
B13: 社内システムとする。(インターネット公開型システムとしない。)
B14: ヒアリングシート システムとは、別Webアプリケーションとする。
B19: 【システム構成】
BG24: № | BI24: システム | BO24: 概要
BI25: 処理例
BG26: ① | BI26: Webシステム | BO26: 受注・マスタ連携
BI27: 受注・マスタ連携
BG28: ② | BI28: Webシステム | BO28: DB Link（PE→Web）
BI29: 案件DBの参照、PE管理DBの参照
BG30: ③ | BI30: Webシステム | BO30: DB Link（mcframe7→Web）
BI31: mcframe7 DBの参照(チェック処理、汎用マスタ参照)
BG32: ④ | BI32: Webシステム | BO32: API連携
BI33: ワークフロー申請、Webデータベース操作
BG34: ⑤ | BI34: POWER EGG | BO34: PE機能 外部DB参照(mcframe7)
BI35: mcframe7 DBの参照
BG36: ⑥ | BI36: POWER EGG | BO36: PE機能 外部DB参照(Webシステム)
BI37: Webシステム DBの参照
BG38: ⑦ | BI38: POWER EGG | BO38: 外部システム連携(PE→Webシステム)
BI39: PEメニューより、Webシステム起動
BG40: ⑧ | BI40: POWER EGG | BO40: TRIGGER（PE→Web）
BI41: ワークフロー申請後のステータス更新等
B56: 【システム構成（ソフトウェア構成）】
C57: Webサーバ 実行環境
C58: サーバ | I58: OS | O58: Windows Server
O59: ※mcframe7・POWER EGGとの共存は想定しない。 | AX59: CP指摘 2022/10/22 落合 mcfとPEのサーバーは別にします
I60: DB | O60: Oracle | AY60: MDSOL 野村 2022/10/25 mcframe7、POWER EGG、WEBサーバ各々別である必要があります。 | CF60: 2022/10/27 落合 問題なし
O61: ※mcframe7用のOracleに構築する。
O62: (Webシステム用のスキーマーを分けて管理する。)
I63: Webサービス | O63: IIS (Microsoft Internet Information Services)
I64: フレームワーク | O64: ASP.NET MVC・.NET Framework 4.8
C66: クライアント | I66: OS | O66: Windows OS
...

Sheet 概要(制限事項)
A1: Webシステム | O1: 文書名 | AC1: モジュールID | AJ1: =表紙!AJ63 -> MS | AQ1: モジュール名 | AX1: =表紙!AX63 -> Webシステム | BL1: 文書番号 | BU1: Version | CB1: Rev.
O2: =表紙!O64 -> アドオン設計書 | AC2: サブモジュールID | AJ2: =表紙!AJ64 -> MSBB | AQ2: サブモジュール名 | AX2: =表紙!AX64 -> Webシステム | BL2: =表紙!BL64 -> M7-US-1140 | BU2: =表紙!BU64 -> 1.0.0 | CB2: =表紙!CB64 -> 2
O3: =RIGHT(CELL("filename",$A$1),LEN(CELL("filename",$A$1))-FIND("]",CELL("filename",$A$1))) -> 概要(制限事項) | AC3: 表題 | AJ3: =表紙!AJ65 -> MSBBPA000 | AQ3: =表紙!AQ65 -> Webシステム(共通概要)
AO5: 概要
B7: 【Web 画面 制限事項】
C8: 項目 | M8: 設定内容 | W8: 備考
C9: ブラウザの『進む』ボタン | M9: ー | W9: 『進む、戻る、更新』等のブラウザ標準ボタンとWebシステム間には制限や制御機能を設けていません。 これらのボタンはブラウザ固有の機能になる為、Webシステムの動作を保証出来ません。
C10: ブラウザの『戻る』ボタン | M10: ー
C11: ブラウザの『更新』ボタン | M11: ー
C12: その他、ブラウザのボタン | M12: ー
C13: 全体 | M13: ー | W13: 各項目の内容は表示・印字幅の制限で文字・数字の全桁数を表示出来ない事が有ります。
W14: ※品名や備考のテキストボックスの項目は、文字数がフルで表示されるように項目幅を調整する。
C15: ※ブラウザの『進む』・『戻る』ボタンを利用し、各画面の初期表示処理が正常に行えない場合はエラーページに遷移する。
C16: 例：見積計算書入力や製品マスタ画面は、第1画面→第2画面→第3画面等の画面遷移をシステムで制御する必要があり、ブラウザの『進む』・『戻る』ボタンを利用した場合に処理が正常に行えない事が有ります。
B18: 【Web 画面の基本動作・制限事項 オフコン画面との相違点 )】
C19: １．キー操作による入力項目間のカーソル移動
D20: （1）カーソル移動に使用するキー ： [Tab]、[Shift+Tab]キー
E21: ・[Tab]： 順方向 へ移動
E22: ・[Shift+Tab]： 逆方向 へ移動
E23: ※キー操作による項目移動はTab,Shift+Tabのみ有効で、これ以外のキーによる操作（例：Enterで項目移動、ファンクションキーで移動）は対象外とする。
D24: （２）カーソル移動の基本動作イメージ
E25: ・入力項目の配置位置を基準に、[Tab]キーの押下毎に [左]→[右]の項目へ ／ [上]→[下]の項目へ 移動する。
E26: ・カーソル移動の例
F27: [Tab]キーの押下毎に[項目①～⑦]の順にカーソルが移動する。
F28: [Shift+Tab]キー押下の場合は逆順に移動する。
E30: 画面
F31: 項目① | K31: 項目② | P31: 項目③
P33: 項目④
P35: 項目⑤ | U35: 項目⑥
F37: 項目⑦
D40: （３）入力項目以外の[ボタン]、[リンク(下線付き)]も上記の[項目］に含まれ、カーソル移動の対象項目となる。
C42: ２．画面外へのカーソル移動の発生
D43: 画面上の最終入力項目(上記例の[項目⑦])で[Tab]キーの押下時、カーソルが入力画面外へ移動する事がある。
D44: （１）移動先の例： ブラウザ画面上の『アドレスバー、タブ、メニューバー』等。
D45: （２）.2復帰方法： マウス操作で任意の入力項目へ移動。
C47: ３．マウス操作でのカーソル移動
D48: （１）任意の入力項目へマウス移動可能。
D49: （２）任意の[ボタン]、[リンク(下線付き)]の実行が可能。
C51: ４．マスタ参照キー項目入力時の動作
D52: （１）キー項目入力後、[Tab]キーの押下にてマスタ参照と参照項目の表示動作が可能。
...

Sheet 概要(Web非機能要件)
A1: Webシステム | O1: 文書名 | AC1: モジュールID | AJ1: =表紙!AJ63 -> MS | AQ1: モジュール名 | AX1: =表紙!AX63 -> Webシステム | BL1: 文書番号 | BU1: Version | CB1: Rev.
O2: =表紙!O64 -> アドオン設計書 | AC2: サブモジュールID | AJ2: =表紙!AJ64 -> MSBB | AQ2: サブモジュール名 | AX2: =表紙!AX64 -> Webシステム | BL2: =表紙!BL64 -> M7-US-1140 | BU2: =表紙!BU64 -> 1.0.0 | CB2: =表紙!CB64 -> 2
O3: =RIGHT(CELL("filename",$A$1),LEN(CELL("filename",$A$1))-FIND("]",CELL("filename",$A$1))) -> 概要(Web非機能要件) | AC3: 表題 | AJ3: =表紙!AJ65 -> MSBBPA000 | AQ3: =表紙!AQ65 -> Webシステム(共通概要)
AO5: 概要
B7: 【Webシステム非機能要件】
C8: １ 標準のクライアント環境
D9: Webシステムを利用するクライアントＰＣの標準環境は下記とします。
E10: ・OS | K10: ： | L10: Windows10
E11: ・ブラウザ | K11: ： | L11: Microsoft Edge、Google Chrome | AA11: →基本検証を行う
E12: ・画面解像度 | K12: ： | L12: 1366＊768 | AA12: →左記をもとに基本1画面に収まる様にプログラム開発する。
E13: ・Microsoft Office | K13: ： | L13: Microsoft 365 | AA13: →基本検証を行う
C15: ２ システムの応答時間(目標値)
D16: No | F16: 項目名 | K16: 操作内容 | W16: CP希望 | AA16: 備考
D17: 1 | F17: 検索処理 | K17: 検索ボタン押下から結果表示まで | X17: 2秒 | AA17: 検索結果 1000件
D18: 2 | F18: 更新処理 | K18: 検索ボタン押下から結果表示まで | X18: 5秒
D19: 3 | F19: 見積計算 | X19: 2秒 | AA19: オフコン2秒なので、5秒だと遅い
D21: 性能目標は、開発時に別途策定する。
D22: システムの応答時間は、N/W・H/W・M/WやクライアントPCの制約も受けるため、実値と乖離がある場合は別途条件などを設けさせて頂く場合があります。
D23: →性能が目標に達成しない場合、チューニング目的でAWSのEC2インスタンス、RDS(Oracle)のスペック変更も検討します。
C25: ３ システムの使用可能範囲
D26: 本プロジェクトで開発するシステムの使用可能範囲は下記の通りです。
D27: ・社内イントラネット（社内ネットワーク）上のパソコンで動作するブラウザ（Microsoft Edge、Google Chrome）から使用可能です。
D28: ・社外（外部）ネットワークからのシステム使用は出来ません。また、携帯端末（タブレット、スマートフォン等）での動作も保証していません。
C30: ４ Webシステム データバックアップについて
D31: mcframe7データベースサーバの同一インスタンス内にでの構築を前提とする。
D32: →mcframe7DBバックアップに準拠する。
D33: 1日一回の自動バックアップとともにトランザクションログが取得される。→災害などでログが喪失していない限り、任意のタイミングにリカバリすることが可能。
D34: ※詳細は、インフラバックアップ資料に記載。
C36: ５ Webシステム 使用履歴データ出力
D37: ・Webシステムにログイン後、ログインID毎の「ログイン、ログアウト、主入力画面」の使用履歴データをデータベース内の操作ログ、テキストログに出力(記録)します。
D38: （使用履歴 … 当該画面で検索、登録等を実行した実績）
D39: ※ログの保存項目に関しては、[システムログ]シートを参照
D40: ・但し、システムにはその操作ログを直接参照する機能が有りません。
D41: →操作ログを参照・加工する場合は、Web側のデータベースに直接アクセスし、データ出力・加工作業を行なっていただきます。
D43: ・製品マスタ・取引先マスタ・主要トランに関しては、テーブル単位での履歴を保存する。
D44: ※TRIGGER機能で、テーブル更新時に履歴テーブルに登録前情報を保存する。
E45: →mcframe7と同様に履歴テーブルは、テーブル名 + [_R]とする。
E46: 項目に関しては、履歴取得のテーブルに履歴ID(NO)、履歴種類を付加したテーブル構成とする。主キーは、履歴ID(連番)とする。
E47: ※レスポンスを考慮し、各テーブルの履歴を取得する・しないは可変とする。
D48: テーブル項目例
...

Sheet 概要(ログイン)
A1: Webシステム | O1: 文書名 | AC1: モジュールID | AJ1: =表紙!AJ63 -> MS | AQ1: モジュール名 | AX1: =表紙!AX63 -> Webシステム | BL1: 文書番号 | BU1: Version | CB1: Rev.
O2: =表紙!O64 -> アドオン設計書 | AC2: サブモジュールID | AJ2: =表紙!AJ64 -> MSBB | AQ2: サブモジュール名 | AX2: =表紙!AX64 -> Webシステム | BL2: =表紙!BL64 -> M7-US-1140 | BU2: =表紙!BU64 -> 1.0.0 | CB2: =表紙!CB64 -> 2
O3: =RIGHT(CELL("filename",$A$1),LEN(CELL("filename",$A$1))-FIND("]",CELL("filename",$A$1))) -> 概要(ログイン) | AC3: 表題 | AJ3: =表紙!AJ65 -> MSBBPA000 | AQ3: =表紙!AQ65 -> Webシステム(共通概要)
AO5: 概要
B7: 【ログインに関して】
B8: ・WEBシステムは、POWER EGGの外部システム連携機能にてシングルサインオンすることを前提とする。
B9: ※本Webシステムには、SAML認証の機能は、構築しません。
B10: POWER EGGからのシングルサインオンとユーザー・パスワード認証機能のみとします。
C11: POWER EGGのメニューから外部Webシステムにシングルサインオン（自動ログイン）する機能を利用する。
C13: Webシステム(起動する外部システム側)に、HTMLのFORMに値を受け取りログインできる仕組みを構築する。
C14: ユーザＩＤ、パスワードをHTMLのFORMから入力する機能を実装する。
D15: ※POWER EGG3.0 管理者マニュアル（第10章 外部システム連携:10.2 外部システムへのシングルサインオンに詳細記載）
D16: 初回起動時にPOWER EGGのクライアント側に設定が必要となります。(システム固定設定も可能)
E17: ※POWER EGG3.0 ユーザーズマニュアル 基本編（第3章 個人設定:3.15 シングルサインオンに詳細記載）
B19: ・多重ログインに関して
C20: 同一ログインIDによる多重ログインは制御しません。
C21: ※POWER EGG自体が多重ログイン可能なため。
C22: ただし、本システムもPOWER EGGも同一ユーザで、同時にログインし操作しないでください。
C23: POWER EGG は一社員一ユーザＩＤで構成されます。同一ユーザ ID で同時にログインし、操作を行うとデータの不整合が発生する恐れがあります。
C24: Webシステムに関しても、ログインIDにてログを保存するため、操作ログが不正なログとなり、データのトレーサビリティが正常に行えなくなります。
B27: ・ログイン処理に関して
D28: ログイン処理
D58: WEBシステムのログインフローに関して
B88: ・mcframe7、POWER EGG、WEBシステムへのURL連携に関して
C89: 各機能URL起動にて連携することを想定しているが、前提条件として各システムログインされた状態であることを必須条件とする。
AE91: 起動元システム | AM91: 起動システム | AT91: ケース
AE92: POWER EGG | AK92: → | AM92: mcframe7 | AT92: メニューから機能を起動
AK93: → | AM93: Webシステム | AT93: メニューから機能を起動
AK94: → | AM94: Webシステム | AT94: ＷＦ申請時のURL参照
AT95: ＷＦ起票者が参照するとは、限らないためログインした状態が必要となる。

Sheet 概要(メニュー制御・DAC)
A1: Webシステム | O1: 文書名 | AC1: モジュールID | AJ1: =表紙!AJ63 -> MS | AQ1: モジュール名 | AX1: =表紙!AX63 -> Webシステム | BL1: 文書番号 | BU1: Version | CB1: Rev.
O2: =表紙!O64 -> アドオン設計書 | AC2: サブモジュールID | AJ2: =表紙!AJ64 -> MSBB | AQ2: サブモジュール名 | AX2: =表紙!AX64 -> Webシステム | BL2: =表紙!BL64 -> M7-US-1140 | BU2: =表紙!BU64 -> 1.0.0 | CB2: =表紙!CB64 -> 2
O3: =RIGHT(CELL("filename",$A$1),LEN(CELL("filename",$A$1))-FIND("]",CELL("filename",$A$1))) -> 概要(メニュー制御・DAC) | AC3: 表題 | AJ3: =表紙!AJ65 -> MSBBPA000 | AQ3: =表紙!AQ65 -> Webシステム(共通概要)
AO5: 概要
B7: 【メニュー制御関して】
B8: ・メニュー制御は、基本共通として、個人単位に機能の使用可否を設定する。(使用しない項目は非表示となる。)
B9: →メニューDBにて共通メニューを取り決め、メニュー非表示DBにて個人単位にメニューを非表示とする。
B10: ※例として、大分類=見積の機能が全て使用しない場合、見積のタブも非表示となる。
C13: 見積 | J13: ▼ | K13: 製品マスタ | R13: ▼ | S13: 受注 | Z13: ▼ | AA13: マスタ | AH13: ▼
C14: ≫ | D14: 見積計算書入力 | M14: タイトル領域
C15: ≫ | D15: 御見積書登録・発行
C16: ≫ | D16: 見積計算書一覧照会
C17: ≫ | D17: 御見積書一覧照会
C18: ≫ | D18: FSC製品化チェックシート出力
B24: 【DAC制御に関して】
B25: ・WEBシステムのDAC制御関しては、表示・出力する対象データに対して、拠点CDの絞込み(変更不可)によって制御/実現する。
B26: ※ログインDB.管理者区分が管理者の場合は、拠点による変更を可能とする。
B27: ※製品マスタは、拠点コードが画面に持たず、各拠点のデータを参照可能とする。
C29: 登録画面
C37: 一覧照会画面

Sheet 概要(ユーザインタフェース共通仕様)
A1: Webシステム | O1: 文書名 | AC1: モジュールID | AJ1: MS | AQ1: モジュール名 | AX1: Webシステム | BL1: 文書番号 | BU1: Version | CB1: Rev.
O2: アドオン設計書 | AC2: サブモジュールID | AJ2: MSBB | AQ2: サブモジュール名 | AX2: Webシステム | BL2: M7-US-1140 | BU2: 1.0.0 | CB2: 1
O3: =RIGHT(CELL("filename",$A$1),LEN(CELL("filename",$A$1))-FIND("]",CELL("filename",$A$1))) -> 概要(ユーザインタフェース共通仕様) | AC3: 表題 | AJ3: - | AQ3: Webシステム(共通概要)
AO5: 概要
B7: 【Webシステム画面】
C8: 分類
C9: 分類 | K9: 説明
C10: 登録画面 | K10: データの登録を行う画面
K11: 例：見積計算書入力、製品マスタ 等
C12: 一覧照会・検索画面 | K12: マスタ・トランデータ等の検索を行う画面
K13: 例：見積計算書一覧照会、Web御見積書一覧照会 等
C14: 簡易検索画面 | K14: 一覧表示し、選択結果(コード、名称)を元画面に返す
C16: 帳票 | K16: 帳票・レポート
K17: 例：見積計算書、御見積書 等
C19: レイアウト（登録画面）
D21: 操作種別 | N21: ○登録 | R21: ○訂正 | V21: ○削除 | Z21: ○参照
N23: コード
D27: 基本情報 | J27: 取引分類
D47: Webシステムの論理削除に関して | DP47: CP指摘 2022/09/22 三宅 論理削除されたデータの復活画面は必要か(画面無しでも復活手順を作っておくことは必要)
E48: 削除登録で削除flg=onで更新する。 | DQ48: →共通仕様に展開
F49: 一覧照会(検索)画面：抽出条件に削除flg☑を追加する。(デフォルト☑off) | DQ49: MDSOL 2022/10/31 野村 論理削除に関しての記述追加(削除仕様・復活方法) | EV49: 2022/11/04 落合 問題なし
F50: ［操作種別：登録・更新］時のDB参照項目は、削除flg□(off)を条件とする。 | AF50: →論理削除された状態での登録を許可しない。(例：取引先マスタが論理削除された状態で、見積書計算で論理削除取引先マスタデータの選択・入力を許可しない。)
F51: ［操作種別：参照］時は、削除flgを加味しない。 | AF51: →過去データ参照のため、論理削除データも表示する。
E53: マスタデータの復活手順
E54: ［操作種別：削除登録］でデータを呼び出し、削除データを呼び出した場合、削除取消とする（取引先マスタ・製品マスタ・版型/木型マスタは、データ復活可能とする。）
F55: 削除登録で削除flg=offで更新する。
C58: レイアウト（一覧照会・検索画面）
BX59: －
D61: 拠点 | AC61: 担当者 | BR61: * | BS61: あいまい検索可能
D62: 日付 | P62: ~
D63: コード | P63: ~
D65: ワード | P65: *
D72: ステータス | J72: ☑未承認 | N72: ☑承認済
D75: № | F75: 担当 | H75: 担当者名 | BY75: △
D76: 1 | F76: 1234 | H76: XXXXX6
D77: 2 | F77: 1234 | H77: XXXXX6
D78: 3 | F78: 1234 | H78: XXXXX6
D79: 4 | F79: 1234 | H79: XXXXX6
D80: 5 | F80: 1234 | H80: XXXXX6
D81: 6 | F81: 1234 | H81: XXXXX6
...

Sheet 概要(メニュー体系)
A1: Webシステム | O1: 文書名 | AC1: モジュールID | AJ1: =表紙!AJ63 -> MS | AQ1: モジュール名 | AX1: =表紙!AX63 -> Webシステム | BL1: 文書番号 | BU1: Version | CB1: Rev.
O2: =表紙!O64 -> アドオン設計書 | AC2: サブモジュールID | AJ2: =表紙!AJ64 -> MSBB | AQ2: サブモジュール名 | AX2: =表紙!AX64 -> Webシステム | BL2: =表紙!BL64 -> M7-US-1140 | BU2: =表紙!BU64 -> 1.0.0 | CB2: =表紙!CB64 -> 2
O3: =RIGHT(CELL("filename",$A$1),LEN(CELL("filename",$A$1))-FIND("]",CELL("filename",$A$1))) -> 概要(メニュー体系) | AC3: 表題 | AJ3: =表紙!AJ65 -> MSBBPA000 | AQ3: =表紙!AQ65 -> Webシステム(共通概要)
AO5: 概要
B7: 【メニュー体系】
D15: ≫ログイン | P15: ≫TOP画面 | AB15: ≫メニュー(大分類) | AN15: ≫機能
B59: 【画面遷移】
B69: 【Web ヘッダー】
C74: ≫ログイン情報表示 | J74: 拠点：〇〇 | O74: 担当者：〇〇 〇〇
C75: ≫ログアウト
B79: 【Web メニュー・データ制御】
C80: ログイン情報を参照し、各機能への遷移・データ参照を制御する。
C82: （例） | E82: 拠点＝本社でログイン時、他拠点のデータは参照不可。
E83: 担当者〇〇は、受注入力使用不可。等
C85: ※POWER EGGの組織図機能と関連して、階層レベルでの制御は想定しない。
D86: 上長〇〇は、担当者〇１・担当者〇２のデータ参照可能。
C87: →要件確認後、ログインテーブルの項目検討。
C88: →現行は、拠点単位にデータ参照可能

Sheet 概要(機能一覧)
A1: Webシステム | O1: 文書名 | AC1: モジュールID | AJ1: =表紙!AJ63 -> MS | AQ1: モジュール名 | AX1: =表紙!AX63 -> Webシステム | BL1: 文書番号 | BU1: Version | CB1: Rev.
O2: =表紙!O64 -> アドオン設計書 | AC2: サブモジュールID | AJ2: =表紙!AJ64 -> MSBB | AQ2: サブモジュール名 | AX2: =表紙!AX64 -> Webシステム | BL2: =表紙!BL64 -> M7-US-1140 | BU2: =表紙!BU64 -> 1.0.0 | CB2: =表紙!CB64 -> 2
O3: =RIGHT(CELL("filename",$A$1),LEN(CELL("filename",$A$1))-FIND("]",CELL("filename",$A$1))) -> 概要(機能一覧) | AC3: 表題 | AJ3: =表紙!AJ65 -> MSBBPA000 | AQ3: =表紙!AQ65 -> Webシステム(共通概要)
AO5: 概要
B7: 【機能一覧】
B8: № | D8: ID | J8: 区分1 | N8: 区分2 | R8: 機能名 | AD8: 機能概要 | BB8: 備考
B9: - | D9: MSBBPA000 | J9: 共通仕様 | R9: Webシステム(共通仕様)
B10: - | D10: MSBBPACOM | J10: 共通仕様 | R10: Webシステム(共通詳細仕様) | AD10: 業務ロジックの共通仕様 | BB10: 主に見積計算書・製品マスタ・受注入力の共通仕様
B11: - | D11: MSBBPAMCF | J11: 共通仕様 | R11: システム(共通詳細仕様) | AD11: 業務ロジックの共通仕様 | BB11: 売上計算・重量計算など(mcframe7・web共通)
B12: 1 | D12: MSBBPA001 | J12: 画面 | N12: 登録 | R12: ログイン画面 | AD12: Webシステムのログイン画面 | BB12: POWER EGGの外部システム連携機能にてシングルサインオンすることを前提とする
B13: 2 | D13: MSBBPA002 | J13: 画面 | N13: 照会 | R13: TOP画面 | AD13: WebシステムのTOP画面
B14: 3 | D14: MSBBPA010 | J14: 画面 | N14: 登録 | R14: Web見積計算書入力
B15: 4 | D15: MSBBPA011 | J15: 関数仕様 | R15: 見積計算 | AD15: 見積計算ロジック
B16: 5 | D16: MSBBPA020 | J16: 画面 | N16: 照会・検索 | R16: Web見積計算書一覧照会
B17: 6 | D17: MSBBPA030 | J17: 画面 | N17: 登録 | R17: Web御見積書登録・発行
B18: 7 | D18: MSBBPA040 | J18: 画面 | N18: 照会・検索 | R18: Web御見積書一覧照会
B19: 8 | D19: MSBBPA050 | J19: 画面 | N19: マスタ | R19: Web製品マスタ
B20: 9 | D20: MSBBPA060 | J20: 画面 | N20: 照会・検索 | R20: Web製品マスタ一覧照会
B21: 10 | D21: MSBBPA070 | J21: 画面 | N21: 登録 | R21: Web受注入力
B22: 11 | D22: MSBBPA080 | J22: 画面 | N22: 照会・検索 | R22: Web受注一覧照会
B23: 12 | D23: MSBBPA090 | J23: 画面 | N23: 登録 | R23: Web受注一覧登録(単価訂正)
B24: 13 | D24: MSBBPA100 | J24: 画面 | N24: 帳票発行 | R24: WebFSC製品化チェックシート出力
B25: 14 | D25: MSBBPA110 | J25: 画面 | N25: マスタ | R25: Web取引先マスタ | BB25: 得意先マスタ→取引先マスタに変更
B26: 15 | D26: MSBBPA120 | J26: 画面 | N26: 照会・検索 | R26: Web取引先一覧照会
B27: 16 | D27: MSBBPA130 | J27: 画面 | N27: マスタ | R27: Webシート単価マスタ
B28: 17 | D28: MSBBPA140 | J28: 画面 | N28: マスタ | R28: Web版型・木型マスタ
B29: 18 | D29: MSBBPA150 | J29: 画面 | N29: 照会・検索 | R29: Web版型・木型マスタ一覧照会
B30: 19 | D30: MSBBPA900 | J30: 画面 | N30: 照会・検索 | R30: Web汎用検索(共通検索) | AD30: 簡易検索画面
B31: 20
B32: 21
B33: 22
B36: 【帳票一覧】
B37: № | D37: ID | J37: 区分1 | N37: 区分2 | R37: 機能名 | AD37: 機能概要 | BB37: 備考
B38: 1 | D38: MSBBRA010 | J38: 帳票 | N38: PDF | R38: 見積計算書
B39: 2 | D39: MSBBRA020 | J39: 帳票 | N39: PDF | R39: 見積計算書(価格無しVER) | BB39: 2022/5/24 シ設計追加
B40: 3 | D40: MSBBRA030 | J40: 帳票 | N40: PDF | R40: 御見積書
B41: 4 | D41: MSBBRA040 | J41: 帳票 | N41: EXCEL | R41: FSC製品化チェックシート
B42: 5 | D42: MSBBRA050 | J42: 帳票 | N42: PDF | R42: 受注伝票 | BB42: 2022/8/4 シ設計追加
B43: 6
B44: 7
...

Sheet 概要(MCF機能一覧)
A1: Webシステム | O1: 文書名 | AC1: モジュールID | AJ1: =表紙!AJ63 -> MS | AQ1: モジュール名 | AX1: =表紙!AX63 -> Webシステム | BL1: 文書番号 | BU1: Version | CB1: Rev.
O2: =表紙!O64 -> アドオン設計書 | AC2: サブモジュールID | AJ2: =表紙!AJ64 -> MSBB | AQ2: サブモジュール名 | AX2: =表紙!AX64 -> Webシステム | BL2: =表紙!BL64 -> M7-US-1140 | BU2: =表紙!BU64 -> 1.0.0 | CB2: =表紙!CB64 -> 2
O3: =RIGHT(CELL("filename",$A$1),LEN(CELL("filename",$A$1))-FIND("]",CELL("filename",$A$1))) -> 概要(MCF機能一覧) | AC3: 表題 | AJ3: =表紙!AJ65 -> MSBBPA000 | AQ3: =表紙!AQ65 -> Webシステム(共通概要)
A5: 概要(MCF機能一覧) ※バッティング確認用
B7: 【機能一覧】
B8: № | D8: ID | J8: 区分1 | N8: 区分2 | R8: 機能名 | AD8: 機能概要 | BB8: 備考
B9: 1
B10: 2
B11: 3
B12: 4
B13: 5
B14: 6
B15: 7
B16: 8
B17: 9
B18: 10
B21: 【帳票一覧】
B22: № | D22: ID | J22: 区分1 | N22: 区分2 | R22: 機能名 | AD22: 機能概要 | BB22: 備考
B23: 1 | D23: MSBERA010 | J23: 帳票(MCF) | N23: PDF | R23: 納品書兼受領書
B24: 2 | D24: MSBERA020 | J24: 帳票(MCF) | N24: PDF | R24: 積込指示書
B25: 3 | D25: MSBERA030 | J25: 帳票(MCF) | N25: PDF | R25: 在庫場所別出荷案内書
B26: 4
B27: 5
B28: 6
B29: 7
B30: 8
B33: 【バッチ一覧】
B34: № | D34: ID | J34: 区分1 | N34: 区分2 | R34: 機能名 | AD34: 機能概要 | BB34: 備考
B35: 1 | D35: MSBBBA010 | J35: バッチ | R35: 製品マスタ連携
B36: 2 | D36: MSBBBA020 | J36: バッチ | R36: 取引先マスタ連携
B37: ※受注連携は、カスタマイズとなる。
B40: 【VIEW一覧】
B41: № | D41: ID | J41: 区分1 | N41: 区分2 | R41: 機能名 | AD41: 機能概要 | BB41: 備考
B42: 1
B43: 2
B44: 3
B45: 4
B46: 5

Sheet ログイン画面
A1: Webシステム | O1: 文書名 | AC1: モジュールID | AJ1: =表紙!AJ63 -> MS | AQ1: モジュール名 | AX1: =表紙!AX63 -> Webシステム | BL1: 文書番号 | BU1: Version | CB1: Rev.
O2: =表紙!O64 -> アドオン設計書 | AC2: サブモジュールID | AJ2: =表紙!AJ64 -> MSBB | AQ2: サブモジュール名 | AX2: =表紙!AX64 -> Webシステム | BL2: =表紙!BL64 -> M7-US-1140 | BU2: =表紙!BU64 -> 1.0.0 | CB2: =表紙!CB64 -> 2
O3: =RIGHT(CELL("filename",$A$1),LEN(CELL("filename",$A$1))-FIND("]",CELL("filename",$A$1))) -> ログイン画面 | AC3: 表題 | AJ3: =表紙!AJ65 -> MSBBPA000 | AQ3: =表紙!AQ65 -> Webシステム(共通概要)
A5: 画面イメージ
C8: 【機能概要】
D9: 1. | E9: ログイン画面
E10: POWER EGGの外部システム連携機能にてシングルサインオンすることを前提とするため、通常は利用しない。
E11: ※直接ログインしたい場合やログアウトボタン押下時、シングルサインオンのログイン処理にて失敗した場合に遷移する。
E12: 共通・TOP画面の共通ヘッダーは利用しない。
C14: 【レイアウト】
C16: WEBシステム
D18: ログイン
H22: ログインID
H24: パスワード
K28: エラーメッセージ表示エリア
C33: 【前提条件】
D34: 1. | E34: ログイン情報は、POWER EGG ＤＢにて管理する。
BX73: － | CA73: － | CB73: … | CC73: 抽出条件を閉じる
BX74: +
CA75: + | CB75: … | CC75: 抽出条件を開く
BX77: +
D79: № | F79: 担当 | H79: 担当者名 | K79: 得意先 | N79: 得意先名 | R79: 案件№ | W79: 案件名 | AA79: 見積計算書№ | AF79: 見積作成日 | AJ79: 顧客品名 | AU79: 見積数 | AY79: 決定予想 | BA79: 見積平米 | BE79: ㎡単価 | BI79: 金額 | BM79: 見積区分 | BO79: 承認ステータス | BR79: 計算書 | BT79: 製品コード
D80: 1 | F80: 1234 | H80: XXXXX6 | K80: 12345 | N80: XXXXXXX8 | R80: 1234567-001 | W80: XXXXXXX8 | AA80: 12345678-01 | AF80: 2022/7/1 | AJ80: XXXXXXXXX1XXXXX6 | AQ80: XXXXXXX8 | AU80: 9999999 | BA80: 9999999 | BE80: 9999999 | BI80: 9999999 | BM80: 通常 | BO80: 承認済 | BR80: □
D81: 2 | F81: 1234 | H81: XXXXX6 | K81: 12345 | N81: XXXXXXX8 | R81: 1234567-001 | W81: XXXXXXX8 | AA81: 12345678-02 | AF81: 2022/7/1 | AJ81: XXXXXXXXX1XXXXX6 | AQ81: XXXXXXX8 | AU81: 9999999 | BA81: 9999999 | BE81: 9999999 | BI81: 9999999 | BM81: 通常 | BO81: 承認済 | BR81: □
D82: 3 | F82: 1234 | H82: XXXXX6 | K82: 12345 | N82: XXXXXXX8 | R82: 1234567-001 | W82: XXXXXXX8 | AA82: 12345678-03 | AF82: 2022/7/1 | AJ82: XXXXXXXXX1XXXXX6 | AQ82: XXXXXXX8 | AU82: 9999999 | AY82: ● | BA82: 9999999 | BE82: 9999999 | BI82: 9999999 | BM82: 通常 | BO82: 承認済 | BR82: □ | BT82: A9999999-01
D83: 4 | F83: 1234 | H83: XXXXX6 | K83: 12345 | N83: XXXXXXX8 | R83: 1234567-001 | W83: XXXXXXX8 | AA83: 12345678-04 | AF83: 2022/7/1 | AJ83: XXXXXXXXX1XXXXX6 | AQ83: XXXXXXX8 | AU83: 9999999 | BA83: 9999999 | BE83: 9999999 | BI83: 9999999 | BM83: 通常 | BO83: 承認済 | BR83: □
D84: 5 | F84: 1234 | H84: XXXXX6 | K84: 12345 | N84: XXXXXXX8 | R84: 1234567-001 | W84: XXXXXXX8 | AA84: 12345678-05 | AF84: 2022/7/1 | AJ84: XXXXXXXXX1XXXXX6 | AQ84: XXXXXXX8 | AU84: 9999999 | BA84: 9999999 | BE84: 9999999 | BI84: 9999999 | BM84: 通常 | BO84: 承認済 | BR84: □
D85: 6 | F85: 1234 | H85: XXXXX6 | K85: 12345 | N85: XXXXXXX8 | R85: 1234567-001 | W85: XXXXXXX8 | AA85: 12345680-01 | AF85: 2022/7/1 | AJ85: YYYYYYYYY1XXXXX6 | AQ85: XXXXXX01 | AU85: 9999999 | AY85: ● | BA85: 9999999 | BE85: 9999999 | BI85: 9999999 | BM85: 決定 | BO85: 未承認 | BR85: □ | BT85: A9999999-01
D86: 7 | F86: 1234 | H86: XXXXX6 | K86: 12345 | N86: XXXXXXX8 | R86: 1234567-001 | W86: XXXXXXX8 | AA86: 12345681-01 | AF86: 2022/7/1 | AJ86: YYYYYYYYY1XXXXX6 | AQ86: XXXXXX02 | AU86: 9999999 | AY86: ● | BA86: 9999999 | BE86: 9999999 | BI86: 9999999 | BM86: 決定 | BO86: 未承認 | BR86: □ | BT86: A9999999-01
D87: 8 | F87: 1234 | H87: XXXXX6 | K87: 12345 | N87: XXXXXXX8 | R87: 1234567-001 | W87: XXXXXXX8 | AA87: 12345682-01 | AF87: 2022/7/1 | AJ87: YYYYYYYYY1XXXXX6 | AQ87: XXXXXX03 | AU87: 9999999 | AY87: ● | BA87: 9999999 | BE87: 9999999 | BI87: 9999999 | BM87: 決定 | BO87: 未承認 | BR87: □ | BT87: A9999999-01
D88: 9 | F88: 1234 | H88: XXXXX6 | K88: 12345 | N88: XXXXXXX8 | R88: 1234567-001 | W88: XXXXXXX8 | AA88: 12345683-01 | AF88: 2022/7/1 | AJ88: YYYYYYYYY1XXXXX6 | AQ88: XXXXXX04 | AU88: 9999999 | BA88: 9999999 | BE88: 9999999 | BI88: 9999999 | BM88: 通常 | BO88: 未承認 | BR88: □
D89: 10 | F89: 1234 | H89: XXXXX6 | K89: 12345 | N89: XXXXXXX8 | R89: 1234567-001 | W89: XXXXXXX8 | AA89: 12345683-02 | AF89: 2022/7/1 | AJ89: YYYYYYYYY1XXXXX6 | AQ89: XXXXXX05 | AU89: 9999999 | AY89: ● | BA89: 9999999 | BE89: 9999999 | BI89: 9999999 | BM89: 決定 | BO89: 未承認 | BR89: □ | BT89: A9999999-01
D90: 11 | F90: 1234 | H90: XXXXX6 | K90: 12345 | N90: XXXXXXX8 | R90: 1234567-001 | W90: XXXXXXX8 | AA90: 12345683-02 | AF90: 2022/7/1 | AJ90: YYYYYYYYY1XXXXX6 | AQ90: XXXXXX05 | AU90: 9999999 | AY90: ● | BA90: 9999999 | BE90: 9999999 | BI90: 9999999 | BM90: 決定 | BO90: 未承認 | BR90: □ | BT90: A9999999-01
D91: 12 | F91: 1234 | H91: XXXXX6 | K91: 12345 | N91: XXXXXXX8 | R91: 1234567-001 | W91: XXXXXXX8 | AA91: 12345683-02 | AF91: 2022/7/1 | AJ91: YYYYYYYYY1XXXXX6 | AQ91: XXXXXX05 | AU91: 9999999 | AY91: ● | BA91: 9999999 | BE91: 9999999 | BI91: 9999999 | BM91: 決定 | BO91: 未承認 | BR91: □ | BT91: A9999999-01
D92: 13 | F92: 1234 | H92: XXXXX6 | K92: 12345 | N92: XXXXXXX8 | R92: 1234567-001 | W92: XXXXXXX8 | AA92: 12345683-02 | AF92: 2022/7/1 | AJ92: YYYYYYYYY1XXXXX6 | AQ92: XXXXXX05 | AU92: 9999999 | AY92: ● | BA92: 9999999 | BE92: 9999999 | BI92: 9999999 | BM92: 決定 | BO92: 未承認 | BR92: □ | BT92: A9999999-01
D93: 14 | F93: 1234 | H93: XXXXX6 | K93: 12345 | N93: XXXXXXX8 | R93: 1234567-001 | W93: XXXXXXX8 | AA93: 12345683-02 | AF93: 2022/7/1 | AJ93: YYYYYYYYY1XXXXX6 | AQ93: XXXXXX05 | AU93: 9999999 | AY93: ● | BA93: 9999999 | BE93: 9999999 | BI93: 9999999 | BM93: 決定 | BO93: 未承認 | BR93: □ | BT93: A9999999-01
D94: 15 | F94: 1234 | H94: XXXXX6 | K94: 12345 | N94: XXXXXXX8 | R94: 1234567-001 | W94: XXXXXXX8 | AA94: 12345683-02 | AF94: 2022/7/1 | AJ94: YYYYYYYYY1XXXXX6 | AQ94: XXXXXX05 | AU94: 9999999 | AY94: ● | BA94: 9999999 | BE94: 9999999 | BI94: 9999999 | BM94: 決定 | BO94: 未承認 | BR94: □ | BT94: A9999999-01
D95: 16 | F95: 1234 | H95: XXXXX6 | K95: 12345 | N95: XXXXXXX8 | R95: 1234567-001 | W95: XXXXXXX8 | AA95: 12345683-02 | AF95: 2022/7/1 | AJ95: YYYYYYYYY1XXXXX6 | AQ95: XXXXXX05 | AU95: 9999999 | AY95: ● | BA95: 9999999 | BE95: 9999999 | BI95: 9999999 | BM95: 決定 | BO95: 未承認 | BR95: □ | BT95: A9999999-01
D96: 17 | F96: 1234 | H96: XXXXX6 | K96: 12345 | N96: XXXXXXX8 | R96: 1234567-001 | W96: XXXXXXX8 | AA96: 12345683-02 | AF96: 2022/7/1 | AJ96: YYYYYYYYY1XXXXX6 | AQ96: XXXXXX05 | AU96: 9999999 | AY96: ● | BA96: 9999999 | BE96: 9999999 | BI96: 9999999 | BM96: 決定 | BO96: 未承認 | BR96: □ | BT96: A9999999-01
D97: 18 | F97: 1234 | H97: XXXXX6 | K97: 12345 | N97: XXXXXXX8 | R97: 1234567-001 | W97: XXXXXXX8 | AA97: 12345683-02 | AF97: 2022/7/1 | AJ97: YYYYYYYYY1XXXXX6 | AQ97: XXXXXX05 | AU97: 9999999 | AY97: ● | BA97: 9999999 | BE97: 9999999 | BI97: 9999999 | BM97: 決定 | BO97: 未承認 | BR97: □ | BT97: A9999999-01
...

Sheet 項目説明(ログイン画面)
A1: =表紙!A54 -> Webシステム | K1: 文書名 | U1: モジュールID | Z1: =表紙!$AJ$63 -> MS | AE1: モジュール名 | AJ1: =表紙!$AX$63 -> Webシステム | AS1: 文書番号 | AZ1: Version | BF1: Rev.
K2: =表紙!O64 -> アドオン設計書 | U2: ｻﾌﾞﾓｼﾞｭｰﾙID | Z2: =表紙!$AJ$64 -> MSBB | AE2: ｻﾌﾞﾓｼﾞｭｰﾙ名 | AJ2: =表紙!$AX$64 -> Webシステム | AS2: =表紙!$BL$64 -> M7-US-1140 | AZ2: =表紙!$BU$64 -> 1.0.0 | BF2: =表紙!$CB$64 -> 2
K3: =RIGHT(CELL("filename",$A$1),LEN(CELL("filename",$A$1))-FIND("]",CELL("filename",$A$1))) -> 項目説明(ログイン画面) | U3: 表題 | Z3: =表紙!$AJ$65 -> MSBBPA000 | AE3: =表紙!$AQ$65 -> Webシステム(共通概要)
A5: ログイン画面
B6: ログイン | N6: 説明 | BE6: リ | BF6: 型 | BG6: 参 | BH6: コ | BI6: 入 | BJ6: 非 | BK6: Ｏ
B7: ログインID | BF7: S
B8: パスワード | BF8: S
B9: ログイン | M9: ログイン処理を実施する | BF9: B
B10: エラーメッセージ | M10: エラーメッセージ表示エリア | BF10: S

Sheet 処理詳細(ログイン画面)
A1: =表紙!A54 -> Webシステム | K1: 文書名 | U1: モジュールID | Z1: =表紙!$AJ$63 -> MS | AE1: モジュール名 | AJ1: =表紙!$AX$63 -> Webシステム | AS1: 文書番号 | AZ1: Version | BF1: Rev.
K2: =表紙!O64 -> アドオン設計書 | U2: ｻﾌﾞﾓｼﾞｭｰﾙID | Z2: =表紙!$AJ$64 -> MSBB | AE2: ｻﾌﾞﾓｼﾞｭｰﾙ名 | AJ2: =表紙!$AX$64 -> Webシステム | AS2: =表紙!$BL$64 -> M7-US-1140 | AZ2: =表紙!$BU$64 -> 1.0.0 | BF2: =表紙!$CB$64 -> 2
K3: =RIGHT(CELL("filename",$A$1),LEN(CELL("filename",$A$1))-FIND("]",CELL("filename",$A$1))) -> 処理詳細(ログイン画面) | U3: 表題 | Z3: =表紙!$AJ$65 -> MSBBPA000 | AE3: =表紙!$AQ$65 -> Webシステム(共通概要)
A5: ログイン/ログアウト/共通画面
A6: No | B6: 入力 | J6: 処理 | BD6: 出力
A7: 1 | B7: 初期起動時
K9: セッションを破棄する
A12: 2 | B12: ログイン | J12: ログインボタン押下時
K14: ログイン(外部呼出し時、含む)
K15: ≫ログイン時、ログイン情報を取得し、セッション変数に保持する。
L17: ログイン処理
M18: チェック処理
N19: ログインIDが無い場合:ユーザIDを入力してください。 | AD19: →エラー領域にメッセージを表示する。
N20: パスワードが無い場合:パスワードを入力してください。 | AD20: →エラー領域にメッセージを表示する。
M22: ① | N22: 外部呼出し時 | T22: HTMLのFORMに値(userid)
N23: ログイン画面時 | T23: 画面.ログインID | AD23: をキーとして、ログインDBを参照する。
M25: ② | N25: 外部呼出し時 | T25: HTMLのFORMに値(pass) | AD25: とログインDB.パスワードと一致すれば正常ログインとして処理する
N26: ログイン画面時 | T26: 画面.パスワード | AD26: 一致しない場合、「ユーザIDまたはパスワードが違います。」と
AD27: →エラー領域にメッセージを表示する。
L29: 正常ログイン時、「ユーザID、管理者区分、拠点CD、担当者CD」情報をセッションに保持する。
K31: ログデータの出力
K32: ≫各機能の初期起動時にログインログを出力する。

Sheet ログインVIEW
A1: =表紙!A54 -> Webシステム | K1: 文書名 | U1: モジュールID | Z1: =表紙!$AJ$63 -> MS | AE1: モジュール名 | AJ1: =表紙!$AX$63 -> Webシステム | AS1: 文書番号 | AZ1: Version | BF1: Rev.
K2: =表紙!O64 -> アドオン設計書 | U2: ｻﾌﾞﾓｼﾞｭｰﾙID | Z2: =表紙!$AJ$64 -> MSBB | AE2: ｻﾌﾞﾓｼﾞｭｰﾙ名 | AJ2: =表紙!$AX$64 -> Webシステム | AS2: =表紙!$BL$64 -> M7-US-1140 | AZ2: =表紙!$BU$64 -> 1.0.0 | BF2: =表紙!$CB$64 -> 2
K3: =RIGHT(CELL("filename",$A$1),LEN(CELL("filename",$A$1))-FIND("]",CELL("filename",$A$1))) -> ログインVIEW | U3: 表題 | Z3: =表紙!$AJ$65 -> MSBBPA000 | AE3: =表紙!$AQ$65 -> Webシステム(共通概要)
A5: テーブル名 | O5: 日本語名 | AE5: 種別 | AK5: 備考
A6: HT2_EMPLOYEE、WEBDB結合VIEW | O6: ログイン | AE6: アドオン(新規) | AK6: PEテーブルとなるためDBLINKにて参照する
A8: 主キー | D8: 項目名 | O8: 日本語名 | AE8: 型 | AG8: 桁 | AI8: Null | AK8: 説明 | BL8: 値の制限 | BM8: 設定仕様 | BN8: 未設定時の振る舞い
O9: 社員ID | AE9: N | AG9: 10 | AK9: HT2_EMPLOYEE(PE標準テーブル)
O10: 名前 | AE10: C | AK10: HT2_EMPLOYEE(PE標準テーブル)
O11: ふりがな | AE11: C | AK11: HT2_EMPLOYEE(PE標準テーブル)
A12: 〇 | O12: ユーザID | AE12: C | AK12: HT2_EMPLOYEE(PE標準テーブル)
O13: パスワード | AK13: WEBDB(付加項目)
O14: 管理者区分 | AE14: F | AI14: N | AK14: WEBDB(付加項目) | AR14: 管理者、一般利用者は判断する区分 | BL14: 0、1 | BM14: 「1=管理者」設定時、拠点コードの変更を可能とする。 | BN14: [0、1]どちらか必須設定
O15: 拠点CD | AE15: N | AI15: N | AK15: WEBDB(付加項目) | BL15: 拠点マスタに登録された値 | BN15: 必須設定
O16: 担当者CD | AE16: C | AG16: 500 | AI16: N | AK16: WEBDB(付加項目) | BL16: 担当者マスタに登録された値 | BN16: 必須設定
O17: 登録日時 | AE17: D
O18: 登録者 | AE18: N | AG18: 10
O19: 最終更新日時 | AE19: D
O20: 最終更新者 | AE20: N | AG20: 10

Sheet 共通・TOP画面
A1: Webシステム | O1: 文書名 | AC1: モジュールID | AJ1: =表紙!AJ63 -> MS | AQ1: モジュール名 | AX1: =表紙!AX63 -> Webシステム | BL1: 文書番号 | BU1: Version | CB1: Rev.
O2: =表紙!O64 -> アドオン設計書 | AC2: サブモジュールID | AJ2: =表紙!AJ64 -> MSBB | AQ2: サブモジュール名 | AX2: =表紙!AX64 -> Webシステム | BL2: =表紙!BL64 -> M7-US-1140 | BU2: =表紙!BU64 -> 1.0.0 | CB2: =表紙!CB64 -> 2
O3: =RIGHT(CELL("filename",$A$1),LEN(CELL("filename",$A$1))-FIND("]",CELL("filename",$A$1))) -> 共通・TOP画面 | AC3: 表題 | AJ3: =表紙!AJ65 -> MSBBPA000 | AQ3: =表紙!AQ65 -> Webシステム(共通概要)
A5: 画面イメージ
C8: 【機能概要】
D9: 1. | E9: Webシステムの共通画面(共通ヘッダー)
D10: 2. | E10: Webシステムに遷移された場合に表示されるTOP画面
C12: 【レイアウト】
C14: 見積 | J14: ▼ | K14: 製品マスタ | R14: ▼ | S14: 受注 | Z14: ▼ | AA14: マスタ | AH14: ▼ | BQ14: ○○拠点 ○○ ○○
C15: ≫ | D15: 見積計算書入力 | M15: タイトル領域
C16: ≫ | D16: 御見積書登録・発行
C17: ≫ | D17: 見積計算書一覧照会
C18: ≫ | D18: 御見積書一覧照会
C19: ≫ | D19: FSC製品化チェックシート出力
D21: お知らせ
D23: № | F23: 表示日付 | J23: タイトル
D24: 1 | F24: 2022/7/1 | J24: △△△△△△△△△△
D25: 2 | F25: 2022/7/1 | J25: △△△△△△△△△△
D26: 3 | F26: 2022/7/1 | J26: △△△△△△△△△△
D27: 4 | F27: 2022/7/1 | J27: △△△△△△△△△△
D28: 5 | F28: 2022/7/1 | J28: △△△△△△△△△△
D29: 6 | F29: 2022/7/1 | J29: △△△△△△△△△△
D30: 7 | F30: 2022/7/1 | J30: △△△△△△△△△△
D31: 8 | F31: 2022/7/1 | J31: △△△△△△△△△△
D32: 9 | F32: 2022/7/1 | J32: △△△△△△△△△△
D33: 10 | F33: 2022/7/1 | J33: △△△△△△△△△△
C38: 【前提条件】
D39: 1. | E39: お知らせのデータ登録・データメンテナンス用の画面は用意しない。データの投入はSQLやDBに直接アクセスしメンテする。
D40: 2. | E40: メニューのデータ登録・データメンテナンス用の画面は用意しない。データの投入はSQLやDBに直接アクセスしメンテする。

Sheet 項目説明(共通・TOP画面)
A1: =表紙!A54 -> Webシステム | K1: 文書名 | U1: モジュールID | Z1: =表紙!$AJ$63 -> MS | AE1: モジュール名 | AJ1: =表紙!$AX$63 -> Webシステム | AS1: 文書番号 | AZ1: Version | BF1: Rev.
K2: =表紙!O64 -> アドオン設計書 | U2: ｻﾌﾞﾓｼﾞｭｰﾙID | Z2: =表紙!$AJ$64 -> MSBB | AE2: ｻﾌﾞﾓｼﾞｭｰﾙ名 | AJ2: =表紙!$AX$64 -> Webシステム | AS2: =表紙!$BL$64 -> M7-US-1140 | AZ2: =表紙!$BU$64 -> 1.0.0 | BF2: =表紙!$CB$64 -> 2
K3: =RIGHT(CELL("filename",$A$1),LEN(CELL("filename",$A$1))-FIND("]",CELL("filename",$A$1))) -> 項目説明(共通・TOP画面) | U3: 表題 | Z3: =表紙!$AJ$65 -> MSBBPA000 | AE3: =表紙!$AQ$65 -> Webシステム(共通概要)
A5: 共通画面
B6: メニュー | N6: 説明 | BE6: リ | BF6: 型 | BG6: 参 | BH6: コ | BI6: 入 | BJ6: 非 | BK6: Ｏ
B7: 大分類 | M7: メニューコントロール：大分類選択により、分類された機能一覧を表示する | BF7: B
B8: 機能 | M8: 機能選択により、機能一覧に遷移する | BF8: B
B9: 拠点名 | M9: 拠点名を表示する | BF9: S
B10: 担当者名 | M10: 担当者名を表示する | BF10: S
B11: タイトル | M11: 機能ID + 機能名を表示する | BF11: S
A14: TOP画面
B15: お知らせ一覧 | N15: 説明 | BE15: リ | BF15: 型 | BG15: 参 | BH15: コ | BI15: 入 | BJ15: 非 | BK15: Ｏ
B16: お知らせ | M16: タイトル：「お知らせ」を表示する | BF16: S
B17: No | M17: 行番を表示する | BF17: S
B18: 表示日付 | M18: 表示日付を表示する | BF18: S
B19: タイトル(URL) | M19: タイトルを表示する、URL情報付きの場合は、リンク可能とする | BF19: S

Sheet 処理詳細(共通・TOP画面)
A1: =表紙!A54 -> Webシステム | K1: 文書名 | U1: モジュールID | Z1: =表紙!$AJ$63 -> MS | AE1: モジュール名 | AJ1: =表紙!$AX$63 -> Webシステム | AS1: 文書番号 | AZ1: Version | BF1: Rev.
K2: =表紙!O64 -> アドオン設計書 | U2: ｻﾌﾞﾓｼﾞｭｰﾙID | Z2: =表紙!$AJ$64 -> MSBB | AE2: ｻﾌﾞﾓｼﾞｭｰﾙ名 | AJ2: =表紙!$AX$64 -> Webシステム | AS2: =表紙!$BL$64 -> M7-US-1140 | AZ2: =表紙!$BU$64 -> 1.0.0 | BF2: =表紙!$CB$64 -> 2
K3: =RIGHT(CELL("filename",$A$1),LEN(CELL("filename",$A$1))-FIND("]",CELL("filename",$A$1))) -> 処理詳細(共通・TOP画面) | U3: 表題 | Z3: =表紙!$AJ$65 -> MSBBPA000 | AE3: =表紙!$AQ$65 -> Webシステム(共通概要)
A5: ログイン/ログアウト/共通画面
A6: No | B6: 入力 | J6: 処理 | BD6: 出力
A7: 1 | B7: ログイン
K9: ログイン(外部呼出し時、含む)
K10: ≫ログイン時、ログイン情報を取得し、セッション変数に保持する。
K12: ログデータの出力
K13: ≫各機能の初期起動時にログインログを出力する。
A15: 2 | B15: メニューセット
K17: メニューDBより、メニューを設定する
L18: メニュー：大分類、機能名
K19: ※メニュー情報取得時にメニュー非表示DB.担当者CD OR 部門に設定された情報を除外して取得する
K20: ログイン担当者 = メニュー非表示DB.担当者CDとする
A22: 3 | B22: TOP画面データセット
K24: お知らせDBより、お知らせ一覧にデータをセットする
L25: No | R25: ・・・ | T25: 行番
L26: 表示日付 | R26: ・・・ | T26: お知らせDB.表示日
L27: タイトル(URL) | R27: ・・・ | T27: お知らせDB.タイトル
T28: ※URL設定時は、タイトルをリンク表示する
L29: 抽出条件：本日日付(処理日) >= お知らせDB.公開日
A31: 4 | B31: ログアウト
K33: システムをログアウト処理する。(セッション変数の破棄)
K35: ログデータの出力
K36: ≫各機能の初期起動時にログアウトログを出力する。

Sheet お知らせ
A1: =表紙!A54 -> Webシステム | K1: 文書名 | U1: モジュールID | Z1: =表紙!$AJ$63 -> MS | AE1: モジュール名 | AJ1: =表紙!$AX$63 -> Webシステム | AS1: 文書番号 | AZ1: Version | BF1: Rev.
K2: =表紙!O64 -> アドオン設計書 | U2: ｻﾌﾞﾓｼﾞｭｰﾙID | Z2: =表紙!$AJ$64 -> MSBB | AE2: ｻﾌﾞﾓｼﾞｭｰﾙ名 | AJ2: =表紙!$AX$64 -> Webシステム | AS2: =表紙!$BL$64 -> M7-US-1140 | AZ2: =表紙!$BU$64 -> 1.0.0 | BF2: =表紙!$CB$64 -> 2
K3: =RIGHT(CELL("filename",$A$1),LEN(CELL("filename",$A$1))-FIND("]",CELL("filename",$A$1))) -> お知らせ | U3: 表題 | Z3: =表紙!$AJ$65 -> MSBBPA000 | AE3: =表紙!$AQ$65 -> Webシステム(共通概要)
A5: テーブル名 | O5: 日本語名 | AE5: 種別
O6: お知らせ | AE6: アドオン(新規)
A8: 主キー | D8: 項目名 | O8: 日本語名 | AE8: 型 | AG8: 桁 | AI8: Null | AK8: 説明 | BL8: 値の制限 | BM8: 設定仕様 | BN8: 未設定時の振る舞い
A9: 〇 | O9: お知らせSEQ | AE9: N | AG9: 10,0 | AI9: N | AK9: 自動採番
O10: 表示日 | AE10: D
O11: 停止日 | AE11: D
O12: タイトル | AE12: C
O13: URL | AE13: C
D14: MEMO1 | O14: メモ１ | AE14: C | AG14: 100 | AI14: Y
D15: MEMO2 | O15: メモ２ | AE15: C | AG15: 100 | AI15: Y
D16: MEMO3 | O16: メモ３ | AE16: C | AG16: 100 | AI16: Y
D17: DEL_FLG | O17: 論理削除ＦＬＧ | AE17: F | AI17: N | AK17: 論理削除を示すフラグ
D18: DEL_USR_ID | O18: 論理削除ユーザＩＤ | AE18: C | AG18: 500 | AI18: Y
D19: DEL_USR_NM | O19: 論理削除ユーザ名 | AE19: C | AG19: 100 | AI19: Y
D20: DEL_TS | O20: 論理削除日時 | AE20: TS | AG20: 0 | AI20: Y
D21: INS_USR_ID | O21: 登録ユーザＩＤ | AE21: C | AG21: 500 | AI21: Y
D22: INS_USR_NM | O22: 登録ユーザ名 | AE22: C | AG22: 100 | AI22: Y
D23: INS_TS | O23: 登録日時 | AE23: TS | AG23: 0 | AI23: Y
D24: INS_FUNC_ID | O24: 登録機能ＩＤ | AE24: C | AG24: 50 | AI24: Y
D25: UPD_CNTR | O25: 更新カウンタ | AE25: N | AG25: 9,0 | AI25: Y
D26: UPD_USR_ID | O26: 更新ユーザＩＤ | AE26: C | AG26: 500 | AI26: Y
D27: UPD_USR_NM | O27: 更新ユーザ名 | AE27: C | AG27: 100 | AI27: Y
D28: UPD_TS | O28: 更新日時 | AE28: TS | AG28: 0 | AI28: Y
D29: UPD_FUNC_ID | O29: 更新機能ＩＤ | AE29: C | AG29: 50 | AI29: Y
D30: UPD_SRV_REQ_NO | O30: 更新リクエストＮＯ | AE30: C | AG30: 50 | AI30: Y

Sheet 汎用検索(共通検索)
A1: =表紙!A54 -> Webシステム | K1: 文書名 | U1: モジュールID | Z1: =表紙!$AJ$63 -> MS | AE1: モジュール名 | AJ1: =表紙!$AX$63 -> Webシステム | AS1: 文書番号 | AZ1: Version | BF1: Rev.
K2: =表紙!O64 -> アドオン設計書 | U2: ｻﾌﾞﾓｼﾞｭｰﾙID | Z2: =表紙!$AJ$64 -> MSBB | AE2: ｻﾌﾞﾓｼﾞｭｰﾙ名 | AJ2: =表紙!$AX$64 -> Webシステム | AS2: =表紙!$BL$64 -> M7-US-1140 | AZ2: =表紙!$BU$64 -> 1.0.0 | BF2: =表紙!$CB$64 -> 2
K3: =RIGHT(CELL("filename",$A$1),LEN(CELL("filename",$A$1))-FIND("]",CELL("filename",$A$1))) -> 汎用検索(共通検索) | U3: 表題 | Z3: =表紙!$AJ$65 -> MSBBPA000 | AE3: =表紙!$AQ$65 -> Webシステム(共通概要)
A5: 画面イメージ
C7: 【機能概要】
D8: 1. | E8: Web汎用検索(共通検索)画面
E9: 検索画面の項目・結果の戻り値を関数化し、共通化する
E10: ※個別の検索画面を用意しない項目用の検索画面
E11: 個別の検索画面：製品マスタ一覧照会・見積一覧照会
C13: 【レイアウト】
C15: ○○検索
D17: 抽出条件列1 | P17: * | AQ17: * | AR17: あいまい検索可能
D18: 抽出条件列2 | P18: *
D22: № | F22: コード | K22: 名称
D23: 1 | F23: 12345678-01 | K23: XXXXXXXXX1XXXXX6
D24: 2 | F24: 12345678-02 | K24: XXXXXXXXX1XXXXX6
D25: 3 | F25: 12345678-03 | K25: XXXXXXXXX1XXXXX6
D26: 4 | F26: 12345678-04 | K26: XXXXXXXXX1XXXXX6
D27: 5 | F27: 12345678-05 | K27: XXXXXXXXX1XXXXX6
D28: 6 | F28: 12345680-01 | K28: YYYYYYYYY1XXXXX6
D29: 7 | F29: 12345681-01 | K29: YYYYYYYYY1XXXXX6
D30: 8 | F30: 12345682-01 | K30: YYYYYYYYY1XXXXX6
D31: 9 | F31: 12345683-01 | K31: YYYYYYYYY1XXXXX6
D32: 10 | F32: 12345683-02 | K32: YYYYYYYYY1XXXXX6
C39: 【前提条件】
D40: 1. | E40: 抽出条件は、最大2つとし、あいまい検索とする。
C42: 【対象検索画面】
D43: 項目 | K43: 呼出元画面 | Z43: 参照テーブル | AJ43: あいまい検索1 | AQ43: あいまい検索2 | AX43: 備考
E44: 簡易検索項目 | K44: 1 | L44: 2 | M44: 3 | N44: 4 | O44: 5 | P44: 6 | Q44: 7 | R44: 8 | S44: 9 | T44: 10 | U44: 11 | V44: 12 | W44: 13 | X44: 14 | Y44: 15 | Z44: ()付きは汎用マスタ
K45: Web見積入力（見積計算処理） | L45: Web見積計算書一覧照会 | M45: Web御見積書登録・発行 | N45: Web御見積書一覧照会 | O45: Web製品マスタ | P45: Web製品マスタ一覧照会 | Q45: Web受注入力 | R45: Web受注一覧照会 | S45: Web受注一覧登録(単価訂正) | T45: WebFSC製品化チェックシート出力 | U45: Web取引先マスタ | V45: Web取引先一覧照会 | W45: Webシート単価マスタ | X45: Web版型・木型マスタ | Y45: Web版型・木型マスタ一覧照会
D46: 案件No | K46: ● | L46: ● | M46: ● | N46: ● | O46: ● | P46: ● | Q46: ● | R46: ● | T46: ● | Z46: ヒアリングシート | AJ46: 案件No | AQ46: 案件名
D47: 原紙コード(表) | K47: ● | L47: ● | O47: ● | P47: ● | Q47: ● | R47: ● | Z47: 原紙マスタ品目マスタ | AJ47: 原紙コード(表) | AQ47: 原紙名(品目) | AX47: 原紙コード取得 品目区分:6 原料の品目CD1~5桁 グルーピング 原紙名称 取得した原紙コードに11桁右0埋めして品目CDとし 品名を1行取得する。 | BM47: REV2.0 原紙コード、原紙名の参照方法変更
D48: 印刷コード(表) | K48: ● | L48: ● | O48: ● | P48: ● | Q48: ● | R48: ● | Z48: 印刷CD | AF48: (M014) | AJ48: 印刷コード(表) | AQ48: 印刷名
D49: エンボスコード(表) | K49: ● | L49: ● | O49: ● | P49: ● | Q49: ● | R49: ● | Z49: エンボスCD | AF49: (M016) | AJ49: エンボスコード(表) | AQ49: エンボス名
D50: メーカ(表) | K50: ● | O50: ● | Q50: ● | Z50: 取引先マスタ | AJ50: メーカコード(表) | AQ50: メーカ名(取引先名)
D51: 原紙コード(中) | K51: ● | L51: ● | O51: ● | P51: ● | Q51: ● | R51: ● | Z51: 原紙マスタ品目マスタ | AJ51: 原紙コード(中) | AQ51: 原紙名(品目) | AX51: 原紙コード取得 品目区分:6 原料の品目CD1~5桁 グルーピング 原紙名称 取得した原紙コードに11桁右0埋めして品目CDとし 品名を1行取得する。 | BM51: REV2.0 原紙コード、原紙名の参照方法変更
D52: 印刷コード(中) | K52: ● | L52: ● | O52: ● | P52: ● | Q52: ● | R52: ● | Z52: 印刷CD | AF52: (M014) | AJ52: 印刷コード(中) | AQ52: 印刷名
D53: エンボスコード(中) | K53: ● | L53: ● | O53: ● | P53: ● | Q53: ● | R53: ● | Z53: エンボスCD | AF53: (M016) | AJ53: エンボスコード(中) | AQ53: エンボス名
D54: メーカ(中) | K54: ● | O54: ● | Q54: ● | Z54: 取引先マスタ | AJ54: メーカコード(中) | AQ54: メーカ名(取引先名)
D55: 原紙コード(裏) | K55: ● | L55: ● | O55: ● | P55: ● | Q55: ● | R55: ● | Z55: 原紙マスタ品目マスタ | AJ55: 原紙コード(裏) | AQ55: 原紙名(品目) | AX55: 原紙コード取得 品目区分:6 原料の品目CD1~5桁 グルーピング 原紙名称 取得した原紙コードに11桁右0埋めして品目CDとし 品名を1行取得する。 | BM55: REV2.0 原紙コード、原紙名の参照方法変更
...

Sheet 項目説明(共通検索)
A1: =表紙!A54 -> Webシステム | K1: 文書名 | U1: モジュールID | Z1: =表紙!$AJ$63 -> MS | AE1: モジュール名 | AJ1: =表紙!$AX$63 -> Webシステム | AS1: 文書番号 | AZ1: Version | BF1: Rev.
K2: =表紙!O64 -> アドオン設計書 | U2: ｻﾌﾞﾓｼﾞｭｰﾙID | Z2: =表紙!$AJ$64 -> MSBB | AE2: ｻﾌﾞﾓｼﾞｭｰﾙ名 | AJ2: =表紙!$AX$64 -> Webシステム | AS2: =表紙!$BL$64 -> M7-US-1140 | AZ2: =表紙!$BU$64 -> 1.0.0 | BF2: =表紙!$CB$64 -> 2
K3: =RIGHT(CELL("filename",$A$1),LEN(CELL("filename",$A$1))-FIND("]",CELL("filename",$A$1))) -> 項目説明(共通検索) | U3: 表題 | Z3: =表紙!$AJ$65 -> MSBBPA000 | AE3: =表紙!$AQ$65 -> Webシステム(共通概要)
A5: 汎用検索(共通検索)
B6: ヘッダー | N6: 説明 | BE6: リ | BF6: 型 | BG6: 参 | BH6: コ | BI6: 入 | BJ6: 非 | BK6: Ｏ
A7: ● | B7: 抽出条件列1 | M7: 抽出条件に使用する。あいまい検索とする | BF7: S
A8: ● | B8: 抽出条件列2 | M8: 抽出条件に使用する。あいまい検索とする | BF8: S
B10: 一覧 | N10: 説明 | BE10: リ | BF10: 型 | BG10: 参 | BH10: コ | BI10: 入 | BJ10: 非 | BK10: Ｏ
B11: № | M11: 行番 | BF11: S
B12: コード | BF12: S
B13: 名称 | BF13: S
B14: … | BF14: S
M15: 一覧クリック処理にて「フッター：選択」処理を行う | BF15: S
B17: フッター | N17: 説明 | BE17: リ | BF17: 型 | BG17: 参 | BH17: コ | BI17: 入 | BJ17: 非 | BK17: Ｏ
B18: 戻る | M18: 呼出元に戻る(処理無くポップアップ画面を閉じる) | BF18: B
B19: CSV出力 | BF19: B
B20: 選択 | M20: 呼出元に結果を返す(ポップアップ画面を閉じる) | BF20: B
BF21: B

Sheet 処理詳細(共通検索)
A1: =表紙!A54 -> Webシステム | K1: 文書名 | U1: モジュールID | Z1: =表紙!$AJ$63 -> MS | AE1: モジュール名 | AJ1: =表紙!$AX$63 -> Webシステム | AS1: 文書番号 | AZ1: Version | BF1: Rev.
K2: =表紙!O64 -> アドオン設計書 | U2: ｻﾌﾞﾓｼﾞｭｰﾙID | Z2: =表紙!$AJ$64 -> MSBB | AE2: ｻﾌﾞﾓｼﾞｭｰﾙ名 | AJ2: =表紙!$AX$64 -> Webシステム | AS2: =表紙!$BL$64 -> M7-US-1140 | AZ2: =表紙!$BU$64 -> 1.0.0 | BF2: =表紙!$CB$64 -> 2
K3: =RIGHT(CELL("filename",$A$1),LEN(CELL("filename",$A$1))-FIND("]",CELL("filename",$A$1))) -> 処理詳細(共通検索) | U3: 表題 | Z3: =表紙!$AJ$65 -> MSBBPA000 | AE3: =表紙!$AQ$65 -> Webシステム(共通概要)
A5: 汎用検索：汎用検索は、共通化する
A6: No | B6: 入力 | J6: 処理 | BD6: 出力
A7: 1 | B7: 呼出元
K9: 各項目の検索ボタンを押下すると、ポップアップ画面(汎用検索)を呼び出す
K10: 印刷 | Y10: エンボス
B13: IN | K13: ※ | L13: 専用の検索画面がある場合は、専用の検索画面とする
C14: タイトル
C15: 抽出条件列1
C16: 抽出条件列2
C17: 抽出SQL
A19: 2 | B19: 汎用検索
K21: 初期表示
L22: 引数のタイトルをタイトル項目にセットする
L23: 一覧に抽出SQLより取得したデータをセットする
K25: 抽出条件列1・2値変更時
L26: 抽出SQLに抽出条件列1・2の入力値(あいまい検索)を追加してデータを再取得し、データをセットする
L27: 抽出条件列1・2の入力時：抽出条件列1(あいまい検索) AND 抽出条件列2(あいまい検索) の条件でデータ抽出する
K29: データ選択時
L30: 選択行のデータを呼出元に返す
A32: 3 | B32: 呼出元
K34: 汎用検索画面で取得したデータをセットする | BD34: OUT
K35: 印刷 | Y35: エンボス | BE35: 選択行
K36: 9999 | P36: XXXXXXXXX1 | BF36: コード
BF37: 名称

Sheet 処理詳細(各機能共通処理)
A1: =表紙!A54 -> Webシステム | K1: 文書名 | U1: モジュールID | Z1: =表紙!$AJ$63 -> MS | AE1: モジュール名 | AJ1: =表紙!$AX$63 -> Webシステム | AS1: 文書番号 | AZ1: Version | BF1: Rev.
K2: =表紙!O64 -> アドオン設計書 | U2: ｻﾌﾞﾓｼﾞｭｰﾙID | Z2: =表紙!$AJ$64 -> MSBB | AE2: ｻﾌﾞﾓｼﾞｭｰﾙ名 | AJ2: =表紙!$AX$64 -> Webシステム | AS2: =表紙!$BL$64 -> M7-US-1140 | AZ2: =表紙!$BU$64 -> 1.0.0 | BF2: =表紙!$CB$64 -> 2
K3: =RIGHT(CELL("filename",$A$1),LEN(CELL("filename",$A$1))-FIND("]",CELL("filename",$A$1))) -> 処理詳細(各機能共通処理) | U3: 表題 | Z3: =表紙!$AJ$65 -> MSBBPA000 | AE3: =表紙!$AQ$65 -> Webシステム(共通概要)
A5: 各機能共通処理
A6: No | B6: 入力 | J6: 処理 | BD6: 出力
A7: 1 | B7: 初期表示
K9: ログデータの出力
K10: ≫各機能の初期起動時に開始ログを出力する。 | BD10: 更新入出力仕様.NO1
K12: データセット
L13: ① | M13: 拠点コンボボックスに拠点マスタデータをセットする。
L14: ※ | M14: ログインマスタ.管理者区分が管理者でない場合、拠点コンボボックスは使用不可とする。
L15: ② | M15: 担当者コンボボックスにログインマスタデータをセットする。(拠点コード=ログインマスタ.拠点)
K17: 初期値セット
L18: ① | M18: 拠点コンボボックスからログインマスタ.拠点を選択する。
L19: ② | M19: 担当者コンボボックスからログインマスタ.ログインIDを選択する。
A22: 2 | B22: 画面操作
K24: ログデータの出力
K25: ≫特定の画面操作が行われた時、ログデータを操作ログテーブルに出力する。 | BD25: 更新入出力仕様.NO3
BD26: 更新入出力仕様.NO4
K27: 拠点コンボボックスの選択変更時
L28: ① | M28: 担当者コンボボックスにログインマスタデータをセットする。(拠点コード=選択された拠点コード)
K30: エラー時のログ出力 | BD30: 更新入出力仕様.NO5
K31: 例外エラー時のログ出力 | BD31: 更新入出力仕様.NO6
A34: 3 | B34: 画面終了/画面移動時
K36: ログデータの出力
K37: ≫各機能の初期起動時に終了ログを出力する。 | BD37: 更新入出力仕様.NO2

Sheet 更新入出力仕様(システムログ)
A1: =表紙!A54 -> Webシステム | K1: 文書名 | U1: モジュールID | Z1: =表紙!$AJ$63 -> MS | AE1: モジュール名 | AJ1: =表紙!$AX$63 -> Webシステム | AS1: 文書番号 | AZ1: Version | BF1: Rev.
K2: =表紙!O64 -> アドオン設計書 | U2: ｻﾌﾞﾓｼﾞｭｰﾙID | Z2: =表紙!$AJ$64 -> MSBB | AE2: ｻﾌﾞﾓｼﾞｭｰﾙ名 | AJ2: =表紙!$AX$64 -> Webシステム | AS2: =表紙!$BL$64 -> M7-US-1140 | AZ2: =表紙!$BU$64 -> 1.0.0 | BF2: =表紙!$CB$64 -> 2
K3: =RIGHT(CELL("filename",$A$1),LEN(CELL("filename",$A$1))-FIND("]",CELL("filename",$A$1))) -> 更新入出力仕様(システムログ) | U3: 表題 | Z3: =表紙!$AJ$65 -> MSBBPA000 | AE3: =表紙!$AQ$65 -> Webシステム(共通概要)
A5: ログテーブルへの書き込み(INSERTのみ)
A6: No | G6: 1 | S6: ロジック名称 | Z6: ログイン | AH6: 備考
A7: 処理分類 | E7: 追加
A8: No | C8: 転送先 | V8: 転送元 | AQ8: 説明
C9: 種 | D9: オブジェクト | K9: 項目名 | V9: 種 | W9: オブジェクト | AF9: 項目名
A10: 1 | C10: T | D10: システムログ | K10: システムログSEQ | AQ10: 指定しない(自動採番)
A11: 2 | C11: T | D11: システムログ | K11: 処理日付 | AF11: SYSDATE | AQ11: DBサーバの現在時刻セット
A12: 3 | C12: T | D12: システムログ | K12: ログインＩＤ | W12: セッション | AF12: ログインＩＤ
A13: 4 | C13: T | D13: システムログ | K13: 拠点ＣＤ | W13: セッション | AF13: 拠点ＣＤ
A14: 5 | C14: T | D14: システムログ | K14: 担当者ＣＤ | W14: セッション | AF14: 担当者ＣＤ
A15: 6 | C15: T | D15: システムログ | K15: ログ区分 | AF15: 1
A16: 7 | C16: T | D16: システムログ | K16: 処理件名 | AF16: ログイン処理
A17: 8 | C17: T | D17: システムログ | K17: 処理内容
A18: 9 | C18: T | D18: システムログ | K18: 処理結果
A19: 10 | C19: T | D19: システムログ | K19: 例外メッセージ
A20: 11 | C20: T | D20: システムログ | K20: 例外詳細情報
A21: 12 | C21: T | D21: システムログ | K21: 実行SQL
A22: 13
A23: 14
A24: 15
A26: No | G26: 2 | S26: ロジック名称 | Z26: ログアウト | AH26: 備考
A27: 処理分類 | E27: 追加
A28: No | C28: 転送先 | V28: 転送元 | AQ28: 説明
C29: 種 | D29: オブジェクト | K29: 項目名 | V29: 種 | W29: オブジェクト | AF29: 項目名
A30: 1 | C30: T | D30: システムログ | K30: システムログSEQ | AQ30: 指定しない(自動採番)
A31: 2 | C31: T | D31: システムログ | K31: 処理日付 | AF31: SYSDATE | AQ31: DBサーバの現在時刻セット
A32: 3 | C32: T | D32: システムログ | K32: ログインＩＤ | W32: セッション | AF32: ログインＩＤ
A33: 4 | C33: T | D33: システムログ | K33: 拠点ＣＤ | W33: セッション | AF33: 拠点ＣＤ
A34: 5 | C34: T | D34: システムログ | K34: 担当者ＣＤ | W34: セッション | AF34: 担当者ＣＤ
A35: 6 | C35: T | D35: システムログ | K35: ログ区分 | AF35: 1
A36: 7 | C36: T | D36: システムログ | K36: 処理件名 | AF36: ログアウト処理
A37: 8 | C37: T | D37: システムログ | K37: 処理内容
A38: 9 | C38: T | D38: システムログ | K38: 処理結果
A39: 10 | C39: T | D39: システムログ | K39: 例外メッセージ
A40: 11 | C40: T | D40: システムログ | K40: 例外詳細情報
A41: 12 | C41: T | D41: システムログ | K41: 実行SQL
A42: 13
...

Sheet システムログ
A1: =表紙!A54 -> Webシステム | K1: 文書名 | U1: モジュールID | Z1: =表紙!$AJ$63 -> MS | AE1: モジュール名 | AJ1: =表紙!$AX$63 -> Webシステム | AS1: 文書番号 | AZ1: Version | BF1: Rev.
K2: =表紙!O64 -> アドオン設計書 | U2: ｻﾌﾞﾓｼﾞｭｰﾙID | Z2: =表紙!$AJ$64 -> MSBB | AE2: ｻﾌﾞﾓｼﾞｭｰﾙ名 | AJ2: =表紙!$AX$64 -> Webシステム | AS2: =表紙!$BL$64 -> M7-US-1140 | AZ2: =表紙!$BU$64 -> 1.0.0 | BF2: =表紙!$CB$64 -> 2
K3: =RIGHT(CELL("filename",$A$1),LEN(CELL("filename",$A$1))-FIND("]",CELL("filename",$A$1))) -> システムログ | U3: 表題 | Z3: =表紙!$AJ$65 -> MSBBPA000 | AE3: =表紙!$AQ$65 -> Webシステム(共通概要)
A5: テーブル名 | O5: 日本語名 | AE5: 種別
O6: システムログ | AE6: アドオン(新規)
A8: 主キー | D8: 項目名 | O8: 日本語名 | AE8: 型 | AG8: 桁 | AI8: Null | AK8: 説明 | BL8: 値の制限 | BM8: 設定仕様 | BN8: 未設定時の振る舞い
A9: 〇 | O9: システムログSEQ | AE9: N | AG9: 10,0 | AI9: N | AK9: 自動採番
O10: 処理日付 | AE10: D | AI10: Y | AK10: ログ登録日時
O11: ログインＩＤ | AE11: C | AI11: Y | AK11: ログイン情報よりセット
O12: 拠点ＣＤ | AE12: C | AI12: Y | AK12: ログイン情報よりセット
O13: 担当者ＣＤ | AE13: C | AI13: Y | AK13: ログイン情報よりセット
O14: ログ区分 | AE14: N | AI14: Y | AK14: 1:ログイン, 2:ログアウト, 3:処理開始, 5:処理終了, 7:エラー, 9:例外
O15: 処理件名 | AE15: C | AI15: Y | AK15: 例) 見積計算書の登録処理
O16: 処理内容 | AE16: C | AI16: Y | AK16: 例) 見積計算書の登録処理を開始しました
O17: 処理結果 | AE17: C | AI17: Y | AK17: 例) 正常登録 (3件)
O18: 例外メッセージ | AE18: C | AI18: Y | AK18: Exception.Message
O19: 例外詳細情報 | AE19: CLOB | AI19: Y | AK19: Exception.Tostring
O20: 実行SQL | AE20: C | AG20: 1000 | AI20: Y
D21: MEMO1 | O21: メモ１ | AE21: C | AG21: 100 | AI21: Y
D22: MEMO2 | O22: メモ２ | AE22: C | AG22: 100 | AI22: Y
D23: MEMO3 | O23: メモ３ | AE23: C | AG23: 100 | AI23: Y
D24: DEL_FLG | O24: 論理削除ＦＬＧ | AE24: F | AI24: N | AK24: 論理削除を示すフラグ
D25: DEL_USR_ID | O25: 論理削除ユーザＩＤ | AE25: C | AG25: 500 | AI25: Y
D26: DEL_USR_NM | O26: 論理削除ユーザ名 | AE26: C | AG26: 100 | AI26: Y
D27: DEL_TS | O27: 論理削除日時 | AE27: TS | AG27: 0 | AI27: Y
D28: INS_USR_ID | O28: 登録ユーザＩＤ | AE28: C | AG28: 500 | AI28: Y
D29: INS_USR_NM | O29: 登録ユーザ名 | AE29: C | AG29: 100 | AI29: Y
D30: INS_TS | O30: 登録日時 | AE30: TS | AG30: 0 | AI30: Y
D31: INS_FUNC_ID | O31: 登録機能ＩＤ | AE31: C | AG31: 50 | AI31: Y
D32: UPD_CNTR | O32: 更新カウンタ | AE32: N | AG32: 9,0 | AI32: Y
D33: UPD_USR_ID | O33: 更新ユーザＩＤ | AE33: C | AG33: 500 | AI33: Y
D34: UPD_USR_NM | O34: 更新ユーザ名 | AE34: C | AG34: 100 | AI34: Y
D35: UPD_TS | O35: 更新日時 | AE35: TS | AG35: 0 | AI35: Y
D36: UPD_FUNC_ID | O36: 更新機能ＩＤ | AE36: C | AG36: 50 | AI36: Y
D37: UPD_SRV_REQ_NO | O37: 更新リクエストＮＯ | AE37: C | AG37: 50 | AI37: Y

Sheet web.config
A1: =表紙!A54 -> Webシステム | K1: 文書名 | U1: モジュールID | Z1: =表紙!$AJ$63 -> MS | AE1: モジュール名 | AJ1: =表紙!$AX$63 -> Webシステム | AS1: 文書番号 | AZ1: Version | BF1: Rev.
K2: =表紙!O64 -> アドオン設計書 | U2: ｻﾌﾞﾓｼﾞｭｰﾙID | Z2: =表紙!$AJ$64 -> MSBB | AE2: ｻﾌﾞﾓｼﾞｭｰﾙ名 | AJ2: =表紙!$AX$64 -> Webシステム | AS2: =表紙!$BL$64 -> M7-US-1140 | AZ2: =表紙!$BU$64 -> 1.0.0 | BF2: =表紙!$CB$64 -> 2
K3: =RIGHT(CELL("filename",$A$1),LEN(CELL("filename",$A$1))-FIND("]",CELL("filename",$A$1))) -> web.config | U3: 表題 | Z3: =表紙!$AJ$65 -> MSBBPA000 | AE3: =表紙!$AQ$65 -> Webシステム(共通概要)
A5: web.config設定 (appSettings)
A6: key | P6: value | AE6: 項目説明
B7: CsvFileEncoding | Q7: utf-8 | AE7: CSVファイルの文字コード
B9: Details_MaxLimit_MSBBPA020 | Q9: 1,000 | AE9: 最大表示件数：Web見積計算書一覧照会
B10: Details_MaxLimit_MSBBPA040 | Q10: 1,000 | AE10: 最大表示件数：Web御見積書一覧照会
B11: Details_MaxLimit_MSBBPA060 | Q11: 1,000 | AE11: 最大表示件数：Web製品マスタ一覧照会
B12: Details_MaxLimit_MSBBPA080 | Q12: 1,000 | AE12: 最大表示件数：Web受注一覧照会
B13: Details_MaxLimit_MSBBPA120 | Q13: 1,000 | AE13: 最大表示件数：Web取引先一覧照会
B14: Details_MaxLimit_MSBBPA150 | Q14: 1,000 | AE14: 最大表示件数：Web版型・木型マスタ一覧照会
B16: CsvDefaultFileName_MSBBPA020 | Q16: Web見積計算書一覧照会 | AE16: CSV初期名称：Web見積計算書一覧照会
B17: CsvDefaultFileName_MSBBPA040 | Q17: Web御見積書一覧照会 | AE17: CSV初期名称：Web御見積書一覧照会
B18: CsvDefaultFileName_MSBBPA060 | Q18: Web製品マスタ一覧照会 | AE18: CSV初期名称：Web製品マスタ一覧照会
B19: CsvDefaultFileName_MSBBPA080 | Q19: Web受注一覧照会 | AE19: CSV初期名称：Web受注一覧照会
B20: CsvDefaultFileName_MSBBPA120 | Q20: Web取引先一覧照会 | AE20: CSV初期名称：Web取引先一覧照会
... B31: MSBBPA030_Details2_Init_Word03 | Q31: 8,版代 | AE31: 御見積書明細初期セット文字(行数,初期文言)
B32: MSBBPA030_Details2_Init_Word04 | AE32: 御見積書明細初期セット文字(行数,初期文言)
B33: MSBBPA030_Details2_Init_Word05 | AE33: 御見積書明細初期セット文字(行数,初期文言)
B35: MSBBPA030_Init_納入場所 | Q35: 貴社ご指定場所 | AE35: 御見積書登録画面 - 初期表示文字 | AR35: … | AT35: 納入場所
B36: MSBBPA030_Init_納入期限 | Q36: 別途お打合せ | AE36: 御見積書登録画面 - 初期表示文字 | AR36: … | AT36: 納入期限
B37: MSBBPA030_Init_見積有効期限 | Q37: お見積り後3ヶ月 | AE37: 御見積書登録画面 - 初期表示文字 | AR37: … | AT37: 見積有効期限
B38: MSBBPA030_Init_別途運賃 | Q38: 遠距離は別途 | AE38: 御見積書登録画面 - 初期表示文字 | AR38: … | AT38: 別途運賃
B40: ExcelFileName_MSBBPA100 | Q40: FSCチェックシート | AE40: FSCチェックシートのファイル名
B41: MSBBPA100_ExcelFormat01 | Q41: 製品用チェックシート,C:\temp\A.xls | AE41: value(名称,ひな型保存パス(サーバパス))
B42: MSBBPA100_ExcelFormat02 | Q42: ○○用チェックシート,C:\temp\b.xlsx | AE42: value(名称,ひな型保存パス(サーバパス))
B43: MSBBPA100_ExcelFormat03 | AE43: value(名称,ひな型保存パス(サーバパス))
B44: MSBBPA100_ExcelFormat04 | AE44: value(名称,ひな型保存パス(サーバパス))
B45: MSBBPA100_ExcelFormat05 | AE45: value(名称,ひな型保存パス(サーバパス))
B46: MSBBPA100_ExcelFormat06 | AE46: value(名称,ひな型保存パス(サーバパス))
B47: MSBBPA100_ExcelFormat07 | AE47: value(名称,ひな型保存パス(サーバパス))
B48: MSBBPA100_ExcelFormat08 | AE48: value(名称,ひな型保存パス(サーバパス))
B49: MSBBPA100_ExcelFormat09 | AE49: value(名称,ひな型保存パス(サーバパス))
B50: MSBBPA100_ExcelFormat10 | AE50: value(名称,ひな型保存パス(サーバパス))
B52: MSBBPA090_PE_Title | Q52: 単価訂正 | AE52: 単価訂正のWF件名
B54: PE_SERVER | Q54: PEサーバ名
B55: PE_Link_CST_MEMO | Q55: 得意先メモリンク | AE55: http://PESERVER/pe4j/XDB/XDB0103d.jsf?p1=得意先メモテーブル&
B56: PE_Link_DLV_MEMO | Q56: 納入先メモリンク | AE56: http://PESERVER/pe4j/XDB/XDB0103d.jsf?p1=納入先メモメモテーブル&
B57: PE_CST_TABLE_NAME | Q57: 得意先テーブル名称(VIEW)
...

Sheet メニュー
A1: =表紙!A54 -> Webシステム | K1: 文書名 | U1: モジュールID | Z1: =表紙!$AJ$63 -> MS | AE1: モジュール名 | AJ1: =表紙!$AX$63 -> Webシステム | AS1: 文書番号 | AZ1: Version | BF1: Rev.
K2: =表紙!O64 -> アドオン設計書 | U2: ｻﾌﾞﾓｼﾞｭｰﾙID | Z2: =表紙!$AJ$64 -> MSBB | AE2: ｻﾌﾞﾓｼﾞｭｰﾙ名 | AJ2: =表紙!$AX$64 -> Webシステム | AS2: =表紙!$BL$64 -> M7-US-1140 | AZ2: =表紙!$BU$64 -> 1.0.0 | BF2: =表紙!$CB$64 -> 2
K3: =RIGHT(CELL("filename",$A$1),LEN(CELL("filename",$A$1))-FIND("]",CELL("filename",$A$1))) -> メニュー | U3: 表題 | Z3: =表紙!$AJ$65 -> MSBBPA000 | AE3: =表紙!$AQ$65 -> Webシステム(共通概要)
A5: テーブル名 | O5: 日本語名 | AE5: 種別
O6: メニュー | AE6: アドオン(新規)
A8: 主キー | D8: 項目名 | O8: 日本語名 | AE8: 型 | AG8: 桁 | AI8: Null | AK8: 説明 | BL8: 値の制限 | BM8: 設定仕様 | BN8: 未設定時の振る舞い
A9: 〇 | O9: 大分類NO | AE9: N | AG9: 10 | AI9: N
A10: 〇 | O10: 機能NO | AE10: N | AG10: 10 | AI10: N
O11: 大分類名 | AE11: C | AG11: 20 | AI11: Y | AK11: 最初に取得できた大分類名を表示する
O12: 機能名 | AE12: C | AG12: 20 | AI12: Y
O13: URL | AE13: C | AG13: 100 | AI13: Y | AK13: リンク先の各機能もしくはURLを指定する
D14: MEMO1 | O14: メモ１ | AE14: C | AG14: 100 | AI14: Y
D15: MEMO2 | O15: メモ２ | AE15: C | AG15: 100 | AI15: Y
D16: MEMO3 | O16: メモ３ | AE16: C | AG16: 100 | AI16: Y
D17: DEL_FLG | O17: 論理削除ＦＬＧ | AE17: F | AI17: N | AK17: 論理削除を示すフラグ
D18: DEL_USR_ID | O18: 論理削除ユーザＩＤ | AE18: C | AG18: 500 | AI18: Y
D19: DEL_USR_NM | O19: 論理削除ユーザ名 | AE19: C | AG19: 100 | AI19: Y
D20: DEL_TS | O20: 論理削除日時 | AE20: TS | AG20: 0 | AI20: Y
D21: INS_USR_ID | O21: 登録ユーザＩＤ | AE21: C | AG21: 500 | AI21: Y
D22: INS_USR_NM | O22: 登録ユーザ名 | AE22: C | AG22: 100 | AI22: Y
D23: INS_TS | O23: 登録日時 | AE23: TS | AG23: 0 | AI23: Y
D24: INS_FUNC_ID | O24: 登録機能ＩＤ | AE24: C | AG24: 50 | AI24: Y
D25: UPD_CNTR | O25: 更新カウンタ | AE25: N | AG25: 9,0 | AI25: Y
D26: UPD_USR_ID | O26: 更新ユーザＩＤ | AE26: C | AG26: 500 | AI26: Y
D27: UPD_USR_NM | O27: 更新ユーザ名 | AE27: C | AG27: 100 | AI27: Y
D28: UPD_TS | O28: 更新日時 | AE28: TS | AG28: 0 | AI28: Y
D29: UPD_FUNC_ID | O29: 更新機能ＩＤ | AE29: C | AG29: 50 | AI29: Y
D30: UPD_SRV_REQ_NO | O30: 更新リクエストＮＯ | AE30: C | AG30: 50 | AI30: Y

Sheet メニュー非表示
A1: =表紙!A54 -> Webシステム | K1: 文書名 | U1: モジュールID | Z1: =表紙!$AJ$63 -> MS | AE1: モジュール名 | AJ1: =表紙!$AX$63 -> Webシステム | AS1: 文書番号 | AZ1: Version | BF1: Rev.
K2: =表紙!O64 -> アドオン設計書 | U2: ｻﾌﾞﾓｼﾞｭｰﾙID | Z2: =表紙!$AJ$64 -> MSBB | AE2: ｻﾌﾞﾓｼﾞｭｰﾙ名 | AJ2: =表紙!$AX$64 -> Webシステム | AS2: =表紙!$BL$64 -> M7-US-1140 | AZ2: =表紙!$BU$64 -> 1.0.0 | BF2: =表紙!$CB$64 -> 2
K3: =RIGHT(CELL("filename",$A$1),LEN(CELL("filename",$A$1))-FIND("]",CELL("filename",$A$1))) -> メニュー非表示 | U3: 表題 | Z3: =表紙!$AJ$65 -> MSBBPA000 | AE3: =表紙!$AQ$65 -> Webシステム(共通概要)
A5: テーブル名 | O5: 日本語名 | AE5: 種別
O6: メニュー非表示 | AE6: アドオン(新規)
A8: 主キー | D8: 項目名 | O8: 日本語名 | AE8: 型 | AG8: 桁 | AI8: Null | AK8: 説明 | BL8: 値の制限 | BM8: 設定仕様 | BN8: 未設定時の振る舞い
A9: 〇 | O9: 機能NO | AE9: N | AG9: 10 | AI9: N
A10: 〇 | O10: 担当者CD OR 部門単位 | AE10: N | AI10: N
D11: MEMO1 | O11: メモ１ | AE11: C | AG11: 100 | AI11: Y
D12: MEMO2 | O12: メモ２ | AE12: C | AG12: 100 | AI12: Y
D13: MEMO3 | O13: メモ３ | AE13: C | AG13: 100 | AI13: Y
D14: DEL_FLG | O14: 論理削除ＦＬＧ | AE14: F | AI14: N | AK14: 論理削除を示すフラグ
D15: DEL_USR_ID | O15: 論理削除ユーザＩＤ | AE15: C | AG15: 500 | AI15: Y
D16: DEL_USR_NM | O16: 論理削除ユーザ名 | AE16: C | AG16: 100 | AI16: Y
D17: DEL_TS | O17: 論理削除日時 | AE17: TS | AG17: 0 | AI17: Y
D18: INS_USR_ID | O18: 登録ユーザＩＤ | AE18: C | AG18: 500 | AI18: Y
D19: INS_USR_NM | O19: 登録ユーザ名 | AE19: C | AG19: 100 | AI19: Y
D20: INS_TS | O20: 登録日時 | AE20: TS | AG20: 0 | AI20: Y
D21: INS_FUNC_ID | O21: 登録機能ＩＤ | AE21: C | AG21: 50 | AI21: Y
D22: UPD_CNTR | O22: 更新カウンタ | AE22: N | AG22: 9,0 | AI22: Y
D23: UPD_USR_ID | O23: 更新ユーザＩＤ | AE23: C | AG23: 500 | AI23: Y
D24: UPD_USR_NM | O24: 更新ユーザ名 | AE24: C | AG24: 100 | AI24: Y
D25: UPD_TS | O25: 更新日時 | AE25: TS | AG25: 0 | AI25: Y
D26: UPD_FUNC_ID | O26: 更新機能ＩＤ | AE26: C | AG26: 50 | AI26: Y
D27: UPD_SRV_REQ_NO | O27: 更新リクエストＮＯ | AE27: C | AG27: 50 | AI27: Y

Sheet |

Sheet 図・表
B2: 操作種別切替時の画面の振る舞い
C3: 切替先の種別
B4: 切替元の種別 | C4: 登録 | D4: 訂正 | E4: 削除 | F4: 参照
B5: 登録 | C5: ー | D5: 画面クリア | E5: 画面クリア | F5: 画面クリア
B6: 訂正 | C6: 画面クリア | D6: ー | E6: 画面クリア | F6: 画面クリア
B7: 削除 | C7: 画面クリア | D7: 画面クリア | E7: ー | F7: 画面クリア
B8: 参照 | C8: 新規モード （引用登録） | D8: 訂正モード | E8: 削除モード | F8: ー

Sheet オートコンプリート
D2: コード選択時
E3: ・コードの入力で、名称をリストに表示させることが可能。
E5: 原紙 | J5: K | BL5: 原紙コード | BY5: 原紙名称
K7: G0000001 Kライナ | BM7: G0000001 | BY7: Kライナ
K8: G0000002 耐水Kライナ | BM8: G0000002 | BY8: 耐水Kライナ
K9: G0000003 撥水Kライナ | BM9: G0000003 | BY9: 撥水Kライナ
BM10: G0000004 | BY10: 防水ライナ
BM11: G0000005 | BY11: 白ライナ
BM12: G0000006 | BY12: Jライナ
D15: コード選択後
E16: ・コード選択後に、名称を入力欄にセットするこことが可能。
E18: 原紙 | J18: G0000002 | V18: 耐水Kライナ
D20: 懸念点
E21: コード選択では、DBアクセスを伴なうため、リストの表示できるまで時間がかかることが推測される
E22: ⇒エンドユーザが画面の反応が鈍いと感じる場合があります

Sheet ログイン履歴
A1: =表紙!A54 -> Webシステム | K1: 文書名 | U1: モジュールID | Z1: =表紙!$AJ$63 -> MS | AE1: モジュール名 | AJ1: =表紙!$AX$63 -> Webシステム | AS1: 文書番号 | AZ1: Version | BF1: Rev.
K2: =表紙!O64 -> アドオン設計書 | U2: ｻﾌﾞﾓｼﾞｭｰﾙID | Z2: =表紙!$AJ$64 -> MSBB | AE2: ｻﾌﾞﾓｼﾞｭｰﾙ名 | AJ2: =表紙!$AX$64 -> Webシステム | AS2: =表紙!$BL$64 -> M7-US-1140 | AZ2: =表紙!$BU$64 -> 1.0.0 | BF2: =表紙!$CB$64 -> 2
K3: =RIGHT(CELL("filename",$A$1),LEN(CELL("filename",$A$1))-FIND("]",CELL("filename",$A$1))) -> ログイン履歴 | U3: 表題 | Z3: =表紙!$AJ$65 -> MSBBPA000 | AE3: =表紙!$AQ$65 -> Webシステム(共通概要)
A5: テーブル名 | O5: 日本語名 | AE5: 種別 | AK5: 備考
A6: 実テーブル名 + _R | O6: ログイン履歴 | AE6: アドオン(新規)
A8: 主キー | D8: 項目名 | O8: 日本語名 | AE8: 型 | AG8: 桁 | AI8: Null | AK8: 説明 | BL8: 値の制限 | BM8: 設定仕様 | BN8: 未設定時の振る舞い
A9: 〇 | D9: HST_ID | O9: 履歴ID(NO) | AE9: N | AG9: 24 | AI9: N | AK9: シーケンスNO(連番)
D10: HST_TYPE | O10: 履歴種類 | AE10: C | AG10: 2 | AI10: N | AK10: INSERT、UPDATE、DELETEの種類
O11: 社員ID | AE11: N | AG11: 10 | AK11: HT2_EMPLOYEE(PE標準テーブル)
O12: 名前 | AE12: C | AK12: HT2_EMPLOYEE(PE標準テーブル)
O13: ふりがな | AE13: C | AK13: HT2_EMPLOYEE(PE標準テーブル)
O14: ユーザID | AE14: C | AK14: HT2_EMPLOYEE(PE標準テーブル)
O15: パスワード | AK15: WEBDB(付加項目)
O16: 管理者区分 | AE16: F | AI16: N | AK16: WEBDB(付加項目) | AR16: 管理者、一般利用者は判断する区分 | BL16: 0、1 | BM16: 「1=管理者」設定時、拠点コードの変更を可能とする。 | BN16: [0、1]どちらか必須設定
O17: 拠点CD | AE17: N | AI17: N | AK17: WEBDB(付加項目) | BL17: 拠点マスタに登録された値 | BN17: 必須設定
O18: 担当者CD | AE18: C | AG18: 500 | AI18: N | AK18: WEBDB(付加項目) | BL18: 担当者マスタに登録された値 | BN18: 必須設定
O19: 登録日時 | AE19: D
O20: 登録者 | AE20: N | AG20: 10
O21: 最終更新日時 | AE21: D
O22: 最終更新者 | AE22: N | AG22: 10
