Workbook
Name Rev.: [2]表紙!$U$22
Name Rev.: 表紙!$U$22
Name Revision: #REF!
Name Revision: [3]表紙!$AP$5
Name Ver.: #REF!
Name Ver.: 表紙!$AE$26
Name Version: #REF!
Name Version: [3]表紙!$AJ$5
Name ご確認者: #REF!
Name ご確認者: 表紙!$AG$40
Name ご確認日: #REF!
Name ご確認日: 表紙!$AG$42
Name サブシステム名: #REF!
Name サブシステム名: 表紙!$U$28
Name システム名: #REF!
Name システム名: 表紙!$U$26
Name プロジェクト名: #REF!
Name プロジェクト名: 表紙!$U$18
Name 開発区分: #REF!
Name 開発区分: 表紙!$U$36
Name 機能ＩＤ: #REF!
Name 機能ＩＤ: 表紙!$U$32
Name 機能区分: #REF!
Name 機能区分: 表紙!$U$34
Name 機能名称: #REF!
Name 機能名称: 表紙!$U$30
Name 顧客名: #REF!
Name 顧客名: 表紙!$U$16
Name 最終更新者: #REF!
Name 最終更新者: 表紙!$AB$40
Name 最終更新日: #REF!
Name 最終更新日: 表紙!$AB$42
Name 作成者: #REF!
Name 作成者: 表紙!$W$40
Name 作成日: #REF!
Name 作成日: 表紙!$W$42
Name 章: #REF!
Name 章: 表紙!$M$10
Name 発行日: #REF!
Name 発行日: #REF!
Name 文書番号: #REF!
Name 文書番号: [3]表紙!$O$5
Name 文書番号_カスタマイズ: '[3]表紙（カスタマイズ）'!$U$20
Name 文書名: 表紙!$M$10
Name 文書名: #REF!
Name 文書名: [3]表紙!$M$15
Name 文書名_カスタマイズ: '[3]表紙（カスタマイズ）'!$M$10

Sheet 目次
A1: アドオン設計書作成ガイド
C3: ■アドオン設計と成果物について
D4: ・システム設計フェーズとソフトウェア設計フェーズでアドオンの処理仕様を定義する
D5: ・システム設計フェーズとソフトウェア設計フェーズの成果物がアドオン設計書であり、ソフトウェア製作フェーズのインプットとなる
C7: ■各設計フェーズ毎のアドオン設計書作成範囲
D8: ・システム設計フェーズ：他機能との関連を定義するとともに、画面や帳票、ファイル入出力を中心とした外部入出力の設計を行う
D9: ・ソフトウェア設計フェーズ：内部処理を中心とした設計を行う
U11: ◎ | W11: … | X11: システム設計フェーズで作成
U12: ○ | W12: … | X12: システム設計フェーズで基本仕様を定義して、ソフトウェア設計フェーズで詳細化する
U13: △ | W13: … | X13: 必要に応じて（例えば標準仕様から変更がない場合は不要）
U14: ‐ | W14: … | X14: 不要
W15: … | X15: ソフトウェア設計フェーズで作成
D17: 各設計書と作成対象シートのマトリックス | S17: ※カスタマイズ：標準機能に機能を追加する アドオン：新規で機能を開発する
D18: EXCELシート | N18: 画面設計書 | W18: バッチ設計書 | AF18: 帳票設計書 | AO18: ＢＩ設計書 | AT18: .Net設計書 | BB18: EXCELシート | BL18: WebDB設計書 | BR18: 帳票設計書 | BX18: 汎用申請設計書
N19: カスタマイズ | S19: アドオン | W19: カスタマイズ | AB19: アドオン | AF19: カスタマイズ | AK19: アドオン | AO19: アドオン | AT19: アドオン | BL19: アドオン | BR19: アドオン | BX19: アドオン
D20: 概要 | N20: ◎ | O20: ※1 | S20: ◎ | W20: ◎ | X20: ※1 | AB20: ◎ | AF20: ◎ | AG20: ※1 | AK20: ◎ | AO20: ◎ | AT20: ◎ | BB20: 機能概要 | BL20: ◎ | BR20: ◎ | BX20: ◎
D21: レイアウト | N21: ◎ | O21: ※2 | S21: ◎ | W21: ‐ | AB21: ‐ | AF21: ◎ | AG21: ※2 | AK21: ◎ | AO21: ◎ | AT21: ◎ | BB21: アプリケーションフロー | BL21: ◎ | BR21: ー | BX21: ◎
D22: 項目説明 | N22: △ | S22: ○ | W22: ‐ | AB22: ‐ | AF22: △ | AK22: ○ | AO22: ○ | AT22: ○ | BB22: データベース設定 | BL22: ◎ | BR22: ー | BX22: ◎
D23: 引数説明 | N23: ‐ | S23: ‐ | W23: △ | AB23: ◎ | AF23: ‐ | AK23: ‐ | AO23: ‐ | AT23: ◎ | BB23: フィールド設定 | BL23: ◎ | BR23: ー | BX23: ◎
D24: 処理概要 | N24: ◎ | S24: ◎ | W24: ◎ | AB24: ◎ | AF24: ◎ | AK24: ◎ | AO24: ◎ | AT24: ◎ | BB24: 一覧表示画面設定 | BL24: ◎ | BR24: ー | BX24: ◎
D25: 処理詳細 | BB25: 表示編集画面設定 | BL25: ◎ | BR25: ー | BX25: ◎
D26: 処理・サービス関連図 | N26: △ | S26: ◎ | W26: △ | AB26: ◎ | AF26: ‐ | AK26: ‐ | AO26: ‐ | AT26: ◎ | BB26: 明細画面設定 | BL26: △ | BN26: ※3 | BR26: ー | BX26: △ | BZ26: ※3
D27: 検索入出力仕様 | N27: △ | S27: ○ | W27: △ | AB27: ○ | AF27: ‐ | AK27: ‐ | AO27: ‐ | AT27: ○ | BB27: 集計表示設定 | BL27: △ | BN27: ※4 | BR27: ー | BX27: △ | BZ27: ※4
D28: 更新入出力仕様 | N28: △ | S28: ○ | W28: △ | AB28: ○ | AF28: ‐ | AK28: ‐ | AO28: ‐ | AT28: ○ | BB28: 絞り込み条件設定 | BL28: △ | BN28: ※5 | BR28: ー | BX28: △ | BZ28: ※5
D29: ファイル入出力仕様 | N29: △ | S29: △ | W29: ‐ | AB29: ‐ | AF29: ‐ | AK29: ‐ | AO29: ‐ | AT29: △ | BB29: その他設定 | BR29: ー
D30: 画面遷移 | N30: △ | S30: ◎ | W30: ‐ | AB30: ‐ | AF30: ‐ | AK30: ‐ | AO30: ‐ | AT30: ◎ | BB30: 帳票イメージ | BL30: ー | BR30: ◎ | BX30: ー
D31: メッセージ一覧 | N31: △ | S31: △ | W31: △ | AB31: △ | AF31: ‐ | AK31: ‐ | AO31: ‐ | AT31: △ | BB31: 項目設計 | BL31: ー | BR31: ◎ | BX31: ー
D32: 補足説明 | N32: △ | S32: △ | W32: △ | AB32: △ | AF32: △ | AK32: △ | AO32: △ | AT32: △ | BB32: 補足説明 | BL32: △ | BR32: △ | BX32: △
D33: サービス呼出編集仕様 | N33: - | S33: - | W33: - | AB33: - | AF33: - | AK33: - | AO33: - | AT33: - | BB33: 補足説明(詳細)
D35: ※1 | G35: 別シートでカスタマイズ内容を記載する | BB35: ※3 | BE35: 単票画面は記載しない
D36: ※2 | G36: 吹き出しでカスタマイズ内容を記載する | BB36: ※4 | BE36: 集計・グラフ機能を使用する場合に記載する
BB37: ※5 | BE37: 共通設定のみ記載する(個別設定は、記載しない)

Sheet 表紙
AW2: サブモジュール
AW3: MA_マスタ管理
AW4: MB_業務共通
AW5: MG_原価管理
AW6: MSBA_需給管理
M7: 基本設計 | AW7: MSBB_販売管理
AW8: MSBC_生産管理
AW9: MSBD_購買管理
M10: アドオン設計書 | AW10: MSBE_在庫物流管理
AW11: MSBF_品質管理
AW12: MSBG_債権管理
AW13: MSBH_債務管理
AW14: MSBI_締処理
AW15: MSUA_リスト・入力補助
M16: 顧客 | U16: 株式会社クラウン・パッケージ | AW16: PF_ESBアダプタ
M18: プロジェクト名 | U18: 基幹システム刷新PJ | AW18: 機能区分
AW19: 画面
M20: 文書番号 | AW20: 帳票
AW21: バッチ
M22: Ｒｅｖ． | U22: {=MAX(_xlfn.NUMBERVALUE(改訂!A7:E42))} -> 8 | AW22: マスタ
M24: 機密性区分 | U24: 取扱注意（Ｃ） | AW24: 開発区分
AW25: カスタマイズ
M26: システム名 | U26: mcframe7 | AC26: Ver. | AE26: 7.0.2 | AW26: アドオン
AW27: －
M28: サブモジュール | U28: MSBB_販売管理
M30: 機能名 | U30: =M50 -> 製品マスタ連携
M32: 機能ID | U32: =G50 -> MSBBA010
M34: 機能区分 | U34: バッチ
M36: 開発区分 | U36: アドオン
W39: 作成 | AB39: 最終更新 | AG39: ご確認
W40: MDSOL | AB40: =改訂!AZ2 -> MDSOL石田
W42: 44637 | AB42: =改訂!BJ2 -> 45016
A48: 文書番号 | G48: 画面ID | M48: 画面名 | V48: Version | AB48: Revision
A50: M7-US-1140 | G50: MSBBA010 | M50: 製品マスタ連携 | V50: 1.0.0 | AB50: 3
A53: 共通（元データ）
A54: Webシステム | K54: 文書名 | U54: モジュールID | Z54: MS | AE54: モジュール名 | AJ54: 見積管理 | AS54: 文書番号 | AZ54: Version | BF54: Rev.
K55: 画面説明書 | U55: ｻﾌﾞﾓｼﾞｭｰﾙID | Z55: MSBB | AE55: ｻﾌﾞﾓｼﾞｭｰﾙ名 | AJ55: Webシステム | AS55: M7-US-1140 | AZ55: 1.0.0 | BF55: 3
K56: 表紙 | U56: 表題 | Z56: - | AE56: 製品マスタ連携
A57: 共通（リンク用）
A58: =A54 -> Webシステム | K58: 文書名 | U58: モジュールID | Z58: =Z54 -> MS | AE58: モジュール名 | AJ58: =AJ54 -> 見積管理 | AS58: 文書番号 | AZ58: Version | BF58: Rev.
...

Sheet 改訂
A1: 第7章 | K1: 改訂 | AU1: 作成者 | AZ1: MDSOL | BE1: 作成日 | BJ1: =表紙!W42 -> 44637 | BP1: Rev.
AU2: 修正者 | AZ2: =BM20 -> MDSOL石田 | BE2: 改訂日 | BJ2: =MAX(改訂!BM7:BQ58) -> 45016 | BP2: =表紙!CB64 -> 8
A5: Rev. | F5: 改定内容 | BC5: 頁 | BM5: 変更日 変更者 | BR5: 確認日 確認者
A7: 1 | F7: 新規作成 | BM7: 44865
BM8: MDSOL
A9: 2.0 | F9: 仕様連絡書：RCS-1040 品目の採番体系を変更 | BC9: 更新入出力仕様_品目マスタ 補足説明資料_mcframeとのキー比較 更新入出力仕様_（アドオン）事業所別原紙巾マスタ 更新入出力仕様_（アドオン）原紙マスタ | BM9: 44889 | BR9: 44889
BM10: MDSOL | BR10: MDSOL
A11: 2 | F11: 仕様連絡書：RCS-1062に伴う下記改定を実施 案件NOをDBの項目は、案件NO(親)＋案件NO(子)＋案件NO(部材)に分割する ※画面項目は、1つとする | BC11: 検索入出力仕様、更新入出力仕様_品目マスタ | BM11: 44894 | BR11: 44895
BM12: MDSOL | BR12: MDSOL 奥本
A13: 2 | F13: 仕様連絡書：RCS-1062に伴う下記改定を実施 FSC製品区分に統合(FSC認証製品＝FSC製品区分)、FSC材質区分が重複２つ | BC13: 検索入出力仕様 | BM13: 44894 | BR13: 44895
BM14: MDSOL | BR14: MDSOL 奥本
A15: 2 | F15: 仕様連絡書：RCS-1062に伴う下記改定を実施 高品質→高管理、各画面から項目削除、DB項目としては残す | BC15: 検索入出力仕様 更新入出力仕様_品目マスタ | BM15: 44896 | BR15: 44896
BM16: MDSOL | BR16: MDSOL 奥本
A17: 3 | F17: 仕様連絡書：RCS-1170に伴う下記改定を実施 印刷原紙の品目単位を追加する | BC17: 概要 処理概要 検索入出力仕様 更新入出力仕様_品目マスタ | BM17: 44945 | BR17: 44945
BM18: MDSOL | BR18: MDSOL 奥本
A19: 3 | F19: 仕様連絡書：RCS-1170に伴う下記改定を実施 原紙マスタの更新を削除する | BC19: 検索入出力仕様 更新入出力仕様_品目マスタ | BM19: 44945 | BR19: 44945
BM20: MDSOL石田 | BR20: MDSOL 奥本
A21: 4 | F21: 仕様連絡書：RCS-1115 処理概要図にMRP対象マップを追加 | BC21: 処理概要図 | BM21: 44959 | BR21: 44960
BM22: MDSOL石田 | BR22: MDSOL 奥本
A23: 4 | F23: 仕様連絡書：RCS-1115 概要シートと更新入出力仕様の表列を合わせる。 ※更新入出力仕様は概要をさらに細分化したものとする。 | BC23: 概要 更新入出力仕様_○○ | BM23: 44960 | BR23: 44960
BM24: MDSOL石田 | BR24: MDSOL 奥本
A25: 5 | F25: シ設計集中見直し（RCS-1229）:参照元_見積計算書ＮＯ 項目削除／項目見直し(見積計算書ＮＯ) | BC25: 検索入出力仕様 | BM25: 44964 | BR25: 44964
BM26: MDSOL野村 | BR26: MDSOL 奥本
A27: 6 | F27: シ設計集中見直し（RCS-1229）:品目区分と品目区分詳細設定の設定方法記載 | BC27: 更新入出力仕様_品目マスタ、 補足説明資料_品目区分設定方法 | BM27: 44965 | BR27: 44966
BM28: MDSOL石田 | BR28: MDSOL 奥本
A29: 6 | F29: シ設計集中見直し（RCS-1229）:マスタ設定値の変更 | BC29: 更新入出力仕様_品目詳細マスタ、 更新入出力仕様_BOMマスタ | BM29: 44965 | BR29: 44966
BM30: MDSOL石田 | BR30: MDSOL 奥本
A31: 6 | F31: シ設計集中見直し（RCS-1229）:本支店単価マスタの連携廃止 | BC31: 概要、処理概要、 更新入出力仕様_本支店単価マスタ、補足説明資料_mcframeとのキー比較 | BM31: 44965 | BR31: 44966
BM32: MDSOL石田 | BR32: MDSOL 奥本
A33: 6 | F33: シ設計集中見直し（RCS-1229）:刷版手配の親子関係補足 | BC33: 補足説明資料_親子関係 | BM33: 44965 | BR33: 44966
BM34: MDSOL石田 | BR34: MDSOL 奥本
A35: 7 | F35: シ設計集中見直し（RCS-1229）:事業所別原紙巾マスタのキー見直しによる訂正 | BC35: 更新入出力仕様_（アドオン）事業所別原紙巾マスタ | BM35: 44966 | BR35: 44966
BM36: MDSOL石田 | BR36: MDSOL 奥本
A37: 8 | F37: 仕様連絡書：RCS-1369 に伴う下記改定を実施 品目区分詳細の訂正 商品・製品印刷原紙の削除 | BC37: 補足説明資料_品目区分設定方法 | BM37: 45016 | BR37: 45016
BM38: MDSOL石田 | BR38: MDSOL 奥本
A39: 8 | F39: 仕様連絡書：RCS-1369 に伴う下記改定を実施 本支店単価マスタの連携復活 | BC39: 概要、処理概要、 更新入出力仕様_本支店単価マスタ、補足説明資料_mcframeとのキー比較 | BM39: 45016 | BR39: 45016
BM40: MDSOL石田 | BR40: MDSOL 奥本

Sheet 概要
A1: =表紙!A54 -> Webシステム | O1: 文書名 | AC1: モジュールID | AJ1: =表紙!AJ63 -> MS | AQ1: モジュール名 | AX1: =表紙!AX63 -> 見積管理 | BL1: 文書番号 | BU1: Version | CB1: Rev.
O2: =表紙!O64 -> アドオン設計書 | AC2: サブモジュールID | AJ2: =表紙!AJ64 -> MSBB | AQ2: サブモジュール名 | AX2: =表紙!AX64 -> Webシステム | BL2: =表紙!BL64 -> M7-US-1140 | BU2: =表紙!BU64 -> 7.0.2 | CB2: =表紙!CB64 -> 8
O3: =RIGHT(CELL("filename",$A$1),LEN(CELL("filename",$A$1))-FIND("]",CELL("filename",$A$1))) -> 概要 | AC3: 表題 | AJ3: =表紙!AJ65 -> - | AQ3: =表紙!AQ65 -> 製品マスタ連携
AO5: 概要
B7: 【業務要件】
C8: カスタマイズ | G8: 内容
C9: No.
C10: 97 | G10: ・WEB製品マスタ、受注からmcframe7への品目関連マスタ送信
B13: 【説明】
C14: 製品基本マスタ、製品加工工程マスタ、製品ロット別単価マスタからmcframeのマスタへ登録・更新を行う。
C15: 起動はジョブ起動となる。
B17: 【目的】
C18: ・WEBの製品マスタ、受注からmcframe７の販売管理、生産管理が動作するようにマスタ連携する。
AP20: 凡例
C21: 製品マスタ承認・更新時にマスタ連携を実施する。 | AR21: 〇：連携対象
M22: 品目区分 | AR22: △：条件により連携 | AZ22: 品目区分説明
C23: 製品マスタ連携対象テーブル | M23: 商品 | U23: 製品 | AC23: 中間品 | AK23: 資材 | AS23: 原材料 | AW23: 原材料 | BA23: 原材料 | BI23: 商品：商品構成あり（加工品）、商品構成なし（諸口品目在庫管理対象） | CJ23: REV4.0 更新入出力仕様に合わせて資材の追加
C24: テーブル | M24: 構成あり | Q24: 構成なし | U24: 内 | Y24: 外 | AC24: 内 | AG24: 外 | AK24: 在庫管理品 | AO24: 非在庫品 | AS24: 購買 | AW24: 印刷原紙 | BA24: 諸口 | BI24: 製品：製品
C25: 品目マスタ（共通） | M25: ○ | U25: 〇 | AC25: 〇 | AK25: ○ | AS25: 〇 | AW25: 〇 | BI25: 中間品：工程仕掛品
C26: 品目マスタ（会社） | M26: ○ | U26: 〇 | AC26: 〇 | AK26: ○ | AS26: 〇 | AW26: 〇 | BI26: 原材料：カートン、コートボール
C27: 品目詳細マスタ | M27: ○ | U27: 〇 | Y27: 〇 | AC27: 〇 | AG27: 〇 | AK27: ○ | AS27: 〇 | AW27: 〇 | BI27: 原材料（印刷原紙）：印刷原紙
C28: 品目格納先マスタ | M28: △ | U28: △ | Y28: △ | AC28: △ | AG28: △ | AK28: △ | AS28: △ | AW28: △ | BI28: 原材料（諸口）：梱包資材等
C29: BOMマスタ | M29: ○ | U29: 〇 | AC29: 〇 | AK29: 〇 | BI29: ※１ 連携処理で番号採番。番号体系は「コード体系」参照
C30: 品目工程マスタ | M30: ○ | U30: 〇 | Y30: 〇 | AC30: 〇 | AG30: 〇 | BI30: ※２ 印刷原紙とそれ以外で番号体系が異なる
C31: 工程工数マスタ | M31: ○ | U31: 〇 | AC31: 〇
C32: 得意先販売単価マスタ | M32: ○ | U32: 〇
C33: 加工単価マスタ | M33: △ | Y33: △ | AG33: △
C34: 購買単価マスタ | AK34: △ | AS34: △ | AW34: △
C35: （アドオン）本支店単価マスタ | M35: ○ | U35: 〇 | CJ35: REV6.0 本支店単価マスタの廃止 | CU35: REV8.0 本支店単価マスタの復活
C36: （アドオン）原紙マスタ | AW36: 〇
C37: （アドオン）事業所別原紙巾マスタ | AW37: 〇
C38: 品目単位マスタ | AW38: 〇 | CJ38: REV3.0 品目単位マスタの追加
AP40: 凡例
C41: シート受注、商品購買受注時にマスタ連携を実施する。 | AR41: 〇：連携対象
M42: 品目区分 | AR42: △：条件により連携 | BD42: 品目区分説明
C43: 受注マスタ連携対象テーブル | M43: 商品 | Y43: 製品 | AG43: 中間品 | AO43: 資材 | AW43: 原材料 | BA43: 原材料 | BE43: 原材料 | BJ43: 商品：商品構成あり（加工品）、商品構成なし（諸口品目在庫管理対象） | CJ43: REV4.0 更新入出力仕様に合わせて資材の追加
C44: テーブル | M44: 構成あり | Q44: 構成なし | U44: 版型 | Y44: 内 | AC44: 外 | AG44: 内 | AK44: 外 | AO44: 在庫管理品 | AS44: 非在庫品 | AW44: 購買 | BA44: 印刷原紙 | BE44: 諸口 | BJ44: 製品：製品
C45: 品目マスタ（共通） | U45: ○ | Y45: 〇 | AG45: 〇 | AO45: ○ | AW45: 〇 | BA45: 〇 | BJ45: 中間品：工程仕掛品
C46: 品目マスタ（会社） | U46: ○ | Y46: 〇 | AG46: 〇 | AO46: ○ | AW46: 〇 | BA46: 〇 | BJ46: 原材料：カートン、コートボール
C47: 品目詳細マスタ | Y47: 〇 | AC47: 〇 | AG47: 〇 | AK47: 〇 | AO47: ○ | AW47: 〇 | BA47: 〇 | BJ47: 原材料（印刷原紙）：印刷原紙
...

Sheet レイアウト_
A1: =表紙!A54 -> Webシステム | K1: 文書名 | U1: モジュールID | Z1: =表紙!$AJ$63 -> MS | AE1: モジュール名 | AJ1: =表紙!$AX$63 -> 見積管理 | AS1: 文書番号 | AZ1: Version | BF1: Rev.
K2: =表紙!O64 -> アドオン設計書 | U2: ｻﾌﾞﾓｼﾞｭｰﾙID | Z2: =表紙!$AJ$64 -> MSBB | AE2: ｻﾌﾞﾓｼﾞｭｰﾙ名 | AJ2: =表紙!$AX$64 -> Webシステム | AS2: =表紙!$BL$64 -> M7-US-1140 | AZ2: =表紙!$BU$64 -> 7.0.2 | BF2: =表紙!$CB$64 -> 8
K3: =RIGHT(CELL("filename",$A$1),LEN(CELL("filename",$A$1))-FIND("]",CELL("filename",$A$1))) -> レイアウト_ | U3: 表題 | Z3: =表紙!$AJ$65 -> - | AE3: =表紙!$AQ$65 -> 製品マスタ連携
A5: 画面イメージ
B7: ≫凡例
Q8: ・・・ | S8: ボタン
C9: 見積計算書№ | Q9: ・・・ | S9: 検索項目(検索画面表示選択)
C10: 品名 | Q10: ・・・ | S10: 入力項目
C11: 得意先 | Q11: ・・・ | S11: 表示項目(得意先名称、原紙名等)
C12: 操作種別 | I12: ●登録 | M12: ○訂正 | Q12: ・・・ | S12: 選択項目(一つのみ選択可能)
C13: 受注区分 | Q13: ・・・ | S13: 選択項目(一つのみ選択可能)
C14: 作業順 | I14: ☑AAA | M14: ☑BBB | Q14: ・・・ | S14: 選択項目(複数選択可能)
C16: TOP画面
D21: 操作種別 | J21: ●登録 | N21: ○訂正 | R21: ○削除 | V21: ○参照
D23: 御見積書№ | J23: (件名:オートフィルタ) | AD23: 製品CD | AJ23: (品名:オートフィルタ)
AD24: (セット品)
D25: ↑新規時 有効 | AD25: ↑訂正、削除、参照時 有効
D31: 案件№
D32: 得意先
D34: セット部品
D36: № | F36: 詳細 | I36: 製品CD | Q36: 製品名
E37: 1 | Q37: 味比べ3P箱 (見・蓋・仕切り)
D40: 部材
D42: № | F42: 確定 | I42: セット | L42: 詳細 | O42: 見積計算書№ | T42: 製品CD | AB42: 製品名
E43: 1 | F43: □ | I43: □ | AB43: 味比べ3P箱 身
E44: 2 | F44: □ | I44: □ | AB44: 味比べ3P箱 蓋
E45: 3 | F45: □ | I45: □ | AB45: 味比べ3P箱 仕切り
C54: 製品マスタ入力詳細（部材）
D59: 操作種別 | J59: ●登録 | N59: ○訂正 | R59: ○削除 | V59: ○参照
D61: 製品CD
D63: 案件№
D64: 得意先
D66: 受注区分 | J66: 1 | L66: 製品 | T66: 製品区分 | Z66: 13 | AB66: Gプリント | AJ66: 責任部門 | AP66: 5120 | AU66: 名古屋製造 | AZ66: FSC認証管理№
D67: セット比率 | J67: 1.000 | T67: 製品用途 | Z67: 81 | AB67: 雑貨 | AJ67: シート部門 | AP67: 5120 | AU67: 名古屋製造 | AZ67: 物流区分 | BJ67: (1:物流箱)
D68: 機密情報 | N68: (1:社外秘) | T68: 奪取区分 | AD68: (1:奪取) | AJ68: 重要区分 | AT68: (A B C D) | AZ68: Mチェン | BJ68: (1:ライバル、2:社内)
D69: 品質区分 | N69: (1:高品質) | T69: 出荷検査 | AD69: (1:要検査) | AJ69: 高管理 | AT69: (1:高) | AZ69: 製品計上区分
D70: ユネスコマーク | N70: (1:使用) | T70: 折鶴マーク | AD70: (1:広島折鶴、2:CP折鶴) | AZ70: FSC認証製品 | BJ70: (1:客、2:CP、3:マークナシ)
D71: 4M契約 | N71: (1:有) | T71: TKP折れシワ基準 | AD71: (1:標準、2:高品質) | AZ71: FSC材質区分 | BJ71: (1:ミックス、2:リサイクル)
D72: 容リ支払 | T72: 識別表示 | AZ72: 食品安全 | BJ72: (1:FSSC22000)
D74: 使用料 | M74: .0 | N74: / | Q74: .0 | R74: / | U74: .0 | V74: / | Y74: .0
...

Sheet 処理詳細
A1: =表紙!A54 -> Webシステム | K1: 文書名 | U1: モジュールID | Z1: =表紙!$AJ$63 -> MS | AE1: モジュール名 | AJ1: =表紙!$AX$63 -> 見積管理 | AS1: 文書番号 | AZ1: Version | BF1: Rev.
K2: =表紙!O64 -> アドオン設計書 | U2: ｻﾌﾞﾓｼﾞｭｰﾙID | Z2: =表紙!$AJ$64 -> MSBB | AE2: ｻﾌﾞﾓｼﾞｭｰﾙ名 | AJ2: =表紙!$AX$64 -> Webシステム | AS2: =表紙!$BL$64 -> M7-US-1140 | AZ2: =表紙!$BU$64 -> 7.0.2 | BF2: =表紙!$CB$64 -> 8
K3: =RIGHT(CELL("filename",$A$1),LEN(CELL("filename",$A$1))-FIND("]",CELL("filename",$A$1))) -> 処理詳細 | U3: 表題 | Z3: =表紙!$AJ$65 -> - | AE3: =表紙!$AQ$65 -> 製品マスタ連携
A5: No | B5: 入力 | J5: 処理 | BD5: 出力
A6: 1 | B6: 初期表示
A12: 2 | B12: 画面操作
A18: 3 | B18: 検索【F1】

Sheet 処理・サービス関連図
A1: =表紙!A54 -> Webシステム | K1: 文書名 | U1: モジュールID | Z1: =表紙!$AJ$63 -> MS | AE1: モジュール名 | AJ1: =表紙!$AX$63 -> 見積管理 | AS1: 文書番号 | AZ1: Version | BF1: Rev.
K2: =表紙!O64 -> アドオン設計書 | U2: ｻﾌﾞﾓｼﾞｭｰﾙID | Z2: =表紙!$AJ$64 -> MSBB | AE2: ｻﾌﾞﾓｼﾞｭｰﾙ名 | AJ2: =表紙!$AX$64 -> Webシステム | AS2: =表紙!$BL$64 -> M7-US-1140 | AZ2: =表紙!$BU$64 -> 7.0.2 | BF2: =表紙!$CB$64 -> 8
K3: =RIGHT(CELL("filename",$A$1),LEN(CELL("filename",$A$1))-FIND("]",CELL("filename",$A$1))) -> 処理・サービス関連図 | U3: 表題 | Z3: =表紙!$AJ$65 -> - | AE3: =表紙!$AQ$65 -> 製品マスタ連携
BM25: REV4.0 品質対応 MRP処理対象マップテーブルの追加

Sheet 処理概要
A1: =表紙!A54 -> Webシステム | K1: 文書名 | U1: モジュールID | Z1: =表紙!$AJ$63 -> MS | AE1: モジュール名 | AJ1: =表紙!$AX$63 -> 見積管理 | AS1: 文書番号 | AZ1: Version | BF1: Rev.
K2: =表紙!O64 -> アドオン設計書 | U2: ｻﾌﾞﾓｼﾞｭｰﾙID | Z2: =表紙!$AJ$64 -> MSBB | AE2: ｻﾌﾞﾓｼﾞｭｰﾙ名 | AJ2: =表紙!$AX$64 -> Webシステム | AS2: =表紙!$BL$64 -> M7-US-1140 | AZ2: =表紙!$BU$64 -> 7.0.2 | BF2: =表紙!$CB$64 -> 8
K3: =RIGHT(CELL("filename",$A$1),LEN(CELL("filename",$A$1))-FIND("]",CELL("filename",$A$1))) -> 処理概要 | U3: 表題 | Z3: =表紙!$AJ$65 -> - | AE3: =表紙!$AQ$65 -> 製品マスタ連携
A5: No | B5: 入力 | J5: 処理 | BD5: 出力
A6: 1 | B6: 初期処理
B7: 入力引数）
C8: 起動区分
J9: １．起動区分判定
K10: 1-1)処理区分：1 製品マスタの場合
L11: 製品マスタ連携処理を実行する。
K12: 1-2)処理区分：それ以外 受注の場合
L13: 受注マスタ連携処理を実行する
A15: ２ | B15: 製品マスタ連携処理
J16: １．処理対象取得
K17: 1-1)製品基本マスタ取得
L18: 処理対象の製品基本マスタ情報を取得する。 | BD18: 検索入出力仕様1
L19: ・検索条件
L20: 製品基本マスタ.ステータス：承認済み
L21: 製品基本マスタ.mcframe7転送FLG:未転送
J24: 2 | K24: マスタ連携処理
L25: 製品CDごとに以下処理を実施する。
M26: １）製品関連マスタの取得
N27: 製品CDを条件に製品加工工程マスタを取得する。 | BD27: 検索入出力仕様2
N28: 製品CDを条件に製品加工材料マスタを取得する。 | BD28: 検索入出力仕様3
N29: 製品CDを条件に製品連産品マスタを取得する。 | BD29: 検索入出力仕様4
N30: 製品CDを条件に製品ロット別単価マスタを取得する。 | BD30: 検索入出力仕様5
M31: ２）製品加工工程マスタのデータ分、以下処理を実施する。
N32: 2-1)品目マスタマッピング | BD32: 更新入出力仕様_品目マスタ
O33: ※既に登録されていないか？製品CDと枝番２の工程で確認をする。
N34: 2-2)品目詳細マスタマッピング | BD34: 更新入出力仕様_品目詳細マスタ
N35: 2-3)品目工程マスタマッピング | BD35: 更新入出力仕様_品目工程マスタ
N36: 2-4)品目格納先マスタマッピング | BD36: 更新入出力仕様_品目格納先マスタ
N37: 2-5)工程工数マスタマッピング | BD37: 更新入出力仕様_工程工数マスタ
N38: 2-6)購買単価マスタマッピング | BD38: 更新入出力仕様_購買単価マスタ
N39: 2-7)加工単価マスタマッピング | BD39: 更新入出力仕様_加工単価マスタ
N40: 2-8)（アドオン）事業所別原紙巾マスタマッピング | BD40: 更新入出力仕様_（アドオン）事業所別原紙巾マスタ
N41: 2-9)（アドオン）原紙マスタマッピング | BD41: 更新入出力仕様_（アドオン）原紙マスタ
M42: ３）製品加工材料マスタを元にBOMマスタを作成する
N43: ３－１）BOMマスタの登録 | BD43: 更新入出力仕様_BOMマスタ
M44: ４）製品処理
...

Sheet 引数説明
A1: =表紙!A54 -> Webシステム | K1: 文書名 | U1: モジュールID | Z1: =表紙!$AJ$63 -> MS | AE1: モジュール名 | AJ1: =表紙!$AX$63 -> 見積管理 | AS1: 文書番号 | AZ1: Version | BF1: Rev.
K2: =表紙!O64 -> アドオン設計書 | U2: ｻﾌﾞﾓｼﾞｭｰﾙID | Z2: =表紙!$AJ$64 -> MSBB | AE2: ｻﾌﾞﾓｼﾞｭｰﾙ名 | AJ2: =表紙!$AX$64 -> Webシステム | AS2: =表紙!$BL$64 -> M7-US-1140 | AZ2: =表紙!$BU$64 -> 7.0.2 | BF2: =表紙!$CB$64 -> 8
K3: =RIGHT(CELL("filename",$A$1),LEN(CELL("filename",$A$1))-FIND("]",CELL("filename",$A$1))) -> 引数説明 | U3: 表題 | Z3: =表紙!$AJ$65 -> - | AE3: =表紙!$AQ$65 -> 製品マスタ連携
B5: オペレーションＩＤ/名称：SloRecvIfImp_Upd01/取込
A6: 必 | B6: 項目名 | N6: 説明 | AS6: 未設定時の振る舞い
B7: 得意先ＣＤ | M7: 受注受信ＩＦの検索条件

Sheet 検索入出力仕様
A1: =表紙!A54 -> Webシステム | K1: 文書名 | U1: モジュールID | Z1: =表紙!$AJ$63 -> MS | AE1: モジュール名 | AJ1: =表紙!$AX$63 -> 見積管理 | AS1: 文書番号 | AZ1: Version | BF1: Rev.
K2: =表紙!O64 -> アドオン設計書 | U2: ｻﾌﾞﾓｼﾞｭｰﾙID | Z2: =表紙!$AJ$64 -> MSBB | AE2: ｻﾌﾞﾓｼﾞｭｰﾙ名 | AJ2: =表紙!$AX$64 -> Webシステム | AS2: =表紙!$BL$64 -> M7-US-1140 | AZ2: =表紙!$BU$64 -> 7.0.2 | BF2: =表紙!$CB$64 -> 8
K3: =RIGHT(CELL("filename",$A$1),LEN(CELL("filename",$A$1))-FIND("]",CELL("filename",$A$1))) -> 検索入出力仕様 | U3: 表題 | Z3: =表紙!$AJ$65 -> - | AE3: =表紙!$AQ$65 -> 製品マスタ連携
A5: No | G5: 1 | H5: 製品基本マスタ | S5: ボタン | AH5: 備考
A6: 処理分類 | E6: 検索 | S6: ソート順
A7: No | C7: 転送先 | V7: 転送元 | AQ7: 説明
C8: 種 | D8: オブジェクト | K8: 項目名 | V8: 種 | W8: オブジェクト | AF8: 項目名
D9: 製品基本マスタ | K9: 製品コード | V9: T | W9: 製品基本マスタ | AF9: 製品コード
D10: 製品基本マスタ | K10: 品目コード | V10: T | W10: 製品基本マスタ | AF10: 品目コード
D11: 製品基本マスタ | K11: 枝番１ | V11: T | W11: 製品基本マスタ | AF11: 枝番１
D12: 製品基本マスタ | K12: 枝番２ | V12: T | W12: 製品基本マスタ | AF12: 枝番２
D13: 製品基本マスタ | K13: 枝番３ | V13: T | W13: 製品基本マスタ | AF13: 枝番３
D14: 製品基本マスタ | K14: 案件NO(親)、(子)、(部材) | V14: T | W14: 製品基本マスタ | AF14: 案件NO(親)、(子)、(部材) | BM14: Rev2.0 変更
D15: 製品基本マスタ | K15: 御見積書NO | V15: T | W15: 製品基本マスタ | AF15: 御見積書NO
D16: 製品基本マスタ | K16: 見積計算書NO | V16: T | W16: 製品基本マスタ | AF16: 見積計算書NO
D17: 製品基本マスタ | K17: 参照元_見積計算書NO | V17: T | W17: 製品基本マスタ | AF17: 参照元_見積計算書NO | BM17: Rev5.0 見積計算書ＮＯ項目 重複削除
D18: 製品基本マスタ | K18: 得意先コード | V18: T | W18: 製品基本マスタ | AF18: 得意先コード
D19: 製品基本マスタ | K19: セット製品CD | V19: T | W19: 製品基本マスタ | AF19: セット製品CD
D20: 製品基本マスタ | K20: セット品名 | V20: T | W20: 製品基本マスタ | AF20: セット品名
D21: 製品基本マスタ | K21: 親子区分 | V21: T | W21: 製品基本マスタ | AF21: 親子区分
D22: 製品基本マスタ | K22: 顧客品名1 | V22: T | W22: 製品基本マスタ | AF22: 顧客品名1
D23: 製品基本マスタ | K23: 顧客品名2 | V23: T | W23: 製品基本マスタ | AF23: 顧客品名2
D24: 製品基本マスタ | K24: 顧客品番 | V24: T | W24: 製品基本マスタ | AF24: 顧客品番
D25: 製品基本マスタ | K25: CP品名1 | V25: T | W25: 製品基本マスタ | AF25: CP品名1
D26: 製品基本マスタ | K26: CP品名2 | V26: T | W26: 製品基本マスタ | AF26: CP品名2
D27: 製品基本マスタ | K27: JANコード | V27: T | W27: 製品基本マスタ | AF27: JANコード
D28: 製品基本マスタ | K28: セット比率 | V28: T | W28: 製品基本マスタ | AF28: セット比率
D29: 製品基本マスタ | K29: 製品用途 | V29: T | W29: 製品基本マスタ | AF29: 製品用途
... D36: 製品基本マスタ | K36: 出荷検査 | V36: T | W36: 製品基本マスタ | AF36: 出荷検査
D37: 製品基本マスタ | K37: 高品質 | V37: T | W37: 製品基本マスタ | AF37: 高品質 | BM37: Rev2.0 項目削除(高品質 項目削除)
D38: 製品基本マスタ | K38: 製品形状 | V38: T | W38: 製品基本マスタ | AF38: 製品形状
D39: 製品基本マスタ | K39: ユネスコマーク | V39: T | W39: 製品基本マスタ | AF39: ユネスコマーク
D40: 製品基本マスタ | K40: 折鶴マーク | V40: T | W40: 製品基本マスタ | AF40: 折鶴マーク
D41: 製品基本マスタ | K41: FSC認証製品 | V41: T | W41: 製品基本マスタ | AF41: FSC認証製品 | BM41: Rev2.0 項目削除(FSC認証製品＝FSC製品区分)
D42: 製品基本マスタ | K42: FSC材質区分 | V42: T | W42: 製品基本マスタ | AF42: FSC材質区分
D43: 製品基本マスタ | K43: FSC製品区分 | V43: T | W43: 製品基本マスタ | AF43: FSC製品区分
D44: 製品基本マスタ | K44: FSC管理NO | V44: T | W44: 製品基本マスタ | AF44: FSC管理NO
D45: 製品基本マスタ | K45: 4M契約 | V45: T | W45: 製品基本マスタ | AF45: 4M契約
D46: 製品基本マスタ | K46: TKP折れシワ基準 | V46: T | W46: 製品基本マスタ | AF46: TKP折れシワ基準
D47: 製品基本マスタ | K47: FSC材質区分 | V47: T | W47: 製品基本マスタ | AF47: FSC材質区分 | BM47: Rev2.0 項目削除(FSC材質区分が２つ)
...

Sheet 更新入出力仕様
A1: =表紙!A54 -> Webシステム | K1: 文書名 | U1: モジュールID | Z1: =表紙!$AJ$63 -> MS | AE1: モジュール名 | AJ1: =表紙!$AX$63 -> 見積管理 | AS1: 文書番号 | AZ1: Version | BF1: Rev.
K2: =表紙!O64 -> アドオン設計書 | U2: ｻﾌﾞﾓｼﾞｭｰﾙID | Z2: =表紙!$AJ$64 -> MSBB | AE2: ｻﾌﾞﾓｼﾞｭｰﾙ名 | AJ2: =表紙!$AX$64 -> Webシステム | AS2: =表紙!$BL$64 -> M7-US-1140 | AZ2: =表紙!$BU$64 -> 7.0.2 | BF2: =表紙!$CB$64 -> 8
K3: =RIGHT(CELL("filename",$A$1),LEN(CELL("filename",$A$1))-FIND("]",CELL("filename",$A$1))) -> 更新入出力仕様 | U3: 表題 | Z3: =表紙!$AJ$65 -> - | AE3: =表紙!$AQ$65 -> 製品マスタ連携
A5: No | G5: 1 | H5: 製品基本マスタ | S5: ロジック名称 | AH5: 備考
A6: 処理分類 | E6: 更新
A7: No | C7: 転送先 | V7: 転送元 | AQ7: 説明
C8: 種 | D8: オブジェクト | K8: 項目名 | V8: 種 | W8: オブジェクト | AF8: 項目名
A9: 1 | C9: T | D9: 製品基本マスタ | K9: ステータス | AQ9: 固定:9 転送済み
A10: 2 | C10: T | D10: 製品基本マスタ | K10: mcframe7転送FLG | AQ10: 固定:1
A17: No | G17: 2 | H17: 受注加工工程マスタ | S17: ロジック名称 | AH17: 備考
A18: 処理分類 | E18: 追加
A19: No | C19: 転送先 | V19: 転送元 | AQ19: 説明
C20: 種 | D20: オブジェクト | K20: 項目名 | V20: 種 | W20: オブジェクト | AF20: 項目名
A21: 1 | C21: T | D21: 受注加工工程マスタ | K21: Web受注NO | V21: T | W21: 受注加工工程マスタ | AF21: Web受注NO | AQ21: OBJECTで保持している受注加工工程マスタ
A22: 2 | C22: T | D22: 受注加工工程マスタ | K22: Web受注明細NO | V22: T | W22: 受注加工工程マスタ | AF22: Web受注明細NO | AQ22: OBJECTで保持している受注加工工程マスタ
A23: 3 | C23: T | D23: 受注加工工程マスタ | K23: 製品コード | V23: T | W23: 製品加工工程マスタ | AF23: 製品コード
A24: 4 | C24: T | D24: 受注加工工程マスタ | K24: 作業コード | V24: T | W24: 製品加工工程マスタ | AF24: 作業コード
A25: 5 | C25: T | D25: 受注加工工程マスタ | K25: 工程コード | V25: T | W25: 製品加工工程マスタ | AF25: 工程コード
A26: 6 | C26: T | D26: 受注加工工程マスタ | K26: TOP品目コード | V26: T | W26: 製品加工工程マスタ | AF26: TOP品目コード
A27: 7 | C27: T | D27: 受注加工工程マスタ | K27: TOP品目_枝番1 | V27: T | W27: 製品加工工程マスタ | AF27: TOP品目_枝番1
A28: 8 | C28: T | D28: 受注加工工程マスタ | K28: TOP品目_枝番2 | V28: T | W28: 製品加工工程マスタ | AF28: TOP品目_枝番2
A29: 9 | C29: T | D29: 受注加工工程マスタ | K29: TOP品目_枝番3 | V29: T | W29: 製品加工工程マスタ | AF29: TOP品目_枝番3
A30: 10 | C30: T | D30: 受注加工工程マスタ | K30: 品目コード | V30: T | W30: 製品加工工程マスタ | AF30: 品目コード
A31: 11 | C31: T | D31: 受注加工工程マスタ | K31: 枝番1 | V31: T | W31: 製品加工工程マスタ | AF31: 枝番1
A32: 12 | C32: T | D32: 受注加工工程マスタ | K32: 枝番2 | V32: T | W32: 製品加工工程マスタ | AF32: 枝番2
A33: 13 | C33: T | D33: 受注加工工程マスタ | K33: 枝番3 | V33: T | W33: 製品加工工程マスタ | AF33: 枝番3
A34: 14 | C34: T | D34: 受注加工工程マスタ | K34: ワーキンググループＣＤ | V34: T | W34: 製品加工工程マスタ | AF34: ワーキンググループＣＤ
... A67: 47 | C67: T | D67: 受注加工工程マスタ | K67: 製造順優先項目８ | V67: T | W67: 製品加工工程マスタ | AF67: 製造順優先項目８
A69: No | G69: 3 | H69: MRP処理対象マップ | S69: ロジック名称 | AH69: 備考
A70: 処理分類 | E70: 追加
A71: No | C71: 転送先 | V71: 転送元 | AQ71: 説明
C72: 種 | D72: オブジェクト | K72: 項目名 | V72: 種 | W72: オブジェクト | AF72: 項目名
A73: 1 | C73: T | D73: MRP処理対象マップ | K73: 手配ＮＯ１ | V73: T | W73: 受注加工工程マスタ | AF73: 手配NO１ | AQ73: OBJECTで保持している受注加工工程マスタ
A74: 2 | C74: T | D74: MRP処理対象マップ | K74: 実行順 | V74: T | AQ74: 固定:0
A75: 3 | C75: T | D75: MRP処理対象マップ | K75: 会社ＣＤ | V75: T | AQ75: 会社CD
A76: 4 | C76: T | D76: MRP処理対象マップ | K76: ワーキンググループＣＤ | V76: T | W76: 受注加工工程マスタ | AF76: ワーキンググループＣＤ
A77: 5 | C77: T | D77: MRP処理対象マップ | K77: MRPeaフォルダ | V77: T | AQ77: 固定：NULL

Sheet 更新入出力仕様_品目マスタ
A1: =表紙!A54 -> Webシステム | K1: 文書名 | U1: モジュールID | Z1: =表紙!$AJ$63 -> MS | AE1: モジュール名 | AJ1: =表紙!$AX$63 -> 見積管理 | AS1: 文書番号 | AZ1: Version | BF1: Rev.
K2: =表紙!O64 -> アドオン設計書 | U2: ｻﾌﾞﾓｼﾞｭｰﾙID | Z2: =表紙!$AJ$64 -> MSBB | AE2: ｻﾌﾞﾓｼﾞｭｰﾙ名 | AJ2: =表紙!$AX$64 -> Webシステム | AS2: =表紙!$BL$64 -> M7-US-1140 | AZ2: =表紙!$BU$64 -> 7.0.2 | BF2: =表紙!$CB$64 -> 8
K3: =RIGHT(CELL("filename",$A$1),LEN(CELL("filename",$A$1))-FIND("]",CELL("filename",$A$1))) -> 更新入出力仕様_品目マスタ | U3: 表題 | Z3: =表紙!$AJ$65 -> - | AE3: =表紙!$AQ$65 -> 製品マスタ連携
A5: No | G5: 1 | H5: 品目マスタ（共通）_製品 | S5: ロジック名称 | AH5: 備考 | BP5: 品目区分別設定値
A6: 処理分類 | E6: 登録 | BP6: 商品 | BV6: 製品 | BZ6: 中間品 | CD6: 資材 | CF6: 資材 | CH6: 原料 | CJ6: 原料 | CL6: その他
A7: No | C7: 転送先 | V7: 転送元 | AQ7: 説明 | BP7: 構成あり | BR7: 構成なし | BT7: 版型 | BV7: 内 | BX7: 外 | BZ7: 内 | CB7: 外 | CD7: 在庫管理品（カートン等） | CF7: 非在庫品 | CH7: 購買 | CJ7: 印刷原紙 | CL7: 購買
C8: 種 | D8: オブジェクト | K8: 項目名 | V8: 種 | W8: オブジェクト | AF8: 項目名 | BP8: オブジェクト | BQ8: 項目名 | BR8: オブジェクト | BS8: 項目名 | BT8: オブジェクト | BU8: 項目名 | BV8: オブジェクト | BW8: 項目名 | BX8: オブジェクト | BY8: 項目名 | BZ8: オブジェクト | CA8: 項目名 | CB8: オブジェクト | CC8: 項目名 | CD8: オブジェクト | CE8: 項目名 | CF8: オブジェクト | CG8: 項目名 | CH8: オブジェクト | CI8: 項目名 | CJ8: オブジェクト | CK8: 項目名 | CL8: オブジェクト | CM8: 項目名
C9: T | D9: 品目マスタ（共通） | K9: 品目ＣＤ | AQ9: 自動設定 | BT9: WEB受注明細 | BU9: 版型NO ※H+数値7桁 | BV9: 製品基本マスタ | BW9: 製品連番 | BZ9: 製品基本マスタ | CA9: 製品連番 | CE9: M＋1000000～連番 | CK9: 製品基本マスタ.原紙コード＋製品基本マスタ.印刷コード＋製品基本マスタ.エンボスコード | CN9: Rev2.0変更 資材と原紙、版型の採番ルール変更
C10: T | D10: 品目マスタ（共通） | K10: 枝番１ | V10: 画 | W10: 製品基本マスタ | BU10: NULL | BV10: 製品基本マスタ | BW10: 製品枝番 | BZ10: 製品基本マスタ | CA10: 製品枝番 | CE10: NULL | CJ10: 原紙マスタ | CK10: 坪量
C11: T | D11: 品目マスタ（共通） | K11: 枝番２ | V11: 画 | W11: 製品基本マスタ | BU11: NULL | BW11: NULL | BZ11: 加工工程マスタ | CA11: 工程 | CE11: NULL | CJ11: 製品基本マスタ | CK11: 刃渡り_巾
C12: T | D12: 品目マスタ（共通） | K12: 枝番３ | V12: 画 | W12: 製品基本マスタ | BU12: NULL | BW12: NULL | CA12: NULL | CE12: NULL | CJ12: 製品加工工程マスタ | CK12: 工程
C13: T | D13: 品目マスタ（共通） | K13: 品名 | V13: 画 | W13: 製品基本マスタ | AF13: CP品名（CP品名1+全角スペース＋CP品名2） | BT13: WEB受注明細 | BU13: CP品名（CP品名1+全角スペース＋CP品名2） | BV13: 製品基本マスタ | BW13: CP品名（CP品名1+全角スペース＋CP品名2） 例：もつ鍋化粧箱（海千様） 身 | BZ13: 製品基本マスタ | CA13: CP品名+工程名（CP品名1+全角スペース＋ CP品名2＋全角スペース＋工程名） | CD13: 製品基本マスタ | CE13: 得意先品名＋部材名 | CJ13: 原紙マスタ | CK13: 原紙名
C14: T | D14: 品目マスタ（共通） | K14: 品目別名１ | V14: 画 | W14: 製品基本マスタ | AF14: 得意先品名（部材名は入れない） | BT14: WEB受注明細 | BU14: 得意先品名（部材名は入れない） | BV14: 製品基本マスタ | BW14: 得意先品名（部材名は入れない） | BZ14: 製品基本マスタ | CA14: 得意先品名（部材名は入れない） | CD14: 製品基本マスタ | CE14: クラウン品名 | CJ14: 原紙マスタ | CK14: 原紙略称
C15: T | D15: 品目マスタ（共通） | K15: 品目別名２ | V15: 画 | W15: 製品基本マスタ | AF15: 得意先品名２ （部材名） | BU15: 得意先品名２ （部材名） | BV15: 製品基本マスタ | BW15: 得意先品名２ （部材名） | BZ15: 製品基本マスタ | CA15: 得意先品名２ （部材名） | CD15: 製品基本マスタ | CE15: 部材名（身、蓋、仕切り） | CJ15: 原紙マスタ | CK15: 原紙カナ名
C16: T | D16: 品目マスタ（共通） | K16: 品目別名３ | V16: 画 | W16: 製品基本マスタ | AF16: CP品名1 | BU16: CP品名1 | BV16: 製品基本マスタ | BW16: CP品名1 | CA16: CP品名1 | CE16: 荷姿 | CJ16: 製品基本マスタ | CK16: メーカー名
C17: T | D17: 品目マスタ（共通） | K17: 品目別名４ | V17: 画 | W17: 製品基本マスタ | AF17: CP品名2 | BU17: CP品名2 | BV17: 製品基本マスタ | BW17: CP品名2 | CA17: CP品名2 | CE17: NULL | CK17: NULL
C18: T | D18: 品目マスタ（共通） | K18: 品目分類ＣＤ１ | V18: 画 | W18: 製品基本マスタ | AF18: 段 | BU18: NULL | BV18: 製品基本マスタ | BW18: 段 | BZ18: 製品基本マスタ | CA18: 段 | CE18: NULL | CK18: NULL
C19: T | D19: 品目マスタ（共通） | K19: 品目分類ＣＤ２ | V19: 画 | W19: 製品基本マスタ | AF19: 製品区分 | BU19: NULL | BV19: 製品基本マスタ | BW19: 製品区分 | BZ19: 製品基本マスタ | CA19: 製品区分 | CE19: NULL | CK19: NULL
C20: T | D20: 品目マスタ（共通） | K20: 品目分類ＣＤ３ | AQ20: NULL | BU20: NULL | BW20: NULL | CA20: NULL | CE20: 製品の品目CD | CK20: NULL
C21: T | D21: 品目マスタ（共通） | K21: 品目分類ＣＤ４ | V21: 画 | W21: 製品基本マスタ | AF21: 戦略商品区分 | BU21: NULL | BV21: 製品基本マスタ | BW21: 戦略商品区分 | BZ21: 製品基本マスタ | CA21: NULL | CE21: NULL | CK21: NULL
C22: T | D22: 品目マスタ（共通） | K22: 品目分類ＣＤ５ | V22: 画 | W22: 製品基本マスタ | AF22: 原紙区分（小） | BU22: NULL | BV22: 製品基本マスタ | BW22: 原紙区分（小） | BZ22: 製品基本マスタ | CA22: NULL | CE22: NULL | CJ22: 原紙マスタ | CK22: 原紙区分（小）
C23: T | D23: 品目マスタ（共通） | K23: 品目分類ＣＤ６ | V23: 画 | W23: 製品基本マスタ | AF23: 用途 | BU23: NULL | BV23: 製品基本マスタ | BW23: 用途 | BZ23: 製品基本マスタ | CA23: 用途 | CE23: NULL | CK23: NULL
C24: T | D24: 品目マスタ（共通） | K24: 品目分類ＣＤ７ | V24: 画 | W24: 製品基本マスタ | AF24: 機密区分 | BU24: NULL | BV24: 製品基本マスタ | BW24: 機密区分 | BZ24: 製品基本マスタ | CA24: 機密区分 | CE24: NULL | CK24: NULL
C25: T | D25: 品目マスタ（共通） | K25: 品目分類ＣＤ８ | V25: 画 | W25: 製品基本マスタ | AF25: 品質区分 | BU25: NULL | BV25: 製品基本マスタ | BW25: 品質区分 | BZ25: 製品基本マスタ | CA25: 品質区分 | CE25: NULL | CK25: NULL | CP25: Rev2.0 項目変更(高品質 項目削除、品質区分に変更)
C26: T | D26: 品目マスタ（共通） | K26: 品目分類ＣＤ９ | V26: 画 | W26: 製品基本マスタ | AF26: ＦＳＣ区分 | BU26: NULL | BV26: 製品基本マスタ | BW26: ＦＳＣ区分 | BZ26: 製品基本マスタ | CA26: ＦＳＣ区分 | CE26: NULL | CJ26: 原紙マスタ | CK26: ＦＳＣ区分
C27: T | D27: 品目マスタ（共通） | K27: 品目分類ＣＤ１０ | V27: 画 | W27: 製品基本マスタ | AF27: 製品パターン | BU27: NULL | BV27: 製品基本マスタ | BW27: 製品パターン | BZ27: 製品基本マスタ | CA27: 製品パターン | CE27: NULL | CK27: NULL
C28: T | D28: 品目マスタ（共通） | K28: 在庫管理区分 | AQ28: 1:する | BU28: 1:する | BW28: 1:する | CA28: 1:する | CE28: 1:する | CK28: 1:する
C29: T | D29: 品目マスタ（共通） | K29: 資産管理区分 | AQ29: 1:する | BU29: 1:する | BW29: 1:する | CA29: 1:する | CE29: 1:する | CK29: 1:する
C30: T | D30: 品目マスタ（共通） | K30: 諸口品ＦＬＧ | AQ30: 0:しない | BU30: 0:しない | BW30: 0:しない | CA30: 0:しない | CE30: 0:しない | CK30: 0:しない
C31: T | D31: 品目マスタ（共通） | K31: 値引品目ＦＬＧ | AQ31: 0:しない | BU31: 0:しない | BW31: 0:しない | CA31: 0:しない | CE31: 0:しない | CK31: 0:しない
C32: T | D32: 品目マスタ（共通） | K32: 単位ＣＤ | V32: 画 | W32: 製品基本マスタ | AF32: 単位 | BT32: WEB受注明細 | BU32: 数量単位 | BV32: 製品基本マスタ | BW32: 数量単位 | BZ32: 製品基本マスタ | CA32: 枚 | CE32: 個 | CK32: 個
C33: T | D33: 品目マスタ（共通） | K33: 小数部有効桁数 | V33: 画 | W33: 製品基本マスタ→単位マスタ | AF33: 単位小数部有効桁数 | BT33: 単位マスタ | BU33: 単位小数部有効桁数 | BV33: 単位マスタ | BW33: 単位小数部有効桁数 | BZ33: 単位マスタ | CA33: 単位小数部有効桁数 | CD33: 単位マスタ | CE33: 単位小数部有効桁数 | CK33: 単位小数部有効桁数
C34: T | D34: 品目マスタ（共通） | K34: 端数処理区分 | V34: 画 | W34: 製品基本マスタ→単位マスタ | AF34: 端数処理区分 | BT34: 単位マスタ | BU34: 端数処理区分 | BV34: 単位マスタ | BW34: 端数処理区分 | BZ34: 単位マスタ | CA34: 端数処理区分 | CD34: 単位マスタ | CE34: 端数処理区分 | CK34: 端数処理区分
C35: T | D35: 品目マスタ（共通） | K35: 容積単位ＣＤ | AQ35: m3 | BU35: NULL | BW35: NULL | CA35: NULL | CE35: NULL | CK35: NULL
C36: T | D36: 品目マスタ（共通） | K36: 容積 | AQ36: 計算 | BU36: NULL | BW36: NULL | CA36: NULL | CE36: NULL | CK36: NULL
C37: T | D37: 品目マスタ（共通） | K37: 重量単位ＣＤ | AQ37: KG | BU37: NULL | BW37: NULL | CA37: NULL | CE37: NULL | CK37: NULL
C38: T | D38: 品目マスタ（共通） | K38: 重量 | AQ38: 計算 | BU38: NULL | BW38: NULL | CA38: NULL | CE38: NULL | CK38: NULL
C39: T | D39: 品目マスタ（共通） | K39: 入り目単位ＣＤ | AQ39: NULL | BU39: NULL | BW39: NULL | CA39: NULL | CE39: NULL | CK39: NULL
C40: T | D40: 品目マスタ（共通） | K40: 入り目数量 | AQ40: NULL | BU40: NULL | BW40: NULL | CA40: NULL | CE40: NULL | CK40: NULL
C41: T | D41: 品目マスタ（共通） | K41: 単位容積（ｍ３） | AQ41: 計算 | BU41: NULL | BW41: NULL | CA41: NULL | CE41: NULL | CK41: NULL
...

Sheet 更新入出力仕様_品目詳細マスタ
A1: =表紙!A54 -> Webシステム | K1: 文書名 | U1: モジュールID | Z1: =表紙!$AJ$63 -> MS | AE1: モジュール名 | AJ1: =表紙!$AX$63 -> 見積管理 | AS1: 文書番号 | AZ1: Version | BF1: Rev.
K2: =表紙!O64 -> アドオン設計書 | U2: ｻﾌﾞﾓｼﾞｭｰﾙID | Z2: =表紙!$AJ$64 -> MSBB | AE2: ｻﾌﾞﾓｼﾞｭｰﾙ名 | AJ2: =表紙!$AX$64 -> Webシステム | AS2: =表紙!$BL$64 -> M7-US-1140 | AZ2: =表紙!$BU$64 -> 7.0.2 | BF2: =表紙!$CB$64 -> 8
K3: =RIGHT(CELL("filename",$A$1),LEN(CELL("filename",$A$1))-FIND("]",CELL("filename",$A$1))) -> 更新入出力仕様_品目詳細マスタ | U3: 表題 | Z3: =表紙!$AJ$65 -> - | AE3: =表紙!$AQ$65 -> 製品マスタ連携
A5: No | G5: 1 | H5: 品目詳細マスタ_製品 | S5: ロジック名称 | AH5: 備考 | BP5: 品目区分別設定値 | CR5: 通常パタン （前工程仕掛品を投入して、加工） | CT5: 連産品（N丁取り） | CV5: 複数仕掛品を投入 （タンデム） | CX5: 購入品（都度採番）手配対象 | CZ5: 外注品（都度採番）手配対象 ※有償/無償支給 | DB5: 外注品（都度採番）手配対象 ※自給品（無償支給）（材料・仕入の支払い分割） | DD5: 消耗品（在庫管理対象外）手配対象 | DF5: 共通品目（発注点発注）を投入 | DH5: 共通品目（MRP発注）を投入 | DK5: REV4.0 商品を概要と合わせる
A6: 処理分類 | E6: 登録 | BP6: 商品 | BV6: 製品 | BZ6: 中間品 | CH6: 資材 | CJ6: 資材 | CL6: 原料 | CN6: その他 | DK6: REV6.0 版型をMRP対象外にする
A7: No | C7: 転送先 | V7: 転送元 | AQ7: 説明 | BP7: 構成あり | BR7: 構成なし | BT7: 版型 | BV7: 内 | BX7: 外 | BZ7: 内（自事業所） | CB7: 内（他事業所） | CD7: 外 | CF7: 購買 | CH7: 在庫管理品（カートン等） | CJ7: 非在庫品 | CL7: 購買 | CN7: 購買
C8: 種 | D8: オブジェクト | K8: 項目名 | V8: 種 | W8: オブジェクト | AF8: 項目名 | BP8: オブジェクト | BQ8: 項目名 | BR8: オブジェクト | BS8: 項目名 | BT8: オブジェクト | BU8: 項目名 | BV8: オブジェクト | BW8: 項目名 | BX8: オブジェクト | BY8: 項目名 | BZ8: オブジェクト | CA8: 項目名 | CB8: オブジェクト | CC8: 項目名 | CD8: オブジェクト | CE8: 項目名 | CF8: オブジェクト | CG8: 項目名 | CH8: オブジェクト | CI8: 項目名 | CJ8: オブジェクト | CK8: 項目名 | CL8: オブジェクト | CM8: 項目名 | CN8: オブジェクト | CO8: 項目名 | CR8: オブジェクト | CS8: 項目名 | CT8: オブジェクト | CU8: 項目名 | CV8: オブジェクト | CW8: 項目名 | CX8: オブジェクト | CY8: 項目名 | CZ8: オブジェクト | DA8: 項目名 | DB8: オブジェクト | DC8: 項目名 | DD8: オブジェクト | DE8: 項目名 | DF8: オブジェクト | DG8: 項目名 | DH8: オブジェクト | DI8: 項目名
C9: T | D9: 品目詳細マスタ | K9: 品目ＣＤ | V9: T | W9: 品目マスタ | AF9: 品目CD | BT9: 品目マスタ（共通） | BU9: 品目ＣＤ | BV9: 品目マスタ（共通） | BW9: 品目ＣＤ | BX9: 品目マスタ（共通） | BY9: 品目ＣＤ | BZ9: 品目マスタ（共通） | CA9: 品目ＣＤ | CB9: 品目マスタ（共通） | CC9: 品目ＣＤ | CD9: 品目マスタ（共通） | CE9: 品目ＣＤ | CF9: 品目マスタ（共通） | CG9: 品目ＣＤ | CH9: 品目マスタ（共通） | CI9: 品目ＣＤ | CR9: 品目マスタ（共通） | CS9: 品目ＣＤ | CT9: 品目マスタ（共通） | CU9: 品目ＣＤ | CV9: 品目マスタ（共通） | CW9: 品目ＣＤ | CX9: 品目マスタ（共通） | CY9: 品目ＣＤ | CZ9: 品目マスタ（共通） | DA9: 品目ＣＤ | DB9: 品目マスタ（共通） | DC9: 品目ＣＤ | DF9: 品目マスタ（共通） | DG9: 品目ＣＤ | DH9: 品目マスタ（共通） | DI9: 品目ＣＤ
C10: T | D10: 品目詳細マスタ | K10: 枝番１ | V10: T | W10: 品目マスタ | AF10: 枝番１ | BT10: 品目マスタ（共通） | BU10: 枝番１ | BV10: 品目マスタ（共通） | BW10: 枝番１ | BX10: 品目マスタ（共通） | BY10: 枝番１ | BZ10: 品目マスタ（共通） | CA10: 枝番１ | CB10: 品目マスタ（共通） | CC10: 枝番１ | CD10: 品目マスタ（共通） | CE10: 枝番１ | CF10: 品目マスタ（共通） | CG10: 枝番１ | CH10: 品目マスタ（共通） | CI10: 枝番１ | CR10: 品目マスタ（共通） | CS10: 枝番１ | CT10: 品目マスタ（共通） | CU10: 枝番１ | CV10: 品目マスタ（共通） | CW10: 枝番１ | CX10: 品目マスタ（共通） | CY10: 枝番１ | CZ10: 品目マスタ（共通） | DA10: 枝番１ | DB10: 品目マスタ（共通） | DC10: 枝番１ | DF10: 品目マスタ（共通） | DG10: 枝番１ | DH10: 品目マスタ（共通） | DI10: 枝番１
C11: T | D11: 品目詳細マスタ | K11: 枝番２ | V11: T | W11: 品目マスタ | AF11: 枝番２ | BT11: 品目マスタ（共通） | BU11: 枝番２ | BV11: 品目マスタ（共通） | BW11: 枝番２ | BX11: 品目マスタ（共通） | BY11: 枝番２ | BZ11: 品目マスタ（共通） | CA11: 枝番２ | CB11: 品目マスタ（共通） | CC11: 枝番２ | CD11: 品目マスタ（共通） | CE11: 枝番２ | CF11: 品目マスタ（共通） | CG11: 枝番２ | CH11: 品目マスタ（共通） | CI11: 枝番２ | CR11: 品目マスタ（共通） | CS11: 枝番２ | CT11: 品目マスタ（共通） | CU11: 枝番２ | CV11: 品目マスタ（共通） | CW11: 枝番２ | CX11: 品目マスタ（共通） | CY11: 枝番２ | CZ11: 品目マスタ（共通） | DA11: 枝番２ | DB11: 品目マスタ（共通） | DC11: 枝番２ | DF11: 品目マスタ（共通） | DG11: 枝番２ | DH11: 品目マスタ（共通） | DI11: 枝番２
C12: T | D12: 品目詳細マスタ | K12: 枝番３ | V12: T | W12: 品目マスタ | AF12: 枝番３ | BT12: 品目マスタ（共通） | BU12: 枝番３ | BV12: 品目マスタ（共通） | BW12: 枝番３ | BX12: 品目マスタ（共通） | BY12: 枝番３ | BZ12: 品目マスタ（共通） | CA12: 枝番３ | CB12: 品目マスタ（共通） | CC12: 枝番３ | CD12: 品目マスタ（共通） | CE12: 枝番３ | CF12: 品目マスタ（共通） | CG12: 枝番３ | CH12: 品目マスタ（共通） | CI12: 枝番３ | CR12: 品目マスタ（共通） | CS12: 枝番３ | CT12: 品目マスタ（共通） | CU12: 枝番３ | CV12: 品目マスタ（共通） | CW12: 枝番３ | CX12: 品目マスタ（共通） | CY12: 枝番３ | CZ12: 品目マスタ（共通） | DA12: 枝番３ | DB12: 品目マスタ（共通） | DC12: 枝番３ | DF12: 品目マスタ（共通） | DG12: 枝番３ | DH12: 品目マスタ（共通） | DI12: 枝番３
C13: T | D13: 品目詳細マスタ | K13: 製造場所ＣＤ | V13: 画 | W13: 製品基本マスタ | AF13: 製造場所 | AQ13: 最終工程製造場所 | BU13: NULL | BV13: 製品加工工程マスタ | BW13: 号機 | BX13: 場所マスタ | BY13: 場所 ※外注場所 | BZ13: 製品加工工程マスタ | CA13: 号機 | CC13: NULL | CD13: 場所マスタ | CE13: 場所 ※外注場所 | CG13: NULL | CI13: NULL | CR13: 製品加工工程マスタ | CS13: 号機 | CT13: 製品加工工程マスタ | CU13: 号機 | CV13: 製品加工工程マスタ | CW13: 号機 | CY13: NULL | CZ13: 場所マスタ | DA13: 場所 ※外注場所 | DB13: 場所マスタ | DC13: 場所 ※外注場所 | DG13: NULL | DI13: NULL
C14: T | D14: 品目詳細マスタ | K14: 発注先ＣＤ | V14: 画 | W14: 製品基本マスタ | AF14: 発注先 | BT14: WEB木型・版型管理マスタ | BU14: 発注先 | BW14: NULL | BX14: 製品加工工程マスタ | BY14: 発注先 | CA14: NULL | CC14: NULL | CD14: 製品加工工程マスタ | CE14: 発注先 | CF14: 製品加工工程マスタ | CG14: 発注先 | CH14: 製品加工工程マスタ | CI14: 発注先 | CS14: NULL | CU14: NULL | CW14: NULL | CX14: 製品加工工程マスタ | CY14: 発注先 | CZ14: 製品加工工程マスタ | DA14: 発注先 | DB14: 製品加工工程マスタ | DC14: 発注先 | DF14: 製品加工工程マスタ | DG14: 発注先 | DH14: 製品加工工程マスタ | DI14: 発注先
C15: T | D15: 品目詳細マスタ | K15: メーカＣＤ | AQ15: NULL | BU15: NULL | BW15: NULL | BY15: NULL | CA15: NULL | CC15: NULL | CE15: NULL | CG15: NULL | CI15: NULL | CS15: NULL | CU15: NULL | CW15: NULL | CY15: NULL | DA15: NULL | DC15: NULL | DG15: NULL | DI15: NULL
C16: T | D16: 品目詳細マスタ | K16: 依頼先場所ＣＤ | AQ16: NULL | BU16: NULL | BW16: NULL | BY16: NULL | CA16: NULL | CB16: 製品加工工程マスタ | CC16: 号機 | CE16: NULL | CG16: NULL | CI16: NULL | CS16: NULL | CU16: NULL | CW16: NULL | CY16: NULL | DA16: NULL | DC16: NULL | DG16: NULL | DI16: NULL
C17: T | D17: 品目詳細マスタ | K17: ワーキンググループＣＤ | BT17: WEB木型・版型管理マスタ | BU17: 拠点 | BV17: 製品基本マスタ | BW17: WG | BX17: 製品基本マスタ | BY17: WG | BZ17: 製品基本マスタ | CA17: WG | CB17: 製品基本マスタ | CC17: WG | CD17: 製品基本マスタ | CE17: WG | CF17: 製品基本マスタ | CG17: WG | CH17: 製品基本マスタ | CI17: WG | CR17: 製品基本マスタ | CS17: WG | CT17: 製品基本マスタ | CU17: WG | CV17: 製品基本マスタ | CW17: WG | CX17: 製品基本マスタ | CY17: WG | CZ17: 製品基本マスタ | DA17: WG | DB17: 製品基本マスタ | DC17: WG | DF17: 製品基本マスタ | DG17: WG | DH17: 製品基本マスタ | DI17: WG
C18: T | D18: 品目詳細マスタ | K18: 構成パタン | AQ18: 1 | BU18: 1 | BW18: 1 | BY18: 1 | CA18: 1 | CC18: 1 | CE18: 1 | CG18: 1 | CI18: 1 | CS18: 1 | CU18: 1 | CW18: 1 | CY18: 1 | DA18: 1 | DC18: 1 | DG18: 1 | DI18: 1
C19: T | D19: 品目詳細マスタ | K19: 適用開始日 | AQ19: 処理日 | BU19: 処理日 | BW19: 処理日 | BY19: 処理日 | CA19: 処理日 | CC19: 処理日 | CE19: 処理日 | CG19: 処理日 | CI19: 処理日 | CS19: 処理日 | CU19: 処理日 | CW19: 処理日 | CY19: 処理日 | DA19: 処理日 | DC19: 処理日 | DG19: 処理日 | DI19: 処理日
C20: T | D20: 品目詳細マスタ | K20: 会社ＣＤ | AQ20: 会社CD | BU20: 会社CD | BW20: 会社CD | BY20: 会社CD | CA20: 会社CD | CC20: 会社CD | CE20: 会社CD | CG20: 会社CD | CI20: 会社CD | CS20: 会社CD | CU20: 会社CD | CW20: 会社CD | CY20: 会社CD | DA20: 会社CD | DC20: 会社CD | DG20: 会社CD | DI20: 会社CD
C21: T | D21: 品目詳細マスタ | K21: 適用終了日 | AQ21: 2099/12/31 | BU21: 73050 | BW21: 73050 | BY21: 73050 | CA21: 73050 | CC21: 73050 | CE21: 73050 | CG21: 73050 | CI21: 73050 | CS21: 73050 | CU21: 73050 | CW21: 73050 | CY21: 73050 | DA21: 73050 | DC21: 73050 | DG21: 73050 | DI21: 73050
C22: T | D22: 品目詳細マスタ | K22: 工程パタン | AQ22: 1 | BU22: 1 | BW22: 1 | BY22: 1 | CA22: 1 | CC22: 1 | CE22: 1 | CG22: 1 | CI22: 1 | CS22: 1 | CU22: 1 | CW22: 1 | CY22: 1 | DA22: 1 | DC22: 1 | DG22: 1 | DI22: 1
C23: T | D23: 品目詳細マスタ | K23: 製造ＬＴ | V23: 画 | W23: 製品加工マスタ | AF23: 負荷日数 | AQ23: 0 | BU23: 0 | BW23: 0 | BY23: 0 | CA23: 0 | CC23: 0 | CE23: 0 | CG23: 0 | CI23: 0 | CS23: 0 | CU23: 0 | CW23: 0 | CY23: 0 | DA23: 0 | DC23: 0 | DG23: 0 | DI23: 0
C24: T | D24: 品目詳細マスタ | K24: 製造ＬＴ加算基準数量 | AQ24: NULL | BU24: NULL | BW24: NULL | BY24: NULL | CA24: NULL | CC24: NULL | CE24: NULL | CG24: NULL | CI24: NULL | CS24: NULL | CU24: NULL | CW24: NULL | CY24: NULL | DA24: NULL | DC24: NULL | DG24: NULL | DI24: NULL
C25: T | D25: 品目詳細マスタ | K25: 購入ＬＴ | V25: 画 | W25: 製品加工マスタ | AF25: 負荷日数
C26: T | D26: 品目詳細マスタ | K26: 購入ＬＴ加算基準数量 | AQ26: NULL | BU26: NULL | BW26: NULL | BY26: NULL | CA26: NULL | CC26: NULL | CE26: NULL | CG26: NULL | CI26: NULL | CS26: NULL | CU26: NULL | CW26: NULL | CY26: NULL | DA26: NULL | DC26: NULL | DG26: NULL | DI26: NULL
C27: T | D27: 品目詳細マスタ | K27: 検収ＬＴ | AQ27: NULL | BU27: NULL | BW27: NULL | BY27: NULL | CA27: NULL | CC27: NULL | CE27: NULL | CG27: NULL | CI27: NULL | CS27: NULL | CU27: NULL | CW27: NULL | CY27: NULL | DA27: NULL | DC27: NULL | DG27: NULL | DI27: NULL
C28: T | D28: 品目詳細マスタ | K28: 安全ＬＴ | AQ28: 固定:1 | BU28: 固定:1 | BW28: 固定:1 | BY28: 固定:1 | CA28: 固定:1 | CC28: 固定:1 | CE28: 固定:1 | CG28: 固定:1 | CI28: 固定:1 | CS28: 固定:1 | CU28: 固定:1 | CW28: 固定:1 | CY28: 固定:1 | DA28: 固定:1 | DC28: 固定:1 | DG28: 固定:1 | DI28: 固定:1
C29: T | D29: 品目詳細マスタ | K29: オーダ自動確定期間（日） | AQ29: NULL | BU29: NULL | BW29: NULL | BY29: NULL | CA29: NULL | CC29: NULL | CE29: NULL | CG29: NULL | CI29: NULL | CS29: NULL | CU29: NULL | CW29: NULL | CY29: NULL | DA29: NULL | DC29: NULL | DG29: NULL | DI29: NULL
C30: T | D30: 品目詳細マスタ | K30: 曜日まとめ区分 | AQ30: NULL | BU30: NULL | BW30: NULL | BY30: NULL | CA30: NULL | CC30: NULL | CE30: NULL | CG30: NULL | CI30: NULL | CS30: NULL | CU30: NULL | CW30: NULL | CY30: NULL | DA30: NULL | DC30: NULL | DG30: NULL | DI30: NULL
C31: T | D31: 品目詳細マスタ | K31: 曜日まとめ期間（週） | AQ31: NULL | BU31: NULL | BW31: NULL | BY31: NULL | CA31: NULL | CC31: NULL | CE31: NULL | CG31: NULL | CI31: NULL | CS31: NULL | CU31: NULL | CW31: NULL | CY31: NULL | DA31: NULL | DC31: NULL | DG31: NULL | DI31: NULL
C32: T | D32: 品目詳細マスタ | K32: ロットまとめ期間（日） | AQ32: NULL | BU32: NULL | BW32: NULL | BY32: NULL | CA32: NULL | CC32: NULL | CE32: NULL | CG32: NULL | CI32: NULL | CS32: NULL | CU32: NULL | CW32: NULL | CY32: NULL | DA32: NULL | DC32: NULL | DG32: NULL | DI32: NULL
C33: T | D33: 品目詳細マスタ | K33: 最小ロット数量 | CT33: 製品加工マスタ | CU33: 台数
C34: T | D34: 品目詳細マスタ | K34: 刻みロット数量 | CT34: 製品加工マスタ | CU34: 台数
C35: T | D35: 品目詳細マスタ | K35: 最大ロット数量
C36: T | D36: 品目詳細マスタ | K36: 最大オーダ件数 | AQ36: NULL | BU36: NULL | BW36: NULL | BY36: NULL | CA36: NULL | CC36: NULL | CE36: NULL | CG36: NULL | CI36: NULL | CS36: NULL | CU36: NULL | CW36: NULL | CY36: NULL | DA36: NULL | DC36: NULL | DG36: NULL | DI36: NULL
C37: T | D37: 品目詳細マスタ | K37: 優先順 | AQ37: NULL | BU37: NULL | BW37: NULL | BY37: NULL | CA37: NULL | CC37: NULL | CE37: NULL | CG37: NULL | CI37: NULL | CS37: NULL | CU37: NULL | CW37: NULL | CY37: NULL | DA37: NULL | DC37: NULL | DG37: NULL | DI37: NULL
C38: T | D38: 品目詳細マスタ | K38: オーダ比率 | AQ38: 1 | BU38: 1 | BW38: 1 | BY38: 1 | CA38: 1 | CC38: 1 | CE38: 1 | CG38: 1 | CI38: 1 | CS38: 1 | CU38: 1 | CW38: 1 | CY38: 1 | DA38: 1 | DC38: 1 | DG38: 1 | DI38: 1
C39: T | D39: 品目詳細マスタ | K39: 出来高予定数量 | AQ39: 1 | BU39: 1 | BW39: 1 | BY39: 1 | CA39: 1 | CC39: 1 | CE39: 1 | CG39: 1 | CI39: 1 | CS39: 1 | CU39: 1 | CW39: 1 | CY39: 1 | DA39: 1 | DC39: 1 | DG39: 1 | DI39: 1
C40: T | D40: 品目詳細マスタ | K40: 製造指図数量 | AQ40: 1 | BU40: 0 | BW40: 0 | BY40: 0 | CA40: 0 | CC40: 0 | CE40: 0 | CG40: 0 | CI40: 0 | CS40: 0 | CU40: 0 | CW40: 0 | CY40: 0 | DA40: 0 | DC40: 0 | DG40: 0 | DI40: 0
C41: T | D41: 品目詳細マスタ | K41: 固定必要数量 | AQ41: NULL | BU41: NULL | BW41: NULL | BY41: NULL | CA41: NULL | CC41: NULL | CE41: NULL | CG41: NULL | CI41: NULL | CS41: NULL | CU41: NULL | CW41: NULL | CY41: NULL | DA41: NULL | DC41: NULL | DG41: NULL | DI41: NULL
...

Sheet 更新入出力仕様_品目工程マスタ 
A1: =表紙!A54 -> Webシステム | K1: 文書名 | U1: モジュールID | Z1: =表紙!$AJ$63 -> MS | AE1: モジュール名 | AJ1: =表紙!$AX$63 -> 見積管理 | AS1: 文書番号 | AZ1: Version | BF1: Rev.
K2: =表紙!O64 -> アドオン設計書 | U2: ｻﾌﾞﾓｼﾞｭｰﾙID | Z2: =表紙!$AJ$64 -> MSBB | AE2: ｻﾌﾞﾓｼﾞｭｰﾙ名 | AJ2: =表紙!$AX$64 -> Webシステム | AS2: =表紙!$BL$64 -> M7-US-1140 | AZ2: =表紙!$BU$64 -> 7.0.2 | BF2: =表紙!$CB$64 -> 8
K3: =RIGHT(CELL("filename",$A$1),LEN(CELL("filename",$A$1))-FIND("]",CELL("filename",$A$1))) -> 更新入出力仕様_品目工程マスタ | U3: 表題 | Z3: =表紙!$AJ$65 -> - | AE3: =表紙!$AQ$65 -> 製品マスタ連携
A5: No | G5: 1 | H5: 品目工程マスタ | S5: ロジック名称 | AH5: 備考 | BP5: 品目区分別設定値 | CP5: REV4.0 商品を概要と合わせる
A6: 処理分類 | E6: 登録 | BP6: 商品 | BV6: 製品 | BZ6: 中間品 | CF6: 資材 | CH6: 資材 | CJ6: 原料 | CL6: その他
A7: No | C7: 転送先 | V7: 転送元 | AQ7: 説明 | BP7: 構成あり | BR7: 構成なし | BT7: 版型 | BV7: 内 | BX7: 外 | BZ7: 内 | CB7: 外 | CD7: 購買 | CF7: 在庫管理品（カートン等） | CH7: 非在庫品 | CJ7: 購買 | CL7: 購買
C8: 種 | D8: オブジェクト | K8: 項目名 | V8: 種 | W8: オブジェクト | AF8: 項目名 | BP8: オブジェクト | BQ8: 項目名 | BR8: オブジェクト | BS8: 項目名 | BT8: オブジェクト | BU8: 項目名 | BV8: オブジェクト | BW8: 項目名 | BX8: オブジェクト | BY8: 項目名 | BZ8: オブジェクト | CA8: 項目名 | CB8: オブジェクト | CC8: 項目名 | CD8: オブジェクト | CE8: 項目名 | CF8: オブジェクト | CG8: 項目名 | CH8: オブジェクト | CI8: 項目名 | CJ8: オブジェクト | CK8: 項目名 | CL8: オブジェクト | CM8: 項目名
C9: T | D9: 品目工程マスタ | K9: 品目ＣＤ | V9: T | W9: 品目マスタ | AF9: 品目CD | AQ9: 工程CDに対応する品目CD | BV9: 品目マスタ（共通） | BW9: 品目ＣＤ | BZ9: 品目マスタ（共通） | CA9: 品目ＣＤ
C10: T | D10: 品目工程マスタ | K10: 枝番１ | V10: T | W10: 品目マスタ | AF10: 枝番１ | AQ10: 工程CDに対応する品目枝番１ | BV10: 品目マスタ（共通） | BW10: 枝番１ | BZ10: 品目マスタ（共通） | CA10: 枝番１
C11: T | D11: 品目工程マスタ | K11: 枝番２ | V11: T | W11: 品目マスタ | AF11: 枝番２ | AQ11: 工程CDに対応する品目枝番２ | BV11: 品目マスタ（共通） | BW11: 枝番２ | BZ11: 品目マスタ（共通） | CA11: 枝番２
C12: T | D12: 品目工程マスタ | K12: 枝番３ | V12: T | W12: 品目マスタ | AF12: 枝番３ | AQ12: 工程CDに対応する品目枝番３ | BV12: 品目マスタ（共通） | BW12: 枝番３ | BZ12: 品目マスタ（共通） | CA12: 枝番３
C13: T | D13: 品目工程マスタ | K13: 場所ＣＤ | V13: 画 | W13: 製品加工工程マスタ | AF13: 号機/発注 | AQ13: ワーキンググループごと、工程毎の号機 | BV13: 製品加工工程マスタ | BW13: 号機 | BZ13: 製品加工工程マスタ | CA13: 号機
C14: T | D14: 品目工程マスタ | K14: 工程パタン | AQ14: 固定:1 | BW14: 固定:1 | CA14: 固定:1
C15: T | D15: 品目工程マスタ | K15: 工程ＣＤ | V15: 画 | W15: 製品加工工程マスタ | AF15: 作業順CD | BV15: 製品加工工程マスタ | BW15: 作業工程CD | BZ15: 製品加工工程マスタ | CA15: 作業工程CD
C16: T | D16: 品目工程マスタ | K16: 工程連番 | AQ16: 固定:1 | BW16: 固定:1 | CA16: 固定:1
C17: T | D17: 品目工程マスタ | K17: 適用開始日 | AQ17: 処理日付 | BW17: 処理日付 | CA17: 処理日付
C18: T | D18: 品目工程マスタ | K18: 会社ＣＤ | AQ18: 固定：会社CD | BW18: 固定：会社CD | CA18: 固定：会社CD
C19: T | D19: 品目工程マスタ | K19: 適用終了日 | AQ19: 固定：2099/12/31 | BW19: 固定：2099/12/31 | CA19: 固定：2099/12/31
C20: T | D20: 品目工程マスタ | K20: 工順 | V20: 画 | W20: 製品加工工程マスタ | AF20: 作業順 | BV20: 製品加工工程マスタ | BW20: 作業順 | BZ20: 製品加工工程マスタ | CA20: 作業順
C21: T | D21: 品目工程マスタ | K21: 工程ＬＴ | AQ21: 固定:0 | BW21: 固定:0 | CA21: 固定:0
C22: T | D22: 品目工程マスタ | K22: 工程ＬＴ加算基準数量 | AQ22: 固定：NULL | BW22: 固定：NULL | CA22: 固定：NULL
C23: T | D23: 品目工程マスタ | K23: 工程オフセット区分 | AQ23: 1：着手日起算 2：完了日起算 1：着手日起算 | BW23: 1：着手日起算 2：完了日起算 1：着手日起算 | CA23: 1：着手日起算 2：完了日起算 1：着手日起算
C24: T | D24: 品目工程マスタ | K24: 工程オフセット | AQ24: 固定：0 | BW24: 固定：0 | CA24: 固定：0
C25: T | D25: 品目工程マスタ | K25: 工程オフセット加算基準数量 | AQ25: 固定：NULL | BW25: 固定：NULL | CA25: 固定：NULL
C26: T | D26: 品目工程マスタ | K26: 工程管理単位ＣＤ | AQ26: 固定：NULL | BW26: 固定：NULL | CA26: 固定：NULL
C27: T | D27: 品目工程マスタ | K27: 工程基準単位数量 | AQ27: 固定：NULL | BW27: 固定：NULL | CA27: 固定：NULL
C28: T | D28: 品目工程マスタ | K28: 工程換算単位数量 | AQ28: 固定：NULL | BW28: 固定：NULL | CA28: 固定：NULL
C29: T | D29: 品目工程マスタ | K29: 小数部有効桁数 | AQ29: 固定：0 | BW29: 固定：0 | CA29: 固定：0
C30: T | D30: 品目工程マスタ | K30: 換算端数処理区分 | AQ30: 1：切り上げ 2：切り捨て 3：四捨五入 固定：NULL | BW30: 1：切り上げ 2：切り捨て 3：四捨五入 固定：NULL | CA30: 1：切り上げ 2：切り捨て 3：四捨五入 固定：NULL
C31: T | D31: 品目工程マスタ | K31: 出来高計上工程ＦＬＧ | AQ31: 最終作業順：1 出来高工程 それ以外:0 | BW31: 最終作業順：1 出来高工程 それ以外:0 | CA31: 最終作業順：1 出来高工程 それ以外:0
C32: T | D32: 品目工程マスタ | K32: 出来高工程比率 | AQ32: 出来高工程以外： 固定：NULL 出来高工程： 0 | BW32: 出来高工程以外： 固定：NULL 出来高工程： 0 | CA32: 出来高工程以外： 固定：NULL 出来高工程： 0
... C34: T | D34: 品目工程マスタ | K34: 工程場所ＣＤ | AQ34: 固定：NULL | BW34: 固定：NULL | CA34: 固定：NULL
C35: T | D35: 品目工程マスタ | K35: 期限起算日使用工程ＦＬＧ | AQ35: 0 | BW35: 0 | CA35: 0
C36: T | D36: 品目工程マスタ | K36: 工程下限収率 | AQ36: 固定：NULL | BW36: 固定：NULL | CA36: 固定：NULL
C37: T | D37: 品目工程マスタ | K37: 工程標準収率 | AQ37: 固定：NULL | BW37: 固定：NULL | CA37: 固定：NULL
C38: T | D38: 品目工程マスタ | K38: 工程上限収率 | AQ38: 固定：NULL | BW38: 固定：NULL | CA38: 固定：NULL
C39: T | D39: 品目工程マスタ | K39: 仕掛進捗率 | AQ39: 固定：NULL | BW39: 固定：NULL | CA39: 固定：NULL
C40: T | D40: 品目工程マスタ | K40: 手配ＮＯ１ | AQ40: 固定：NULL | BW40: 固定：NULL | CA40: 固定：NULL
C41: T | D41: 品目工程マスタ | K41: 手配ＮＯ２ | AQ41: 固定：NULL | BW41: 固定：NULL | CA41: 固定：NULL
C42: T | D42: 品目工程マスタ | K42: 手配ＮＯ３ | AQ42: 固定：NULL | BW42: 固定：NULL | CA42: 固定：NULL
...

Sheet 更新入出力仕様_品目格納先マスタ 
A1: =表紙!A54 -> Webシステム | K1: 文書名 | U1: モジュールID | Z1: =表紙!$AJ$63 -> MS | AE1: モジュール名 | AJ1: =表紙!$AX$63 -> 見積管理 | AS1: 文書番号 | AZ1: Version | BF1: Rev.
K2: =表紙!O64 -> アドオン設計書 | U2: ｻﾌﾞﾓｼﾞｭｰﾙID | Z2: =表紙!$AJ$64 -> MSBB | AE2: ｻﾌﾞﾓｼﾞｭｰﾙ名 | AJ2: =表紙!$AX$64 -> Webシステム | AS2: =表紙!$BL$64 -> M7-US-1140 | AZ2: =表紙!$BU$64 -> 7.0.2 | BF2: =表紙!$CB$64 -> 8
K3: =RIGHT(CELL("filename",$A$1),LEN(CELL("filename",$A$1))-FIND("]",CELL("filename",$A$1))) -> 更新入出力仕様_品目格納先マスタ | U3: 表題 | Z3: =表紙!$AJ$65 -> - | AE3: =表紙!$AQ$65 -> 製品マスタ連携
A5: No | G5: 1 | H5: 品目格納先マスタ_製品 | S5: ロジック名称 | AH5: 備考 | BP5: 品目区分別設定値 | CQ5: REV4.0 商品を概要と合わせる
A6: 処理分類 | E6: 登録 | BP6: 商品 | BV6: 製品 | CB6: 中間品 | CH6: 資材 | CJ6: 資材 | CL6: 原料 | CN6: その他
A7: No | C7: 転送先 | V7: 転送元 | AQ7: 説明 | BP7: 構成あり | BR7: 構成なし | BT7: 版型 | BV7: 内 | BX7: 外 | BZ7: 購買 | CB7: 内 | CD7: 外 | CF7: 購買 | CH7: 在庫管理品（カートン等） | CJ7: 非在庫品 | CL7: 購買 | CN7: 購買
C8: 種 | D8: オブジェクト | K8: 項目名 | V8: 種 | W8: オブジェクト | AF8: 項目名 | BP8: オブジェクト | BQ8: 項目名 | BR8: オブジェクト | BS8: 項目名 | BT8: オブジェクト | BU8: 項目名 | BV8: オブジェクト | BW8: 項目名 | BX8: オブジェクト | BY8: 項目名 | BZ8: オブジェクト | CA8: 項目名 | CB8: オブジェクト | CC8: 項目名 | CD8: オブジェクト | CE8: 項目名 | CF8: オブジェクト | CG8: 項目名 | CH8: オブジェクト | CI8: 項目名 | CJ8: オブジェクト | CK8: 項目名 | CL8: オブジェクト | CM8: 項目名 | CN8: オブジェクト | CO8: 項目名
C9: T | D9: 品目格納先マスタ | K9: 品目ＣＤ | V9: T | W9: 品目マスタ | AF9: 品目CD | BV9: 品目マスタ（共通） | BW9: 品目ＣＤ | BX9: 品目マスタ（共通） | BY9: 品目ＣＤ | CB9: 品目マスタ（共通） | CC9: 品目ＣＤ | CD9: 品目マスタ（共通） | CE9: 品目ＣＤ | CF9: 品目マスタ（共通） | CG9: 品目ＣＤ | CH9: 品目マスタ（共通） | CI9: 品目ＣＤ
C10: T | D10: 品目格納先マスタ | K10: 枝番１ | V10: T | W10: 品目マスタ | AF10: 枝番１ | BV10: 品目マスタ（共通） | BW10: 枝番１ | BX10: 品目マスタ（共通） | BY10: 枝番１ | CB10: 品目マスタ（共通） | CC10: 枝番１ | CD10: 品目マスタ（共通） | CE10: 枝番１ | CF10: 品目マスタ（共通） | CG10: 枝番１ | CH10: 品目マスタ（共通） | CI10: 枝番１
C11: T | D11: 品目格納先マスタ | K11: 枝番２ | V11: T | W11: 品目マスタ | AF11: 枝番２ | BV11: 品目マスタ（共通） | BW11: 枝番２ | BX11: 品目マスタ（共通） | BY11: 枝番２ | CB11: 品目マスタ（共通） | CC11: 枝番２ | CD11: 品目マスタ（共通） | CE11: 枝番２ | CF11: 品目マスタ（共通） | CG11: 枝番２ | CH11: 品目マスタ（共通） | CI11: 枝番２
C12: T | D12: 品目格納先マスタ | K12: 枝番３ | V12: T | W12: 品目マスタ | AF12: 枝番３ | BV12: 品目マスタ（共通） | BW12: 枝番３ | BX12: 品目マスタ（共通） | BY12: 枝番３ | CB12: 品目マスタ（共通） | CC12: 枝番３ | CD12: 品目マスタ（共通） | CE12: 枝番３ | CF12: 品目マスタ（共通） | CG12: 枝番３ | CH12: 品目マスタ（共通） | CI12: 枝番３
C13: T | D13: 品目格納先マスタ | K13: 格納場所ＣＤ | BV13: 製品加工工程マスタ | BW13: 入庫先 | BX13: 製品加工工程マスタ | BY13: 入庫先 | CB13: 製品加工工程マスタ | CC13: 入庫先 | CD13: 製品加工工程マスタ | CE13: 入庫先 | CF13: 製品加工工程マスタ | CG13: 入庫先 | CH13: 製品加工工程マスタ | CI13: 入庫先
C14: T | D14: 品目格納先マスタ | K14: 会社ＣＤ | AQ14: 会社 | BW14: 定数.会社 | BY14: 定数.会社 | CC14: 定数.会社 | CE14: 定数.会社 | CG14: 定数.会社 | CI14: 定数.会社
C15: T | D15: 品目格納先マスタ | K15: 優先順 | BW15: 固定:1 | BY15: 固定:1 | CC15: 固定:1 | CE15: 固定:1 | CG15: 固定:1 | CI15: 固定:1
C16: T | D16: 品目格納先マスタ | K16: メモ１ | BW16: NULL | BY16: NULL | CC16: NULL | CE16: NULL | CG16: NULL | CI16: NULL
C17: T | D17: 品目格納先マスタ | K17: メモ２ | BW17: NULL | BY17: NULL | CC17: NULL | CE17: NULL | CG17: NULL | CI17: NULL
C18: T | D18: 品目格納先マスタ | K18: メモ３ | BW18: NULL | BY18: NULL | CC18: NULL | CE18: NULL | CG18: NULL | CI18: NULL
C19: T | D19: 品目格納先マスタ | K19: 論理削除ＦＬＧ | AQ19: 0 | BW19: 0 | BY19: 0 | CC19: 0 | CE19: 0 | CG19: 0 | CI19: 0
C20: T | D20: 品目格納先マスタ | K20: 論理削除ユーザＩＤ | AQ20: NULL | BW20: NULL | BY20: NULL | CC20: NULL | CE20: NULL | CG20: NULL | CI20: NULL
C21: T | D21: 品目格納先マスタ | K21: 論理削除ユーザ名 | AQ21: NULL | BW21: NULL | BY21: NULL | CC21: NULL | CE21: NULL | CG21: NULL | CI21: NULL
C22: T | D22: 品目格納先マスタ | K22: 論理削除日時 | AQ22: NULL | BW22: NULL | BY22: NULL | CC22: NULL | CE22: NULL | CG22: NULL | CI22: NULL
C23: T | D23: 品目格納先マスタ | K23: 登録ユーザＩＤ | AQ23: 登録ユーザー | BW23: 登録ユーザー | BY23: 登録ユーザー | CC23: 登録ユーザー | CE23: 登録ユーザー | CG23: 登録ユーザー | CI23: 登録ユーザー
C24: T | D24: 品目格納先マスタ | K24: 登録ユーザ名 | AQ24: 登録ユーザー名 | BW24: 登録ユーザー名 | BY24: 登録ユーザー名 | CC24: 登録ユーザー名 | CE24: 登録ユーザー名 | CG24: 登録ユーザー名 | CI24: 登録ユーザー名
C25: T | D25: 品目格納先マスタ | K25: 登録日時 | AQ25: 処理日時 | BW25: 処理日時 | BY25: 処理日時 | CC25: 処理日時 | CE25: 処理日時 | CG25: 処理日時 | CI25: 処理日時
C26: T | D26: 品目格納先マスタ | K26: 登録機能ＩＤ
C27: T | D27: 品目格納先マスタ | K27: 更新カウンタ | AQ27: 0 | BW27: 0 | BY27: 0 | CC27: 0 | CE27: 0 | CG27: 0 | CI27: 0
C28: T | D28: 品目格納先マスタ | K28: 更新ユーザＩＤ | AQ28: 登録ユーザー | BW28: 登録ユーザー | BY28: 登録ユーザー | CC28: 登録ユーザー | CE28: 登録ユーザー | CG28: 登録ユーザー | CI28: 登録ユーザー
C29: T | D29: 品目格納先マスタ | K29: 更新ユーザ名 | AQ29: 登録ユーザー名 | BW29: 登録ユーザー名 | BY29: 登録ユーザー名 | CC29: 登録ユーザー名 | CE29: 登録ユーザー名 | CG29: 登録ユーザー名 | CI29: 登録ユーザー名
C30: T | D30: 品目格納先マスタ | K30: 更新日時 | AQ30: 処理日時 | BW30: 処理日時 | BY30: 処理日時 | CC30: 処理日時 | CE30: 処理日時 | CG30: 処理日時 | CI30: 処理日時
C31: T | D31: 品目格納先マスタ | K31: 更新機能ＩＤ
C32: T | D32: 品目格納先マスタ | K32: 更新リクエストＮＯ
BP34: 品目格納先は同一物流グループ内の場合に作成する。 | BR34: 品目格納先は同一物流グループ内の場合に作成する。 | BT34: 品目格納先は同一物流グループ内の場合に作成する。

Sheet 更新入出力仕様_得意先販売単価マスタ 
A1: =表紙!A54 -> Webシステム | K1: 文書名 | U1: モジュールID | Z1: =表紙!$AJ$63 -> MS | AE1: モジュール名 | AJ1: =表紙!$AX$63 -> 見積管理 | AS1: 文書番号 | AZ1: Version | BF1: Rev.
K2: =表紙!O64 -> アドオン設計書 | U2: ｻﾌﾞﾓｼﾞｭｰﾙID | Z2: =表紙!$AJ$64 -> MSBB | AE2: ｻﾌﾞﾓｼﾞｭｰﾙ名 | AJ2: =表紙!$AX$64 -> Webシステム | AS2: =表紙!$BL$64 -> M7-US-1140 | AZ2: =表紙!$BU$64 -> 7.0.2 | BF2: =表紙!$CB$64 -> 8
K3: =RIGHT(CELL("filename",$A$1),LEN(CELL("filename",$A$1))-FIND("]",CELL("filename",$A$1))) -> 更新入出力仕様_得意先販売単価マスタ | U3: 表題 | Z3: =表紙!$AJ$65 -> - | AE3: =表紙!$AQ$65 -> 製品マスタ連携
A5: No | G5: 1 | H5: 客先販売単価マスタ_製品 | S5: ロジック名称 | AH5: 備考 | BP5: 品目区分別設定値 | CM5: REV4.0 商品を概要と合わせる
A6: 処理分類 | E6: 登録 | BP6: 商品 | BV6: 製品 | BZ6: 中間品 | CD6: 資材 | CF6: 資材 | CH6: 原料 | CJ6: その他
A7: No | C7: 転送先 | V7: 転送元 | AQ7: 説明 | BP7: 構成あり | BR7: 構成なし | BT7: 版型 | BV7: 内 | BX7: 外 | BZ7: 内 | CB7: 外 | CD7: 在庫管理品（カートン等） | CF7: 非在庫品 | CH7: 購買 | CJ7: 購買
C8: 種 | D8: オブジェクト | K8: 項目名 | V8: 種 | W8: オブジェクト | AF8: 項目名 | BP8: オブジェクト | BQ8: 項目名 | BR8: オブジェクト | BS8: 項目名 | BT8: オブジェクト | BU8: 項目名 | BV8: オブジェクト | BW8: 項目名 | BX8: オブジェクト | BY8: 項目名 | BZ8: オブジェクト | CA8: 項目名 | CB8: オブジェクト | CC8: 項目名 | CD8: オブジェクト | CE8: 項目名 | CF8: オブジェクト | CG8: 項目名 | CH8: オブジェクト | CI8: 項目名 | CJ8: オブジェクト | CK8: 項目名
C9: T | D9: 客先販売単価マスタ | K9: 得意先ＣＤ | V9: 画 | W9: 製品ロット別単価マスタ | AF9: 得意先CD | BV9: 製品ロット別単価マスタ | BW9: 得意先CD
C10: T | D10: 客先販売単価マスタ | K10: 納品先ＣＤ | AQ10: NULL | BW10: NULL
C11: T | D11: 客先販売単価マスタ | K11: 仕向先ＣＤ１ | AQ11: NULL | BW11: NULL
C12: T | D12: 客先販売単価マスタ | K12: 仕向先ＣＤ２ | AQ12: NULL | BW12: NULL
C13: T | D13: 客先販売単価マスタ | K13: 仕向先ＣＤ３ | AQ13: NULL | BW13: NULL
C14: T | D14: 客先販売単価マスタ | K14: 販売単価分類ＣＤ | AQ14: NULL | BW14: NULL
C15: T | D15: 客先販売単価マスタ | K15: 品目ＣＤ | V15: T | W15: 品目マスタ | AF15: 品目CD | BV15: 品目マスタ（共通） | BW15: 品目ＣＤ
C16: T | D16: 客先販売単価マスタ | K16: 枝番１ | V16: T | W16: 品目マスタ | AF16: 枝番１ | BV16: 品目マスタ（共通） | BW16: 枝番１
C17: T | D17: 客先販売単価マスタ | K17: 枝番２ | V17: T | W17: 品目マスタ | AF17: 枝番２ | BV17: 品目マスタ（共通） | BW17: 枝番２
C18: T | D18: 客先販売単価マスタ | K18: 枝番３ | V18: T | W18: 品目マスタ | AF18: 枝番３ | BV18: 品目マスタ（共通） | BW18: 枝番３
C19: T | D19: 客先販売単価マスタ | K19: 単位ＣＤ | V19: T | W19: 品目マスタ | AF19: 単位CD | BV19: 品目マスタ（共通） | BW19: 単位CD
C20: T | D20: 客先販売単価マスタ | K20: ロット数量 | V20: 画 | W20: 製品ロット別単価マスタ | AF20: ロット | BV20: 製品ロット別単価マスタ | BW20: ロット別数量
C21: T | D21: 客先販売単価マスタ | K21: 通貨ＣＤ | AQ21: JPY | BW21: JPY
C22: T | D22: 客先販売単価マスタ | K22: ワーキンググループＣＤ | AQ22: 最終工程のWGを設定する | BV22: 製品ロット別単価マスタ | BW22: WG
C23: T | D23: 客先販売単価マスタ | K23: 適用開始日 | V23: 画 | W23: 製品ロット別単価マスタ | AF23: 適用開始日 | BV23: 製品ロット別単価マスタ | BW23: 適用日
C24: T | D24: 客先販売単価マスタ | K24: 会社ＣＤ | AQ24: 会社CD | BW24: 会社CD
C25: T | D25: 客先販売単価マスタ | K25: 適用終了日 | V25: 画 | W25: 製品ロット別単価マスタ | AF25: 適用終了日 | BW25: 73050
C26: T | D26: 客先販売単価マスタ | K26: 単価 | V26: 画 | W26: 製品ロット別単価マスタ | AF26: 単価 | BV26: 製品ロット別単価マスタ | BW26: ロット別単価
C27: T | D27: 客先販売単価マスタ | K27: 改定前単価 | AQ27: NULL | BW27: NULL
C28: T | D28: 客先販売単価マスタ | K28: 仮単価ＦＬＧ | BW28: 本単価
C29: T | D29: 客先販売単価マスタ | K29: 掛率（％） | AQ29: NULL | BV29: 製品ロット別単価マスタ | BW29: NULL
C30: T | D30: 客先販売単価マスタ | K30: 改定前掛率（％） | AQ30: NULL | BW30: NULL
C31: T | D31: 客先販売単価マスタ | K31: 予備単価１ | AQ31: NULL | BW31: NULL
C32: T | D32: 客先販売単価マスタ | K32: 予備単価２ | AQ32: NULL | BW32: NULL
C33: T | D33: 客先販売単価マスタ | K33: 予備単価３ | AQ33: NULL | BW33: NULL
C34: T | D34: 客先販売単価マスタ | K34: 原価対象外ＦＬＧ | AQ34: 1 | BW34: 1
C35: T | D35: 客先販売単価マスタ | K35: メモ１
C36: T | D36: 客先販売単価マスタ | K36: メモ２
C37: T | D37: 客先販売単価マスタ | K37: メモ３
C38: T | D38: 客先販売単価マスタ | K38: 論理削除ＦＬＧ | AQ38: 0 | BW38: 0
C39: T | D39: 客先販売単価マスタ | K39: 論理削除ユーザＩＤ | AQ39: NULL | BW39: NULL
C40: T | D40: 客先販売単価マスタ | K40: 論理削除ユーザ名 | AQ40: NULL | BW40: NULL
C41: T | D41: 客先販売単価マスタ | K41: 論理削除日時 | AQ41: NULL | BW41: NULL
...

Sheet 更新入出力仕様_（アドオン）本支店単価マスタ 
A1: =表紙!A54 -> Webシステム | K1: 文書名 | U1: モジュールID | Z1: =表紙!$AJ$63 -> MS | AE1: モジュール名 | AJ1: =表紙!$AX$63 -> 見積管理 | AS1: 文書番号 | AZ1: Version | BF1: Rev.
K2: =表紙!O64 -> アドオン設計書 | U2: ｻﾌﾞﾓｼﾞｭｰﾙID | Z2: =表紙!$AJ$64 -> MSBB | AE2: ｻﾌﾞﾓｼﾞｭｰﾙ名 | AJ2: =表紙!$AX$64 -> Webシステム | AS2: =表紙!$BL$64 -> M7-US-1140 | AZ2: =表紙!$BU$64 -> 7.0.2 | BF2: =表紙!$CB$64 -> 8
K3: =RIGHT(CELL("filename",$A$1),LEN(CELL("filename",$A$1))-FIND("]",CELL("filename",$A$1))) -> 更新入出力仕様_（アドオン）本支店単価マスタ | U3: 表題 | Z3: =表紙!$AJ$65 -> - | AE3: =表紙!$AQ$65 -> 製品マスタ連携
A5: No | G5: 1 | H5: （アドオン）本支店単価マスタ | S5: ロジック名称 | AH5: 備考 | BP5: 品目区分別設定値 | CM5: REV4.0 商品を概要と合わせる
A6: 処理分類 | E6: 登録 | BP6: 商品 | BV6: 製品 | BZ6: 中間品 | CD6: 資材 | CF6: 資材 | CH6: 原料 | CJ6: その他 | CM6: REV6.0 本支店単価マスタの連携廃止 | DA6: REV8.0 本支店単価マスタの復活
A7: No | C7: 転送先 | V7: 転送元 | AQ7: 説明 | BP7: 構成あり | BR7: 構成なし | BT7: 版型 | BV7: 内 | BX7: 外 | BZ7: 内 | CB7: 外 | CD7: 在庫管理品（カートン等） | CF7: 非在庫品 | CH7: 購買 | CJ7: 購買
C8: 種 | D8: オブジェクト | K8: 項目名 | V8: 種 | W8: オブジェクト | AF8: 項目名 | BP8: オブジェクト | BQ8: 項目名 | BR8: オブジェクト | BS8: 項目名 | BT8: オブジェクト | BU8: 項目名 | BV8: オブジェクト | BW8: 項目名 | BX8: オブジェクト | BY8: 項目名 | BZ8: オブジェクト | CA8: 項目名 | CB8: オブジェクト | CC8: 項目名 | CD8: オブジェクト | CE8: 項目名 | CF8: オブジェクト | CG8: 項目名 | CH8: オブジェクト | CI8: 項目名 | CJ8: オブジェクト | CK8: 項目名
C9: T | D9: （アドオン）本支店単価マスタ | K9: 得意先ＣＤ | V9: 画 | W9: 製品基本マスタ | AF9: 得意先CD | BV9: 製品ロット別単価マスタ | BW9: 得意先CD
C10: T | D10: （アドオン）本支店単価マスタ | K10: 品目ＣＤ | V10: T | W10: 品目マスタ | AF10: 品目CD | BV10: 品目マスタ（共通） | BW10: 品目ＣＤ
C11: T | D11: （アドオン）本支店単価マスタ | K11: 枝番１ | V11: T | W11: 品目マスタ | AF11: 枝番１ | BV11: 品目マスタ（共通） | BW11: 枝番１
C12: T | D12: （アドオン）本支店単価マスタ | K12: 枝番２ | V12: T | W12: 品目マスタ | AF12: 枝番２ | BV12: 品目マスタ（共通） | BW12: 枝番２
C13: T | D13: （アドオン）本支店単価マスタ | K13: 枝番３ | V13: T | W13: 品目マスタ | AF13: 枝番３ | BV13: 品目マスタ（共通） | BW13: 枝番３
C14: T | D14: （アドオン）本支店単価マスタ | K14: 単位ＣＤ | V14: T | W14: 品目マスタ | AF14: 単位CD | BV14: 品目マスタ（共通） | BW14: 単位CD
C15: T | D15: （アドオン）本支店単価マスタ | K15: ロット数量 | V15: 画 | W15: 製品基本マスタ | AF15: ロット | BV15: 製品ロット別単価マスタ | BW15: ロット別数量1~5
C16: T | D16: （アドオン）本支店単価マスタ | K16: 通貨ＣＤ | AQ16: JPY | BW16: JPY
C17: T | D17: （アドオン）本支店単価マスタ | K17: 適用開始日 | V17: 画 | W17: 製品基本マスタ | AF17: 適用開始日 | BW17: 処理日付
C18: T | D18: （アドオン）本支店単価マスタ | K18: 適用終了日 | V18: 画 | W18: 製品基本マスタ | AF18: 適用終了日 | BW18: 73050
C19: T | D19: （アドオン）本支店単価マスタ | K19: 単価 | V19: 画 | W19: 製品基本マスタ | AF19: 本支店単価 | BV19: 製品ロット別単価マスタ | BW19: 本支店単価１~５
C20: T | D20: （アドオン）本支店単価マスタ | K20: 仮単価ＦＬＧ | V20: 画 | W20: 製品基本マスタ | AF20: 仮単価 | BV20: 製品ロット別単価マスタ | BW20: 仮単価
C21: T | D21: （アドオン）本支店単価マスタ | K21: 原価対象外ＦＬＧ | AQ21: 1 | BW21: 1
C22: T | D22: （アドオン）本支店単価マスタ | K22: メモ１ | BW22: NULL
C23: T | D23: （アドオン）本支店単価マスタ | K23: メモ２ | BW23: NULL
C24: T | D24: （アドオン）本支店単価マスタ | K24: メモ３ | BW24: NULL
C25: T | D25: （アドオン）本支店単価マスタ | K25: 論理削除ＦＬＧ | AQ25: 0 | BW25: 0
C26: T | D26: （アドオン）本支店単価マスタ | K26: 論理削除ユーザＩＤ | AQ26: NULL | BW26: NULL
C27: T | D27: （アドオン）本支店単価マスタ | K27: 論理削除ユーザ名 | AQ27: NULL | BW27: NULL
C28: T | D28: （アドオン）本支店単価マスタ | K28: 論理削除日時 | AQ28: NULL | BW28: NULL
C29: T | D29: （アドオン）本支店単価マスタ | K29: 登録ユーザＩＤ | AQ29: 登録ユーザー | BW29: 登録ユーザー
C30: T | D30: （アドオン）本支店単価マスタ | K30: 登録ユーザ名 | AQ30: 登録ユーザー名 | BW30: 登録ユーザー名
C31: T | D31: （アドオン）本支店単価マスタ | K31: 登録日時 | AQ31: 処理日時 | BW31: 処理日時
C32: T | D32: （アドオン）本支店単価マスタ | K32: 登録機能ＩＤ
C33: T | D33: （アドオン）本支店単価マスタ | K33: 更新カウンタ | AQ33: 0 | BW33: 0
C34: T | D34: （アドオン）本支店単価マスタ | K34: 更新ユーザＩＤ | AQ34: 登録ユーザー | BW34: 登録ユーザー
C35: T | D35: （アドオン）本支店単価マスタ | K35: 更新ユーザ名 | AQ35: 登録ユーザー名 | BW35: 登録ユーザー名
C36: T | D36: （アドオン）本支店単価マスタ | K36: 更新日時 | AQ36: 処理日時 | BW36: 処理日時
C37: T | D37: （アドオン）本支店単価マスタ | K37: 更新機能ＩＤ
C38: T | D38: （アドオン）本支店単価マスタ | K38: 更新リクエストＮＯ
A39: No | G39: 2 | H39: （アドオン）本支店単価マスタ | S39: ロジック名称 | AH39: 備考 | BP39: 品目区分別設定値
A40: 処理分類 | E40: 更新 | BP40: 商品 | BV40: 製品 | BZ40: 中間品 | CD40: 資材 | CF40: 資材 | CH40: 原料 | CJ40: その他
A41: No | C41: 転送先 | V41: 転送元 | AQ41: 説明 | BP41: 構成あり | BR41: 構成なし | BT41: 版型 | BV41: 内 | BX41: 外 | BZ41: 内 | CB41: 外 | CD41: 在庫管理品（カートン等） | CF41: 非在庫品 | CH41: 購買 | CJ41: 購買
...

Sheet 更新入出力仕様_購買単価マスタ 
A1: =表紙!A54 -> Webシステム | K1: 文書名 | U1: モジュールID | Z1: =表紙!$AJ$63 -> MS | AE1: モジュール名 | AJ1: =表紙!$AX$63 -> 見積管理 | AS1: 文書番号 | AZ1: Version | BF1: Rev.
K2: =表紙!O64 -> アドオン設計書 | U2: ｻﾌﾞﾓｼﾞｭｰﾙID | Z2: =表紙!$AJ$64 -> MSBB | AE2: ｻﾌﾞﾓｼﾞｭｰﾙ名 | AJ2: =表紙!$AX$64 -> Webシステム | AS2: =表紙!$BL$64 -> M7-US-1140 | AZ2: =表紙!$BU$64 -> 7.0.2 | BF2: =表紙!$CB$64 -> 8
K3: =RIGHT(CELL("filename",$A$1),LEN(CELL("filename",$A$1))-FIND("]",CELL("filename",$A$1))) -> 更新入出力仕様_購買単価マスタ | U3: 表題 | Z3: =表紙!$AJ$65 -> - | AE3: =表紙!$AQ$65 -> 製品マスタ連携
A5: No | G5: 1 | H5: 購買単価マスタ_製品 | S5: ロジック名称 | AH5: 備考 | BR5: 品目区分別設定値 | CP5: REV4.0 商品を概要と合わせる
A6: 処理分類 | E6: 登録 | BR6: 商品 | BX6: 製品 | CB6: 中間品 | CH6: 資材 | CJ6: 資材 | CL6: 原料 | CN6: その他
A7: No | C7: 転送先 | V7: 転送元 | AQ7: 説明 | BR7: 構成あり | BT7: 構成なし | BV7: 版型 | BX7: 内 | BZ7: 外 | CB7: 内 | CD7: 外 | CF7: 購買 | CH7: 在庫管理品（カートン等） | CJ7: 非在庫品 | CL7: 購買 | CN7: 購買
C8: 種 | D8: オブジェクト | K8: 項目名 | V8: 種 | W8: オブジェクト | AF8: 項目名 | BR8: オブジェクト | BS8: 項目名 | BT8: オブジェクト | BU8: 項目名 | BV8: オブジェクト | BW8: 項目名 | BX8: オブジェクト | BY8: 項目名 | BZ8: オブジェクト | CA8: 項目名 | CB8: オブジェクト | CC8: 項目名 | CD8: オブジェクト | CE8: 項目名 | CF8: オブジェクト | CG8: 項目名 | CH8: オブジェクト | CI8: 項目名 | CJ8: オブジェクト | CK8: 項目名 | CL8: オブジェクト | CM8: 項目名 | CN8: オブジェクト | CO8: 項目名
C9: T | D9: 購買単価マスタ | K9: 品目ＣＤ | V9: T | W9: 品目マスタ | AF9: 品目CD | CF9: 品目マスタ（共通） | CG9: 品目ＣＤ | CH9: 品目マスタ（共通） | CI9: 品目ＣＤ
C10: T | D10: 購買単価マスタ | K10: 枝番１ | V10: T | W10: 品目マスタ | AF10: 枝番１ | CF10: 品目マスタ（共通） | CG10: 枝番１ | CH10: 品目マスタ（共通） | CI10: 枝番１
C11: T | D11: 購買単価マスタ | K11: 枝番２ | V11: T | W11: 品目マスタ | AF11: 枝番２ | CF11: 品目マスタ（共通） | CG11: 枝番２ | CH11: 品目マスタ（共通） | CI11: 枝番２
C12: T | D12: 購買単価マスタ | K12: 枝番３ | V12: T | W12: 品目マスタ | AF12: 枝番３ | CF12: 品目マスタ（共通） | CG12: 枝番３ | CH12: 品目マスタ（共通） | CI12: 枝番３
C13: T | D13: 購買単価マスタ | K13: 発注先ＣＤ | V13: 画 | W13: 製品ロット別単価マスタ | AF13: 購買品の発注先 | CF13: 製品加工工程マスタ | CG13: 発注先 | CH13: 製品加工工程マスタ | CI13: 発注先
C14: T | D14: 購買単価マスタ | K14: メーカＣＤ | AQ14: NULL | CG14: NULL | CI14: NULL
C15: T | D15: 購買単価マスタ | K15: 単位ＣＤ | V15: 画 | W15: 製品ロット別単価マスタ | AF15: 単価単位 | CF15: 品目マスタ（共通） | CG15: 単位CD | CH15: 品目マスタ（共通） | CI15: 単位CD
C16: T | D16: 購買単価マスタ | K16: ロット数量 | V16: 画 | W16: 製品ロット別単価マスタ | AF16: ロット | CG16: 1 | CI16: 1
C17: T | D17: 購買単価マスタ | K17: 通貨ＣＤ | AQ17: JPY | CG17: JPY | CI17: JPY
C18: T | D18: 購買単価マスタ | K18: 納入場所ＣＤ | AQ18: NULL | CG18: NULL | CI18: NULL
C19: T | D19: 購買単価マスタ | K19: 納品先ＣＤ | AQ19: NULL | CG19: NULL | CI19: NULL
C20: T | D20: 購買単価マスタ | K20: ワーキンググループＣＤ | AQ20: NULL | CG20: NULL | CI20: NULL
C21: T | D21: 購買単価マスタ | K21: 適用開始日 | V21: 画 | W21: 製品ロット別単価マスタ | AF21: 適用開始日 | CG21: 単価適用日
