Workbook
Name Rev.: 表紙!$U$22
Name Ver.: 表紙!$AE$26
Name ご確認者: 表紙!$AG$40
Name ご確認日: 表紙!$AG$42
Name サブシステム名: 表紙!$U$28
Name システム名: 表紙!$U$26
Name プロジェクト名: 表紙!$U$18
Name 開発区分: 表紙!$U$36
Name 機能ＩＤ: 表紙!$U$32
Name 機能区分: 表紙!$U$34
Name 機能名称: 表紙!$U$30
Name 顧客名: 表紙!$U$16
Name 最終更新者: 表紙!$AB$40
Name 最終更新日: 表紙!$AB$42
Name 作成者: 表紙!$W$40
Name 作成日: 表紙!$W$42
Name 章: 表紙!$M$10
Name 文書名: 表紙!$M$10

Sheet 目次
A1: アドオン設計書作成ガイド
C3: ■アドオン設計と成果物について
D4: ・システム設計フェーズとソフトウェア設計フェーズでアドオンの処理仕様を定義する
D5: ・システム設計フェーズとソフトウェア設計フェーズの成果物がアドオン設計書であり、ソフトウェア製作フェーズのインプットとなる
C7: ■各設計フェーズ毎のアドオン設計書作成範囲
D8: ・システム設計フェーズ：他機能との関連を定義するとともに、画面や帳票、ファイル入出力を中心とした外部入出力の設計を行う
D9: ・ソフトウェア設計フェーズ：内部処理を中心とした設計を行う
U11: ◎ | W11: … | X11: システム設計フェーズで作成
U12: ○ | W12: … | X12: システム設計フェーズで基本仕様を定義して、ソフトウェア設計フェーズで詳細化する
U13: △ | W13: … | X13: 必要に応じて（例えば標準仕様から変更がない場合は不要）
U14: ‐ | W14: … | X14: 不要
W15: … | X15: ソフトウェア設計フェーズで作成
D17: 各設計書と作成対象シートのマトリックス | S17: ※カスタマイズ：標準機能に機能を追加する アドオン：新規で機能を開発する
D18: EXCELシート | N18: 画面設計書 | W18: バッチ設計書 | AF18: 帳票設計書 | AO18: ＢＩ設計書 | AT18: .Net設計書 | BB18: EXCELシート | BL18: WebDB設計書 | BR18: 帳票設計書 | BX18: 汎用申請設計書
N19: カスタマイズ | S19: アドオン | W19: カスタマイズ | AB19: アドオン | AF19: カスタマイズ | AK19: アドオン | AO19: アドオン | AT19: アドオン | BL19: アドオン | BR19: アドオン | BX19: アドオン
D20: 概要 | N20: ◎ | O20: ※1 | S20: ◎ | W20: ◎ | X20: ※1 | AB20: ◎ | AF20: ◎ | AG20: ※1 | AK20: ◎ | AO20: ◎ | AT20: ◎ | BB20: 機能概要 | BL20: ◎ | BR20: ◎ | BX20: ◎
D21: レイアウト | N21: ◎ | O21: ※2 | S21: ◎ | W21: ‐ | AB21: ‐ | AF21: ◎ | AG21: ※2 | AK21: ◎ | AO21: ◎ | AT21: ◎ | BB21: アプリケーションフロー | BL21: ◎ | BR21: ー | BX21: ◎
D22: 項目説明 | N22: △ | S22: ○ | W22: ‐ | AB22: ‐ | AF22: △ | AK22: ○ | AO22: ○ | AT22: ○ | BB22: データベース設定 | BL22: ◎ | BR22: ー | BX22: ◎
D23: 引数説明 | N23: ‐ | S23: ‐ | W23: △ | AB23: ◎ | AF23: ‐ | AK23: ‐ | AO23: ‐ | AT23: ◎ | BB23: フィールド設定 | BL23: ◎ | BR23: ー | BX23: ◎
D24: 処理概要 | N24: ◎ | S24: ◎ | W24: ◎ | AB24: ◎ | AF24: ◎ | AK24: ◎ | AO24: ◎ | AT24: ◎ | BB24: 一覧表示画面設定 | BL24: ◎ | BR24: ー | BX24: ◎
D25: 処理詳細 | BB25: 表示編集画面設定 | BL25: ◎ | BR25: ー | BX25: ◎
D26: 処理・サービス関連図 | N26: △ | S26: ◎ | W26: △ | AB26: ◎ | AF26: ‐ | AK26: ‐ | AO26: ‐ | AT26: ◎ | BB26: 明細画面設定 | BL26: △ | BN26: ※3 | BR26: ー | BX26: △ | BZ26: ※3
D27: 検索入出力仕様 | N27: △ | S27: ○ | W27: △ | AB27: ○ | AF27: ‐ | AK27: ‐ | AO27: ‐ | AT27: ○ | BB27: 集計表示設定 | BL27: △ | BN27: ※4 | BR27: ー | BX27: △ | BZ27: ※4
D28: 更新入出力仕様 | N28: △ | S28: ○ | W28: △ | AB28: ○ | AF28: ‐ | AK28: ‐ | AO28: ‐ | AT28: ○ | BB28: 絞り込み条件設定 | BL28: △ | BN28: ※5 | BR28: ー | BX28: △ | BZ28: ※5
D29: ファイル入出力仕様 | N29: △ | S29: △ | W29: ‐ | AB29: ‐ | AF29: ‐ | AK29: ‐ | AO29: ‐ | AT29: △ | BB29: その他設定 | BR29: ー
D30: 画面遷移 | N30: △ | S30: ◎ | W30: ‐ | AB30: ‐ | AF30: ‐ | AK30: ‐ | AO30: ‐ | AT30: ◎ | BB30: 帳票イメージ | BL30: ー | BR30: ◎ | BX30: ー
D31: メッセージ一覧 | N31: △ | S31: △ | W31: △ | AB31: △ | AF31: ‐ | AK31: ‐ | AO31: ‐ | AT31: △ | BB31: 項目設計 | BL31: ー | BR31: ◎ | BX31: ー
D32: 補足説明 | N32: △ | S32: △ | W32: △ | AB32: △ | AF32: △ | AK32: △ | AO32: △ | AT32: △ | BB32: 補足説明 | BL32: △ | BR32: △ | BX32: △
D33: サービス呼出編集仕様 | N33: - | S33: - | W33: - | AB33: - | AF33: - | AK33: - | AO33: - | AT33: - | BB33: 補足説明(詳細)
D35: ※1 | G35: 別シートでカスタマイズ内容を記載する | BB35: ※3 | BE35: 単票画面は記載しない
D36: ※2 | G36: 吹き出しでカスタマイズ内容を記載する | BB36: ※4 | BE36: 集計・グラフ機能を使用する場合に記載する
BB37: ※5 | BE37: 共通設定のみ記載する(個別設定は、記載しない)

Sheet 表紙
AW2: サブモジュール
AW3: MA_マスタ管理
AW4: MB_業務共通
AW5: MG_原価管理
AW6: MSBA_需給管理
M7: 基本設計 | AW7: MSBB_販売管理
AW8: MSBC_生産管理
AW9: MSBD_購買管理
M10: アドオン設計書 | AW10: MSBE_在庫物流管理
AW11: MSBF_品質管理
AW12: MSBG_債権管理
AW13: MSBH_債務管理
AW14: MSBI_締処理
AW15: MSUA_リスト・入力補助
M16: 顧客 | U16: 株式会社クラウン・パッケージ | AW16: PF_ESBアダプタ
M18: プロジェクト名 | U18: 基幹システム刷新PJ | AW18: 機能区分
AW19: 画面
M20: 文書番号 | AW20: 帳票
AW21: バッチ
M22: Ｒｅｖ． | U22: {=MAX(_xlfn.NUMBERVALUE(改訂!A7:E46))} -> 3 | AW22: マスタ
M24: 機密性区分 | U24: 取扱注意（Ｃ） | AW24: 開発区分
AW25: カスタマイズ
M26: システム名 | U26: POWER EGG | AC26: Ver. | AE26: 7.0.2 | AW26: アドオン
AW27: －
M28: サブモジュール | U28: MSBB_販売管理
M30: 機能名 | U30: =M50 -> POWER EGG
M32: 機能ID | U32: =G50 -> MSBBLA010
M34: 機能区分 | U34: 画面
M36: 開発区分 | U36: アドオン
W39: 作成 | AB39: 最終更新 | AG39: ご確認
W40: MDSOL | AB40: =改訂!AZ2 -> MDSOL
W42: 44824 | AB42: =改訂!BJ2 -> 45065
A48: 文書番号 | G48: 画面ID | M48: 画面名 | V48: Version | AB48: Revision
A50: M7-US-1140 | G50: MSBBLA010 | M50: POWER EGG | V50: 1.0.0 | AB50: =改訂!BP2 -> 3
A53: 共通（元データ）
A54: POWER EGG | K54: 文書名 | U54: モジュールID | Z54: MS | AE54: モジュール名 | AJ54: POWER EGG | AS54: 文書番号 | AZ54: Version | BF54: Rev.
K55: 画面説明書 | U55: ｻﾌﾞﾓｼﾞｭｰﾙID | Z55: MSBB | AE55: ｻﾌﾞﾓｼﾞｭｰﾙ名 | AJ55: POWER EGG | AS55: M7-US-1140 | AZ55: 1.0.0 | BF55: =改訂!BP2 -> 3
K56: 表紙 | U56: 表題 | Z56: - | AE56: POWER EGG
A57: 共通（リンク用）
A58: =A54 -> POWER EGG | K58: 文書名 | U58: モジュールID | Z58: =Z54 -> MS | AE58: モジュール名 | AJ58: =AJ54 -> POWER EGG | AS58: 文書番号 | AZ58: Version | BF58: Rev.
...

Sheet 改訂
A1: 第7章 | K1: 改訂 | AU1: 作成者 | AZ1: MDSOL | BE1: 作成日 | BJ1: =表紙!W42 -> 44824 | BP1: Rev.
AU2: 修正者 | AZ2: MDSOL | BE2: 改訂日 | BJ2: =MAX(BM7:BQ50) -> 45065 | BP2: {=MAX(_xlfn.NUMBERVALUE(A7:E50))} -> 3
A5: Rev. | F5: 改定内容 | BC5: 頁 | BM5: 変更日 変更者 | BR5: 確認日 確認者
A7: 1 | F7: 新規作成
A9: 2 | F9: 2022年12月22日（木）PE①決定内容の反映、画面イメージの追加 | BC9: 概要、アプリケーションフロー ③得意先・納品先メモ ⑩変更連絡依頼 | BM9: 44972
BM10: MDSOL
A11: 3 | F11: 詳細設計時の打合せ内容の反映 （2023年2月15日（水）PE②、2023年5月19日（金）PE③打合せ決定内容の反映） | BC11: 概要、アプリケーションフロー 集計表示設定 ⑥不適合品報告書 ②デザイン負荷:削除 ④納品先メモ:削除 | BM11: 45065 | BR11: 45076
BM12: MDSOL | BR12: MDSOL
F13: 詳細設計書の内容反映(一覧表示画面設定、表示編集画面設定、明細画面設定をサンプルから詳細設定にて打合せした内容に設定変更) | BC13: 一覧表示画面設定 表示編集画面設定 →各機能単位に明記 | BM13: 45065 | BR13: 45076
BM14: MDSOL | BR14: MDSOL

Sheet 概要
A1: =表紙!A54 -> POWER EGG | O1: 文書名 | AC1: モジュールID | AJ1: =表紙!$AJ$63 -> MS | AQ1: モジュール名 | AX1: =表紙!$AX$63 -> POWER EGG | BL1: 文書番号 | BU1: Version | CB1: Rev.
O2: =表紙!O64 -> アドオン設計書 | AC2: サブモジュールID | AJ2: =表紙!$AJ$64 -> MSBB | AQ2: サブモジュール名 | AX2: =表紙!$AX$64 -> POWER EGG | BL2: =表紙!$BL$64 -> M7-US-1140 | BU2: =表紙!$BU$64 -> 7.0.2 | CB2: =表紙!$CB$64 -> 3
O3: =RIGHT(CELL("filename",$A$1),LEN(CELL("filename",$A$1))-FIND("]",CELL("filename",$A$1))) -> 概要 | AC3: 表題 | AJ3: =表紙!$AJ$65 -> - | AQ3: =表紙!$AQ$65 -> POWER EGG
AO5: 概要
B7: 【業務要件】
C8: カスタマイズ | G8: 内容
C9: No.
G10: POWER EGGシステムを構築する(WEB DB、汎用申請機能を構築する)
C11: 121 | G11: 受注変更連絡書を出力する
C12: 122 | G12: POWER EGGの汎用申請での構築とする。版型発注書の出力は、PEからアドオン対応にて出力する。版型発注書(正/控え)と管理表を出力する。3枚印字（営業用、業務用、発注用）
B15: 【機能概要】
C16: WEBDB機能一覧 | AS16: ※CP開発分に関しては、サンプルとして提供する。CP引取り分は、仕様書記述の対象外とする。
C17: WEBDB名称 | Q17: 概要 | AO17: 備考 | BL17: MDSOL開発
C18: 目標管理・訪問計画 | Q18: 目標管理・訪問計画のWEBDB | AO18: CP様開発項目、目標管理 | BL18: サンプル提供
AO19: 目標管理・訪問計画入力を統合(データ区分で制御)
C20: 案件管理 | Q20: 案件管理のWEBDB | AO20: CP引取り(2022/5/30 PEセッション) | BL20: -
C21: 営業日報 | Q21: 営業日報のWEBDB | AO21: CP引取り(2022/5/30 PEセッション) | BL21: -
C22: 顧客情報/動向 | Q22: 顧客情報/動向のWEBDB | AO22: CP引取り(2022/5/30 PEセッション) | BL22: -
C23: デザイン実績登録 | Q23: デザイン実績登録のWEBDB | AO23: CP引取り(2022/5/30 PEセッション) | BL23: -
C24: デザイン負荷確認 | Q24: デザイン負荷確認のWEBDB | AO24: サンプル提示：2023/2/15 モーションボードで実現する | BL24: - | BS24: 2023/2/15 モーションボードで実現する | CJ24: REV3.0:デザイン負荷確認 モーションボードで実現するため不要
C25: 得意先・納入先メモ | Q25: 得意先・納入先メモのWEBDB | AO25: 2022/6/24 受注セッション追加 | BL25: ○ | BS25: 2023/2/15 モーションボードで実現を検討する | CJ25: REV2.0:2022/12/22 変更
C26: 納入先メモ | Q26: 納入先メモのWEBDB | AO26: 2022/6/24 受注セッション追加 | BL26: - | BS26: →課題：WEBシステムとの連携 | CJ26: 納品先メモは得意先メモの一部となる。分類情報に追加(得意先・納品先メモ)される。
C27: 版型発注書 | Q27: 版型発注書のWEBDB | AO27: 版型マスタよりAPI連携 | BL27: ○
C28: 不適合報告書 | Q28: 不適合報告書のWEBDB | AO28: 汎用申請→WEBDB機能を使用する ※定義は汎用申請 | BL28: ○
C30: 帳票一覧 | AO30: ※CP開発分に関しては、サンプルとして提供する。CP引取り分は、仕様書記述の対象外とする。
C31: 帳票名称 | Q31: 概要 | AO31: 備考
C32: 版型発注書 | Q32: POWER EGG帳票：版型発注書 | AO32: CP様開発項目 | BL32: サンプル提供
C34: 汎用申請(WF)一覧 | AO34: ※CP開発分に関しては、サンプルとして提供する。CP引取り分は、仕様書記述の対象外とする。
C35: WF名称 | Q35: 概要 | AO35: 備考
C36: サンプル依頼WF | Q36: サンプル依頼の汎用申請 | AO36: CP引取り(2022/4/21 PEセッション) | BL36: -
C37: 図面作成WF | Q37: 図面作成の汎用申請 | AO37: CP引取り(2022/4/21 PEセッション) | BL37: -
C38: 見積確認WF | Q38: 見積確認の汎用申請(御見積書・見積計算書の確認ワークフロー) | BL38: ○
C39: 入稿ミーティング開催依頼WF | Q39: 入稿ミーティング開催依頼の汎用申請 | AO39: CP引取り(2022/4/21 PEセッション) | BL39: -
C40: 製造テスト依頼WF | Q40: 製造テスト依頼の汎用申請 | AO40: CP引取り(2022/4/21 PEセッション) | BL40: -
C41: 得意先マスタWF | Q41: 得意先マスタの汎用申請 | BL41: ○
C42: 見積確定WF | Q42: 見積確定の汎用申請 | BL42: ○
Q43: ※FSC時、ルートを分岐する：FSCチェックシートを手動で添付する
C44: マスタ確定WF | Q44: マスタ確定の汎用申請 | AO44: 見積確定WFの一連WFとする | BL44: -
C45: 版型発注依頼WF | Q45: 版型発注依頼の汎用申請 | AO45: 見積確定WFの一連WFとする | BL45: -
C46: 変更連絡依頼WF | Q46: 変更連絡依頼の汎用申請 | BL46: ○
...

Sheet アプリケーションフロー
A1: =表紙!A54 -> POWER EGG | K1: 文書名 | U1: モジュールID | Z1: =表紙!$AJ$63 -> MS | AE1: モジュール名 | AJ1: =表紙!$AX$63 -> POWER EGG | AS1: 文書番号 | AZ1: Version | BF1: Rev.
K2: =表紙!O64 -> アドオン設計書 | U2: ｻﾌﾞﾓｼﾞｭｰﾙID | Z2: =表紙!$AJ$64 -> MSBB | AE2: ｻﾌﾞﾓｼﾞｭｰﾙ名 | AJ2: =表紙!$AX$64 -> POWER EGG | AS2: =表紙!$BL$64 -> M7-US-1140 | AZ2: =表紙!$BU$64 -> 7.0.2 | BF2: =表紙!$CB$64 -> 3
K3: =RIGHT(CELL("filename",$A$1),LEN(CELL("filename",$A$1))-FIND("]",CELL("filename",$A$1))) -> アプリケーションフロー | U3: 表題 | Z3: =表紙!$AJ$65 -> - | AE3: =表紙!$AQ$65 -> POWER EGG
B6: アプリケーションフロー名 | J6: 目標管理・訪問計画 | AH6: 備考
C8: POWER EGG画面遷移
B26: アプリケーションフロー名 | J26: デザイン負荷確認 | AH26: 備考 | BM26: REV3.0:モーションボードで実現するため、削除
C28: POWER EGG画面遷移
Y36: 集計設定 | AE36: 集計表示名 | AM36: 表示方法 | AU36: 使用区分
AE37: デザイン負荷集計 | AM37: 折れ線グラフ | AU37: 使用する
B46: アプリケーションフロー名 | J46: 得意先・納品先メモ | AH46: 備考 | BM46: REV2.0:2022/12/22 変更
BM47: 納品先メモは得意先メモの一部となる。分類情報に追加(得意先・納品先メモ)される。
C48: POWER EGG画面遷移
H58: 得意先・納品先メモを確認しつつ、WEB画面を登録する
B66: アプリケーションフロー名 | J66: 納品先メモ | AH66: 備考
C68: POWER EGG画面遷移
H78: 得意先メモを確認しつつ、WEB画面を登録する
B86: アプリケーションフロー名 | J86: 版型発注書 | AH86: 備考
C88: POWER EGG画面遷移
N96: ※再連携にて、基本上書きされるためPE上で更新を行わない
O98: API連携
B106: アプリケーションフロー名 | J106: 不適合報告書 | AH106: 備考
C108: POWER EGG画面遷移
D111: 汎用申請
AP113: 不適合報告書データを保存し、管理資料等に2次利用する
AP114: →CSV出力機能は、PE標準機能に有り
AP116: 承認後のデータは、メンテ可能
Y117: 申請データコピー
B126: データベース名 | J126: 見積確認 | AH126: 備考
C128: POWER EGG画面遷移
T131: 汎用申請
AK139: ステータス更新
P141: 御見積書
P142: 見積計算書を手動添付
B146: データベース名 | J146: 得意先マスタ | AH146: 備考
C148: POWER EGG画面遷移
T151: 汎用申請
BM153: ステータス更新ではなく、操作種別：事前登録、登録で分岐する
B166: データベース名 | J166: 見積確定 | AH166: 備考
C168: POWER EGG画面遷移
Q171: 汎用申請
...

Sheet DB設定(WEBDB)
A1: =表紙!A54 -> POWER EGG | K1: 文書名 | U1: モジュールID | Z1: =表紙!$AJ$63 -> MS | AE1: モジュール名 | AJ1: =表紙!$AX$63 -> POWER EGG | AS1: 文書番号 | AZ1: Version | BF1: Rev.
K2: =表紙!O64 -> アドオン設計書 | U2: ｻﾌﾞﾓｼﾞｭｰﾙID | Z2: =表紙!$AJ$64 -> MSBB | AE2: ｻﾌﾞﾓｼﾞｭｰﾙ名 | AJ2: =表紙!$AX$64 -> POWER EGG | AS2: =表紙!$BL$64 -> M7-US-1140 | AZ2: =表紙!$BU$64 -> 7.0.2 | BF2: =表紙!$CB$64 -> 3
K3: =RIGHT(CELL("filename",$A$1),LEN(CELL("filename",$A$1))-FIND("]",CELL("filename",$A$1))) -> DB設定(WEBDB) | U3: 表題 | Z3: =表紙!$AJ$65 -> - | AE3: =表紙!$AQ$65 -> POWER EGG
C6: データベース設定 | K6: ※フォルダ名:現行設定は、（詳細設計完了時）となる。本番環境時は、設定を変更すること。
C7: 設定項目 | K7: 設定内容① | AI7: 設定内容② | BG7: 設定内容③
C8: データベース名 | K8: 目標管理・訪問計画入力 | AI8: デザイン負荷確認 | BG8: 得意先・納入先メモ
C9: アクセス権限 | K9: 会社 | S9: 設定範囲 | AA9: 権限 | AI9: 会社 | AQ9: 設定範囲 | AY9: 権限 | BG9: 会社 | BO9: 設定範囲 | BW9: 権限
K10: システム管理者 | S10: ー | AA10: データベース管理者 | AI10: システム管理者 | AQ10: ー | AY10: データベース管理者 | BG10: システム管理者 | BO10: ー | BW10: データベース管理者
C15: CSV出力権限情報 | K15: 会社 | S15: 設定範囲 | AA15: 権限 | AI15: 会社 | AQ15: 設定範囲 | AY15: 権限 | BG15: 会社 | BO15: 設定範囲 | BW15: 権限
K16: 全会社 | S16: 社員（情報担当） | AA16: CSV出力可 | AI16: 全会社 | AQ16: 社員（情報担当） | AY16: CSV出力可 | BG16: 全会社 | BO16: 社員（情報担当） | BW16: CSV出力可
C21: 備考
C22: 説明
C23: コメント欄使用有無 | K23: 使用する | AI23: 使用する | BG23: 使用する
C24: 関連情報URL使用有無 | K24: 使用する | AI24: 使用する | BG24: 使用する
C25: 明細行有無 | K25: 無し | AI25: 無し | BG25: 有り
C26: スマートフォン使用有無 | K26: 使用しない | AI26: 使用しない | BG26: 使用しない
C27: 行一括編集使用有無 | K27: 使用しない | AI27: 使用しない | BG27: 使用しない
C28: 使用区分 | K28: 使用中 | AI28: 使用中 | BG28: 使用中
C29: フォルダ名 | K29: （詳細設計完了時） | AI29: （詳細設計完了時） | BG29: （詳細設計完了時）
C30: WebDB間連携情報 | K30: フィールド名 | Q30: 連携元DB名 | W30: 連携元フィールド名 | AC30: 削除時動作 | AI30: フィールド名 | AO30: 連携元DB名 | AU30: 連携元フィールド名 | BA30: 削除時動作 | BG30: フィールド名 | BM30: 連携元DB名 | BS30: 連携元フィールド名 | BY30: 削除時動作
C34: 汎用申請設定情報 | K34: 入力申請事項 | S34: 申請データコピー区分 | AA34: コピー元データベース | AI34: 入力申請事項 | AQ34: 申請データコピー区分 | AY34: コピー元データベース | BG34: 入力申請事項 | BO34: 申請データコピー区分 | BW34: コピー元データベース
C37: 設定項目 | K37: 設定内容④ | AI37: 設定内容⑤ | BG37: 設定内容⑥
C38: データベース名 | K38: 納入先メモ | AI38: 版型発注書 | BG38: 不適合報告書
C39: アクセス権限 | K39: 会社 | S39: 設定範囲 | AA39: 権限 | AI39: 会社 | AQ39: 設定範囲 | AY39: 権限 | BG39: 会社 | BO39: 設定範囲 | BW39: 権限
K40: システム管理者 | S40: ー | AA40: データベース管理者 | AI40: システム管理者 | AQ40: ー | AY40: データベース管理者 | BG40: システム管理者 | BO40: ー | BW40: データベース管理者
C45: CSV出力権限情報 | K45: 会社 | S45: 設定範囲 | AA45: 権限 | AI45: 会社 | AQ45: 設定範囲 | AY45: 権限 | BG45: 会社 | BO45: 設定範囲 | BW45: 権限
K46: 全会社 | S46: 社員（情報担当） | AA46: CSV出力可 | AI46: 全会社 | AQ46: 社員（情報担当） | AY46: CSV出力可 | BG46: 全会社 | BO46: 社員（情報担当） | BW46: CSV出力可
C51: 備考 | AI51: WEB版型マスタより、API連携
C52: 説明
C53: コメント欄使用有無 | K53: 使用する | AI53: 使用する | BG53: 使用する
C54: 関連情報URL使用有無 | K54: 使用する | AI54: 使用する | BG54: 使用する
C55: 明細行有無 | K55: 有り | AI55: 無し | BG55: 無し
C56: スマートフォン使用有無 | K56: 使用しない | AI56: 使用しない | BG56: 使用しない
C57: 行一括編集使用有無 | K57: 使用しない | AI57: 使用しない | BG57: 使用しない
C58: 使用区分 | K58: 使用中 | AI58: 使用中 | BG58: 使用中
C59: フォルダ名 | K59: （詳細設計完了時） | AI59: （詳細設計完了時） | BG59: （詳細設計完了時）
C60: WebDB間連携情報 | K60: フィールド名 | Q60: 連携元DB名 | W60: 連携元フィールド名 | AC60: 削除時動作 | AI60: フィールド名 | AO60: 連携元DB名 | AU60: 連携元フィールド名 | BA60: 削除時動作 | BG60: フィールド名 | BM60: 連携元DB名 | BS60: 連携元フィールド名 | BY60: 削除時動作
C64: 汎用申請設定情報 | K64: 入力申請事項 | S64: 申請データコピー区分 | AA64: コピー元データベース | AI64: 入力申請事項 | AQ64: 申請データコピー区分 | AY64: コピー元データベース | BG64: 入力申請事項 | BO64: 申請データコピー区分 | BW64: コピー元データベース
BG65: 12 | BH65: 不適合報告書WF | BO65: 決裁時にコピー | BW65: 不適合報告書

Sheet DB設定(汎用申請)
A1: =表紙!A54 -> POWER EGG | K1: 文書名 | U1: モジュールID | Z1: =表紙!$AJ$63 -> MS | AE1: モジュール名 | AJ1: =表紙!$AX$63 -> POWER EGG | AS1: 文書番号 | AZ1: Version | BF1: Rev.
K2: =表紙!O64 -> アドオン設計書 | U2: ｻﾌﾞﾓｼﾞｭｰﾙID | Z2: =表紙!$AJ$64 -> MSBB | AE2: ｻﾌﾞﾓｼﾞｭｰﾙ名 | AJ2: =表紙!$AX$64 -> POWER EGG | AS2: =表紙!$BL$64 -> M7-US-1140 | AZ2: =表紙!$BU$64 -> 7.0.2 | BF2: =表紙!$CB$64 -> 3
K3: =RIGHT(CELL("filename",$A$1),LEN(CELL("filename",$A$1))-FIND("]",CELL("filename",$A$1))) -> DB設定(汎用申請) | U3: 表題 | Z3: =表紙!$AJ$65 -> - | AE3: =表紙!$AQ$65 -> POWER EGG
C6: データベース設定 | K6: ※フォルダ名:現行設定は、（詳細設計完了時）となる。本番環境時は、設定を変更すること。
C7: 設定項目 | K7: ⑦設定内容 | AI7: ⑧設定内容 | BG7: ⑨設定内容
C8: データベース名 | K8: 見積確認WF | AI8: 得意先マスタWF | BG8: 見積確定WF
C9: アクセス権限 | K9: 会社 | S9: 設定範囲 | AA9: 権限 | AI9: 会社 | AQ9: 設定範囲 | AY9: 権限 | BG9: 会社 | BO9: 設定範囲 | BW9: 権限
K10: システム管理者 | S10: ー | AA10: データベース管理者 | AI10: システム管理者 | AQ10: ー | AY10: データベース管理者 | BG10: システム管理者 | BO10: ー | BW10: データベース管理者
C15: CSV出力権限情報 | K15: 会社 | S15: 設定範囲 | AA15: 権限 | AI15: 会社 | AQ15: 設定範囲 | AY15: 権限 | BG15: 会社 | BO15: 設定範囲 | BW15: 権限
K16: 全会社 | S16: 社員（情報担当） | AA16: CSV出力可 | AI16: 全会社 | AQ16: 社員（情報担当） | AY16: CSV出力可 | BG16: 全会社 | BO16: 社員（情報担当） | BW16: CSV出力可
C21: 備考
C22: 説明
C23: 明細行有無 | K23: 無し | AI23: 無し | BG23: 無し
C24: スマートフォン使用有無 | K24: 使用しない | AI24: 使用しない | BG24: 使用しない
C25: 使用区分 | K25: 使用中 | AI25: 使用中 | BG25: 使用中
C26: フォルダ名 | K26: （詳細設計完了時） | AI26: （詳細設計完了時） | BG26: （詳細設計完了時）
C27: 汎用申請設定情報 | K27: 入力申請事項 | S27: 申請データコピー区分 | AA27: コピー元データベース | AI27: 入力申請事項 | AQ27: 申請データコピー区分 | AY27: コピー元データベース | BG27: 入力申請事項 | BO27: 申請データコピー区分 | BW27: コピー元データベース
C30: 設定項目 | K30: ⑩設定内容 | AI30: ⑪設定内容 | BG30: ⑫設定内容
C31: データベース名 | K31: 変更連絡依頼WF | AI31: 単価訂正WF | BG31: 集金チェックリストWF
C32: アクセス権限 | K32: 会社 | S32: 設定範囲 | AA32: 権限 | AI32: 会社 | AQ32: 設定範囲 | AY32: 権限 | BG32: 会社 | BO32: 設定範囲 | BW32: 権限
K33: システム管理者 | S33: ー | AA33: データベース管理者 | AI33: システム管理者 | AQ33: ー | AY33: データベース管理者 | BG33: システム管理者 | BO33: ー | BW33: データベース管理者
C38: CSV出力権限情報 | K38: 会社 | S38: 設定範囲 | AA38: 権限 | AI38: 会社 | AQ38: 設定範囲 | AY38: 権限 | BG38: 会社 | BO38: 設定範囲 | BW38: 権限
K39: 全会社 | S39: 社員（情報担当） | AA39: CSV出力可 | AI39: 全会社 | AQ39: 社員（情報担当） | AY39: CSV出力可 | BG39: 全会社 | BO39: 社員（情報担当） | BW39: CSV出力可
C44: 備考
C45: 説明
C46: 明細行有無 | K46: 無し | AI46: 無し | BG46: 無し
C47: スマートフォン使用有無 | K47: 使用しない | AI47: 使用しない | BG47: 使用しない
C48: 使用区分 | K48: 使用中 | AI48: 使用中 | BG48: 使用中
C49: フォルダ名 | K49: （詳細設計完了時） | AI49: （詳細設計完了時） | BG49: （詳細設計完了時）
C50: 汎用申請設定情報 | K50: 入力申請事項 | S50: 申請データコピー区分 | AA50: コピー元データベース | AI50: 入力申請事項 | AQ50: 申請データコピー区分 | AY50: コピー元データベース | BG50: 入力申請事項 | BO50: 申請データコピー区分 | BW50: コピー元データベース
C53: 設定項目 | K53: ⑬設定内容 | AI53: ⑭設定内容
C54: データベース名 | K54: 差額明細書WF | AI54: 不適合品報告書WF | AQ54: ※フィールド設定はWEBDBと同様
C55: アクセス権限 | K55: 会社 | S55: 設定範囲 | AA55: 権限 | AI55: 会社 | AQ55: 設定範囲 | AY55: 権限
K56: システム管理者 | S56: ー | AA56: データベース管理者 | AI56: システム管理者 | AQ56: ー | AY56: データベース管理者
C61: CSV出力権限情報 | K61: 会社 | S61: 設定範囲 | AA61: 権限 | AI61: 会社 | AQ61: 設定範囲 | AY61: 権限
K62: 全会社 | S62: 社員（情報担当） | AA62: CSV出力可 | AI62: 全会社 | AQ62: 社員（情報担当） | AY62: CSV出力可
C67: 備考
C68: 説明
C69: 明細行有無 | K69: 無し | AI69: 無し
C70: スマートフォン使用有無 | K70: 使用しない | AI70: 使用しない
...

Sheet 集計表示設定
A1: =表紙!A54 -> POWER EGG | K1: 文書名 | U1: モジュールID | Z1: =表紙!$AJ$63 -> MS | AE1: モジュール名 | AJ1: =表紙!$AX$63 -> POWER EGG | AS1: 文書番号 | AZ1: Version | BF1: Rev.
K2: =表紙!O64 -> アドオン設計書 | U2: ｻﾌﾞﾓｼﾞｭｰﾙID | Z2: =表紙!$AJ$64 -> MSBB | AE2: ｻﾌﾞﾓｼﾞｭｰﾙ名 | AJ2: =表紙!$AX$64 -> POWER EGG | AS2: =表紙!$BL$64 -> M7-US-1140 | AZ2: =表紙!$BU$64 -> 7.0.2 | BF2: =表紙!$CB$64 -> 3
K3: =RIGHT(CELL("filename",$A$1),LEN(CELL("filename",$A$1))-FIND("]",CELL("filename",$A$1))) -> 集計表示設定 | U3: 表題 | Z3: =表紙!$AJ$65 -> - | AE3: =表紙!$AQ$65 -> POWER EGG
B6: データベース名 | J6: デザイン負荷集計 | BM6: REV3.0:モーションボードで実現するため、削除
C10: ■使用区分
C11: 使用区分
C12: 使用する
C14: ■アクセス権限情報
C15: No | E15: 会社 | N15: 設定範囲 | W15: 権限
C16: 1 | E16: 全会社 | W16: 参照・編集可
C17: 2
C19: ■集計定義
C20: 設定項目 | K20: 設定内容
C21: 表示方法 | K21: （全項目）
C22: 分類項目 | K22: 項目 | T22: 設定 | AC22: 備考
C23: 大分類 | K23: 日付 | T23: 日で集計
C24: 中分類
C25: 小分類
C26: 合計・小計の表示 | K26: □ 合計・小計を表示する
C27: クロス（横軸） | K27: □ クロス集計を行なう
C28: 集計項目
C30: ■集計方法・集計項目
C31: No | E31: 集計方法 | O31: 集計項目 | Y31: 備考
C32: 1 | E32: 合計 | O32: 工数
C33: 2 | E33: 合計 | O33: しきい値1
C34: 3 | E34: 合計 | O34: しきい値2
C35: 4
C36: 5
C38: ■ソート順
C39: No | E39: 項目 | O39: 昇順・降順 | Y39: 備考
C40: 1
C41: 2
C42: 3
C44: ■絞り込み条件
C45: No | E45: 項目 | Y45: 備考
C46: 1

Sheet ①目標管理・訪問計画
A1: =表紙!A54 -> POWER EGG | K1: 文書名 | U1: モジュールID | Z1: =表紙!$AJ$63 -> MS | AE1: モジュール名 | AJ1: =表紙!$AX$63 -> POWER EGG | AS1: 文書番号 | AZ1: Version | BF1: Rev.
K2: アドオン設計書(フィールド設定) | U2: ｻﾌﾞﾓｼﾞｭｰﾙID | Z2: =表紙!$AJ$64 -> MSBB | AE2: ｻﾌﾞﾓｼﾞｭｰﾙ名 | AJ2: =表紙!$AX$64 -> POWER EGG | AS2: =表紙!$BL$64 -> M7-US-1140 | AZ2: =表紙!$BU$64 -> 7.0.2 | BF2: =表紙!$CB$64 -> 3
K3: =RIGHT(CELL("filename",$A$1),LEN(CELL("filename",$A$1))-FIND("]",CELL("filename",$A$1))) -> ①目標管理・訪問計画 | U3: 表題 | Z3: =表紙!$AJ$65 -> - | AE3: =表紙!$AQ$65 -> POWER EGG
A5: フィールド設定
A6: 区分 | C6: Webデータベース | L6: 明細行有無 | S6: 無 | V6: 備考
A7: No | C7: フィールド名 | L7: 形式 | S7: 桁数 | V7: 表示幅 | Y7: 半角英数字 | AC7: 必須 | AE7: ソート | AH7: 再利用 | AK7: キー | AM7: デフォルト値 | AS7: 説明
A8: 1 | C8: 拠点CD | L8: 文字列(1行) | S8: 4000 | AE8: ○
A9: 2 | C9: 拠点名 | L9: 文字列(1行) | S9: 4000 | AE9: ○
A10: 3 | C10: 部署CD | L10: 文字列(1行) | S10: 4000 | AE10: ○
A11: 4 | C11: 部署名 | L11: 文字列(1行) | S11: 4000 | AE11: ○
A12: 5 | C12: 担当者CD | L12: 文字列(1行) | S12: 4000 | AE12: ○
A13: 6 | C13: 担当者名 | L13: 文字列(1行) | S13: 4000 | AE13: ○
A14: 7 | C14: 得意先CD | L14: 文字列(1行) | S14: 4000 | AE14: ○
A15: 8 | C15: 得意先名 | L15: 文字列(1行) | S15: 4000 | AE15: ○
A16: 9 | C16: 得意先ランク | L16: 文字列(1行) | S16: 2 | AE16: ○ | AS16: 期単位に設定可能
A17: 10 | C17: 年度 | L17: 数値 | S17: 4 | AE17: ○ | AS17: YYYY形式
A18: 11 | C18: 期 | L18: 数値 | S18: 2 | AE18: ○
A19: 12 | C19: 目標区分 | L19: ドロップダウンリスト | S19: - | AE19: ○ | AS19: 選択項目:目標,実績
A20: 13 | C20: データ区分 | L20: ドロップダウンリスト | S20: - | AE20: ○ | AS20: 選択項目:→に記載 | BH20: データ区分
A21: 14 | C21: 単位 | L21: 文字列(1行) | S21: 4000 | AE21: ○ | BH21: 選択項目 | BL21: 訪問件数
A22: 15 | C22: 04月 | L22: 数値 | S22: 10,2 | AE22: ○ | BL22: 受注プリフル
A23: 16 | C23: 05月 | L23: 数値 | S23: 10,2 | AE23: ○ | BL23: 受注片面
A24: 17 | C24: 06月 | L24: 数値 | S24: 10,2 | AE24: ○ | BL24: 売上プリフル
A25: 18 | C25: 07月 | L25: 数値 | S25: 10,2 | AE25: ○ | BL25: 売上マイクロ
A26: 19 | C26: 08月 | L26: 数値 | S26: 10,2 | AE26: ○ | BL26: 売上金額
A27: 20 | C27: 09月 | L27: 数値 | S27: 10,2 | AE27: ○ | BL27: 売上片面
A28: 21 | C28: 10月 | L28: 数値 | S28: 10,2 | AE28: ○ | BL28: 売上両面
A29: 22 | C29: 11月 | L29: 数値 | S29: 10,2 | AE29: ○
A30: 23 | C30: 12月 | L30: 数値 | S30: 10,2 | AE30: ○
A31: 24 | C31: 01月 | L31: 数値 | S31: 10,2 | AE31: ○
A32: 25 | C32: 02月 | L32: 数値 | S32: 10,2 | AE32: ○
A33: 26 | C33: 03月 | L33: 数値 | S33: 10,2 | AE33: ○
A34: 27 | C34: TOTAL | L34: 数値 | S34: 10,2 | AE34: ○
A37: 目標管理・訪問計画 一覧表示画面編集
B39: データベース名 | J39: 目標管理・訪問計画
C41: ■画面一覧定義
C42: No | E42: 一覧表示画面名 | O42: 表示方法 | T42: 使用区分 | X42: 備考
C43: 1 | E43: （全項目） | O43: 一覧表示 | T43: 使用しない
C44: 2 | E44: 目標管理・訪問計画 | O44: 一覧表示 | T44: 使用する
C46: ■画面イメージ
...

Sheet ②デザイン負荷
A1: =表紙!A54 -> POWER EGG | K1: 文書名 | U1: モジュールID | Z1: =表紙!$AJ$63 -> MS | AE1: モジュール名 | AJ1: =表紙!$AX$63 -> POWER EGG | AS1: 文書番号 | AZ1: Version | BF1: Rev.
K2: アドオン設計書(フィールド設定) | U2: ｻﾌﾞﾓｼﾞｭｰﾙID | Z2: =表紙!$AJ$64 -> MSBB | AE2: ｻﾌﾞﾓｼﾞｭｰﾙ名 | AJ2: =表紙!$AX$64 -> POWER EGG | AS2: =表紙!$BL$64 -> M7-US-1140 | AZ2: =表紙!$BU$64 -> 7.0.2 | BF2: =表紙!$CB$64 -> 3
K3: =RIGHT(CELL("filename",$A$1),LEN(CELL("filename",$A$1))-FIND("]",CELL("filename",$A$1))) -> ②デザイン負荷 | U3: 表題 | Z3: =表紙!$AJ$65 -> - | AE3: =表紙!$AQ$65 -> POWER EGG
A5: フィールド設定
A6: 区分 | C6: Webデータベース | L6: 明細行有無 | S6: 無 | V6: 備考
A7: No | C7: フィールド名 | L7: 形式 | S7: 桁数 | V7: 表示幅 | Y7: 半角英数字 | AC7: 必須 | AE7: ソート | AH7: 再利用 | AK7: キー | AM7: デフォルト値 | AS7: 説明
A8: 1 | C8: デザイン負荷SEQ | L8: 自動採番 | S8: - | AE8: ○ | AK8: ○
A9: 2 | C9: 拠点CD | L9: 文字列(1行) | S9: 4000 | AE9: ○
A10: 3 | C10: 拠点名 | L10: 文字列(1行) | S10: 4000 | AE10: ○
A11: 4 | C11: 部署CD | L11: 文字列(1行) | S11: 4000 | AE11: ○
A12: 5 | C12: 部署名 | L12: 文字列(1行) | S12: 4000 | AE12: ○
A13: 6 | C13: 日付 | L13: 日付項目 | S13: - | AE13: ○
A14: 7 | C14: 工数 | L14: 数値 | S14: 10,2 | AE14: ○
A15: 8 | C15: しきい値1 | L15: 数値 | S15: 10,2 | AE15: ○
A16: 9 | C16: しきい値2 | L16: 数値 | S16: 10,2 | AE16: ○
A17: 10 | C17: しきい値3 | L17: 数値 | S17: 10,2 | AE17: ○
A18: 11 | C18: しきい値4 | L18: 数値 | S18: 10,2 | AE18: ○
A19: 12 | C19: しきい値5 | L19: 数値 | S19: 10,2 | AE19: ○

Sheet ④納品先メモ
A1: =表紙!A54 -> POWER EGG | K1: 文書名 | U1: モジュールID | Z1: =表紙!$AJ$63 -> MS | AE1: モジュール名 | AJ1: =表紙!$AX$63 -> POWER EGG | AS1: 文書番号 | AZ1: Version | BF1: Rev.
K2: アドオン設計書(フィールド設定) | U2: ｻﾌﾞﾓｼﾞｭｰﾙID | Z2: =表紙!$AJ$64 -> MSBB | AE2: ｻﾌﾞﾓｼﾞｭｰﾙ名 | AJ2: =表紙!$AX$64 -> POWER EGG | AS2: =表紙!$BL$64 -> M7-US-1140 | AZ2: =表紙!$BU$64 -> 7.0.2 | BF2: =表紙!$CB$64 -> 3
K3: =RIGHT(CELL("filename",$A$1),LEN(CELL("filename",$A$1))-FIND("]",CELL("filename",$A$1))) -> ④納品先メモ | U3: 表題 | Z3: =表紙!$AJ$65 -> - | AE3: =表紙!$AQ$65 -> POWER EGG
A5: フィールド設定
A6: 区分 | C6: Webデータベース | L6: 明細行有無 | S6: 有 | V6: 備考
A7: No | C7: フィールド名 | L7: 形式 | S7: 桁数 | V7: 表示幅 | Y7: 半角英数字 | AC7: 必須 | AE7: ソート | AH7: 再利用 | AK7: キー | AM7: デフォルト値 | AS7: 説明
A8: 1 | C8: 納品先CD | L8: DB 参照項目 | S8: - | AE8: ○
A9: 2 | C9: 納品先CD_表示用 | L9: 文字列(1行) | S9: 4000 | AC9: ○ | AK9: ○ | AS9: DB参照時に選択時にコピー
A10: 3 | C10: 納品先名 | L10: 文字列(1行) | S10: 4000 | AE10: ○ | AS10: DB参照時に選択時にコピー
A14: 明細
A15: No | C15: フィールド名 | L15: 形式 | S15: 桁数 | V15: 表示幅 | Y15: 半角英数字 | AC15: 必須 | AE15: ソート | AH15: 再利用 | AK15: キー | AM15: デフォルト値 | AS15: 説明
A16: 1 | C16: 案件NO | L16: DB 参照項目 | S16: -
A17: 2 | C17: 案件NO_表示用 | L17: 文字列(1行) | S17: 4000 | AS17: DB参照時に選択時にコピー
A18: 3 | C18: 案件名 | L18: 文字列(1行) | S18: 4000 | AS18: DB参照時に選択時にコピー
A19: 4 | C19: 製品CD | L19: DB 参照項目 | S19: -
A20: 5 | C20: 製品CD_表示用 | L20: 文字列(1行) | S20: 4000 | AS20: DB参照時に選択時にコピー
A21: 6 | C21: 製品名1 | L21: 文字列(1行) | S21: 4000 | AS21: DB参照時に選択時にコピー
A22: 7 | C22: 製品名2 | L22: 文字列(1行) | S22: 4000 | AS22: DB参照時に選択時にコピー
A23: 8 | C23: 分類1 | L23: ドロップダウンリスト | S23: - | AS23: 設定例:見積、製品マスタ、受注、製造、出荷、売上
A24: 9 | C24: 分類2 | L24: ドロップダウンリスト | S24: -
A25: 10 | C25: 分類3 | L25: ドロップダウンリスト | S25: -
A26: 11 | C26: 納品先メモ | L26: 文字列(複数行) | S26: 4000
A27: 12

Sheet ③得意先・納品先メモ
A1: =表紙!A54 -> POWER EGG | K1: 文書名 | U1: モジュールID | Z1: =表紙!$AJ$63 -> MS | AE1: モジュール名 | AJ1: =表紙!$AX$63 -> POWER EGG | AS1: 文書番号 | AZ1: Version | BF1: Rev.
K2: アドオン設計書(フィールド設定) | U2: ｻﾌﾞﾓｼﾞｭｰﾙID | Z2: =表紙!$AJ$64 -> MSBB | AE2: ｻﾌﾞﾓｼﾞｭｰﾙ名 | AJ2: =表紙!$AX$64 -> POWER EGG | AS2: =表紙!$BL$64 -> M7-US-1140 | AZ2: =表紙!$BU$64 -> 7.0.2 | BF2: =表紙!$CB$64 -> 3
K3: =RIGHT(CELL("filename",$A$1),LEN(CELL("filename",$A$1))-FIND("]",CELL("filename",$A$1))) -> ③得意先・納品先メモ | U3: 表題 | Z3: =表紙!$AJ$65 -> - | AE3: =表紙!$AQ$65 -> POWER EGG
A5: フィールド設定
A6: 区分 | C6: Webデータベース | L6: 明細行有無 | S6: 有 | V6: 備考
A7: No | C7: フィールド名 | L7: 形式 | S7: 桁数 | V7: 表示幅 | Y7: 半角英数字 | AC7: 必須 | AE7: ソート | AH7: 再利用 | AK7: キー | AM7: デフォルト値 | AS7: 説明
A8: 1 | C8: 得意先CD | L8: DB 参照項目 | S8: -
A9: 2 | C9: 得意先CD_表示用 | L9: 文字列(1行) | S9: 4000 | AC9: ○ | AE9: ○ | AK9: ○ | AS9: DB参照時に選択時にコピー
A10: 3 | C10: 得意先名 | L10: 文字列(1行) | S10: 4000 | AE10: ○ | AS10: DB参照時に選択時にコピー
A13: 明細
A14: No | C14: フィールド名 | L14: 形式 | S14: 桁数 | V14: 表示幅 | Y14: 半角英数字 | AC14: 必須 | AE14: ソート | AH14: 再利用 | AK14: キー | AM14: デフォルト値 | AS14: 説明
A15: 1 | C15: 案件NO | L15: DB 参照項目 | S15: -
A16: 2 | C16: 案件NO_表示用 | L16: 文字列(1行) | S16: 4000 | AS16: DB参照時に選択時にコピー
A17: 3 | C17: 案件名 | L17: 文字列(1行) | S17: 4000 | AS17: DB参照時に選択時にコピー
A18: 4 | C18: 製品CD | L18: DB 参照項目 | S18: -
A19: 5 | C19: 製品CD_表示用 | L19: 文字列(1行) | S19: 4000 | AS19: DB参照時に選択時にコピー
A20: 6 | C20: 製品名1 | L20: 文字列(1行) | S20: 4000 | AS20: DB参照時に選択時にコピー
A21: 7 | C21: 製品名2 | L21: 文字列(1行) | S21: 4000 | AS21: DB参照時に選択時にコピー | CE21: REV2.0:2022/12/22 変更
A22: 8 | C22: 分類1 | L22: ドロップダウンリスト | AS22: 得意先メモ・納品先メモ | CE22: 納品先メモは得意先メモの一部となる。分類情報に追加(得意先・納品先メモ)される。
A23: 9 | C23: 分類2 | L23: ドロップダウンリスト | S23: - | AS23: 設定例:見積、製品マスタ、受注、製造、出荷、売上
A24: 10 | C24: 分類3 | L24: ドロップダウンリスト | S24: -
A25: 11 | C25: 得意先・納入先メモ | L25: 文字列(複数行) | S25: 4000
A29: 得意先・納品先メモ 一覧表示画面編集
B31: データベース名 | J31: 得意先・納品先メモ
C33: ■画面一覧定義
C34: No | E34: 一覧表示画面名 | O34: 表示方法 | T34: 使用区分 | X34: 備考
C35: 1 | E35: （全項目） | O35: 一覧表示 | T35: 使用しない
C36: 2 | E36: 得意先・納品先メモ | O36: 一覧表示 | T36: 使用する
C38: ■画面イメージ
C45: ■明細画面イメージ
C58: ■画面定義
C59: 設定項目 | K59: 設定内容
C60: 画面名 | K60: 得意先・納品先メモ
C61: アクセス権限 | K61: 会社 | T61: 設定範囲 | AC61: 権限
K62: 全会社 | AC62: 参照可
C63: 表示方法 | K63: 一覧表示
C64: ソート条件 | K64: 項目 | AE64: ソート順
K65: 得意先CD_表示用 | AE65: 昇順
C68: 絞り込み条件
C69: 表示編集画面 | K69: 得意先・納品先メモ
...

Sheet ⑤版型発注書
A1: =表紙!A54 -> POWER EGG | K1: 文書名 | U1: モジュールID | Z1: =表紙!$AJ$63 -> MS | AE1: モジュール名 | AJ1: =表紙!$AX$63 -> POWER EGG | AS1: 文書番号 | AZ1: Version | BF1: Rev.
K2: アドオン設計書(フィールド設定) | U2: ｻﾌﾞﾓｼﾞｭｰﾙID | Z2: =表紙!$AJ$64 -> MSBB | AE2: ｻﾌﾞﾓｼﾞｭｰﾙ名 | AJ2: =表紙!$AX$64 -> POWER EGG | AS2: =表紙!$BL$64 -> M7-US-1140 | AZ2: =表紙!$BU$64 -> 7.0.2 | BF2: =表紙!$CB$64 -> 3
K3: =RIGHT(CELL("filename",$A$1),LEN(CELL("filename",$A$1))-FIND("]",CELL("filename",$A$1))) -> ⑤版型発注書 | U3: 表題 | Z3: =表紙!$AJ$65 -> - | AE3: =表紙!$AQ$65 -> POWER EGG
A5: フィールド設定
A6: 区分 | C6: Webデータベース | L6: 明細行有無 | S6: 無 | V6: 備考 | AC6: API連携:再連携にて、基本上書きされるためPE上で更新を行わない ※発行用のため型は文字列とする。
A7: No | C7: フィールド名 | L7: 形式 | S7: 桁数 | V7: 表示幅 | Y7: 半角英数字 | AC7: 必須 | AE7: ソート | AH7: 再利用 | AK7: キー | AM7: デフォルト値 | AS7: 説明
A8: 1 | C8: 拠点 | L8: 文字列（1 行） | S8: 4000 | AH8: ○
A9: 2 | C9: 部門CD | L9: 文字列（1 行） | S9: 4000 | AH9: ○
A10: 3 | C10: 営業担当CD | L10: 文字列（1 行） | S10: 4000 | AH10: ○
A11: 4 | C11: 営業担当名 | L11: 文字列（1 行） | S11: 4000 | AH11: ○
A12: 5 | C12: 得意先CD | L12: 文字列（1 行） | S12: 4000 | AH12: ○
A13: 6 | C13: 得意先名 | L13: 文字列（1 行） | S13: 4000 | AH13: ○
A14: 7 | C14: 発注先CD | L14: 文字列（1 行） | S14: 4000 | AH14: ○
A15: 8 | C15: 発注先名 | L15: 文字列（1 行） | S15: 4000 | AH15: ○
A16: 9 | C16: 納期 | L16: 文字列（1 行） | S16: 4000 | AH16: ○
A17: 10 | C17: 手配NO | L17: 文字列（1 行） | S17: 4000 | AH17: ○
A18: 11 | C18: 品名 | L18: 文字列（1 行） | S18: 4000 | AH18: ○
A19: 12 | C19: 発注品目 | L19: 文字列（1 行） | S19: 4000 | AH19: ○ | AS19: EXCELの数式にて、対象をチェックする
A20: 13 | C20: 発注品目_その他 | L20: 文字列（1 行） | S20: 4000 | AH20: ○
A21: 14 | C21: 発注内容 | L21: 文字列（1 行） | S21: 4000 | AH21: ○ | AS21: EXCELの数式にて、対象をチェックする
A22: 15 | C22: 発注内容_その他 | L22: 文字列（1 行） | S22: 4000 | AH22: ○
A23: 16 | C23: 加工予定先 | L23: 文字列（1 行） | S23: 4000 | AH23: ○
A24: 17 | C24: 版型NO | L24: 文字列（1 行） | S24: 4000 | AH24: ○
A25: 18 | C25: 段構成 | L25: 文字列（1 行） | S25: 4000 | AH25: ○
A26: 19 | C26: 抜方向 | L26: 文字列（1 行） | S26: 4000 | AH26: ○ | AS26: EXCELの数式にて、対象をチェックする
A27: 20 | C27: 面付 | L27: 文字列（1 行） | S27: 4000 | AH27: ○
A28: 21 | C28: シート寸法1 | L28: 文字列（1 行） | S28: 4000 | AH28: ○
A29: 22 | C29: シート寸法2 | L29: 文字列（1 行） | S29: 4000 | AH29: ○
A30: 23 | C30: 本数 | L30: 文字列（1 行） | S30: 4000 | AH30: ○
A31: 24 | C31: 色数 | L31: 文字列（1 行） | S31: 4000 | AH31: ○
A32: 25 | C32: 刃渡り寸法 | L32: 文字列（1 行） | S32: 4000 | AH32: ○
A33: 26 | C33: フレキソ版厚 | L33: 文字列（1 行） | S33: 4000 | AH33: ○
A34: 27 | C34: シリンダーサイズ | L34: 文字列（1 行） | S34: 4000 | AH34: ○
A35: 28 | C35: 見積価格 | L35: 文字列（1 行） | S35: 4000 | AH35: ○
A36: 29 | C36: 仕入価格 | L36: 文字列（1 行） | S36: 4000 | AH36: ○
A37: 30 | C37: 決定価格 | L37: 文字列（1 行） | S37: 4000 | AH37: ○
A38: 31 | C38: 売上日 | L38: 文字列（1 行） | S38: 4000 | AH38: ○
... A62: 55 | C62: 備考欄_注意事項 | L62: 文字列(複数行) | S62: 4000 | AH62: ○
A63: 版型発注書 一覧表示画面編集
B65: データベース名 | J65: 版型発注書
...

Sheet ⑥不適合品報告書
A1: POWER EGG | K1: 文書名 | U1: モジュールID | Z1: MS | AE1: モジュール名 | AJ1: POWER EGG | AS1: 文書番号 | AZ1: Version | BF1: Rev.
K2: アドオン設計書(フィールド設定) | U2: ｻﾌﾞﾓｼﾞｭｰﾙID | Z2: MSBB | AE2: ｻﾌﾞﾓｼﾞｭｰﾙ名 | AJ2: POWER EGG | AS2: M7-US-1140 | AZ2: 7.0.2 | BF2: 1
K3: 不適合品報告書 | U3: 表題 | Z3: - | AE3: POWER EGG
A5: フィールド設定
A6: 区分 | C6: 汎用申請・Webデータベース | L6: 明細行有無 | S6: 無 | V6: 備考
A7: No | C7: フィールド名 | L7: 形式 | S7: 桁数 | V7: 表示幅 | Y7: 半角英数字 | AC7: 必須 | AE7: ソート | AH7: 再利用 | AK7: キー | AM7: デフォルト値 | AS7: 説明
A8: 1 | C8: 申請者 | L8: 社員選択 | S8: - | AC8: ○ | AM8: ログイン社員 | AS8: 汎用申請システム項目(固定)
A9: 2 | C9: 申請日 | L9: 日付項目 | S9: - | AC9: ○ | AM9: @sys | AS9: 汎用申請システム項目
A10: 3 | C10: 件名 | L10: 文字列（1 行） | S10: 4000 | AC10: ○ | AS10: 汎用申請システム項目
A11: 4 | C11: 優先度 | L11: ラジオボタン | S11: - | AC11: ○ | AS11: 汎用申請システム項目(通常、緊急)
A12: 1 | C12: 報告書No | L12: 自動採番 | S12: - | AS12: 汎用申請：自動採番 WebDB：文字列(1行)、4000
A13: 2 | C13: 作成部署 | L13: 部門選択 | S13: - | AC13: ○ | AE13: ○ | AM13: ログイン社員の部門
A14: 3 | C14: 作成者 | L14: 社員選択 | S14: - | AC14: ○ | AE14: ○ | AM14: ログイン社員
A15: 4 | C15: 作成日 | L15: 日付項目 | S15: - | AC15: ○ | AE15: ○ | AM15: @sys
A16: 5 | C16: 作成時刻 | L16: 時刻項目 | S16: - | AC16: ○ | AE16: ○ | AM16: @sys
A17: 6 | C17: 手配NO | L17: DB 参照項目 | S17: - | AS17: 手配NO=受注NO
A18: 7 | C18: 手配NO_表示用 | L18: 文字列(1行) | S18: 4000 | AE18: ○ | AS18: DB参照時に選択時にコピー
A19: 8 | C19: 社内外区分 | L19: ドロップダウンリスト | S19: - | AS19: 1:社内不適合、2:顧客クレーム、3:顧客苦情
A20: 9 | C20: 拠点CD | L20: DB 参照項目 | S20: - | AE20: ○
A21: 10 | C21: 拠点CD_表示用 | L21: 文字列(1行) | S21: 4000 | AE21: ○ | AS21: DB参照時に選択時にコピー
A22: 11 | C22: 拠点名 | L22: 文字列(1行) | S22: 4000 | AE22: ○ | AS22: DB参照時に選択時にコピー
A23: 12 | C23: 製品CD | L23: DB 参照項目 | S23: - | AS23: 製品CD=マスターNO
A24: 13 | C24: 製品CD_表示用 | L24: 文字列(1行) | S24: 4000 | AC24: ○ | AE24: ○ | AS24: DB参照時に選択時にコピー
A25: 14 | C25: 製品名1 | L25: 文字列(1行) | S25: 4000 | AE25: ○ | AS25: DB参照時に選択時にコピー
A26: 15 | C26: 製品名2 | L26: 文字列(1行) | S26: 4000 | AE26: ○ | AS26: DB参照時に選択時にコピー
A27: 16 | C27: 寸法 | L27: 文字列(1行) | S27: 4000 | AS27: DB参照時に選択時にコピー
A28: 17 | C28: 得意先CD | L28: DB 参照項目 | S28: -
A29: 18 | C29: 得意先CD_表示用 | L29: 文字列(1行) | S29: 4000 | AC29: ○ | AE29: ○ | AS29: DB参照時に選択時にコピー
A30: 19 | C30: 得意先名 | L30: 文字列(1行) | S30: 4000 | AE30: ○ | AS30: DB参照時に選択時にコピー
A31: 20 | C31: 納品先CD | L31: DB 参照項目 | S31: -
A32: 21 | C32: 納品先CD_表示用 | L32: 文字列(1行) | S32: 4000 | AC32: ○ | AE32: ○ | AS32: DB参照時に選択時にコピー
A33: 22 | C33: 納品先名 | L33: 文字列(1行) | S33: 4000 | AE33: ○ | AS33: DB参照時に選択時にコピー
A34: 23 | C34: 発生日 | L34: 日付項目 | S34: -
A35: 24 | C35: 発生場所 | L35: 文字列(1行) | S35: 4000
A36: 25 | C36: 納入数 | L36: 数値 | S36: 10
A37: 26 | C37: クレーム数 | L37: 数値 | S37: 10
A38: 27 | C38: 段構成 | L38: 文字列(1行) | S38: 4000 | AS38: DB参照時に選択時にコピー(段、表中裏原紙)
A39: 28 | C39: 実損金額 | L39: 数値 | S39: 10,2
A40: 29 | C40: 稟議NO | L40: 文字列(1行) | S40: 4000 | AS40: 稟議NOの下に「10万を超えた場合は稟議申請の
AS41: うえ、稟議NOを登録すること。」のコメントを追加
...

Sheet ⑥連動項目設定
A1: POWER EGG | K1: 文書名 | U1: モジュールID | Z1: MS | AE1: モジュール名 | AJ1: POWER EGG | AS1: 文書番号 | AZ1: Version | BF1: Rev.
K2: アドオン設計書(フィールド設定) | U2: ｻﾌﾞﾓｼﾞｭｰﾙID | Z2: MSBB | AE2: ｻﾌﾞﾓｼﾞｭｰﾙ名 | AJ2: POWER EGG | AS2: M7-US-1140 | AZ2: 7.0.2 | BF2: 1
K3: 不適合品報告書 | U3: 表題 | Z3: - | AE3: POWER EGG
A5: 連動項目設定
A6: No | C6: 連動元項目 | L6: 連動項目 | U6: 連動項目２
A7: 1 | C7: 要因１_リスト | L7: 要因２_リスト | U7: 要因内容_リスト
C9: 背景色黄色を☑ありで表現
C10: ※実際の設定イメージは、下記となる。
C22: 連動元項目:要因１_リスト、連動項目：要因２_リストと連動項目２：要因内容_リストの組み合わせ設定
C23: 要因１_リスト：未選択 | M23: 設定なし
C24: 要因１_リスト：1 | M24: 要因２_リスト：空白 | W24: 要因２_リスト：0 | AG24: 要因２_リスト：1 | AQ24: 要因２_リスト：2 | BA24: 要因２_リスト：3 | BK24: 要因２_リスト：4 | BU24: 要因２_リスト：5
C25: 要因内容_リスト | M25: 空白 | W25: 空白 | AG25: 空白 | AQ25: 空白 | BA25: 空白 | BK25: 空白 | BU25: 空白
M26: 1：0：0：受注ミス | W26: 1：0：0：受注ミス | AG26: 1：0：0：受注ミス | AQ26: 1：0：0：受注ミス | BA26: 1：0：0：受注ミス | BK26: 1：0：0：受注ミス | BU26: 1：0：0：受注ミス
M27: 1：1：0：手配/処理ミス | W27: 1：1：0：手配/処理ミス | AG27: 1：1：0：手配/処理ミス | AQ27: 1：1：0：手配/処理ミス | BA27: 1：1：0：手配/処理ミス | BK27: 1：1：0：手配/処理ミス | BU27: 1：1：0：手配/処理ミス
M28: 1：1：1：図面間違い | W28: 1：1：1：図面間違い | AG28: 1：1：1：図面間違い | AQ28: 1：1：1：図面間違い | BA28: 1：1：1：図面間違い | BK28: 1：1：1：図面間違い | BU28: 1：1：1：図面間違い
M29: 1：1：2：段構成間違い | W29: 1：1：2：段構成間違い | AG29: 1：1：2：段構成間違い | AQ29: 1：1：2：段構成間違い | BA29: 1：1：2：段構成間違い | BK29: 1：1：2：段構成間違い | BU29: 1：1：2：段構成間違い
M30: 1：1：3：寸法間違い | W30: 1：1：3：寸法間違い | AG30: 1：1：3：寸法間違い | AQ30: 1：1：3：寸法間違い | BA30: 1：1：3：寸法間違い | BK30: 1：1：3：寸法間違い | BU30: 1：1：3：寸法間違い
M31: 1：1：4：数量間違い | W31: 1：1：4：数量間違い | AG31: 1：1：4：数量間違い | AQ31: 1：1：4：数量間違い | BA31: 1：1：4：数量間違い | BK31: 1：1：4：数量間違い | BU31: 1：1：4：数量間違い
M32: 1：1：5：色校正間違い | W32: 1：1：5：色校正間違い | AG32: 1：1：5：色校正間違い | AQ32: 1：1：5：色校正間違い | BA32: 1：1：5：色校正間違い | BK32: 1：1：5：色校正間違い | BU32: 1：1：5：色校正間違い
M33: 1：1：6：品名間違い | W33: 1：1：6：品名間違い | AG33: 1：1：6：品名間違い | AQ33: 1：1：6：品名間違い | BA33: 1：1：6：品名間違い | BK33: 1：1：6：品名間違い | BU33: 1：1：6：品名間違い
M34: 1：1：7：形状間違い | W34: 1：1：7：形状間違い | AG34: 1：1：7：形状間違い | AQ34: 1：1：7：形状間違い | BA34: 1：1：7：形状間違い | BK34: 1：1：7：形状間違い | BU34: 1：1：7：形状間違い
M35: 1：1：8：納期間違い | W35: 1：1：8：納期間違い | AG35: 1：1：8：納期間違い | AQ35: 1：1：8：納期間違い | BA35: 1：1：8：納期間違い | BK35: 1：1：8：納期間違い | BU35: 1：1：8：納期間違い
M36: 1：1：9：設計間違い | W36: 1：1：9：設計間違い | AG36: 1：1：9：設計間違い | AQ36: 1：1：9：設計間違い | BA36: 1：1：9：設計間違い | BK36: 1：1：9：設計間違い | BU36: 1：1：9：設計間違い
M37: 1：1：10：仕様間違い | W37: 1：1：10：仕様間違い | AG37: 1：1：10：仕様間違い | AQ37: 1：1：10：仕様間違い | BA37: 1：1：10：仕様間違い | BK37: 1：1：10：仕様間違い | BU37: 1：1：10：仕様間違い
... M49: 1：1：22：原紙ｍ不足 | W49: 1：1：22：原紙ｍ不足 | AG49: 1：1：22：原紙ｍ不足 | AQ49: 1：1：22：原紙ｍ不足 | BA49: 1：1：22：原紙ｍ不足 | BK49: 1：1：22：原紙ｍ不足 | BU49: 1：1：22：原紙ｍ不足
C50: 要因１_リスト：2 | M50: 要因２_リスト：空白 | W50: 要因２_リスト：0 | AG50: 要因２_リスト：1 | AQ50: 要因２_リスト：2 | BA50: 要因２_リスト：3 | BK50: 要因２_リスト：4 | BU50: 要因２_リスト：5
C51: 要因内容_リスト | M51: 空白 | W51: 空白 | AG51: 空白 | AQ51: 空白 | BA51: 空白 | BK51: 空白 | BU51: 空白
M52: 2：0：0：原材料不良 | W52: 2：0：0：原材料不良 | AG52: 2：0：0：原材料不良 | AQ52: 2：0：0：原材料不良 | BA52: 2：0：0：原材料不良 | BK52: 2：0：0：原材料不良 | BU52: 2：0：0：原材料不良
M53: 2：1：0：原紙不良 | W53: 2：1：0：原紙不良 | AG53: 2：1：0：原紙不良 | AQ53: 2：1：0：原紙不良 | BA53: 2：1：0：原紙不良 | BK53: 2：1：0：原紙不良 | BU53: 2：1：0：原紙不良
M54: 2：1：1：印刷不良 | W54: 2：1：1：印刷不良 | AG54: 2：1：1：印刷不良 | AQ54: 2：1：1：印刷不良 | BA54: 2：1：1：印刷不良 | BK54: 2：1：1：印刷不良 | BU54: 2：1：1：印刷不良
M55: 2：1：2：破れ | W55: 2：1：2：破れ | AG55: 2：1：2：破れ | AQ55: 2：1：2：破れ | BA55: 2：1：2：破れ | BK55: 2：1：2：破れ | BU55: 2：1：2：破れ
M56: 2：1：3：キズ | W56: 2：1：3：キズ | AG56: 2：1：3：キズ | AQ56: 2：1：3：キズ | BA56: 2：1：3：キズ | BK56: 2：1：3：キズ | BU56: 2：1：3：キズ
M57: 2：1：4：汚れ | W57: 2：1：4：汚れ | AG57: 2：1：4：汚れ | AQ57: 2：1：4：汚れ | BA57: 2：1：4：汚れ | BK57: 2：1：4：汚れ | BU57: 2：1：4：汚れ
M58: 2：1：5：シワ | W58: 2：1：5：シワ | AG58: 2：1：5：シワ | AQ58: 2：1：5：シワ | BA58: 2：1：5：シワ | BK58: 2：1：5：シワ | BU58: 2：1：5：シワ
M59: 2：1：6：剥がれ | W59: 2：1：6：剥がれ | AG59: 2：1：6：剥がれ | AQ59: 2：1：6：剥がれ | BA59: 2：1：6：剥がれ | BK59: 2：1：6：剥がれ | BU59: 2：1：6：剥がれ
M60: 2：1：7：凹み | W60: 2：1：7：凹み | AG60: 2：1：7：凹み | AQ60: 2：1：7：凹み | BA60: 2：1：7：凹み | BK60: 2：1：7：凹み | BU60: 2：1：7：凹み
M61: 2：1：8：色違い | W61: 2：1：8：色違い | AG61: 2：1：8：色違い | AQ61: 2：1：8：色違い | BA61: 2：1：8：色違い | BK61: 2：1：8：色違い | BU61: 2：1：8：色違い
M62: 2：1：9：抄きムラ | W62: 2：1：9：抄きムラ | AG62: 2：1：9：抄きムラ | AQ62: 2：1：9：抄きムラ | BA62: 2：1：9：抄きムラ | BK62: 2：1：9：抄きムラ | BU62: 2：1：9：抄きムラ
M63: 2：1：10：水濡れ | W63: 2：1：10：水濡れ | AG63: 2：1：10：水濡れ | AQ63: 2：1：10：水濡れ | BA63: 2：1：10：水濡れ | BK63: 2：1：10：水濡れ | BU63: 2：1：10：水濡れ
... M75: 2：1：22：原紙M不足 | W75: 2：1：22：原紙M不足 | AG75: 2：1：22：原紙M不足 | AQ75: 2：1：22：原紙M不足 | BA75: 2：1：22：原紙M不足 | BK75: 2：1：22：原紙M不足 | BU75: 2：1：22：原紙M不足
...

Sheet ⑥連動項目設定(不適合要因(FAE09P))
A1: POWER EGG | K1: 文書名 | U1: モジュールID | Z1: MS | AE1: モジュール名 | AJ1: POWER EGG | AS1: 文書番号 | AZ1: Version | BF1: Rev.
K2: アドオン設計書(フィールド設定) | U2: ｻﾌﾞﾓｼﾞｭｰﾙID | Z2: MSBB | AE2: ｻﾌﾞﾓｼﾞｭｰﾙ名 | AJ2: POWER EGG | AS2: M7-US-1140 | AZ2: 7.0.2 | BF2: 1
K3: 不適合品報告書 | U3: 表題 | Z3: - | AE3: POWER EGG
A5: 不適合要因(FAE09P)
C6: 元データ
C7: 要因１ | E7: 要因２ | G7: 要因３ | I7: 要因内容
C8: 1 | E8: 0 | G8: 0 | I8: 受注ミス
C9: 1 | E9: 1 | G9: 0 | I9: 手配/処理ミス
C10: 1 | E10: 1 | G10: 1 | I10: 図面間違い
C11: 1 | E11: 1 | G11: 2 | I11: 段構成間違い
C12: 1 | E12: 1 | G12: 3 | I12: 寸法間違い
C13: 1 | E13: 1 | G13: 4 | I13: 数量間違い
C14: 1 | E14: 1 | G14: 5 | I14: 色校正間違い
C15: 1 | E15: 1 | G15: 6 | I15: 品名間違い
C16: 1 | E16: 1 | G16: 7 | I16: 形状間違い
C17: 1 | E17: 1 | G17: 8 | I17: 納期間違い
C18: 1 | E18: 1 | G18: 9 | I18: 設計間違い
... C467: 9 | E467: 1 | G467: 10 | I467: 詳細不明

Sheet ⑦見積確認
A1: =表紙!A54 -> POWER EGG | K1: 文書名 | U1: モジュールID | Z1: =表紙!$AJ$63 -> MS | AE1: モジュール名 | AJ1: =表紙!$AX$63 -> POWER EGG | AS1: 文書番号 | AZ1: Version | BF1: Rev.
K2: アドオン設計書(フィールド設定) | U2: ｻﾌﾞﾓｼﾞｭｰﾙID | Z2: =表紙!$AJ$64 -> MSBB | AE2: ｻﾌﾞﾓｼﾞｭｰﾙ名 | AJ2: =表紙!$AX$64 -> POWER EGG | AS2: =表紙!$BL$64 -> M7-US-1140 | AZ2: =表紙!$BU$64 -> 7.0.2 | BF2: =表紙!$CB$64 -> 3
K3: =RIGHT(CELL("filename",$A$1),LEN(CELL("filename",$A$1))-FIND("]",CELL("filename",$A$1))) -> ⑦見積確認 | U3: 表題 | Z3: =表紙!$AJ$65 -> - | AE3: =表紙!$AQ$65 -> POWER EGG
A5: フィールド設定
A6: 区分 | C6: Webデータベース | L6: 明細行有無 | S6: 無 | V6: 備考
A7: No | C7: フィールド名 | L7: 形式 | S7: 桁数 | V7: 表示幅 | Y7: 半角英数字 | AC7: 必須 | AE7: ソート | AH7: 再利用 | AK7: キー | AM7: デフォルト値 | AS7: 説明
A8: 1 | C8: 申請者 | L8: 社員選択 | S8: - | AC8: ○ | AM8: ログイン社員 | AS8: 汎用申請システム項目(固定)
A9: 2 | C9: 申請日 | L9: 日付項目 | S9: - | AC9: ○ | AM9: @sys | AS9: 汎用申請システム項目
A10: 3 | C10: 件名 | L10: 文字列（1 行） | S10: 4000 | AC10: ○ | AS10: 汎用申請システム項目
A11: 4 | C11: 優先度 | L11: ラジオボタン | S11: - | AC11: ○ | AS11: 汎用申請システム項目(通常、緊急)
A12: 5 | C12: 営業担当 | L12: 社員選択 | S12: 4000 | AC12: ○ | AE12: ○ | AM12: ログイン社員
A13: 6 | C13: 営業コメント | L13: 文字列(複数行) | S13: 4000 | AC13: ○ | AE13: ○
A14: 7 | C14: 確認区分 | L14: ドロップダウンリスト | S14: - | AC14: ○ | AE14: ○ | AS14: 選択項目:御見積書No,見積計算書No
A15: 8 | C15: 御見積書No | L15: DB 参照項目 | S15: -
A16: 9 | C16: 御見積書No_表示用 | L16: 文字列(1行) | S16: 4000 | AE16: ○ | AS16: DB参照時に選択時にコピー
A17: 10 | C17: 拠点CD | L17: 文字列(1行) | S17: 4000 | AE17: ○ | AS17: DB参照時に選択時にコピー
A18: 11 | C18: 拠点名 | L18: 文字列(1行) | S18: 4000 | AE18: ○ | AS18: DB参照時に選択時にコピー
A19: 12 | C19: 得意先CD | L19: 文字列（1 行） | S19: 4000 | AS19: DB参照時に選択時にコピー
A20: 13 | C20: 得意先名 | L20: 文字列（1 行） | S20: 4000 | AS20: DB参照時に選択時にコピー
A21: 14 | C21: 見積計算書No1 | L21: 文字列(1行) | S21: 4000 | AE21: ○ | AS21: DB参照時に選択時にコピー
A22: 15 | C22: 顧客品名1 | L22: 文字列(1行) | S22: 4000 | AE22: ○ | AS22: DB参照時に選択時にコピー(顧客品名1+2)
A23: 16 | C23: 見積数1 | L23: 数値 | S23: 10 | AE23: ○ | AS23: DB参照時に選択時にコピー
A24: 17 | C24: 単価1 | L24: 数値 | S24: 10,2 | AE24: ○ | AS24: DB参照時に選択時にコピー
A25: 18 | C25: 金額1 | L25: 数値 | S25: 10,2 | AE25: ○ | AS25: DB参照時に選択時にコピー
A26: 19 | C26: 見積計算書No2 | L26: 文字列(1行) | S26: 4000 | AE26: ○ | AS26: DB参照時に選択時にコピー
A27: 20 | C27: 顧客品名2 | L27: 文字列(1行) | S27: 4000 | AE27: ○ | AS27: DB参照時に選択時にコピー(顧客品名1+2)
A28: 21 | C28: 見積数2 | L28: 数値 | S28: 10 | AE28: ○ | AS28: DB参照時に選択時にコピー
A29: 22 | C29: 単価2 | L29: 数値 | S29: 10,2 | AE29: ○ | AS29: DB参照時に選択時にコピー
A30: 23 | C30: 金額2 | L30: 数値 | S30: 10,2 | AE30: ○ | AS30: DB参照時に選択時にコピー
A31: 24 | C31: 見積計算書No3 | L31: 文字列(1行) | S31: 4000 | AE31: ○ | AS31: DB参照時に選択時にコピー
A32: 25 | C32: 顧客品名3 | L32: 文字列(1行) | S32: 4000 | AE32: ○ | AS32: DB参照時に選択時にコピー(顧客品名1+2)
A33: 26 | C33: 見積数3 | L33: 数値 | S33: 10 | AE33: ○ | AS33: DB参照時に選択時にコピー
A34: 27 | C34: 単価3 | L34: 数値 | S34: 10,2 | AE34: ○ | AS34: DB参照時に選択時にコピー
A35: 28 | C35: 金額3 | L35: 数値 | S35: 10,2 | AE35: ○ | AS35: DB参照時に選択時にコピー
A36: 29 | C36: 見積計算書備考 | L36: 文字列(複数行) | S36: 4000 | AE36: ○ | AS36: DB参照時に選択時にコピー(4行以上含む場合にコメント)
A37: 30 | C37: 合計金額 | L37: 数値 | S37: 10,2 | AE37: ○ | AS37: DB参照時に選択時にコピー
A38: 31 | C38: 見積計算書No | L38: DB 参照項目 | S38: -
A39: 32 | C39: 見積計算書No_表示用 | L39: 文字列(1行) | S39: 4000 | AE39: ○ | AS39: DB参照時に選択時にコピー
A40: 33 | C40: 見積計算書_顧客品名1 | L40: 文字列(1行) | S40: 4000 | AE40: ○ | AS40: DB参照時に選択時にコピー
A41: 34 | C41: 見積計算書_顧客品名2 | L41: 文字列(1行) | S41: 4000 | AE41: ○ | AS41: DB参照時に選択時にコピー
...

Sheet ⑧得意先マスタ
A1: =表紙!A54 -> POWER EGG | K1: 文書名 | U1: モジュールID | Z1: =表紙!$AJ$63 -> MS | AE1: モジュール名 | AJ1: =表紙!$AX$63 -> POWER EGG | AS1: 文書番号 | AZ1: Version | BF1: Rev.
K2: アドオン設計書(フィールド設定) | U2: ｻﾌﾞﾓｼﾞｭｰﾙID | Z2: =表紙!$AJ$64 -> MSBB | AE2: ｻﾌﾞﾓｼﾞｭｰﾙ名 | AJ2: =表紙!$AX$64 -> POWER EGG | AS2: =表紙!$BL$64 -> M7-US-1140 | AZ2: =表紙!$BU$64 -> 7.0.2 | BF2: =表紙!$CB$64 -> 3
K3: =RIGHT(CELL("filename",$A$1),LEN(CELL("filename",$A$1))-FIND("]",CELL("filename",$A$1))) -> ⑧得意先マスタ | U3: 表題 | Z3: =表紙!$AJ$65 -> - | AE3: =表紙!$AQ$65 -> POWER EGG
A5: フィールド設定
A6: 区分 | C6: Webデータベース | L6: 明細行有無 | S6: 無 | V6: 備考
A7: No | C7: フィールド名 | L7: 形式 | S7: 桁数 | V7: 表示幅 | Y7: 半角英数字 | AC7: 必須 | AE7: ソート | AH7: 再利用 | AK7: キー | AM7: デフォルト値 | AS7: 説明
A8: 1 | C8: 申請者 | L8: 社員選択 | S8: - | AC8: ○ | AM8: ログイン社員 | AS8: 汎用申請システム項目(固定)
A9: 2 | C9: 申請日 | L9: 日付項目 | S9: - | AC9: ○ | AM9: @sys | AS9: 汎用申請システム項目
A10: 3 | C10: 件名 | L10: 文字列（1 行） | S10: 4000 | AC10: ○ | AS10: 汎用申請システム項目
A11: 4 | C11: 優先度 | L11: ラジオボタン | S11: - | AC11: ○ | AS11: 汎用申請システム項目(通常、緊急)
A12: 5 | C12: 営業担当 | L12: 社員選択 | S12: 4000 | AC12: ○ | AE12: ○ | AM12: ログイン社員
A13: 6 | C13: 営業コメント | L13: 文字列(複数行) | S13: 4000 | AC13: ○ | AE13: ○
A14: 7 | C14: 得意先CD | L14: DB 参照項目 | S14: - | AE14: ○ | AK14: ○
A15: 8 | C15: 得意先CD_表示用 | L15: 文字列(1行) | S15: 4000 | AC15: ○ | AS15: DB参照時に選択時にコピー
A16: 9 | C16: 得意先名 | L16: 文字列(1行) | S16: 4000 | AE16: ○ | AS16: DB参照時に選択時にコピー
A18: 得意先マスタ 一覧表示画面編集
B20: データベース名 | J20: 得意先マスタ
C22: ■画面一覧定義
C23: No | E23: 一覧表示画面名 | O23: 表示方法 | T23: 使用区分 | X23: 備考
C24: 1 | E24: （全項目） | O24: 一覧表示 | T24: 使用しない
C25: 2 | E25: 得意先マスタ | O25: 一覧表示 | T25: 使用する
C27: ■画面イメージ
C35: ■画面定義
C36: 設定項目 | K36: 設定内容
C37: 画面名 | K37: 得意先マスタ
C38: アクセス権限 | K38: 会社 | T38: 設定範囲 | AC38: 権限
K39: 全会社 | AC39: 参照可
C40: 表示方法 | K40: 一覧表示
C41: ソート条件 | K41: 項目 | AE41: ソート順
K42: No | AE42: 昇順
C45: 絞り込み条件
C46: 表示編集画面 | K46: 得意先マスタ
C48: ■レイアウト設定
C49: No. | E49: 項目見出し書式 | P49: フィールド名 | AA49: 条件付き書式設定
C50: 1 | E50: No | P50: No
C51: 2 | E51: 拠点 | P51: 拠点
C52: 3 | E52: 部門CD | P52: 部門CD
C53: 4 | E53: 営業担当CD | P53: 営業担当CD
C54: 5 | E54: 営業担当名 | P54: 営業担当名
C55: 6 | E55: 手配NO | P55: 手配NO
...

Sheet ⑨見積確定
A1: =表紙!A54 -> POWER EGG | K1: 文書名 | U1: モジュールID | Z1: =表紙!$AJ$63 -> MS | AE1: モジュール名 | AJ1: =表紙!$AX$63 -> POWER EGG | AS1: 文書番号 | AZ1: Version | BF1: Rev.
K2: アドオン設計書(フィールド設定) | U2: ｻﾌﾞﾓｼﾞｭｰﾙID | Z2: =表紙!$AJ$64 -> MSBB | AE2: ｻﾌﾞﾓｼﾞｭｰﾙ名 | AJ2: =表紙!$AX$64 -> POWER EGG | AS2: =表紙!$BL$64 -> M7-US-1140 | AZ2: =表紙!$BU$64 -> 7.0.2 | BF2: =表紙!$CB$64 -> 3
K3: =RIGHT(CELL("filename",$A$1),LEN(CELL("filename",$A$1))-FIND("]",CELL("filename",$A$1))) -> ⑨見積確定 | U3: 表題 | Z3: =表紙!$AJ$65 -> - | AE3: =表紙!$AQ$65 -> POWER EGG
A5: フィールド設定
A6: 区分 | C6: Webデータベース | L6: 明細行有無 | S6: 無 | V6: 備考
A7: No | C7: フィールド名 | L7: 形式 | S7: 桁数 | V7: 表示幅 | Y7: 半角英数字 | AC7: 必須 | AE7: ソート | AH7: 再利用 | AK7: キー | AM7: デフォルト値 | AS7: 説明
A8: 1 | C8: 申請者 | L8: 社員選択 | S8: - | AC8: ○ | AM8: ログイン社員 | AS8: 汎用申請システム項目(固定)
A9: 2 | C9: 申請日 | L9: 日付項目 | S9: - | AC9: ○ | AM9: @sys | AS9: 汎用申請システム項目
A10: 3 | C10: 件名 | L10: 文字列（1 行） | S10: 4000 | AC10: ○ | AS10: 汎用申請システム項目
A11: 4 | C11: 優先度 | L11: ラジオボタン | S11: - | AC11: ○ | AS11: 汎用申請システム項目(通常、緊急)
A12: 5 | C12: 営業担当 | L12: 社員選択 | S12: 4000 | AC12: ○ | AE12: ○ | AM12: ログイン社員
A13: 6 | C13: 営業コメント | L13: 文字列(複数行) | S13: 4000 | AC13: ○ | AE13: ○
A14: 7 | C14: 御見積書No | L14: DB 参照項目 | S14: -
A15: 8 | C15: 御見積書No_表示用 | L15: 文字列(1行) | S15: 4000 | AE15: ○ | AS15: DB参照時に選択時にコピー
A16: 9 | C16: 拠点CD | L16: 文字列(1行) | S16: 4000 | AE16: ○ | AS16: DB参照時に選択時にコピー
A17: 10 | C17: 拠点名 | L17: 文字列(1行) | S17: 4000 | AE17: ○ | AS17: DB参照時に選択時にコピー
A18: 11 | C18: 得意先CD | L18: 文字列（1 行） | S18: 4000 | AS18: DB参照時に選択時にコピー
A19: 12 | C19: 得意先名 | L19: 文字列（1 行） | S19: 4000 | AS19: DB参照時に選択時にコピー
A20: 13 | C20: 見積計算書No1 | L20: 文字列(1行) | S20: 4000 | AE20: ○ | AS20: DB参照時に選択時にコピー
A21: 14 | C21: 顧客品名1 | L21: 文字列(1行) | S21: 4000 | AE21: ○ | AS21: DB参照時に選択時にコピー(顧客品名1+2)
A22: 15 | C22: 見積計算書No2 | L22: 文字列(1行) | S22: 4000 | AE22: ○ | AS22: DB参照時に選択時にコピー
A23: 16 | C23: 顧客品名2 | L23: 文字列(1行) | S23: 4000 | AE23: ○ | AS23: DB参照時に選択時にコピー(顧客品名1+2)
A24: 17 | C24: 見積計算書No3 | L24: 文字列(1行) | S24: 4000 | AE24: ○ | AS24: DB参照時に選択時にコピー
A25: 18 | C25: 顧客品名3 | L25: 文字列(1行) | S25: 4000 | AE25: ○ | AS25: DB参照時に選択時にコピー(顧客品名1+2)
A26: 19 | C26: 見積計算書No4 | L26: 文字列(1行) | S26: 4000 | AE26: ○ | AS26: DB参照時に選択時にコピー
A27: 20 | C27: 顧客品名4 | L27: 文字列(1行) | S27: 4000 | AE27: ○ | AS27: DB参照時に選択時にコピー(顧客品名1+2)
A28: 21 | C28: 見積計算書No5 | L28: 文字列(1行) | S28: 4000 | AE28: ○ | AS28: DB参照時に選択時にコピー
A29: 22 | C29: 顧客品名5 | L29: 文字列(1行) | S29: 4000 | AE29: ○ | AS29: DB参照時に選択時にコピー(顧客品名1+2)
A30: 23 | C30: 見積計算書No6 | L30: 文字列(1行) | S30: 4000 | AE30: ○ | AS30: DB参照時に選択時にコピー
A31: 24 | C31: 顧客品名6 | L31: 文字列(1行) | S31: 4000 | AE31: ○ | AS31: DB参照時に選択時にコピー(顧客品名1+2)
... A35: 28 | C35: 顧客品名8 | L35: 文字列(1行) | S35: 4000 | AE35: ○ | AS35: DB参照時に選択時にコピー(顧客品名1+2)
A36: 29 | C36: 見積_添付ファイル | L36: 添付ファイル | S36: - | AS36: 見積計算書,御見積書
A37: 30 | C37: 木型・版型No1 | L37: DB 参照項目 | S37: - | AS37: 追加画面で設定
A38: 31 | C38: 木型・版型No2 | L38: DB 参照項目 | S38: - | AS38: 追加画面で設定
A39: 32 | C39: 木型・版型No3 | L39: DB 参照項目 | S39: - | AS39: 追加画面で設定
A40: 33 | C40: 木型・版型No4 | L40: DB 参照項目 | S40: - | AS40: 追加画面で設定
A41: 34 | C41: 木型・版型No5 | L41: DB 参照項目 | S41: - | AS41: 追加画面で設定
A42: 35 | C42: 木型・版型No6 | L42: DB 参照項目 | S42: - | AS42: 追加画面で設定
A43: 36 | C43: 木型・版型No7 | L43: DB 参照項目 | S43: - | AS43: 追加画面で設定
A44: 37 | C44: 木型・版型No8 | L44: DB 参照項目 | S44: - | AS44: 追加画面で設定
...

Sheet ⑩変更連絡依頼
A1: =表紙!A54 -> POWER EGG | K1: 文書名 | U1: モジュールID | Z1: =表紙!$AJ$63 -> MS | AE1: モジュール名 | AJ1: =表紙!$AX$63 -> POWER EGG | AS1: 文書番号 | AZ1: Version | BF1: Rev.
K2: アドオン設計書(フィールド設定) | U2: ｻﾌﾞﾓｼﾞｭｰﾙID | Z2: =表紙!$AJ$64 -> MSBB | AE2: ｻﾌﾞﾓｼﾞｭｰﾙ名 | AJ2: =表紙!$AX$64 -> POWER EGG | AS2: =表紙!$BL$64 -> M7-US-1140 | AZ2: =表紙!$BU$64 -> 7.0.2 | BF2: =表紙!$CB$64 -> 3
K3: =RIGHT(CELL("filename",$A$1),LEN(CELL("filename",$A$1))-FIND("]",CELL("filename",$A$1))) -> ⑩変更連絡依頼 | U3: 表題 | Z3: =表紙!$AJ$65 -> - | AE3: =表紙!$AQ$65 -> POWER EGG
A5: フィールド設定
A6: 区分 | C6: Webデータベース | L6: 明細行有無 | S6: 無 | V6: 備考
A7: No | C7: フィールド名 | L7: 形式 | S7: 桁数 | V7: 表示幅 | Y7: 半角英数字 | AC7: 必須 | AE7: ソート | AH7: 再利用 | AK7: キー | AM7: デフォルト値 | AS7: 説明
A8: 1 | C8: 申請者 | L8: 社員選択 | S8: - | AC8: ○ | AM8: ログイン社員 | AS8: 汎用申請システム項目(固定)
A9: 2 | C9: 申請日 | L9: 日付項目 | S9: - | AC9: ○ | AM9: @sys | AS9: 汎用申請システム項目
A10: 3 | C10: 件名 | L10: 文字列（1 行） | S10: 4000 | AC10: ○ | AS10: 汎用申請システム項目
A11: 4 | C11: 優先度 | L11: ラジオボタン | S11: - | AC11: ○ | AS11: 汎用申請システム項目(通常、緊急)
A12: 5 | C12: 担当 | L12: 社員選択 | S12: 4000 | AC12: ○ | AE12: ○ | AM12: ログイン社員
A13: 6 | C13: 手配NO | L13: DB 参照項目 | S13: - | AS13: 手配NO=受注NO
A14: 7 | C14: 手配NO_表示用 | L14: 文字列(1行) | S14: 4000 | AE14: ○ | AS14: DB参照時に選択時にコピー
A15: 8 | C15: 製品CD | L15: DB 参照項目 | S15: - | AS15: 製品CD=マスターNO
A16: 9 | C16: 製品CD_表示用 | L16: 文字列(1行) | S16: 4000 | AC16: ○ | AE16: ○ | AS16: DB参照時に選択時にコピー
A17: 10 | C17: CP品名1 | L17: 文字列(1行) | S17: 4000 | AE17: ○ | AS17: DB参照時に選択時にコピー | CD17: REV2.0:詳細設計時の打合せ内容の反映
A18: 11 | C18: CP品名2 | L18: 文字列(1行) | S18: 4000 | AE18: ○ | AS18: DB参照時に選択時にコピー
A19: 12 | C19: 得意先CD | L19: DB 参照項目 | S19: -
A20: 13 | C20: 得意先CD_表示用 | L20: 文字列(1行) | S20: 4000 | AC20: ○ | AE20: ○ | AS20: DB参照時に選択時にコピー
A21: 14 | C21: 得意先名 | L21: 文字列(1行) | S21: 4000 | AE21: ○ | AS21: DB参照時に選択時にコピー
A22: 15 | C22: 入力日 | L22: 日付項目 | S22: - | AC22: ○ | AE22: ○
A23: 16 | C23: 発行部署 | L23: 部門選択 | S23: - | AC23: ○ | AE23: ○ | AM23: ログイン社員の部門
A24: 17 | C24: 発行者 | L24: 社員選択 | S24: - | AC24: ○ | AE24: ○ | AM24: ログイン社員
A25: 18 | C25: 発行日 | L25: 日付項目 | S25: - | AC25: ○ | AE25: ○ | AM25: @sys
A26: 19 | C26: 発行時刻 | L26: 時刻項目 | S26: - | AC26: ○ | AE26: ○ | AM26: @sys
A27: 20 | C27: 変更年月日 | L27: 日付項目 | S27: - | AE27: ○
A28: 21 | C28: 変更範囲 | L28: チェックボックス | S28: - | AE28: ○ | AS28: マスター、受注、その他
A29: 22 | C29: 変更範囲その他 | L29: 文字列 | S29: 4000 | AE29: ○ | AS29: 変更範囲がその他の場合、入力する
A30: 23 | C30: 変更内容 | L30: チェックボックス | S30: - | AE30: ○ | AS30: 納期変更、数量変更、要因変更
A31: 24 | C31: 現状_数量 | L31: 数値 | S31: 10 | AE31: ○ | AS31: DB参照時に選択時にコピー
A32: 25 | C32: 現状_納期 | L32: 日付項目 | S32: - | AE32: ○ | AS32: DB参照時に選択時にコピー
A33: 26 | C33: 現状_納入先 | L33: 文字列(1行) | S33: 4000 | AE33: ○ | AS33: DB参照時に選択時にコピー
A34: 27 | C34: 現状_構成原紙(表) | L34: 文字列(1行) | S34: 4000 | AE34: ○ | AS34: DB参照時に選択時にコピー
A35: 28 | C35: 現状_構成原紙(中) | L35: 文字列(1行) | S35: 4000 | AE35: ○ | AS35: DB参照時に選択時にコピー
A36: 29 | C36: 現状_構成原紙(裏) | L36: 文字列(1行) | S36: 4000 | AE36: ○ | AS36: DB参照時に選択時にコピー
A37: 30 | C37: 変更_数量 | L37: 数値 | S37: 10 | AE37: ○
A38: 31 | C38: 変更_納期 | L38: 日付項目 | S38: - | AE38: ○
A39: 32 | C39: 変更_納入先 | L39: 文字列(1行) | S39: 4000 | AE39: ○
A40: 33 | C40: 変更_構成原紙(表) | L40: 文字列(1行) | S40: 4000 | AE40: ○
A41: 34 | C41: 変更_構成原紙(中) | L41: 文字列(1行) | S41: 4000 | AE41: ○
...

Sheet ⑪単価訂正
A1: =表紙!A54 -> POWER EGG | K1: 文書名 | U1: モジュールID | Z1: =表紙!$AJ$63 -> MS | AE1: モジュール名 | AJ1: =表紙!$AX$63 -> POWER EGG | AS1: 文書番号 | AZ1: Version | BF1: Rev.
K2: アドオン設計書(フィールド設定) | U2: ｻﾌﾞﾓｼﾞｭｰﾙID | Z2: =表紙!$AJ$64 -> MSBB | AE2: ｻﾌﾞﾓｼﾞｭｰﾙ名 | AJ2: =表紙!$AX$64 -> POWER EGG | AS2: =表紙!$BL$64 -> M7-US-1140 | AZ2: =表紙!$BU$64 -> 7.0.2 | BF2: =表紙!$CB$64 -> 3
K3: =RIGHT(CELL("filename",$A$1),LEN(CELL("filename",$A$1))-FIND("]",CELL("filename",$A$1))) -> ⑪単価訂正 | U3: 表題 | Z3: =表紙!$AJ$65 -> - | AE3: =表紙!$AQ$65 -> POWER EGG
A5: フィールド設定
A6: 区分 | C6: Webデータベース | L6: 明細行有無 | S6: 無 | V6: 備考 | AC6: API連携を想定
A7: No | C7: フィールド名 | L7: 形式 | S7: 桁数 | V7: 表示幅 | Y7: 半角英数字 | AC7: 必須 | AE7: ソート | AH7: 再利用 | AK7: キー | AM7: デフォルト値 | AS7: 説明
A8: 1 | C8: 申請者 | L8: 社員選択 | S8: - | AC8: ○ | AM8: ログイン社員 | AS8: 汎用申請システム項目(固定)
A9: 2 | C9: 申請日 | L9: 日付項目 | S9: - | AC9: ○ | AM9: @sys | AS9: 汎用申請システム項目
A10: 3 | C10: 件名 | L10: 文字列（1 行） | S10: 4000 | AC10: ○ | AS10: 汎用申請システム項目
A11: 4 | C11: 優先度 | L11: ラジオボタン | S11: - | AC11: ○ | AS11: 汎用申請システム項目(通常、緊急)
A12: 5 | C12: 手配NO1 | L12: 文字列(1行) | S12: 4000 | AE12: ○
A13: 6 | C13: 手配NO2 | L13: 文字列(1行) | S13: 4000 | AE13: ○
A14: 7 | C14: 手配NO3 | L14: 文字列(1行) | S14: 4000 | AE14: ○
A15: 8 | C15: 得意先 | L15: 文字列(1行) | S15: 4000 | AE15: ○
A16: 9 | C16: 得意先名 | L16: 文字列(1行) | S16: 4000 | AE16: ○
A17: 10 | C17: 注文書NO | L17: 文字列(1行) | S17: 4000 | AE17: ○
A18: 11 | C18: 製品CD/品目CD | L18: 文字列(1行) | S18: 4000 | AE18: ○
A19: 12 | C19: 品名1 | L19: 文字列(1行) | S19: 4000 | AE19: ○
A20: 13 | C20: 品名2 | L20: 文字列(1行) | S20: 4000 | AE20: ○
A21: 14 | C21: 受注日 | L21: 日付項目 | S21: - | AE21: ○
A22: 15 | C22: 客先納期 | L22: 日付項目 | S22: - | AE22: ○
A23: 16 | C23: 数量 | L23: 数値 | S23: 10 | AE23: ○
A24: 17 | C24: 単位 | L24: 文字列(1行) | S24: 4000 | AE24: ○
A25: 18 | C25: 特値 | L25: チェックボックス | S25: - | AE25: ○
A26: 19 | C26: 単価 | L26: 数値 | S26: 10,2 | AE26: ○
A27: 20 | C27: 単価変更理由 | L27: 文字列(1行) | S27: 4000 | AE27: ○
A28: 21 | C28: 個別単価(変更前) | L28: 数値 | S28: 10,2 | AE28: ○
A29: 22 | C29: セット単価(変更前) | L29: 数値 | S29: 10,2 | AE29: ○
A30: 23 | C30: 金額 | L30: 数値 | S30: 10,2 | AE30: ○
A31: 24 | C31: 納品先CD | L31: 文字列(1行) | S31: 4000 | AE31: ○
A32: 25 | C32: 納品先名 | L32: 文字列(1行) | S32: 4000 | AE32: ○
A33: 26 | C33: 製品区分_大 | L33: 文字列(1行) | S33: 4000 | AE33: ○
A34: 27 | C34: 製品区分_中 | L34: 文字列(1行) | S34: 4000 | AE34: ○
A35: 28 | C35: 製品区分_小 | L35: 文字列(1行) | S35: 4000 | AE35: ○
A36: 29 | C36: 不適合手配NO | L36: 文字列(1行) | S36: 4000 | AE36: ○
A37: 30 | C37: 納入備考 | L37: 文字列(1行) | S37: 4000 | AE37: ○
A38: 31 | C38: 伝票備考 | L38: 文字列(1行) | S38: 4000 | AE38: ○
A39: 32 | C39: 段 | L39: 文字列(1行) | S39: 4000 | AE39: ○
A40: 33 | C40: 表(構成情報) | L40: 文字列(1行) | S40: 4000 | AE40: ○
A41: 34 | C41: 中(構成情報) | L41: 文字列(1行) | S41: 4000 | AE41: ○
...

Sheet ⑫集金チェックリスト
A1: =表紙!A54 -> POWER EGG | K1: 文書名 | U1: モジュールID | Z1: =表紙!$AJ$63 -> MS | AE1: モジュール名 | AJ1: =表紙!$AX$63 -> POWER EGG | AS1: 文書番号 | AZ1: Version | BF1: Rev.
K2: アドオン設計書(フィールド設定) | U2: ｻﾌﾞﾓｼﾞｭｰﾙID | Z2: =表紙!$AJ$64 -> MSBB | AE2: ｻﾌﾞﾓｼﾞｭｰﾙ名 | AJ2: =表紙!$AX$64 -> POWER EGG | AS2: =表紙!$BL$64 -> M7-US-1140 | AZ2: =表紙!$BU$64 -> 7.0.2 | BF2: =表紙!$CB$64 -> 3
K3: =RIGHT(CELL("filename",$A$1),LEN(CELL("filename",$A$1))-FIND("]",CELL("filename",$A$1))) -> ⑫集金チェックリスト | U3: 表題 | Z3: =表紙!$AJ$65 -> - | AE3: =表紙!$AQ$65 -> POWER EGG
A5: フィールド設定
A6: 区分 | C6: 汎用申請 | L6: 明細行有無 | S6: 無 | V6: 備考
A7: No | C7: フィールド名 | L7: 形式 | S7: 桁数 | V7: 表示幅 | Y7: 半角英数字 | AC7: 必須 | AE7: ソート | AH7: 再利用 | AK7: キー | AM7: デフォルト値 | AS7: 説明
A8: 1 | C8: 申請者 | L8: 社員選択 | S8: - | AC8: ○ | AM8: ログイン社員 | AS8: 汎用申請システム項目(固定)
A9: 2 | C9: 申請日 | L9: 日付項目 | S9: - | AC9: ○ | AM9: @sys | AS9: 汎用申請システム項目
A10: 3 | C10: 件名 | L10: 文字列（1 行） | S10: 4000 | AC10: ○ | AS10: 汎用申請システム項目
A11: 4 | C11: 優先度 | L11: ラジオボタン | S11: - | AC11: ○ | AS11: 汎用申請システム項目(通常、緊急)
A12: 5 | C12: 添付ファイル | L12: 添付ファイル | S12: -
A13: 6 | C13: 申請メモ | L13: 複数行 | S13: 4000
A14: 7
A15: 8
A17: 集金チェックリスト 一覧表示画面編集
B19: データベース名 | J19: 集金チェックリスト
C21: ■画面一覧定義
C22: No | E22: 一覧表示画面名 | O22: 表示方法 | T22: 使用区分 | X22: 備考
C23: 1 | E23: （全項目） | O23: 一覧表示 | T23: 使用しない
C24: 2 | E24: 集金チェックリスト | O24: 一覧表示 | T24: 使用する
C26: ■画面イメージ
C34: ■画面定義
C35: 設定項目 | K35: 設定内容
C36: 画面名 | K36: 集金チェックリスト
C37: アクセス権限 | K37: 会社 | T37: 設定範囲 | AC37: 権限
K38: 全会社 | AC38: 参照可
C39: 表示方法 | K39: 一覧表示
C40: ソート条件 | K40: 項目 | AE40: ソート順
K41: No | AE41: 昇順
C44: 絞り込み条件
C45: 表示編集画面 | K45: 集金チェックリスト
C47: ■レイアウト設定
C48: No. | E48: 項目見出し書式 | P48: フィールド名 | AA48: 条件付き書式設定
C49: 1 | E49: No | P49: No
C50: 2 | E50: 登録日時 | P50: 登録日時
C51: 3 | E51: 登録者 | P51: 登録者
C52: 4 | E52: 最終更新日時 | P52: 最終更新日時
C53: 5 | E53: 最終更新者 | P53: 最終更新者
C54: 6 | E54: 申請受付番号 | P54: 申請受付番号
C55: 7 | E55: 申請者 | P55: 申請者
...

Sheet ⑬差額明細書
A1: =表紙!A54 -> POWER EGG | K1: 文書名 | U1: モジュールID | Z1: =表紙!$AJ$63 -> MS | AE1: モジュール名 | AJ1: =表紙!$AX$63 -> POWER EGG | AS1: 文書番号 | AZ1: Version | BF1: Rev.
K2: アドオン設計書(フィールド設定) | U2: ｻﾌﾞﾓｼﾞｭｰﾙID | Z2: =表紙!$AJ$64 -> MSBB | AE2: ｻﾌﾞﾓｼﾞｭｰﾙ名 | AJ2: =表紙!$AX$64 -> POWER EGG | AS2: =表紙!$BL$64 -> M7-US-1140 | AZ2: =表紙!$BU$64 -> 7.0.2 | BF2: =表紙!$CB$64 -> 3
K3: =RIGHT(CELL("filename",$A$1),LEN(CELL("filename",$A$1))-FIND("]",CELL("filename",$A$1))) -> ⑬差額明細書 | U3: 表題 | Z3: =表紙!$AJ$65 -> - | AE3: =表紙!$AQ$65 -> POWER EGG
A5: フィールド設定
A6: 区分 | C6: 汎用申請 | L6: 明細行有無 | S6: 無 | V6: 備考
A7: No | C7: フィールド名 | L7: 形式 | S7: 桁数 | V7: 表示幅 | Y7: 半角英数字 | AC7: 必須 | AE7: ソート | AH7: 再利用 | AK7: キー | AM7: デフォルト値 | AS7: 説明
A8: 1 | C8: 申請者 | L8: 社員選択 | S8: - | AC8: ○ | AM8: ログイン社員 | AS8: 汎用申請システム項目(固定)
A9: 2 | C9: 申請日 | L9: 日付項目 | S9: - | AC9: ○ | AM9: @sys | AS9: 汎用申請システム項目
A10: 3 | C10: 件名 | L10: 文字列（1 行） | S10: 4000 | AC10: ○ | AS10: 汎用申請システム項目
A11: 4 | C11: 優先度 | L11: ラジオボタン | S11: - | AC11: ○ | AS11: 汎用申請システム項目(通常、緊急)
A12: 5 | C12: 添付ファイル | L12: 添付ファイル | S12: -
A13: 6 | C13: 申請メモ | L13: 複数行 | S13: 4000
A14: 7
A15: 8
A17: 差額明細書 一覧表示画面編集
B19: データベース名 | J19: 差額明細書
C21: ■画面一覧定義
C22: No | E22: 一覧表示画面名 | O22: 表示方法 | T22: 使用区分 | X22: 備考
C23: 1 | E23: （全項目） | O23: 一覧表示 | T23: 使用しない
C24: 2 | E24: 差額明細書 | O24: 一覧表示 | T24: 使用する
C26: ■画面イメージ
C34: ■画面定義
C35: 設定項目 | K35: 設定内容
C36: 画面名 | K36: 差額明細書
C37: アクセス権限 | K37: 会社 | T37: 設定範囲 | AC37: 権限
K38: 全会社 | AC38: 参照可
C39: 表示方法 | K39: 一覧表示
C40: ソート条件 | K40: 項目 | AE40: ソート順
K41: No | AE41: 昇順
C44: 絞り込み条件
C45: 表示編集画面 | K45: 差額明細書
C47: ■レイアウト設定
C48: No. | E48: 項目見出し書式 | P48: フィールド名 | AA48: 条件付き書式設定
C49: 1 | E49: No | P49: No
C50: 2 | E50: 登録日時 | P50: 登録日時
C51: 3 | E51: 登録者 | P51: 登録者
C52: 4 | E52: 最終更新日時 | P52: 最終更新日時
C53: 5 | E53: 最終更新者 | P53: 最終更新者
C54: 6 | E54: 申請受付番号 | P54: 申請受付番号
C55: 7 | E55: 申請者 | P55: 申請者
...
