Workbook
Name Rev.: '[2]表紙（カスタマイズ）'!$U$22
Name Rev.: '表紙（カスタマイズ）'!$U$22
Name Revision: [2]表紙!$AP$5
Name Revision: 表紙!$AP$5
Name Ver.: '[2]表紙（カスタマイズ）'!$AE$26
Name Ver.: '表紙（カスタマイズ）'!$AE$26
Name Version: [2]表紙!$AJ$5
Name Version: 表紙!$AJ$5
Name ご確認者: '表紙（カスタマイズ）'!$AG$40
Name ご確認日: '表紙（カスタマイズ）'!$AG$42
Name サブシステム名: '表紙（カスタマイズ）'!$U$28
Name システム名: '表紙（カスタマイズ）'!$U$26
Name プロジェクト名: '表紙（カスタマイズ）'!$U$18
Name 開発区分: '表紙（カスタマイズ）'!$U$36
Name 機能ＩＤ: '表紙（カスタマイズ）'!$U$32
Name 機能区分: '表紙（カスタマイズ）'!$U$34
Name 機能名称: '表紙（カスタマイズ）'!$U$30
Name 顧客名: '表紙（カスタマイズ）'!$U$16
Name 最終更新者: '表紙（カスタマイズ）'!$AB$40
Name 最終更新日: '表紙（カスタマイズ）'!$AB$42
Name 作成者: '表紙（カスタマイズ）'!$W$40
Name 作成日: '表紙（カスタマイズ）'!$W$42
Name 章: '表紙（カスタマイズ）'!$M$10
Name 発行日: 表紙!$C$31
Name 文書番号: [2]表紙!$O$5
Name 文書番号: 表紙!$O$5
Name 文書番号_カスタマイズ: '[2]表紙（カスタマイズ）'!$U$20
Name 文書番号_カスタマイズ: '表紙（カスタマイズ）'!$U$20
Name 文書名: [2]表紙!$M$15
Name 文書名: 表紙!$M$15
Name 文書名_カスタマイズ: '[2]表紙（カスタマイズ）'!$M$10
Name 文書名_カスタマイズ: '表紙（カスタマイズ）'!$M$10

Sheet 表紙（カスタマイズ）
M7: 基本設計
M10: バッチ機能
M16: 顧客 | U16: 株式会社H
M18: プロジェクト名 | U18: ERPシステム
M20: 文書番号 | U20: J052-0-0001
M22: Ｒｅｖ． | U22: {=MAX(_xlfn.NUMBERVALUE('変更来歴（カスタマイズ）'!A6:A30))} -> 0.1
M24: 機密性区分 | U24: 取扱注意（Ｃ）
M26: システム名 | U26: mcframe7 | AC26: Ver. | AE26: 7.0.1
M28: サブモジュール | U28: 原価管理 | AW28: 業務共通
AW29: 原価管理
M30: 機能名 | U30: 配賦費用実績ＩＦ取込バッチ | AW30: 承認管理
AW31: 生産管理
M32: 機能ID | U32: MGBGB0020
M34: 機能区分 | U34: バッチ | AW34: 画面
AW35: 帳票
M36: 開発区分 | U36: カスタマイズ | AW36: バッチ
AW38: カスタマイズ
W39: 作成 | AB39: 最終更新 | AG39: ご確認 | AW39: アドオン
W40: {='変更来歴（カスタマイズ）'!AV6:AV6} -> MDSOL | AB40: =IF(COUNTA('変更来歴（カスタマイズ）'!AV6:AV30),INDEX('変更来歴（カスタマイズ）'!AV6:AV30,MATCH("*", '変更来歴（カスタマイズ）'!AV6:AV30,-1)),"") -> TBK
W42: {='変更来歴（カスタマイズ）'!AQ6:AQ6} -> 44102 | AB42: =MAX('変更来歴（カスタマイズ）'!AQ6:AQ30) -> 44699

Sheet 表紙
B3: mcframe 7 | O3: 文書番号 | U3: バッチID | AA3: バッチ名 | AJ3: Version | AP3: Revision
O5: M7-US-1311 | U5: MGBGB0020 | AA5: 配賦費用実績ＩＦ取込バッチ | AJ5: 7.0.1 | AP5: r01.01
B7: 【MGBG】配賦管理
M15: バッチ説明書
C29: 発行日
C31: 43008
A38: 共通（元データ）
A39: mcframe 7 | K39: 文書名 | U39: モジュールID | Z39: MG | AE39: モジュール名 | AJ39: 原価管理 | AS39: 文書番号 | AZ39: Version | BF39: Rev.
K40: =文書名 -> バッチ説明書 | U40: ｻﾌﾞﾓｼﾞｭｰﾙID | Z40: MGBG | AE40: ｻﾌﾞﾓｼﾞｭｰﾙ名 | AJ40: 配賦管理 | AS40: =文書番号 -> M7-US-1311 | AZ40: =Version -> 7.0.1 | BF40: =Revision -> r01.01
K41: =RIGHT(CELL("filename",$A$1),LEN(CELL("filename",$A$1))-FIND("]",CELL("filename",$A$1))) -> #VALUE! | U41: 表題 | Z41: MGBGB0020 | AE41: 配賦費用実績ＩＦ取込バッチ
A42: 共通（リンク用）
A43: =表紙!$A$39 -> mcframe 7 | K43: 文書名 | U43: モジュールID | Z43: =表紙!$Z$39 -> MG | AE43: モジュール名 | AJ43: =表紙!$AJ$39 -> 原価管理 | AS43: 文書番号 | AZ43: Version | BF43: Rev.
K44: =文書名 -> バッチ説明書 | U44: ｻﾌﾞﾓｼﾞｭｰﾙID | Z44: =表紙!$Z$40 -> MGBG | AE44: ｻﾌﾞﾓｼﾞｭｰﾙ名 | AJ44: =表紙!$AJ$40 -> 配賦管理 | AS44: =文書番号 -> M7-US-1311 | AZ44: =Version -> 7.0.1 | BF44: =Revision -> r01.01
K45: =RIGHT(CELL("filename",$A$1),LEN(CELL("filename",$A$1))-FIND("]",CELL("filename",$A$1))) -> #VALUE! | U45: 表題 | Z45: =表紙!$Z$41 -> MGBGB0020 | AE45: =表紙!$AE$41 -> 配賦費用実績ＩＦ取込バッチ
A47: 概要シート用
A48: =表紙!$A$39 -> mcframe 7 | O48: 文書名 | AC48: モジュールID | AJ48: =表紙!$Z$39 -> MG | AQ48: モジュール名 | AX48: =表紙!$AJ$39 -> 原価管理 | BL48: 文書番号 | BU48: Version | CB48: Rev.
O49: =文書名 -> バッチ説明書 | AC49: サブモジュールID | AJ49: =表紙!$Z$40 -> MGBG | AQ49: サブモジュール名 | AX49: =表紙!$AJ$40 -> 配賦管理 | BL49: =文書番号 -> M7-US-1311 | BU49: =Version -> 7.0.1 | CB49: =Revision -> r01.01
O50: =RIGHT(CELL("filename",$A$1),LEN(CELL("filename",$A$1))-FIND("]",CELL("filename",$A$1))) -> #VALUE! | AC50: 表題 | AJ50: =表紙!$Z$41 -> MGBGB0020 | AQ50: =表紙!$AE$41 -> 配賦費用実績ＩＦ取込バッチ

Sheet 変更来歴（カスタマイズ）
A1: =INDIRECT("表紙!$A$39") -> mcframe 7 | K1: 文書名 | U1: モジュールID | Z1: =INDIRECT("表紙!$Z$39") -> MG | AG1: モジュール名 | AL1: =INDIRECT("表紙!$AJ$39") -> 原価管理 | AU1: 文書番号 | BB1: Version | BH1: Rev.
K2: =文書名_カスタマイズ -> バッチ機能 | U2: ｻﾌﾞﾓｼﾞｭｰﾙID | Z2: =INDIRECT("表紙!$Z$40") -> MGBG | AG2: ｻﾌﾞﾓｼﾞｭｰﾙ名 | AL2: =INDIRECT("表紙!$AJ$40") -> 配賦管理 | AU2: =文書番号_カスタマイズ -> J052-0-0001 | BB2: =Ver. -> 7.0.1 | BH2: =Rev. -> 0.1
K3: =RIGHT(CELL("filename",$A$1),LEN(CELL("filename",$A$1))-FIND("]",CELL("filename",$A$1))) -> #VALUE! | U3: 表題 | Z3: =INDIRECT("表紙!$Z$41") -> MGBGB0020 | AG3: =INDIRECT("表紙!$AE$41") -> 配賦費用実績ＩＦ取込バッチ
A5: Rev. | E5: 変更内容 | W5: 変更・追加箇所 | AQ5: 作成更新日 | AV5: 作成更新者 | BA5: 備考
A6: 0.01 | E6: 初版作成 | AQ6: 44102 | AV6: MDSOL
A7: 0.02 | E7: 売上計上後の追加発生費用対応 | W7: 「機能概要」を追加する | AQ7: 44106 | AV7: MDSOL | BA7: 概要（カスタマイズ）
W8: 「他勘定入出庫データ登録処理」を追加する | BA8: 処理詳細
W9: 「3.他勘定入庫データ登録」、「4.他勘定出庫データ登録」を追加 | BA9: 更新入出力仕様
A10: 0.03 | E10: ミス・クレーム経費対応 | W10: 手配ＮＯ１と手配ＮＯ２で製番TOP品目を取得する。 | AQ10: 44119 | AV10: MDSOL | BA10: 処理詳細
A11: 0.04 | E11: ミス製番と営繕修理製番の固定品目運用対応 | W11: ミス製番と営繕修理製番の場合、固定品目を取得するロジックを追加 | AQ11: 44139 | AV11: MDSOL | BA11: 処理詳細
A12: 0.05 | E12: 詳細設計書作成 | AQ12: 44176 | AV12: TBK
A13: 0.06 | E13: 配賦費用受信時の固定品目設定対応 | W13: 「処理詳細」 4.1 品目ＣＤの設定を修正する | AQ13: 44298 | AV13: MDSOL | BA13: システム試験障害票対応（C0001、H0002）
E14: SSから取り込んだ部門CD（任意値）を固定値（AXXXM）に変換する
A15: 0.07 | E15: 配賦費用受信時0円エラー発生対応 | W15: 「処理詳細」配賦費用実績受信ＩＦの金額ゼロデータを処理対象外にする。 | AQ15: 44522 | AV15: MDSOL | BA15: 運用試験障害票対応（UN-047）
A16: 0.08 | E16: ミス製番とクレーム製番仕様変更対応 | W16: 「処理詳細」 4.1 (2)品目ＣＤの設定 | AQ16: 44635 | AV16: MDSOL | BA16: 運用試験障害票対応（UN-090）
A17: 0.09 | E17: 経費取込時に０円工数データが大量に作成される対応 | W17: 「処理詳細」 6.1（3）0円工数重複データチェックする | AQ17: 44691 | AV17: TBK | BA17: 運用試験障害票対応（UN-139）
A18: 0.10 | E18: 他勘定入出庫データが大量に作成される対応 | W18: 「処理詳細」 7.3（1）③他勘定入出庫登録可能チェック | AQ18: 44699 | AV18: TBK

Sheet 変更来歴
A1: =INDIRECT("表紙!$A$39") -> mcframe 7 | K1: 文書名 | U1: モジュールID | Z1: =INDIRECT("表紙!$Z$39") -> MG | AG1: モジュール名 | AL1: =INDIRECT("表紙!$AJ$39") -> 原価管理 | AU1: 文書番号 | BB1: Version | BH1: Rev.
K2: =文書名 -> バッチ説明書 | U2: ｻﾌﾞﾓｼﾞｭｰﾙID | Z2: =INDIRECT("表紙!$Z$40") -> MGBG | AG2: ｻﾌﾞﾓｼﾞｭｰﾙ名 | AL2: =INDIRECT("表紙!$AJ$40") -> 配賦管理 | AU2: =文書番号 -> M7-US-1311 | BB2: =Version -> 7.0.1 | BH2: =Revision -> r01.01
K3: =RIGHT(CELL("filename",$A$1),LEN(CELL("filename",$A$1))-FIND("]",CELL("filename",$A$1))) -> #VALUE! | U3: 表題 | Z3: =INDIRECT("表紙!$Z$41") -> MGBGB0020 | AG3: =INDIRECT("表紙!$AE$41") -> 配賦費用実績ＩＦ取込バッチ
A5: Rev. | I5: 変更内容 | Y5: 変更・追加箇所 | AS5: 発行日 | BA5: 備考
A6: r01.01 | I6: 初版作成 | AS6: 43008 | BA6: 2016
Y7: 12345
Y8: 12345
A35: 本ドキュメントの著作権は、東洋ビジネスエンジニアリング株式会社（B-EN-G）またはB-EN-Gのライセンサーに帰属します。

Sheet 概要
A1: =表紙!$A$39 -> mcframe 7 | O1: 文書名 | AC1: モジュールID | AJ1: =表紙!$Z$39 -> MG | AQ1: モジュール名 | AX1: =表紙!$AJ$39 -> 原価管理 | BL1: 文書番号 | BU1: Version | CB1: Rev.
O2: =文書名 -> バッチ説明書 | AC2: サブモジュールID | AJ2: =表紙!$Z$40 -> MGBG | AQ2: サブモジュール名 | AX2: =表紙!$AJ$40 -> 配賦管理 | BL2: =文書番号 -> M7-US-1311 | BU2: =Version -> 7.0.1 | CB2: =Revision -> r01.01
O3: =RIGHT(CELL("filename",$A$1),LEN(CELL("filename",$A$1))-FIND("]",CELL("filename",$A$1))) -> #VALUE! | AC3: 表題 | AJ3: =表紙!$Z$41 -> MGBGB0020 | AQ3: =表紙!$AE$41 -> 配賦費用実績ＩＦ取込バッチ
AO5: 概要
B7: 【説明】
C8: 他システムから受信した配賦費用実績データを配賦費用実績ＩＦデータに取り込むバッチ
B10: 【類似機能がある画面】
C11: なし
B13: 【目的】
C15: オペレーションＩＤ/名称 | O15: 目的（レベル１） | AC15: 目的（レベル２） | BF15: 利用シーン/補足
C16: ActAlcIf_Upd01 | O16: 他システムから受信した | BF16: 【利用シーン】
C17: 配賦費用実績ＩＦ取込 | O17: 配賦費用実績データを取り込む。 | BF17: ・他システムから配賦費用実績データを取り込み、原価管理で使用する場合。
B20: 【処理結果確認】
C21: ログ確認画面 | O21: 【バッチログ確認】画面
C22: 【バッチ・ＩＦデータ確認】画面 | O22: 使用する（修正可）
C23: 詳細確認画面 | O23: 【配賦費用実績ＩＦ一覧】画面
B25: 【処理関連図/サービス関連図】
C26: ■ActAlcIf_Upd01/配賦費用実績ＩＦ取込
U27: 更新処理
B43: 【オペレーション一覧】
C45: ID | O45: 処理名 | AB45: 処理概要
C46: ActAlcIf_Upd01 | O46: 配賦費用実績ＩＦ取込 | AB46: 他システムから受信した配賦費用実績受信インターフェースデータを配賦費用実績インターフェースに取り込む。
B48: 【SQLID一覧】
C49: なし
B51: 【自由記述】
C52: ■ | D52: 取込処理
C53: ・ | D53: 取込処理はデータＮＯの小さい順に、データＮＯ単位で行われる。ひとつのデータＮＯの取込処理が正常終了するたびにコミットが実行される。エラーが発生した場合はロールバックして、そこで取込処理は終了する（次のデータＮＯの処理には移らない）。
C54: ・ | D54: 取込処理は追加のみ行われる。更新は行われない。
C55: ・ | D55: 再取込がオンの場合、データＮＯ単位の処理の最初に取込先のデータが削除される。
C56: ・ | D56: 取込元の対象データは以下の条件で取得される。
D57: ○ | E57: 引数の年月ＦＲＯＭ≦年月≦引数の年月ＴＯ
D58: ○ | E58: 引数の計算カテゴリと一致（引数の計算カテゴリが未設定の場合は条件に含まれない）
D59: ○ | E59: 取込対象ＦＬＧがオン
D60: ○ | E60: ＰＧ実行状況区分が「1：未処理」「3：エラー」（ただし、再取込がオンの場合は条件に含まれない）
C61: ・ | D61: 取込処理の結果に応じて、受信ＩＦテーブルのＰＧ実行状況区分に以下の区分値が設定される。
D62: 「2：処理済」 | I62: 正常に取り込まれた場合に設定される。
D63: 「3：エラー」 | I63: エラーが発生した場合に設定される。
D64: 「4：スキップ」 | I64: 配賦科目ＣＤ、ワーキンググループＣＤを取得するために必要な以下のマスタが登録されていない場合に設定される。処理は中断されない。
I65: ・ | J65: 勘定科目対応マスタ、または、補助勘定科目対応マスタ
I66: ・ | J66: 配賦費用取込マスタ
...

Sheet 概要（カスタマイズ）
A1: =表紙!$A$39 -> mcframe 7 | O1: 文書名 | AC1: モジュールID | AJ1: =表紙!$Z$39 -> MG | AQ1: モジュール名 | AX1: =表紙!$AJ$39 -> 原価管理 | BL1: 文書番号 | BU1: Version | CB1: Rev.
O2: =文書名_カスタマイズ -> バッチ機能 | AC2: サブモジュールID | AJ2: =表紙!$Z$40 -> MGBG | AQ2: サブモジュール名 | AX2: =表紙!$AJ$40 -> 配賦管理 | BL2: =文書番号_カスタマイズ -> J052-0-0001 | BU2: =Ver. -> 7.0.1 | CB2: =Rev. -> 0.1
O3: =RIGHT(CELL("filename",$A$1),LEN(CELL("filename",$A$1))-FIND("]",CELL("filename",$A$1))) -> #VALUE! | AC3: 表題 | AJ3: =表紙!$Z$41 -> MGBGB0020 | AQ3: =表紙!$AE$41 -> 配賦費用実績ＩＦ取込バッチ
AO5: 概要
B7: 【業務要件】
C8: カスタマイズ | G8: 内容
C9: No.
C10: 23 | G10: SuperStream（残高マスタ）からmcframe（配賦費用実績）の連携時に、受信ＩＦにて入力データに、
G11: 費用配賦先の「対象製番」と「対象品目」を付加させ、原価計算時に適正な配賦計算を行う。
B14: 【機能概要】
C15: 1. | D15: SuperStreamからの費用連携（残高マスタ→部門別発生費用）において、
D16: mcframe側の受信ＩＦにて、以下の処理を行う。
D17: ・ | E17: 機能コード１、2を手配ＮＯ１、2として受信する | W17: ・・・ＰＪ特定のため
D18: ・ | E18: 製番TOP品目を設定する | W18: ・・・品目特定のため
D19: ・ | E19: ０円工数実績計上 | W19: ・・・配賦対象とするため
C20: 2. | D20: 売上計上後の費用連携の場合、製番TOP品目の他勘定入庫及び他勘定出庫データを登録する。
B22: 【前提条件】
C23: 1. | D23: 賦課対象品目は、製番TOP品目とする。
B25: 【起動タイミング】
C26: ・ | D26: 定期起動（1回/１か月）
C27: ・ | D27: 任意起動（汎用バッチオンライン実行）

Sheet 引数説明
A1: =表紙!$A$39 -> mcframe 7 | K1: 文書名 | U1: モジュールID | Z1: =表紙!$Z$39 -> MG | AE1: モジュール名 | AJ1: =表紙!$AJ$39 -> 原価管理 | AS1: 文書番号 | AZ1: Version | BF1: Rev.
K2: =文書名 -> バッチ説明書 | U2: ｻﾌﾞﾓｼﾞｭｰﾙID | Z2: =表紙!$Z$40 -> MGBG | AE2: ｻﾌﾞﾓｼﾞｭｰﾙ名 | AJ2: =表紙!$AJ$40 -> 配賦管理 | AS2: =文書番号 -> M7-US-1311 | AZ2: =Version -> 7.0.1 | BF2: =Revision -> r01.01
K3: =RIGHT(CELL("filename",$A$1),LEN(CELL("filename",$A$1))-FIND("]",CELL("filename",$A$1))) -> #VALUE! | U3: 表題 | Z3: =表紙!$Z$41 -> MGBGB0020 | AE3: =表紙!$AE$41 -> 配賦費用実績ＩＦ取込バッチ
B5: オペレーションＩＤ/名称：ActAlcIf_Upd01/配賦費用実績ＩＦ取込
A6: 必 | B6: 項目名 | N6: 説明 | AS6: 未設定時の振る舞い
A7: ● | B7: 年月ＦＲＯＭ | M7: 取込対象の開始年月を指定する。
A8: ● | B8: 年月ＴＯ | M8: 取込対象の終了年月を指定する。
B9: 計算カテゴリＣＤ | M9: 取込対象の計算カテゴリＣＤを指定する。 | AS9: すべての計算カテゴリを取込対象とする。
B10: ワーキンググループＣＤ | M10: 配賦費用実績ＩＦデータのワーキンググループＣＤに設定されるＣＤを指定する。 | AS10: マスタから取得したワーキンググループＣＤを設定する。
B11: 再取込 | M11: オンの場合、再取込する。 | AS11: 追加のみを行う。

Sheet 処理・サービス関連図
A1: =表紙!$A$39 -> mcframe 7 | K1: 文書名 | U1: モジュールID | Z1: =表紙!$Z$39 -> MG | AE1: モジュール名 | AJ1: =表紙!$AJ$39 -> 原価管理 | AS1: 文書番号 | AZ1: Version | BF1: Rev.
K2: =文書名_カスタマイズ -> バッチ機能 | U2: ｻﾌﾞﾓｼﾞｭｰﾙID | Z2: =表紙!$Z$40 -> MGBG | AE2: ｻﾌﾞﾓｼﾞｭｰﾙ名 | AJ2: =表紙!$AJ$40 -> 配賦管理 | AS2: =文書番号_カスタマイズ -> J052-0-0001 | AZ2: =Ver. -> 7.0.1 | BF2: =Rev. -> 0.1
K3: =RIGHT(CELL("filename",$A$1),LEN(CELL("filename",$A$1))-FIND("]",CELL("filename",$A$1))) -> #VALUE! | U3: 表題 | Z3: =表紙!$Z$41 -> MGBGB0020 | AE3: =表紙!$AE$41 -> 配賦費用実績ＩＦ取込バッチ
AT6: 凡例
BE7: 画面
AX9: 外部システムサービス | BE9: サービス
BE11: テーブル
BE13: サービス・テーブルのグループ
BE15: ファイル
BE17: 帳票

Sheet 処理詳細 (システム設計時)
A1: =表紙!$A$39 -> mcframe 7 | K1: 文書名 | U1: モジュールID | Z1: =表紙!$Z$39 -> MG | AE1: モジュール名 | AJ1: =表紙!$AJ$39 -> 原価管理 | AS1: 文書番号 | AZ1: Version | BF1: Rev.
K2: =文書名_カスタマイズ -> バッチ機能 | U2: ｻﾌﾞﾓｼﾞｭｰﾙID | Z2: =表紙!$Z$40 -> MGBG | AE2: ｻﾌﾞﾓｼﾞｭｰﾙ名 | AJ2: =表紙!$AJ$40 -> 配賦管理 | AS2: =文書番号_カスタマイズ -> J052-0-0001 | AZ2: =Ver. -> 7.0.1 | BF2: =Rev. -> 0.04
K3: =RIGHT(CELL("filename",$A$1),LEN(CELL("filename",$A$1))-FIND("]",CELL("filename",$A$1))) -> #VALUE! | U3: 表題 | Z3: =表紙!$Z$41 -> MGBGB0020 | AE3: =表紙!$AE$41 -> 配賦費用実績ＩＦ取込バッチ
A5: No | B5: 入力 | J5: 処理 | BD5: 出力
A6: 1 | B6: 受信変換
J7: 1. | K7: 開始をバッチログメッセージに出力する。 | BD7: 【バッチログメッセージ】
K8: ・標準から変更なし。
J10: 2. | K10: 配賦費用実績ＩＦ取込前チェックを行う。
K11: ・標準から変更なし。
B13: 【配賦費用実績受信ＩＦ】 | J13: 3. | K13: 配賦費用実績受信ＩＦから処理対象データを抽出する。
K14: ・標準から変更なし。
J16: 4. | K16: 処理対象データを編集する。
K17: ・品目ＣＤに製番TOP品目を設定する。
L18: 品目マスタから「メモ１」＝対象製番（※） 且つ 「品目分類」＝製番TOP品目 のレコードを取得する。
L19: ※ | M19: 手配ＮＯ２未指定の場合、対象製番＝手配ＮＯ１
M20: 手配ＮＯ２を指定した場合、対象製番＝手配ＮＯ１＋'-'+手配ＮＯ２
L21: 品目マスタからデータを取得できない場合、ミス製番（手配NO２が１～８０）と営繕修理製番（手配NO１が97始まり）の場合、汎用マスタから固定品目を取得する。
L22: 製番TOP品目を取得できない場合、または複数品目を取得した場合、品目ＣＤを設定しない。（配賦費用実績ＩＦデータとしては登録する。）
K23: ・手配ＮＯ１にＩＦ予備ＣＨＡＲ項目１を設定する。
K24: ・手配ＮＯ２にＩＦ予備ＣＨＡＲ項目２を設定する。
K26: ・下記項目以外は、標準から変更なし。
L27: ① | M27: 品目ＣＤ
L28: ② | M28: 手配ＮＯ１、手配ＮＯ２
J30: 5. | K30: 【配賦費用実績ＩＦ】の登録処理を実行する。 | BD30: 【配賦費用実績ＩＦ】
K31: ・標準から変更なし。
B33: 【汎用マスタ】 | J33: 6. | K33: 工数実績を登録する。 | BD33: 【工数実績】
K34: 【汎用マスタ】に設定されている配賦科目ＣＤに対して、工数実績を新規登録する。
B36: 【受注明細】 | J36: 7. | K36: 対象製番が売上計上済みの場合、製番TOP品目の他勘定入庫及び他勘定出庫データを登録する。
B37: 【売上実績明細】 | K37: ・条件
B38: 【汎用マスタ】 | L38: 以下すべての条件を満たす場合、売上計上済として扱う。
L39: ① | M39: 製番TOP品目の受注明細が存在する
L40: ② | M40: 製番TOP品目の受注明細の販売状況ステータスが「完了」になること
L41: ③ | M41: 配賦費用実績ＩＦ．計上月 ＞ 売上実績明細．計上月（最遅）
K42: ・処理
L43: 7.1 他勘定入庫データを登録する。 | BD43: 【他勘定振替実績ヘッダ】
M44: 項目設定仕様は「処理詳細」の「3.他勘定入庫データ登録」を参照 | BD44: 【他勘定振替実績明細】
L45: 7.2 他勘定出庫データを登録する。
M46: 項目設定仕様は「処理詳細」の「4.他勘定出庫データ登録」を参照
J48: 8. | K48: 終了をバッチログメッセージに出力する。 | BD48: 【バッチログメッセージ】
K49: ・標準から変更なし。

Sheet 処理詳細（ソフトウェア開発時）
A1: =表紙!$A$39 -> mcframe 7 | K1: 文書名 | U1: モジュールID | Z1: =表紙!$Z$39 -> MG | AE1: モジュール名 | AJ1: =表紙!$AJ$39 -> 原価管理 | AS1: 文書番号 | AZ1: Version | BF1: Rev.
K2: =文書名_カスタマイズ -> バッチ機能 | U2: ｻﾌﾞﾓｼﾞｭｰﾙID | Z2: =表紙!$Z$40 -> MGBG | AE2: ｻﾌﾞﾓｼﾞｭｰﾙ名 | AJ2: =表紙!$AJ$40 -> 配賦管理 | AS2: =文書番号_カスタマイズ -> J052-0-0001 | AZ2: =Ver. -> 7.0.1 | BF2: =Rev. -> 0.1
K3: =RIGHT(CELL("filename",$A$1),LEN(CELL("filename",$A$1))-FIND("]",CELL("filename",$A$1))) -> #VALUE! | U3: 表題 | Z3: =表紙!$Z$41 -> MGBGB0020 | AE3: =表紙!$AE$41 -> 配賦費用実績ＩＦ取込バッチ
A5: No | B5: 入力 | J5: 処理 | BD5: 出力
A6: 1 | B6: 受信変換
J7: 1. | K7: 開始をバッチログメッセージに出力する。 | BD7: 【バッチログメッセージ】
K8: ・標準から変更なし。
J10: 2. | K10: 配賦費用実績ＩＦ取込前チェックを行う。
K11: ・標準から変更なし。
B13: 【配賦費用実績受信ＩＦ】 | J13: 3. | K13: 配賦費用実績受信ＩＦから処理対象データを抽出する。
K15: 3.1 配賦費用実績受信ＩＦの金額 = 0円のデータを処理対象外にする。
K16: ※3.1（0円データ排除）以外は標準から変更なし。
J18: 4. | K18: 処理対象データを編集する。
K19: （注） | M19: 標準通り、上記3.で抽出した処理対象データを１件ずつ処理する。
K20: 4.1 | M20: 品目ＣＤの設定
L21: 特記：
M22: 製番TOP品目の取得仕様としては「バッチ機能_MSLAB1230_工数実績受信ＩＦ取込バッチ」と同じであるため、
M23: 以下の取得ロジックはMCData用ユーティリティ（MBUCL_MCDataUtil）にて共通化する。
M24: INPUT用の引数としては、「処理対象データ」ＩＦ予備ＣＨＡＲ項目１（手配ＮＯ１），
AA25: 「処理対象データ」ＩＦ予備ＣＨＡＲ項目２（手配ＮＯ２）とする。
B27: 【品目マスタ】 | L27: 品目ＣＤに、以下の抽出条件で取得した【品目マスタ】品目ＣＤで設定する。
L28: (1) | N28: 対象品目の特定
N29: ① | O29: 「処理対象データ」ＩＦ予備ＣＨＡＲ項目２（手配ＮＯ２） <> '*'の場合（手配ＮＯ２未指定）、
O30: 以下の抽出条件で特定する。
O31: ■抽出条件
P32: 【品目マスタ】メモ１（共通） | Z32: ＝ | AC32: 「処理対象データ」ＩＦ予備ＣＨＡＲ項目１（手配ＮＯ１）
N33: ② | O33: ①以外
O34: ■抽出条件
P35: 【品目マスタ】メモ１（共通） | Z35: ＝ | AC35: 「処理対象データ」ＩＦ予備ＣＨＡＲ項目１
AC36: ＋'-'＋「処理対象データ」ＩＦ予備ＣＨＡＲ項目２
L38: (2) | N38: 品目ＣＤの設定
N39: ① | O39: (1)で１件のみ抽出した場合、
O40: (1)で抽出した【品目マスタ】「品目ＣＤ」で設定する。
N42: ② | O42: (1)で０件を抽出した場合、
O43: a. | P43: 「処理対象データ」ＩＦ予備ＣＨＡＲ項目１が97（※営繕修理製番）始まりの場合
P44: 以下、汎用マスタから取得して設定する。
B46: 【汎用マスタ】 | P46: ■抽出仕様
Q47: SELECT
S48: 文字列１
Q49: FROM
...

Sheet 更新入出力仕様
A1: =表紙!$A$39 -> mcframe 7 | K1: 文書名 | U1: モジュールID | Z1: =表紙!$Z$39 -> MG | AE1: モジュール名 | AJ1: =表紙!$AJ$39 -> 原価管理 | AS1: 文書番号 | AZ1: Version | BF1: Rev.
K2: =文書名_カスタマイズ -> バッチ機能 | U2: ｻﾌﾞﾓｼﾞｭｰﾙID | Z2: =表紙!$Z$40 -> MGBG | AE2: ｻﾌﾞﾓｼﾞｭｰﾙ名 | AJ2: =表紙!$AJ$40 -> 配賦管理 | AS2: =文書番号_カスタマイズ -> J052-0-0001 | AZ2: =Ver. -> 7.0.1 | BF2: =Rev. -> 0.1
K3: =RIGHT(CELL("filename",$A$1),LEN(CELL("filename",$A$1))-FIND("]",CELL("filename",$A$1))) -> #VALUE! | U3: 表題 | Z3: =表紙!$Z$41 -> MGBGB0020 | AE3: =表紙!$AE$41 -> 配賦費用実績ＩＦ取込バッチ
A5: No | G5: 1 | S5: ロジック名称 | Z5: ActAlcIf_Upd01 | AH5: 備考 | AK5: 配賦費用実績ＩＦ取込
A6: 処理分類 | E6: 更新
A7: No | C7: 転送先 | V7: 転送元 | AQ7: 説明
C8: 種 | D8: オブジェクト | K8: 項目名 | V8: 種 | W8: オブジェクト | AF8: 項目名
A9: 1 | C9: T | D9: 配賦費用実績ＩＦ | K9: 品目ＣＤ | V9: T | W9: 配賦費用実績受信ＩＦ | AF9: - | AQ9: ＩＦ予備ＣＨＡＲ項目１とＩＦ予備ＣＨＡＲ項目２を抽出条件に、【品目マスタ】「品目ＣＤ」を特定して設定する。 ※詳細は処理詳細シートを参照
A10: 2 | C10: T | D10: 配賦費用実績ＩＦ | K10: 手配ＮＯ１ | V10: T | W10: 配賦費用実績受信ＩＦ | AF10: ＩＦ予備ＣＨＡＲ項目１ | AQ10: 機能コード１
A11: 3 | C11: T | D11: 配賦費用実績ＩＦ | K11: 手配ＮＯ２ | V11: T | W11: 配賦費用実績受信ＩＦ | AF11: ＩＦ予備ＣＨＡＲ項目２ | AQ11: 機能コード２
A13: No | G13: 2 | S13: ロジック名称 | Z13: ActAlcIf_Upd01 | AH13: 備考 | AK13: 工数実績登録
A14: 処理分類 | E14: 追加
A15: No | C15: 転送先 | V15: 転送元 | AQ15: 説明
C16: 種 | D16: オブジェクト | K16: 項目名 | V16: 種 | W16: オブジェクト | AF16: 項目名
A17: 1 | C17: T | D17: 工数実績 | K17: 工数実績ＮＯ | V17: T | AQ17: シーケンス（MSS_WKACT）より発番
A18: 2 | C18: T | D18: 工数実績 | K18: 製造実績ＮＯ | V18: T | AQ18: NULL
A19: 3 | C19: T | D19: 工数実績 | K19: 品目製造指図ＮＯ | V19: T | AQ19: NULL
A20: 4 | C20: T | D20: 工数実績 | K20: 工程実績ＮＯ | V20: T | AQ20: NULL
A21: 5 | C21: T | D21: 工数実績 | K21: 工数予定ＮＯ | V21: T | AQ21: NULL
A22: 6 | C22: T | D22: 工数実績 | K22: 分割連番 | V22: T | AQ22: NULL
A23: 7 | C23: T | D23: 工数実績 | K23: 工数管理ＣＤ | V23: T | W23: 汎用マスタ | AF23: 文字列１ | AQ23: 【汎用マスタ】汎用分類ＣＤ＝'G001'（0円工数作成対象配賦科目ＣＤ）、かつ 【汎用マスタ】キー１＝【配賦費用実績ＩＦ】配賦科目ＣＤ で抽出する。
A24: 8 | C24: T | D24: 工数実績 | K24: 工数 | V24: T | AQ24: 「1」固定
A25: 9 | C25: T | D25: 工数実績 | K25: 着手時刻 | V25: T | AQ25: NULL
A26: 10 | C26: T | D26: 工数実績 | K26: 終了時刻 | V26: T | AQ26: NULL
A27: 11 | C27: T | D27: 工数実績 | K27: 中断時間 | V27: T | AQ27: NULL
A28: 12 | C28: T | D28: 工数実績 | K28: 計上日 | V28: T | W28: 配賦費用実績ＩＦ | AF28: 年月
A29: 13 | C29: T | D29: 工数実績 | K29: 工数理由ＣＤ | V29: T | AQ29: NULL
A30: 14 | C30: T | D30: 工数実績 | K30: 自動工数計算更新許可ＦＬＧ | V30: T | AQ30: FALSE
A31: 15 | C31: T | D31: 工数実績 | K31: 勤務種類ＣＤ | V31: T | AQ31: NULL
A32: 16 | C32: T | D32: 工数実績 | K32: 部門ＣＤ | V32: T | W32: 配賦費用実績ＩＦ | AF32: 部門ＣＤ | AQ32: 部門ＣＤが非NULLの場合、優先で設定する。
V33: T | W33: 汎用マスタ | AF33: キー１ | AQ33: 部門ＣＤがNULLの場合、以下の条件で抽出して設定する。 【汎用マスタ】汎用分類ＣＤ＝'G002'（0円工数作成用設定）
A34: 17 | C34: T | D34: 工数実績 | K34: 場所ＣＤ | V34: T | W34: 配賦費用実績ＩＦ | AF34: 場所ＣＤ | AQ34: 場所ＣＤが非NULLの場合、優先で設定する。
V35: T | W35: 汎用マスタ | AF35: キー２ | AQ35: 場所ＣＤがNULLの場合、以下の条件で抽出して設定する。 【汎用マスタ】汎用分類ＣＤ＝'G002'（0円工数作成用設定）
A36: 18 | C36: T | D36: 工数実績 | K36: 棚・ラインＣＤ | V36: T | AQ36: NULL
A37: 19 | C37: T | D37: 工数実績 | K37: 作業者部門ＣＤ | V37: T | AQ37: NULL
A38: 20 | C38: T | D38: 工数実績 | K38: 作業者ＣＤ | V38: T | AQ38: NULL
A39: 21 | C39: T | D39: 工数実績 | K39: 工程ＣＤ | V39: T | AQ39: NULL
A40: 22 | C40: T | D40: 工数実績 | K40: 手配ＮＯ１ | V40: T | W40: 配賦費用実績ＩＦ | AF40: 手配ＮＯ１
A41: 23 | C41: T | D41: 工数実績 | K41: 手配ＮＯ２ | V41: T | W41: 配賦費用実績ＩＦ | AF41: 手配ＮＯ２
A42: 24 | C42: T | D42: 工数実績 | K42: 手配ＮＯ３ | V42: T | W42: 配賦費用実績ＩＦ | AF42: 手配ＮＯ３
...

Sheet メッセージ一覧
A1: =表紙!$A$39 -> mcframe 7 | K1: 文書名 | U1: モジュールID | Z1: =表紙!$Z$39 -> MG | AE1: モジュール名 | AJ1: =表紙!$AJ$39 -> 原価管理 | AS1: 文書番号 | AZ1: Version | BF1: Rev.
K2: バッチ説明書 | U2: ｻﾌﾞﾓｼﾞｭｰﾙID | Z2: =表紙!$Z$40 -> MGBG | AE2: ｻﾌﾞﾓｼﾞｭｰﾙ名 | AJ2: =表紙!$AJ$40 -> 配賦管理 | AS2: =文書番号 -> M7-US-1311 | AZ2: 7.0.1 | BF2: r01.01
K3: =RIGHT(CELL("filename",$A$1),LEN(CELL("filename",$A$1))-FIND("]",CELL("filename",$A$1))) -> #VALUE! | U3: 表題 | Z3: =表紙!$Z$41 -> MGBGB0020 | AE3: =表紙!$AE$41 -> 配賦費用実績ＩＦ取込バッチ
A5: No | C5: 新/変 | E5: 種別 | G5: メッセージ内容 | AQ5: 備考（パラメータ等） | BG5: メッセージID
A6: 1 | C6: 新 | E6: W | G6: 汎用マスタには登録されていません。 汎用分類ＣＤ：{1} | AQ6: {1}：汎用分類ＣＤ | BG6: MBUCLA0001
A7: 2 | C7: 新 | E7: W | G7: 汎用マスタに１件のみ登録してください。 汎用分類ＣＤ：{1} | AQ7: {1}：汎用分類ＣＤ | BG7: MBUCLA0002
A8: 3 | C8: 新 | E8: W | G8: 汎用マスタに１件のみ登録してください。 汎用分類ＣＤ：{1} キー１：{2} | AQ8: {1}：汎用分類ＣＤ {2}：キー１ | BG8: MBUCLA0003

Sheet バッチ・ＩＦデータ確認
A1: =表紙!$A$39 -> mcframe 7 | K1: 文書名 | U1: モジュールID | Z1: =表紙!$Z$39 -> MG | AE1: モジュール名 | AJ1: =表紙!$AJ$39 -> 原価管理 | AS1: 文書番号 | AZ1: Version | BF1: Rev.
K2: バッチ説明書 | U2: ｻﾌﾞﾓｼﾞｭｰﾙID | Z2: =表紙!$Z$40 -> MGBG | AE2: ｻﾌﾞﾓｼﾞｭｰﾙ名 | AJ2: =表紙!$AJ$40 -> 配賦管理 | AS2: =文書番号 -> M7-US-1311 | AZ2: 7.0.1 | BF2: r01.01
K3: =RIGHT(CELL("filename",$A$1),LEN(CELL("filename",$A$1))-FIND("]",CELL("filename",$A$1))) -> #VALUE! | U3: 表題 | Z3: =表紙!$Z$41 -> MGBGB0020 | AE3: =表紙!$AE$41 -> 配賦費用実績ＩＦ取込バッチ
B5: 検索 | N5: 説明
B6: データ行ＮＯ
B7: データＮＯ
B8: ＰＧ実行状況区分
B9: ＰＧ実行状況区分名
B10: データ更新区分
B11: データ更新区分名
B12: 外部システムＣＤ
B13: 外部システムデータＮＯ
B14: 外部システムデータ行ＮＯ
B15: 送信元レコード作成日時ＦＲＯＭ
B16: 送信元レコード作成日時ＴＯ
B17: 取込対象ＦＬＧ.true
... B32: 更新日時ＴＯ
B34: 一覧 | N34: 説明
B35: データ行ＮＯ
B36: データＮＯ
B37: ＰＧ実行状況区分 | M37: 取込された場合は「2:処理済」、チェック処理でエラーが発生した場合は「3:エラー」
B38: ＰＧ実行状況区分名
B39: 送受信状況区分
B40: 送受信状況区分名
B41: データ更新区分
B42: データ更新区分名
B43: 外部システムＣＤ
B44: 外部システムデータＮＯ
B45: 外部システムデータ行ＮＯ
B46: 送信元レコード作成日時
B47: 取込対象ＦＬＧ
B48: 計算カテゴリＣＤ
B49: 年月
... B91: 更新リクエストＮＯ

Sheet 補足説明
A1: =表紙!$A$39 -> mcframe 7 | K1: 文書名 | U1: モジュールID | Z1: =表紙!$Z$39 -> MG | AE1: モジュール名 | AJ1: =表紙!$AJ$39 -> 原価管理 | AS1: 文書番号 | AZ1: Version | BF1: Rev.
K2: =文書名_カスタマイズ -> バッチ機能 | U2: ｻﾌﾞﾓｼﾞｭｰﾙID | Z2: =表紙!$Z$40 -> MGBG | AE2: ｻﾌﾞﾓｼﾞｭｰﾙ名 | AJ2: =表紙!$AJ$40 -> 配賦管理 | AS2: =文書番号_カスタマイズ -> J052-0-0001 | AZ2: =Ver. -> 7.0.1 | BF2: =Rev. -> 0.1
K3: =RIGHT(CELL("filename",$A$1),LEN(CELL("filename",$A$1))-FIND("]",CELL("filename",$A$1))) -> #VALUE! | U3: 表題 | Z3: =表紙!$Z$41 -> MGBGB0020 | AE3: =表紙!$AE$41 -> 配賦費用実績ＩＦ取込バッチ
C9: 費用の分類
C10: 製番区分 | H10: 製番連番 | N10: 所要の発生源 | U10: PLM設定可否 | AA10: 取得仕様 | BC10: 複数件があった場合
C11: 本体 | H11: 通常 | N11: 受注登録 | U11: 〇 | AA11: 品目マスタから「メモ１」＝対象製番 且つ 「品目分類」＝製番TOP品目 のレコードを取得する | BC11: エラー
H12: ミス・クレーム | N12: 日次生産依頼 | U12: 〇
C13: 部品 | H13: 通常 | N13: 受注登録 | U13: 〇
H14: ミス・クレーム | N14: 日次生産依頼 | U14: 〇
C15: マル販 | N15: 受注登録 | U15: 〇
C16: サービス | N16: 受注登録 | U16: 〇
C17: 研究開発 | N17: ？ | U17: 〇 | AA17: 品目マスタから「メモ１」＝対象製番 且つ 「品目分類」＝製番TOP品目 のレコードを取得する
C18: 営繕修理 | N18: ？ | U18: ×
C19: 固定資産 | N19: ？ | U19: ×
