Workbook
Name Rev.: '[2]表紙（カスタマイズ）'!$U$22
Name Rev.: '表紙（カスタマイズ）'!$U$22
Name Revision: [2]表紙!$AP$5
Name Revision: 表紙!$AP$5
Name Ver.: '[2]表紙（カスタマイズ）'!$AE$26
Name Ver.: '表紙（カスタマイズ）'!$AE$26
Name Version: [2]表紙!$AJ$5
Name Version: 表紙!$AJ$5
Name ご確認者: '表紙（カスタマイズ）'!$AG$40
Name ご確認日: '表紙（カスタマイズ）'!$AG$42
Name サブシステム名: '表紙（カスタマイズ）'!$U$28
Name システム名: '表紙（カスタマイズ）'!$U$26
Name プロジェクト名: '表紙（カスタマイズ）'!$U$18
Name 開発区分: '表紙（カスタマイズ）'!$U$36
Name 機能ＩＤ: '表紙（カスタマイズ）'!$U$32
Name 機能区分: '表紙（カスタマイズ）'!$U$34
Name 機能名称: '表紙（カスタマイズ）'!$U$30
Name 顧客名: '表紙（カスタマイズ）'!$U$16
Name 最終更新者: '表紙（カスタマイズ）'!$AB$40
Name 最終更新日: '表紙（カスタマイズ）'!$AB$42
Name 作成者: '表紙（カスタマイズ）'!$W$40
Name 作成日: '表紙（カスタマイズ）'!$W$42
Name 章: '表紙（カスタマイズ）'!$M$10
Name 発行日: 表紙!$C$31
Name 文書番号: [2]表紙!$O$5
Name 文書番号: 表紙!$O$5
Name 文書番号_カスタマイズ: '[2]表紙（カスタマイズ）'!$U$20
Name 文書番号_カスタマイズ: '表紙（カスタマイズ）'!$U$20
Name 文書名: [2]表紙!$M$15
Name 文書名: 表紙!$M$15
Name 文書名_カスタマイズ: '[2]表紙（カスタマイズ）'!$M$10
Name 文書名_カスタマイズ: '表紙（カスタマイズ）'!$M$10

Sheet 表紙（カスタマイズ）
M7: 基本設計
M10: 画面機能
M16: 顧客 | U16: 株式会社H
M18: プロジェクト名 | U18: ERPシステム
M20: 文書番号 | U20: J052-0-0001
M22: Ｒｅｖ． | U22: {=MAX(_xlfn.NUMBERVALUE('変更来歴（カスタマイズ）'!A6:A30))} -> 0.04
M24: 機密性区分 | U24: 取扱注意（Ｃ）
M26: システム名 | U26: mcframe7 | AC26: Ver. | AE26: 7.0.1
M28: サブモジュール | U28: 購買管理 | AW28: 業務共通
AW29: 原価管理
M30: 機能名 | U30: 発注一覧登録 | AW30: 購買管理
AW31: 生産管理
M32: 機能ID | U32: MSBDP0090
M34: 機能区分 | U34: 画面 | AW34: 画面
AW35: 帳票
M36: 開発区分 | U36: カスタマイズ | AW36: バッチ
AW38: カスタマイズ
W39: 作成 | AB39: 最終更新 | AG39: ご確認 | AW39: アドオン
W40: ='変更来歴（カスタマイズ）'!AV6 -> MDSOL | AB40: =IF(COUNTA('変更来歴（カスタマイズ）'!AV6:AV30),INDEX('変更来歴（カスタマイズ）'!AV6:AV30,MATCH("*", '変更来歴（カスタマイズ）'!AV6:AV30,-1)),"") -> TBK
W42: ='変更来歴（カスタマイズ）'!AQ6 -> 44075 | AB42: =MAX('変更来歴（カスタマイズ）'!AQ6:AU30) -> 44230

Sheet 表紙
B3: mcframe 7 | O3: 文書番号 | U3: 画面ID | AA3: 画面名 | AJ3: Version | AP3: Revision
O5: M7-US-1104 | U5: MSBDP0090 | AA5: 発注一覧登録 | AJ5: 7.0.1 | AP5: r02.05
B7: 【MSBD】購買管理
M15: 画面説明書
C29: 発行日
C31: 43332
A38: 共通（元データ）
A39: mcframe 7 | K39: 文書名 | U39: モジュールID | Z39: MS | AE39: モジュール名 | AJ39: SCM | AS39: 文書番号 | AZ39: Version | BF39: Rev.
K40: =文書名 -> 画面説明書 | U40: ｻﾌﾞﾓｼﾞｭｰﾙID | Z40: MSBD | AE40: ｻﾌﾞﾓｼﾞｭｰﾙ名 | AJ40: 購買管理 | AS40: =文書番号 -> M7-US-1104 | AZ40: 7.0.0 | BF40: r00.01
K41: =RIGHT(CELL("filename",$A$1),LEN(CELL("filename",$A$1))-FIND("]",CELL("filename",$A$1))) -> 表紙 | U41: 表題 | Z41: MSBDP0090 | AE41: 発注一覧登録
A42: 共通（リンク用）
A43: =表紙!$A$39 -> mcframe 7 | K43: 文書名 | U43: モジュールID | Z43: =表紙!$Z$39 -> MS | AE43: モジュール名 | AJ43: =表紙!$AJ$39 -> SCM | AS43: 文書番号 | AZ43: Version | BF43: Rev.
K44: =文書名 -> 画面説明書 | U44: ｻﾌﾞﾓｼﾞｭｰﾙID | Z44: =表紙!$Z$40 -> MSBD | AE44: ｻﾌﾞﾓｼﾞｭｰﾙ名 | AJ44: =表紙!$AJ$40 -> 購買管理 | AS44: =文書番号 -> M7-US-1104 | AZ44: =Version -> 7.0.1 | BF44: =Revision -> r02.05
K45: =RIGHT(CELL("filename",$A$1),LEN(CELL("filename",$A$1))-FIND("]",CELL("filename",$A$1))) -> 表紙 | U45: 表題 | Z45: =表紙!$Z$41 -> MSBDP0090 | AE45: =表紙!$AE$41 -> 発注一覧登録
A47: 概要シート用
A48: =表紙!$A$39 -> mcframe 7 | O48: 文書名 | AC48: モジュールID | AJ48: =表紙!$Z$39 -> MS | AQ48: モジュール名 | AX48: =表紙!$AJ$39 -> SCM | BL48: 文書番号 | BU48: Version | CB48: Rev.
O49: =文書名 -> 画面説明書 | AC49: サブモジュールID | AJ49: =表紙!$Z$40 -> MSBD | AQ49: サブモジュール名 | AX49: =表紙!$AJ$40 -> 購買管理 | BL49: =文書番号 -> M7-US-1104 | BU49: =Version -> 7.0.1 | CB49: =Revision -> r02.05
O50: =RIGHT(CELL("filename",$A$1),LEN(CELL("filename",$A$1))-FIND("]",CELL("filename",$A$1))) -> 表紙 | AC50: 表題 | AJ50: =表紙!$Z$41 -> MSBDP0090 | AQ50: =表紙!$AE$41 -> 発注一覧登録

Sheet 変更来歴（カスタマイズ）
A1: =INDIRECT("表紙!$A$39") -> mcframe 7 | K1: 文書名 | U1: モジュールID | Z1: =INDIRECT("表紙!$Z$39") -> MS | AG1: モジュール名 | AL1: =INDIRECT("表紙!$AJ$39") -> SCM | AU1: 文書番号 | BB1: Version | BH1: Rev.
K2: 基本設計 | U2: ｻﾌﾞﾓｼﾞｭｰﾙID | Z2: =INDIRECT("表紙!$Z$40") -> MSBD | AG2: ｻﾌﾞﾓｼﾞｭｰﾙ名 | AL2: =INDIRECT("表紙!$AJ$40") -> 購買管理 | AU2: J052-0-0001 | BB2: 7.0.1 | BH2: =Rev. -> 0.04
K3: =RIGHT(CELL("filename",$A$1),LEN(CELL("filename",$A$1))-FIND("]",CELL("filename",$A$1))) -> 変更来歴（カスタマイズ） | U3: 表題 | Z3: =INDIRECT("表紙!$Z$41") -> MSBDP0090 | AG3: =INDIRECT("表紙!$AE$41") -> 発注一覧登録
A5: Rev. | E5: 変更内容 | W5: 変更・追加箇所 | AQ5: 作成更新日 | AV5: 作成更新者 | BA5: 備考
A6: 0.01 | E6: 初版作成 | AQ6: 44075 | AV6: MDSOL
A7: 0.02 | E7: レビュー対応 | W7: 帳票出力オプションの並び順変更 | AQ7: 44154 | AV7: MDSOL | BA7: 画面イメージ、項目説明（カスタマイズ）
W8: 新規発行、再発行（現品票）、再発行（現品票以外）ボタンの制御仕様 | BA8: 補足説明
E9: 協定品場合の購買単価チェックを追加する（課題No.144） | BA9: 概要（カスタマイズ）、処理詳細
A10: 0.03 | E10: 詳細設計書作成 | AQ10: 44172 | AV10: TBK
A11: 0.04 | E11: 詳細設計レビュー対応 | W11: 更新入出力仕様シートを追加 | AQ11: 44230 | AV11: TBK | BA11: 更新入出力仕様
W12: 発注済みのチェックロジック詳細を追加 | BA12: 処理詳細
E13: 開発QA-T-0001対応 | W13: 現品票印刷（明細）ボタンの追加 | BA13: 画面イメージ、項目説明（カスタマイズ）
E14: 開発QA-T-0006対応 | W14: 品目別名１の追加 | BA14: 概要（カスタマイズ）、項目説明（カスタマイズ）

Sheet 変更来歴
A1: =INDIRECT("表紙!$A$39") -> mcframe 7 | K1: 文書名 | U1: モジュールID | Z1: =INDIRECT("表紙!$Z$39") -> MS | AG1: モジュール名 | AL1: =INDIRECT("表紙!$AJ$39") -> SCM | AU1: 文書番号 | BB1: Version | BH1: Rev.
K2: =文書名 -> 画面説明書 | U2: ｻﾌﾞﾓｼﾞｭｰﾙID | Z2: =INDIRECT("表紙!$Z$40") -> MSBD | AG2: ｻﾌﾞﾓｼﾞｭｰﾙ名 | AL2: =INDIRECT("表紙!$AJ$40") -> 購買管理 | AU2: =文書番号 -> M7-US-1104 | BB2: =Version -> 7.0.1 | BH2: =Revision -> r02.05
K3: =RIGHT(CELL("filename",$A$1),LEN(CELL("filename",$A$1))-FIND("]",CELL("filename",$A$1))) -> 変更来歴 | U3: 表題 | Z3: =INDIRECT("表紙!$Z$41") -> MSBDP0090 | AG3: =INDIRECT("表紙!$AE$41") -> 発注一覧登録
A5: Rev. | I5: 変更内容 | Y5: 変更・追加箇所 | AS5: 発行日 | BA5: 備考
A6: r01.01 | I6: 初版作成 | AS6: 42916 | BA6: 2016
A7: r02.01 | I7: 変更注文書発行予定日の行コピー欄（「コ」の欄）に「コ」を記載 | Y7: 項目説明 | AS7: 43008
A8: 〃 | I8: 「変更注文書発行予定日」を「為替レート」の下に移動 | Y8: 項目説明 | AS8: 〃
A9: 〃 | I9: 検索の欄に「発注予定ＮＯ」を追加 | Y9: 項目説明 | AS9: 〃
A10: 〃 | I10: 「注文書発行日ＦＲＯＭ」、「注文書発行日ＴＯ」を削除 | Y10: 項目説明 | AS10: 〃
A11: 〃 | I11: 「注文書発行日」を「注文書発行日時」に変更。 | Y11: 項目説明 | AS11: 〃
A12: 〃 | I12: 複数明細のボリュームディスカウント単価取得機能追加に伴う修正。 ・目的の表で「発注予定のまとめ対象を選択する」の補足を削除 ・自由記述の「単票形式画面との差異」を削除 | Y12: 概要 | AS12: 〃
A13: 〃 | I13: 「削除可能」を「取消可能」に変更 | Y13: 項目説明 | AS13: 〃
A14: 〃 | I14: ソート順を追加 | Y14: 概要 | AS14: 〃
A15: 〃 | I15: データアクセスコントロールを追加 | Y15: 概要 | AS15: 〃
A16: 〃 | I16: 一覧ダブルクリックを追加 | Y16: 画面遷移 | AS16: 〃
A17: 〃 | I17: 一覧の「負担部門」をコンボボックスから入力補助に変更 | Y17: 項目説明 | AS17: 〃
A18: 〃 | I18: 検索に「直納区分」、「直納区分名」を追加 | Y18: 項目説明 | AS18: 〃
A19: 〃 | I19: 一覧に「納品先部署」「納品先担当者」「配送先部署」「配送先担当者」を追加 | Y19: 項目説明 | AS19: 〃
... A22: 〃 | I22: 画面イメージ差し替え | Y22: 画面イメージ | AS22: 〃
A23: r02.02 | I23: ・一覧の「外注」「製造場所」「製造場所名」「構成パタン」の項目位置を修正 ・一覧の「製造場所」「構成パタン」を入力可能にしリストロジック欄をコンボボックスに修正 ・一覧の「発注先」「製造場所」「メーカ」「発注予定作成元区分」の説明を修正 ・一覧の「発注予定作成元ＮＯ」の行コピー欄をクリア ・共通項目４の「行コピー」の説明を修正 | Y23: 項目説明 | AS23: 43199 | BA23: MS7011#107に伴う修正
A24: r02.03 | I24: 標準納入ＬＴの説明を修正 | Y24: 項目説明 | AS24: 43262
A25: 〃 | I25: 納入残数量の説明を修正 | Y25: 項目説明 | AS25: 〃 | BA25: MS7011#212に伴う修正
A26: r02.04 | I26: 「非同期」を追加 | Y26: 項目説明 | AS26: 43294 | BA26: MS7011#504に伴う修正
A27: 〃 | I27: 検索欄に「ＥＤＩ対象」枠を追加 | Y27: 項目説明 | AS27: 〃 | BA27: MS7011#600に伴う修正
A28: 〃 | I28: 一覧に以下の項目を追加。 今回ＥＤＩ、前回ＥＤＩ、ＥＤＩ予備文字列１、ＥＤＩ予備文字列２、ＥＤＩ予備文字列３、ＥＤＩ予備文字列４、ＥＤＩ予備文字列５、ＥＤＩ予備数値、ＥＤＩ予備日付、ＥＤＩ明細予備文字列１、ＥＤＩ明細予備文字列２、ＥＤＩ明細予備文字列３、ＥＤＩ明細予備文字列４、ＥＤＩ明細予備文字列５、ＥＤＩ明細予備数値、ＥＤＩ明細予備日付 | Y28: 項目説明 | AS28: 〃 | BA28: 〃
A29: 〃 | I29: 上記修正に伴い、画面イメージを修正 | Y29: 画面イメージ | AS29: 〃 | BA29: 〃
A30: r02.05 | I30: 【SQLID一覧】を修正 | Y30: 概要 | AS30: 43332 | BA30: MS7012#001に伴う修正
A31: 〃 | I31: ファイル入力について追記 | Y31: 〃 | AS31: 〃 | BA31: MS7012#004に伴う修正
A32: 〃 | I32: 一覧の入力可、ファイル入力の対象とする項目について修正 | Y32: 項目説明 | AS32: 〃
A35: 本ドキュメントの著作権は、東洋ビジネスエンジニアリング株式会社（B-EN-G）またはB-EN-Gのライセンサーに帰属します。

Sheet 概要（カスタマイズ）
A1: =INDIRECT("表紙!$A$39") -> mcframe 7 | O1: 文書名 | AC1: モジュールID | AJ1: =INDIRECT("表紙!$Z$39") -> MS | AQ1: モジュール名 | AX1: =INDIRECT("表紙!$AJ$39") -> SCM | BL1: 文書番号 | BU1: Version | CB1: Rev.
O2: =文書名_カスタマイズ -> 画面機能 | AC2: サブモジュールID | AJ2: =INDIRECT("表紙!$Z$40") -> MSBD | AQ2: サブモジュール名 | AX2: =INDIRECT("表紙!$AJ$40") -> 購買管理 | BL2: =文書番号_カスタマイズ -> J052-0-0001 | BU2: =Ver. -> 7.0.1 | CB2: =Rev. -> 0.04
O3: =RIGHT(CELL("filename",$A$1),LEN(CELL("filename",$A$1))-FIND("]",CELL("filename",$A$1))) -> 概要（カスタマイズ） | AC3: 表題 | AJ3: =INDIRECT("表紙!$Z$41") -> MSBDP0090 | AQ3: =INDIRECT("表紙!$AE$41") -> 発注一覧登録
AO5: 概要
B7: 【業務要件】
C8: カスタマイズ | G8: 内容
C9: No.
C10: 5 | G10: 発注登録画面または発注一覧登録画面より、注文書を発行する。画面にてオプション選択した場合には、同時に現品票も発行する。
G11: また、承認前に仮注文書を発行できる。
C12: 6 | G12: 発注登録画面または発注一覧登録画面より、発注入力時点で納品書、受領書、見積書を出力する。
B15: 【機能概要】
C16: 1. | D16: 下記帳票のチェックボックスを設け、個別に出力するかを指定可能とする。
D17: ・ | E17: 仮注文書
D18: ・ | E18: 現品票
D19: ・ | E19: 見積書
D20: ・ | E20: 納品書
D21: ・ | E21: 受領書
D22: ・ | E22: 注文書
C23: 2. | D23: 標準では伝票の最終承認後に帳票を出力可能となるが、発注入力完了時点で出力できるようにする。
D24: 帳票出力可否の制御詳細は補足説明シートを参照。
C25: 3. | D25: 注文書は承認前に注文書発行でき、その場合にはタイトルを「仮注文書」とする。
D26: 「現品票発行済ＦＬＧ」、「仮注文書発行済ＦＬＧ」をアドオンする。
C27: 4. | D27: 現品票は新規帳票（アドオン）とし、オプション選択にて、注文書と同時に発行できる。
C28: 5. | D28: mcframe標準の納品書と同一レイアウトで受領書、見積書も出力する。（タイトルのみ異なるイメージ）
C29: 6. | D29: 金額は見積書のみ出力するものとし、納品書、受領書には出力しない。（1円発注の場合、金額を印字しない）
C30: 7. | D30: 発注登録時、協定品の場合に購買単価マスタの登録有無をチェックし、登録がない場合エラー（処理継続不可）とする。
C31: 8. | D31: 検索項目に「品目別名１」を追加。
D32: 一覧項目に「品目別名１」を追加。
B34: 【前提条件】
C35: 特になし。

Sheet 概要
A1: =INDIRECT("表紙!$A$39") -> mcframe 7 | O1: 文書名 | AC1: モジュールID | AJ1: =INDIRECT("表紙!$Z$39") -> MS | AQ1: モジュール名 | AX1: =INDIRECT("表紙!$AJ$39") -> SCM | BL1: 文書番号 | BU1: Version | CB1: Rev.
O2: 画面説明書 | AC2: サブモジュールID | AJ2: =INDIRECT("表紙!$Z$40") -> MSBD | AQ2: サブモジュール名 | AX2: =INDIRECT("表紙!$AJ$40") -> 購買管理 | BL2: =文書番号 -> M7-US-1104 | BU2: =Version -> 7.0.1 | CB2: =Revision -> r02.05
O3: =RIGHT(CELL("filename",$A$1),LEN(CELL("filename",$A$1))-FIND("]",CELL("filename",$A$1))) -> 概要 | AC3: 表題 | AJ3: =INDIRECT("表紙!$Z$41") -> MSBDP0090 | AQ3: =INDIRECT("表紙!$AE$41") -> 発注一覧登録
AO5: 概要
B7: 【説明】
C8: 発注予定をもとにした発注、および計画外の発注を一括で登録する画面
B10: 【目的】
C12: 目的（レベル１） | Q12: 目的（レベル２） | AT12: 利用シーン/補足 | BV12: 操作種別/検索モード
C13: 発注を登録する。 | Q13: 発注予定を元にした発注を登録する。 | BV13: 登録する
Q14: 計画外の発注を登録する。 | BV14: 登録する
Q15: ファイル入力で発注データを一括で取り込む。 | AT15: 【利用シーン】 | BV15: 登録する
AT16: 別途用意した取り込み用のファイルを元にして一括で計画外の発注を登録する場合。
C17: 発注を取り消す。 | Q17: 発注ヘッダを取り消す。 | AT17: 【補足】 | BV17: 取り消す
AT18: 同一発注ヘッダの中の全明細を取り消すか、検索モードを「ヘッダ」にして取り消すと、
AT19: 注文書の取り消しとして扱われる。
Q20: 発注明細を取り消す。 | AT20: 【補足】 | BV20: 取り消す
AT21: 同一発注ヘッダ中の一部明細を取り消すと、注文書の訂正として扱われる。
AT22: （取り消した明細の行削除）
C23: 発注の進捗状況を確認する。 | Q23: 発注明細の購買状況区分で発注の進捗状況を確認する。 | BV23: 参照する
C24: 納期遅れを確認・分析する。 | Q24: 遅れ見込数を確認する。 | AT24: 【利用シーン】 | BV24: 参照する
Q25: ※発注明細の「遅れ見込数」を確認する。 | AT25: 発注後、購買状況区分が完了になるまでの間に、どの程度の遅れ（数量）が
AT26: 見込まれるかを分析する場合。
AT27: 【補足】
AT28: 自由記述の「発注状況の確認および分析方法について」を参照。
Q29: 納入希望日遅れを分析する。 | AT29: 【利用シーン】 | BV29: 参照する
AT30: 検索条件の「納入希望日遅れ」をオンで検索し、納入希望日
AT31: （発注時に指定した納入希望日）よりも遅い納入があった発注明細を
AT32: 分析する場合。
AT33: 【補足】
AT34: 自由記述の「発注状況の確認および分析方法について」を参照。
Q35: 回答納期遅れを分析する。 | AT35: 【利用シーン】 | BV35: 参照する
AT36: 検索条件の「回答納期日遅れ」をオンで検索し、
AT37: 発注先から受領した納期回答よりも遅い納入があった発注明細を分析する場合。
AT38: 【補足】
AT39: 自由記述の「発注状況の確認および分析方法について」を参照。
Q40: 進捗率を分析する。 | AT40: 【利用シーン】 | BV40: 参照する
Q41: ※発注明細の「入荷進捗率」、「仕入進捗率」で進捗の度合いを分析する。 | AT41: 入荷あるいは仕入が未完了の発注明細において、
AT42: 入荷あるいは仕入の進捗がどの程度かを分析する場合。
AT43: 【補足】
AT44: 自由記述の「発注状況の確認および分析方法について」を参照。
...

Sheet 画面イメージ
A1: =INDIRECT("表紙!$A$39") -> mcframe 7 | K1: 文書名 | U1: モジュールID | Z1: =INDIRECT("表紙!$Z$39") -> MS | AE1: モジュール名 | AJ1: =INDIRECT("表紙!$AJ$39") -> SCM | AS1: 文書番号 | AZ1: Version | BF1: Rev.
K2: 画面説明書 | U2: ｻﾌﾞﾓｼﾞｭｰﾙID | Z2: =INDIRECT("表紙!$Z$40") -> MSBD | AE2: ｻﾌﾞﾓｼﾞｭｰﾙ名 | AJ2: =INDIRECT("表紙!$AJ$40") -> 購買管理 | AS2: =文書番号 -> M7-US-1104 | AZ2: =Version -> 7.0.1 | BF2: =Rev. -> 0.04
K3: =RIGHT(CELL("filename",$A$1),LEN(CELL("filename",$A$1))-FIND("]",CELL("filename",$A$1))) -> 画面イメージ | U3: 表題 | Z3: =INDIRECT("表紙!$Z$41") -> MSBDP0090 | AE3: =INDIRECT("表紙!$AE$41") -> 発注一覧登録
A5: 画面イメージ

Sheet 項目説明（カスタマイズ）
A1: =INDIRECT("表紙!$A$39") -> mcframe 7 | K1: 文書名 | U1: モジュールID | Z1: =INDIRECT("表紙!$Z$39") -> MS | AE1: モジュール名 | AJ1: =INDIRECT("表紙!$AJ$39") -> SCM | AS1: 文書番号 | AZ1: Version | BF1: Rev.
K2: 画面説明書 | U2: ｻﾌﾞﾓｼﾞｭｰﾙID | Z2: =INDIRECT("表紙!$Z$40") -> MSBD | AE2: ｻﾌﾞﾓｼﾞｭｰﾙ名 | AJ2: =INDIRECT("表紙!$AJ$40") -> 購買管理 | AS2: =文書番号 -> M7-US-1104 | AZ2: =Version -> 7.0.1 | BF2: =Rev. -> 0.04
K3: =RIGHT(CELL("filename",$A$1),LEN(CELL("filename",$A$1))-FIND("]",CELL("filename",$A$1))) -> 項目説明（カスタマイズ） | U3: 表題 | Z3: =INDIRECT("表紙!$Z$41") -> MSBDP0090 | AE3: =INDIRECT("表紙!$AE$41") -> 発注一覧登録
A5: 変更 | D5: 操作種別 | N5: 説明 | BE5: リ | BF5: 型 | BG5: 参 | BH5: コ | BI5: 入 | BJ5: 非 | BK5: Ｏ
C6: ● | D6: 登録する | BF6: R
C7: ● | D7: まとめる | BF7: R
C8: ● | D8: 取り消す | BF8: R
C9: ● | D9: 参照する | BF9: R
C10: ● | D10: 帳票発行 | BF10: R
D12: 検索モード | N12: 説明 | BE12: リ | BF12: 型 | BG12: 参 | BH12: コ | BI12: 入 | BJ12: 非 | BK12: Ｏ
C13: ● | D13: 明細 | BF13: R
C14: ● | D14: ヘッダ | BF14: R
D16: 注文書 | N16: 説明 | BE16: リ | BF16: 型 | BG16: 参 | BH16: コ | BI16: 入 | BJ16: 非 | BK16: Ｏ
C17: ○ | D17: 未発行 | M17: 未発行データを検索対象とする場合にオンにする。 | BF17: F
C18: ○ | D18: 再発行 | M18: 再発行データを検索対象とする場合にオンにする。 | BF18: F
D20: 検索 > 発注承認状況 | N20: 説明 | BE20: リ | BF20: 型 | BG20: 参 | BH20: コ | BI20: 入 | BJ20: 非 | BK20: Ｏ
C21: ○ | D21: 未承認 | M21: 発注承認状況が未承認のデータを検索対象とする場合にオンにする。 | BF21: F
C22: ○ | D22: 一次承認済 | M22: 発注承認状況が一次承認済のデータを検索対象とする場合にオンにする。 | BF22: F
C23: ○ | D23: 最終承認済 | M23: 発注承認状況が最終承認済のデータを検索対象とする場合にオンにする。 | BF23: F
C24: ○ | D24: 却下 | M24: 発注承認状況が却下のデータを検索対象とする場合にオンにする。 | BF24: F
C25: ○ | D25: 否認 | M25: 発注承認状況が否認のデータを検索対象とする場合にオンにする。 | BF25: F
C26: ○ | D26: 対象外 | M26: 発注承認状況が対象外のデータを検索対象とする場合にオンにする。 | BF26: F
D28: 検索 > 諸口品 | N28: 説明 | BE28: リ | BF28: 型 | BG28: 参 | BH28: コ | BI28: 入 | BJ28: 非 | BK28: Ｏ
C29: ○ | D29: 通常品 | M29: 品目が通常品のデータを検索対象とする場合にオンにする。 | BF29: F
C30: ○ | D30: 諸口品 | M30: 品目が諸口品のデータを検索対象とする場合にオンにする。 | BF30: F
D32: 検索 > Ｉ／Ｖ取引対象 | N32: 説明 | BE32: リ | BF32: 型 | BG32: 参 | BH32: コ | BI32: 入 | BJ32: 非 | BK32: Ｏ
C33: ○ | D33: 対象 | M33: 発注先がインボイス取引対象のデータを検索対象とする場合にオンにする。 | BF33: F
C34: ○ | D34: 対象外 | M34: 発注先がインボイス取引対象ではないデータを検索対象とする場合にオンにする。 | BF34: F
D36: 検索 > ＥＤＩ対象 | N36: 説明 | BE36: リ | BF36: 型 | BG36: 参 | BH36: コ | BI36: 入 | BJ36: 非 | BK36: Ｏ
C37: ○ | D37: 対象 | M37: ・「登録する」「まとめる」種別 発注先がＥＤＩ発注送信対象の発注予定を検索する場合にオンにする。 ・「取り消す」「参照する」「帳票発行」 ＥＤＩで発注送信した発注データを検索する場合にオンにする。 | BF37: F
C38: ○ | D38: 対象外 | M38: ・「登録する」「まとめる」種別 発注先がＥＤＩ発注送信対象外の発注予定を検索する場合にオンにする。 ・「取り消す」「参照する」「帳票発行」 ＥＤＩで発注送信していない発注データを検索する場合にオンにする。 | BF38: F
D40: 検索 > 入荷 | N40: 説明 | BE40: リ | BF40: 型 | BG40: 参 | BH40: コ | BI40: 入 | BJ40: 非 | BK40: Ｏ
C41: ○ | D41: 未入荷 | M41: 未入荷のデータを検索対象とする場合にオンにする。 ※入荷実績の発生していないデータ | BF41: F
C42: ○ | D42: 一部入荷 | M42: 一部入荷のデータを検索対象とする場合にオンにする。 ※「入荷数量＜発注数量」かつ、入荷予定が打切りされていないデータ | BF42: F
C43: ○ | D43: 入荷完了 | M43: 入荷完了のデータを検索対象とする場合にオンにする。 ※「発注数量≦入荷数量」となっているか、入荷予定が打切りされているデータ | BF43: F
D45: 検索 > 仕入 | N45: 説明 | BE45: リ | BF45: 型 | BG45: 参 | BH45: コ | BI45: 入 | BJ45: 非 | BK45: Ｏ
C46: ○ | D46: 未仕入 | M46: 未仕入のデータを検索対象とする場合にオンにする。 ※仕入実績の発生していないデータ | BF46: F
C47: ○ | D47: 一部仕入 | M47: 一部仕入のデータを検索対象とする場合にオンにする。 ※「仕入数量＋検収不良数量＜発注数量」かつ、仕入予定が打切りされていないデータ | BF47: F
C48: ○ | D48: 仕入完了 | M48: 仕入完了のデータを検索対象とする場合にオンにする。 ※「発注数量≦仕入数量＋検収不良数量」となっているか、仕入予定が打切りされているデータ | BF48: F
D50: 検索 | N50: 説明 | BE50: リ | BF50: 型 | BG50: 参 | BH50: コ | BI50: 入 | BJ50: 非 | BK50: Ｏ
...

Sheet 項目説明
A1: =INDIRECT("表紙!$A$39") -> mcframe 7 | K1: 文書名 | U1: モジュールID | Z1: =INDIRECT("表紙!$Z$39") -> MS | AE1: モジュール名 | AJ1: =INDIRECT("表紙!$AJ$39") -> SCM | AS1: 文書番号 | AZ1: Version | BF1: Rev.
K2: 画面説明書 | U2: ｻﾌﾞﾓｼﾞｭｰﾙID | Z2: =INDIRECT("表紙!$Z$40") -> MSBD | AE2: ｻﾌﾞﾓｼﾞｭｰﾙ名 | AJ2: =INDIRECT("表紙!$AJ$40") -> 購買管理 | AS2: =文書番号 -> M7-US-1104 | AZ2: =Version -> 7.0.1 | BF2: =Revision -> r02.05
K3: =RIGHT(CELL("filename",$A$1),LEN(CELL("filename",$A$1))-FIND("]",CELL("filename",$A$1))) -> 項目説明 | U3: 表題 | Z3: =INDIRECT("表紙!$Z$41") -> MSBDP0090 | AE3: =INDIRECT("表紙!$AE$41") -> 発注一覧登録
B5: 操作種別 | N5: 説明 | BE5: リ | BF5: 型 | BG5: 参 | BH5: コ | BI5: 入 | BJ5: 非 | BK5: Ｏ
A6: ● | B6: 登録する | BF6: R
A7: ● | B7: まとめる | BF7: R
A8: ● | B8: 取り消す | BF8: R
A9: ● | B9: 参照する | BF9: R
A10: ● | B10: 帳票発行 | BF10: R
B12: 検索モード | N12: 説明 | BE12: リ | BF12: 型 | BG12: 参 | BH12: コ | BI12: 入 | BJ12: 非 | BK12: Ｏ
A13: ● | B13: 明細 | BF13: R
A14: ● | B14: ヘッダ | BF14: R
B16: 注文書 | N16: 説明 | BE16: リ | BF16: 型 | BG16: 参 | BH16: コ | BI16: 入 | BJ16: 非 | BK16: Ｏ
A17: ○ | B17: 未発行 | M17: 未発行データを検索対象とする場合にオンにする。 | BF17: F
A18: ○ | B18: 再発行 | M18: 再発行データを検索対象とする場合にオンにする。 | BF18: F
B20: 検索 > 発注承認状況 | N20: 説明 | BE20: リ | BF20: 型 | BG20: 参 | BH20: コ | BI20: 入 | BJ20: 非 | BK20: Ｏ
A21: ○ | B21: 未承認 | M21: 発注承認状況が未承認のデータを検索対象とする場合にオンにする。 | BF21: F
A22: ○ | B22: 一次承認済 | M22: 発注承認状況が一次承認済のデータを検索対象とする場合にオンにする。 | BF22: F
A23: ○ | B23: 最終承認済 | M23: 発注承認状況が最終承認済のデータを検索対象とする場合にオンにする。 | BF23: F
A24: ○ | B24: 却下 | M24: 発注承認状況が却下のデータを検索対象とする場合にオンにする。 | BF24: F
A25: ○ | B25: 否認 | M25: 発注承認状況が否認のデータを検索対象とする場合にオンにする。 | BF25: F
A26: ○ | B26: 対象外 | M26: 発注承認状況が対象外のデータを検索対象とする場合にオンにする。 | BF26: F
B28: 検索 > 諸口品 | N28: 説明 | BE28: リ | BF28: 型 | BG28: 参 | BH28: コ | BI28: 入 | BJ28: 非 | BK28: Ｏ
A29: ○ | B29: 通常品 | M29: 品目が通常品のデータを検索対象とする場合にオンにする。 | BF29: F
A30: ○ | B30: 諸口品 | M30: 品目が諸口品のデータを検索対象とする場合にオンにする。 | BF30: F
B32: 検索 > Ｉ／Ｖ取引対象 | N32: 説明 | BE32: リ | BF32: 型 | BG32: 参 | BH32: コ | BI32: 入 | BJ32: 非 | BK32: Ｏ
A33: ○ | B33: 対象 | M33: 発注先がインボイス取引対象のデータを検索対象とする場合にオンにする。 | BF33: F
A34: ○ | B34: 対象外 | M34: 発注先がインボイス取引対象ではないデータを検索対象とする場合にオンにする。 | BF34: F
B36: 検索 > ＥＤＩ対象 | N36: 説明 | BE36: リ | BF36: 型 | BG36: 参 | BH36: コ | BI36: 入 | BJ36: 非 | BK36: Ｏ
A37: ○ | B37: 対象 | M37: ・「登録する」「まとめる」種別 発注先がＥＤＩ発注送信対象の発注予定を検索する場合にオンにする。 ・「取り消す」「参照する」「帳票発行」 ＥＤＩで発注送信した発注データを検索する場合にオンにする。 | BF37: F
A38: ○ | B38: 対象外 | M38: ・「登録する」「まとめる」種別 発注先がＥＤＩ発注送信対象外の発注予定を検索する場合にオンにする。 ・「取り消す」「参照する」「帳票発行」 ＥＤＩで発注送信していない発注データを検索する場合にオンにする。 | BF38: F
B40: 検索 > 入荷 | N40: 説明 | BE40: リ | BF40: 型 | BG40: 参 | BH40: コ | BI40: 入 | BJ40: 非 | BK40: Ｏ
A41: ○ | B41: 未入荷 | M41: 未入荷のデータを検索対象とする場合にオンにする。 ※入荷実績の発生していないデータ | BF41: F
A42: ○ | B42: 一部入荷 | M42: 一部入荷のデータを検索対象とする場合にオンにする。 ※「入荷数量＜発注数量」かつ、入荷予定が打切りされていないデータ | BF42: F
A43: ○ | B43: 入荷完了 | M43: 入荷完了のデータを検索対象とする場合にオンにする。 ※「発注数量≦入荷数量」となっているか、入荷予定が打切りされているデータ | BF43: F
B45: 検索 > 仕入 | N45: 説明 | BE45: リ | BF45: 型 | BG45: 参 | BH45: コ | BI45: 入 | BJ45: 非 | BK45: Ｏ
A46: ○ | B46: 未仕入 | M46: 未仕入のデータを検索対象とする場合にオンにする。 ※仕入実績の発生していないデータ | BF46: F
A47: ○ | B47: 一部仕入 | M47: 一部仕入のデータを検索対象とする場合にオンにする。 ※「仕入数量＋検収不良数量＜発注数量」かつ、仕入予定が打切りされていないデータ | BF47: F
A48: ○ | B48: 仕入完了 | M48: 仕入完了のデータを検索対象とする場合にオンにする。 ※「発注数量≦仕入数量＋検収不良数量」となっているか、仕入予定が打切りされているデータ | BF48: F
B50: 検索 | N50: 説明 | BE50: リ | BF50: 型 | BG50: 参 | BH50: コ | BI50: 入 | BJ50: 非 | BK50: Ｏ
...

Sheet 画面遷移
A1: =表紙!$A$39 -> mcframe 7 | K1: 文書名 | U1: モジュールID | Z1: =表紙!$Z$39 -> MS | AE1: モジュール名 | AJ1: =表紙!$AJ$39 -> SCM | AS1: 文書番号 | AZ1: Version | BF1: Rev.
K2: =文書名 -> 画面説明書 | U2: ｻﾌﾞﾓｼﾞｭｰﾙID | Z2: =表紙!$Z$40 -> MSBD | AE2: ｻﾌﾞﾓｼﾞｭｰﾙ名 | AJ2: =表紙!$AJ$40 -> 購買管理 | AS2: =文書番号 -> M7-US-1104 | AZ2: =Version -> 7.0.1 | BF2: =Revision -> r02.05
K3: =RIGHT(CELL("filename",$A$1),LEN(CELL("filename",$A$1))-FIND("]",CELL("filename",$A$1))) -> 画面遷移 | U3: 表題 | Z3: =表紙!$Z$41 -> MSBDP0090 | AE3: =表紙!$AE$41 -> 発注一覧登録
A5: ID | D5: 処理名 | Y5: ダブルクリック対象 | AH5: ダブルクリック処理条件
A6: S01 | D6: 納期調整
B8: 遷移処理
B9: 遷移先画面ＩＤ | I9: MSBDP0120
B10: 遷移先画面名 | I10: 購買納期調整登録
B11: 遷移条件 | I11: 操作種別が「登録する」で登録後、操作種別が「取り消す」で登録前、操作種別が「参照する」のいずれか
B12: 引継項目・種別 | I12: 遷移元画面項目 | AJ12: 遷移先画面項目
I13: 発注明細ＮＯ（検索モードが「明細」の場合） | AJ13: 検索対象ＮＯ（発注明細ＮＯ)
AJ14: 操作種別：本画面の操作種別が「登録する」の場合、「納入指示」。
AJ15: それ以外は「参照する」
I16: 発注ＮＯ（検索モードが「ヘッダ」の場合） | AJ16: 検索対象ＮＯ（発注ＮＯ)
AJ17: 操作種別：「参照する」
B18: 遷移後のアクション | I18: 検索
A21: ID | D21: 処理名 | Y21: ダブルクリック対象 | AH21: ダブルクリック処理条件
A22: S02 | D22: 発注登録 | Y22: 一覧 | AH22: 操作種別が「取り消す」、「参照する」、「帳票発行」のいずれかである場合
B24: 遷移処理
B25: 遷移先画面ＩＤ | I25: MSBDP0080
B26: 遷移先画面名 | I26: 発注登録
B27: 遷移条件 | I27: 操作種別が「登録する」で登録後、操作種別が「取り消す」で登録前、操作種別が「参照する」・「まとめる」のいずれか
B28: 引継項目 | I28: 遷移元画面項目 | AJ28: 遷移先画面項目
I29: 発注ＮＯ | AJ29: 発注ＮＯ
AJ30: 操作種別：「参照する」
B31: 遷移後のアクション | I31: 検索
A37: ID | D37: 処理名 | Y37: ダブルクリック対象 | AH37: ダブルクリック処理条件
A38: S03 | D38: 仕入実績
B40: 遷移処理
B41: 遷移先画面ＩＤ | I41: MSBDP0140
B42: 遷移先画面名 | I42: 仕入実績登録
B43: 遷移条件 | I43: 操作種別が「登録する」で登録後、操作種別が「取り消す」で登録前、操作種別が「参照する」のいずれか、かつ、仕入対象外でない場合
B44: 引継項目 | I44: 遷移元画面項目 | AJ44: 遷移先画面項目
I45: 発注ＮＯ | AJ45: 検索対象ＮＯ（発注ＮＯ)
AJ46: 操作種別：「登録する」
B47: 遷移後のアクション | I47: 検索
A49: ID | D49: 処理名 | Y49: ダブルクリック対象 | AH49: ダブルクリック処理条件
A50: S04 | D50: 仕入直送
B52: 遷移処理
B53: 遷移先画面ＩＤ | I53: MSBBP1360
...

Sheet 処理・サービス関連図
A1: =INDIRECT("表紙!$A$39") -> mcframe 7 | O1: 文書名 | AC1: モジュールID | AJ1: =INDIRECT("表紙!$Z$39") -> MS | AQ1: モジュール名 | AX1: =INDIRECT("表紙!$AJ$39") -> SCM | BL1: 文書番号 | BU1: Version | CB1: Rev.
O2: =文書名_カスタマイズ -> 画面機能 | AC2: サブモジュールID | AJ2: =INDIRECT("表紙!$Z$40") -> MSBD | AQ2: サブモジュール名 | AX2: =INDIRECT("表紙!$AJ$40") -> 購買管理 | BL2: =文書番号_カスタマイズ -> J052-0-0001 | BU2: =Ver. -> 7.0.1 | CB2: =Rev. -> 0.04
O3: =RIGHT(CELL("filename",$A$1),LEN(CELL("filename",$A$1))-FIND("]",CELL("filename",$A$1))) -> 処理・サービス関連図 | AC3: 表題 | AJ3: =INDIRECT("表紙!$Z$41") -> MSBDP0090 | AQ3: =INDIRECT("表紙!$AE$41") -> 発注一覧登録
BQ6: 凡例
CB7: 画面
BU9: 外部システムサービス | CB9: サービス
CB11: テーブル
CB13: サービス・テーブルのグループ
CB15: ファイル
CB17: 帳票

Sheet 処理詳細 (システム設計時)
A1: mcframe 7 | K1: 文書名 | U1: モジュールID | Z1: =INDIRECT("表紙!$Z$39") -> MS | AE1: モジュール名 | AJ1: =INDIRECT("表紙!$AJ$39") -> SCM | AS1: 文書番号 | AZ1: Version | BF1: Rev.
K2: 画面機能 | U2: ｻﾌﾞﾓｼﾞｭｰﾙID | Z2: =INDIRECT("表紙!$Z$40") -> MSBD | AE2: ｻﾌﾞﾓｼﾞｭｰﾙ名 | AJ2: =INDIRECT("表紙!$AJ$40") -> 購買管理 | AS2: J052-0-0001 | AZ2: 7.0.1 | BF2: 0.02
K3: =RIGHT(CELL("filename",$A$1),LEN(CELL("filename",$A$1))-FIND("]",CELL("filename",$A$1))) -> 処理詳細 (システム設計時) | U3: 表題 | Z3: =INDIRECT("表紙!$Z$41") -> MSBDP0090 | AE3: =INDIRECT("表紙!$AE$41") -> 発注一覧登録
A5: No | B5: 入力 | J5: 処理 | BD5: 出力
A6: 1 | B6: Srch01/検索 | J6: 発注情報を検索する
K7: 標準から変更なし。
A9: 2 | B9: Srch02/検索 | J9: 発注予定を検索する
K10: 標準から変更なし。
A12: 3 | B12: Ins01/登録 | J12: 発注を登録する。
J13: 1. | K13: 発注情報の登録処理。 | BD13: 【発注ヘッダ】
K14: ・発注登録時、協定品の場合に購買単価マスタの登録有無をチェックし、登録がない場合エラー（処理継続不可）とする。 | BD14: 【発注明細】
K15: ・協定品場合の購買単価チェック以外は、標準から変更なし。
J17: 2. | K17: 承認提供サービス（MBBAL5010）を呼び出して、発注承認データを作成する。
K18: 2.1 | M18: 承認提供サービスを実行するための上り電文の設定を行う。
M19: ・承認作成元拡張項目１に「発注伝票区分」を設定する。
N20: 全発注明細が協定品の場合、「1：協定品発注伝票」を設定する。
N21: 全発注明細が通常品の場合、「2：通常品発注伝票」を設定する。
N22: 協定品と通常品が混在した場合、「2：通常品発注伝票」を設定する。
M23: ・承認作成元拡張項目１以外は標準通り。
K25: 2.2 | M25: 承認提供サービスを実行する。 | BD25: 【承認情報ヘッダ】
M26: ・標準から変更なし。 | BD26: 【承認情報明細】
A28: 4 | B28: Del01/取消 | J28: 発注を取り消す。
K29: 標準から変更なし。
A31: 5 | B31: Prnt01/帳票発行 | J31: 帳票を発行する。
J32: 1. | K32: 選択されているチェックボックスに応じて、帳票を発行する。
K33: 詳細仕様は「補足説明」を参照。

Sheet 処理詳細（ソフトウェア開発時）
A1: mcframe 7 | K1: 文書名 | U1: モジュールID | Z1: =INDIRECT("表紙!$Z$39") -> MS | AE1: モジュール名 | AJ1: =INDIRECT("表紙!$AJ$39") -> SCM | AQ1: 文書番号 | AX1: Version | BD1: Rev.
K2: =文書名_カスタマイズ -> 画面機能 | U2: ｻﾌﾞﾓｼﾞｭｰﾙID | Z2: =INDIRECT("表紙!$Z$40") -> MSBD | AE2: ｻﾌﾞﾓｼﾞｭｰﾙ名 | AJ2: =INDIRECT("表紙!$AJ$40") -> 購買管理 | AQ2: =文書番号_カスタマイズ -> J052-0-0001 | AX2: =Ver. -> 7.0.1 | BD2: =Rev. -> 0.04
K3: =RIGHT(CELL("filename",$A$1),LEN(CELL("filename",$A$1))-FIND("]",CELL("filename",$A$1))) -> 処理詳細（ソフトウェア開発時） | U3: 表題 | Z3: =INDIRECT("表紙!$Z$41") -> MSBDP0090 | AE3: =INDIRECT("表紙!$AE$41") -> 発注一覧登録
A5: No | B5: 入力 | J5: 処理 | BB5: 出力
A6: 1 | B6: Srch01/検索 | J6: 発注情報を検索する
K7: 標準から変更なし。
A9: 2 | B9: Srch02/検索 | J9: 発注予定を検索する
K10: 標準から変更なし。
A12: 3 | B12: Ins01/登録 | J12: 発注を登録する。
J13: 1. | K13: 発注情報の登録処理
K14: ・ | L14: 協定品（注）の場合に購買単価マスタの登録有無をチェックし、登録がない場合エラーメッセージを出し処理を中止する。 | BB14: メッセージID:
L15: （注） | N15: 協定品の判別は以下となる。 | BD15: MSBDLA0001
N16: 発注明細の発注品目の「品目分類ＣＤ４」='a'（※） | AH16: ※定数「協定品区分」で定義する。
AH17: ※「協定品区分」は複数指定不可。
L18: ■抽出条件
N19: 【購買単価マスタ】品目 | Z19: ＝ | AF19: 【発注明細】品目
N20: 【購買単価マスタ】単位 | Z20: ＝ | AF20: 【発注明細】取引単位
N21: 【購買単価マスタ】適用開始日 | Z21: ＝ | AF21: 運用日付
N22: 【購買単価マスタ】適用終了日 | Z22: ＝ | AF22: 運用日付
K24: ・ | L24: 協定品以外は、標準から変更なし。
J26: 2. | K26: 承認提供サービス（MBBAL5010）の呼び出し
K27: 上り電文の「承認作成元拡張項目１」を、以下の仕様で設定する。
K28: 発注ＮＯ単位で、すべての発注明細の発注品目の「品目分類ＣＤ４」が、
K29: ・ | L29: 同一値の場合、
L30: １件目の発注明細の発注品目の「品目分類ＣＤ４」を設定する。
K31: ・ | L31: 上記以外、
L32: NULLを設定する。
K34: 特記：
L35: 該当処理は、承認一覧登録画面でアドオンされた品目分類ＣＤ４の検索と表示するため。
L36: 詳細は、基本設計書の「画面機能_MBBAP0020_承認一覧登録」の「概要（カスタマイズ）」シートの【特記事項】NO.1を参照。
K38: 以外、標準から変更なし。
A41: 4 | B41: Del01/取消 | J41: 発注を取り消す。
K42: 標準から変更なし。
A44: 5 | B44: Prnt01/帳票発行 | J44: 帳票を発行する。
J45: 1. | K45: 操作種別：登録するの場合
K46: チェックオンの帳票（見積書、仮注文書、注文書、受領書、納品書、現品票）を出力する。
K47: 以外、標準から変更なし。
K48: 特記：
L49: 新規登録後に未承認となった発注の注文書は、標準の通り以下のエラーメッセージが出力される。
L50: メッセージＩＤ： | R50: MSBDL0014
...

Sheet 更新入出力仕様
A1: mcframe 7 | K1: 文書名 | U1: モジュールID | Z1: =INDIRECT("表紙!$Z$39") -> MS | AE1: モジュール名 | AJ1: =INDIRECT("表紙!$AJ$39") -> SCM | AQ1: 文書番号 | AX1: Version | BD1: Rev.
K2: =文書名_カスタマイズ -> 画面機能 | U2: ｻﾌﾞﾓｼﾞｭｰﾙID | Z2: =INDIRECT("表紙!$Z$40") -> MSBD | AE2: ｻﾌﾞﾓｼﾞｭｰﾙ名 | AJ2: =INDIRECT("表紙!$AJ$40") -> 購買管理 | AQ2: =文書番号_カスタマイズ -> J052-0-0001 | AX2: =Ver. -> 7.0.1 | BD2: =Rev. -> 0.04
K3: =RIGHT(CELL("filename",$A$1),LEN(CELL("filename",$A$1))-FIND("]",CELL("filename",$A$1))) -> 更新入出力仕様 | U3: 表題 | Z3: =INDIRECT("表紙!$Z$41") -> MSBDP0090 | AE3: =INDIRECT("表紙!$AE$41") -> 発注一覧登録
A5: No | P5: 1 | Q5: ボタン | AB5: 更新する | AO5: ロジック名称 | AZ5: Prnt01/帳票発行
A6: 備考 | F6: 【発注ヘッダ】の項目設定仕様
A7: No | D7: 転送先 | AB7: 転送元 | AZ7: 説明
D8: 種 | F8: オブジェクト | Q8: 項目名 | AB8: 種 | AD8: オブジェクト | AO8: 項目名
A9: =ROW()-8 -> 1 | D9: T | F9: 【発注ヘッダ】 | Q9: 注文書発行済ＦＬＧ | AB9: 画 | AD9: 共通項目４ | AO9: 注文書 | AZ9: 画面．注文書ＦＬＧ=オンの場合、発注NOをキーに【発注ヘッダ】注文書発行済ＦＬＧをオンに更新する。 ※【発注ヘッダ】発注改訂番号が上がった場合でも、注文書発行済ＦＬＧはオフにリセットしない。 | BK9: 開発QA-T-0003_発注一覧登録において、各種帳票再発行の定義について
A10: =ROW()-8 -> 2 | Q10: 見積書発行済ＦＬＧ | AB10: 画 | AD10: 共通項目４ | AO10: 見積書 | AZ10: 画面．見積書ＦＬＧ=オンの場合、発注NOをキーに【発注ヘッダ】見積書発行済ＦＬＧをオンに更新する。 ※【発注ヘッダ】発注改訂番号が上がった場合でも、見積書発行済ＦＬＧはオフにリセットしない。
A11: =ROW()-8 -> 3 | Q11: 仮注文書発行済ＦＬＧ | AB11: 画 | AD11: 共通項目４ | AO11: 仮注文書 | AZ11: 画面．仮注文書ＦＬＧ=オンの場合、発注NOをキーに【発注ヘッダ】仮注文書発行済ＦＬＧをオンに更新する。 ※【発注ヘッダ】発注改訂番号が上がった場合でも、仮注文書発行済ＦＬＧはオフにリセットしない。
A12: =ROW()-8 -> 4 | Q12: 納品書発行済ＦＬＧ | AB12: 画 | AD12: 共通項目４ | AO12: 納品書 | AZ12: 画面．納品書ＦＬＧ=オンの場合、発注NOをキーに【発注ヘッダ】納品書発行済ＦＬＧをオンに更新する。 ※【発注ヘッダ】発注改訂番号が上がった場合でも、納品書発行済ＦＬＧはオフにリセットしない。
A13: =ROW()-8 -> 5 | Q13: 受領書発行済ＦＬＧ | AB13: 画 | AD13: 共通項目４ | AO13: 受領書 | AZ13: 画面．受領書ＦＬＧ=オンの場合、発注NOをキーに【発注ヘッダ】受領書発行済ＦＬＧをオンに更新する。 ※【発注ヘッダ】発注改訂番号が上がった場合でも、受領書発行済ＦＬＧはオフにリセットしない。
A14: No | P14: 2 | Q14: ボタン | AB14: 更新する | AO14: ロジック名称 | AZ14: Prnt01/帳票発行
A15: 備考 | F15: 【発注明細】の項目設定仕様
A16: No | D16: 転送先 | AB16: 転送元 | AZ16: 説明
D17: 種 | F17: オブジェクト | Q17: 項目名 | AB17: 種 | AD17: オブジェクト | AO17: 項目名
A18: 1 | D18: T | F18: 【発注明細】 | Q18: 現品票発行済ＦＬＧ | AB18: 画 | AD18: 共通項目４ | AO18: 現品票 | AZ18: 画面．現品票ＦＬＧ=オンの場合、発注明細NOをキーに【発注明細】現品票発行済ＦＬＧをオンに更新する。 ※【発注明細】発注改訂番号が上がった場合でも、現品票発行済ＦＬＧはオフにリセットしない。

Sheet メッセージ一覧
A1: =INDIRECT("表紙!$A$39") -> mcframe 7 | O1: 文書名 | V1: モジュールID | AC1: =INDIRECT("表紙!$Z$39") -> MS | AJ1: モジュール名 | AQ1: =INDIRECT("表紙!$AJ$39") -> SCM | BE1: 文書番号 | BN1: Version | BU1: Rev.
O2: =文書名_カスタマイズ -> 画面機能 | V2: サブモジュールID | AC2: =INDIRECT("表紙!$Z$40") -> MSBD | AJ2: サブモジュール名 | AQ2: =INDIRECT("表紙!$AJ$40") -> 購買管理 | BE2: =文書番号_カスタマイズ -> J052-0-0001 | BN2: =Ver. -> 7.0.1 | BU2: =Rev. -> 0.04
O3: =RIGHT(CELL("filename",$A$1),LEN(CELL("filename",$A$1))-FIND("]",CELL("filename",$A$1))) -> メッセージ一覧 | V3: 表題 | AC3: =INDIRECT("表紙!$Z$41") -> MSBDP0090 | AJ3: =INDIRECT("表紙!$AE$41") -> 発注一覧登録
A5: No | C5: 新/変 | E5: 種別 | G5: メッセージ内容 | BE5: 備考（パラメータ等） | BU5: メッセージID
A6: 1 | C6: 新 | E6: W | G6: 協定品は購買単価マスタには登録する必要です。 品目ＣＤ：{1} | BE6: {1}：協定品の品目ＣＤ | BU6: MSBDLA0001
A7: 2 | C7: 新 | E7: W | G7: 発注取消データに対して、注文書以外の帳票は発行できません。 | BU7: MSBDPA0002
A8: 3 | C8: 新 | E8: W | G8: {1}がすでに発行済です。 行番号：{2} | BE8: {1}：以下の帳票種類名のいずれか 見積書、仮注文書、注文書、現品票、受領書、納品書 {2}：行番号 | BU8: MSBDPA0003
A9: 4 | C9: 新 | E9: W | G9: 最終承認済となった仮注文書は発行できません。 行番号：{1} | BE9: {1}：行番号 | BU9: MSBDPA0004
A10: 5 | C10: 新 | E10: W | G10: 現品票以外の帳票は発行できません。 | BU10: MSBDPA0005
A11: 6 | C11: 新 | E11: W | G11: 現品票を選択してください。 | BU11: MSBDPA0006
A12: 7 | C12: 新 | E12: W | G12: {1}は新規発行済ではないため、再発行できません。 行番号：{2} | BE12: {1}：以下の帳票種類名のいずれか 見積書、仮注文書、注文書、現品票、受領書、納品書 {2}：行番号 | BU12: MSBDPA0007
A13: 8 | C13: 新 | E13: W | G13: 現品票は発行できません。 | BU13: MSBDPA0008

Sheet 補足説明
A1: =INDIRECT("表紙!$A$39") -> mcframe 7 | O1: 文書名 | AC1: モジュールID | AJ1: =INDIRECT("表紙!$Z$39") -> MS | AQ1: モジュール名 | AX1: =INDIRECT("表紙!$AJ$39") -> SCM | BL1: 文書番号 | BU1: Version | CB1: Rev.
O2: =文書名_カスタマイズ -> 画面機能 | AC2: サブモジュールID | AJ2: =INDIRECT("表紙!$Z$40") -> MSBD | AQ2: サブモジュール名 | AX2: =INDIRECT("表紙!$AJ$40") -> 購買管理 | BL2: =文書番号_カスタマイズ -> J052-0-0001 | BU2: =Ver. -> 7.0.1 | CB2: =Rev. -> 0.04
O3: =RIGHT(CELL("filename",$A$1),LEN(CELL("filename",$A$1))-FIND("]",CELL("filename",$A$1))) -> 補足説明 | AC3: 表題 | AJ3: =INDIRECT("表紙!$Z$41") -> MSBDP0090 | AQ3: =INDIRECT("表紙!$AE$41") -> 発注一覧登録
B6: 1．各帳票の出力制御
C7: 承認前に、「仮注文書」を出力可能とする。
C8: 「注文書」は承認後のみ、出力可能とする。
C9: 発注伝票が承認対象外の場合、「仮注文書」も「注文書」も出力可能。
I11: 発注承認状況
I12: 未承認 | M12: 一次承認済 | S12: 最終承認済 | X12: 却下 | AA12: 否認 | AD12: 承認対象外 | AL12: 発注承認状況 各ステータスの内容は以下の通り。
C13: 見積書 | I13: 〇 | N13: 〇 | T13: 〇 | X13: 〇 | AA13: 〇 | AD13: 〇
C14: 仮注文書 | I14: 〇 | N14: 〇 | T14: × | X14: 〇 | AA14: 〇 | AD14: 〇
C15: 注文書 | I15: × | N15: × | T15: 〇 | X15: × | AA15: × | AD15: 〇
C16: 現品票 | I16: 〇 | N16: 〇 | T16: 〇 | X16: 〇 | AA16: 〇 | AD16: 〇
C17: 受領書 | I17: 〇 | N17: 〇 | T17: 〇 | X17: 〇 | AA17: 〇 | AD17: 〇
C18: 納品書 | I18: 〇 | N18: 〇 | T18: 〇 | X18: 〇 | AA18: 〇 | AD18: 〇
C20: ※ | E20: 発注取消データに対して、注文書を発行できる。
E21: 発注取消データに対して、注文書以外の帳票（仮注文書含む）は発行できない。
B23: 2．各帳票の金額印字仕様
I25: 単価・金額 | N25: 備考
I26: 印字
C27: 見積書 | I27: 〇 | N27: １円発注対応
C28: 注文書（仮） | I28: 〇 | N28: １円発注対応
C29: 注文書 | I29: 〇
C30: 現品票 | I30: ×
C31: 受領書 | I31: ×
C32: 納品書 | I32: ×
B34: 3．新規発行、再発行（現品票）、再発行（現品票以外）ボタンの制御仕様
C36: 帳票ごとの発行ステータス管理（発行済／未発行）は以下の粒度で行う。
I37: 管理粒度
C38: 見積書 | I38: 発注NO単位
C39: 注文書（仮）
C40: 注文書
C41: 受領書
C42: 納品書
C43: 現品票 | I43: 発注明細NO単位
C45: 新規発行、再発行（現品票）、再発行（現品票以外）ボタンの制御仕様は以下の通り。
H46: 発行済のみ(※1) | N46: 未発行のみ(※2) | U46: 発行済・未発行混在
C47: 新規発行 | H47: エラー | N47: - | U47: エラー
C48: 再発行 | H48: - | N48: エラー | U48: エラー
C50: ※1 発行対象帳票に対して、選択行は全て「発行済」の状態である
...
