Workbook

Sheet ﾚﾋﾞｭｰ評価ｼｰﾄ
F2: レビュー評価シート | S2: 作 成 日
N3: ※本評価シートは作業成果物に添付して，登録すること。
C4: ﾚﾋﾞｭｰ形式： （○を記入） | G4: ○ | H4: ピアレビュー | K4: 公式レビュー | N4: （注1） ：ピア/公式ﾚﾋﾞｭｰを行うドキュメントの場合の必須記入項目 （注2） ：計算式セル（入力不要）
B6: 担当 部課名 | I6: 部 | L6: 課 | M6: 作成者
B7: PID | F7: ー | J7: PJ件名 | L7: 株式会社クラウン・パッケージ新基幹システム導入
B9: レビュー対象 | D9: ﾄﾞｷｭﾒﾝﾄ番号/ﾌﾟﾛｸﾞﾗﾑ番号 | H9: =IF(査読ｼｰﾄ!C37="","（転記）",査読ｼｰﾄ!C37) -> （転記） | K9: ﾄﾞｷｭﾒﾝﾄ名/ﾌﾟﾛｸﾞﾗﾑ名 | N9: =IF(査読ｼｰﾄ!C38="","（転記）",査読ｼｰﾄ!C38) -> 単体試験要領書_MSBBPA100_【画面】WebFSC製品化チェックシート出力.xlsx
D10: 種類(該当に○) | F10: 要件定義書 | L10: 試験要領書 | Q10: プロジェクト実行計画書
F11: 基本設計書（外部仕様書） | L11: 試験成績書 | Q11: プロジェクト完了報告書
F12: 詳細設計書（内部仕様書） | K12: ○ | L12: ソースプログラムリスト | Q12: 結合テスト計画書
F13: プログラム仕様書 | L13: その他 | Q13: システムテスト計画書
D14: ドキュメント | G14: ページ数(頁) | J14: =IF(査読ｼｰﾄ!J37=0,"（転記）",査読ｼｰﾄ!J37) -> （転記） | K14: 作成工数（Hr）
D15: ソースプログラムリスト | G15: ライン数（KL） | J15: =IF(査読ｼｰﾄ!J38=0,"（転記）",査読ｼｰﾄ!J38) -> （転記） | K15: ﾓｼﾞｭｰﾙ数(個)
E17: (D) | F17: 計画段階での誤り | H17: D1：計画内容の抜け | O17: =査読ｼｰﾄ!N12 -> 0 | P17: 件 | R17: 体制 | S17: 区分 | T17: 名前 | V17: 人数
H18: D2：計画内容の誤り，不整合，記述不足 | O18: =査読ｼｰﾄ!Q12 -> 0 | P18: 件 | S18: 当該仕様担当者
H19: DZ：その他 | O19: =査読ｼｰﾄ!T12 -> 0 | P19: 件 | S19: 上位仕様担当者
B20: レビュー結果 | D20: 誤り分類 | E20: (0) | F20: 要件定義段階での誤り | H20: 0A:要件の抜け及び解釈誤り | O20: =査読ｼｰﾄ!W12 -> 0 | P20: 件 | S20: 下位仕様担当者
H21: 0B:要件定義の誤り | O21: =査読ｼｰﾄ!Z12 -> 0 | P21: 件 | S21: 営業担当者
H22: 0C:システム化対象範囲外とのインターフェースの誤り | O22: =査読ｼｰﾄ!AC12 -> 0 | P22: 件 | S22: ＰＪ外有識者（QA)
H23: 0Z:その他 | O23: =査読ｼｰﾄ!AF12 -> 0 | P23: 件 | S23: 製外
E24: (1) | F24: 基本設計（外部設計）段階での誤り | H24: 1A:外部仕様の抜け及び要件定義の解釈誤り | O24: =査読ｼｰﾄ!AI12 -> 0 | P24: 件 | S24: PL
H25: 1B:外部仕様の誤り | O25: =査読ｼｰﾄ!AL12 -> 0 | P25: 件 | S25: QR
H26: 1C:機能間インターフェース仕様の誤り | O26: =査読ｼｰﾄ!AO12 -> 0 | P26: 件 | S26: その他
H27: 1Z:その他 | O27: =査読ｼｰﾄ!AR12 -> 0 | P27: 件
E28: (2) | F28: 詳細設計/プログラム設計(内部設計)段階での誤り | H28: 2A:内部設計漏れ及び外部仕様の解釈誤り | O28: =査読ｼｰﾄ!AU12 -> 0 | P28: 件 | S28: 合 計 （人） | V28: =SUM(V18:W27) -> 0
H29: 2B:内部設計の誤り | O29: =査読ｼｰﾄ!AX12 -> 0 | P29: 件
H30: 2C:モジュール間インターフェース仕様の誤り | O30: =査読ｼｰﾄ!BA12 -> 0 | P30: 件 | R30: 品質目標 | S30: 基準 | T30: 計画 | V30: 実績
H31: 2Z:その他 | O31: =査読ｼｰﾄ!BD12 -> 0 | P31: 件 | S31: ドキュメントレビュー 指摘率(件/頁) | V31: =IF(J14="（転記）",0,J45/J14) -> 0
E32: (3) | F32: コーディング段階での誤り | H32: 3A:設計どおりのコーディングがされていない | O32: =査読ｼｰﾄ!BG12 -> 0 | P32: 件
H33: 3B:不注意なコーディング・ミス | O33: =査読ｼｰﾄ!BJ12 -> 0 | P33: 件 | S33: ドキュメントレビュー 誤り指摘率(件/頁) | V33: =IF(J14="（転記）",0,N45/J14) -> 0
H34: 3Z:その他 | O34: =査読ｼｰﾄ!BP12 -> 0 | P34: 件
E35: (4) | F35: その他 | H35: 4A:お客様からの仕様変更 | O35: =査読ｼｰﾄ!BS12 -> 0 | P35: 件 | S35: コードレビュー 指摘率(件/KL) | V35: =IF(J15="（転記）",0,J45/J15) -> 0
H36: 4B:表現不備(誤字/脱字など) | O36: =査読ｼｰﾄ!BV12 -> 0 | P36: 件
E37: (5) | F37: 試験段階での誤り | H37: 5A:仕様の解釈誤り | O37: =査読ｼｰﾄ!CE12 -> 0 | P37: 件 | S37: コードレビュー 誤り指摘率(件/KL) | V37: =IF(J15="（転記）",0,N45/J15) -> 0
H38: 5B:試験仕様の誤り | O38: =査読ｼｰﾄ!CH12 -> 0 | P38: 件
H39: 5C:試験プログラム/データの誤り | O39: =査読ｼｰﾄ!CK12 -> 0 | P39: 件 | S39: ドキュメントレビュー 密度(Ｈｒ/頁) | V39: =IF(J14="（転記）",0,O46/J14) -> 0
H40: 5D:試験項目抜け | O40: =査読ｼｰﾄ!CN12 -> 0 | P40: 件
H41: 5Z:その他 | O41: =査読ｼｰﾄ!CQ12 -> 0 | P41: 件 | S41: コードレビュー 密度(Ｈｒ/KL) | V41: =IF(J15="（転記）",0,O46/J15) -> 0
E42: (6) | F42: プロ完段階での誤り | H42: 6A：報告内容の抜け | O42: =査読ｼｰﾄ!CT12 -> 0 | P42: 件
H43: 6B：報告内容の誤り，不整合，記述不足 | O43: =査読ｼｰﾄ!CW12 -> 0 | P43: 件
H44: 6Z：その他 | O44: =査読ｼｰﾄ!CZ12 -> 0 | P44: 件
...

Sheet 査読ｼｰﾄ記入要領
L1: ＜査読シートの誤り分類の集計＞
L3: 誤り分類 | N3: 件数 | O3: 誤り分類 | Q3: 件数 | R3: 誤り分類 | T3: 件数 | U3: 誤り分類 | W3: 件数 | X3: 誤り分類 | Z3: 件数 | AA3: 誤り分類 | AC3: 件数 | AD3: 誤り分類 | AF3: 件数 | AG3: 誤り分類 | AI3: 件数 | AJ3: 誤り分類 | AL3: 件数 | AM3: 誤り分類 | AO3: 件数 | AP3: 誤り分類 | AR3: 件数 | AS3: 誤り分類 | AU3: 件数 | AV3: 誤り分類 | AX3: 件数 | AY3: 誤り分類 | BA3: 件数 | BB3: 誤り分類 | BD3: 件数 | BE3: 誤り分類 | BG3: 件数 | BH3: 誤り分類 | BJ3: 件数 | BK3: 誤り分類 | BM3: 件数 | BN3: 誤り分類 | BP3: 件数 | BQ3: 誤り分類 | BS3: 件数 | BT3: 誤り分類 | BV3: 件数 | BW3: 誤り分類 | BY3: 件数 | BZ3: 誤り分類 | CB3: 件数 | CC3: 誤り分類 | CE3: 件数 | CF3: 誤り分類 | CH3: 件数 | CI3: 誤り分類 | CK3: 件数 | CL3: 誤り分類 | CN3: 件数 | CO3: 誤り分類 | CQ3: 件数 | CR3: 誤り分類 | CT3: 件数 | CU3: 誤り分類 | CW3: 件数 | CX3: 誤り分類 | CZ3: 件数
L4: Ｄ１ | N4: =IF(ISNUMBER(DCOUNTA(査読範囲,L3,L3:L4)), DCOUNTA(査読範囲,L3,L3:L4), 0) -> 0 | O4: Ｄ２ | Q4: =IF(ISNUMBER(DCOUNTA(査読範囲,O3,O3:O4)), DCOUNTA(査読範囲,O3,O3:O4), 0) -> 0 | R4: ＤＺ | T4: =IF(ISNUMBER(DCOUNTA(査読範囲,R3,R3:R4)), DCOUNTA(査読範囲,R3,R3:R4), 0) -> 0 | U4: ０Ａ | W4: =IF(ISNUMBER(DCOUNTA(査読範囲,U3,U3:U4)), DCOUNTA(査読範囲,U3,U3:U4), 0) -> 0 | X4: ０Ｂ | Z4: =IF(ISNUMBER(DCOUNTA(査読範囲,X3,X3:X4)), DCOUNTA(査読範囲,X3,X3:X4), 0) -> 0 | AA4: ０Ｃ | AC4: =IF(ISNUMBER(DCOUNTA(査読範囲,AA3,AA3:AA4)), DCOUNTA(査読範囲,AA3,AA3:AA4), 0) -> 0 | AD4: ０Ｚ | AF4: =IF(ISNUMBER(DCOUNTA(査読範囲,AD3,AD3:AD4)), DCOUNTA(査読範囲,AD3,AD3:AD4), 0) -> 0 | AG4: １Ａ | AI4: =IF(ISNUMBER(DCOUNTA(査読範囲,AG3,AG3:AG4)), DCOUNTA(査読範囲,AG3,AG3:AG4), 0) -> 0 | AJ4: １Ｂ | AL4: =IF(ISNUMBER(DCOUNTA(査読範囲,AJ3,AJ3:AJ4)), DCOUNTA(査読範囲,AJ3,AJ3:AJ4), 0) -> 0 | AM4: １Ｃ | AO4: =IF(ISNUMBER(DCOUNTA(査読範囲,AM3,AM3:AM4)), DCOUNTA(査読範囲,AM3,AM3:AM4), 0) -> 0 | AP4: １Ｚ | AR4: =IF(ISNUMBER(DCOUNTA(査読範囲,AP3,AP3:AP4)), DCOUNTA(査読範囲,AP3,AP3:AP4), 0) -> 0 | AS4: ２Ａ | AU4: =IF(ISNUMBER(DCOUNTA(査読範囲,AS3,AS3:AS4)), DCOUNTA(査読範囲,AS3,AS3:AS4), 0) -> 0 | AV4: ２Ｂ | AX4: =IF(ISNUMBER(DCOUNTA(査読範囲,AV3,AV3:AV4)), DCOUNTA(査読範囲,AV3,AV3:AV4), 0) -> 0 | AY4: ２Ｃ | BA4: =IF(ISNUMBER(DCOUNTA(査読範囲,AY3,AY3:AY4)), DCOUNTA(査読範囲,AY3,AY3:AY4), 0) -> 0 | BB4: ２Ｚ | BD4: =IF(ISNUMBER(DCOUNTA(査読範囲,BB3,BB3:BB4)), DCOUNTA(査読範囲,BB3,BB3:BB4), 0) -> 0 | BE4: ３Ａ | BG4: =IF(ISNUMBER(DCOUNTA(査読範囲,BE3,BE3:BE4)), DCOUNTA(査読範囲,BE3,BE3:BE4), 0) -> 0 | BH4: ３Ｂ | BJ4: =IF(ISNUMBER(DCOUNTA(査読範囲,BH3,BH3:BH4)), DCOUNTA(査読範囲,BH3,BH3:BH4), 0) -> 0 | BK4: ３Ｃ | BM4: =IF(ISNUMBER(DCOUNTA(査読範囲,BK3,BK3:BK4)), DCOUNTA(査読範囲,BK3,BK3:BK4), 0) -> 0 | BN4: ３Ｚ | BP4: =IF(ISNUMBER(DCOUNTA(査読範囲,BN3,BN3:BN4)), DCOUNTA(査読範囲,BN3,BN3:BN4), 0) -> 0 | BQ4: ４Ａ | BS4: =IF(ISNUMBER(DCOUNTA(査読範囲,BQ3,BQ3:BQ4)), DCOUNTA(査読範囲,BQ3,BQ3:BQ4), 0) -> 0 | BT4: ４Ｂ | BV4: =IF(ISNUMBER(DCOUNTA(査読範囲,BT3,BT3:BT4)), DCOUNTA(査読範囲,BT3,BT3:BT4), 0) -> 0 | BW4: ４Ｃ | BY4: =IF(ISNUMBER(DCOUNTA(査読範囲,BW3,BW3:BW4)), DCOUNTA(査読範囲,BW3,BW3:BW4), 0) -> 0 | BZ4: ４Ｚ | CB4: =IF(ISNUMBER(DCOUNTA(査読範囲,BZ3,BZ3:BZ4)), DCOUNTA(査読範囲,BZ3,BZ3:BZ4), 0) -> 0 | CC4: ５Ａ | CE4: =IF(ISNUMBER(DCOUNTA(査読範囲,CC3,CC3:CC4)), DCOUNTA(査読範囲,CC3,CC3:CC4), 0) -> 0 | CF4: ５Ｂ | CH4: =IF(ISNUMBER(DCOUNTA(査読範囲,CF3,CF3:CF4)), DCOUNTA(査読範囲,CF3,CF3:CF4), 0) -> 0 | CI4: ５Ｃ | CK4: =IF(ISNUMBER(DCOUNTA(査読範囲,CI3,CI3:CI4)), DCOUNTA(査読範囲,CI3,CI3:CI4), 0) -> 0 | CL4: ５Ｄ | CN4: =IF(ISNUMBER(DCOUNTA(査読範囲,CL3,CL3:CL4)), DCOUNTA(査読範囲,CL3,CL3:CL4), 0) -> 0 | CO4: ５Ｚ | CQ4: =IF(ISNUMBER(DCOUNTA(査読範囲,CO3,CO3:CO4)), DCOUNTA(査読範囲,CO3,CO3:CO4), 0) -> 0 | CR4: ６Ａ | CT4: =IF(ISNUMBER(DCOUNTA(査読範囲,CR3,CR3:CR4)), DCOUNTA(査読範囲,CR3,CR3:CR4), 0) -> 0 | CU4: ６Ｂ | CW4: =IF(ISNUMBER(DCOUNTA(査読範囲,CU3,CU3:CU4)), DCOUNTA(査読範囲,CU3,CU3:CU4), 0) -> 0 | CX4: ６Ｚ | CZ4: =IF(ISNUMBER(DCOUNTA(査読範囲,CX3,CX3:CX4)), DCOUNTA(査読範囲,CX3,CX3:CX4), 0) -> 0
L5: 誤り分類 | N5: 件数 | O5: 誤り分類 | Q5: 件数 | R5: 誤り分類 | T5: 件数 | U5: 誤り分類 | W5: 件数 | X5: 誤り分類 | Z5: 件数 | AA5: 誤り分類 | AC5: 件数 | AD5: 誤り分類 | AF5: 件数 | AG5: 誤り分類 | AI5: 件数 | AJ5: 誤り分類 | AL5: 件数 | AM5: 誤り分類 | AO5: 件数 | AP5: 誤り分類 | AR5: 件数 | AS5: 誤り分類 | AU5: 件数 | AV5: 誤り分類 | AX5: 件数 | AY5: 誤り分類 | BA5: 件数 | BB5: 誤り分類 | BD5: 件数 | BE5: 誤り分類 | BG5: 件数 | BH5: 誤り分類 | BJ5: 件数 | BK5: 誤り分類 | BM5: 件数 | BN5: 誤り分類 | BP5: 件数 | BQ5: 誤り分類 | BS5: 件数 | BT5: 誤り分類 | BV5: 件数 | BW5: 誤り分類 | BY5: 件数 | BZ5: 誤り分類 | CB5: 件数 | CC5: 誤り分類 | CE5: 件数 | CF5: 誤り分類 | CH5: 件数 | CI5: 誤り分類 | CK5: 件数 | CL5: 誤り分類 | CN5: 件数 | CO5: 誤り分類 | CQ5: 件数 | CR5: 誤り分類 | CT5: 件数 | CU5: 誤り分類 | CW5: 件数 | CX5: 誤り分類 | CZ5: 件数
L6: D1 | N6: =IF(ISNUMBER(DCOUNTA(査読範囲,L5,L5:L6)), DCOUNTA(査読範囲,L5,L5:L6), 0) -> 0 | O6: D2 | Q6: =IF(ISNUMBER(DCOUNTA(査読範囲,O5,O5:O6)), DCOUNTA(査読範囲,O5,O5:O6), 0) -> 0 | R6: DZ | T6: =IF(ISNUMBER(DCOUNTA(査読範囲,R5,R5:R6)), DCOUNTA(査読範囲,R5,R5:R6), 0) -> 0 | U6: 0A | W6: =IF(ISNUMBER(DCOUNTA(査読範囲,U5,U5:U6)), DCOUNTA(査読範囲,U5,U5:U6), 0) -> 0 | X6: 0B | Z6: =IF(ISNUMBER(DCOUNTA(査読範囲,X5,X5:X6)), DCOUNTA(査読範囲,X5,X5:X6), 0) -> 0 | AA6: 0C | AC6: =IF(ISNUMBER(DCOUNTA(査読範囲,AA5,AA5:AA6)), DCOUNTA(査読範囲,AA5,AA5:AA6), 0) -> 0 | AD6: 0Z | AF6: =IF(ISNUMBER(DCOUNTA(査読範囲,AD5,AD5:AD6)), DCOUNTA(査読範囲,AD5,AD5:AD6), 0) -> 0 | AG6: 1A | AI6: =IF(ISNUMBER(DCOUNTA(査読範囲,AG5,AG5:AG6)), DCOUNTA(査読範囲,AG5,AG5:AG6), 0) -> 0 | AJ6: 1B | AL6: =IF(ISNUMBER(DCOUNTA(査読範囲,AJ5,AJ5:AJ6)), DCOUNTA(査読範囲,AJ5,AJ5:AJ6), 0) -> 0 | AM6: 1C | AO6: =IF(ISNUMBER(DCOUNTA(査読範囲,AM5,AM5:AM6)), DCOUNTA(査読範囲,AM5,AM5:AM6), 0) -> 0 | AP6: 1Z | AR6: =IF(ISNUMBER(DCOUNTA(査読範囲,AP5,AP5:AP6)), DCOUNTA(査読範囲,AP5,AP5:AP6), 0) -> 0 | AS6: 2A | AU6: =IF(ISNUMBER(DCOUNTA(査読範囲,AS5,AS5:AS6)), DCOUNTA(査読範囲,AS5,AS5:AS6), 0) -> 0 | AV6: 2B | AX6: =IF(ISNUMBER(DCOUNTA(査読範囲,AV5,AV5:AV6)), DCOUNTA(査読範囲,AV5,AV5:AV6), 0) -> 0 | AY6: 2C | BA6: =IF(ISNUMBER(DCOUNTA(査読範囲,AY5,AY5:AY6)), DCOUNTA(査読範囲,AY5,AY5:AY6), 0) -> 0 | BB6: 2Z | BD6: =IF(ISNUMBER(DCOUNTA(査読範囲,BB5,BB5:BB6)), DCOUNTA(査読範囲,BB5,BB5:BB6), 0) -> 0 | BE6: 3A | BG6: =IF(ISNUMBER(DCOUNTA(査読範囲,BE5,BE5:BE6)), DCOUNTA(査読範囲,BE5,BE5:BE6), 0) -> 0 | BH6: 3B | BJ6: =IF(ISNUMBER(DCOUNTA(査読範囲,BH5,BH5:BH6)), DCOUNTA(査読範囲,BH5,BH5:BH6), 0) -> 0 | BK6: 3C | BM6: =IF(ISNUMBER(DCOUNTA(査読範囲,BK5,BK5:BK6)), DCOUNTA(査読範囲,BK5,BK5:BK6), 0) -> 0 | BN6: 3Z | BP6: =IF(ISNUMBER(DCOUNTA(査読範囲,BN5,BN5:BN6)), DCOUNTA(査読範囲,BN5,BN5:BN6), 0) -> 0 | BQ6: 4A | BS6: =IF(ISNUMBER(DCOUNTA(査読範囲,BQ5,BQ5:BQ6)), DCOUNTA(査読範囲,BQ5,BQ5:BQ6), 0) -> 0 | BT6: 4B | BV6: =IF(ISNUMBER(DCOUNTA(査読範囲,BT5,BT5:BT6)), DCOUNTA(査読範囲,BT5,BT5:BT6), 0) -> 0 | BW6: 4C | BY6: =IF(ISNUMBER(DCOUNTA(査読範囲,BW5,BW5:BW6)), DCOUNTA(査読範囲,BW5,BW5:BW6), 0) -> 0 | BZ6: 4Z | CB6: =IF(ISNUMBER(DCOUNTA(査読範囲,BZ5,BZ5:BZ6)), DCOUNTA(査読範囲,BZ5,BZ5:BZ6), 0) -> 0 | CC6: 5A | CE6: =IF(ISNUMBER(DCOUNTA(査読範囲,CC5,CC5:CC6)), DCOUNTA(査読範囲,CC5,CC5:CC6), 0) -> 0 | CF6: 5B | CH6: =IF(ISNUMBER(DCOUNTA(査読範囲,CF5,CF5:CF6)), DCOUNTA(査読範囲,CF5,CF5:CF6), 0) -> 0 | CI6: 5C | CK6: =IF(ISNUMBER(DCOUNTA(査読範囲,CI5,CI5:CI6)), DCOUNTA(査読範囲,CI5,CI5:CI6), 0) -> 0 | CL6: 5D | CN6: =IF(ISNUMBER(DCOUNTA(査読範囲,CL5,CL5:CL6)), DCOUNTA(査読範囲,CL5,CL5:CL6), 0) -> 0 | CO6: 5Z | CQ6: =IF(ISNUMBER(DCOUNTA(査読範囲,CO5,CO5:CO6)), DCOUNTA(査読範囲,CO5,CO5:CO6), 0) -> 0 | CR6: 6A | CT6: =IF(ISNUMBER(DCOUNTA(査読範囲,CR5,CR5:CR6)), DCOUNTA(査読範囲,CR5,CR5:CR6), 0) -> 0 | CU6: 6B | CW6: =IF(ISNUMBER(DCOUNTA(査読範囲,CU5,CU5:CU6)), DCOUNTA(査読範囲,CU5,CU5:CU6), 0) -> 0 | CX6: 6Z | CZ6: =IF(ISNUMBER(DCOUNTA(査読範囲,CX5,CX5:CX6)), DCOUNTA(査読範囲,CX5,CX5:CX6), 0) -> 0
L7: 誤り分類 | N7: 件数 | O7: 誤り分類 | Q7: 件数 | R7: 誤り分類 | T7: 件数 | U7: 誤り分類 | W7: 件数 | X7: 誤り分類 | Z7: 件数 | AA7: 誤り分類 | AC7: 件数 | AD7: 誤り分類 | AF7: 件数 | AG7: 誤り分類 | AI7: 件数 | AJ7: 誤り分類 | AL7: 件数 | AM7: 誤り分類 | AO7: 件数 | AP7: 誤り分類 | AR7: 件数 | AS7: 誤り分類 | AU7: 件数 | AV7: 誤り分類 | AX7: 件数 | AY7: 誤り分類 | BA7: 件数 | BB7: 誤り分類 | BD7: 件数 | BE7: 誤り分類 | BG7: 件数 | BH7: 誤り分類 | BJ7: 件数 | BK7: 誤り分類 | BM7: 件数 | BN7: 誤り分類 | BP7: 件数 | BQ7: 誤り分類 | BS7: 件数 | BT7: 誤り分類 | BV7: 件数 | BW7: 誤り分類 | BY7: 件数 | BZ7: 誤り分類 | CB7: 件数 | CC7: 誤り分類 | CE7: 件数 | CF7: 誤り分類 | CH7: 件数 | CI7: 誤り分類 | CK7: 件数 | CL7: 誤り分類 | CN7: 件数 | CO7: 誤り分類 | CQ7: 件数 | CR7: 誤り分類 | CT7: 件数 | CU7: 誤り分類 | CW7: 件数 | CX7: 誤り分類 | CZ7: 件数
L8: Ｄ1 | N8: =IF(ISNUMBER(DCOUNTA(査読範囲,L7,L7:L8)), DCOUNTA(査読範囲,L7,L7:L8), 0) -> 0 | O8: Ｄ1 | Q8: =IF(ISNUMBER(DCOUNTA(査読範囲,O7,O7:O8)), DCOUNTA(査読範囲,O7,O7:O8), 0) -> 0 | R8: ＤZ | T8: =IF(ISNUMBER(DCOUNTA(査読範囲,R7,R7:R8)), DCOUNTA(査読範囲,R7,R7:R8), 0) -> 0 | U8: ０A | W8: =IF(ISNUMBER(DCOUNTA(査読範囲,U7,U7:U8)), DCOUNTA(査読範囲,U7,U7:U8), 0) -> 0 | X8: ０B | Z8: =IF(ISNUMBER(DCOUNTA(査読範囲,X7,X7:X8)), DCOUNTA(査読範囲,X7,X7:X8), 0) -> 0 | AA8: ０C | AC8: =IF(ISNUMBER(DCOUNTA(査読範囲,AA7,AA7:AA8)), DCOUNTA(査読範囲,AA7,AA7:AA8), 0) -> 0 | AD8: ０Z | AF8: =IF(ISNUMBER(DCOUNTA(査読範囲,AD7,AD7:AD8)), DCOUNTA(査読範囲,AD7,AD7:AD8), 0) -> 0 | AG8: １A | AI8: =IF(ISNUMBER(DCOUNTA(査読範囲,AG7,AG7:AG8)), DCOUNTA(査読範囲,AG7,AG7:AG8), 0) -> 0 | AJ8: １B | AL8: =IF(ISNUMBER(DCOUNTA(査読範囲,AJ7,AJ7:AJ8)), DCOUNTA(査読範囲,AJ7,AJ7:AJ8), 0) -> 0 | AM8: １C | AO8: =IF(ISNUMBER(DCOUNTA(査読範囲,AM7,AM7:AM8)), DCOUNTA(査読範囲,AM7,AM7:AM8), 0) -> 0 | AP8: １Z | AR8: =IF(ISNUMBER(DCOUNTA(査読範囲,AP7,AP7:AP8)), DCOUNTA(査読範囲,AP7,AP7:AP8), 0) -> 0 | AS8: ２A | AU8: =IF(ISNUMBER(DCOUNTA(査読範囲,AS7,AS7:AS8)), DCOUNTA(査読範囲,AS7,AS7:AS8), 0) -> 0 | AV8: ２B | AX8: =IF(ISNUMBER(DCOUNTA(査読範囲,AV7,AV7:AV8)), DCOUNTA(査読範囲,AV7,AV7:AV8), 0) -> 0 | AY8: ２C | BA8: =IF(ISNUMBER(DCOUNTA(査読範囲,AY7,AY7:AY8)), DCOUNTA(査読範囲,AY7,AY7:AY8), 0) -> 0 | BB8: ２Z | BD8: =IF(ISNUMBER(DCOUNTA(査読範囲,BB7,BB7:BB8)), DCOUNTA(査読範囲,BB7,BB7:BB8), 0) -> 0 | BE8: ３A | BG8: =IF(ISNUMBER(DCOUNTA(査読範囲,BE7,BE7:BE8)), DCOUNTA(査読範囲,BE7,BE7:BE8), 0) -> 0 | BH8: ３B | BJ8: =IF(ISNUMBER(DCOUNTA(査読範囲,BH7,BH7:BH8)), DCOUNTA(査読範囲,BH7,BH7:BH8), 0) -> 0 | BK8: ３C | BM8: =IF(ISNUMBER(DCOUNTA(査読範囲,BK7,BK7:BK8)), DCOUNTA(査読範囲,BK7,BK7:BK8), 0) -> 0 | BN8: ３Z | BP8: =IF(ISNUMBER(DCOUNTA(査読範囲,BN7,BN7:BN8)), DCOUNTA(査読範囲,BN7,BN7:BN8), 0) -> 0 | BQ8: ４A | BS8: =IF(ISNUMBER(DCOUNTA(査読範囲,BQ7,BQ7:BQ8)), DCOUNTA(査読範囲,BQ7,BQ7:BQ8), 0) -> 0 | BT8: ４B | BV8: =IF(ISNUMBER(DCOUNTA(査読範囲,BT7,BT7:BT8)), DCOUNTA(査読範囲,BT7,BT7:BT8), 0) -> 0 | BW8: ４C | BY8: =IF(ISNUMBER(DCOUNTA(査読範囲,BW7,BW7:BW8)), DCOUNTA(査読範囲,BW7,BW7:BW8), 0) -> 0 | BZ8: ４Z | CB8: =IF(ISNUMBER(DCOUNTA(査読範囲,BZ7,BZ7:BZ8)), DCOUNTA(査読範囲,BZ7,BZ7:BZ8), 0) -> 0 | CC8: ５A | CE8: =IF(ISNUMBER(DCOUNTA(査読範囲,CC7,CC7:CC8)), DCOUNTA(査読範囲,CC7,CC7:CC8), 0) -> 0 | CF8: ５B | CH8: =IF(ISNUMBER(DCOUNTA(査読範囲,CF7,CF7:CF8)), DCOUNTA(査読範囲,CF7,CF7:CF8), 0) -> 0 | CI8: ５C | CK8: =IF(ISNUMBER(DCOUNTA(査読範囲,CI7,CI7:CI8)), DCOUNTA(査読範囲,CI7,CI7:CI8), 0) -> 0 | CL8: ５D | CN8: =IF(ISNUMBER(DCOUNTA(査読範囲,CL7,CL7:CL8)), DCOUNTA(査読範囲,CL7,CL7:CL8), 0) -> 0 | CO8: ５Z | CQ8: =IF(ISNUMBER(DCOUNTA(査読範囲,CO7,CO7:CO8)), DCOUNTA(査読範囲,CO7,CO7:CO8), 0) -> 0 | CR8: ６A | CT8: =IF(ISNUMBER(DCOUNTA(査読範囲,CR7,CR7:CR8)), DCOUNTA(査読範囲,CR7,CR7:CR8), 0) -> 0 | CU8: ６B | CW8: =IF(ISNUMBER(DCOUNTA(査読範囲,CU7,CU7:CU8)), DCOUNTA(査読範囲,CU7,CU7:CU8), 0) -> 0 | CX8: ６Z | CZ8: =IF(ISNUMBER(DCOUNTA(査読範囲,CX7,CX7:CX8)), DCOUNTA(査読範囲,CX7,CX7:CX8), 0) -> 0
L9: 誤り分類 | N9: 件数 | O9: 誤り分類 | Q9: 件数 | R9: 誤り分類 | T9: 件数 | U9: 誤り分類 | W9: 件数 | X9: 誤り分類 | Z9: 件数 | AA9: 誤り分類 | AC9: 件数 | AD9: 誤り分類 | AF9: 件数 | AG9: 誤り分類 | AI9: 件数 | AJ9: 誤り分類 | AL9: 件数 | AM9: 誤り分類 | AO9: 件数 | AP9: 誤り分類 | AR9: 件数 | AS9: 誤り分類 | AU9: 件数 | AV9: 誤り分類 | AX9: 件数 | AY9: 誤り分類 | BA9: 件数 | BB9: 誤り分類 | BD9: 件数 | BE9: 誤り分類 | BG9: 件数 | BH9: 誤り分類 | BJ9: 件数 | BK9: 誤り分類 | BM9: 件数 | BN9: 誤り分類 | BP9: 件数 | BQ9: 誤り分類 | BS9: 件数 | BT9: 誤り分類 | BV9: 件数 | BW9: 誤り分類 | BY9: 件数 | BZ9: 誤り分類 | CB9: 件数 | CC9: 誤り分類 | CE9: 件数 | CF9: 誤り分類 | CH9: 件数 | CI9: 誤り分類 | CK9: 件数 | CL9: 誤り分類 | CN9: 件数 | CO9: 誤り分類 | CQ9: 件数 | CR9: 誤り分類 | CT9: 件数 | CU9: 誤り分類 | CW9: 件数 | CX9: 誤り分類 | CZ9: 件数
L10: d1 | O10: d2 | R10: dz | U10: 0ａ | W10: =IF(ISNUMBER(DCOUNTA(査読範囲,U9,U9:U10)), DCOUNTA(査読範囲,U9,U9:U10), 0) -> 0 | X10: 0ｂ | Z10: =IF(ISNUMBER(DCOUNTA(査読範囲,X9,X9:X10)), DCOUNTA(査読範囲,X9,X9:X10), 0) -> 0 | AA10: 0ｃ | AC10: =IF(ISNUMBER(DCOUNTA(査読範囲,AA9,AA9:AA10)), DCOUNTA(査読範囲,AA9,AA9:AA10), 0) -> 0 | AD10: 0ｚ | AF10: =IF(ISNUMBER(DCOUNTA(査読範囲,AD9,AD9:AD10)), DCOUNTA(査読範囲,AD9,AD9:AD10), 0) -> 0 | AG10: 1ａ | AI10: =IF(ISNUMBER(DCOUNTA(査読範囲,AG9,AG9:AG10)), DCOUNTA(査読範囲,AG9,AG9:AG10), 0) -> 0 | AJ10: 1ｂ | AL10: =IF(ISNUMBER(DCOUNTA(査読範囲,AJ9,AJ9:AJ10)), DCOUNTA(査読範囲,AJ9,AJ9:AJ10), 0) -> 0 | AM10: 1ｃ | AO10: =IF(ISNUMBER(DCOUNTA(査読範囲,AM9,AM9:AM10)), DCOUNTA(査読範囲,AM9,AM9:AM10), 0) -> 0 | AP10: 1ｚ | AR10: =IF(ISNUMBER(DCOUNTA(査読範囲,AP9,AP9:AP10)), DCOUNTA(査読範囲,AP9,AP9:AP10), 0) -> 0 | AS10: 2ａ | AU10: =IF(ISNUMBER(DCOUNTA(査読範囲,AS9,AS9:AS10)), DCOUNTA(査読範囲,AS9,AS9:AS10), 0) -> 0 | AV10: 2ｂ | AX10: =IF(ISNUMBER(DCOUNTA(査読範囲,AV9,AV9:AV10)), DCOUNTA(査読範囲,AV9,AV9:AV10), 0) -> 0 | AY10: 2ｃ | BA10: =IF(ISNUMBER(DCOUNTA(査読範囲,AY9,AY9:AY10)), DCOUNTA(査読範囲,AY9,AY9:AY10), 0) -> 0 | BB10: 2ｚ | BD10: =IF(ISNUMBER(DCOUNTA(査読範囲,BB9,BB9:BB10)), DCOUNTA(査読範囲,BB9,BB9:BB10), 0) -> 0 | BE10: 3ａ | BG10: =IF(ISNUMBER(DCOUNTA(査読範囲,BE9,BE9:BE10)), DCOUNTA(査読範囲,BE9,BE9:BE10), 0) -> 0 | BH10: 3ｂ | BJ10: =IF(ISNUMBER(DCOUNTA(査読範囲,BH9,BH9:BH10)), DCOUNTA(査読範囲,BH9,BH9:BH10), 0) -> 0 | BK10: 3ｃ | BM10: =IF(ISNUMBER(DCOUNTA(査読範囲,BK9,BK9:BK10)), DCOUNTA(査読範囲,BK9,BK9:BK10), 0) -> 0 | BN10: 3ｚ | BP10: =IF(ISNUMBER(DCOUNTA(査読範囲,BN9,BN9:BN10)), DCOUNTA(査読範囲,BN9,BN9:BN10), 0) -> 0 | BQ10: 4ａ | BS10: =IF(ISNUMBER(DCOUNTA(査読範囲,BQ9,BQ9:BQ10)), DCOUNTA(査読範囲,BQ9,BQ9:BQ10), 0) -> 0 | BT10: 4ｂ | BV10: =IF(ISNUMBER(DCOUNTA(査読範囲,BT9,BT9:BT10)), DCOUNTA(査読範囲,BT9,BT9:BT10), 0) -> 0 | BW10: 4ｃ | BY10: =IF(ISNUMBER(DCOUNTA(査読範囲,BW9,BW9:BW10)), DCOUNTA(査読範囲,BW9,BW9:BW10), 0) -> 0 | BZ10: 4ｚ | CB10: =IF(ISNUMBER(DCOUNTA(査読範囲,BZ9,BZ9:BZ10)), DCOUNTA(査読範囲,BZ9,BZ9:BZ10), 0) -> 0 | CC10: 5ａ | CE10: =IF(ISNUMBER(DCOUNTA(査読範囲,CC9,CC9:CC10)), DCOUNTA(査読範囲,CC9,CC9:CC10), 0) -> 0 | CF10: 5ｂ | CH10: =IF(ISNUMBER(DCOUNTA(査読範囲,CF9,CF9:CF10)), DCOUNTA(査読範囲,CF9,CF9:CF10), 0) -> 0 | CI10: 5ｃ | CK10: =IF(ISNUMBER(DCOUNTA(査読範囲,CI9,CI9:CI10)), DCOUNTA(査読範囲,CI9,CI9:CI10), 0) -> 0 | CL10: 5Ｄ | CN10: =IF(ISNUMBER(DCOUNTA(査読範囲,CL9,CL9:CL10)), DCOUNTA(査読範囲,CL9,CL9:CL10), 0) -> 0 | CO10: 5ｚ | CQ10: =IF(ISNUMBER(DCOUNTA(査読範囲,CO9,CO9:CO10)), DCOUNTA(査読範囲,CO9,CO9:CO10), 0) -> 0 | CR10: 6ａ | CT10: =IF(ISNUMBER(DCOUNTA(査読範囲,CR9,CR9:CR10)), DCOUNTA(査読範囲,CR9,CR9:CR10), 0) -> 0 | CU10: 6ｂ | CW10: =IF(ISNUMBER(DCOUNTA(査読範囲,CU9,CU9:CU10)), DCOUNTA(査読範囲,CU9,CU9:CU10), 0) -> 0 | CX10: 6ｚ | CZ10: =IF(ISNUMBER(DCOUNTA(査読範囲,CX9,CX9:CX10)), DCOUNTA(査読範囲,CX9,CX9:CX10), 0) -> 0
L11: 合計 | N11: ”D1”合計 | Q11: ”D2”合計 | T11: ”DZ”合計 | W11: ”0A”合計 | Z11: ”0B”合計 | AC11: ”0C”合計 | AF11: ”0Z”合計 | AG11: 合計 | AI11: ”1A”合計 | AL11: ”1B”合計 | AO11: ”1C”合計 | AR11: ”1Z”合計 | AU11: ”2A”合計 | AX11: ”2B”合計 | BA11: ”2C”合計 | BD11: ”2Z”合計 | BG11: ”3A”合計 | BJ11: ”3B”合計 | BM11: ”3C”合計 | BP11: ”3Z”合計 | BS11: ”4A”合計 | BV11: ”4B”合計 | BY11: ”4C”合計 | CB11: ”4Z”合計 | CE11: ”5A”合計 | CH11: ”5B”合計 | CK11: ”5C”合計 | CN11: ”5D”合計 | CQ11: ”5Z”合計 | CT11: ”6A”合計 | CW11: ”6B”合計 | CZ11: ”6Z”合計
L12: =SUM(N12:CZ12) -> 0 | N12: =SUBTOTAL(9,N4:N10) -> 0 | Q12: =SUBTOTAL(9,Q4:Q10) -> 0 | T12: =SUBTOTAL(9,T4:T10) -> 0 | W12: =SUBTOTAL(9,W4:W10) -> 0 | Z12: =SUBTOTAL(9,Z4:Z10) -> 0 | AC12: =SUBTOTAL(9,AC4:AC10) -> 0 | AF12: =SUBTOTAL(9,AF4:AF10) -> 0 | AI12: =SUBTOTAL(9,AI4:AI10) -> 0 | AL12: =SUBTOTAL(9,AL4:AL10) -> 0 | AO12: =SUBTOTAL(9,AO4:AO10) -> 0 | AR12: =SUBTOTAL(9,AR4:AR10) -> 0 | AU12: =SUBTOTAL(9,AU4:AU10) -> 0 | AX12: =SUBTOTAL(9,AX4:AX10) -> 0 | BA12: =SUBTOTAL(9,BA4:BA10) -> 0 | BD12: =SUBTOTAL(9,BD4:BD10) -> 0 | BG12: =SUBTOTAL(9,BG4:BG10) -> 0 | BJ12: =SUBTOTAL(9,BJ4:BJ10) -> 0 | BM12: 未使用 | BP12: =SUBTOTAL(9,BP4:BP10) -> 0 | BS12: =SUBTOTAL(9,BS4:BS10) -> 0 | BV12: =SUBTOTAL(9,BV4:BV10) -> 0 | BY12: 未使用 | CB12: 未使用 | CE12: =SUBTOTAL(9,CE4:CE10) -> 0 | CH12: =SUBTOTAL(9,CH4:CH10) -> 0 | CK12: =SUBTOTAL(9,CK4:CK10) -> 0 | CN12: =SUBTOTAL(9,CN4:CN10) -> 0 | CQ12: =SUBTOTAL(9,CQ4:CQ10) -> 0 | CT12: =SUBTOTAL(9,CT4:CT10) -> 0 | CW12: =SUBTOTAL(9,CW4:CW10) -> 0 | CZ12: =SUBTOTAL(9,CZ4:CZ10) -> 0
U16: 回数 | V16: 記入日 | W16: 誤り分類 | X16: コメント数 | Y16: 日付記入数 | Z16: 日付累計
U17: 1 | V17: =IF(ISNUMBER(SMALL(記入日範囲,1)), SMALL(記入日範囲,1), " ") | X17: =IF(ISNUMBER(DCOUNTA(査読範囲,W16,V16:V17)), DCOUNTA(査読範囲,W16,V16:V17), 0) -> 0 | Y17: =IF(ISNUMBER(DCOUNTA(査読範囲,V16,V16:V17)), DCOUNTA(査読範囲,V16,V16:V17), 0) -> 0 | Z17: =Y17 -> 0
V18: 記入日 | W18: 誤り分類
U19: 2 | V19: =IF(ISNUMBER(SMALL(記入日範囲,Z17+1)), SMALL(記入日範囲,Z17+1), " ") | X19: =IF(ISNUMBER(DCOUNTA(査読範囲,W18,V18:V19)), DCOUNTA(査読範囲,W18,V18:V19), 0) -> 0 | Y19: =IF(ISNUMBER(DCOUNTA(査読範囲,V18,V18:V19)), DCOUNTA(査読範囲,V18,V18:V19), 0) -> 0 | Z19: =Z17+Y19 -> 0
V20: 記入日 | W20: 誤り分類
U21: 3 | V21: =IF(ISNUMBER(SMALL(記入日範囲,Z19+1)), SMALL(記入日範囲,Z19+1), " ") | X21: =IF(ISNUMBER(DCOUNTA(査読範囲,W20,V20:V21)), DCOUNTA(査読範囲,W20,V20:V21), 0) -> 0 | Y21: =IF(ISNUMBER(DCOUNTA(査読範囲,V20,V20:V21)), DCOUNTA(査読範囲,V20,V20:V21), 0) -> 0 | Z21: =Z19+Y21 -> 0
V22: 記入日 | W22: 誤り分類
U23: 4 | V23: =IF(ISNUMBER(SMALL(記入日範囲,Z21+1)), SMALL(記入日範囲,Z21+1), " ") | X23: =IF(ISNUMBER(DCOUNTA(査読範囲,W22,V22:V23)), DCOUNTA(査読範囲,W22,V22:V23), 0) -> 0 | Y23: =IF(ISNUMBER(DCOUNTA(査読範囲,V22,V22:V23)), DCOUNTA(査読範囲,V22,V22:V23), 0) -> 0 | Z23: =Z21+Y23 -> 0
V24: 記入日 | W24: 誤り分類
U25: 5 | V25: =IF(ISNUMBER(SMALL(記入日範囲,Z23+1)), SMALL(記入日範囲,Z23+1), " ") | X25: =IF(ISNUMBER(DCOUNTA(査読範囲,W24,V24:V25)), DCOUNTA(査読範囲,W24,V24:V25), 0) -> 0 | Y25: =IF(ISNUMBER(DCOUNTA(査読範囲,V24,V24:V25)), DCOUNTA(査読範囲,V24,V24:V25), 0) -> 0 | Z25: =Z23+Y25 -> 0
C26: 査読コメント | V26: 記入日 | W26: 誤り分類
C27: <>""
D31: 査 読 シ ー ト
A33: ＜必須記入項目＞以下の区分毎に，色分けされた必須項目を記入する。（注）赤字セルは，計算式（入力不要） | J33: 回答期限
C34: ：レビューア
C35: ：回答者 （インスペクション／公式レビュー対象ドキュメントの場合は，緑色セルも記入する）
A37: ﾄﾞｷｭﾒﾝﾄ番号： | G37: ページ数(頁) or ライン数（KL) | J37: 5
A38: ﾄﾞｷｭﾒﾝﾄ名／ ﾌﾟﾛｸﾞﾗﾑ名 ： | C38: システムフロー_S100_01f_レビューシート.xls
I40: ﾚﾋﾞｭｰ指摘率（件/頁）orｺｰﾄﾞﾚﾋﾞｭｰ指摘率（件/KL） | J40: =IF(J37<>0,DCOUNTA(査読範囲,C43,C26:C27)/J37,IF(J38<>0,DCOUNTA(査読範囲,C43,C26:C27)/J38,0)) -> #NAME?
C41: ﾚﾋﾞｭｰ工数(Hr) | D41: 1.5 | F41: （複数ﾒﾝﾊﾞによるﾚﾋﾞｭｰの場合，工数加算する）
A43: No. | B43: ページ | C43: 査読コメント | D43: 記入日 | E43: 記入者 | F43: 回 答 | G43: 回答日 | H43: 回答者 | I43: 誤り分類 | J43: 処置期限 | K43: 確認
A44: 1
A45: =A44+1 -> 2
A46: =A45+1 -> 3
A47: =A46+1 -> 4
A48: =A47+1 -> 5
A49: =A48+1 -> 6
A50: =A49+1 -> 7
A51: =A50+1 -> 8
...

Sheet 査読ｼｰﾄ
L1: ＜査読シートの誤り分類の集計＞
L3: 誤り分類 | N3: 件数 | O3: 誤り分類 | Q3: 件数 | R3: 誤り分類 | T3: 件数 | U3: 誤り分類 | W3: 件数 | X3: 誤り分類 | Z3: 件数 | AA3: 誤り分類 | AC3: 件数 | AD3: 誤り分類 | AF3: 件数 | AG3: 誤り分類 | AI3: 件数 | AJ3: 誤り分類 | AL3: 件数 | AM3: 誤り分類 | AO3: 件数 | AP3: 誤り分類 | AR3: 件数 | AS3: 誤り分類 | AU3: 件数 | AV3: 誤り分類 | AX3: 件数 | AY3: 誤り分類 | BA3: 件数 | BB3: 誤り分類 | BD3: 件数 | BE3: 誤り分類 | BG3: 件数 | BH3: 誤り分類 | BJ3: 件数 | BK3: 誤り分類 | BM3: 件数 | BN3: 誤り分類 | BP3: 件数 | BQ3: 誤り分類 | BS3: 件数 | BT3: 誤り分類 | BV3: 件数 | BW3: 誤り分類 | BY3: 件数 | BZ3: 誤り分類 | CB3: 件数 | CC3: 誤り分類 | CE3: 件数 | CF3: 誤り分類 | CH3: 件数 | CI3: 誤り分類 | CK3: 件数 | CL3: 誤り分類 | CN3: 件数 | CO3: 誤り分類 | CQ3: 件数 | CR3: 誤り分類 | CT3: 件数 | CU3: 誤り分類 | CW3: 件数 | CX3: 誤り分類 | CZ3: 件数
L4: Ｄ１ | N4: =IF(ISNUMBER(DCOUNTA(査読範囲,L3,L3:L4)), DCOUNTA(査読範囲,L3,L3:L4), 0) -> 0 | O4: Ｄ２ | Q4: =IF(ISNUMBER(DCOUNTA(査読範囲,O3,O3:O4)), DCOUNTA(査読範囲,O3,O3:O4), 0) -> 0 | R4: ＤＺ | T4: =IF(ISNUMBER(DCOUNTA(査読範囲,R3,R3:R4)), DCOUNTA(査読範囲,R3,R3:R4), 0) -> 0 | U4: ０Ａ | W4: =IF(ISNUMBER(DCOUNTA(査読範囲,U3,U3:U4)), DCOUNTA(査読範囲,U3,U3:U4), 0) -> 0 | X4: ０Ｂ | Z4: =IF(ISNUMBER(DCOUNTA(査読範囲,X3,X3:X4)), DCOUNTA(査読範囲,X3,X3:X4), 0) -> 0 | AA4: ０Ｃ | AC4: =IF(ISNUMBER(DCOUNTA(査読範囲,AA3,AA3:AA4)), DCOUNTA(査読範囲,AA3,AA3:AA4), 0) -> 0 | AD4: ０Ｚ | AF4: =IF(ISNUMBER(DCOUNTA(査読範囲,AD3,AD3:AD4)), DCOUNTA(査読範囲,AD3,AD3:AD4), 0) -> 0 | AG4: １Ａ | AI4: =IF(ISNUMBER(DCOUNTA(査読範囲,AG3,AG3:AG4)), DCOUNTA(査読範囲,AG3,AG3:AG4), 0) -> 0 | AJ4: １Ｂ | AL4: =IF(ISNUMBER(DCOUNTA(査読範囲,AJ3,AJ3:AJ4)), DCOUNTA(査読範囲,AJ3,AJ3:AJ4), 0) -> 0 | AM4: １Ｃ | AO4: =IF(ISNUMBER(DCOUNTA(査読範囲,AM3,AM3:AM4)), DCOUNTA(査読範囲,AM3,AM3:AM4), 0) -> 0 | AP4: １Ｚ | AR4: =IF(ISNUMBER(DCOUNTA(査読範囲,AP3,AP3:AP4)), DCOUNTA(査読範囲,AP3,AP3:AP4), 0) -> 0 | AS4: ２Ａ | AU4: =IF(ISNUMBER(DCOUNTA(査読範囲,AS3,AS3:AS4)), DCOUNTA(査読範囲,AS3,AS3:AS4), 0) -> 0 | AV4: ２Ｂ | AX4: =IF(ISNUMBER(DCOUNTA(査読範囲,AV3,AV3:AV4)), DCOUNTA(査読範囲,AV3,AV3:AV4), 0) -> 0 | AY4: ２Ｃ | BA4: =IF(ISNUMBER(DCOUNTA(査読範囲,AY3,AY3:AY4)), DCOUNTA(査読範囲,AY3,AY3:AY4), 0) -> 0 | BB4: ２Ｚ | BD4: =IF(ISNUMBER(DCOUNTA(査読範囲,BB3,BB3:BB4)), DCOUNTA(査読範囲,BB3,BB3:BB4), 0) -> 0 | BE4: ３Ａ | BG4: =IF(ISNUMBER(DCOUNTA(査読範囲,BE3,BE3:BE4)), DCOUNTA(査読範囲,BE3,BE3:BE4), 0) -> 0 | BH4: ３Ｂ | BJ4: =IF(ISNUMBER(DCOUNTA(査読範囲,BH3,BH3:BH4)), DCOUNTA(査読範囲,BH3,BH3:BH4), 0) -> 0 | BK4: ３Ｃ | BM4: =IF(ISNUMBER(DCOUNTA(査読範囲,BK3,BK3:BK4)), DCOUNTA(査読範囲,BK3,BK3:BK4), 0) -> 0 | BN4: ３Ｚ | BP4: =IF(ISNUMBER(DCOUNTA(査読範囲,BN3,BN3:BN4)), DCOUNTA(査読範囲,BN3,BN3:BN4), 0) -> 0 | BQ4: ４Ａ | BS4: =IF(ISNUMBER(DCOUNTA(査読範囲,BQ3,BQ3:BQ4)), DCOUNTA(査読範囲,BQ3,BQ3:BQ4), 0) -> 0 | BT4: ４Ｂ | BV4: =IF(ISNUMBER(DCOUNTA(査読範囲,BT3,BT3:BT4)), DCOUNTA(査読範囲,BT3,BT3:BT4), 0) -> 0 | BW4: ４Ｃ | BY4: =IF(ISNUMBER(DCOUNTA(査読範囲,BW3,BW3:BW4)), DCOUNTA(査読範囲,BW3,BW3:BW4), 0) -> 0 | BZ4: ４Ｚ | CB4: =IF(ISNUMBER(DCOUNTA(査読範囲,BZ3,BZ3:BZ4)), DCOUNTA(査読範囲,BZ3,BZ3:BZ4), 0) -> 0 | CC4: ５Ａ | CE4: =IF(ISNUMBER(DCOUNTA(査読範囲,CC3,CC3:CC4)), DCOUNTA(査読範囲,CC3,CC3:CC4), 0) -> 0 | CF4: ５Ｂ | CH4: =IF(ISNUMBER(DCOUNTA(査読範囲,CF3,CF3:CF4)), DCOUNTA(査読範囲,CF3,CF3:CF4), 0) -> 0 | CI4: ５Ｃ | CK4: =IF(ISNUMBER(DCOUNTA(査読範囲,CI3,CI3:CI4)), DCOUNTA(査読範囲,CI3,CI3:CI4), 0) -> 0 | CL4: ５Ｄ | CN4: =IF(ISNUMBER(DCOUNTA(査読範囲,CL3,CL3:CL4)), DCOUNTA(査読範囲,CL3,CL3:CL4), 0) -> 0 | CO4: ５Ｚ | CQ4: =IF(ISNUMBER(DCOUNTA(査読範囲,CO3,CO3:CO4)), DCOUNTA(査読範囲,CO3,CO3:CO4), 0) -> 0 | CR4: ６Ａ | CT4: =IF(ISNUMBER(DCOUNTA(査読範囲,CR3,CR3:CR4)), DCOUNTA(査読範囲,CR3,CR3:CR4), 0) -> 0 | CU4: ６Ｂ | CW4: =IF(ISNUMBER(DCOUNTA(査読範囲,CU3,CU3:CU4)), DCOUNTA(査読範囲,CU3,CU3:CU4), 0) -> 0 | CX4: ６Ｚ | CZ4: =IF(ISNUMBER(DCOUNTA(査読範囲,CX3,CX3:CX4)), DCOUNTA(査読範囲,CX3,CX3:CX4), 0) -> 0
L5: 誤り分類 | N5: 件数 | O5: 誤り分類 | Q5: 件数 | R5: 誤り分類 | T5: 件数 | U5: 誤り分類 | W5: 件数 | X5: 誤り分類 | Z5: 件数 | AA5: 誤り分類 | AC5: 件数 | AD5: 誤り分類 | AF5: 件数 | AG5: 誤り分類 | AI5: 件数 | AJ5: 誤り分類 | AL5: 件数 | AM5: 誤り分類 | AO5: 件数 | AP5: 誤り分類 | AR5: 件数 | AS5: 誤り分類 | AU5: 件数 | AV5: 誤り分類 | AX5: 件数 | AY5: 誤り分類 | BA5: 件数 | BB5: 誤り分類 | BD5: 件数 | BE5: 誤り分類 | BG5: 件数 | BH5: 誤り分類 | BJ5: 件数 | BK5: 誤り分類 | BM5: 件数 | BN5: 誤り分類 | BP5: 件数 | BQ5: 誤り分類 | BS5: 件数 | BT5: 誤り分類 | BV5: 件数 | BW5: 誤り分類 | BY5: 件数 | BZ5: 誤り分類 | CB5: 件数 | CC5: 誤り分類 | CE5: 件数 | CF5: 誤り分類 | CH5: 件数 | CI5: 誤り分類 | CK5: 件数 | CL5: 誤り分類 | CN5: 件数 | CO5: 誤り分類 | CQ5: 件数 | CR5: 誤り分類 | CT5: 件数 | CU5: 誤り分類 | CW5: 件数 | CX5: 誤り分類 | CZ5: 件数
L6: D1 | N6: =IF(ISNUMBER(DCOUNTA(査読範囲,L5,L5:L6)), DCOUNTA(査読範囲,L5,L5:L6), 0) -> 0 | O6: D2 | Q6: =IF(ISNUMBER(DCOUNTA(査読範囲,O5,O5:O6)), DCOUNTA(査読範囲,O5,O5:O6), 0) -> 0 | R6: DZ | T6: =IF(ISNUMBER(DCOUNTA(査読範囲,R5,R5:R6)), DCOUNTA(査読範囲,R5,R5:R6), 0) -> 0 | U6: 0A | W6: =IF(ISNUMBER(DCOUNTA(査読範囲,U5,U5:U6)), DCOUNTA(査読範囲,U5,U5:U6), 0) -> 0 | X6: 0B | Z6: =IF(ISNUMBER(DCOUNTA(査読範囲,X5,X5:X6)), DCOUNTA(査読範囲,X5,X5:X6), 0) -> 0 | AA6: 0C | AC6: =IF(ISNUMBER(DCOUNTA(査読範囲,AA5,AA5:AA6)), DCOUNTA(査読範囲,AA5,AA5:AA6), 0) -> 0 | AD6: 0Z | AF6: =IF(ISNUMBER(DCOUNTA(査読範囲,AD5,AD5:AD6)), DCOUNTA(査読範囲,AD5,AD5:AD6), 0) -> 0 | AG6: 1A | AI6: =IF(ISNUMBER(DCOUNTA(査読範囲,AG5,AG5:AG6)), DCOUNTA(査読範囲,AG5,AG5:AG6), 0) -> 0 | AJ6: 1B | AL6: =IF(ISNUMBER(DCOUNTA(査読範囲,AJ5,AJ5:AJ6)), DCOUNTA(査読範囲,AJ5,AJ5:AJ6), 0) -> 0 | AM6: 1C | AO6: =IF(ISNUMBER(DCOUNTA(査読範囲,AM5,AM5:AM6)), DCOUNTA(査読範囲,AM5,AM5:AM6), 0) -> 0 | AP6: 1Z | AR6: =IF(ISNUMBER(DCOUNTA(査読範囲,AP5,AP5:AP6)), DCOUNTA(査読範囲,AP5,AP5:AP6), 0) -> 0 | AS6: 2A | AU6: =IF(ISNUMBER(DCOUNTA(査読範囲,AS5,AS5:AS6)), DCOUNTA(査読範囲,AS5,AS5:AS6), 0) -> 0 | AV6: 2B | AX6: =IF(ISNUMBER(DCOUNTA(査読範囲,AV5,AV5:AV6)), DCOUNTA(査読範囲,AV5,AV5:AV6), 0) -> 0 | AY6: 2C | BA6: =IF(ISNUMBER(DCOUNTA(査読範囲,AY5,AY5:AY6)), DCOUNTA(査読範囲,AY5,AY5:AY6), 0) -> 0 | BB6: 2Z | BD6: =IF(ISNUMBER(DCOUNTA(査読範囲,BB5,BB5:BB6)), DCOUNTA(査読範囲,BB5,BB5:BB6), 0) -> 0 | BE6: 3A | BG6: =IF(ISNUMBER(DCOUNTA(査読範囲,BE5,BE5:BE6)), DCOUNTA(査読範囲,BE5,BE5:BE6), 0) -> 0 | BH6: 3B | BJ6: =IF(ISNUMBER(DCOUNTA(査読範囲,BH5,BH5:BH6)), DCOUNTA(査読範囲,BH5,BH5:BH6), 0) -> 0 | BK6: 3C | BM6: =IF(ISNUMBER(DCOUNTA(査読範囲,BK5,BK5:BK6)), DCOUNTA(査読範囲,BK5,BK5:BK6), 0) -> 0 | BN6: 3Z | BP6: =IF(ISNUMBER(DCOUNTA(査読範囲,BN5,BN5:BN6)), DCOUNTA(査読範囲,BN5,BN5:BN6), 0) -> 0 | BQ6: 4A | BS6: =IF(ISNUMBER(DCOUNTA(査読範囲,BQ5,BQ5:BQ6)), DCOUNTA(査読範囲,BQ5,BQ5:BQ6), 0) -> 0 | BT6: 4B | BV6: =IF(ISNUMBER(DCOUNTA(査読範囲,BT5,BT5:BT6)), DCOUNTA(査読範囲,BT5,BT5:BT6), 0) -> 0 | BW6: 4C | BY6: =IF(ISNUMBER(DCOUNTA(査読範囲,BW5,BW5:BW6)), DCOUNTA(査読範囲,BW5,BW5:BW6), 0) -> 0 | BZ6: 4Z | CB6: =IF(ISNUMBER(DCOUNTA(査読範囲,BZ5,BZ5:BZ6)), DCOUNTA(査読範囲,BZ5,BZ5:BZ6), 0) -> 0 | CC6: 5A | CE6: =IF(ISNUMBER(DCOUNTA(査読範囲,CC5,CC5:CC6)), DCOUNTA(査読範囲,CC5,CC5:CC6), 0) -> 0 | CF6: 5B | CH6: =IF(ISNUMBER(DCOUNTA(査読範囲,CF5,CF5:CF6)), DCOUNTA(査読範囲,CF5,CF5:CF6), 0) -> 0 | CI6: 5C | CK6: =IF(ISNUMBER(DCOUNTA(査読範囲,CI5,CI5:CI6)), DCOUNTA(査読範囲,CI5,CI5:CI6), 0) -> 0 | CL6: 5D | CN6: =IF(ISNUMBER(DCOUNTA(査読範囲,CL5,CL5:CL6)), DCOUNTA(査読範囲,CL5,CL5:CL6), 0) -> 0 | CO6: 5Z | CQ6: =IF(ISNUMBER(DCOUNTA(査読範囲,CO5,CO5:CO6)), DCOUNTA(査読範囲,CO5,CO5:CO6), 0) -> 0 | CR6: 6A | CT6: =IF(ISNUMBER(DCOUNTA(査読範囲,CR5,CR5:CR6)), DCOUNTA(査読範囲,CR5,CR5:CR6), 0) -> 0 | CU6: 6B | CW6: =IF(ISNUMBER(DCOUNTA(査読範囲,CU5,CU5:CU6)), DCOUNTA(査読範囲,CU5,CU5:CU6), 0) -> 0 | CX6: 6Z | CZ6: =IF(ISNUMBER(DCOUNTA(査読範囲,CX5,CX5:CX6)), DCOUNTA(査読範囲,CX5,CX5:CX6), 0) -> 0
L7: 誤り分類 | N7: 件数 | O7: 誤り分類 | Q7: 件数 | R7: 誤り分類 | T7: 件数 | U7: 誤り分類 | W7: 件数 | X7: 誤り分類 | Z7: 件数 | AA7: 誤り分類 | AC7: 件数 | AD7: 誤り分類 | AF7: 件数 | AG7: 誤り分類 | AI7: 件数 | AJ7: 誤り分類 | AL7: 件数 | AM7: 誤り分類 | AO7: 件数 | AP7: 誤り分類 | AR7: 件数 | AS7: 誤り分類 | AU7: 件数 | AV7: 誤り分類 | AX7: 件数 | AY7: 誤り分類 | BA7: 件数 | BB7: 誤り分類 | BD7: 件数 | BE7: 誤り分類 | BG7: 件数 | BH7: 誤り分類 | BJ7: 件数 | BK7: 誤り分類 | BM7: 件数 | BN7: 誤り分類 | BP7: 件数 | BQ7: 誤り分類 | BS7: 件数 | BT7: 誤り分類 | BV7: 件数 | BW7: 誤り分類 | BY7: 件数 | BZ7: 誤り分類 | CB7: 件数 | CC7: 誤り分類 | CE7: 件数 | CF7: 誤り分類 | CH7: 件数 | CI7: 誤り分類 | CK7: 件数 | CL7: 誤り分類 | CN7: 件数 | CO7: 誤り分類 | CQ7: 件数 | CR7: 誤り分類 | CT7: 件数 | CU7: 誤り分類 | CW7: 件数 | CX7: 誤り分類 | CZ7: 件数
L8: Ｄ1 | N8: =IF(ISNUMBER(DCOUNTA(査読範囲,L7,L7:L8)), DCOUNTA(査読範囲,L7,L7:L8), 0) -> 0 | O8: Ｄ1 | Q8: =IF(ISNUMBER(DCOUNTA(査読範囲,O7,O7:O8)), DCOUNTA(査読範囲,O7,O7:O8), 0) -> 0 | R8: ＤZ | T8: =IF(ISNUMBER(DCOUNTA(査読範囲,R7,R7:R8)), DCOUNTA(査読範囲,R7,R7:R8), 0) -> 0 | U8: ０A | W8: =IF(ISNUMBER(DCOUNTA(査読範囲,U7,U7:U8)), DCOUNTA(査読範囲,U7,U7:U8), 0) -> 0 | X8: ０B | Z8: =IF(ISNUMBER(DCOUNTA(査読範囲,X7,X7:X8)), DCOUNTA(査読範囲,X7,X7:X8), 0) -> 0 | AA8: ０C | AC8: =IF(ISNUMBER(DCOUNTA(査読範囲,AA7,AA7:AA8)), DCOUNTA(査読範囲,AA7,AA7:AA8), 0) -> 0 | AD8: ０Z | AF8: =IF(ISNUMBER(DCOUNTA(査読範囲,AD7,AD7:AD8)), DCOUNTA(査読範囲,AD7,AD7:AD8), 0) -> 0 | AG8: １A | AI8: =IF(ISNUMBER(DCOUNTA(査読範囲,AG7,AG7:AG8)), DCOUNTA(査読範囲,AG7,AG7:AG8), 0) -> 0 | AJ8: １B | AL8: =IF(ISNUMBER(DCOUNTA(査読範囲,AJ7,AJ7:AJ8)), DCOUNTA(査読範囲,AJ7,AJ7:AJ8), 0) -> 0 | AM8: １C | AO8: =IF(ISNUMBER(DCOUNTA(査読範囲,AM7,AM7:AM8)), DCOUNTA(査読範囲,AM7,AM7:AM8), 0) -> 0 | AP8: １Z | AR8: =IF(ISNUMBER(DCOUNTA(査読範囲,AP7,AP7:AP8)), DCOUNTA(査読範囲,AP7,AP7:AP8), 0) -> 0 | AS8: ２A | AU8: =IF(ISNUMBER(DCOUNTA(査読範囲,AS7,AS7:AS8)), DCOUNTA(査読範囲,AS7,AS7:AS8), 0) -> 0 | AV8: ２B | AX8: =IF(ISNUMBER(DCOUNTA(査読範囲,AV7,AV7:AV8)), DCOUNTA(査読範囲,AV7,AV7:AV8), 0) -> 0 | AY8: ２C | BA8: =IF(ISNUMBER(DCOUNTA(査読範囲,AY7,AY7:AY8)), DCOUNTA(査読範囲,AY7,AY7:AY8), 0) -> 0 | BB8: ２Z | BD8: =IF(ISNUMBER(DCOUNTA(査読範囲,BB7,BB7:BB8)), DCOUNTA(査読範囲,BB7,BB7:BB8), 0) -> 0 | BE8: ３A | BG8: =IF(ISNUMBER(DCOUNTA(査読範囲,BE7,BE7:BE8)), DCOUNTA(査読範囲,BE7,BE7:BE8), 0) -> 0 | BH8: ３B | BJ8: =IF(ISNUMBER(DCOUNTA(査読範囲,BH7,BH7:BH8)), DCOUNTA(査読範囲,BH7,BH7:BH8), 0) -> 0 | BK8: ３C | BM8: =IF(ISNUMBER(DCOUNTA(査読範囲,BK7,BK7:BK8)), DCOUNTA(査読範囲,BK7,BK7:BK8), 0) -> 0 | BN8: ３Z | BP8: =IF(ISNUMBER(DCOUNTA(査読範囲,BN7,BN7:BN8)), DCOUNTA(査読範囲,BN7,BN7:BN8), 0) -> 0 | BQ8: ４A | BS8: =IF(ISNUMBER(DCOUNTA(査読範囲,BQ7,BQ7:BQ8)), DCOUNTA(査読範囲,BQ7,BQ7:BQ8), 0) -> 0 | BT8: ４B | BV8: =IF(ISNUMBER(DCOUNTA(査読範囲,BT7,BT7:BT8)), DCOUNTA(査読範囲,BT7,BT7:BT8), 0) -> 0 | BW8: ４C | BY8: =IF(ISNUMBER(DCOUNTA(査読範囲,BW7,BW7:BW8)), DCOUNTA(査読範囲,BW7,BW7:BW8), 0) -> 0 | BZ8: ４Z | CB8: =IF(ISNUMBER(DCOUNTA(査読範囲,BZ7,BZ7:BZ8)), DCOUNTA(査読範囲,BZ7,BZ7:BZ8), 0) -> 0 | CC8: ５A | CE8: =IF(ISNUMBER(DCOUNTA(査読範囲,CC7,CC7:CC8)), DCOUNTA(査読範囲,CC7,CC7:CC8), 0) -> 0 | CF8: ５B | CH8: =IF(ISNUMBER(DCOUNTA(査読範囲,CF7,CF7:CF8)), DCOUNTA(査読範囲,CF7,CF7:CF8), 0) -> 0 | CI8: ５C | CK8: =IF(ISNUMBER(DCOUNTA(査読範囲,CI7,CI7:CI8)), DCOUNTA(査読範囲,CI7,CI7:CI8), 0) -> 0 | CL8: ５D | CN8: =IF(ISNUMBER(DCOUNTA(査読範囲,CL7,CL7:CL8)), DCOUNTA(査読範囲,CL7,CL7:CL8), 0) -> 0 | CO8: ５Z | CQ8: =IF(ISNUMBER(DCOUNTA(査読範囲,CO7,CO7:CO8)), DCOUNTA(査読範囲,CO7,CO7:CO8), 0) -> 0 | CR8: ６A | CT8: =IF(ISNUMBER(DCOUNTA(査読範囲,CR7,CR7:CR8)), DCOUNTA(査読範囲,CR7,CR7:CR8), 0) -> 0 | CU8: ６B | CW8: =IF(ISNUMBER(DCOUNTA(査読範囲,CU7,CU7:CU8)), DCOUNTA(査読範囲,CU7,CU7:CU8), 0) -> 0 | CX8: ６Z | CZ8: =IF(ISNUMBER(DCOUNTA(査読範囲,CX7,CX7:CX8)), DCOUNTA(査読範囲,CX7,CX7:CX8), 0) -> 0
L9: 誤り分類 | N9: 件数 | O9: 誤り分類 | Q9: 件数 | R9: 誤り分類 | T9: 件数 | U9: 誤り分類 | W9: 件数 | X9: 誤り分類 | Z9: 件数 | AA9: 誤り分類 | AC9: 件数 | AD9: 誤り分類 | AF9: 件数 | AG9: 誤り分類 | AI9: 件数 | AJ9: 誤り分類 | AL9: 件数 | AM9: 誤り分類 | AO9: 件数 | AP9: 誤り分類 | AR9: 件数 | AS9: 誤り分類 | AU9: 件数 | AV9: 誤り分類 | AX9: 件数 | AY9: 誤り分類 | BA9: 件数 | BB9: 誤り分類 | BD9: 件数 | BE9: 誤り分類 | BG9: 件数 | BH9: 誤り分類 | BJ9: 件数 | BK9: 誤り分類 | BM9: 件数 | BN9: 誤り分類 | BP9: 件数 | BQ9: 誤り分類 | BS9: 件数 | BT9: 誤り分類 | BV9: 件数 | BW9: 誤り分類 | BY9: 件数 | BZ9: 誤り分類 | CB9: 件数 | CC9: 誤り分類 | CE9: 件数 | CF9: 誤り分類 | CH9: 件数 | CI9: 誤り分類 | CK9: 件数 | CL9: 誤り分類 | CN9: 件数 | CO9: 誤り分類 | CQ9: 件数 | CR9: 誤り分類 | CT9: 件数 | CU9: 誤り分類 | CW9: 件数 | CX9: 誤り分類 | CZ9: 件数
L10: d1 | O10: d2 | R10: dz | U10: 0ａ | W10: =IF(ISNUMBER(DCOUNTA(査読範囲,U9,U9:U10)), DCOUNTA(査読範囲,U9,U9:U10), 0) -> 0 | X10: 0ｂ | Z10: =IF(ISNUMBER(DCOUNTA(査読範囲,X9,X9:X10)), DCOUNTA(査読範囲,X9,X9:X10), 0) -> 0 | AA10: 0ｃ | AC10: =IF(ISNUMBER(DCOUNTA(査読範囲,AA9,AA9:AA10)), DCOUNTA(査読範囲,AA9,AA9:AA10), 0) -> 0 | AD10: 0ｚ | AF10: =IF(ISNUMBER(DCOUNTA(査読範囲,AD9,AD9:AD10)), DCOUNTA(査読範囲,AD9,AD9:AD10), 0) -> 0 | AG10: 1ａ | AI10: =IF(ISNUMBER(DCOUNTA(査読範囲,AG9,AG9:AG10)), DCOUNTA(査読範囲,AG9,AG9:AG10), 0) -> 0 | AJ10: 1ｂ | AL10: =IF(ISNUMBER(DCOUNTA(査読範囲,AJ9,AJ9:AJ10)), DCOUNTA(査読範囲,AJ9,AJ9:AJ10), 0) -> 0 | AM10: 1ｃ | AO10: =IF(ISNUMBER(DCOUNTA(査読範囲,AM9,AM9:AM10)), DCOUNTA(査読範囲,AM9,AM9:AM10), 0) -> 0 | AP10: 1ｚ | AR10: =IF(ISNUMBER(DCOUNTA(査読範囲,AP9,AP9:AP10)), DCOUNTA(査読範囲,AP9,AP9:AP10), 0) -> 0 | AS10: 2ａ | AU10: =IF(ISNUMBER(DCOUNTA(査読範囲,AS9,AS9:AS10)), DCOUNTA(査読範囲,AS9,AS9:AS10), 0) -> 0 | AV10: 2ｂ | AX10: =IF(ISNUMBER(DCOUNTA(査読範囲,AV9,AV9:AV10)), DCOUNTA(査読範囲,AV9,AV9:AV10), 0) -> 0 | AY10: 2ｃ | BA10: =IF(ISNUMBER(DCOUNTA(査読範囲,AY9,AY9:AY10)), DCOUNTA(査読範囲,AY9,AY9:AY10), 0) -> 0 | BB10: 2ｚ | BD10: =IF(ISNUMBER(DCOUNTA(査読範囲,BB9,BB9:BB10)), DCOUNTA(査読範囲,BB9,BB9:BB10), 0) -> 0 | BE10: 3ａ | BG10: =IF(ISNUMBER(DCOUNTA(査読範囲,BE9,BE9:BE10)), DCOUNTA(査読範囲,BE9,BE9:BE10), 0) -> 0 | BH10: 3ｂ | BJ10: =IF(ISNUMBER(DCOUNTA(査読範囲,BH9,BH9:BH10)), DCOUNTA(査読範囲,BH9,BH9:BH10), 0) -> 0 | BK10: 3ｃ | BM10: =IF(ISNUMBER(DCOUNTA(査読範囲,BK9,BK9:BK10)), DCOUNTA(査読範囲,BK9,BK9:BK10), 0) -> 0 | BN10: 3ｚ | BP10: =IF(ISNUMBER(DCOUNTA(査読範囲,BN9,BN9:BN10)), DCOUNTA(査読範囲,BN9,BN9:BN10), 0) -> 0 | BQ10: 4ａ | BS10: =IF(ISNUMBER(DCOUNTA(査読範囲,BQ9,BQ9:BQ10)), DCOUNTA(査読範囲,BQ9,BQ9:BQ10), 0) -> 0 | BT10: 4ｂ | BV10: =IF(ISNUMBER(DCOUNTA(査読範囲,BT9,BT9:BT10)), DCOUNTA(査読範囲,BT9,BT9:BT10), 0) -> 0 | BW10: 4ｃ | BY10: =IF(ISNUMBER(DCOUNTA(査読範囲,BW9,BW9:BW10)), DCOUNTA(査読範囲,BW9,BW9:BW10), 0) -> 0 | BZ10: 4ｚ | CB10: =IF(ISNUMBER(DCOUNTA(査読範囲,BZ9,BZ9:BZ10)), DCOUNTA(査読範囲,BZ9,BZ9:BZ10), 0) -> 0 | CC10: 5ａ | CE10: =IF(ISNUMBER(DCOUNTA(査読範囲,CC9,CC9:CC10)), DCOUNTA(査読範囲,CC9,CC9:CC10), 0) -> 0 | CF10: 5ｂ | CH10: =IF(ISNUMBER(DCOUNTA(査読範囲,CF9,CF9:CF10)), DCOUNTA(査読範囲,CF9,CF9:CF10), 0) -> 0 | CI10: 5ｃ | CK10: =IF(ISNUMBER(DCOUNTA(査読範囲,CI9,CI9:CI10)), DCOUNTA(査読範囲,CI9,CI9:CI10), 0) -> 0 | CL10: 5Ｄ | CN10: =IF(ISNUMBER(DCOUNTA(査読範囲,CL9,CL9:CL10)), DCOUNTA(査読範囲,CL9,CL9:CL10), 0) -> 0 | CO10: 5ｚ | CQ10: =IF(ISNUMBER(DCOUNTA(査読範囲,CO9,CO9:CO10)), DCOUNTA(査読範囲,CO9,CO9:CO10), 0) -> 0 | CR10: 6ａ | CT10: =IF(ISNUMBER(DCOUNTA(査読範囲,CR9,CR9:CR10)), DCOUNTA(査読範囲,CR9,CR9:CR10), 0) -> 0 | CU10: 6ｂ | CW10: =IF(ISNUMBER(DCOUNTA(査読範囲,CU9,CU9:CU10)), DCOUNTA(査読範囲,CU9,CU9:CU10), 0) -> 0 | CX10: 6ｚ | CZ10: =IF(ISNUMBER(DCOUNTA(査読範囲,CX9,CX9:CX10)), DCOUNTA(査読範囲,CX9,CX9:CX10), 0) -> 0
L11: 合計 | N11: ”D1”合計 | Q11: ”D2”合計 | T11: ”DZ”合計 | W11: ”0A”合計 | Z11: ”0B”合計 | AC11: ”0C”合計 | AF11: ”0Z”合計 | AG11: 合計 | AI11: ”1A”合計 | AL11: ”1B”合計 | AO11: ”1C”合計 | AR11: ”1Z”合計 | AU11: ”2A”合計 | AX11: ”2B”合計 | BA11: ”2C”合計 | BD11: ”2Z”合計 | BG11: ”3A”合計 | BJ11: ”3B”合計 | BM11: ”3C”合計 | BP11: ”3Z”合計 | BS11: ”4A”合計 | BV11: ”4B”合計 | BY11: ”4C”合計 | CB11: ”4Z”合計 | CE11: ”5A”合計 | CH11: ”5B”合計 | CK11: ”5C”合計 | CN11: ”5D”合計 | CQ11: ”5Z”合計 | CT11: ”6A”合計 | CW11: ”6B”合計 | CZ11: ”6Z”合計
L12: =SUM(N12:CZ12) -> 0 | N12: =SUBTOTAL(9,N4:N10) -> 0 | Q12: =SUBTOTAL(9,Q4:Q10) -> 0 | T12: =SUBTOTAL(9,T4:T10) -> 0 | W12: =SUBTOTAL(9,W4:W10) -> 0 | Z12: =SUBTOTAL(9,Z4:Z10) -> 0 | AC12: =SUBTOTAL(9,AC4:AC10) -> 0 | AF12: =SUBTOTAL(9,AF4:AF10) -> 0 | AI12: =SUBTOTAL(9,AI4:AI10) -> 0 | AL12: =SUBTOTAL(9,AL4:AL10) -> 0 | AO12: =SUBTOTAL(9,AO4:AO10) -> 0 | AR12: =SUBTOTAL(9,AR4:AR10) -> 0 | AU12: =SUBTOTAL(9,AU4:AU10) -> 0 | AX12: =SUBTOTAL(9,AX4:AX10) -> 0 | BA12: =SUBTOTAL(9,BA4:BA10) -> 0 | BD12: =SUBTOTAL(9,BD4:BD10) -> 0 | BG12: =SUBTOTAL(9,BG4:BG10) -> 0 | BJ12: =SUBTOTAL(9,BJ4:BJ10) -> 0 | BM12: 未使用 | BP12: =SUBTOTAL(9,BP4:BP10) -> 0 | BS12: =SUBTOTAL(9,BS4:BS10) -> 0 | BV12: =SUBTOTAL(9,BV4:BV10) -> 0 | BY12: 未使用 | CB12: 未使用 | CE12: =SUBTOTAL(9,CE4:CE10) -> 0 | CH12: =SUBTOTAL(9,CH4:CH10) -> 0 | CK12: =SUBTOTAL(9,CK4:CK10) -> 0 | CN12: =SUBTOTAL(9,CN4:CN10) -> 0 | CQ12: =SUBTOTAL(9,CQ4:CQ10) -> 0 | CT12: =SUBTOTAL(9,CT4:CT10) -> 0 | CW12: =SUBTOTAL(9,CW4:CW10) -> 0 | CZ12: =SUBTOTAL(9,CZ4:CZ10) -> 0
U16: 回数 | V16: 記入日 | W16: 誤り分類 | X16: コメント数 | Y16: 日付記入数 | Z16: 日付累計
U17: 1 | V17: =IF(ISNUMBER(SMALL(記入日範囲,1)), SMALL(記入日範囲,1), " ") | X17: =IF(ISNUMBER(DCOUNTA(査読範囲,W16,V16:V17)), DCOUNTA(査読範囲,W16,V16:V17), 0) -> 0 | Y17: =IF(ISNUMBER(DCOUNTA(査読範囲,V16,V16:V17)), DCOUNTA(査読範囲,V16,V16:V17), 0) -> 0 | Z17: =Y17 -> 0
V18: 記入日 | W18: 誤り分類
U19: 2 | V19: =IF(ISNUMBER(SMALL(記入日範囲,Z17+1)), SMALL(記入日範囲,Z17+1), " ") | X19: =IF(ISNUMBER(DCOUNTA(査読範囲,W18,V18:V19)), DCOUNTA(査読範囲,W18,V18:V19), 0) -> 0 | Y19: =IF(ISNUMBER(DCOUNTA(査読範囲,V18,V18:V19)), DCOUNTA(査読範囲,V18,V18:V19), 0) -> 0 | Z19: =Z17+Y19 -> 0
V20: 記入日 | W20: 誤り分類
U21: 3 | V21: =IF(ISNUMBER(SMALL(記入日範囲,Z19+1)), SMALL(記入日範囲,Z19+1), " ") | X21: =IF(ISNUMBER(DCOUNTA(査読範囲,W20,V20:V21)), DCOUNTA(査読範囲,W20,V20:V21), 0) -> 0 | Y21: =IF(ISNUMBER(DCOUNTA(査読範囲,V20,V20:V21)), DCOUNTA(査読範囲,V20,V20:V21), 0) -> 0 | Z21: =Z19+Y21 -> 0
V22: 記入日 | W22: 誤り分類
U23: 4 | V23: =IF(ISNUMBER(SMALL(記入日範囲,Z21+1)), SMALL(記入日範囲,Z21+1), " ") | X23: =IF(ISNUMBER(DCOUNTA(査読範囲,W22,V22:V23)), DCOUNTA(査読範囲,W22,V22:V23), 0) -> 0 | Y23: =IF(ISNUMBER(DCOUNTA(査読範囲,V22,V22:V23)), DCOUNTA(査読範囲,V22,V22:V23), 0) -> 0 | Z23: =Z21+Y23 -> 0
V24: 記入日 | W24: 誤り分類
U25: 5 | V25: =IF(ISNUMBER(SMALL(記入日範囲,Z23+1)), SMALL(記入日範囲,Z23+1), " ") | X25: =IF(ISNUMBER(DCOUNTA(査読範囲,W24,V24:V25)), DCOUNTA(査読範囲,W24,V24:V25), 0) -> 0 | Y25: =IF(ISNUMBER(DCOUNTA(査読範囲,V24,V24:V25)), DCOUNTA(査読範囲,V24,V24:V25), 0) -> 0 | Z25: =Z23+Y25 -> 0
C26: 査読コメント | V26: 記入日 | W26: 誤り分類
C27: <>""
D31: 査 読 シ ー ト
A33: ＜必須記入項目＞以下の区分毎に，色分けされた必須項目を記入する。（注）赤字セルは，計算式（入力不要） | J33: 回答期限
C34: ：レビューア
C35: ：回答者 （インスペクション／公式レビュー対象ドキュメントの場合は，緑色セルも記入する）
A37: ﾄﾞｷｭﾒﾝﾄ番号： | G37: ページ数(頁) or ライン数（KL)
A38: ﾄﾞｷｭﾒﾝﾄ名／ ﾌﾟﾛｸﾞﾗﾑ名 ： | C38: 単体試験要領書_MSBBPA100_【画面】WebFSC製品化チェックシート出力.xlsx
I40: ﾚﾋﾞｭｰ指摘率（件/頁）orｺｰﾄﾞﾚﾋﾞｭｰ指摘率（件/KL） | J40: =IF(J37<>0,DCOUNTA(査読範囲,C43,C26:C27)/J37,IF(J38<>0,DCOUNTA(査読範囲,C43,C26:C27)/J38,0)) -> 0
C41: ﾚﾋﾞｭｰ工数(Hr) | F41: （複数ﾒﾝﾊﾞによるﾚﾋﾞｭｰの場合，工数加算する）
A43: No. | B43: ページ | C43: 査読コメント | D43: 記入日 | E43: 記入者 | F43: 回 答 | G43: 回答日 | H43: 回答者 | I43: 誤り分類 | J43: 処置期限 | K43: 確認
A44: 1 | C44: ケース４７ 確認対象：版型No ⇒どこに記載がある | D44: 44972 | E44: TBK徐 | F44: 修正しました。 | G44: 44973 | H44: TBK高 | K44: TBK徐
A45: =A44+1 -> 2 | C45: 帳票出力確認に関して FSC製品化チェックシートは、その他帳票と異なり、WEB内で完結するため、単体の試験に含めてください WEBから直接ダウンロードでEXCEL出力する ※項目値が合っているかどうかは、【帳票】FSC製品化チェックシートでの確認となります | D45: 45023 | E45: MDSOL 野村 | F45: 修正しました。 | G45: 45029 | H45: TBK徐
A46: =A45+1 -> 3 | C46: FSC管理NOが正しく採番されるかことを確認ください | D46: 45023 | E46: MDSOL 野村 | F46: 追加しました。 | G46: 45029 | H46: TBK徐
A47: =A46+1 -> 4 | C47: 出力フォーマット変更時に選択したフォーマットでFSC製品化チェックシートが出力されることを確認ください。 ※【帳票】FSC製品化チェックシート側に含まれていれば問題ありません。 | D47: 45023 | E47: MDSOL 野村 | F47: 追加しました。 | G47: 45029 | H47: TBK徐
A48: =A47+1 -> 5
A49: =A48+1 -> 6
A50: =A49+1 -> 7
A51: =A50+1 -> 8
...

Sheet 単体テスト要領書レビューチェックリスト
D1: 実施日： | E1: 44971
D2: 実施者： | E2: TBK高
A3: 単体テスト要領書チェックリスト（Ｒｅｖ１．０）
A5: ドキュメント番号： | C5: =査読ｼｰﾄ!C38 -> 単体試験要領書_MSBBPA100_【画面】WebFSC製品化チェックシート出力.xlsx | D5: 機能区分： | E5: 画面
A7: チェック項目 | B7: No. | C7: チェック内容 | D7: 結果 (○／×／－) | E7: 画面 | F7: 帳票（紙） | G7: 帳票（Ex） | H7: バッチ | I7: Ｉ／Ｆ
A9: ０．全体 | B9: 1 | C9: 全ページがレビュー済みであるか。 | D9: 〇 | E9: ● | F9: ● | G9: ● | H9: ● | I9: ●
B10: 2 | C10: 語句が統一されていることを確認したか。（業務用語はお客様と認識を合わせておく） 例）納品先と納入先 ⇒ 納品先、仕入先⇒発注先 等 ※業務用語集はドキュメント・リンク集から参照のこと | D10: 〇 | E10: ● | F10: ● | G10: ● | H10: ● | I10: ●
B11: 3 | C11: 仕様書を印刷した際に、各ページにヘッダが存在すること。 | D11: 〇 | E11: ● | F11: ● | G11: ● | H11: ● | I11: ●
B12: 4 | C12: 試験実施の要否が正しく記載されていること なお「×」のものについては理由が明記されていること ※試験ができない項目に「○」がついていないか ※試験を実施すべき項目に「×」がついていないか | D12: 〇 | E12: ● | F12: ● | G12: ● | H12: ● | I12: ●
B13: 5 | C13: 誰でも試験を実施できる内容になっているか。 必要に応じて「試験データシート」または「試験シート」にInput/Outputが明記されているか | D13: 〇 | E13: ● | F13: ● | G13: ● | H13: ● | I13: ●
B14: 6 | C14: テスト方法、期待される結果が曖昧な表現となっていないこと 例1 正しく処理されること × ログファイルに以下が出力されること 〇 処理件数：0件 戻り値：0 ←期待される結果として、具体的な値、事象を記載すること 例2 詳細設計通りであること × 別紙：詳細設計書.DB項目転送シートの編集内容通りに値が設定されていること 〇 ←詳細設計書.DB項目転送シートのINS02の表を別紙に添付する。 単体試験成績書で結果のエビデンスと表横にOK、NGを記載していただくイメージ | D14: 〇 | E14: ● | F14: ● | G14: ● | H14: ● | I14: ●
A16: １．画面全体 | B16: 1 | C16: ＜全体＞ レイアウトが設計書の画面イメージと一致していることを確認する。 タブがある場合は、全てのタブについて確認する。 遷移元からの指定やパラメータなどの処理条件でレイアウトが異なる場合、全ての条件で確認する。 ・項目やボタンの配置 ・画面サイズ ・一覧枠の項目並び順 | D16: 〇 | E16: ●
B17: 2 | C17: ＜名称＞ トップバーに画面名称が正しく表示されていることを確認する。 | D17: 〇 | E17: ●
B18: 3 | C18: ＜各項目タイトル＞ 各項目のタイトル（ラベル）が設計書と一致していることを確認する。 | D18: 〇 | E18: ●
B19: 4 | C19: ＜ボタンのタイトル＞ 各ボタンのタイトル（ラベル）が設計書と一致していることを確認する。 | D19: 〇 | E19: ●
B20: 5 | C20: ＜一覧枠のサイズ＞ 一覧枠のサイズが設計書と一致していることを確認する。 | D20: 〇 | E20: ●
B21: 6 | C21: ＜一覧枠のタイトル＞ 一覧枠のタイトルが設計書と一致していることを確認する。 | D21: 〇 | E21: ●
B22: 7 | C22: ＜入力枠＞ 入力項目の桁・型・種類（入力補助/コンボボックス）が設計書と一致していることを確認する。 | D22: 〇 | E22: ●
B23: 8 | C23: ＜入力枠 一覧＞ 入力項目の桁・型・種類（入力補助/コンボボックス）が設計書と一致していることを確認する。 | D23: 〇 | E23: ●
B24: 9 | C24: ＜最大化・最小化＞ 画面の最大化、最小化、ドラッグによるサイズ変更が可能であること（設計書に記載がなければフレームワークの標準仕様とする）を確認する。 | D24: 〇 | E24: ●
B25: 10 | C25: ＜「×」ボタン動作＞ 「×」ボタン押下時に画面が終了することを確認する。 ・更新中の項目があれば確認ダイアログを表示する。 | D25: 〇 | E25: ●
A27: ２．画面初期動作 | B27: 1 | C27: ＜初期表示時の項目制御＞ 画面起動時に項目毎に必要に応じて「入力可」「入力不可」の制御が行われていることを確認する。 ・遷移元の指定やパラメータなどの処理条件によって制御が異なる場合、全ての条件で確認する。 ※各フィールドやボタンについて 項目シートに直接記載するかデータシートまたはマトリックスシートに記載しているか | D27: 〇 | E27: ●
B28: 2 | C28: ＜初期表示時のボタン制御＞ 画面起動時にボタン毎に必要に応じて「押下可」「押下不可」の制御が行われていることを確認する。 ・遷移元の指定やパラメータなどの処理条件によって制御が異なる場合、全ての条件で確認する。 ※各ボタンについて 項目シートに直接記載するかデータシートまたはマトリックスシートに記載しているか | D28: 〇 | E28: ●
B29: 3 | C29: ＜初期値の設定＞ 画面起動時の入力項目に設定されている値が設計書と一致していることを確認する。 ・初期値が設定されていない項目は、設定されていないことを確認する。 ・遷移元の指定やパラメータなどの処理条件によって初期値が異なる場合、全ての条件で確認する。 ※各フィールドおよび値について 項目シートに直接記載するかデータシートまたはマトリックスシートに記載しているか | D29: 〇 | E29: ●
A31: ３．画面基本動作 | B31: 1 | C31: ＜Tabキー移動＞ TabキーまたはEnterキーでの移動が設計書と一致していることを確認する。 （画面項目定義の項目順に準拠していること） | D31: 〇 | E31: ●
B32: 2 | C32: ＜ファンクションキー(F1)の押下＞ ファンクションキー押下時の動作が標準仕様、または設計書と一致していることを確認する。 ・検索ボタン | D32: 〇 | E32: ●
B33: 3 | C33: ＜ファンクションキー(F2)の押下＞ ファンクションキー押下時の動作が標準仕様、または設計書と一致していることを確認する。 ・入力補助画面起動 | D33: 〇 | E33: ●
B34: 4 | C34: ＜ファンクションキー(F5)の押下＞ ファンクションキー押下時の動作が標準仕様、または設計書と一致していることを確認する。 ・行追加ボタン | D34: 〇 | E34: ●
B35: 5 | C35: ＜ファンクションキー(F6)の押下＞ ファンクションキー押下時の動作が標準仕様、または設計書と一致していることを確認する。 ・行削除ボタン | D35: 〇 | E35: ●
B36: 6 | C36: ＜ファンクションキー(F7)の押下＞ ファンクションキー押下時の動作が標準仕様、または設計書と一致していることを確認する。 ・テーブルクリアボタン | D36: 〇 | E36: ●
B37: 7 | C37: ＜ファンクションキー(F9)の押下＞ ファンクションキー押下時の動作が標準仕様、または設計書と一致していることを確認する。 ・登録ボタン | D37: 〇 | E37: ●
B38: 8 | C38: ＜ファンクションキー(F12)の押下＞ ファンクションキー押下時の動作が標準仕様、または設計書と一致していることを確認する。 ・削除ボタン | D38: 〇 | E38: ●
B39: 9 | C39: ＜ファンクションキー(F17)の押下＞ ファンクションキー押下時の動作が標準仕様、または設計書と一致していることを確認する。 ・行コピーボタン | D39: 〇 | E39: ●
B40: 10 | C40: ＜入力補助の動作＞ 全項目の入力補助について、起動と値の受渡しが設計書と一致していることを確認する。 ・マスタから値を取得する場合は、マスタを準備する。 ・遷移元の指定やパラメータなどの処理条件によってリストが異なる場合、全ての条件で確認する。 | D40: 〇 | E40: ●
B41: 11 | C41: ＜コンボボックスの動作＞ 全項目のコンボボックスについて、起動と値の受渡しが設計書と一致していることを確認する。 ※システム仕様書の「項目説明」に記載のあるもの全てが対象 ・マスタから値を取得する場合は、マスタを準備する。 ・遷移元の指定やパラメータなどの処理条件によってリストが異なる場合、全ての条件で確認する。 Ex.倉庫CDに所属する場所CDの入力が可能（所属しない場合には入力不可） | D41: 〇 | E41: ●
B42: 12 | C42: ＜入力項目の値の制限＞ 各項目に対して、形式（日付、数値）、桁数、右詰、左詰、及びIME制御（全半角）が設計書と一致していることを確認する。 | D42: 〇 | E42: ●
B43: 13 | C43: ＜数値の有効桁数（表示形式）＞ 全数値項目に対して、は小数点以下の桁数、端数の扱い（四捨五入、切り上げ、切り捨て）が設計書と一致していることを確認する。 | D43: 〇 | E43: ●
B44: 14 | C44: ＜日付の表示形式＞ 全日付項目に対して、は表示形式（YMD形式など）が設計書と一致していることを確認する。 | D44: 〇 | E44: ●
A46: ４．画面イベント | C46: ＜検索ボタン＞ 検索ボタンによって発生するイベントが設計書と一致していることを確認する。 以下の試験項目は必ず含めること。
B47: 1 | C47: ・対象０件の場合の検索結果を確認する。 | D47: 〇 | E47: ●
...
