Workbook
Name Revision: #REF!
Name Version: #REF!
Name Version: #REF!
Name Version: #REF!
Name Version: #REF!
Name Version: #REF!
Name Version: #REF!
Name Version: #REF!
Name Version: #REF!
Name Version: #REF!
Name 発行日: #REF!
Name 文書番号: #REF!
Name 文書番号_カスタマイズ: '[2]表紙（カスタマイズ）'!$U$20
Name 文書名: #REF!
Name 文書名: #REF!
Name 文書名: #REF!
Name 文書名: #REF!
Name 文書名: #REF!
Name 文書名: #REF!
Name 文書名: #REF!
Name 文書名: #REF!
Name 文書名: #REF!
Name 文書名_カスタマイズ: '[2]表紙（カスタマイズ）'!$M$10

Sheet 暫定対応
B2: ■シート商品
B4: ・ | C4: シート加工と同じ動きにする。
C5: ※品目の指定と工程の編集に関する画面の制御が難しいため、客先の結論（なんらか纏めているよう）待ち
B8: ■原紙受注
B10: ・ | C10: 原紙ＣＤ（表）を指定して工程入力が無くても、受注登録を可能にする。 | J10: ※ここも詳しい制御は客先に確認してから決める
C11: ・品目ＣＤの発番：原紙ＣＤ＋印刷ＣＤ＋エンボスＣＤ
C12: 枝番１～３：*
C13: ※マスタ連携時に巾と坪量を決めて、受注明細を更新する。
B15: ・ | C15: 巻きMを自由入力する。
C16: ※業務上の意味：巻取り原紙（原紙ロール）１本の長さ（M）
C17: 巻取り原紙を販売する時に入力される。販売単位：本、受注連携時に、巻きM×数量（本）＝原紙のM数

Sheet 受注パタンの纏め
B2: TOP画面 | G2: 基本情報画面 | J2: 受注入力パタン
B3: 受注区分 | D3: 指定可能品目 | H3: 製品区分
B4: 10 | C4: 加工製品 | D4: 製品マスタ | G4: 指定する製品の製品区分 | J4: 1.加工受注
H5: 12 | I5: 加工
H6: 13 | I6: Ｇプリント
H7: 21 | I7: 巻ボール
H8: 23 | I8: 片面加工
H9: 31 | I9: プリフル
H10: 32 | I10: 刷本支給
B11: 11 | C11: 加工商品 | D11: 製品マスタ | G11: 指定する製品の製品区分 | J11: 1.加工受注
H12: 12 | I12: 加工
H13: 13 | I13: Ｇプリント
H14: 21 | I14: 巻ボール
H15: 23 | I15: 片面加工
H16: 31 | I16: プリフル
H17: 32 | I17: 刷本支給
D18: 品目マスタ | E18: ※検索条件 | J18: ※諸口ＦＬＧで判断
E19: 品目区分 | F19: 1:商品 | G19: 指定する品目の品目詳細区分で判断 | J19: 諸口ＦＬＧ＝0 | K19: 3.商品購買
E20: 品目区分詳細 | F20: 112:商品加工 | H20: 12 | I20: 加工 | J20: 諸口ＦＬＧ＝1 | K20: 4.商品購買（有償支給、諸口）
F21: 113:商品Ｇプリント | H21: 13 | I21: Ｇプリント
F22: 121:商品巻ボール | H22: 21 | I22: 巻ボール
F23: 123:商品片面加工 | H23: 23 | I23: 片面加工
F24: 131:商品プリフル | H24: 31 | I24: プリフル
F25: 132:商品刷本支給 | H25: 32 | I25: 刷本支給
B27: 20 | C27: シート製品 | D27: 画面で採番する | G27: 画面より指定
H28: 11 | I28: シート | J28: 2.シート受注
H29: 22 | I29: 片面シート
B31: 21 | C31: シート商品 | D31: 画面で採番する | G31: 画面より指定
H32: 11 | I32: シート | J32: 2.シート受注
H33: 22 | I33: 片面シート
D35: 品目マスタ | E35: ※検索条件 | J35: ※諸口ＦＬＧで判断
E36: 品目区分 | F36: 1:商品 | G36: 指定する品目の品目詳細区分で判断 | J36: 諸口ＦＬＧ＝0 | K36: 3.商品購買
E37: 品目区分詳細 | F37: 111:商品シート | H37: 11 | I37: シート | J37: 諸口ＦＬＧ＝1 | K37: 4.商品購買（有償支給、諸口）
F38: 122:商品片面シート | H38: 22 | I38: 片面シート
B40: 30 | C40: 購買品 | D40: 品目マスタ | E40: ※検索条件① | G40: 指定する品目の品目詳細区分で判断 | J40: ※諸口ＦＬＧで判断
E41: 品目区分 | F41: 1:商品 | J41: 諸口ＦＬＧ＝0 | K41: 3.商品購買
E42: 品目区分詳細 | F42: 151:外装シート | H42: 51 | I42: 外装シート | J42: 諸口ＦＬＧ＝1 | K42: 4.商品購買（有償支給、諸口）
F43: 152:外装ケース | H43: 52 | I43: 外装ケース
F44: 162:商品その他 | H44: 62 | I44: その他
F45: 171:袋 | H45: 71 | I45: 袋
...

Sheet 原紙
C3: 原紙マスタ

Sheet 汎用マスタ
F1: 必須 | G1: 必須 | H1: 必須 | I1: 必須 | J1: 必須 | K1: 必須 | L1: 必須 | M1: 必須 | N1: 必須 | O1: 必須 | P1: 必須 | Q1: 必須
A2: 一覧に戻る | E2: 論理名 | F2: 汎用分類ＣＤ | G2: キー１ | H2: キー２ | I2: キー３ | J2: キー４ | K2: キー５ | L2: キー６ | M2: キー７ | N2: キー８ | O2: キー９ | P2: キー１０ | Q2: 会社ＣＤ | R2: 文字列１ | S2: 文字列２ | T2: 文字列３ | U2: 文字列４ | V2: 文字列５ | W2: 文字列６ | X2: 文字列７ | Y2: 文字列８ | Z2: 文字列９ | AA2: 文字列１０ | AB2: 文字列１１ | AC2: 文字列１２ | AD2: 文字列１３ | AE2: 文字列１４ | AF2: 文字列１５ | AG2: 文字列１６ | AH2: 文字列１７ | AI2: 文字列１８ | AJ2: 文字列１９ | AK2: 文字列２０ | AL2: 数値１ | AM2: 数値２ | AN2: 数値３ | AO2: 数値４ | AP2: 数値５ | AQ2: 数値６ | AR2: 数値７ | AS2: 数値８ | AT2: 数値９ | AU2: 数値１０ | AV2: 日付１ | AW2: 日付２ | AX2: 日付３ | AY2: 日付４ | AZ2: 日付５ | BA2: 日付６ | BB2: 日付７ | BC2: 日付８ | BD2: 日付９ | BE2: 日付１０ | BF2: フラグ１ | BG2: フラグ２ | BH2: フラグ３ | BI2: フラグ４ | BJ2: フラグ５ | BK2: フラグ６ | BL2: フラグ７ | BM2: フラグ８ | BN2: フラグ９ | BO2: フラグ１０ | BP2: メモ１ | BQ2: メモ２ | BR2: メモ３ | BS2: 論理削除ＦＬＧ | BT2: 論理削除ユーザＩＤ | BU2: 論理削除ユーザ名 | BV2: 論理削除日時 | BW2: 登録ユーザＩＤ | BX2: 登録ユーザ名 | BY2: 登録日時 | BZ2: 登録機能ＩＤ | CA2: 更新カウンタ | CB2: 更新ユーザＩＤ | CC2: 更新ユーザ名 | CD2: 更新日時 | CE2: 更新機能ＩＤ | CF2: 更新リクエストＮＯ
E3: 型 | F3: VARCHAR2 | G3: VARCHAR2 | H3: VARCHAR2 | I3: VARCHAR2 | J3: VARCHAR2 | K3: VARCHAR2 | L3: VARCHAR2 | M3: VARCHAR2 | N3: VARCHAR2 | O3: VARCHAR2 | P3: VARCHAR2 | Q3: VARCHAR2 | R3: VARCHAR2 | S3: VARCHAR2 | T3: VARCHAR2 | U3: VARCHAR2 | V3: VARCHAR2 | W3: VARCHAR2 | X3: VARCHAR2 | Y3: VARCHAR2 | Z3: VARCHAR2 | AA3: VARCHAR2 | AB3: VARCHAR2 | AC3: VARCHAR2 | AD3: VARCHAR2 | AE3: VARCHAR2 | AF3: VARCHAR2 | AG3: VARCHAR2 | AH3: VARCHAR2 | AI3: VARCHAR2 | AJ3: VARCHAR2 | AK3: VARCHAR2 | AL3: NUMBER | AM3: NUMBER | AN3: NUMBER | AO3: NUMBER | AP3: NUMBER | AQ3: NUMBER | AR3: NUMBER | AS3: NUMBER | AT3: NUMBER | AU3: NUMBER | AV3: DATE | AW3: DATE | AX3: DATE | AY3: DATE | AZ3: DATE | BA3: DATE | BB3: DATE | BC3: DATE | BD3: DATE | BE3: DATE | BF3: CHAR | BG3: CHAR | BH3: CHAR | BI3: CHAR | BJ3: CHAR | BK3: CHAR | BL3: CHAR | BM3: CHAR | BN3: CHAR | BO3: CHAR | BP3: VARCHAR2 | BQ3: VARCHAR2 | BR3: VARCHAR2 | BS3: CHAR | BT3: VARCHAR2 | BU3: VARCHAR2 | BV3: TIMESTAMP | BW3: VARCHAR2 | BX3: VARCHAR2 | BY3: TIMESTAMP | BZ3: VARCHAR2 | CA3: NUMBER | CB3: VARCHAR2 | CC3: VARCHAR2 | CD3: TIMESTAMP | CE3: VARCHAR2 | CF3: VARCHAR2
E4: 桁数 | F4: 5 | G4: 20 | H4: 20 | I4: 20 | J4: 20 | K4: 20 | L4: 20 | M4: 20 | N4: 20 | O4: 20 | P4: 20 | Q4: 10 | R4: 100 | S4: 100 | T4: 100 | U4: 100 | V4: 100 | W4: 100 | X4: 100 | Y4: 100 | Z4: 100 | AA4: 100 | AB4: 100 | AC4: 100 | AD4: 100 | AE4: 100 | AF4: 100 | AG4: 100 | AH4: 100 | AI4: 100 | AJ4: 100 | AK4: 100 | AL4: 21,8 | AM4: 21,8 | AN4: 21,8 | AO4: 21,8 | AP4: 21,8 | AQ4: 21,8 | AR4: 21,8 | AS4: 21,8 | AT4: 21,8 | AU4: 21,8 | BF4: 1 | BG4: 1 | BH4: 1 | BI4: 1 | BJ4: 1 | BK4: 1 | BL4: 1 | BM4: 1 | BN4: 1 | BO4: 1 | BP4: 100 | BQ4: 100 | BR4: 100 | BS4: 1 | BT4: 500 | BU4: 100 | BV4: 3 | BW4: 500 | BX4: 100 | BY4: 3 | BZ4: 50 | CA4: 90 | CB4: 500 | CC4: 100 | CD4: 3 | CE4: 50 | CF4: 50
C5: 汎用分類 | D5: 省略可否 | E5: 用途 | F5: GP_GRP_CD | G5: KEY1 | H5: KEY2 | I5: KEY3 | J5: KEY4 | K5: KEY5 | L5: KEY6 | M5: KEY7 | N5: KEY8 | O5: KEY9 | P5: KEY10 | Q5: CO_CD | R5: CHAR1 | S5: CHAR2 | T5: CHAR3 | U5: CHAR4 | V5: CHAR5 | W5: CHAR6 | X5: CHAR7 | Y5: CHAR8 | Z5: CHAR9 | AA5: CHAR10 | AB5: CHAR11 | AC5: CHAR12 | AD5: CHAR13 | AE5: CHAR14 | AF5: CHAR15 | AG5: CHAR16 | AH5: CHAR17 | AI5: CHAR18 | AJ5: CHAR19 | AK5: CHAR20 | AL5: NUM1 | AM5: NUM2 | AN5: NUM3 | AO5: NUM4 | AP5: NUM5 | AQ5: NUM6 | AR5: NUM7 | AS5: NUM8 | AT5: NUM9 | AU5: NUM10 | AV5: DT1 | AW5: DT2 | AX5: DT3 | AY5: DT4 | AZ5: DT5 | BA5: DT6 | BB5: DT7 | BC5: DT8 | BD5: DT9 | BE5: DT10 | BF5: FLG1 | BG5: FLG2 | BH5: FLG3 | BI5: FLG4 | BJ5: FLG5 | BK5: FLG6 | BL5: FLG7 | BM5: FLG8 | BN5: FLG9 | BO5: FLG10 | BP5: MEMO1 | BQ5: MEMO2 | BR5: MEMO3 | BS5: DEL_FLG | BT5: DEL_USR_ID | BU5: DEL_USR_NM | BV5: DEL_TS | BW5: INS_USR_ID | BX5: INS_USR_NM | BY5: INS_TS | BZ5: INS_FUNC_ID | CA5: UPD_CNTR | CB5: UPD_USR_ID | CC5: UPD_USR_NM | CD5: UPD_TS | CE5: UPD_FUNC_ID | CF5: UPD_SRV_REQ_NO
B6: 定義 | C6: WEB受注画面制御 | D6: 省略不可。省略時処理エラー。 | F6: M111 | G6: 受注区分 | H6: 品目区分 | I6: 品目区分詳細 | J6: 諸口ＦＬＧ | L6: 受注区分名 （設定確認要） | M6: 品目区分名 （設定確認要） | N6: 品目区分詳細名 （設定確認要） | O6: 諸口ＦＬＧ （設定確認要） | P6: 表示順 | Q6: CROWN01 | R6: 製品区分 | S6: 受注入力パタン | U6: 製品区分名 | V6: 受注入力パタン名 | BX6: 朱 | BY6: 1/17
B7: データ例 | F7: M111 | G7: 10 | H7: * | I7: * | J7: * | K7: * | L7: 加工製品 | M7: * | N7: * | O7: * | P7: 1 | Q7: J0001 | R7: 12 | S7: 1 | U7: 加工 | V7: 加工品受注（新規入力） | BF7: 0 | BG7: 0 | BH7: 0 | BI7: 0 | BJ7: 0 | BK7: 0 | BL7: 0 | BM7: 0 | BN7: 0 | BO7: 0 | BS7: 0
F8: M111 | G8: 10 | H8: * | I8: * | J8: * | K8: * | L8: 加工製品 | M8: * | N8: * | O8: * | P8: 2 | Q8: J0001 | R8: 13 | S8: 1 | U8: Ｇプリント | V8: 加工品受注（新規入力） | BF8: 0 | BG8: 0 | BH8: 0 | BI8: 0 | BJ8: 0 | BK8: 0 | BL8: 0 | BM8: 0 | BN8: 0 | BO8: 0 | BS8: 0
F9: M111 | G9: 10 | H9: * | I9: * | J9: * | K9: * | L9: 加工製品 | M9: * | N9: * | O9: * | P9: 3 | Q9: J0001 | R9: 21 | S9: 1 | U9: 巻ボール | V9: 加工品受注（新規入力） | BF9: 0 | BG9: 0 | BH9: 0 | BI9: 0 | BJ9: 0 | BK9: 0 | BL9: 0 | BM9: 0 | BN9: 0 | BO9: 0 | BS9: 0
F10: M111 | G10: 10 | H10: * | I10: * | J10: * | K10: * | L10: 加工製品 | M10: * | N10: * | O10: * | P10: 4 | Q10: J0001 | R10: 23 | S10: 1 | U10: 片面加工 | V10: 加工品受注（新規入力） | BF10: 0 | BG10: 0 | BH10: 0 | BI10: 0 | BJ10: 0 | BK10: 0 | BL10: 0 | BM10: 0 | BN10: 0 | BO10: 0 | BS10: 0
F11: M111 | G11: 10 | H11: * | I11: * | J11: * | K11: * | L11: 加工製品 | M11: * | N11: * | O11: * | P11: 5 | Q11: J0001 | R11: 31 | S11: 1 | U11: プリフル | V11: 加工品受注（新規入力） | BF11: 0 | BG11: 0 | BH11: 0 | BI11: 0 | BJ11: 0 | BK11: 0 | BL11: 0 | BM11: 0 | BN11: 0 | BO11: 0 | BS11: 0
F12: M111 | G12: 10 | H12: * | I12: * | J12: * | K12: * | L12: 加工製品 | M12: * | N12: * | O12: * | P12: 6 | Q12: J0001 | R12: 32 | S12: 1 | U12: 刷本支給 | V12: 加工品受注（新規入力） | BF12: 0 | BG12: 0 | BH12: 0 | BI12: 0 | BJ12: 0 | BK12: 0 | BL12: 0 | BM12: 0 | BN12: 0 | BO12: 0 | BS12: 0
F13: M111 | G13: 10 | H13: 2 | I13: 212 | J13: 0 | K13: * | L13: 加工製品 | M13: 製品 | N13: 加工 | O13: * | P13: * | Q13: J0001 | R13: 12 | S13: 3 | U13: 加工 | BF13: 0 | BG13: 0 | BH13: 0 | BI13: 0 | BJ13: 0 | BK13: 0 | BL13: 0 | BM13: 0 | BN13: 0 | BO13: 0 | BS13: 1
F14: M111 | G14: 10 | H14: 2 | I14: 213 | J14: 0 | K14: * | L14: 加工製品 | M14: 製品 | N14: Ｇプリント | O14: * | P14: * | Q14: J0001 | R14: 13 | S14: 3 | U14: Ｇプリント | BF14: 0 | BG14: 0 | BH14: 0 | BI14: 0 | BJ14: 0 | BK14: 0 | BL14: 0 | BM14: 0 | BN14: 0 | BO14: 0 | BS14: 1
F15: M111 | G15: 10 | H15: 2 | I15: 221 | J15: 0 | K15: * | L15: 加工製品 | M15: 製品 | N15: 巻ボール | O15: * | P15: * | Q15: J0001 | R15: 21 | S15: 3 | U15: 巻ボール | BF15: 0 | BG15: 0 | BH15: 0 | BI15: 0 | BJ15: 0 | BK15: 0 | BL15: 0 | BM15: 0 | BN15: 0 | BO15: 0 | BS15: 1
F16: M111 | G16: 10 | H16: 2 | I16: 223 | J16: 0 | K16: * | L16: 加工製品 | M16: 製品 | N16: 片面加工 | O16: * | P16: * | Q16: J0001 | R16: 23 | S16: 3 | U16: 片面加工 | BF16: 0 | BG16: 0 | BH16: 0 | BI16: 0 | BJ16: 0 | BK16: 0 | BL16: 0 | BM16: 0 | BN16: 0 | BO16: 0 | BS16: 1
F17: M111 | G17: 10 | H17: 2 | I17: 231 | J17: 0 | K17: * | L17: 加工製品 | M17: 製品 | N17: プリフル | O17: * | P17: * | Q17: J0001 | R17: 31 | S17: 3 | U17: プリフル | BF17: 0 | BG17: 0 | BH17: 0 | BI17: 0 | BJ17: 0 | BK17: 0 | BL17: 0 | BM17: 0 | BN17: 0 | BO17: 0 | BS17: 1
F18: M111 | G18: 10 | H18: 2 | I18: 232 | J18: 0 | K18: * | L18: 加工製品 | M18: 製品 | N18: 刷本支給 | O18: * | P18: * | Q18: J0001 | R18: 32 | S18: 3 | U18: 刷本支給 | BF18: 0 | BG18: 0 | BH18: 0 | BI18: 0 | BJ18: 0 | BK18: 0 | BL18: 0 | BM18: 0 | BN18: 0 | BO18: 0 | BS18: 1
F19: M111 | G19: 11 | H19: * | I19: * | J19: * | K19: * | L19: 加工製品 | M19: * | N19: * | O19: * | P19: 1 | Q19: J0001 | R19: 12 | S19: 1 | U19: 加工 | V19: 加工品受注（新規入力） | BF19: 0 | BG19: 0 | BH19: 0 | BI19: 0 | BJ19: 0 | BK19: 0 | BL19: 0 | BM19: 0 | BN19: 0 | BO19: 0 | BS19: 0
F20: M111 | G20: 11 | H20: * | I20: * | J20: * | K20: * | L20: 加工製品 | M20: * | N20: * | O20: * | P20: 2 | Q20: J0001 | R20: 13 | S20: 1 | U20: Ｇプリント | V20: 加工品受注（新規入力） | BF20: 0 | BG20: 0 | BH20: 0 | BI20: 0 | BJ20: 0 | BK20: 0 | BL20: 0 | BM20: 0 | BN20: 0 | BO20: 0 | BS20: 0
F21: M111 | G21: 11 | H21: * | I21: * | J21: * | K21: * | L21: 加工製品 | M21: * | N21: * | O21: * | P21: 3 | Q21: J0001 | R21: 21 | S21: 1 | U21: 巻ボール | V21: 加工品受注（新規入力） | BF21: 0 | BG21: 0 | BH21: 0 | BI21: 0 | BJ21: 0 | BK21: 0 | BL21: 0 | BM21: 0 | BN21: 0 | BO21: 0 | BS21: 0
F22: M111 | G22: 11 | H22: * | I22: * | J22: * | K22: * | L22: 加工製品 | M22: * | N22: * | O22: * | P22: 4 | Q22: J0001 | R22: 23 | S22: 1 | U22: 片面加工 | V22: 加工品受注（新規入力） | BF22: 0 | BG22: 0 | BH22: 0 | BI22: 0 | BJ22: 0 | BK22: 0 | BL22: 0 | BM22: 0 | BN22: 0 | BO22: 0 | BS22: 0
F23: M111 | G23: 11 | H23: * | I23: * | J23: * | K23: * | L23: 加工製品 | M23: * | N23: * | O23: * | P23: 5 | Q23: J0001 | R23: 31 | S23: 1 | U23: プリフル | V23: 加工品受注（新規入力） | BF23: 0 | BG23: 0 | BH23: 0 | BI23: 0 | BJ23: 0 | BK23: 0 | BL23: 0 | BM23: 0 | BN23: 0 | BO23: 0 | BS23: 0
F24: M111 | G24: 11 | H24: * | I24: * | J24: * | K24: * | L24: 加工製品 | M24: * | N24: * | O24: * | P24: 6 | Q24: J0001 | R24: 32 | S24: 1 | U24: 刷本支給 | V24: 加工品受注（新規入力） | BF24: 0 | BG24: 0 | BH24: 0 | BI24: 0 | BJ24: 0 | BK24: 0 | BL24: 0 | BM24: 0 | BN24: 0 | BO24: 0 | BS24: 0
F25: M111 | G25: 11 | H25: 1 | I25: 112 | J25: 0 | K25: * | L25: 加工商品 | M25: 商品 | N25: 商品加工 | O25: * | P25: * | Q25: J0001 | R25: 12 | S25: 3 | U25: 加工 | V25: 商品購買 | BF25: 0 | BG25: 0 | BH25: 0 | BI25: 0 | BJ25: 0 | BK25: 0 | BL25: 0 | BM25: 0 | BN25: 0 | BO25: 0 | BS25: 0
F26: M111 | G26: 11 | H26: 1 | I26: 113 | J26: 0 | K26: * | L26: 加工商品 | M26: 商品 | N26: 商品Ｇプリント | O26: * | P26: * | Q26: J0001 | R26: 13 | S26: 3 | U26: Ｇプリント | V26: 商品購買 | BF26: 0 | BG26: 0 | BH26: 0 | BI26: 0 | BJ26: 0 | BK26: 0 | BL26: 0 | BM26: 0 | BN26: 0 | BO26: 0 | BS26: 0
F27: M111 | G27: 11 | H27: 1 | I27: 121 | J27: 0 | K27: * | L27: 加工商品 | M27: 商品 | N27: 商品巻ボール | O27: * | P27: * | Q27: J0001 | R27: 21 | S27: 3 | U27: 巻ボール | V27: 商品購買 | BF27: 0 | BG27: 0 | BH27: 0 | BI27: 0 | BJ27: 0 | BK27: 0 | BL27: 0 | BM27: 0 | BN27: 0 | BO27: 0 | BS27: 0
F28: M111 | G28: 11 | H28: 1 | I28: 123 | J28: 2.シート受注 | K28: * | L28: 加工商品 | M28: 商品 | N28: 商品片面加工 | O28: * | P28: * | Q28: J0001 | R28: 23 | S28: 3 | U28: 片面加工 | V28: 商品購買 | BF28: 0 | BG28: 0 | BH28: 0 | BI28: 0 | BJ28: 0 | BK28: 0 | BL28: 0 | BM28: 0 | BN28: 0 | BO28: 0 | BS28: 0
F29: M111 | G29: 11 | H29: 1 | I29: 131 | J29: 0 | K29: * | L29: 加工商品 | M29: 商品 | N29: 商品プリフル | O29: * | P29: * | Q29: J0001 | R29: 31 | S29: 3 | U29: プリフル | V29: 商品購買 | BF29: 0 | BG29: 0 | BH29: 0 | BI29: 0 | BJ29: 0 | BK29: 0 | BL29: 0 | BM29: 0 | BN29: 0 | BO29: 0 | BS29: 0
F30: M111 | G30: 11 | H30: 1 | I30: 132 | J30: 0 | K30: * | L30: 加工商品 | M30: 商品 | N30: 商品刷本支給 | O30: * | P30: * | Q30: J0001 | R30: 32 | S30: 3 | U30: 刷本支給 | V30: 商品購買 | BF30: 0 | BG30: 0 | BH30: 0 | BI30: 0 | BJ30: 0 | BK30: 0 | BL30: 0 | BM30: 0 | BN30: 0 | BO30: 0 | BS30: 0
F31: M111 | G31: 11 | H31: 1 | I31: 112 | J31: 1 | K31: * | L31: 加工商品 | M31: 商品 | N31: 商品加工 | O31: 諸口 | P31: * | Q31: J0001 | R31: 12 | S31: 4 | U31: 加工 | V31: 商品購買（諸口）、経費品 | BF31: 0 | BG31: 0 | BH31: 0 | BI31: 0 | BJ31: 0 | BK31: 0 | BL31: 0 | BM31: 0 | BN31: 0 | BO31: 0 | BS31: 0
F32: M111 | G32: 11 | H32: 1 | I32: 113 | J32: 1 | K32: * | L32: 加工商品 | M32: 商品 | N32: 商品Ｇプリント | O32: 諸口 | P32: * | Q32: J0001 | R32: 13 | S32: 4 | U32: Ｇプリント | V32: 商品購買（諸口）、経費品 | BF32: 0 | BG32: 0 | BH32: 0 | BI32: 0 | BJ32: 0 | BK32: 0 | BL32: 0 | BM32: 0 | BN32: 0 | BO32: 0 | BS32: 0
F33: M111 | G33: 11 | H33: 1 | I33: 121 | J33: 1 | K33: * | L33: 加工商品 | M33: 商品 | N33: 商品巻ボール | O33: 諸口 | P33: * | Q33: J0001 | R33: 21 | S33: 4 | U33: 巻ボール | V33: 商品購買（諸口）、経費品 | BF33: 0 | BG33: 0 | BH33: 0 | BI33: 0 | BJ33: 0 | BK33: 0 | BL33: 0 | BM33: 0 | BN33: 0 | BO33: 0 | BS33: 0
F34: M111 | G34: 11 | H34: 1 | I34: 123 | J34: 1 | K34: * | L34: 加工商品 | M34: 商品 | N34: 商品片面加工 | O34: 諸口 | P34: * | Q34: J0001 | R34: 23 | S34: 4 | U34: 片面加工 | V34: 商品購買（諸口）、経費品 | BF34: 0 | BG34: 0 | BH34: 0 | BI34: 0 | BJ34: 0 | BK34: 0 | BL34: 0 | BM34: 0 | BN34: 0 | BO34: 0 | BS34: 0
F35: M111 | G35: 11 | H35: 1 | I35: 131 | J35: 1 | K35: * | L35: 加工商品 | M35: 商品 | N35: 商品プリフル | O35: 諸口 | P35: * | Q35: J0001 | R35: 31 | S35: 4 | U35: プリフル | V35: 商品購買（諸口）、経費品 | BF35: 0 | BG35: 0 | BH35: 0 | BI35: 0 | BJ35: 0 | BK35: 0 | BL35: 0 | BM35: 0 | BN35: 0 | BO35: 0 | BS35: 0
F36: M111 | G36: 11 | H36: 1 | I36: 132 | J36: 1 | K36: * | L36: 加工商品 | M36: 商品 | N36: 商品刷本支給 | O36: 諸口 | P36: * | Q36: J0001 | R36: 32 | S36: 4 | U36: 刷本支給 | V36: 商品購買（諸口）、経費品 | BF36: 0 | BG36: 0 | BH36: 0 | BI36: 0 | BJ36: 0 | BK36: 0 | BL36: 0 | BM36: 0 | BN36: 0 | BO36: 0 | BS36: 0
F37: M111 | G37: 20 | H37: * | I37: * | J37: * | K37: * | L37: シート製品 | M37: * | N37: * | O37: * | P37: 1 | Q37: J0001 | R37: 11 | S37: 2 | U37: シート | V37: シート受注（新規入力） | BF37: 0 | BG37: 0 | BH37: 0 | BI37: 0 | BJ37: 0 | BK37: 0 | BL37: 0 | BM37: 0 | BN37: 0 | BO37: 0 | BS37: 0
F38: M111 | G38: 20 | H38: * | I38: * | J38: * | K38: * | L38: シート製品 | M38: * | N38: * | O38: * | P38: 2 | Q38: J0001 | R38: 22 | S38: 2 | U38: 片面シート | V38: シート受注（新規入力） | BF38: 0 | BG38: 0 | BH38: 0 | BI38: 0 | BJ38: 0 | BK38: 0 | BL38: 0 | BM38: 0 | BN38: 0 | BO38: 0 | BS38: 0
F39: M111 | G39: 20 | H39: 2 | I39: 211 | J39: 0 | K39: * | L39: シート製品 | M39: 製品 | N39: シート | O39: * | P39: * | Q39: J0001 | R39: 11 | S39: 2 | U39: シート | V39: シート受注 | BF39: 0 | BG39: 0 | BH39: 0 | BI39: 0 | BJ39: 0 | BK39: 0 | BL39: 0 | BM39: 0 | BN39: 0 | BO39: 0 | BS39: 1
F40: M111 | G40: 20 | H40: 2 | I40: 222 | J40: 0 | K40: * | L40: シート製品 | M40: 製品 | N40: 片面シート | O40: * | P40: * | Q40: J0001 | R40: 22 | S40: 2 | U40: 片面シート | V40: シート受注 | BF40: 0 | BG40: 0 | BH40: 0 | BI40: 0 | BJ40: 0 | BK40: 0 | BL40: 0 | BM40: 0 | BN40: 0 | BO40: 0 | BS40: 1
...

Sheet 補足説明資料_受注画面制御
A1: =[3]表紙!A54 -> Webシステム | O1: 文書名 | AC1: モジュールID | AJ1: =[3]表紙!AJ64 -> MSBB | AQ1: モジュール名 | AX1: =[3]表紙!AX64 -> Webシステム | BL1: 文書番号 | BU1: Version | CB1: Rev.
O2: =[3]表紙!O65 -> 表紙 | AC2: サブモジュールID | AJ2: =[3]表紙!AJ65 -> MSBBPA070 | AQ2: サブモジュール名 | AX2: =[3]表紙!AX65 -> 0 | BL2: =[3]表紙!BL65 -> 0 | BU2: =[3]表紙!BU65 -> 0 | CB2: =[3]表紙!CB65 -> 0
O3: =RIGHT(CELL("filename",$A$1),LEN(CELL("filename",$A$1))-FIND("]",CELL("filename",$A$1))) -> 補足説明資料_受注画面制御 | AC3: 表題 | AJ3: =[3]表紙!AJ66 -> 0 | AQ3: =[3]表紙!AQ66 -> 0
AO5: 補足説明
V7: 受注業務パタン | CJ7: V7.0 画面制御の追加 | CV7: V8.0 受注画面制御の詳細化
G8: 画面項目 | V8: 加工受注 | AB8: シート受注 | AH8: 商品購買 | AN8: 版型 | AT8: 有償支給 | AZ8: 経費品 | BF8: 原紙売り（受発注方式） | BL8: 輪切り | CJ8: V7.0 画面制御の追加 | CV8: V8.0 受注画面制御の詳細化
G9: 第1画面（TOP画面） 基本情報 | V9: ○ | AB9: ○ | AH9: ○ | AN9: ● | AT9: ○ | AZ9: ○ | BF9: ○ | BL9: ○ | CJ9: V7.0 画面制御の追加 | CV9: V8.0 受注画面制御の詳細化
G10: 第1画面（TOP画面） 受注明細 | V10: ○ | AB10: - | AH10: - | AN10: - | AT10: - | AZ10: - | BF10: - | BL10: - | CJ10: V7.0 画面制御の追加 | CV10: V8.0 受注画面制御の詳細化
G11: 第2画面（基本情報）基本情報 | V11: 〇 | AB11: 〇 | AH11: 〇 | AN11: ● | AT11: 〇 | AZ11: 〇 | BF11: ○ | BL11: ○ | CJ11: V7.0 画面制御の追加 | CV11: V8.0 受注画面制御の詳細化
G12: 第2画面（基本情報）構成情報 | V12: ● | AB12: 〇 | AH12: - | AN12: ● | AT12: - | AZ12: - | BF12: ○ | BL12: ○ | CJ12: V7.0 画面制御の追加 | CV12: V8.0 受注画面制御の詳細化
G13: 第2画面（基本情報）仕入情報 | V13: 〇 | AB13: 〇 | AH13: 〇 | AN13: ● | AT13: - | AZ13: - | BF13: ○ | BL13: ○ | CJ13: V7.0 画面制御の追加 | CV13: V8.0 受注画面制御の詳細化
G14: 第2画面（基本情報）備考 | V14: 〇 | AB14: 〇 | AH14: 〇 | AN14: ● | AT14: ○ | AZ14: ○ | BF14: ○ | BL14: ○ | CJ14: V7.0 画面制御の追加 | CV14: V8.0 受注画面制御の詳細化
G15: 第3画面（工程情報）工程情報 | V15: ● | AB15: 〇 | AH15: - | AN15: - | AT15: - | AZ15: - | BF15: ○ | BL15: ○ | CJ15: V7.0 画面制御の追加 | CV15: V8.0 受注画面制御の詳細化
G16: ポップアップ（詳細入力画面）基本情報 | V16: ● | AB16: 〇 | AH16: - | AN16: - | AT16: - | AZ16: - | BF16: ○ | BL16: ○ | CJ16: V7.0 画面制御の追加 | CV16: V8.0 受注画面制御の詳細化
G17: ポップアップ（詳細入力画面）外注情報 | V17: ● | AB17: 〇 | AH17: - | AN17: - | AT17: - | AZ17: - | BF17: ○ | BL17: ○ | CJ17: V7.0 画面制御の追加 | CV17: V8.0 受注画面制御の詳細化
G18: ポップアップ（詳細入力画面）工程情報 | V18: ● | AB18: 〇 | AH18: - | AN18: - | AT18: - | AZ18: - | BF18: ○ | BL18: ○ | CJ18: V7.0 画面制御の追加 | CV18: V8.0 受注画面制御の詳細化
G19: ポップアップ（詳細入力画面）作業明細 | V19: ● | AB19: 〇 | AH19: - | AN19: - | AT19: - | AZ19: - | BF19: ○ | BL19: ○ | CJ19: V7.0 画面制御の追加 | CV19: V8.0 受注画面制御の詳細化
... G21: 第4画面（材料設定）材料明細 | V21: ● | AB21: 〇 | AH21: - | AN21: - | AT21: - | AZ21: - | BF21: ○ | BL21: ○ | CJ21: V7.0 画面制御の追加 | CV21: V8.0 受注画面制御の詳細化
CJ22: V7.0 画面制御の追加 | CV22: V8.0 受注画面制御の詳細化
G23: ※注釈 | CJ23: V7.0 画面制御の追加 | CV23: V8.0 受注画面制御の詳細化
H24: 〇：編集可能 | CJ24: V7.0 画面制御の追加 | CV24: V8.0 受注画面制御の詳細化
H25: ●：参照のみ | CJ25: V7.0 画面制御の追加 | CV25: V8.0 受注画面制御の詳細化
H26: -：非表示 | CJ26: V7.0 画面制御の追加 | CV26: V8.0 受注画面制御の詳細化
CJ27: V7.0 画面制御の追加 | CV27: V8.0 受注画面制御の詳細化
G28: 受注区分、製品区分の組合せがどの受注業務パタンにあたるかは「受発注パタン詳細」シート参照 | CJ28: V7.0 画面制御の追加 | CV28: V8.0 受注画面制御の詳細化
CJ29: V7.0 画面制御の追加 | CV29: V8.0 受注画面制御の詳細化
CV30: V8.0 受注画面制御の詳細化
CV31: V8.0 受注画面制御の詳細化
CV32: V8.0 受注画面制御の詳細化
CV33: V8.0 受注画面制御の詳細化
CV34: V8.0 受注画面制御の詳細化
CV35: V8.0 受注画面制御の詳細化
CV36: V8.0 受注画面制御の詳細化
CV37: V8.0 受注画面制御の詳細化
CV38: V8.0 受注画面制御の詳細化
CV39: V8.0 受注画面制御の詳細化
CV40: V8.0 受注画面制御の詳細化
CV41: V8.0 受注画面制御の詳細化
... CV184: V8.0 受注画面制御の詳細化

Sheet 1_加工受注
A3: 画面イメージ
B5: ≫凡例
Q6: ・・・ | S6: ボタン
C7: 見積計算書№ | Q7: ・・・ | S7: 検索項目(検索画面表示選択)
C8: 品名 | Q8: ・・・ | S8: 入力項目
C9: 得意先 | Q9: ・・・ | S9: 表示項目(得意先名称、原紙名等)
C10: 操作種別 | I10: ●登録 | M10: ○訂正 | Q10: ・・・ | S10: 選択項目(一つのみ選択可能)
C11: 受注区分 | Q11: ・・・ | S11: 選択項目(一つのみ選択可能)
C12: 作業順 | I12: ☑AAA | M12: ☑BBB | Q12: ・・・ | S12: 選択項目(複数選択可能)
B15: 〇加工品受注初期表示
D16: ログイン営業担当の部門が初期設定
C21: TOP画面
D23: 操作種別 | J23: ●登録 | N23: ○訂正 | R23: ○削除 | V23: ○参照 | FT23: 2022/10/29 落合 記載箇所が不明 | GG23: MDSOL回答 2022/10/31 手配NOの表示条件に追加しました。 2段表示は難しいとのことです。 | HI23: 2022/11/01 落合 問題なし
D24: 受注区分 | S24: 得意先 | AO24: 手配NO | BK24: ←「訂正」「削除」「参照」の時、初期フォーカス
D27: 受注部門 | J27: XXXXXX | O27: 名古屋営業 | AD27: 受注日 | AO27: 受注区分
D28: 得意先 | AD28: 客先納期 | AO28: 数量 | FE28: 2022/10/29 落合 記載箇所が不明 | FR28: MDSOL回答 2022/10/31 WEB受注一覧照会の設計書に追記しました。 | GN28: 2022/11/01 落合 問題なし
FU29: 2022/10/29 落合 入力中の受注を除いて既に超えている場合です。 | GQ29: MDSOL回答 2022/10/31 石田 承知しました。処理概要に得意先指定時（TOP画面、基本画面）を記載致しました。 | HY29: 2022/11/01 落合 問題なし
D30: 注文書No | W30: 先方担当 | AO30: 宛名 | BC30: 様 | EY30: 2022/10/29 落合 問題なし
D31: 運送会社 | W31: 出荷日時 | FD31: 2022/11/01 落合 問題なし
D33: 売価区分
D35: 受注明細
D36: 製品CD | J36: (件名:オートフィルタ) | AC36: ← ｾｯﾄ品目指定することで、以下の一覧に部材品目表示
D39: № | F39: 手配NO1 | I39: 手配NO2 | L39: 手配NO3 | O39: 製品CD/品目CD | T39: CP品名1 | Y39: CP品名2 | AB39: 単位 | AD39: 数量 | AG39: 特値 | AJ39: 個別単価 | AM39: ｾｯﾄ単価 | AP39: 客先納期 | AT39: 手配区分 | AW39: 納品先 | BA39: 納品先名 | BE39: 物流グループ | BH39: 預り売上 | BL39: 売上理由 | BP39: 受注№/受注明細№
E40: 1 | AG40: □ | BI40: □
E41: 2 | AG41: □ | BI41: □
E42: 3 | AG42: □ | BI42: □ | FD42: MDSOL回答 2022/10/31 コピー行追加で納期を変更した場合は、手配NOが同一となるため、まとめ期間内ならまとまります。行追加の場合は分割されます。 | GV42: 2022/11/01 落合 問題なし
F44: ※メニュー「シート受注入力」を選択した場合は、第２画面からスタート
F45: ※メニュー「購買品受注入力」を選択した場合は、第２画面からスタート。 工程情報登録はなし。 入力項目の追加あり。
B52: 〇受注基本情報を入力
C54: TOP画面
D56: 操作種別 | J56: ●登録 | N56: ○訂正 | R56: ○削除 | V56: ○参照
D57: 受注区分 | S57: 得意先 | AO57: 手配NO | BK57: ←「訂正」「削除」「参照」の時、初期フォーカス
D60: 受注部門 | J60: XXXXXX | O60: 名古屋営業 | AD60: 受注日 | AH60: 44622 | AO60: 受注区分 | AS60: 21：加工商品
D61: 得意先 | J61: XXXXXXX | Q61: 得意先A | AD61: 客先納期 | AH61: 44628 | AO61: 数量 | AS61: 5000
D63: 注文書No | J63: XXXXXXXXXXX | W63: 先方担当 | AC63: 田中 | AO63: 宛名 | AS63: 得意先A 営業部 田中 | BC63: 様
D64: 運送会社 | J64: XXXXXXX | O64: コダマ名古屋 | W64: 出荷日時 | AC64: 44627 | AH64: 0.5
D66: 売価区分 | J66: 単品売り
D68: 受注明細
D69: 製品CD | J69: 123456789010000 | Q69: セット品 | AC69: ← ｾｯﾄ品目指定することで、以下の一覧に部材品目表示
D72: № | F72: 手配NO1 | I72: 手配NO2 | L72: 手配NO3 | O72: 製品CD/品目CD | T72: CP品名1 | Y72: CP品名2 | AB72: 単位 | AD72: 数量 | AG72: 特値 | AJ72: 個別単価 | AM72: ｾｯﾄ単価 | AP72: 客先納期 | AT72: 手配区分 | AW72: 納品先 | BA72: 納品先名 | BE72: 物流グループ | BH72: 預り売上 | BL72: 売上理由 | BP72: 受注№/受注明細№
...

Sheet 2_シート受注
A3: 画面イメージ
B5: ≫凡例
Q6: ・・・ | S6: ボタン
C7: 見積計算書№ | Q7: ・・・ | S7: 検索項目(検索画面表示選択)
C8: 品名 | Q8: ・・・ | S8: 入力項目
C9: 得意先 | Q9: ・・・ | S9: 表示項目(得意先名称、原紙名等)
C10: 操作種別 | I10: ●登録 | M10: ○訂正 | Q10: ・・・ | S10: 選択項目(一つのみ選択可能)
C11: 受注区分 | Q11: ・・・ | S11: 選択項目(一つのみ選択可能)
C12: 作業順 | I12: ☑AAA | M12: ☑BBB | Q12: ・・・ | S12: 選択項目(複数選択可能)
B15: 〇シート受注初期表示
D16: ログイン営業担当の部門が初期設定
C21: TOP画面
D23: 操作種別 | J23: ●登録 | N23: ○訂正 | R23: ○削除 | V23: ○参照 | FT23: 2022/10/29 落合 記載箇所が不明 | GG23: MDSOL回答 2022/10/31 手配NOの表示条件に追加しました。 2段表示は難しいとのことです。 | HI23: 2022/11/01 落合 問題なし
D24: 受注区分 | S24: 得意先 | AO24: 手配NO | BK24: ←「訂正」「削除」「参照」の時、初期フォーカス
D27: 受注部門 | J27: XXXXXX | O27: 名古屋営業 | AD27: 受注日 | AO27: 受注区分
D28: 得意先 | AD28: 客先納期 | AO28: 数量 | FE28: 2022/10/29 落合 記載箇所が不明 | FR28: MDSOL回答 2022/10/31 WEB受注一覧照会の設計書に追記しました。 | GN28: 2022/11/01 落合 問題なし
FU29: 2022/10/29 落合 入力中の受注を除いて既に超えている場合です。 | GQ29: MDSOL回答 2022/10/31 石田 承知しました。処理概要に得意先指定時（TOP画面、基本画面）を記載致しました。 | HY29: 2022/11/01 落合 問題なし
D30: 注文書No | W30: 先方担当 | AO30: 宛名 | BC30: 様 | EY30: 2022/10/29 落合 問題なし
D31: 運送会社 | W31: 出荷日時 | FD31: 2022/11/01 落合 問題なし
D33: 売価区分
D35: 受注明細
D36: 製品CD | J36: (件名:オートフィルタ) | AC36: ← ｾｯﾄ品目指定することで、以下の一覧に部材品目表示
D39: № | F39: 手配NO1 | I39: 手配NO2 | L39: 手配NO3 | O39: 製品CD/品目CD | T39: CP品名1 | Y39: CP品名2 | AB39: 単位 | AD39: 数量 | AG39: 特値 | AJ39: 個別単価 | AM39: ｾｯﾄ単価 | AP39: 客先納期 | AT39: 手配区分 | AW39: 納品先 | BA39: 納品先名 | BE39: 物流グループ | BH39: 預り売上 | BL39: 売上理由 | BP39: 受注№/受注明細№
E40: 1 | AG40: □ | BI40: □
E41: 2 | AG41: □ | BI41: □
E42: 3 | AG42: □ | BI42: □ | FD42: MDSOL回答 2022/10/31 コピー行追加で納期を変更した場合は、手配NOが同一となるため、まとめ期間内ならまとまります。行追加の場合は分割されます。 | GV42: 2022/11/01 落合 問題なし
F44: ※メニュー「シート受注入力」を選択した場合は、第２画面からスタート
F45: ※メニュー「購買品受注入力」を選択した場合は、第２画面からスタート。 工程情報登録はなし。 入力項目の追加あり。
B52: 〇受注基本情報を入力
C54: TOP画面
D56: 操作種別 | J56: ●登録 | N56: ○訂正 | R56: ○削除 | V56: ○参照
D57: 受注区分 | S57: 得意先 | AO57: 手配NO | BK57: ←「訂正」「削除」「参照」の時、初期フォーカス
D60: 受注部門 | J60: XXXXXX | O60: 名古屋営業 | AD60: 受注日 | AH60: 44622 | AO60: 受注区分 | AS60: 11：シート商品
D61: 得意先 | J61: XXXXXXX | Q61: 得意先A | AD61: 客先納期 | AH61: 44628 | AO61: 数量 | AS61: 5000
D63: 注文書No | J63: XXXXXXXXXXX | W63: 先方担当 | AC63: 田中 | AO63: 宛名 | AS63: 得意先A 営業部 田中 | BC63: 様
D64: 運送会社 | J64: XXXXXXX | O64: コダマ名古屋 | W64: 出荷日時 | AC64: 44627 | AH64: 0.5
D66: 売価区分 | J66: 単品売り
B78: 〇第２画面初期表示
C79: 第1画面のインプットから初期表示
C80: 第２画面
...

Sheet 3_商品購買
A3: 画面イメージ
B5: ≫凡例
Q6: ・・・ | S6: ボタン
C7: 見積計算書№ | Q7: ・・・ | S7: 検索項目(検索画面表示選択)
C8: 品名 | Q8: ・・・ | S8: 入力項目
C9: 得意先 | Q9: ・・・ | S9: 表示項目(得意先名称、原紙名等)
C10: 操作種別 | I10: ●登録 | M10: ○訂正 | Q10: ・・・ | S10: 選択項目(一つのみ選択可能)
C11: 受注区分 | Q11: ・・・ | S11: 選択項目(一つのみ選択可能)
C12: 作業順 | I12: ☑AAA | M12: ☑BBB | Q12: ・・・ | S12: 選択項目(複数選択可能)
B15: 〇商品購買初期表示
D16: ログイン営業担当の部門が初期設定
C21: TOP画面
D23: 操作種別 | J23: ●登録 | N23: ○訂正 | R23: ○削除 | V23: ○参照 | FT23: 2022/10/29 落合 記載箇所が不明 | GG23: MDSOL回答 2022/10/31 手配NOの表示条件に追加しました。 2段表示は難しいとのことです。 | HI23: 2022/11/01 落合 問題なし
D24: 受注区分 | S24: 得意先 | AO24: 手配NO | BK24: ←「訂正」「削除」「参照」の時、初期フォーカス
D27: 受注部門 | J27: XXXXXX | O27: 名古屋営業 | AD27: 受注日 | AO27: 受注区分
D28: 得意先 | AD28: 客先納期 | AO28: 数量 | FE28: 2022/10/29 落合 記載箇所が不明 | FR28: MDSOL回答 2022/10/31 WEB受注一覧照会の設計書に追記しました。 | GN28: 2022/11/01 落合 問題なし
FU29: 2022/10/29 落合 入力中の受注を除いて既に超えている場合です。 | GQ29: MDSOL回答 2022/10/31 石田 承知しました。処理概要に得意先指定時（TOP画面、基本画面）を記載致しました。 | HY29: 2022/11/01 落合 問題なし
D30: 注文書No | W30: 先方担当 | AO30: 宛名 | BC30: 様 | EY30: 2022/10/29 落合 問題なし
D31: 運送会社 | W31: 出荷日時 | FD31: 2022/11/01 落合 問題なし
D33: 売価区分
D35: 受注明細
D36: 製品CD | J36: (件名:オートフィルタ) | AC36: ← ｾｯﾄ品目指定することで、以下の一覧に部材品目表示
D39: № | F39: 手配NO1 | I39: 手配NO2 | L39: 手配NO3 | O39: 製品CD/品目CD | T39: CP品名1 | Y39: CP品名2 | AB39: 単位 | AD39: 数量 | AG39: 特値 | AJ39: 個別単価 | AM39: ｾｯﾄ単価 | AP39: 客先納期 | AT39: 手配区分 | AW39: 納品先 | BA39: 納品先名 | BE39: 物流グループ | BH39: 預り売上 | BL39: 売上理由 | BP39: 受注№/受注明細№
E40: 1 | AG40: □ | BI40: □
E41: 2 | AG41: □ | BI41: □
E42: 3 | AG42: □ | BI42: □ | FD42: MDSOL回答 2022/10/31 コピー行追加で納期を変更した場合は、手配NOが同一となるため、まとめ期間内ならまとまります。行追加の場合は分割されます。 | GV42: 2022/11/01 落合 問題なし
F44: ※メニュー「シート受注入力」を選択した場合は、第２画面からスタート
F45: ※メニュー「購買品受注入力」を選択した場合は、第２画面からスタート。 工程情報登録はなし。 入力項目の追加あり。
B52: 〇受注基本情報を入力
C54: TOP画面
D56: 操作種別 | J56: ●登録 | N56: ○訂正 | R56: ○削除 | V56: ○参照
D57: 受注区分 | S57: 得意先 | AO57: 手配NO | BK57: ←「訂正」「削除」「参照」の時、初期フォーカス
D60: 受注部門 | J60: XXXXXX | O60: 名古屋営業 | AD60: 受注日 | AH60: 44622 | AO60: 受注区分 | AS60: 30：購買品
D61: 得意先 | J61: XXXXXXX | Q61: 得意先A | AD61: 客先納期 | AH61: 44628 | AO61: 数量 | AS61: 5000
D63: 注文書No | J63: XXXXXXXXXXX | W63: 先方担当 | AC63: 田中 | AO63: 宛名 | AS63: 得意先A 営業部 田中 | BC63: 様
D64: 運送会社 | J64: XXXXXXX | O64: コダマ名古屋 | W64: 出荷日時 | AC64: 44627 | AH64: 0.5
D66: 売価区分 | J66: 単品売り
B78: 〇第２画面初期表示
C79: 第1画面のインプットから初期表示
C80: 第２画面
...

Sheet 3_商品購買（版型）
A3: 画面イメージ
B5: ≫凡例
Q6: ・・・ | S6: ボタン
C7: 見積計算書№ | Q7: ・・・ | S7: 検索項目(検索画面表示選択)
C8: 品名 | Q8: ・・・ | S8: 入力項目
C9: 得意先 | Q9: ・・・ | S9: 表示項目(得意先名称、原紙名等)
C10: 操作種別 | I10: ●登録 | M10: ○訂正 | Q10: ・・・ | S10: 選択項目(一つのみ選択可能)
C11: 受注区分 | Q11: ・・・ | S11: 選択項目(一つのみ選択可能)
C12: 作業順 | I12: ☑AAA | M12: ☑BBB | Q12: ・・・ | S12: 選択項目(複数選択可能)
B15: 〇版型受注表示
D16: ログイン営業担当の部門が初期設定
C21: TOP画面
D23: 操作種別 | J23: ●登録 | N23: ○訂正 | R23: ○削除 | V23: ○参照 | FT23: 2022/10/29 落合 記載箇所が不明 | GG23: MDSOL回答 2022/10/31 手配NOの表示条件に追加しました。 2段表示は難しいとのことです。 | HI23: 2022/11/01 落合 問題なし
D24: 受注区分 | S24: 得意先 | AO24: 手配NO | BK24: ←「訂正」「削除」「参照」の時、初期フォーカス
D27: 受注部門 | J27: XXXXXX | O27: 名古屋営業 | AD27: 受注日 | AO27: 受注区分
D28: 得意先 | AD28: 客先納期 | AO28: 数量 | FE28: 2022/10/29 落合 記載箇所が不明 | FR28: MDSOL回答 2022/10/31 WEB受注一覧照会の設計書に追記しました。 | GN28: 2022/11/01 落合 問題なし
FU29: 2022/10/29 落合 入力中の受注を除いて既に超えている場合です。 | GQ29: MDSOL回答 2022/10/31 石田 承知しました。処理概要に得意先指定時（TOP画面、基本画面）を記載致しました。 | HY29: 2022/11/01 落合 問題なし
D30: 注文書No | W30: 先方担当 | AO30: 宛名 | BC30: 様 | EY30: 2022/10/29 落合 問題なし
D31: 運送会社 | W31: 出荷日時 | FD31: 2022/11/01 落合 問題なし
D33: 売価区分
D35: 受注明細
D36: 製品CD | J36: (件名:オートフィルタ) | AC36: ← ｾｯﾄ品目指定することで、以下の一覧に部材品目表示
D39: № | F39: 手配NO1 | I39: 手配NO2 | L39: 手配NO3 | O39: 製品CD/品目CD | T39: CP品名1 | Y39: CP品名2 | AB39: 単位 | AD39: 数量 | AG39: 特値 | AJ39: 個別単価 | AM39: ｾｯﾄ単価 | AP39: 客先納期 | AT39: 手配区分 | AW39: 納品先 | BA39: 納品先名 | BE39: 物流グループ | BH39: 預り売上 | BL39: 売上理由 | BP39: 受注№/受注明細№
E40: 1 | AG40: □ | BI40: □
E41: 2 | AG41: □ | BI41: □
E42: 3 | AG42: □ | BI42: □ | FD42: MDSOL回答 2022/10/31 コピー行追加で納期を変更した場合は、手配NOが同一となるため、まとめ期間内ならまとまります。行追加の場合は分割されます。 | GV42: 2022/11/01 落合 問題なし
F44: ※メニュー「シート受注入力」を選択した場合は、第２画面からスタート
F45: ※メニュー「購買品受注入力」を選択した場合は、第２画面からスタート。 工程情報登録はなし。 入力項目の追加あり。
B52: 〇参照モードにして手配NOを入力し検索する
C54: TOP画面
D56: 操作種別 | J56: ○登録 | N56: ○訂正 | R56: ○削除 | V56: ●参照
D57: 受注区分 | S57: 得意先 | AO57: 手配NO | AR57: XXXXXXXXXX | BK57: ←「訂正」「削除」「参照」の時、初期フォーカス
D60: 受注部門 | J60: XXXXXX | O60: 名古屋営業 | AD60: 受注日 | AH60: 44622 | AO60: 受注区分 | AS60: 30：購買品
D61: 得意先 | J61: XXXXXXX | Q61: 得意先A | AD61: 客先納期 | AH61: 44628 | AO61: 数量 | AS61: 1
D63: 注文書No | J63: XXXXXXXXXXX | W63: 先方担当 | AC63: 田中 | AO63: 宛名 | AS63: 得意先A 営業部 田中 | BC63: 様
D64: 運送会社 | J64: XXXXXXX | O64: コダマ名古屋 | W64: 出荷日時 | AC64: 44627 | AH64: 0.5
D66: 売価区分 | J66: 単品売り
B79: 〇第２画面初期表示
C80: 第1画面のインプットから初期表示
C81: 第２画面
...

Sheet 4_商品購買（有償支給）
A3: 画面イメージ
B5: ≫凡例
Q6: ・・・ | S6: ボタン
C7: 見積計算書№ | Q7: ・・・ | S7: 検索項目(検索画面表示選択)
C8: 品名 | Q8: ・・・ | S8: 入力項目
C9: 得意先 | Q9: ・・・ | S9: 表示項目(得意先名称、原紙名等)
C10: 操作種別 | I10: ●登録 | M10: ○訂正 | Q10: ・・・ | S10: 選択項目(一つのみ選択可能)
C11: 受注区分 | Q11: ・・・ | S11: 選択項目(一つのみ選択可能)
C12: 作業順 | I12: ☑AAA | M12: ☑BBB | Q12: ・・・ | S12: 選択項目(複数選択可能)
B15: 〇有償支給初期表示
D16: ログイン営業担当の部門が初期設定
C21: TOP画面
D23: 操作種別 | J23: ●登録 | N23: ○訂正 | R23: ○削除 | V23: ○参照 | FT23: 2022/10/29 落合 記載箇所が不明 | GG23: MDSOL回答 2022/10/31 手配NOの表示条件に追加しました。 2段表示は難しいとのことです。 | HI23: 2022/11/01 落合 問題なし
D24: 受注区分 | S24: 得意先 | AO24: 手配NO | BK24: ←「訂正」「削除」「参照」の時、初期フォーカス
D27: 受注部門 | J27: XXXXXX | O27: 名古屋営業 | AD27: 受注日 | AO27: 受注区分
D28: 得意先 | AD28: 客先納期 | AO28: 数量 | FE28: 2022/10/29 落合 記載箇所が不明 | FR28: MDSOL回答 2022/10/31 WEB受注一覧照会の設計書に追記しました。 | GN28: 2022/11/01 落合 問題なし
FU29: 2022/10/29 落合 入力中の受注を除いて既に超えている場合です。 | GQ29: MDSOL回答 2022/10/31 石田 承知しました。処理概要に得意先指定時（TOP画面、基本画面）を記載致しました。 | HY29: 2022/11/01 落合 問題なし
D30: 注文書No | W30: 先方担当 | AO30: 宛名 | BC30: 様 | EY30: 2022/10/29 落合 問題なし
D31: 運送会社 | W31: 出荷日時 | FD31: 2022/11/01 落合 問題なし
D33: 売価区分
D35: 受注明細
D36: 製品CD | J36: (件名:オートフィルタ) | AC36: ← ｾｯﾄ品目指定することで、以下の一覧に部材品目表示
D39: № | F39: 手配NO1 | I39: 手配NO2 | L39: 手配NO3 | O39: 製品CD/品目CD | T39: CP品名1 | Y39: CP品名2 | AB39: 単位 | AD39: 数量 | AG39: 特値 | AJ39: 個別単価 | AM39: ｾｯﾄ単価 | AP39: 客先納期 | AT39: 手配区分 | AW39: 納品先 | BA39: 納品先名 | BE39: 物流グループ | BH39: 預り売上 | BL39: 売上理由 | BP39: 受注№/受注明細№
E40: 1 | AG40: □ | BI40: □
E41: 2 | AG41: □ | BI41: □
E42: 3 | AG42: □ | BI42: □ | FD42: MDSOL回答 2022/10/31 コピー行追加で納期を変更した場合は、手配NOが同一となるため、まとめ期間内ならまとまります。行追加の場合は分割されます。 | GV42: 2022/11/01 落合 問題なし
F44: ※メニュー「シート受注入力」を選択した場合は、第２画面からスタート
F45: ※メニュー「購買品受注入力」を選択した場合は、第２画面からスタート。 工程情報登録はなし。 入力項目の追加あり。
B52: 〇受注基本情報を入力
C54: TOP画面
D56: 操作種別 | J56: ●登録 | N56: ○訂正 | R56: ○削除 | V56: ○参照
D57: 受注区分 | S57: 得意先 | AO57: 手配NO | BK57: ←「訂正」「削除」「参照」の時、初期フォーカス
D60: 受注部門 | J60: XXXXXX | O60: 名古屋営業 | AD60: 受注日 | AH60: 44622 | AO60: 受注区分 | AS60: 30：購買品
D61: 得意先 | J61: XXXXXXX | Q61: 得意先A | AD61: 客先納期 | AH61: 44628 | AO61: 数量 | AS61: 1
D63: 注文書No | J63: XXXXXXXXXXX | W63: 先方担当 | AC63: 田中 | AO63: 宛名 | AS63: 得意先A 営業部 田中 | BC63: 様
D64: 運送会社 | J64: XXXXXXX | O64: コダマ名古屋 | W64: 出荷日時 | AC64: 44627 | AH64: 0.5
D66: 売価区分 | J66: 単品売り
B78: 〇第２画面初期表示
C79: 第1画面のインプットから初期表示
C80: 第２画面
...

Sheet 4_商品購買（諸口）
A3: 画面イメージ
B5: ≫凡例
Q6: ・・・ | S6: ボタン
C7: 見積計算書№ | Q7: ・・・ | S7: 検索項目(検索画面表示選択)
C8: 品名 | Q8: ・・・ | S8: 入力項目
C9: 得意先 | Q9: ・・・ | S9: 表示項目(得意先名称、原紙名等)
C10: 操作種別 | I10: ●登録 | M10: ○訂正 | Q10: ・・・ | S10: 選択項目(一つのみ選択可能)
C11: 受注区分 | Q11: ・・・ | S11: 選択項目(一つのみ選択可能)
C12: 作業順 | I12: ☑AAA | M12: ☑BBB | Q12: ・・・ | S12: 選択項目(複数選択可能)
B15: 〇経費品初期表示
D16: ログイン営業担当の部門が初期設定
C21: TOP画面
D23: 操作種別 | J23: ●登録 | N23: ○訂正 | R23: ○削除 | V23: ○参照 | FT23: 2022/10/29 落合 記載箇所が不明 | GG23: MDSOL回答 2022/10/31 手配NOの表示条件に追加しました。 2段表示は難しいとのことです。 | HI23: 2022/11/01 落合 問題なし
D24: 受注区分 | S24: 得意先 | AO24: 手配NO | BK24: ←「訂正」「削除」「参照」の時、初期フォーカス
D27: 受注部門 | J27: XXXXXX | O27: 名古屋営業 | AD27: 受注日 | AO27: 受注区分
D28: 得意先 | AD28: 客先納期 | AO28: 数量 | FE28: 2022/10/29 落合 記載箇所が不明 | FR28: MDSOL回答 2022/10/31 WEB受注一覧照会の設計書に追記しました。 | GN28: 2022/11/01 落合 問題なし
FU29: 2022/10/29 落合 入力中の受注を除いて既に超えている場合です。 | GQ29: MDSOL回答 2022/10/31 石田 承知しました。処理概要に得意先指定時（TOP画面、基本画面）を記載致しました。 | HY29: 2022/11/01 落合 問題なし
D30: 注文書No | W30: 先方担当 | AO30: 宛名 | BC30: 様 | EY30: 2022/10/29 落合 問題なし
D31: 運送会社 | W31: 出荷日時 | FD31: 2022/11/01 落合 問題なし
D33: 売価区分
D35: 受注明細
D36: 製品CD | J36: (件名:オートフィルタ) | AC36: ← ｾｯﾄ品目指定することで、以下の一覧に部材品目表示
D39: № | F39: 手配NO1 | I39: 手配NO2 | L39: 手配NO3 | O39: 製品CD/品目CD | T39: CP品名1 | Y39: CP品名2 | AB39: 単位 | AD39: 数量 | AG39: 特値 | AJ39: 個別単価 | AM39: ｾｯﾄ単価 | AP39: 客先納期 | AT39: 手配区分 | AW39: 納品先 | BA39: 納品先名 | BE39: 物流グループ | BH39: 預り売上 | BL39: 売上理由 | BP39: 受注№/受注明細№
E40: 1 | AG40: □ | BI40: □
E41: 2 | AG41: □ | BI41: □
E42: 3 | AG42: □ | BI42: □ | FD42: MDSOL回答 2022/10/31 コピー行追加で納期を変更した場合は、手配NOが同一となるため、まとめ期間内ならまとまります。行追加の場合は分割されます。 | GV42: 2022/11/01 落合 問題なし
F44: ※メニュー「シート受注入力」を選択した場合は、第２画面からスタート
F45: ※メニュー「購買品受注入力」を選択した場合は、第２画面からスタート。 工程情報登録はなし。 入力項目の追加あり。
B52: 〇受注基本情報を入力
C54: TOP画面
D56: 操作種別 | J56: ●登録 | N56: ○訂正 | R56: ○削除 | V56: ○参照
D57: 受注区分 | S57: 得意先 | AO57: 手配NO | BK57: ←「訂正」「削除」「参照」の時、初期フォーカス
D60: 受注部門 | J60: XXXXXX | O60: 名古屋営業 | AD60: 受注日 | AH60: 44622 | AO60: 受注区分 | AS60: 30：購買品
D61: 得意先 | J61: XXXXXXX | Q61: 得意先A | AD61: 客先納期 | AH61: 44628 | AO61: 数量 | AS61: 1
D63: 注文書No | J63: XXXXXXXXXXX | W63: 先方担当 | AC63: 田中 | AO63: 宛名 | AS63: 得意先A 営業部 田中 | BC63: 様
D64: 運送会社 | J64: XXXXXXX | O64: コダマ名古屋 | W64: 出荷日時 | AC64: 44627 | AH64: 0.5
D66: 売価区分 | J66: 単品売り
B78: 〇第２画面初期表示
C79: 第1画面のインプットから初期表示
C80: 第２画面
...

Sheet 5_原紙（原紙売り）
A3: 画面イメージ
B5: ≫凡例
Q6: ・・・ | S6: ボタン
C7: 見積計算書№ | Q7: ・・・ | S7: 検索項目(検索画面表示選択)
C8: 品名 | Q8: ・・・ | S8: 入力項目
C9: 得意先 | Q9: ・・・ | S9: 表示項目(得意先名称、原紙名等)
C10: 操作種別 | I10: ●登録 | M10: ○訂正 | Q10: ・・・ | S10: 選択項目(一つのみ選択可能)
C11: 受注区分 | Q11: ・・・ | S11: 選択項目(一つのみ選択可能)
C12: 作業順 | I12: ☑AAA | M12: ☑BBB | Q12: ・・・ | S12: 選択項目(複数選択可能)
B15: 〇原紙売り初期表示
D16: ログイン営業担当の部門が初期設定
C21: TOP画面
D23: 操作種別 | J23: ●登録 | N23: ○訂正 | R23: ○削除 | V23: ○参照 | FT23: 2022/10/29 落合 記載箇所が不明 | GG23: MDSOL回答 2022/10/31 手配NOの表示条件に追加しました。 2段表示は難しいとのことです。 | HI23: 2022/11/01 落合 問題なし
D24: 受注区分 | S24: 得意先 | AO24: 手配NO | BK24: ←「訂正」「削除」「参照」の時、初期フォーカス
D27: 受注部門 | J27: XXXXXX | O27: 名古屋営業 | AD27: 受注日 | AO27: 受注区分
D28: 得意先 | AD28: 客先納期 | AO28: 数量 | FE28: 2022/10/29 落合 記載箇所が不明 | FR28: MDSOL回答 2022/10/31 WEB受注一覧照会の設計書に追記しました。 | GN28: 2022/11/01 落合 問題なし
FU29: 2022/10/29 落合 入力中の受注を除いて既に超えている場合です。 | GQ29: MDSOL回答 2022/10/31 石田 承知しました。処理概要に得意先指定時（TOP画面、基本画面）を記載致しました。 | HY29: 2022/11/01 落合 問題なし
D30: 注文書No | W30: 先方担当 | AO30: 宛名 | BC30: 様 | EY30: 2022/10/29 落合 問題なし
D31: 運送会社 | W31: 出荷日時 | FD31: 2022/11/01 落合 問題なし
D33: 売価区分
D35: 受注明細
D36: 製品CD | J36: (件名:オートフィルタ) | AC36: ← ｾｯﾄ品目指定することで、以下の一覧に部材品目表示
D39: № | F39: 手配NO1 | I39: 手配NO2 | L39: 手配NO3 | O39: 製品CD/品目CD | T39: CP品名1 | Y39: CP品名2 | AB39: 単位 | AD39: 数量 | AG39: 特値 | AJ39: 個別単価 | AM39: ｾｯﾄ単価 | AP39: 客先納期 | AT39: 手配区分 | AW39: 納品先 | BA39: 納品先名 | BE39: 物流グループ | BH39: 預り売上 | BL39: 売上理由 | BP39: 受注№/受注明細№
E40: 1 | AG40: □ | BI40: □
E41: 2 | AG41: □ | BI41: □
E42: 3 | AG42: □ | BI42: □ | FD42: MDSOL回答 2022/10/31 コピー行追加で納期を変更した場合は、手配NOが同一となるため、まとめ期間内ならまとまります。行追加の場合は分割されます。 | GV42: 2022/11/01 落合 問題なし
F44: ※メニュー「シート受注入力」を選択した場合は、第２画面からスタート
F45: ※メニュー「購買品受注入力」を選択した場合は、第２画面からスタート。 工程情報登録はなし。 入力項目の追加あり。
B52: 〇受注基本情報を入力
C54: TOP画面
D56: 操作種別 | J56: ●登録 | N56: ○訂正 | R56: ○削除 | V56: ○参照
D57: 受注区分 | S57: 得意先 | AO57: 手配NO | BK57: ←「訂正」「削除」「参照」の時、初期フォーカス
D60: 受注部門 | J60: XXXXXX | O60: 名古屋営業 | AD60: 受注日 | AH60: 44622 | AO60: 受注区分 | AS60: 40：原紙
D61: 得意先 | J61: XXXXXXX | Q61: 得意先A | AD61: 客先納期 | AH61: 44628 | AO61: 数量 | AS61: 1000
D63: 注文書No | J63: XXXXXXXXXXX | W63: 先方担当 | AC63: 田中 | AO63: 宛名 | AS63: 得意先A 営業部 田中 | BC63: 様
D64: 運送会社 | J64: XXXXXXX | O64: コダマ名古屋 | W64: 出荷日時 | AC64: 44627 | AH64: 0.5
D66: 売価区分 | J66: 単品売り
B78: 〇第２画面初期表示
C79: 第1画面のインプットから初期表示
C80: 第２画面
...

Sheet 5_原紙（輪切り）
A3: 画面イメージ
B5: ≫凡例
Q6: ・・・ | S6: ボタン
C7: 見積計算書№ | Q7: ・・・ | S7: 検索項目(検索画面表示選択)
C8: 品名 | Q8: ・・・ | S8: 入力項目
C9: 得意先 | Q9: ・・・ | S9: 表示項目(得意先名称、原紙名等)
C10: 操作種別 | I10: ●登録 | M10: ○訂正 | Q10: ・・・ | S10: 選択項目(一つのみ選択可能)
C11: 受注区分 | Q11: ・・・ | S11: 選択項目(一つのみ選択可能)
C12: 作業順 | I12: ☑AAA | M12: ☑BBB | Q12: ・・・ | S12: 選択項目(複数選択可能)
B15: 〇原紙売り初期表示
D16: ログイン営業担当の部門が初期設定
C21: TOP画面
D23: 操作種別 | J23: ●登録 | N23: ○訂正 | R23: ○削除 | V23: ○参照 | FT23: 2022/10/29 落合 記載箇所が不明 | GG23: MDSOL回答 2022/10/31 手配NOの表示条件に追加しました。 2段表示は難しいとのことです。 | HI23: 2022/11/01 落合 問題なし
D24: 受注区分 | S24: 得意先 | AO24: 手配NO | BK24: ←「訂正」「削除」「参照」の時、初期フォーカス
D27: 受注部門 | J27: XXXXXX | O27: 名古屋営業 | AD27: 受注日 | AO27: 受注区分
D28: 得意先 | AD28: 客先納期 | AO28: 数量 | FE28: 2022/10/29 落合 記載箇所が不明 | FR28: MDSOL回答 2022/10/31 WEB受注一覧照会の設計書に追記しました。 | GN28: 2022/11/01 落合 問題なし
FU29: 2022/10/29 落合 入力中の受注を除いて既に超えている場合です。 | GQ29: MDSOL回答 2022/10/31 石田 承知しました。処理概要に得意先指定時（TOP画面、基本画面）を記載致しました。 | HY29: 2022/11/01 落合 問題なし
D30: 注文書No | W30: 先方担当 | AO30: 宛名 | BC30: 様 | EY30: 2022/10/29 落合 問題なし
D31: 運送会社 | W31: 出荷日時 | FD31: 2022/11/01 落合 問題なし
D33: 売価区分
D35: 受注明細
D36: 製品CD | J36: (件名:オートフィルタ) | AC36: ← ｾｯﾄ品目指定することで、以下の一覧に部材品目表示
D39: № | F39: 手配NO1 | I39: 手配NO2 | L39: 手配NO3 | O39: 製品CD/品目CD | T39: CP品名1 | Y39: CP品名2 | AB39: 単位 | AD39: 数量 | AG39: 特値 | AJ39: 個別単価 | AM39: ｾｯﾄ単価 | AP39: 客先納期 | AT39: 手配区分 | AW39: 納品先 | BA39: 納品先名 | BE39: 物流グループ | BH39: 預り売上 | BL39: 売上理由 | BP39: 受注№/受注明細№
E40: 1 | AG40: □ | BI40: □
E41: 2 | AG41: □ | BI41: □
E42: 3 | AG42: □ | BI42: □ | FD42: MDSOL回答 2022/10/31 コピー行追加で納期を変更した場合は、手配NOが同一となるため、まとめ期間内ならまとまります。行追加の場合は分割されます。 | GV42: 2022/11/01 落合 問題なし
F44: ※メニュー「シート受注入力」を選択した場合は、第２画面からスタート
F45: ※メニュー「購買品受注入力」を選択した場合は、第２画面からスタート。 工程情報登録はなし。 入力項目の追加あり。
B52: 〇受注基本情報を入力
C54: TOP画面
D56: 操作種別 | J56: ●登録 | N56: ○訂正 | R56: ○削除 | V56: ○参照
D57: 受注区分 | S57: 得意先 | AO57: 手配NO | BK57: ←「訂正」「削除」「参照」の時、初期フォーカス
D60: 受注部門 | J60: XXXXXX | O60: 名古屋営業 | AD60: 受注日 | AH60: 44622 | AO60: 受注区分 | AS60: 40：原紙
D61: 得意先 | J61: XXXXXXX | Q61: 得意先A | AD61: 客先納期 | AH61: 44628 | AO61: 数量 | AS61: 3
D63: 注文書No | J63: XXXXXXXXXXX | W63: 先方担当 | AC63: 田中 | AO63: 宛名 | AS63: 得意先A 営業部 田中 | BC63: 様
D64: 運送会社 | J64: XXXXXXX | O64: コダマ名古屋 | W64: 出荷日時 | AC64: 44627 | AH64: 0.5
D66: 売価区分 | J66: 単品売り
B78: 〇第２画面初期表示
C79: 第1画面のインプットから初期表示
C80: 第２画面
...

Sheet ｜➡参考

Sheet 受注⇒MCの集约
A1: 受注区分 | B1: 受注区分名 | C1: 製品区分大 | D1: 製品区分大名 | E1: 品目区分 | F1: 品目区分名 | G1: 品目区分詳細ＣＤ | H1: 標準品目区分詳細名 | I1: 品目系マスタ登録元 | J1: 製品受注パタン | K1: 受注業務パタン | O1: オーダ区分
A3: 10 | B3: 加工製品 | C3: 12 | D3: 加工 | E3: 2 | F3: 製品 | G3: 212 | H3: 加工 | I3: 製品マスタ | J3: CPで取り扱いがある（品目登録済） | K3: 加工品受注 | M3: =IF(N3<>N2, "1","") -> 1 | N3: =A3&C3&E3&G3&I3&J3&K3 -> 10122212製品マスタCPで取り扱いがある（品目登録済）加工品受注 | O3: 内製
A4: 10 | B4: 加工製品 | C4: 12 | D4: 加工 | E4: 2 | F4: 製品 | G4: 212 | H4: 加工 | I4: 製品マスタ | J4: CPで取り扱いがある（品目登録済） | K4: 加工品受注 | M4: =IF(N4<>N3, "1","") | N4: =A4&C4&E4&G4&I4&J4&K4 -> 10122212製品マスタCPで取り扱いがある（品目登録済）加工品受注 | O4: 内製
A5: 10 | B5: 加工製品 | C5: 12 | D5: 加工 | E5: 2 | F5: 製品 | G5: 212 | H5: 加工 | I5: 製品マスタ | J5: CPで取り扱いがある（品目登録済） | K5: 加工品受注 | M5: =IF(N5<>N4, "1","") | N5: =A5&C5&E5&G5&I5&J5&K5 -> 10122212製品マスタCPで取り扱いがある（品目登録済）加工品受注 | O5: 内製
A6: 10 | B6: 加工製品 | C6: 12 | D6: 加工 | E6: 2 | F6: 製品 | G6: 212 | H6: 加工 | I6: 製品マスタ | J6: CPで取り扱いがある（品目登録済） | K6: 加工品受注 | M6: =IF(N6<>N5, "1","") | N6: =A6&C6&E6&G6&I6&J6&K6 -> 10122212製品マスタCPで取り扱いがある（品目登録済）加工品受注 | O6: 外注
A7: 10 | B7: 加工製品 | C7: 12 | D7: 加工 | E7: 2 | F7: 製品 | G7: 212 | H7: 加工 | I7: 製品マスタ | J7: CPで取り扱いがある（品目登録済） | K7: 加工品受注 | M7: =IF(N7<>N6, "1","") | N7: =A7&C7&E7&G7&I7&J7&K7 -> 10122212製品マスタCPで取り扱いがある（品目登録済）加工品受注 | O7: 外注
A8: 10 | B8: 加工製品 | C8: 12 | D8: 加工 | E8: 2 | F8: 製品 | G8: 212 | H8: 加工 | I8: 製品マスタ | J8: CPで取り扱いがある（品目登録済） | K8: 加工品受注 | M8: =IF(N8<>N7, "1","") | N8: =A8&C8&E8&G8&I8&J8&K8 -> 10122212製品マスタCPで取り扱いがある（品目登録済）加工品受注 | O8: WG間転送
A9: 10 | B9: 加工製品 | C9: 13 | D9: Ｇプリント | E9: 2 | F9: 製品 | G9: 213 | H9: Ｇプリント | I9: 製品マスタ | J9: CPで取り扱いがある（品目登録済） | K9: 加工品受注 | M9: =IF(N9<>N8, "1","") -> 1 | N9: =A9&C9&E9&G9&I9&J9&K9 -> 10132213製品マスタCPで取り扱いがある（品目登録済）加工品受注 | O9: 内製
A10: 10 | B10: 加工製品 | C10: 13 | D10: Ｇプリント | E10: 2 | F10: 製品 | G10: 213 | H10: Ｇプリント | I10: 製品マスタ | J10: CPで取り扱いがある（品目登録済） | K10: 加工品受注 | M10: =IF(N10<>N9, "1","") | N10: =A10&C10&E10&G10&I10&J10&K10 -> 10132213製品マスタCPで取り扱いがある（品目登録済）加工品受注 | O10: 内製
A11: 10 | B11: 加工製品 | C11: 13 | D11: Ｇプリント | E11: 2 | F11: 製品 | G11: 213 | H11: Ｇプリント | I11: 製品マスタ | J11: CPで取り扱いがある（品目登録済） | K11: 加工品受注 | M11: =IF(N11<>N10, "1","") | N11: =A11&C11&E11&G11&I11&J11&K11 -> 10132213製品マスタCPで取り扱いがある（品目登録済）加工品受注 | O11: 内製
A12: 10 | B12: 加工製品 | C12: 13 | D12: Ｇプリント | E12: 2 | F12: 製品 | G12: 213 | H12: Ｇプリント | I12: 製品マスタ | J12: CPで取り扱いがある（品目登録済） | K12: 加工品受注 | M12: =IF(N12<>N11, "1","") | N12: =A12&C12&E12&G12&I12&J12&K12 -> 10132213製品マスタCPで取り扱いがある（品目登録済）加工品受注 | O12: 外注
A13: 10 | B13: 加工製品 | C13: 13 | D13: Ｇプリント | E13: 2 | F13: 製品 | G13: 213 | H13: Ｇプリント | I13: 製品マスタ | J13: CPで取り扱いがある（品目登録済） | K13: 加工品受注 | M13: =IF(N13<>N12, "1","") | N13: =A13&C13&E13&G13&I13&J13&K13 -> 10132213製品マスタCPで取り扱いがある（品目登録済）加工品受注 | O13: 外注
A14: 10 | B14: 加工製品 | C14: 13 | D14: Ｇプリント | E14: 2 | F14: 製品 | G14: 213 | H14: Ｇプリント | I14: 製品マスタ | J14: CPで取り扱いがある（品目登録済） | K14: 加工品受注 | M14: =IF(N14<>N13, "1","") | N14: =A14&C14&E14&G14&I14&J14&K14 -> 10132213製品マスタCPで取り扱いがある（品目登録済）加工品受注 | O14: WG間転送
... A90: 21 | B90: シート商品 | C90: 22 | D90: 片面シート | E90: 1 | F90: 商品 | G90: 122 | H90: 商品片面シート | I90: 品目マスタ | J90: CPで取り扱いが無い（諸口品目） | K90: 商品購買 | M90: =IF(N90<>N89, "1","") | N90: =A90&C90&E90&G90&I90&J90&K90 -> 21221122品目マスタCPで取り扱いが無い（諸口品目）商品購買 | O90: 購買
A91: 30 | B91: 購買品 | C91: 51 | D91: 外装シート | E91: 1 | F91: 商品 | G91: 151 | H91: 外装シート | I91: 品目マスタ | J91: CPで取り扱いが無い（諸口品目） | K91: 商品購買 | M91: =IF(N91<>N90, "1","") -> 1 | N91: =A91&C91&E91&G91&I91&J91&K91 -> 30511151品目マスタCPで取り扱いが無い（諸口品目）商品購買 | O91: 購買
A92: 30 | B92: 購買品 | C92: 51 | D92: 外装シート | E92: 1 | F92: 商品 | G92: 151 | H92: 外装シート | I92: 品目マスタ | J92: CPで取り扱いが無い（諸口品目） | K92: 商品購買 | M92: =IF(N92<>N91, "1","") | N92: =A92&C92&E92&G92&I92&J92&K92 -> 30511151品目マスタCPで取り扱いが無い（諸口品目）商品購買 | O92: 購買
A93: 30 | B93: 購買品 | C93: 52 | D93: 外装ケース | E93: 1 | F93: 商品 | G93: 152 | H93: 外装ケース | I93: 品目マスタ | J93: CPで取り扱いが無い（諸口品目） | K93: 商品購買 | M93: =IF(N93<>N92, "1","") -> 1 | N93: =A93&C93&E93&G93&I93&J93&K93 -> 30521152品目マスタCPで取り扱いが無い（諸口品目）商品購買 | O93: 購買
A94: 30 | B94: 購買品 | C94: 52 | D94: 外装ケース | E94: 1 | F94: 商品 | G94: 152 | H94: 外装ケース | I94: 品目マスタ | J94: CPで取り扱いが無い（諸口品目） | K94: 商品購買 | M94: =IF(N94<>N93, "1","") | N94: =A94&C94&E94&G94&I94&J94&K94 -> 30521152品目マスタCPで取り扱いが無い（諸口品目）商品購買 | O94: 購買
A95: 30 | B95: 購買品 | C95: 62 | D95: その他 | E95: 1 | F95: 商品 | G95: 162 | H95: 商品その他 | I95: 品目マスタ | J95: CPで取り扱いが無い（諸口品目） | K95: 商品購買 | M95: =IF(N95<>N94, "1","") -> 1 | N95: =A95&C95&E95&G95&I95&J95&K95 -> 30621162品目マスタCPで取り扱いが無い（諸口品目）商品購買 | O95: 購買
A96: 30 | B96: 購買品 | C96: 62 | D96: その他 | E96: 1 | F96: 商品 | G96: 162 | H96: 商品その他 | I96: 品目マスタ | J96: CPで取り扱いが無い（諸口品目） | K96: 商品購買 | M96: =IF(N96<>N95, "1","") | N96: =A96&C96&E96&G96&I96&J96&K96 -> 30621162品目マスタCPで取り扱いが無い（諸口品目）商品購買 | O96: 購買
A97: 30 | B97: 購買品 | C97: 63 | D97: デザイン代 | E97: 9 | F97: その他 | G97: 963 | H97: デザイン代 | I97: 品目マスタ | J97: CPで取り扱いが無い（諸口品目） | K97: 経費受注 | M97: =IF(N97<>N96, "1","") -> 1 | N97: =A97&C97&E97&G97&I97&J97&K97 -> 30639963品目マスタCPで取り扱いが無い（諸口品目）経費受注 | O97: -
A98: 30 | B98: 購買品 | C98: 71 | D98: 袋 | E98: 1 | F98: 商品 | G98: 171 | H98: 袋 | I98: 品目マスタ | J98: CPで取り扱いが無い（諸口品目） | K98: 商品購買 | M98: =IF(N98<>N97, "1","") -> 1 | N98: =A98&C98&E98&G98&I98&J98&K98 -> 30711171品目マスタCPで取り扱いが無い（諸口品目）商品購買 | O98: 購買
A99: 30 | B99: 購買品 | C99: 71 | D99: 袋 | E99: 1 | F99: 商品 | G99: 171 | H99: 袋 | I99: 品目マスタ | J99: CPで取り扱いが無い（諸口品目） | K99: 商品購買 | M99: =IF(N99<>N98, "1","") | N99: =A99&C99&E99&G99&I99&J99&K99 -> 30711171品目マスタCPで取り扱いが無い（諸口品目）商品購買 | O99: 購買
A100: 30 | B100: 購買品 | C100: 81 | D100: 運賃 | E100: 9 | F100: その他 | G100: 981 | H100: 運賃 | I100: 品目マスタ | J100: CPで取り扱いが無い（諸口品目） | K100: 経費受注 | M100: =IF(N100<>N99, "1","") -> 1 | N100: =A100&C100&E100&G100&I100&J100&K100 -> 30819981品目マスタCPで取り扱いが無い（諸口品目）経費受注 | O100: -
A101: 30 | B101: 購買品 | C101: 91 | D101: 資材料 | E101: 9 | F101: その他 | G101: 991 | H101: 資材料 | I101: 品目マスタ | J101: CPで取り扱いが無い（諸口品目） | K101: 経費受注 | M101: =IF(N101<>N100, "1","") -> 1 | N101: =A101&C101&E101&G101&I101&J101&K101 -> 30919991品目マスタCPで取り扱いが無い（諸口品目）経費受注 | O101: -
A102: 30 | B102: 購買品 | C102: 92 | D102: 前加工料 | E102: 9 | F102: その他 | G102: 992 | H102: 前加工料 | I102: 品目マスタ | J102: CPで取り扱いが無い（諸口品目） | K102: 経費受注 | M102: =IF(N102<>N101, "1","") -> 1 | N102: =A102&C102&E102&G102&I102&J102&K102 -> 30929992品目マスタCPで取り扱いが無い（諸口品目）経費受注 | O102: -
A103: 30 | B103: 購買品 | C103: 80 | D103: モールド | E103: 1 | F103: 商品 | G103: 180 | H103: モールド | I103: 品目マスタ | J103: CPで取り扱いが無い（諸口品目） | K103: 商品購買 | M103: =IF(N103<>N102, "1","") -> 1 | N103: =A103&C103&E103&G103&I103&J103&K103 -> 30801180品目マスタCPで取り扱いが無い（諸口品目）商品購買 | O103: 購買
A104: 30 | B104: 購買品 | C104: 80 | D104: モールド | E104: 1 | F104: 商品 | G104: 180 | H104: モールド | I104: 品目マスタ | J104: CPで取り扱いが無い（諸口品目） | K104: 商品購買 | M104: =IF(N104<>N103, "1","") | N104: =A104&C104&E104&G104&I104&J104&K104 -> 30801180品目マスタCPで取り扱いが無い（諸口品目）商品購買 | O104: 購買
A105: 40 | B105: 原紙 | C105: 33 | D105: コートボール | E105: 1 | F105: 商品 | G105: 133 | H105: 商品コートボール | I105: 製品マスタ | J105: CPで取り扱いがある（品目登録済） | K105: 加工品受注 | M105: =IF(N105<>N104, "1","") -> 1 | N105: =A105&C105&E105&G105&I105&J105&K105 -> 40331133製品マスタCPで取り扱いがある（品目登録済）加工品受注 | O105: 外注
A106: 40 | B106: 原紙 | C106: 33 | D106: コートボール | E106: 1 | F106: 商品 | G106: 133 | H106: 商品コートボール | I106: 製品マスタ | J106: CPで取り扱いがある（品目登録済） | K106: 加工品受注 | M106: =IF(N106<>N105, "1","") | N106: =A106&C106&E106&G106&I106&J106&K106 -> 40331133製品マスタCPで取り扱いがある（品目登録済）加工品受注 | O106: 外注
A107: 40 | B107: 原紙 | C107: 33 | D107: コートボール | E107: 1 | F107: 商品 | G107: 133 | H107: 商品コートボール | I107: 製品マスタ | J107: CPで取り扱いがある（品目登録済） | K107: 加工品受注 | M107: =IF(N107<>N106, "1","") | N107: =A107&C107&E107&G107&I107&J107&K107 -> 40331133製品マスタCPで取り扱いがある（品目登録済）加工品受注 | O107: WG間転送
A108: 40 | B108: 原紙 | C108: 33 | D108: コートボール | E108: 1 | F108: 商品 | G108: 133 | H108: 商品コートボール | I108: 品目マスタ | J108: CPで取り扱いが無い（諸口品目） | K108: 商品購買 | M108: =IF(N108<>N107, "1","") -> 1 | N108: =A108&C108&E108&G108&I108&J108&K108 -> 40331133品目マスタCPで取り扱いが無い（諸口品目）商品購買 | O108: 購買
A109: 40 | B109: 原紙 | C109: 33 | D109: コートボール | E109: 1 | F109: 商品 | G109: 133 | H109: 商品コートボール | I109: 品目マスタ | J109: CPで取り扱いが無い（諸口品目） | K109: 商品購買 | M109: =IF(N109<>N108, "1","") | N109: =A109&C109&E109&G109&I109&J109&K109 -> 40331133品目マスタCPで取り扱いが無い（諸口品目）商品購買 | O109: 購買
A110: 40 | B110: 原紙 | C110: 33 | D110: コートボール | E110: 2 | F110: 製品 | G110: 233 | H110: コートボール製品 | I110: 製品マスタ | J110: CPで取り扱いがある（品目登録済） | K110: 加工品受注 | M110: =IF(N110<>N109, "1","") -> 1 | N110: =A110&C110&E110&G110&I110&J110&K110 -> 40332233製品マスタCPで取り扱いがある（品目登録済）加工品受注 | O110: 内製
A111: 40 | B111: 原紙 | C111: 33 | D111: コートボール | E111: 2 | F111: 製品 | G111: 233 | H111: コートボール製品 | I111: 製品マスタ | J111: CPで取り扱いがある（品目登録済） | K111: 加工品受注 | M111: =IF(N111<>N110, "1","") | N111: =A111&C111&E111&G111&I111&J111&K111 -> 40332233製品マスタCPで取り扱いがある（品目登録済）加工品受注 | O111: 内製
A112: 40 | B112: 原紙 | C112: 33 | D112: コートボール | E112: 2 | F112: 製品 | G112: 233 | H112: コートボール製品 | I112: 製品マスタ | J112: CPで取り扱いがある（品目登録済） | K112: 加工品受注 | M112: =IF(N112<>N111, "1","") | N112: =A112&C112&E112&G112&I112&J112&K112 -> 40332233製品マスタCPで取り扱いがある（品目登録済）加工品受注 | O112: 内製
A113: 40 | B113: 原紙 | C113: 33 | D113: コートボール | E113: 2 | F113: 製品 | G113: 233 | H113: コートボール製品 | I113: 製品マスタ | J113: CPで取り扱いがある（品目登録済） | K113: 加工品受注 | M113: =IF(N113<>N112, "1","") | N113: =A113&C113&E113&G113&I113&J113&K113 -> 40332233製品マスタCPで取り扱いがある（品目登録済）加工品受注 | O113: 外注
A114: 40 | B114: 原紙 | C114: 33 | D114: コートボール | E114: 2 | F114: 製品 | G114: 233 | H114: コートボール製品 | I114: 製品マスタ | J114: CPで取り扱いがある（品目登録済） | K114: 加工品受注 | M114: =IF(N114<>N113, "1","") | N114: =A114&C114&E114&G114&I114&J114&K114 -> 40332233製品マスタCPで取り扱いがある（品目登録済）加工品受注 | O114: 外注
A115: 40 | B115: 原紙 | C115: 33 | D115: コートボール | E115: 2 | F115: 製品 | G115: 233 | H115: コートボール製品 | I115: 製品マスタ | J115: CPで取り扱いがある（品目登録済） | K115: 加工品受注 | M115: =IF(N115<>N114, "1","") | N115: =A115&C115&E115&G115&I115&J115&K115 -> 40332233製品マスタCPで取り扱いがある（品目登録済）加工品受注 | O115: WG間転送
A116: 40 | B116: 原紙 | C116: 33 | D116: コートボール | E116: 6 | F116: 原料 | G116: 603 | H116: コートボール | I116: WEB受注 | J116: CPで取り扱いがある（品目登録済） | K116: 原紙売り（受発注方式） | M116: =IF(N116<>N115, "1","") -> 1 | N116: =A116&C116&E116&G116&I116&J116&K116 -> 40336603WEB受注CPで取り扱いがある（品目登録済）原紙売り（受発注方式） | O116: 本支店売買（受発注）
...

Sheet 画面制御（試し）
B1: TOP画面
E2: 基本情報 | F2: 受注明細
B3: 受注区分 | D3: 補足 | E3: 全項目 | F3: セット品CDの指定 | G3: 明細行数 | H3: 製品CD | I3: 品目CD | J3: CP品名1 | K3: CP品名2 | L3: 単位 | M3: 数量 | N3: 特値 | O3: 個別単価 | P3: ｾｯﾄ単価 | Q3: 客先納期 | R3: 手配区分 | S3: 納品先 | T3: 納品先名 | U3: 物流グループ | V3: 預り売上 | W3: 売上理由 | X3: 受注№/受注明細№
B4: 10 | C4: 加工製品 | D4: 段ボール受注 | E4: 既存仕様 | G4: 制限なし | H4: 行別選択するか、セット品に含まれる製品 | J4: 次画面入力値 | K4: 次画面入力値 | L4: 製品マスタ | M4: 既存仕様 | N4: 既存仕様 | O4: 既存仕様 | P4: 既存仕様 | Q4: 既存仕様 | R4: 既存仕様 | S4: 既存仕様 | T4: 既存仕様 | U4: 既存仕様 | V4: 既存仕様 | W4: 既存仕様 | X4: 既存仕様
B5: 11 | C5: 加工商品 | D5: 段ボール受注 | E5: 既存仕様 | G5: 制限なし | H5: 行別選択するか、セット品に含まれる製品 | J5: 次画面入力値 | K5: 次画面入力値 | L5: 製品マスタ | M5: 既存仕様 | N5: 既存仕様 | O5: 既存仕様 | P5: 既存仕様 | Q5: 既存仕様 | R5: 既存仕様 | S5: 既存仕様 | T5: 既存仕様 | U5: 既存仕様 | V5: 既存仕様 | W5: 既存仕様 | X5: 既存仕様
B6: 20 | C6: シート製品 | D6: シート受注 | E6: 既存仕様 | F6: 入力不可 | G6: 1行のみ | H6: 保存時採番 | J6: 次画面入力値 | K6: 次画面入力値 | L6: 次画面入力値 | M6: 製品と同じ | N6: 製品と同じ | O6: 製品と同じ | P6: 製品と同じ | Q6: 製品と同じ | R6: 製品と同じ | S6: 製品と同じ | T6: 製品と同じ | U6: 製品と同じ | V6: 製品と同じ | W6: 製品と同じ | X6: 製品と同じ
B7: 21 | C7: シート商品 | D7: シート受注 | E7: 既存仕様 | F7: 入力不可 | G7: 1行のみ | H7: 保存時採番 | J7: 次画面入力値 | K7: 次画面入力値 | L7: 次画面入力値 | M7: 製品と同じ | N7: 製品と同じ | O7: 製品と同じ | P7: 製品と同じ | Q7: 製品と同じ | R7: 製品と同じ | S7: 製品と同じ | T7: 製品と同じ | U7: 製品と同じ | V7: 製品と同じ | W7: 製品と同じ | X7: 製品と同じ
B8: 30 | C8: 購買品 | D8: 経費受注 | E8: 既存仕様 | F8: 入力不可 | G8: 1行のみ | J8: 次画面入力値 | K8: 次画面入力値 | L8: 次画面入力値 | M8: 製品と同じ | N8: 製品と同じ | O8: 製品と同じ | P8: 製品と同じ | Q8: 製品と同じ | R8: 製品と同じ | S8: 製品と同じ | T8: 製品と同じ | U8: 製品と同じ | V8: 製品と同じ | W8: 製品と同じ | X8: 製品と同じ
B9: 40 | C9: 原紙 | D9: 通常受注 （生原紙、加工原紙、印刷原紙） | E9: 既存仕様 | F9: 入力不可 | G9: 1行のみ | J9: 次画面入力値 | K9: 次画面入力値 | L9: 次画面入力値 | M9: 製品と同じ | N9: 製品と同じ | O9: 製品と同じ | P9: 製品と同じ | Q9: 製品と同じ | R9: 製品と同じ | S9: 製品と同じ | T9: 製品と同じ | U9: 製品と同じ | V9: 製品と同じ | W9: 製品と同じ | X9: 製品と同じ
B11: 基本情報画面
E12: 基本情報 | L12: 構成情報 | M12: 仕入情報 | N12: 備考
B13: 受注区分 | D13: 補足 | E13: 製品区分 | H13: 預り売上 | I13: 納入予備 | J13: 営業サンプル | K13: 定数出荷 | L13: 全項目 | M13: 全項目 | N13: 全項目
B14: 10 | C14: 加工製品 | D14: 段ボール受注
B15: 11 | C15: 加工商品 | D15: 段ボール受注
B16: 20 | C16: シート製品 | D16: シート受注
B17: 21 | C17: シート商品 | D17: シート受注
B18: 30 | C18: 購買品 | D18: 経費受注 （運賃、保管料など） | H18: 入力不可 | I18: 入力不可 | J18: 入力不可 | K18: 入力不可 | L18: 入力不可 | M18: 入力不可 | N18: 入力不可
B19: 30 | C19: 購買品 | D19: 通常受注 （経費品以外のMC品目）
B20: 30 | C20: 購買品 | D20: 通常受注 （版型）
B21: 40 | C21: 原紙 | D21: 通常受注 （生原紙、加工原紙、印刷原紙）
B24: 工程情報画面
E25: 工程情報
B26: 受注区分 | D26: 補足 | E26: 全項目
B27: 10 | C27: 加工製品 | D27: 段ボール受注
B28: 11 | C28: 加工商品 | D28: 段ボール受注
B29: 20 | C29: シート製品 | D29: シート受注
B30: 21 | C30: シート商品 | D30: シート受注
B31: 30 | C31: 購買品 | D31: 経費受注 （運賃、保管料など） | E31: 入力不可
B32: 30 | C32: 購買品 | D32: 通常受注 （経費品以外のMC品目） | E32: 入力不可
B33: 30 | C33: 購買品 | D33: 通常受注 （版型） | E33: 入力不可
B34: 40 | C34: 原紙 | D34: 通常受注 （生原紙、加工原紙、印刷原紙）
B36: ポップアップ画面（詳細入力）
E37: 基本情報 | F37: 外注情報 | G37: 工程情報 | H37: 作業明細 | I37: 連産品明細
B38: 受注区分 | D38: 補足 | E38: 全項目 | F38: 全項目 | G38: 全項目 | H38: 全項目 | I38: 全項目
B39: 10 | C39: 加工製品 | D39: 段ボール受注
B40: 11 | C40: 加工商品 | D40: 段ボール受注
B41: 20 | C41: シート製品 | D41: シート受注
B42: 21 | C42: シート商品 | D42: シート受注
B43: 30 | C43: 購買品 | D43: 経費受注 （運賃、保管料など） | E43: 入力不可 | F43: 入力不可 | G43: 入力不可 | H43: 入力不可 | I43: 入力不可
B44: 30 | C44: 購買品 | D44: 通常受注 （経費品以外のMC品目） | E44: 入力不可 | F44: 入力不可 | G44: 入力不可 | H44: 入力不可 | I44: 入力不可
...

Sheet 纏め（試し）
E1: 受注区分・製品区分の組合せ
B2: 受注区分 | C2: 受注区分名 | E2: 受注区分 | F2: 受注区分名 | G2: 製品区分 大 | H2: 製品区分名 大 | J2: 製品区分 | L2: 受注品目 | M2: 製品区分 大 | N2: 製品区分名 大 | O2: 製品 | Q2: 商品
O3: 内製 | P3: 外注 | R3: 本支店売買 | S3: 通常 | T3: 諸口
B4: 10 | C4: 加工製品 | E4: 10 | F4: 加工製品 | G4: 12 | H4: 加工 | J4: 12:加工 | L4: 段ボール（加工品） | M4: 12 | N4: 加工 | O4: 〇 | P4: 〇 | S4: >外注< | T4: 〇 （MC品目マスタ）
B5: 11 | C5: 加工商品 | E5: 10 | F5: 加工製品 | G5: 13 | H5: Ｇプリント | J5: 13:Ｇプリント | M5: 13 | N5: Ｇプリント | O5: 〇 | P5: 〇 | S5: >外注< | T5: 〇 （MC品目マスタ）
B6: 20 | C6: シート製品 | E6: 10 | F6: 加工製品 | G6: 21 | H6: 巻ボール | J6: 21:巻ボール | M6: 21 | N6: 巻ボール | O6: 〇 | P6: 〇 | S6: >外注< | T6: 〇 （MC品目マスタ）
B7: 21 | C7: シート商品 | E7: 10 | F7: 加工製品 | G7: 23 | H7: 片面加工 | J7: 23:片面加工 | M7: 23 | N7: 片面加工 | O7: 〇 | P7: 〇 | S7: >外注< | T7: 〇 （MC品目マスタ）
B8: 30 | C8: 購買品 | E8: 10 | F8: 加工製品 | G8: 31 | H8: プリフル | J8: 31:プリフル | M8: 31 | N8: プリフル | O8: 〇 | P8: 〇 | S8: >外注< | T8: 〇 （MC品目マスタ）
B9: 40 | C9: 原紙 | E9: 10 | F9: 加工製品 | G9: 32 | H9: 刷本支給 | J9: 32:刷本支給 | M9: 32 | N9: 刷本支給 | O9: 〇 | P9: 〇 | S9: >外注< | T9: 〇 （MC品目マスタ）
E10: 11 | F10: 加工商品 | G10: 12 | H10: 加工 | J10: 12:加工 | L10: シート | M10: 11 | N10: シート | O10: 〇 （WEB受注画面採番） | P10: 〇 （WEB受注画面採番） | S10: >外注< | T10: 〇 （MC品目マスタ）
E11: 11 | F11: 加工商品 | G11: 13 | H11: Ｇプリント | J11: 13:Ｇプリント | M11: 22 | N11: 片面シート | O11: 〇 （WEB受注画面採番） | P11: 〇 （WEB受注画面採番） | S11: >外注< | T11: 〇 （MC品目マスタ）
E12: 11 | F12: 加工商品 | G12: 21 | H12: 巻ボール | J12: 21:巻ボール | L12: 原紙 | M12: 33 | N12: コートボール | O12: 〇 （MC品目マスタ、製品マスタ採番済） | P12: 〇 （MC品目マスタ、製品マスタ採番済） | R12: 〇 （WEB受注画面採番） | S12: 〇 （原紙マスタ） | T12: 〇 （MC品目マスタ）
E13: 11 | F13: 加工商品 | G13: 23 | H13: 片面加工 | J13: 23:片面加工 | M13: 41 | N13: 生原紙 | R13: 〇 （WEB受注画面採番） | S13: 〇 （原紙マスタ） | T13: 〇 （MC品目マスタ）
E14: 11 | F14: 加工商品 | G14: 31 | H14: プリフル | J14: 31:プリフル | M14: 42 | N14: 印刷原紙 | O14: 〇 （MC品目マスタ、製品マスタ採番済） | P14: 〇 （MC品目マスタ、製品マスタ採番済） | R14: 〇 （WEB受注画面採番） | S14: 〇 （原紙マスタ） | T14: 〇 （MC品目マスタ）
E15: 11 | F15: 加工商品 | G15: 32 | H15: 刷本支給 | J15: 32:刷本支給 | M15: 43 | N15: 巻取り原紙 | O15: － | P15: － | R15: ー | S15: ー | T15: － | U15: ※受注なし
E16: 20 | F16: シート製品 | G16: 11 | H16: シート | J16: 11:シート | L16: 購買品 | M16: 51 | N16: 外装シート | T16: 〇 （MC品目マスタ）
E17: 20 | F17: シート製品 | G17: 22 | H17: 片面シート | J17: 22:片面シート | M17: 52 | N17: 外装ケース | T17: 〇 （MC品目マスタ）
E18: 21 | F18: シート商品 | G18: 11 | H18: シート | J18: 11:シート | M18: 61 | N18: 版・型 | T18: 〇 （MC品目マスタ）
E19: 21 | F19: シート商品 | G19: 22 | H19: 片面シート | J19: 22:片面シート | M19: 62 | N19: その他 | T19: 〇 （MC品目マスタ）
E20: 30 | F20: 購買品 | G20: 51 | H20: 外装シート | J20: 51:外装シート | M20: 63 | N20: デザイン代 | T20: 〇 （MC品目マスタ） | U20: ※発注無し
E21: 30 | F21: 購買品 | G21: 52 | H21: 外装ケース | J21: 52:外装ケース | M21: 71 | N21: 袋 | T21: 〇 （MC品目マスタ） | U21: ※発注無し
E22: 30 | F22: 購買品 | G22: 62 | H22: その他 | J22: 62:その他 | M22: 81 | N22: 運賃 | T22: 〇 （MC品目マスタ） | U22: ※発注無し
E23: 30 | F23: 購買品 | G23: 63 | H23: デザイン代 | J23: 63:デザイン代 | M23: 91 | N23: 資材料 | T23: 〇 （MC品目マスタ） | U23: ※発注無し
E24: 30 | F24: 購買品 | G24: 71 | H24: 袋 | J24: 71:袋 | M24: 92 | N24: 前加工料 | T24: 〇 （MC品目マスタ） | U24: ※発注無し
E25: 30 | F25: 購買品 | G25: 80 | H25: モールド | J25: 80:モールド
E26: 30 | F26: 購買品 | G26: 81 | H26: 運賃 | J26: 81:運賃
E27: 30 | F27: 購買品 | G27: 91 | H27: 資材料 | J27: 91:資材料
E28: 30 | F28: 購買品 | G28: 92 | H28: 前加工料 | J28: 92:前加工料
E29: 40 | F29: 原紙 | G29: 33 | H29: コートボール | J29: 33:コートボール
E30: 40 | F30: 原紙 | G30: 41 | H30: 生原紙 | J30: 41:生原紙
E31: 40 | F31: 原紙 | G31: 42 | H31: 印刷原紙 | J31: 42:印刷原紙

Sheet 受注業務パタン
Q2: 受注業務パタン
B3: 画面項目 | Q3: 加工受注 | W3: シート受注 | AC3: 商品購買 | AI3: 版型 | AO3: 有償支給 | AU3: 経費品 | BA3: 原紙売り（受発注方式） | BG3: 輪切り
B4: 第1画面（TOP画面） 基本情報 | Q4: ○ | W4: ○ | AC4: ○ | AI4: ● | AO4: ○ | AU4: ○ | BA4: ○ | BG4: ○
B5: 第1画面（TOP画面） 受注明細 | Q5: ○ | W5: - | AC5: - | AI5: - | AO5: - | AU5: - | BA5: - | BG5: -
B6: 第2画面（基本情報）基本情報 | Q6: 〇 | W6: 〇 | AC6: 〇 | AI6: ● | AO6: 〇 | AU6: 〇 | BA6: ○ | BG6: ○
B7: 第2画面（基本情報）構成情報 | Q7: ● | W7: 〇 | AC7: - | AI7: ● | AO7: - | AU7: - | BA7: ○ | BG7: ○
B8: 第2画面（基本情報）仕入情報 | Q8: 〇 | W8: 〇 | AC8: 〇 | AI8: ● | AO8: - | AU8: - | BA8: ○ | BG8: ○
B9: 第2画面（基本情報）備考 | Q9: 〇 | W9: 〇 | AC9: 〇 | AI9: ● | AO9: ○ | AU9: ○ | BA9: ○ | BG9: ○
B10: 第3画面（工程情報）工程情報 | Q10: ● | W10: 〇 | AC10: - | AI10: - | AO10: - | AU10: - | BA10: ○ | BG10: ○
B11: ポップアップ（詳細入力画面）基本情報 | Q11: ● | W11: 〇 | AC11: - | AI11: - | AO11: - | AU11: - | BA11: ○ | BG11: ○
B12: ポップアップ（詳細入力画面）外注情報 | Q12: ● | W12: 〇 | AC12: - | AI12: - | AO12: - | AU12: - | BA12: ○ | BG12: ○
B13: ポップアップ（詳細入力画面）工程情報 | Q13: ● | W13: 〇 | AC13: - | AI13: - | AO13: - | AU13: - | BA13: ○ | BG13: ○
B14: ポップアップ（詳細入力画面）作業明細 | Q14: ● | W14: 〇 | AC14: - | AI14: - | AO14: - | AU14: - | BA14: ○ | BG14: ○
... B16: 第4画面（材料設定）材料明細 | Q16: ● | W16: 〇 | AC16: - | AI16: - | AO16: - | AU16: - | BA16: ○ | BG16: ○
B18: ※注釈
C19: 〇：編集可能
C20: ●：参照のみ
C21: -：非表示
B23: 受注区分、製品区分の組合せがどの受注業務パタンにあたるかは「受発注パタン詳細」シート参照

Sheet 受注⇒MC
A1: No | B1: 元No | C1: 受注区分 | D1: 受注区分名 | E1: 製品区分大 | F1: 製品区分大名 | G1: 品目区分 | H1: 品目区分名 | I1: 品目区分詳細ＣＤ | J1: 標準品目区分詳細名 | K1: オーダ区分 | L1: 品目系マスタ登録元 | M1: 製品受注パタン | N1: 受注業務パタン | O1: マスタ登録先 | AC1: 発注先の登録 | AD1: 単位の登録 | AE1: 発注単価の登録先 | AF1: 巻きｍの登録先 | AT1: 「注文書の出力」シート参照 | AW1: V7.0 画面制御の追加
O2: 品目マスタ（共通） | P2: 品目マスタ（会社） | Q2: 品目詳細マスタ | R2: 品目単位マスタ | S2: 品目格納先マスタ | T2: BOMマスタ | U2: 品目工程マスタ | V2: 工程工数マスタ | W2: 得意先販売単価マスタ | X2: 加工単価マスタ | Y2: 購買単価マスタ | Z2: （アドオン）原紙マスタ | AA2: （アドオン）事業所別原紙巾マスタ | AB2: （アドオン）原紙単価マスタ | AG2: 発注予定発生元 | AH2: オーダ発生元 | AI2: 品目CD | AJ2: 枝番１ | AK2: 枝番２ | AL2: 枝番３ | AM2: 単価単位取得 | AN2: 単価取得 | AO2: 巻きｍ取得 | AP2: 発注単位取得 | AQ2: 工程仕様取得 | AR2: 単価算出 | AS2: 重量算出 | AT2: 出力注文書 | AU2: 発注/製造あり | AW2: V7.0 画面制御の追加
A3: 1 | B3: 1 | C3: 21 | D3: シート商品 | E3: 11 | F3: シート | G3: 1 | H3: 商品 | I3: 111 | J3: 商品シート | K3: 外注 | L3: WEB受注 | M3: CPで取り扱いがある（品目登録済） | N3: シート受注 | O3: ○ | P3: ○ | Q3: ○ | S3: △ | T3: ○ | AC3: WEB受注 | AD3: WEB受注 | AE3: WEB受注 | AF3: - | AG3: MRP | AH3: MRP | AI3: 製品コード(11桁) | AJ3: 連番4桁 | AM3: NULL | AN3: 加工単価マスタ | AO3: NULL | AP3: 発注予定 | AQ3: 〇 | AR3: 〇：加工単価より取得 | AS3: 〇 | AT3: 加工発注書 | AU3: 〇 | AW3: V7.0 画面制御の追加
C4: 21 | D4: シート商品 | E4: 11 | F4: シート | G4: 1 | H4: 商品 | I4: 111 | J4: 商品シート | K4: 外注 | L4: WEB受注 | M4: CPで取り扱いがある（品目登録済） | N4: シート受注 | O4: ○ | P4: ○ | Q4: ○ | S4: △ | T4: ○ | AC4: WEB受注 | AD4: WEB受注 | AE4: WEB受注 | AF4: - | AG4: 受注 | AH4: - | AI4: 製品コード(11桁) | AJ4: 連番4桁 | AM4: NULL | AN4: 受注 | AO4: NULL | AP4: 受注 | AQ4: 〇 | AR4: 〇：受注明細より取得 | AS4: 〇 | AT4: 加工発注書 | AU4: 〇 | AW4: V7.0 画面制御の追加
A5: 2 | B5: 2 | C5: 21 | D5: シート商品 | E5: 11 | F5: シート | G5: 1 | H5: 商品 | I5: 111 | J5: 商品シート | K5: 購買 | L5: 品目マスタ | M5: CPで取り扱いが無い（諸口品目） | N5: 商品購買 | O5: ○ | P5: ○ | Q5: ○ | AC5: WEB受注 | AD5: WEB受注 | AE5: WEB受注 | AF5: - | AG5: MRP | AH5: MRP | AI5: 諸口品目 | AM5: NULL | AN5: NULL | AO5: NULL | AP5: 発注予定 | AQ5: ×：仕様が取得できない | AR5: ×：諸口品のため購買単価マスタがない | AS5: - | AT5: 加工発注書 | AU5: 〇 | AW5: V7.0 画面制御の追加
C6: 21 | D6: シート商品 | E6: 11 | F6: シート | G6: 1 | H6: 商品 | I6: 111 | J6: 商品シート | K6: 購買 | L6: 品目マスタ | M6: CPで取り扱いが無い（諸口品目） | N6: 商品購買 | O6: ○ | P6: ○ | Q6: ○ | AC6: WEB受注 | AD6: WEB受注 | AE6: WEB受注 | AF6: - | AG6: 受注 | AH6: - | AI6: 諸口品目 | AM6: NULL | AN6: 受注 | AO6: NULL | AP6: 受注 | AQ6: ×：仕様が取得できない | AR6: 〇：受注明細より取得 | AS6: - | AT6: 加工発注書 | AU6: 〇 | AW6: V7.0 画面制御の追加
A7: 3 | B7: 3 | C7: 21 | D7: シート商品 | E7: 11 | F7: シート | G7: 1 | H7: 商品 | I7: 111 | J7: 商品シート | K7: WG間転送 | L7: WEB受注 | M7: CPで取り扱いがある（品目登録済） | N7: シート受注 | O7: ○ | P7: ○ | Q7: ○ | S7: △ | T7: ○ | AC7: - | AD7: - | AE7: - | AF7: - | AG7: MRP | AH7: MRP | AI7: 製品コード(11桁) | AJ7: 連番4桁 | AM7: - | AN7: - | AO7: - | AP7: - | AQ7: - | AR7: - | AS7: - | AT7: - | AU7: 〇 | AW7: V7.0 画面制御の追加
A8: 4 | B8: 4 | C8: 11 | D8: 加工商品 | E8: 12 | F8: 加工 | G8: 1 | H8: 商品 | I8: 112 | J8: 商品加工 | K8: 外注 | L8: 製品マスタ | M8: CPで取り扱いがある（品目登録済） | N8: 加工品受注 | O8: ○ | P8: ○ | Q8: ○ | S8: △ | T8: ○ | W8: ○ | X8: △ | AC8: 製品マスタ→WEB受注 | AD8: WEB受注 | AE8: WEB受注 | AF8: - | AG8: MRP | AH8: MRP | AI8: 製品コード(11桁) | AJ8: 連番4桁 | AM8: NULL | AN8: 加工単価マスタ | AO8: NULL | AP8: 発注予定 | AQ8: 〇 | AR8: 〇：加工単価より取得 | AS8: 〇 | AT8: 加工発注書 | AU8: 〇 | AW8: V7.0 画面制御の追加
C9: 11 | D9: 加工商品 | E9: 12 | F9: 加工 | G9: 1 | H9: 商品 | I9: 112 | J9: 商品加工 | K9: 外注 | L9: 製品マスタ | M9: CPで取り扱いがある（品目登録済） | N9: 加工品受注 | O9: ○ | P9: ○ | Q9: ○ | S9: △ | T9: ○ | W9: ○ | X9: △ | AC9: 製品マスタ→WEB受注 | AD9: WEB受注 | AE9: WEB受注 | AF9: - | AG9: 受注 | AH9: - | AI9: 製品コード(11桁) | AJ9: 連番4桁 | AM9: NULL | AN9: 受注 | AO9: NULL | AP9: 受注 | AQ9: 〇 | AR9: 〇：受注明細より取得 | AS9: 〇 | AT9: 加工発注書 | AU9: 〇 | AW9: V7.0 画面制御の追加
