Workbook
Name Rev.: 表紙!$U$22
Name Ver.: 表紙!$AE$26
Name ご確認者: 表紙!$AG$40
Name ご確認日: 表紙!$AG$42
Name サブシステム名: 表紙!$U$28
Name システム名: 表紙!$U$26
Name プロジェクト名: 表紙!$U$18
Name 開発区分: 表紙!$U$36
Name 機能ＩＤ: 表紙!$U$32
Name 機能区分: 表紙!$U$34
Name 機能名称: 表紙!$U$30
Name 顧客名: 表紙!$U$16
Name 最終更新者: 表紙!$AB$40
Name 最終更新日: 表紙!$AB$42
Name 作成者: 表紙!$W$40
Name 作成日: 表紙!$W$42
Name 章: 表紙!$M$10
Name 文書名: 表紙!$M$10

Sheet 目次
A1: アドオン設計書作成ガイド
C3: ■アドオン設計と成果物について
D4: ・システム設計フェーズとソフトウェア設計フェーズでアドオンの処理仕様を定義する
D5: ・システム設計フェーズとソフトウェア設計フェーズの成果物がアドオン設計書であり、ソフトウェア製作フェーズのインプットとなる
C7: ■各設計フェーズ毎のアドオン設計書作成範囲
D8: ・システム設計フェーズ：他機能との関連を定義するとともに、画面や帳票、ファイル入出力を中心とした外部入出力の設計を行う
D9: ・ソフトウェア設計フェーズ：内部処理を中心とした設計を行う
U11: ◎ | W11: … | X11: システム設計フェーズで作成
U12: ○ | W12: … | X12: システム設計フェーズで基本仕様を定義して、ソフトウェア設計フェーズで詳細化する
U13: △ | W13: … | X13: 必要に応じて（例えば標準仕様から変更がない場合は不要）
U14: ‐ | W14: … | X14: 不要
W15: … | X15: ソフトウェア設計フェーズで作成
D17: 各設計書と作成対象シートのマトリックス | S17: ※カスタマイズ：標準機能に機能を追加する アドオン：新規で機能を開発する
D18: EXCELシート | N18: 画面設計書 | W18: バッチ設計書 | AF18: 帳票設計書 | AO18: ＢＩ設計書 | AT18: .Net設計書 | BB18: EXCELシート | BL18: WebDB設計書 | BR18: 帳票設計書 | BX18: 汎用申請設計書
N19: カスタマイズ | S19: アドオン | W19: カスタマイズ | AB19: アドオン | AF19: カスタマイズ | AK19: アドオン | AO19: アドオン | AT19: アドオン | BL19: アドオン | BR19: アドオン | BX19: アドオン
D20: 概要 | N20: ◎ | O20: ※1 | S20: ◎ | W20: ◎ | X20: ※1 | AB20: ◎ | AF20: ◎ | AG20: ※1 | AK20: ◎ | AO20: ◎ | AT20: ◎ | BB20: 機能概要 | BL20: ◎ | BR20: ◎ | BX20: ◎
D21: レイアウト | N21: ◎ | O21: ※2 | S21: ◎ | W21: ‐ | AB21: ‐ | AF21: ◎ | AG21: ※2 | AK21: ◎ | AO21: ◎ | AT21: ◎ | BB21: アプリケーションフロー | BL21: ◎ | BR21: ー | BX21: ◎
D22: 項目説明 | N22: △ | S22: ○ | W22: ‐ | AB22: ‐ | AF22: △ | AK22: ○ | AO22: ○ | AT22: ○ | BB22: データベース設定 | BL22: ◎ | BR22: ー | BX22: ◎
D23: 引数説明 | N23: ‐ | S23: ‐ | W23: △ | AB23: ◎ | AF23: ‐ | AK23: ‐ | AO23: ‐ | AT23: ◎ | BB23: フィールド設定 | BL23: ◎ | BR23: ー | BX23: ◎
D24: 処理概要 | N24: ◎ | S24: ◎ | W24: ◎ | AB24: ◎ | AF24: ◎ | AK24: ◎ | AO24: ◎ | AT24: ◎ | BB24: 一覧表示画面設定 | BL24: ◎ | BR24: ー | BX24: ◎
D25: 処理詳細 | BB25: 表示編集画面設定 | BL25: ◎ | BR25: ー | BX25: ◎
D26: 処理・サービス関連図 | N26: △ | S26: ◎ | W26: △ | AB26: ◎ | AF26: ‐ | AK26: ‐ | AO26: ‐ | AT26: ◎ | BB26: 明細画面設定 | BL26: △ | BN26: ※3 | BR26: ー | BX26: △ | BZ26: ※3
D27: 検索入出力仕様 | N27: △ | S27: ○ | W27: △ | AB27: ○ | AF27: ‐ | AK27: ‐ | AO27: ‐ | AT27: ○ | BB27: 集計表示設定 | BL27: △ | BN27: ※4 | BR27: ー | BX27: △ | BZ27: ※4
D28: 更新入出力仕様 | N28: △ | S28: ○ | W28: △ | AB28: ○ | AF28: ‐ | AK28: ‐ | AO28: ‐ | AT28: ○ | BB28: 絞り込み条件設定 | BL28: △ | BN28: ※5 | BR28: ー | BX28: △ | BZ28: ※5
D29: ファイル入出力仕様 | N29: △ | S29: △ | W29: ‐ | AB29: ‐ | AF29: ‐ | AK29: ‐ | AO29: ‐ | AT29: △ | BB29: その他設定 | BR29: ー
D30: 画面遷移 | N30: △ | S30: ◎ | W30: ‐ | AB30: ‐ | AF30: ‐ | AK30: ‐ | AO30: ‐ | AT30: ◎ | BB30: 帳票イメージ | BL30: ー | BR30: ◎ | BX30: ー
D31: メッセージ一覧 | N31: △ | S31: △ | W31: △ | AB31: △ | AF31: ‐ | AK31: ‐ | AO31: ‐ | AT31: △ | BB31: 項目設計 | BL31: ー | BR31: ◎ | BX31: ー
D32: 補足説明 | N32: △ | S32: △ | W32: △ | AB32: △ | AF32: △ | AK32: △ | AO32: △ | AT32: △ | BB32: 補足説明 | BL32: △ | BR32: △ | BX32: △
D33: サービス呼出編集仕様 | N33: - | S33: - | W33: - | AB33: - | AF33: - | AK33: - | AO33: - | AT33: - | BB33: 補足説明(詳細)
D35: ※1 | G35: 別シートでカスタマイズ内容を記載する | BB35: ※3 | BE35: 単票画面は記載しない
D36: ※2 | G36: 吹き出しでカスタマイズ内容を記載する | BB36: ※4 | BE36: 集計・グラフ機能を使用する場合に記載する
BB37: ※5 | BE37: 共通設定のみ記載する(個別設定は、記載しない)

Sheet 表紙
AW2: サブモジュール
AW3: MA_マスタ管理
AW4: MB_業務共通
AW5: MG_原価管理
AW6: MSBA_需給管理
M7: 基本設計 | AW7: MSBB_販売管理
AW8: MSBC_生産管理
AW9: MSBD_購買管理
M10: アドオン設計書 | AW10: MSBE_在庫物流管理
AW11: MSBF_品質管理
AW12: MSBG_債権管理
AW13: MSBH_債務管理
AW14: MSBI_締処理
AW15: MSUA_リスト・入力補助
M16: 顧客 | U16: 株式会社クラウン・パッケージ | AW16: PF_ESBアダプタ
M18: プロジェクト名 | U18: 基幹システム刷新PJ | AW18: 機能区分
AW19: 画面
M20: 文書番号 | AW20: 帳票
AW21: バッチ
M22: Ｒｅｖ． | U22: {=MAX(_xlfn.NUMBERVALUE(改訂!A7:E52))} -> 2 | AW22: マスタ
M24: 機密性区分 | U24: 取扱注意（Ｃ） | AW24: 開発区分
AW25: カスタマイズ
M26: システム名 | U26: mcframe7 | AC26: Ver. | AE26: 7.0.2 | AW26: アドオン
AW27: －
M28: サブモジュール | U28: MSBB_販売管理
M30: 機能名 | U30: =M50 -> Web共通ロジック
M32: 機能ID | U32: =G50 -> MSBBPACOM
M34: 機能区分 | U34: バッチ
M36: 開発区分 | U36: アドオン
W39: 作成 | AB39: 最終更新 | AG39: ご確認
W40: MDSOL | AB40: =改訂!AZ2 -> MDSOL野村
W42: 44805 | AB42: 44909
A48: 文書番号 | G48: 画面ID | M48: 画面名 | V48: Version | AB48: Revision
A50: M7-US-1140 | G50: MSBBPACOM | M50: Web共通ロジック | V50: 1.0.0 | AB50: 2
A53: 共通（元データ）
A54: Webシステム | K54: 文書名 | U54: モジュールID | Z54: MS | AE54: モジュール名 | AJ54: Webシステム | AS54: 文書番号 | AZ54: Version | BF54: Rev.
K55: 画面説明書 | U55: ｻﾌﾞﾓｼﾞｭｰﾙID | Z55: MSBB | AE55: ｻﾌﾞﾓｼﾞｭｰﾙ名 | AJ55: 販売Webシステム | AS55: M7-US-1140 | AZ55: 1.0.0 | BF55: 2
K56: 表紙 | U56: 表題 | Z56: MSBBPACOM | AE56: Web共通ロジック
A57: 共通（リンク用）
A58: =A54 -> Webシステム | K58: 文書名 | U58: モジュールID | Z58: =Z54 -> MS | AE58: モジュール名 | AJ58: =AJ54 -> Webシステム | AS58: 文書番号 | AZ58: Version | BF58: Rev.
...

Sheet 改訂
A1: 第7章 | K1: 改訂 | AU1: 作成者 | AZ1: MDSOL | BE1: 作成日 | BJ1: =表紙!W42 -> 44805 | BP1: Rev.
AU2: 修正者 | AZ2: =BM16 -> MDSOL野村 | BE2: 改訂日 | BJ2: 44909 | BP2: =表紙!CB64 -> 2
A5: Rev. | F5: 改定内容 | BC5: 頁 | BM5: 変更日 変更者 | BR5: 確認日 確認者
A7: 1 | F7: 新規作成 | BM7: 44865
BM8: MDSOL
A9: 2.0 | F9: 仕様連絡書：RCS-1040 品目の採番体系を変更 | BC9: 共通処理概要(全判変換) | BM9: 44889 | BR9: 44889
BM10: MDSOL | BR10: MDSOL
A11: 2 | F11: 仕様連絡書：RCS-1062に伴う下記改定を実施 案件NOの項目定義に案件(部材)の記述追加、枚葉区分の表示条件追加、FSC製品区分に統合 | BC11: 項目定義、定数一覧 | BM11: 44894 | BR11: 44895
BM12: MDSOL | BR12: MDSOL 奥本
A13: 2 | F13: 仕様連絡書：RCS-1062に伴う下記改定を実施 高品質→高管理、各画面から項目削除、DB項目としては残す | BC13: 項目定義、定数一覧 | BM13: 44896 | BR13: 44896
BM14: MDSOL | BR14: MDSOL 奥本
A15: 2 | F15: 仕様連絡書：RCS-1099に伴う下記改定を実施 web受注入力の納品先指定時に、得意先の法人番号で納品先を絞って選択出来るようにする | BC15: 項目定義に納品先(受注入力)を追加 | BM15: 44909 | BR15: 44909
BM16: MDSOL野村 | BR16: MDSOL 奥本

Sheet 概要
A1: =表紙!A54 -> Webシステム | O1: 文書名 | AC1: モジュールID | AJ1: =表紙!AJ63 -> MS | AQ1: モジュール名 | AX1: =表紙!AX63 -> Webシステム | BL1: 文書番号 | BU1: Version | CB1: Rev.
O2: =表紙!O64 -> アドオン設計書 | AC2: サブモジュールID | AJ2: =表紙!AJ64 -> MSBB | AQ2: サブモジュール名 | AX2: =表紙!AX64 -> 販売Webシステム | BL2: =表紙!BL64 -> M7-US-1140 | BU2: =表紙!BU64 -> 7.0.2 | CB2: =表紙!CB64 -> 2
O3: =RIGHT(CELL("filename",$A$1),LEN(CELL("filename",$A$1))-FIND("]",CELL("filename",$A$1))) -> 概要 | AC3: 表題 | AJ3: =表紙!AJ65 -> MSBBPACOM | AQ3: =表紙!AQ65 -> Web共通ロジック
AO5: 概要
B7: 【説明】
C8: WEBシステム共通の項目定義・業務ロジックについて定義する
B11: 【目的】
C12: 見積・製品マスタ・受注等での共通処理を共通関数化することを目的とする
C13: 項目定義をマトリクス表にして共通化することで、画面間での設定・処理の差異を無くすことや差異を明確(異なる動きをする場合は、個別仕様書に明記する)にすることを目的とする
B16: 【概要】
C17: WEBシステム共通の項目定義・業務ロジック
D18: 項目定義 | J18: ・・・ | L18: オートコンプリート、コンボボックスの画面単位での設定を記述
D19: 定数一覧 | J19: ・・・ | L19: 定数一覧を記述
D20: 共通処理概要 | J20: ・・・ | L20: WEBシステム共通の業務ロジックを記述
B23: 【自由記述】
C24: なし

Sheet 項目定義
A1: =表紙!A54 -> Webシステム | L1: 文書名 | V1: モジュールID | AA1: =表紙!$AJ$63 -> MS | AH1: モジュール名 | AS1: 文書番号 | AZ1: Version | BF1: Rev.
L2: =表紙!O64 -> アドオン設計書 | V2: ｻﾌﾞﾓｼﾞｭｰﾙID | AA2: =表紙!$AJ$64 -> MSBB | AH2: ｻﾌﾞﾓｼﾞｭｰﾙ名 | AS2: =表紙!$BL$64 -> M7-US-1140 | AZ2: =表紙!$BU$64 -> 7.0.2 | BF2: =表紙!$CB$64 -> 2
L3: =RIGHT(CELL("filename",$A$1),LEN(CELL("filename",$A$1))-FIND("]",CELL("filename",$A$1))) -> 項目定義 | V3: 表題 | AA3: =表紙!$AJ$65 -> MSBBPACOM | AH3: =表紙!$AQ$65 -> Web共通ロジック
A5: 項目定義(コンボボックス・オートコンプリート・検索項目)
B7: コンボボックス・オートコンプリートについて定義する
B8: 定数グループの値は、定数一覧より取得する
B9: ※個別仕様がある場合は、個別の仕様書に別途記載する。(例)見積計算書NOのオートコンプリートセット後、画面にデータをセットする等の個別記載が必要な処理
B11: 【コンボボックス・オートコンプリート】
AB12: ↓A:オートコンプリート、C:コンボボックス
B13: 項目 | J13: 機能名 | Z13: 入力 | AB13: テーブル名 | AJ13: 汎用分類 | AM13: コード① | AU13: 名称セット | AV13: 名称② | BD13: 自動補完領域③ | BP13: 表示条件 | CD13: 備考
J14: 1 | K14: 2 | L14: 3 | M14: 4 | N14: 5 | O14: 6 | P14: 7 | Q14: 8 | R14: 9 | S14: 10 | T14: 11 | U14: 12 | V14: 13 | W14: 14 | X14: 15 | Z14: 仕様 | AB14: 定数グループ | BD14: 記述が無い場合、コード + 名称を表示
J15: Web見積入力（見積計算処理） | K15: Web見積計算書一覧照会 | L15: Web御見積書登録・発行 | M15: Web御見積書一覧照会 | N15: Web製品マスタ | O15: Web製品マスタ一覧照会 | P15: Web受注入力 | Q15: Web受注一覧照会 | R15: Web受注一覧登録(単価訂正) | S15: WebFSC製品化チェックシート出力 | T15: Web取引先マスタ | U15: Web取引先一覧照会 | V15: Webシート単価マスタ | W15: Web版型・木型マスタ | X15: Web版型・木型マスタ一覧照会 | Z15: WEB入力コントロール(A・C) | AA15: テーブル・汎用マスタ・定数定義
AJ16: 汎用マスタ時 | AM16: テーブル・汎用マスタ時記入
B17: 見積計算書NO | J17: ● | N17: ● | Z17: A | AA17: テ | AB17: WEB見積計算書 | AM17: 見積計算書NO | AU17: ● | AV17: 顧客品名1 + 顧客品名2 | BD17: 見積計算書NO + 得意先名＋顧客品名1 + 顧客品名2 | CO17: CP指摘 2022/10/27 落合 見積計算書NO + 得意先名＋顧客品名1 + 顧客品名2 | DO17: MDSOL回答 石田 2022/10/28 20221027指摘分は別途回答しますのでお待ちください。 MDSOL回答 石田 2022/10/29 記載致しました | EY17: 2022/11/01 落合 問題なし
B18: 決定見積計算書NO | W18: ● | Z18: A | AA18: テ | AB18: WEB見積計算書 | AM18: 見積計算書NO | AU18: ● | AV18: 顧客品名1 + 顧客品名2 | BD18: 見積計算書NO + 得意先名＋顧客品名1 + 顧客品名2 | CO18: CP指摘 2022/10/27 落合 見積計算書NO + 得意先名＋顧客品名1 + 顧客品名2 | DO18: MDSOL回答 石田 2022/10/29 修正致しました
B19: 御見積書NO | J19: ● | L19: ● | N19: ● | Z19: A | AA19: テ | AB19: WEB御見積書 | AM19: 御見積書NO | AU19: ● | AV19: 案件名
B20: 製品CD | J20: ● | N20: ● | P20: ● | Q20: ● | R20: ● | Z20: A | AA20: テ | AB20: WEB製品基本マスタ | AM20: 製品CD | AU20: ● | AV20: CP品名1 + CP品名2 | BD20: 得意先名＋製品CD + CP品名1 + CP品名2 | CO20: CP指摘 2022/10/27 落合 得意先名＋製品CD + CP品名1 + CP品名2 | DO20: MDSOL回答 石田 2022/10/29 修正致しました
B21: 代表製品CD | W21: ● | Z21: A | AA21: テ | AB21: WEB製品基本マスタ | AM21: 製品CD | AU21: ● | AV21: CP品名1 + CP品名2 | BD21: 得意先名＋製品CD + CP品名1 + CP品名2 | CO21: CP指摘 2022/10/27 落合 得意先名＋製品CD + CP品名1 + CP品名2 | DO21: MDSOL回答 石田 2022/10/29 修正致しました
B22: 製品CD(セット品) | N22: ● | P22: ● | Q22: ● | R22: ● | Z22: A | AA22: テ | AB22: WEB製品基本マスタ | AM22: セット製品CD | AU22: ● | AV22: CP品名1 | BD22: 得意先名＋製品CD + CP品名1 | BP22: 集計:セット製品CD、MAX(CP品名1) | CO22: CP指摘 2022/10/27 落合 得意先名＋製品CD + CP品名1 | DO22: MDSOL回答 石田 2022/10/29 修正致しました
B23: 手配NO | P23: ● | R23: ● | X23: ● | Z23: A | AA23: テ | AB23: WEB受注明細 | AM23: 手配NO(手配NO1～3) | AU23: ● | AV23: CP品名1 + CP品名2 | BD23: 手配NO(手配NO1～3) + 得意先名＋製品CD + CP品名1 + CP品名2＋段＋構成名 | BP23: 得意先指定の場合は得意先、過去3か月指定 | CO23: CP指摘 2022/10/29 落合 手配NO(手配NO1～3) + 得意先名＋製品CD + CP品名1 + CP品名2＋段＋構成名 | DV23: MDSOL回答 石田 2022/10/29 修正致しました
B24: 不適合手配NO | P24: ● | Z24: A | AA24: テ | AB24: WEB受注明細 | AM24: 手配NO(手配NO1～3) | AU24: ● | AV24: CP品名1 + CP品名2 | BD24: 手配NO(手配NO1～3) + 得意先名＋製品CD + CP品名1 + CP品名2＋段＋構成名 | BP24: 得意先指定の場合は得意先、過去3か月指定 | CO24: CP指摘 2022/10/29 落合 手配NO(手配NO1～3) + 得意先名＋製品CD + CP品名1 + CP品名2＋段＋構成名 | DV24: MDSOL回答 石田 2022/10/29 修正致しました
B25: 案件NO | J25: ● | K25: ● | L25: ● | M25: ● | N25: ● | O25: ● | S25: ● | Z25: A | AA25: テ | AB25: ヒアリングシート | AM25: 案件NO | AU25: ● | AV25: 案件名 | BD25: 得意先名＋案件（親）＋案件（子）＋案件（部材）＋登録日付 | CO25: CP指摘 2022/10/27 落合 得意先名＋案件（親）＋案件（子）＋登録日付 | DO25: Rev2.0 変更 | DV25: MDSOL回答 石田 2022/10/29 修正致しました
B26: 得意先 | J26: ● | K26: ● | L26: ● | M26: ● | N26: ● | O26: ● | P26: ● | Q26: ● | R26: ● | S26: ● | V26: ● | W26: ● | Z26: A | AA26: テ | AB26: WEB取引先マスタ | AM26: 取引先CD | AU26: ● | AV26: 取引先名 | BD26: 管轄WG＋取引先CD + 取引先名 +住所1～4＋売上担当者名 | BP26: 得意先FLG=ON | CO26: CP指摘 2022/10/27 落合 管轄WG＋取引先CD + 取引先名 +住所1～4＋売上担当者名 | DV26: MDSOL回答 石田 2022/10/29 修正致しました
B27: 見積拠点 | J27: ● | Z27: C | AA27: 汎 | AB27: 拠点 | AJ27: M044 | AM27: 拠点CD | AV27: 拠点名称
B28: 受注拠点 | J28: ● | Z28: C | AA28: 汎 | AB28: 拠点 | AJ28: M044 | AM28: 拠点CD | AV28: 拠点名称
B29: 拠点 | K29: ● | L29: ● | M29: ● | Q29: ● | R29: ● | S29: ● | T29: ● | V29: ● | W29: ● | X29: ● | Z29: C | AA29: 汎 | AB29: 拠点 | AJ29: M044 | AM29: 拠点CD | AV29: 拠点名称
B30: 受注部門 | P30: ● | Z30: C
B31: 担当者 | J31: ● | K31: ● | L31: ● | M31: ● | Q31: ● | S31: ● | X31: ● | Z31: C | AA31: テ | AB31: 担当者 | AM31: 担当者CD | AV31: 担当者名 | BD31: WG＋主部門名＋担当者名 | CO31: CP指摘 2022/10/27 落合 WG＋主部門名＋担当者名 | DG31: MDSOL回答 石田 2022/10/29 修正致しました
B32: 更新担当者 | O32: ● | Z32: C | AA32: テ | AB32: 担当者 | AM32: 担当者CD | AV32: 担当者名 | BD32: WG＋主部門名＋担当者名 | CO32: CP指摘 2022/10/27 落合 WG＋主部門名＋担当者名 | DG32: MDSOL回答 石田 2022/10/29 修正致しました
B33: 売上担当者 | R33: ● | Z33: C | AA33: テ | AB33: 担当者 | AM33: 担当者CD | AV33: 担当者名 | BD33: WG＋主部門名＋担当者名 | CO33: CP指摘 2022/10/27 落合 WG＋主部門名＋担当者名 | DG33: MDSOL回答 石田 2022/10/29 修正致しました
B34: 営業担当者 | T34: ● | U34: ● | V34: ● | Z34: C | AA34: テ | AB34: 担当者 | AM34: 担当者CD | AV34: 担当者名 | BD34: WG＋主部門名＋担当者名 | CO34: CP指摘 2022/10/27 落合 WG＋主部門名＋担当者名 | DG34: MDSOL回答 石田 2022/10/29 修正致しました
B35: 業務担当者 | T35: ● | U35: ● | Z35: C | AA35: テ | AB35: 担当者 | AM35: 担当者CD | AV35: 担当者名 | BD35: WG＋主部門名＋担当者名 | CO35: CP指摘 2022/10/27 落合 WG＋主部門名＋担当者名 | DG35: MDSOL回答 石田 2022/10/29 修正致しました
B36: 営業担当WG | U36: ● | Z36: C | AA36: テ | AB36: WGマスタ | AM36: WG | AU36: ● | AV36: WG名 | CO36: CP指摘 2022/10/27 落合 WG＋主部門名＋担当者名 | DG36: MDSOL回答 石田 2022/10/29 修正致しました
B37: 業務担当WG | U37: ● | Z37: C | AA37: テ | AB37: WGマスタ | AM37: WG | AU37: ● | AV37: WG名 | CO37: CP指摘 2022/10/27 落合 WG＋主部門名＋担当者名 | DG37: MDSOL回答 石田 2022/10/29 修正致しました
B38: 運送会社 | P38: ● | Q38: ● | R38: ● | Z38: C | AA38: 汎 | AB38: 運送会社マスタ
B39: 受注区分 | J39: ● | K39: ● | N39: ● | O39: ● | P39: ● | Q39: ● | Z39: C | AA39: 汎 | AB39: 受注区分 | AJ39: M036 | AM39: 受注区分 | AV39: 受注区分名 | CD39: 定数定義でも実現可能
B40: 売価区分 | N40: ● | P40: ● | Q40: ● | R40: ● | Z40: C | AA40: 汎 | AB40: 売価区分 | AJ40: M037 | AM40: 売価区分 | AV40: 売価区分 | CD40: 定数定義でも実現可能
B41: 手配区分 | P41: ● | Z41: C | AA41: 定 | AB41: 手配区分
B42: 製品区分(大) | J42: ● | K42: ● | N42: ● | O42: ● | Q42: ● | Z42: C | AA42: 汎 | AB42: 製品区分(大) | AJ42: M030 | AM42: 製品区分(大) | AV42: 製品区分大名
B43: 製品区分(中) | J43: ● | K43: ● | N43: ● | O43: ● | Q43: ● | Z43: C | AA43: 汎 | AB43: 製品区分(中) | AJ43: M030 | AM43: 製品区分(中) | AV43: 製品区分中名
...

Sheet 定数一覧
A1: WEB | B1: C_GRP_CD | C1: C_GRP_NM | D1: C_KEY | E1: C_NAME | G1: V_S | H1: V_N | I1: V_D | J1: C_RMRKS
A2: WEB利用 | B2: 定数グループ | C2: 定数グループ名 | D2: キー | E2: 名称 | F2: 値 | G2: 値(文字) | H2: 値(数値) | I2: 値(日付) | J2: 備考 | K2: MCF標準
B3: FSC_AC_KEY_TYPE | C3: 権限対象 | D3: SCREEN_OPEN | E3: 画面オープン | H3: 0 | K3: ●
B4: FSC_AC_KEY_TYPE | C4: 権限対象 | D4: BUTTON | E4: ボタン | H4: 1 | K4: ●
B5: FSC_AC_KEY_TYPE | C5: 権限対象 | D5: RP_FILE_IO | E5: ファイル | H5: 2 | K5: ●
B6: FSC_AC_KEY_TYPE | C6: 権限対象 | D6: RP_EXCEL_OUT | E6: Excel出力 | H6: 3 | K6: ●
B7: FSC_AC_KEY_TYPE | C7: 権限対象 | D7: RP_EXCEL_IN | E7: Excel入力 | H7: 4 | K7: ●
B8: FSC_AC_KEY_TYPE | C8: 権限対象 | D8: RP_EXCEL_OPEN | E8: Excel起動 | H8: 5 | K8: ●
B9: FSC_AC_KEY_TYPE | C9: 権限対象 | D9: RP_CSV_OUT | E9: CSV出力 | H9: 6 | K9: ●
B10: FSC_AC_KEY_TYPE | C10: 権限対象 | D10: RP_CSV_IN | E10: CSV入力 | H10: 7 | K10: ●
B11: FSC_AC_KEY_TYPE | C11: 権限対象 | D11: RP_OPERATION | E11: 画面操作 | H11: 8 | K11: ●
B12: FSC_AC_KEY_TYPE | C12: 権限対象 | D12: RP_FONT_R_CHG | E12: フォント比率変更 | H12: 9 | K12: ●
B13: FSC_AC_KEY_TYPE | C13: 権限対象 | D13: RP_S_SCR_SZ | E13: 画面位置・サイズ設定 | H13: 10 | K13: ●
B14: FSC_AC_KEY_TYPE | C14: 権限対象 | D14: RP_TB_SZ_CHG | E14: テーブルサイズ変更 | H14: 11 | K14: ●
... B83: FSC_AC_KEY_TYPE | C83: 権限対象 | D83: DCP_PASTE | E83: 貼り付け(日付コンボボックスフィールド) | H83: 124 | K83: ●
B84: FSC_BATCH_LOG_TYP | C84: バッチログ区分 | D84: DATA_LOG | E84: データ | G84: D | K84: ●
B85: FSC_BATCH_LOG_TYP | C85: バッチログ区分 | D85: END_LOG | E85: 終了ログ | G85: E | K85: ●
B86: FSC_BATCH_LOG_TYP | C86: バッチログ区分 | D86: PROC_LOG | E86: 処理経過 | G86: P | K86: ●
B87: FSC_BATCH_LOG_TYP | C87: バッチログ区分 | D87: START_LOG | E87: 開始ログ | G87: S | K87: ●
B88: FSC_BOOKMARK_FW_ACT | C88: 画面遷移連携時動作 | D88: ACT_SEARCH | E88: (検索) | G88: __search__ | K88: ●
B89: FSC_COLOR_KEY | C89: 色設定キー | D89: PANEL_BG2 | E89: 画面枠内の色 | G89: PANEL_BG2 | K89: ●
B90: FSC_COLOR_KEY | C90: 色設定キー | D90: ROOTPANEL_BG | E90: 画面の背景色 | G90: ROOTPANEL_BG | K90: ●
B91: FSC_DATA_TYPE | C91: データ型 | D91: BOOLEAN_TYPE | E91: ブール値 | G91: BOOLEAN | K91: ●
B92: FSC_DATA_TYPE | C92: データ型 | D92: DATE_TYPE | E92: 日付(DATE型) | G92: DATE | K92: ●
B93: FSC_DATA_TYPE | C93: データ型 | D93: NUMBER_TYPE | E93: 数値 | G93: NUMBER | K93: ●
B94: FSC_DATA_TYPE | C94: データ型 | D94: STRING_TYPE | E94: 文字列 | G94: STRING | K94: ●
B95: FSC_DATA_TYPE | C95: データ型 | D95: TIMESTAMP_TYPE | E95: 日付(TIMESTAMP型) | G95: TIMESTAMP | K95: ●
B96: FSC_DAY_OF_WEEK_TYPE | C96: 曜日 | D96: TYPE_SUNDAY | E96: 日曜日 | G96: 1 | K96: ●
B97: FSC_DAY_OF_WEEK_TYPE | C97: 曜日 | D97: TYPE_MONDAY | E97: 月曜日 | G97: 2 | K97: ●
B98: FSC_DAY_OF_WEEK_TYPE | C98: 曜日 | D98: TYPE_TUESDAY | E98: 火曜日 | G98: 3 | K98: ●
B99: FSC_DAY_OF_WEEK_TYPE | C99: 曜日 | D99: TYPE_WEDNESDAY | E99: 水曜日 | G99: 4 | K99: ●
B100: FSC_DAY_OF_WEEK_TYPE | C100: 曜日 | D100: TYPE_THURSDAY | E100: 木曜日 | G100: 5 | K100: ●
B101: FSC_DAY_OF_WEEK_TYPE | C101: 曜日 | D101: TYPE_FRIDAY | E101: 金曜日 | G101: 6 | K101: ●
B102: FSC_DAY_OF_WEEK_TYPE | C102: 曜日 | D102: TYPE_SATURDAY | E102: 土曜日 | G102: 7 | K102: ●
B103: FSC_FRAME_TYPE | C103: フレーム種別 | D103: MODAL | E103: モーダル | G103: MODAL | K103: ●
B104: FSC_FRAME_TYPE | C104: フレーム種別 | D104: MODELESS | E104: モーダレス | G104: MODELESS | K104: ●
B105: FSC_GANTT_TASK_LBL_DELIM | C105: タスク区切り文字 | D105: NEW_LINE | E105: 改行 | G105: LINE_SEP | K105: ●
B106: FSC_GUI_AUTO_FOCUS_TYP | C106: 最大文字数入力時フォーカス移動区分 | D106: NOT_MOVE | E106: 移動しない | G106: n | K106: ●
B107: FSC_GUI_AUTO_FOCUS_TYP | C107: 最大文字数入力時フォーカス移動区分 | D107: MOVE_FOCUS | E107: 移動する | G107: y | K107: ●
B108: FSC_H_ALIGN_TYPE | C108: 横位置 | D108: TYPE_CENTER | E108: 中央揃え | G108: CENTER | K108: ●
...

Sheet 共通処理概要(工程情報SET)
A1: =表紙!A54 -> Webシステム | K1: 文書名 | U1: モジュールID | Z1: =表紙!$AJ$63 -> MS | AE1: モジュール名 | AJ1: =表紙!$AX$63 -> Webシステム | AS1: 文書番号 | AZ1: Version | BF1: Rev.
K2: =表紙!O64 -> アドオン設計書 | U2: ｻﾌﾞﾓｼﾞｭｰﾙID | Z2: =表紙!$AJ$64 -> MSBB | AE2: ｻﾌﾞﾓｼﾞｭｰﾙ名 | AJ2: =表紙!$AX$64 -> 販売Webシステム | AS2: =表紙!$BL$64 -> M7-US-1140 | AZ2: =表紙!$BU$64 -> 7.0.2 | BF2: =表紙!$CB$64 -> 2
K3: =RIGHT(CELL("filename",$A$1),LEN(CELL("filename",$A$1))-FIND("]",CELL("filename",$A$1))) -> 共通処理概要(工程情報SET) | U3: 表題 | Z3: =表紙!$AJ$65 -> MSBBPACOM | AE3: =表紙!$AQ$65 -> Web共通ロジック
A5: 工程情報SET
A6: No | B6: 入力 | J6: 処理 | BD6: 出力
A7: 1 | B7: 処理概要：工程情報SET
D23: ①登録時は、工程の初期表示パターン、訂正・削除・コピー・参照時は、登録済みのデータより工程情報をSETする
P24: データ取得元
D25: 操作種別 | P25: 登録 | Z25: 訂正・削除・コピー・参照
D26: 項目 | F26: 工程CD | P26: 工程の初期表示パターン | Z26: 登録データ
F27: 工程名 | P27: 汎用マスタ(工程) | Z27: 汎用マスタ(工程)
F28: 作業CD | P28: 工程の初期表示パターン | Z28: 登録データ
F29: 作業名 | P29: 汎用マスタ(作業) | Z29: 汎用マスタ(作業)
F30: WG | P30: 自拠点(ログイン拠点) | Z30: 登録データ
F31: 製造場所 | P31: 自拠点(ログイン拠点) | Z31: 登録データ
F32: 仕様1ラベル | P32: 工程仕様VIEW | Z32: 工程仕様VIEW
F33: 仕様1CD | P33: 工程仕様VIEW | Z33: 工程仕様VIEW
F34: 仕様1設定値 | P34: 空白 | Z34: 登録データ
F35: 仕様1_見積必須区分 | P35: 工程仕様VIEW | Z35: 工程仕様VIEW
F36: 仕様1_決定見積必須区分 | P36: 工程仕様VIEW | Z36: 工程仕様VIEW
F37: 仕様1_マスタ必須区分 | P37: 工程仕様VIEW | Z37: 工程仕様VIEW
F38: 仕様1_仕様の最低値 | P38: 工程仕様VIEW | Z38: 工程仕様VIEW
... F43: 版NO | P43: 空白 | Z43: 登録データ
D45: ②必須、背景色セット：仕様1～7_見積必須区分、仕様1～7_決定見積必須区分、仕様1～7_マスタ必須区分を参考に仕様1～7の項目の必須制御と背景色を変更する
D46: 画面 | P46: 条件 | AB46: 背景色 | AN46: 必須チェック
D47: 見積計算書(見積区分=通常) | P47: 仕様1～7_見積必須区分=1 | AB47: ピンク | AN47: 有り
D48: 見積計算書(見積区分=決定見積) | P48: 仕様1～7_決定見積必須区分=1 | AB48: ピンク | AN48: 有り
D49: 製品マスタ・受注 | P49: 仕様1～7_マスタ必須区分=1 | AB49: ピンク | AN49: 有り
D51: ③仕様1～7の入力制御
D52: 仕様1～7_仕様の最低値、仕様1～7_仕様の最大値が設定されている場合、入力値の範囲チェックを実施する
D54: ④仕様設定値マスタの参照
E55: 工程CD、作業CD、仕様CDをキーに仕様設定値マスタを参照し、データが取得可能な仕様に関しては、オブジェクトをコンボボックスとする
E56: →コンボボックス値は、仕様設定値マスタ.設定CDとする

Sheet 工程仕様VIEW
A1: =表紙!A54 -> Webシステム | K1: 文書名 | U1: モジュールID | Z1: =表紙!$AJ$63 -> MS | AE1: モジュール名 | AJ1: =表紙!$AX$63 -> Webシステム | AS1: 文書番号 | AZ1: Version | BF1: Rev.
K2: =表紙!O64 -> アドオン設計書 | U2: ｻﾌﾞﾓｼﾞｭｰﾙID | Z2: =表紙!$AJ$64 -> MSBB | AE2: ｻﾌﾞﾓｼﾞｭｰﾙ名 | AJ2: =表紙!$AX$64 -> 販売Webシステム | AS2: =表紙!$BL$64 -> M7-US-1140 | AZ2: =表紙!$BU$64 -> 7.0.2 | BF2: =表紙!$CB$64 -> 2
K3: =RIGHT(CELL("filename",$A$1),LEN(CELL("filename",$A$1))-FIND("]",CELL("filename",$A$1))) -> 工程仕様VIEW | U3: 表題 | Z3: =表紙!$AJ$65 -> MSBBPACOM | AE3: =表紙!$AQ$65 -> Web共通ロジック
A5: VIEW ID | S5: VIEW名 | AL5: 備考
S6: 工程仕様VIEW
C7: ヘッダ | S7: 出力仕様
S8: テーブル名 | Z8: 項目名 | AL8: 備考
A9: テーブル | O9: スキーマ
C10: 汎用マスタ(工程) | J10: (メインテーブル) | O10: mcf | S10: 【結合条件】
C11: 汎用マスタ(作業) | O11: mcf | S11: 汎用マスタ(工程).工程CD = 汎用マスタ(作業).工程CD
C13: 汎用マスタ(仕様) | O13: mcf | S13: 汎用マスタ(工程).工程CD = 汎用マスタ(仕様).工程CD
D14: 汎用マスタ(仕様)_01 | S14: AND 汎用マスタ(作業).作業CD = 汎用マスタ(仕様).作業CD
S15: AND 汎用マスタ(作業).仕様01_仕様CD = 汎用マスタ(仕様).仕様CD
C16: 汎用マスタ(仕様) | O16: mcf | S16: 汎用マスタ(工程).工程CD = 汎用マスタ(仕様).工程CD
D17: 汎用マスタ(仕様)_02 | S17: AND 汎用マスタ(作業).作業CD = 汎用マスタ(仕様).作業CD
S18: AND 汎用マスタ(作業).仕様02_仕様CD = 汎用マスタ(仕様).仕様CD
C19: 汎用マスタ(仕様) | O19: mcf | S19: 汎用マスタ(工程).工程CD = 汎用マスタ(仕様).工程CD
D20: 汎用マスタ(仕様)_07 | S20: AND 汎用マスタ(作業).作業CD = 汎用マスタ(仕様).作業CD
S21: AND 汎用マスタ(作業).仕様07_仕様CD = 汎用マスタ(仕様).仕様CD
A23: 検索条件
C24: 項目なし
A25: データ行
A26: 1 | C26: 工程CD | S26: 汎用マスタ(工程) | Z26: 工程CD
A27: 2 | C27: 工程名 | S27: 汎用マスタ(工程) | Z27: 工程名
A28: 3 | C28: 工程略称 | S28: 汎用マスタ(工程) | Z28: 工程略称
A29: 4 | C29: 親工程CD | S29: 汎用マスタ(工程) | Z29: 親工程CD
A30: 5 | C30: 作業CD | S30: 汎用マスタ(作業) | Z30: 作業CD
A31: 6 | C31: 作業名 | S31: 汎用マスタ(作業) | Z31: 作業名
A32: 5 | C32: 提出用_見積計算書印字 | S32: 汎用マスタ(作業) | Z32: 作業CD | AL32: 1:印字
A33: 7 | C33: 工程仕様ラベル01 | S33: 汎用マスタ(仕様)_01 | Z33: 仕様名 | AL33: 汎用マスタの工程・作業仕様ラベルより設定
A34: 8 | C34: 工程仕様ラベル02 | S34: 汎用マスタ(仕様)_02 | Z34: 仕様名 | AL34: 汎用マスタの工程・作業仕様ラベルより設定
A35: 9 | C35: 工程仕様ラベル03 | S35: 汎用マスタ(仕様)_03 | Z35: 仕様名 | AL35: 汎用マスタの工程・作業仕様ラベルより設定
A36: 10 | C36: 工程仕様ラベル04 | S36: 汎用マスタ(仕様)_04 | Z36: 仕様名 | AL36: 汎用マスタの工程・作業仕様ラベルより設定
A37: 11 | C37: 工程仕様ラベル05 | S37: 汎用マスタ(仕様)_05 | Z37: 仕様名 | AL37: 汎用マスタの工程・作業仕様ラベルより設定
A38: 12 | C38: 工程仕様ラベル06 | S38: 汎用マスタ(仕様)_06 | Z38: 仕様名 | AL38: 汎用マスタの工程・作業仕様ラベルより設定
A39: 13 | C39: 工程仕様ラベル07 | S39: 汎用マスタ(仕様)_07 | Z39: 仕様名 | AL39: 汎用マスタの工程・作業仕様ラベルより設定
A40: 14 | C40: 工程仕様ラベル略称01 | S40: 汎用マスタ(仕様)_01 | Z40: 仕様略称 | AL40: 汎用マスタの工程・作業仕様ラベルより設定
A41: 15 | C41: 工程仕様ラベル略称02 | S41: 汎用マスタ(仕様)_02 | Z41: 仕様略称 | AL41: 汎用マスタの工程・作業仕様ラベルより設定
A42: 16 | C42: 工程仕様ラベル略称03 | S42: 汎用マスタ(仕様)_03 | Z42: 仕様略称 | AL42: 汎用マスタの工程・作業仕様ラベルより設定
A43: 17 | C43: 工程仕様ラベル略称04 | S43: 汎用マスタ(仕様)_04 | Z43: 仕様略称 | AL43: 汎用マスタの工程・作業仕様ラベルより設定
...

Sheet 共通処理概要
A1: =表紙!A54 -> Webシステム | K1: 文書名 | U1: モジュールID | Z1: =表紙!$AJ$63 -> MS | AE1: モジュール名 | AJ1: =表紙!$AX$63 -> Webシステム | AS1: 文書番号 | AZ1: Version | BF1: Rev.
K2: =表紙!O64 -> アドオン設計書 | U2: ｻﾌﾞﾓｼﾞｭｰﾙID | Z2: =表紙!$AJ$64 -> MSBB | AE2: ｻﾌﾞﾓｼﾞｭｰﾙ名 | AJ2: =表紙!$AX$64 -> 販売Webシステム | AS2: =表紙!$BL$64 -> M7-US-1140 | AZ2: =表紙!$BU$64 -> 7.0.2 | BF2: =表紙!$CB$64 -> 2
K3: =RIGHT(CELL("filename",$A$1),LEN(CELL("filename",$A$1))-FIND("]",CELL("filename",$A$1))) -> 共通処理概要 | U3: 表題 | Z3: =表紙!$AJ$65 -> MSBBPACOM | AE3: =表紙!$AQ$65 -> Web共通ロジック
A5: 工程の初期表示パターン
A6: No | B6: 入力 | J6: 処理 | BD6: 出力
A7: 1 | B7: 処理概要：構成情報の入力内容によって、初期工程を決定する。(見積・シート受注が該当)
C17: →工程情報画面の初期セット工程を決定する
D18: 処理タイミング：基本情報画面から工程情報画面への遷移。(操作種別=登録時)
B23: 入力(引数) | K23: ■工程の初期表示パターン | BD23: 出力 | BN23: 出力テーブルイメージ
C24: 受注区分 | K24: 入力値 | S24: 条件 | AM24: 追加工程 | BE24: 工程・作業テーブル | BN24: 工程CD | BO24: 工程名 | BP24: 作業CD | BQ24: 作業名 | BR24: 仕様01 | BS24: 仕様02 | BT24: 仕様03 | BU24: 仕様04 | BV24: 仕様05 | BW24: 仕様06 | BX24: 仕様07 | BY24: 仕様01 | BZ24: 仕様02
C25: シート段 | K25: 印刷コードあり | S25: 印刷マスタのインキ＝油性なら | AM25: 「輪転グラビア工程」 | BN25: 0020 | BO25: 輪転（グラビア）1 | BP25: 00201 | BQ25: （輪転）グラビア1
C26: 原紙コード(表) | S26: 印刷マスタのインキ＝水性なら | AM26: 「輪転フレマル工程」 | BN26: 0040 | BO26: エンボス1 | BP26: 00401 | BQ26: エンボスCD
C27: 印刷コード(表) | K27: ｴﾝﾎﾞｽコードあり | AM27: 「エンボス工程」 | BN27: 0110 | BO27: 片面コルゲータ
C28: エンボスコード(表) | K28: コルゲータ | S28: 表原紙がなく、中裏が巻き原紙 | AM28: 「片面コルゲータ」
C29: 柄数(表) | S29: 表がコートボールで中・裏が巻き原紙 | AM29: 「片面コルゲータ」
C30: 原紙コード(中) | S30: 表中裏がコートボール | AM30: コルゲータなし
C31: 印刷コード(中) | S31: 表中裏とも原紙なし | AM31: コルゲータなし
C32: エンボスコード(中) | S32: 上記以外 | AM32: 「両面コルゲータ」
C33: 原紙コード(裏) | K33: 枚葉印刷 | S33: フレキソ | AM33: 「紙粉除去」、「フレキソ工程」
C34: 印刷コード(裏) | S34: オフセット | AM34: 「コートボール手配」「コートボール断裁」
C35: エンボスコード(裏) | AM35: 「刷版手配」「紙粉除去」「オフセット工程」「合紙」
C36: 柄数(裏) | K36: 最終機械工程 | S36: 輪転～オフセット | Y36: 上記のとおり
C37: 枚葉印刷 | S37: 合紙 | Y37: 上記条件で合紙なければ追加 | AM37: 「合紙」
C38: 刃渡り_巾 | S38: トムソン | AM38: 「トムソン工程」
C39: 刃渡り_流れ | S39: 箔押 | AM39: 「トムソン」「箔押」
C40: 咥え_前後 | S40: グルア | AM40: 「トムソン」「グルア工程」
C41: 咥え_左右 | S41: テーパー | AM41: 「テーパー工程」
C42: シート寸法_巾 | K42: カートン手配 | AM42: 常に固定セット
C43: シート寸法_流れ | K43: 包装 | AM43: 常に固定セット
C44: 最終機械工程 | K44: 梱包 | AM44: 常に固定セット
C45: 印刷M.ROW
K46: ■工程の初期値セット
K47: 入力値 | S47: 条件 | AM47: 追加工程
K48: 印刷コードあり | S48: 印刷マスタのインキ＝油性なら | AM48: 「輪転グラビア工程」
L49: 印刷コード(表)
L50: 印刷コード(中) | T50: 工程CD | W50: 作業CD | Z50: 仕様01 | AD50: 仕様02 | AH50: 仕様03 | AL50: 仕様04 | AP50: 仕様05 | AT50: 仕様06 | AX50: 仕様07
L51: 印刷コード(裏) | T51: 0020 | W51: 00201 | Z51: 印刷コード(表) | AL51: 印刷M.ニス区分
T52: 0021 | W52: 00211 | Z52: 印刷コード(中) | AL52: 印刷M.ニス区分
T53: 0022 | W53: 00221 | Z53: 印刷コード(裏) | AL53: 印刷M.ニス区分
S55: 印刷マスタのインキ＝水性なら | AM55: 「輪転フレマル工程」
...

Sheet 共通処理概要(全判変換)
A1: =表紙!A54 -> Webシステム | K1: 文書名 | U1: モジュールID | Z1: =表紙!$AJ$63 -> MS | AE1: モジュール名 | AJ1: =表紙!$AX$63 -> Webシステム | AS1: 文書番号 | AZ1: Version | BF1: Rev.
K2: =表紙!O64 -> アドオン設計書 | U2: ｻﾌﾞﾓｼﾞｭｰﾙID | Z2: =表紙!$AJ$64 -> MSBB | AE2: ｻﾌﾞﾓｼﾞｭｰﾙ名 | AJ2: =表紙!$AX$64 -> 販売Webシステム | AS2: =表紙!$BL$64 -> M7-US-1140 | AZ2: =表紙!$BU$64 -> 7.0.2 | BF2: =表紙!$CB$64 -> 2
K3: =RIGHT(CELL("filename",$A$1),LEN(CELL("filename",$A$1))-FIND("]",CELL("filename",$A$1))) -> 共通処理概要(全判変換) | U3: 表題 | Z3: =表紙!$AJ$65 -> MSBBPACOM | AE3: =表紙!$AQ$65 -> Web共通ロジック
A5: 全判変換サブルーチン(スリッタ巾→全般巾計算)
A6: No | B6: 入力 | J6: 処理 | BD6: 出力
A7: 1 | B7: 初期処理
B9: 入力(引数) | K9: 処理項目 | S9: 処理内容 | BD9: 出力
C10: 最終工程WG | S10: 1. | T10: WK事業所CD、WK受注巾、WK数量を設定 | BE10: 表巾 | BM10: ※参考資料：受注全判変換サブルーチン_20220808_v01.xlsx
C11: 号機 | K11: WK事業所CD | T11: WK事業所CD = 最終工程WG | BE11: 全判巾
C12: 製品区分 | K12: WK受注巾 | T12: WK受注巾 = スリッター１巾 + スリッター2巾 | BE12: 全判流れ
C13: 段 | K13: WK数量 | T13: WK数量 = 受注数量 | BE13: 全判数量
C14: 表原紙 | BE14: コルスリ区分
C15: 表印刷CD | S15: 2. | T15: WKフィールド 初期化 | BE15: 割数
C16: 表エンボスCD | T16: WK倍数巾 ＝ ０ | BE16: 最大割数
C17: 中原紙 | T17: WK１巾１ ＝ ０
C18: 中印刷CD | T18: WK１巾２ ＝ ０
C19: 中エンボスCD | T19: WK巾Ａ ＝ “ ”
C20: 裏原紙 | T20: WK巾Ｂ ＝ “ ”
C21: 裏印刷CD | T21: WK２巾１ ＝ ０
C22: 裏エンボスCD | T22: WK原紙巾 ＝ ０
C23: スリッター１巾 | T23: WK全判流れ ＝ ０
C24: スリッター1流れ | T24: WK最小流れコルスリ ＝ ０
C25: 受注数量
C26: スリッター2巾 | S26: 3. | T26: 最大巾取得
C27: スリッター2流れ | T27: 3-1.最終工程WG と 段 より 汎用マスタ（段）参照して
C28: コルスリ区分 | K28: WK巾大 | U28: ・WK巾大を設定
V29: 製品区分 １３（Ｇプリント） 以下 ならば WK巾大 ＝ 受注両面最大巾
V30: 製品区分 １３（Ｇプリント） より大 ならば WK巾大 ＝ 受注片面最大巾
K31: WK最大巾 | U31: ・WK最大巾を設定
V32: WK巾大 ≠ ０ ならば WK最大巾 ＝ WK巾大
V33: WK巾大 ＝ ０ ならば 拠点別に次の通り
W34: WK事業所CDより判定
X35: WK事業所CD ＝ 名古屋 ならば WK最大巾 ＝ １３５０
X36: WK事業所CD ＝ 神奈川 ならば WK最大巾 ＝ １４００
X37: WK事業所CD ＝ 仙台 ならば WK最大巾 ＝ １３５０
X38: WK事業所CD 上記以外 ならば WK最大巾 ＝ １６００
T39: 3-2.汎用マスタ（段） 該当 なければ 全判変換サブルーチン 処理終了
S41: 4. | T41: 大阪ローカル
K42: WKローカル区分 | T42: WK事業所CD ＝ 大阪 ならば
U43: 製品区分： 21（巻ボール）、22（片面シート）、23（片面加工）、31（プリフル）、32（刷本支給）のとき
...

Sheet |→補足シート

Sheet 補足説明資料
A1: =表紙!A54 -> Webシステム | O1: 文書名 | AC1: モジュールID | AJ1: =表紙!AJ64 -> MSBB | AQ1: モジュール名 | AX1: =表紙!AX64 -> 販売Webシステム | BL1: 文書番号 | BU1: Version | CB1: Rev.
O2: =表紙!O65 -> 表紙 | AC2: サブモジュールID | AJ2: =表紙!AJ65 -> MSBBPACOM | AQ2: サブモジュール名 | AX2: =表紙!AX65 -> 0 | BL2: =表紙!BL65 -> 0 | BU2: =表紙!BU65 -> 0 | CB2: =表紙!CB65 -> 0
O3: =RIGHT(CELL("filename",$A$1),LEN(CELL("filename",$A$1))-FIND("]",CELL("filename",$A$1))) -> 補足説明資料 | AC3: 表題 | AJ3: =表紙!AJ66 -> 0 | AQ3: =表紙!AQ66 -> 0
AO5: 補足説明

Sheet 提案ロット処理
B2: 概要： | C2: 見積時に設定されたロット数に不足があると判断した場合に、自動的に提案ロットを設定し、計算結果の表示まで行います。
C3: 計算結果を確認し、提案ロットを採用するかどうかは営業担当者にて選択可能とし、採用する場合にのみ本見積として登録を行います。
B5: 見積ロット提案一覧 | H5: 例１
BC6: 単位 | BH6: 提案ロット１ | BM6: 提案ロット2
B7: 決定見込みロット | D7: 提案ロット | I7: 見積り数 | O7: 5000 | BH7: 1000 | BM7: 3000
B8: 1,000未満 | D8: 1000 | E8: 2000 | I8: (決定予想) | O8: ● | T8: ○ | Y8: ○ | AD8: ○ | AI8: ○ | AN8: ○ | AS8: ○ | AX8: ○
B9: 1,000～ | D9: 1500 | E9: 3000
B10: 2,000～ | D10: 1000 | E10: 3000 | I10: 1,000と3,000が提案ロットとなる
B11: 3,000～ | D11: 1000 | E11: 5000
B12: 4,000～ | D12: 2000 | E12: 6000
B13: 5,000～ | D13: 1000 | E13: 3000 | H13: 例２
B14: 7,000～ | D14: 3000 | E14: 5000 | BC14: 単位 | BH14: 提案ロット１ | BM14: 提案ロット2
B15: 10,000～ | D15: 4000 | E15: 6000 | I15: 見積り数 | O15: 1000 | T15: 3000 | BH15: 5000
B16: 15,000～ | D16: 5000 | E16: 10000 | I16: (決定予想) | O16: ○ | T16: ● | Y16: ○ | AD16: ○ | AI16: ○ | AN16: ○ | AS16: ○ | AX16: ○
I18: 決定見込みロットが3,000の為、1,000と5,000が提案ロットとなるが、1,000（以下）のロットは既に入力済である為、
I19: 5,000のみ提案ロットとしてセットす
H21: 例３
BC22: 単位 | BH22: 提案ロット１ | BM22: 提案ロット2
I23: 見積り数 | O23: 1000 | T23: 3000 | Y23: 7000
I24: (決定予想) | O24: ○ | T24: ● | Y24: ○ | AD24: ○ | AI24: ○ | AN24: ○ | AS24: ○ | AX24: ○
I26: 決定見込みロットが3,000の為、1,000と5,000が提案ロットとなるが、1,000以下および5,000以上のロットは既に入力済である為、
I27: 提案ロットはセットしない

Sheet BOM分岐パターンとBOM関連付け判定方法

Sheet 設定表
B5: 製品コード | C5: 工程コード | D5: 材料CD | E5: 工程材料区分 | F5: 品目ＣＤ | G5: 枝番１ | H5: 枝番２ | I5: 枝番３ | J5: 受給区分 | K5: 受給単価 | L5: 並び順
B6: 000000010001 | C6: 0020 | D6: 002001 | E6: 3：原料 | F6: 表原紙コード | G6: 坪量 | H6: 巾
