Workbook
Name Rev.: 表紙!$U$22
Name Ver.: 表紙!$AE$26
Name ご確認者: 表紙!$AG$40
Name ご確認日: 表紙!$AG$42
Name サブシステム名: 表紙!$U$28
Name システム名: 表紙!$U$26
Name プロジェクト名: 表紙!$U$18
Name 開発区分: 表紙!$U$36
Name 機能ＩＤ: 表紙!$U$32
Name 機能区分: 表紙!$U$34
Name 機能名称: 表紙!$U$30
Name 顧客名: 表紙!$U$16
Name 最終更新者: 表紙!$AB$40
Name 最終更新日: 表紙!$AB$42
Name 作成者: 表紙!$W$40
Name 作成日: 表紙!$W$42
Name 章: 表紙!$M$10
Name 文書名: 表紙!$M$10

Sheet 目次
A1: アドオン設計書作成ガイド
C3: ■アドオン設計と成果物について
D4: ・システム設計フェーズとソフトウェア設計フェーズでアドオンの処理仕様を定義する
D5: ・システム設計フェーズとソフトウェア設計フェーズの成果物がアドオン設計書であり、ソフトウェア製作フェーズのインプットとなる
C7: ■各設計フェーズ毎のアドオン設計書作成範囲
D8: ・システム設計フェーズ：他機能との関連を定義するとともに、画面や帳票、ファイル入出力を中心とした外部入出力の設計を行う
D9: ・ソフトウェア設計フェーズ：内部処理を中心とした設計を行う
U11: ◎ | W11: … | X11: システム設計フェーズで作成
U12: ○ | W12: … | X12: システム設計フェーズで基本仕様を定義して、ソフトウェア設計フェーズで詳細化する
U13: △ | W13: … | X13: 必要に応じて（例えば標準仕様から変更がない場合は不要）
U14: ‐ | W14: … | X14: 不要
W15: … | X15: ソフトウェア設計フェーズで作成
D17: 各設計書と作成対象シートのマトリックス | S17: ※カスタマイズ：標準機能に機能を追加する アドオン：新規で機能を開発する
D18: EXCELシート | N18: 画面設計書 | W18: バッチ設計書 | AF18: 帳票設計書 | AO18: ＢＩ設計書 | AT18: .Net設計書 | BB18: EXCELシート | BL18: WebDB設計書 | BR18: 帳票設計書 | BX18: 汎用申請設計書
N19: カスタマイズ | S19: アドオン | W19: カスタマイズ | AB19: アドオン | AF19: カスタマイズ | AK19: アドオン | AO19: アドオン | AT19: アドオン | BL19: アドオン | BR19: アドオン | BX19: アドオン
D20: 概要 | N20: ◎ | O20: ※1 | S20: ◎ | W20: ◎ | X20: ※1 | AB20: ◎ | AF20: ◎ | AG20: ※1 | AK20: ◎ | AO20: ◎ | AT20: ◎ | BB20: 機能概要 | BL20: ◎ | BR20: ◎ | BX20: ◎
D21: レイアウト | N21: ◎ | O21: ※2 | S21: ◎ | W21: ‐ | AB21: ‐ | AF21: ◎ | AG21: ※2 | AK21: ◎ | AO21: ◎ | AT21: ◎ | BB21: アプリケーションフロー | BL21: ◎ | BR21: ー | BX21: ◎
D22: 項目説明 | N22: △ | S22: ○ | W22: ‐ | AB22: ‐ | AF22: △ | AK22: ○ | AO22: ○ | AT22: ○ | BB22: データベース設定 | BL22: ◎ | BR22: ー | BX22: ◎
D23: 引数説明 | N23: ‐ | S23: ‐ | W23: △ | AB23: ◎ | AF23: ‐ | AK23: ‐ | AO23: ‐ | AT23: ◎ | BB23: フィールド設定 | BL23: ◎ | BR23: ー | BX23: ◎
D24: 処理概要 | N24: ◎ | S24: ◎ | W24: ◎ | AB24: ◎ | AF24: ◎ | AK24: ◎ | AO24: ◎ | AT24: ◎ | BB24: 一覧表示画面設定 | BL24: ◎ | BR24: ー | BX24: ◎
D25: 処理詳細 | BB25: 表示編集画面設定 | BL25: ◎ | BR25: ー | BX25: ◎
D26: 処理・サービス関連図 | N26: △ | S26: ◎ | W26: △ | AB26: ◎ | AF26: ‐ | AK26: ‐ | AO26: ‐ | AT26: ◎ | BB26: 明細画面設定 | BL26: △ | BN26: ※3 | BR26: ー | BX26: △ | BZ26: ※3
D27: 検索入出力仕様 | N27: △ | S27: ○ | W27: △ | AB27: ○ | AF27: ‐ | AK27: ‐ | AO27: ‐ | AT27: ○ | BB27: 集計表示設定 | BL27: △ | BN27: ※4 | BR27: ー | BX27: △ | BZ27: ※4
D28: 更新入出力仕様 | N28: △ | S28: ○ | W28: △ | AB28: ○ | AF28: ‐ | AK28: ‐ | AO28: ‐ | AT28: ○ | BB28: 絞り込み条件設定 | BL28: △ | BN28: ※5 | BR28: ー | BX28: △ | BZ28: ※5
D29: ファイル入出力仕様 | N29: △ | S29: △ | W29: ‐ | AB29: ‐ | AF29: ‐ | AK29: ‐ | AO29: ‐ | AT29: △ | BB29: その他設定 | BR29: ー
D30: 画面遷移 | N30: △ | S30: ◎ | W30: ‐ | AB30: ‐ | AF30: ‐ | AK30: ‐ | AO30: ‐ | AT30: ◎ | BB30: 帳票イメージ | BL30: ー | BR30: ◎ | BX30: ー
D31: メッセージ一覧 | N31: △ | S31: △ | W31: △ | AB31: △ | AF31: ‐ | AK31: ‐ | AO31: ‐ | AT31: △ | BB31: 項目設計 | BL31: ー | BR31: ◎ | BX31: ー
D32: 補足説明 | N32: △ | S32: △ | W32: △ | AB32: △ | AF32: △ | AK32: △ | AO32: △ | AT32: △ | BB32: 補足説明 | BL32: △ | BR32: △ | BX32: △
D33: サービス呼出編集仕様 | N33: - | S33: - | W33: - | AB33: - | AF33: - | AK33: - | AO33: - | AT33: - | BB33: 補足説明(詳細)
D35: ※1 | G35: 別シートでカスタマイズ内容を記載する | BB35: ※3 | BE35: 単票画面は記載しない
D36: ※2 | G36: 吹き出しでカスタマイズ内容を記載する | BB36: ※4 | BE36: 集計・グラフ機能を使用する場合に記載する
BB37: ※5 | BE37: 共通設定のみ記載する(個別設定は、記載しない)

Sheet 表紙
AW2: サブモジュール
AW3: MA_マスタ管理
AW4: MB_業務共通
AW5: MG_原価管理
AW6: MSBA_需給管理
M7: 基本設計 | AW7: MSBB_販売管理
AW8: MSBC_生産管理
AW9: MSBD_購買管理
M10: アドオン設計書 | AW10: MSBE_在庫物流管理
AW11: MSBF_品質管理
AW12: MSBG_債権管理
AW13: MSBH_債務管理
AW14: MSBI_締処理
AW15: MSUA_リスト・入力補助
M16: 顧客 | U16: 株式会社クラウン・パッケージ | AW16: PF_ESBアダプタ
M18: プロジェクト名 | U18: 基幹システム刷新PJ | AW18: 機能区分
AW19: 画面
M20: 文書番号 | AW20: 帳票
AW21: バッチ
M22: Ｒｅｖ． | U22: {=MAX(_xlfn.NUMBERVALUE(改訂!A7:E50))} -> 3 | AW22: マスタ
M24: 機密性区分 | U24: 取扱注意（Ｃ） | AW24: 開発区分
AW25: カスタマイズ
M26: システム名 | U26: Webシステム | AC26: Ver. | AE26: 7.0.2 | AW26: アドオン
AW27: －
M28: サブモジュール | U28: MSBB_販売管理
M30: 機能名 | U30: =M50 -> Web製品マスタ一覧照会
M32: 機能ID | U32: =G50 -> MSBBPA060
M34: 機能区分 | U34: 画面
M36: 開発区分 | U36: アドオン
W39: 作成 | AB39: 最終更新 | AG39: ご確認
W40: MDSOL | AB40: MDSOL
W42: 44812 | AB42: 44896
A48: 文書番号 | G48: 画面ID | M48: 画面名 | V48: Version | AB48: Revision
A50: M7-US-1140 | G50: MSBBPA060 | M50: Web製品マスタ一覧照会 | V50: 1.0.0 | AB50: r01.00
A53: 共通（元データ）
A54: Webシステム | K54: 文書名 | U54: モジュールID | Z54: MS | AE54: モジュール名 | AJ54: Webシステム | AS54: 文書番号 | AZ54: Version | BF54: Rev.
K55: 画面説明書 | U55: ｻﾌﾞﾓｼﾞｭｰﾙID | Z55: MSBB | AE55: ｻﾌﾞﾓｼﾞｭｰﾙ名 | AJ55: 販売Webシステム | AS55: M7-US-1140 | AZ55: 1.0.0 | BF55: r00.00
K56: 中紙 | U56: 中題 | Z56: MSBBPA060 | AE56: Web製品マスタ一覧照会
A57: 共通（リンク用）
A58: =A54 -> Webシステム | K58: 文書名 | U58: モジュールID | Z58: =Z54 -> MS | AE58: モジュール名 | AJ58: =AJ54 -> Webシステム | AS58: 文書番号 | AZ58: Version | BF58: Rev.
...

Sheet 改訂
A1: 第7章 | K1: 改訂 | AU1: 作成者 | AZ1: MDSOL | BE1: 作成日 | BJ1: =表紙!W42 -> 44812 | BP1: Rev.
AU2: 修正者 | AZ2: =BM16 -> TBK徐 | BE2: 改訂日 | BJ2: =BM15 -> 44941 | BP2: =表紙!CB64 -> 3
A5: Rev. | F5: 改定内容 | BC5: 頁 | BM5: 変更日 変更者 | BR5: 確認日 確認者
A7: 1 | F7: 新規作成 | BM7: 44865
BM8: MDSOL
A9: 2 | F9: 仕様連絡書：RCS-1062に伴う下記改定を実施 案件NOをDBの項目は、案件NO(親)＋案件NO(子)＋案件NO(部材)に分割する ※画面項目は、1つとする | BC9: 項目説明、検索入出力仕様 | BM9: 44894 | BR9: 44895
BM10: MDSOL | BR10: MDSOL 奥本
A11: 2 | F11: 仕様連絡書：RCS-1062に伴う下記改定を実施 FSC製品区分に統合(FSC認証製品＝FSC製品区分) | BC11: 画面イメージ、項目説明、検索入出力仕様、ファイル入出力仕様 | BM11: 44894 | BR11: 44895
BM12: MDSOL | BR12: MDSOL 奥本
A13: 2 | F13: 仕様連絡書：RCS-1062に伴う下記改定を実施 高品質→高管理、各画面から項目削除、DB項目としては残す | BC13: 画面イメージ、項目説明、検索入出力仕様、ファイル入出力仕様 | BM13: 44896 | BR13: 44896
BM14: MDSOL | BR14: MDSOL 奥本
A15: 3 | F15: 処理詳細を追加する。 | BC15: 処理詳細 | BM15: 44941
BM16: TBK徐

Sheet 概要
A1: =表紙!A54 -> Webシステム | O1: 文書名 | AC1: モジュールID | AJ1: =表紙!AJ63 -> MS | AQ1: モジュール名 | AX1: =表紙!AX63 -> Webシステム | BL1: 文書番号 | BU1: Version | CB1: Rev.
O2: =表紙!O64 -> アドオン設計書 | AC2: サブモジュールID | AJ2: =表紙!AJ64 -> MSBB | AQ2: サブモジュール名 | AX2: =表紙!AX64 -> 販売Webシステム | BL2: =表紙!BL64 -> M7-US-1140 | BU2: =表紙!BU64 -> 7.0.2 | CB2: =表紙!CB64 -> 3
O3: =RIGHT(CELL("filename",$A$1),LEN(CELL("filename",$A$1))-FIND("]",CELL("filename",$A$1))) -> 概要 | AC3: 表題 | AJ3: =表紙!AJ65 -> MSBBPA060 | AQ3: =表紙!AQ65 -> Web製品マスタ一覧照会
AO5: 概要
B7: 【説明】
C8: 製品マスタの一覧照会画面
B10: 【目的】
C11: 製品マスタを一覧照会する。製品マスタ画面へ遷移する。(参照・訂正)
B13: 【処理関連図/サービス関連図】
C14: ※処理・サービス関連図シートに詳細記載
B16: 【オペレーション一覧】
C17: 製品マスタの検索・照会処理を行う
C18: 製品マスタのCSV出力を行う
B20: 【SQLID一覧】
C21: なし
B23: 【ソート順】
C24: 担当、得意先、案件NO、製品CD
B26: 【データアクセスコントロール】
C27: 拠点による制御
C28: ※詳細は、【MSBBPA000】_共通設計書_アドオン(Webシステム共通仕様)にて定義
B30: 【自由記述】
C31: なし

Sheet 画面イメージ
A1: =表紙!A54 -> Webシステム | K1: 文書名 | U1: モジュールID | Z1: =表紙!$AJ$63 -> MS | AE1: モジュール名 | AJ1: =表紙!$AX$63 -> Webシステム | AS1: 文書番号 | AZ1: Version | BF1: Rev.
K2: =表紙!O64 -> アドオン設計書 | U2: ｻﾌﾞﾓｼﾞｭｰﾙID | Z2: =表紙!$AJ$64 -> MSBB | AE2: ｻﾌﾞﾓｼﾞｭｰﾙ名 | AJ2: =表紙!$AX$64 -> 販売Webシステム | AS2: =表紙!$BL$64 -> M7-US-1140 | AZ2: =表紙!$BU$64 -> 7.0.2 | BF2: =表紙!$CB$64 -> 3
K3: =RIGHT(CELL("filename",$A$1),LEN(CELL("filename",$A$1))-FIND("]",CELL("filename",$A$1))) -> 画面イメージ | U3: 表題 | Z3: =表紙!$AJ$65 -> MSBBPA060 | AE3: =表紙!$AQ$65 -> Web製品マスタ一覧照会
A5: 画面イメージ
B7: ≫凡例
Q8: ・・・ | S8: ボタン
C9: 見積計算書NO | Q9: ・・・ | S9: 検索項目(検索画面表示選択) | AJ9: 参照情報
C10: 品名 | Q10: ・・・ | S10: 入力項目
C11: 得意先 | Q11: ・・・ | S11: 表示項目(得意先名称、原紙名等) | AJ11: 担当者
C12: 操作種別 | I12: ●登録 | M12: ○訂正 | Q12: ・・・ | S12: 選択項目(一つのみ選択可能)
C13: 製品マスタ区分 | Q13: ・・・ | S13: 選択項目(一つのみ選択可能)
C14: 作業順 | I14: ☑AAA | M14: ☑BBB | Q14: ・・・ | S14: 選択項目(複数選択可能)
C16: 見積作成日 | Q16: ・・・ | S16: カレンダー形式
BX22: －
D24: 更新日時 | P24: ~ | AF24: 更新担当者 | BR24: * | BS24: あいまい検索可能
D26: 基本情報
D27: 得意先 | AF27: 案件NO
D28: 製品CD | P28: *
D29: 顧客品名1 | AE29: * | AF29: 顧客品名2 | AU29: *
D30: CP品名1 | AE30: * | AF30: CP品名2 | AU30: * | CL30: CP指摘 2022/10/21 落合 検索条件に受注区分、製品区分（大・中・小）、表中裏のメーカー 追加
D31: 顧客品番 | P31: * | Q31: JANコード | AC31: *
CO32: MDSOL 野村 2022/10/25 修正しました | DH32: 2022/10/27 落合 問題なし
D33: 構成情報 | CP33: 表中裏のメーカー 追加(見積・受注一覧照会にも追加)
D34: シート 段 | J34: E | O34: 原紙 | AC34: 印刷 | AQ34: エンボス | BB34: メーカ | CP34: 製品区分（大・中・小）は追加済みです
F35: 表 | J35: (原紙名:ｵｰﾄﾌｨﾙﾀ) | AC35: (印刷名:ｵｰﾄﾌｨﾙﾀ) | AQ35: (エンボス名:ｵｰﾄﾌｨﾙﾀ) | BB35: (メーカ名:ｵｰﾄﾌｨﾙﾀ) | CP35: 受注区分追加しました
F36: 中 | J36: (原紙名:ｵｰﾄﾌｨﾙﾀ) | AC36: (印刷名:ｵｰﾄﾌｨﾙﾀ) | AQ36: (エンボス名:ｵｰﾄﾌｨﾙﾀ) | BB36: (メーカ名:ｵｰﾄﾌｨﾙﾀ)
F37: 裏 | J37: (原紙名:ｵｰﾄﾌｨﾙﾀ) | AC37: (印刷名:ｵｰﾄﾌｨﾙﾀ) | AQ37: (エンボス名:ｵｰﾄﾌｨﾙﾀ) | BB37: (メーカ名:ｵｰﾄﾌｨﾙﾀ)
D38: 刃渡り（mm) | J38: 巾 | P38: 流れ | U38: ~ | W38: 巾 | AC38: 流れ
D39: シート寸法 | J39: 巾 | P39: 流れ | U39: ~ | W39: 巾 | AC39: 流れ
D41: 製品管理情報
D42: 受注区分 | J42: 製品 | R42: 製品区分 | X42: 大 | AE42: 中 | AL42: 小
D43: セット比率 | R43: 製品用途 | AQ43: 物流区分
D44: 機密情報 | R44: 奪取区分 | AF44: 重要区分 | AQ44: Mチェン
D45: 品質区分 | R45: 出荷検査 | AF45: 製品形状 | CO45: Rev2.0 項目削除(高品質 項目削除)
D46: ユネスコマーク | R46: 折鶴マーク
D47: 4M契約 | R47: TKP折れシワ基準
D48: 容リ支払 | R48: 識別表示 | AQ48: 食品安全
D49: FSC製品区分 | R49: FSC材質区分
D53: NO | F53: 案件NO | K53: 案件名 | O53: 得意先 | R53: 得意先名 | V53: 製品CD | AA53: CP品名 | AL53: 顧客品番 | AP53: JANコード | AV53: 構成情報 | BK53: メーカ
AA54: 品名1 | AH54: 品名2 | AV54: 段 | AX54: 表 | BA54: 中 | BD54: 裏 | BG54: 構成名 | BK54: 表 | BQ54: 中 | BW54: 裏 | CT54: CP指摘 2022/10/21 落合 受注区分、製品区分（大・中・小）、段、表中裏のメーカーCD・メーカー名を追加
...

Sheet 項目説明
A1: =表紙!A54 -> Webシステム | K1: 文書名 | U1: モジュールID | Z1: =表紙!$AJ$63 -> MS | AE1: モジュール名 | AJ1: =表紙!$AX$63 -> Webシステム | AS1: 文書番号 | AZ1: Version | BF1: Rev.
K2: =表紙!O64 -> アドオン設計書 | U2: ｻﾌﾞﾓｼﾞｭｰﾙID | Z2: =表紙!$AJ$64 -> MSBB | AE2: ｻﾌﾞﾓｼﾞｭｰﾙ名 | AJ2: =表紙!$AX$64 -> 販売Webシステム | AS2: =表紙!$BL$64 -> M7-US-1140 | AZ2: =表紙!$BU$64 -> 7.0.2 | BF2: =表紙!$CB$64 -> 3
K3: =RIGHT(CELL("filename",$A$1),LEN(CELL("filename",$A$1))-FIND("]",CELL("filename",$A$1))) -> 項目説明 | U3: 表題 | Z3: =表紙!$AJ$65 -> MSBBPA060 | AE3: =表紙!$AQ$65 -> Web製品マスタ一覧照会
A5: 製品マスタ一覧照会
B6: 抽出条件 | N6: 説明 | BE6: Ｗ | BF6: 型 | BG6: 参 | BH6: 必 | BI6: 入 | BJ6: 非 | BK6: 検
A7: 〇 | B7: 更新日時(From) | M7: 抽出条件として、更新日時(From)を入力する | BE7: カ | BF7: D
A8: 〇 | B8: 更新日時(To) | M8: 抽出条件として、更新日時(To)を入力する | BE8: カ | BF8: D
A9: 〇 | B9: 更新担当者 | M9: 【MSBBPACOM】_共通設計書_アドオン(共通ロジック)にて定義 | BE9: C | BF9: S
B11: 抽出条件 - 基本情報 | N11: 説明 | BE11: Ｗ | BF11: 型 | BG11: 参 | BH11: 必 | BI11: 入 | BJ11: 非 | BK11: 検
A12: 〇 | B12: 得意先 | M12: 【MSBBPACOM】_共通設計書_アドオン(共通ロジック)にて定義 | BE12: A | BF12: S | BK12: 検
A13: 〇 | B13: 案件NO | M13: 【MSBBPACOM】_共通設計書_アドオン(共通ロジック)にて定義 | BE13: A | BF13: S | BK13: 検
A14: 〇 | B14: 製品CD | M14: 【MSBBPACOM】_共通設計書_アドオン(共通ロジック)にて定義 | AZ14: あいまい検索可 | BE14: T | BF14: S
A15: 〇 | B15: 顧客品名1 | M15: 抽出条件として、顧客品名1を入力する | AZ15: あいまい検索可 | BE15: T | BF15: S
A16: 〇 | B16: 顧客品名2 | M16: 抽出条件として、顧客品名2を入力する | AZ16: あいまい検索可 | BE16: T | BF16: S
A17: 〇 | B17: CP品名1 | M17: 抽出条件として、CP品名1を入力する | AZ17: あいまい検索可 | BE17: T | BF17: S
A18: 〇 | B18: CP品名2 | M18: 抽出条件として、CP品名2を入力する | AZ18: あいまい検索可 | BE18: T | BF18: S
A19: 〇 | B19: 顧客品番 | M19: 抽出条件として、顧客品番を入力する | AZ19: あいまい検索可 | BE19: T | BF19: S
A20: 〇 | B20: JANコード | M20: 抽出条件として、JANコードを入力する | AZ20: あいまい検索可 | BE20: T | BF20: S
B22: 抽出条件 - 構成情報/備考 | N22: 説明 | BE22: Ｗ | BF22: 型 | BG22: 参 | BH22: 必 | BI22: 入 | BJ22: 非 | BK22: 検
A23: 〇 | B23: シート段 | M23: 【MSBBPACOM】_共通設計書_アドオン(共通ロジック)にて定義 | BE23: C | BF23: S
A24: 〇 | B24: 原紙コード(表) | M24: 【MSBBPACOM】_共通設計書_アドオン(共通ロジック)にて定義 | BE24: A | BF24: S | BK24: 検
A25: 〇 | B25: 印刷コード(表) | M25: 【MSBBPACOM】_共通設計書_アドオン(共通ロジック)にて定義 | BE25: A | BF25: S | BK25: 検
A26: 〇 | B26: エンボスコード(表) | M26: 【MSBBPACOM】_共通設計書_アドオン(共通ロジック)にて定義 | BE26: A | BF26: S | BK26: 検
A27: 〇 | B27: メーカコード(表) | M27: 【MSBBPACOM】_共通設計書_アドオン(共通ロジック)にて定義 | BE27: A | BF27: S | BK27: 検
A28: 〇 | B28: 原紙コード(中) | M28: 【MSBBPACOM】_共通設計書_アドオン(共通ロジック)にて定義 | BE28: A | BF28: S | BK28: 検
A29: 〇 | B29: 印刷コード(中) | M29: 【MSBBPACOM】_共通設計書_アドオン(共通ロジック)にて定義 | BE29: A | BF29: S | BK29: 検
A30: 〇 | B30: エンボスコード(中) | M30: 【MSBBPACOM】_共通設計書_アドオン(共通ロジック)にて定義 | BE30: A | BF30: S | BK30: 検
A31: 〇 | B31: メーカコード(中) | M31: 【MSBBPACOM】_共通設計書_アドオン(共通ロジック)にて定義 | BE31: A | BF31: S | BK31: 検
A32: 〇 | B32: 原紙コード(裏) | M32: 【MSBBPACOM】_共通設計書_アドオン(共通ロジック)にて定義 | BE32: A | BF32: S | BK32: 検
A33: 〇 | B33: 印刷コード(裏) | M33: 【MSBBPACOM】_共通設計書_アドオン(共通ロジック)にて定義 | BE33: A | BF33: S | BK33: 検
A34: 〇 | B34: エンボスコード(裏) | M34: 【MSBBPACOM】_共通設計書_アドオン(共通ロジック)にて定義 | BE34: A | BF34: S | BK34: 検
A35: 〇 | B35: メーカコード(裏) | M35: 【MSBBPACOM】_共通設計書_アドオン(共通ロジック)にて定義 | BE35: A | BF35: S | BK35: 検
A36: 〇 | B36: 刃渡り_巾(From) | M36: 抽出条件として、刃渡り_巾(From)を入力する | BE36: T | BF36: N
A37: 〇 | B37: 刃渡り_流れ(From) | M37: 抽出条件として、刃渡り_流れ(From)を入力する | BE37: T | BF37: N
A38: 〇 | B38: 刃渡り_巾(To) | M38: 抽出条件として、刃渡り_巾(To)を入力する | BE38: T | BF38: N
A39: 〇 | B39: 刃渡り_流れ(To) | M39: 抽出条件として、刃渡り_流れ(To)を入力する | BE39: T | BF39: N
A40: 〇 | B40: シート寸法_巾(From) | M40: 抽出条件として、シート寸法_巾(From)を入力する | BE40: T | BF40: N
A41: 〇 | B41: シート寸法_流れ(From) | M41: 抽出条件として、シート寸法_流れ(From)を入力する | BE41: T | BF41: N
A42: 〇 | B42: シート寸法_巾(To) | M42: 抽出条件として、シート寸法_巾(To)を入力する | BE42: T | BF42: N
A43: 〇 | B43: シート寸法_流れ(To) | M43: 抽出条件として、シート寸法_流れ(To)を入力する | BE43: T | BF43: N
...

Sheet 引数説明
A1: =表紙!A54 -> Webシステム | K1: 文書名 | U1: モジュールID | Z1: =表紙!$AJ$63 -> MS | AE1: モジュール名 | AJ1: =表紙!$AX$63 -> Webシステム | AS1: 文書番号 | AZ1: Version | BF1: Rev.
K2: =表紙!O64 -> アドオン設計書 | U2: ｻﾌﾞﾓｼﾞｭｰﾙID | Z2: =表紙!$AJ$64 -> MSBB | AE2: ｻﾌﾞﾓｼﾞｭｰﾙ名 | AJ2: =表紙!$AX$64 -> 販売Webシステム | AS2: =表紙!$BL$64 -> M7-US-1140 | AZ2: =表紙!$BU$64 -> 7.0.2 | BF2: =表紙!$CB$64 -> 3
K3: =RIGHT(CELL("filename",$A$1),LEN(CELL("filename",$A$1))-FIND("]",CELL("filename",$A$1))) -> 引数説明 | U3: 表題 | Z3: =表紙!$AJ$65 -> MSBBPA060 | AE3: =表紙!$AQ$65 -> Web製品マスタ一覧照会
B5: オペレーションＩＤ/名称：SloRecvIfImp_Upd01/取込
A6: 必 | B6: 項目名 | N6: 説明 | AS6: 未設定時の振る舞い

Sheet 処理概要
A1: =表紙!A54 -> Webシステム | K1: 文書名 | U1: モジュールID | Z1: =表紙!$AJ$63 -> MS | AE1: モジュール名 | AJ1: =表紙!$AX$63 -> Webシステム | AS1: 文書番号 | AZ1: Version | BF1: Rev.
K2: =表紙!O64 -> アドオン設計書 | U2: ｻﾌﾞﾓｼﾞｭｰﾙID | Z2: =表紙!$AJ$64 -> MSBB | AE2: ｻﾌﾞﾓｼﾞｭｰﾙ名 | AJ2: =表紙!$AX$64 -> 販売Webシステム | AS2: =表紙!$BL$64 -> M7-US-1140 | AZ2: =表紙!$BU$64 -> 7.0.2 | BF2: =表紙!$CB$64 -> 3
K3: =RIGHT(CELL("filename",$A$1),LEN(CELL("filename",$A$1))-FIND("]",CELL("filename",$A$1))) -> 処理概要 | U3: 表題 | Z3: =表紙!$AJ$65 -> MSBBPA060 | AE3: =表紙!$AQ$65 -> Web製品マスタ一覧照会
A5: No | B5: 入力 | J5: 処理 | BD5: 出力
A6: 1 | B6: 初期表示
J7: 1.処理概要
K8: 初期表示
L9: 更新日時 | Q9: ： | R9: 更新日時Fromに当日 - ログインマスタ.初期表示をセット、Toに当日をセットする
L10: 更新担当者 | Q10: ： | R10: ログイン担当者CDを表示する
L11: 表示処理 | Q11: ： | R11: 抽出条件をもとに製品マスタ一覧に結果を表示する | BD11: 検索入出力仕様.NO1
L13: フッターボタン表示・非表示切替
M14: メニューから呼び出された場合(照会画面モード) | AC14: ・・・ | AE14: 製品マスタ詳細ボタンを表示、選択ボタンを非表示とする
M15: 検索画面として呼び出された場合(検索画面モード) | AC15: ・・・ | AE15: 製品マスタ詳細ボタンを非表示、選択ボタンを表示とする
M16: 例)検索画面モード:Web製品マスタから検索画面として呼び出され、選択行を返す場合
A18: 2 | B18: 画面操作
J19: 1.処理概要
K20: ボタン処理
L21: クリアボタン押下 | U21: ： | V21: 画面を初期化する(起動時の状態とする)
L23: 表示ボタン押下 | U23: ： | V23: チェック処理にてエラーとなった場合、後続処理をキャンセルする
L24: (チェック処理) | W24: FROM～TOの整合性チェック | AH24: … | AI24: エラーメッセージ：FROM≦の関係で指定してください。 | BD24: メッセージID.001
L26: 表示ボタン押下 | U26: ： | V26: 抽出条件をもとに製品マスタ一覧に結果を表示する | BD26: 検索入出力仕様.NO1
W27: データ取得できなかった場合、下記メッセージを表示
W28: エラーメッセージ：検索結果がありません。 | BD28: メッセージID.002
L30: CSV出力 | U30: ： | V30: 製品マスタ一覧のデータをCSV出力する | BD30: ファイル入出力仕様.NO1
U31: ※1 CSV出力定義とファイル名は、【MSBBPACOM】_共通設計書_アドオン(共通ロジック)にて定義
U32: ※2 画面に表示されたデータがCSVとして出力される
L34: 製品マスタ詳細ボタン押下 | U34: ： | V34: 製品マスタ入力画面に遷移する(操作種別:参照で遷移する)
W35: 一覧にデータが無いもしくは対象行が選択されてない場合、下記メッセージを表示
W36: エラーメッセージ：選択行がありません。 | BD36: メッセージID.003
U37: → 選択行の製品CD(セット製品CD)をキーに製品マスタのデータを参照する | BD37: 画面遷移.S01.NO1
L39: 選択 | U39: ： | V39: 検索モードで開いた場合に選択結果(1行)を遷移元画面に返す
W40: 一覧にデータが無いもしくは対象行が選択されてない場合、下記メッセージを表示
W41: エラーメッセージ：選択行がありません。 | BD41: メッセージID.003
U42: ※1 選択された製品マスタの1レコードを呼出元に返す
U43: ※2 複数選択は許可しない

Sheet 処理詳細
A1: =表紙!A54 -> Webシステム | K1: 文書名 | U1: モジュールID | Z1: =表紙!$AJ$63 -> MS | AE1: モジュール名 | AJ1: =表紙!$AX$63 -> Webシステム | AS1: 文書番号 | AZ1: Version | BF1: Rev.
K2: =表紙!O64 -> アドオン設計書 | U2: ｻﾌﾞﾓｼﾞｭｰﾙID | Z2: =表紙!$AJ$64 -> MSBB | AE2: ｻﾌﾞﾓｼﾞｭｰﾙ名 | AJ2: =表紙!$AX$64 -> 販売Webシステム | AS2: =表紙!$BL$64 -> M7-US-1140 | AZ2: =表紙!$BU$64 -> 7.0.2 | BF2: =表紙!$CB$64 -> 3
K3: =RIGHT(CELL("filename",$A$1),LEN(CELL("filename",$A$1))-FIND("]",CELL("filename",$A$1))) -> 処理詳細 | U3: 表題 | Z3: =表紙!$AJ$65 -> MSBBPA060 | AE3: =表紙!$AQ$65 -> Web製品マスタ一覧照会
A5: No | B5: 入力 | J5: 処理 | BD5: 出力
A6: 1 | B6: 初期表示
J7: 1.1 | L7: 処理概要参照
A10: 2 | B10: 画面操作
J11: 2.1 | L11: 処理概要参照
A14: 3 | B14: 検索
J15: 3.1 | L15: コンボボックスの初期化
L16: 更新担当者コンボボックスの初期化
M17: ※ | N17: 更新担当者検索_SQLリソースの検索仕様
N18: 【MSBBPACOM】_共通設計書_アドオン(Web共通ロジック)の「処理詳細(共通検索)」シート」を参照する。
L20: シート段コンボボックスの初期化
M21: ※ | N21: シート段検索_SQLリソースの検索仕様
N22: 【MSBBPACOM】_共通設計書_アドオン(Web共通ロジック)の「処理詳細(共通検索)」シート」を参照する。
L24: 製品区分_大コンボボックスの初期化
M25: ※ | N25: 製品区分_大検索_SQLリソースの検索仕様
N26: 【MSBBPACOM】_共通設計書_アドオン(Web共通ロジック)の「処理詳細(共通検索)」シート」を参照する。
L28: 製品区分_中コンボボックスの初期化
M29: ※ | N29: 製品区分_中検索_SQLリソースの検索仕様
N30: 【MSBBPACOM】_共通設計書_アドオン(Web共通ロジック)の「処理詳細(共通検索)」シート」を参照する。
L32: 製品区分_小コンボボックスの初期化
M33: ※ | N33: 製品区分_小検索_SQLリソースの検索仕様
N34: 【MSBBPACOM】_共通設計書_アドオン(Web共通ロジック)の「処理詳細(共通検索)」シート」を参照する。
L36: 製品用途コンボボックスの初期化
M37: ※ | N37: 製品用途検索_SQLリソースの検索仕様
N38: 【MSBBPACOM】_共通設計書_アドオン(Web共通ロジック)の「処理詳細(共通検索)」シート」を参照する。
L40: 物流区分コンボボックスの初期化
M41: ※ | N41: 物流区分検索_SQLリソースの検索仕様
N42: 【MSBBPACOM】_共通設計書_アドオン(Web共通ロジック)の「処理詳細(共通検索)」シート」を参照する。
L44: 機密情報コンボボックスの初期化
M45: ※ | N45: 機密情報検索_SQLリソースの検索仕様
N46: 【MSBBPACOM】_共通設計書_アドオン(Web共通ロジック)の「処理詳細(共通検索)」シート」を参照する。
L48: 奪取区分コンボボックスの初期化
M49: ※ | N49: 奪取区分検索_SQLリソースの検索仕様
N50: 【MSBBPACOM】_共通設計書_アドオン(Web共通ロジック)の「処理詳細(共通検索)」シート」を参照する。
L52: 重要区分コンボボックスの初期化
M53: ※ | N53: 重要区分検索_SQLリソースの検索仕様
N54: 【MSBBPACOM】_共通設計書_アドオン(Web共通ロジック)の「処理詳細(共通検索)」シート」を参照する。
...

Sheet 画面項目制御
J2: 操作種別 | O2: 検索 | S2: R | U2: 有効(必須)
B3: 画面項目 | S3: E | U3: 有効
B4: 抽出条件 | G4: 更新日時(From) | O4: E | S4: RO | U4: 読取のみ
G5: 更新日時(To) | O5: E | S5: D | U5: 無効
G6: 更新担当者 | O6: E | S6: I | U6: 非表示
B7: 抽出条件 - 基本情報 | G7: 得意先 | O7: E
G8: 案件NO | O8: E
G9: 製品CD | O9: E
G10: 顧客品名1 | O10: E
G11: 顧客品名2 | O11: E
G12: CP品名1 | O12: E
G13: CP品名2 | O13: E
G14: 顧客品番 | O14: E
G15: JANコード | O15: E
B16: 抽出条件 - 構成情報/備考 | G16: シート段 | O16: E
G17: 原紙コード(表) | O17: E
G18: 印刷コード(表) | O18: E
G19: エンボスコード(表) | O19: E
G20: メーカコード(表) | O20: E
G21: 原紙コード(中) | O21: E
G22: 印刷コード(中) | O22: E
G23: エンボスコード(中) | O23: E
G24: メーカコード(中) | O24: E
G25: 原紙コード(裏) | O25: E
G26: 印刷コード(裏) | O26: E
G27: エンボスコード(裏) | O27: E
G28: メーカコード(裏) | O28: E
... G59: FSC材質区分 | O59: E
B60: 製品マスタ一覧 | G60: NO | O60: RO
G61: 案件NO | O61: RO
G62: 案件名 | O62: RO
G63: 得意先 | O63: RO
G64: 得意先名 | O64: RO
G65: 製品CD | O65: RO
G66: CP品名1 | O66: RO
G67: CP品名2 | O67: RO
G68: 顧客品番 | O68: RO
G69: JANコード | O69: RO
G70: 段 | O70: RO
G71: 表 | O71: RO
...

Sheet 処理・サービス関連図
A1: =表紙!A54 -> Webシステム | K1: 文書名 | U1: モジュールID | Z1: =表紙!$AJ$63 -> MS | AE1: モジュール名 | AJ1: =表紙!$AX$63 -> Webシステム | AS1: 文書番号 | AZ1: Version | BF1: Rev.
K2: =表紙!O64 -> アドオン設計書 | U2: ｻﾌﾞﾓｼﾞｭｰﾙID | Z2: =表紙!$AJ$64 -> MSBB | AE2: ｻﾌﾞﾓｼﾞｭｰﾙ名 | AJ2: =表紙!$AX$64 -> 販売Webシステム | AS2: =表紙!$BL$64 -> M7-US-1140 | AZ2: =表紙!$BU$64 -> 7.0.2 | BF2: =表紙!$CB$64 -> 3
K3: =RIGHT(CELL("filename",$A$1),LEN(CELL("filename",$A$1))-FIND("]",CELL("filename",$A$1))) -> 処理・サービス関連図 | U3: 表題 | Z3: =表紙!$AJ$65 -> MSBBPA060 | AE3: =表紙!$AQ$65 -> Web製品マスタ一覧照会
C7: 検索処理

Sheet 検索入出力仕様
A1: =表紙!A54 -> Webシステム | K1: 文書名 | U1: モジュールID | Z1: =表紙!$AJ$63 -> MS | AE1: モジュール名 | AJ1: =表紙!$AX$63 -> Webシステム | AS1: 文書番号 | AZ1: Version | BF1: Rev.
K2: =表紙!O64 -> アドオン設計書 | U2: ｻﾌﾞﾓｼﾞｭｰﾙID | Z2: =表紙!$AJ$64 -> MSBB | AE2: ｻﾌﾞﾓｼﾞｭｰﾙ名 | AJ2: =表紙!$AX$64 -> 販売Webシステム | AS2: =表紙!$BL$64 -> M7-US-1140 | AZ2: =表紙!$BU$64 -> 7.0.2 | BF2: =表紙!$CB$64 -> 3
K3: =RIGHT(CELL("filename",$A$1),LEN(CELL("filename",$A$1))-FIND("]",CELL("filename",$A$1))) -> 検索入出力仕様 | U3: 表題 | Z3: =表紙!$AJ$65 -> MSBBPA060 | AE3: =表紙!$AQ$65 -> Web製品マスタ一覧照会
A5: No | G5: 1 | S5: ボタン | Z5: 表示 | AH5: 備考 | AK5: 表示ボタンクリック時処理
A6: 処理分類 | E6: 検索 | S6: ソート順 | Z6: 担当、得意先、案件NO、製品CD
A7: No | C7: 転送先 | V7: 転送元 | AQ7: 説明
C8: 種 | D8: オブジェクト | K8: 項目名 | V8: 種 | W8: オブジェクト | AF8: 項目名
A9: 1 | C9: 画 | D9: 製品マスタ一覧 | K9: NO | AF9: 行番
A10: 2 | C10: 画 | D10: 製品マスタ一覧 | K10: 案件NO | V10: T | W10: 製品マスタ | AF10: 案件NO(親)、(子)、(部材) | AQ10: 表示形式：案件NO(親)+ '-' + 案件NO(子)+ '-' + 案件NO(部材) | BN10: Rev2.0 変更
A11: 3 | C11: 画 | D11: 製品マスタ一覧 | K11: 案件名 | V11: T | W11: 製品マスタ | AA11: 案件管理トラン | AF11: 案件名
A12: 4 | C12: 画 | D12: 製品マスタ一覧 | K12: 得意先 | V12: T | W12: 製品マスタ | AF12: 得意先
A13: 5 | C13: 画 | D13: 製品マスタ一覧 | K13: 得意先名 | V13: T | W13: 取引先マスタ | AF13: 取引先名
A14: 6 | C14: 画 | D14: 製品マスタ一覧 | K14: 製品CD | V14: T | W14: 製品マスタ | AF14: 製品CD
A15: 7 | C15: 画 | D15: 製品マスタ一覧 | K15: CP品名1 | V15: T | W15: 製品マスタ | AF15: CP品名1
A16: 8 | C16: 画 | D16: 製品マスタ一覧 | K16: CP品名2 | V16: T | W16: 製品マスタ | AF16: CP品名2
A17: 9 | C17: 画 | D17: 製品マスタ一覧 | K17: 顧客品番 | V17: T | W17: 製品マスタ | AF17: 顧客品番
A18: 10 | C18: 画 | D18: 製品マスタ一覧 | K18: JANコード | V18: T | W18: 製品マスタ | AF18: JANコード
A19: 11 | C19: 画 | D19: 製品マスタ一覧 | K19: 段 | V19: T | W19: 製品マスタ | AF19: 段
A20: 12 | C20: 画 | D20: 製品マスタ一覧 | K20: 表 | V20: T | W20: 製品マスタ | AF20: 表 | AQ20: 原紙コード(表)+印刷コード(表)+エンボスコード(表)
A21: 13 | C21: 画 | D21: 製品マスタ一覧 | K21: 中 | V21: T | W21: 製品マスタ | AF21: 中 | AQ21: 原紙コード(中)+印刷コード(中)+エンボスコード(中)
A22: 14 | C22: 画 | D22: 製品マスタ一覧 | K22: 裏 | V22: T | W22: 製品マスタ | AF22: 裏 | AQ22: 原紙コード(裏)+印刷コード(裏)+エンボスコード(裏)
A23: 15 | C23: 画 | D23: 製品マスタ一覧 | K23: 構成名 | V23: T | W23: 製品マスタ | AA23: MC品目マスタ | AF23: 構成名 | AI23: (品目名) | AQ23: 原紙名(構成名)は原紙CD+印刷CD+ｴﾝﾎﾞｽCDで品目マスタを参照した品名を表示
A24: 16 | C24: 画 | D24: 製品マスタ一覧 | K24: メーカコード(表)CD | V24: T | W24: 製品マスタ | AF24: メーカコード(表)CD
A25: 17 | C25: 画 | D25: 製品マスタ一覧 | K25: メーカコード(表)名 | V25: T | W25: 取引先マスタ | AF25: メーカコード(表)名
A26: 18 | C26: 画 | D26: 製品マスタ一覧 | K26: メーカコード(中)CD | V26: T | W26: 製品マスタ | AF26: メーカコード(中)CD
A27: 19 | C27: 画 | D27: 製品マスタ一覧 | K27: メーカコード(中)名 | V27: T | W27: 取引先マスタ | AF27: メーカコード(中)名
A28: 20 | C28: 画 | D28: 製品マスタ一覧 | K28: メーカコード(裏)CD | V28: T | W28: 製品マスタ | AF28: メーカコード(裏)CD
A29: 21 | C29: 画 | D29: 製品マスタ一覧 | K29: メーカコード(裏)名 | V29: T | W29: 取引先マスタ | AF29: メーカコード(裏)名
A30: 22 | C30: 画 | D30: 製品マスタ一覧 | K30: 受注区分 | V30: T | W30: 製品マスタ | AF30: 受注区分
A31: 23 | C31: 画 | D31: 製品マスタ一覧 | K31: 製品区分_大 | V31: T | W31: 製品マスタ | AF31: 製品区分_大
A32: 24 | C32: 画 | D32: 製品マスタ一覧 | K32: 製品区分_中 | V32: T | W32: 製品マスタ | AF32: 製品区分_中
A33: 25 | C33: 画 | D33: 製品マスタ一覧 | K33: 製品区分_小 | V33: T | W33: 製品マスタ | AF33: 製品区分_小
A34: 26 | C34: 画 | D34: 製品マスタ一覧 | K34: セット比率 | V34: T | W34: 製品マスタ | AF34: セット比率
A35: 27 | C35: 画 | D35: 製品マスタ一覧 | K35: 製品用途 | V35: T | W35: 製品マスタ | AF35: 製品用途
... A42: 34 | C42: 画 | D42: 製品マスタ一覧 | K42: 出荷検査 | V42: T | W42: 製品マスタ | AF42: 出荷検査
A43: 35 | C43: 画 | D43: 製品マスタ一覧 | K43: 高品質 | V43: T | W43: 製品マスタ | AF43: 高品質 | BM43: Rev2.0 項目削除(高品質 項目削除)
A44: 36 | C44: 画 | D44: 製品マスタ一覧 | K44: 製品形状 | V44: T | W44: 製品マスタ | AF44: 製品形状
A45: 37 | C45: 画 | D45: 製品マスタ一覧 | K45: ユネスコマーク | V45: T | W45: 製品マスタ | AF45: ユネスコマーク
A46: 38 | C46: 画 | D46: 製品マスタ一覧 | K46: 折鶴マーク | V46: T | W46: 製品マスタ | AF46: 折鶴マーク
A47: 39 | C47: 画 | D47: 製品マスタ一覧 | K47: 4M契約 | V47: T | W47: 製品マスタ | AF47: 4M契約
...

Sheet 更新入出力仕様
A1: =表紙!A54 -> Webシステム | K1: 文書名 | U1: モジュールID | Z1: =表紙!$AJ$63 -> MS | AE1: モジュール名 | AJ1: =表紙!$AX$63 -> Webシステム | AS1: 文書番号 | AZ1: Version | BF1: Rev.
K2: =表紙!O64 -> アドオン設計書 | U2: ｻﾌﾞﾓｼﾞｭｰﾙID | Z2: =表紙!$AJ$64 -> MSBB | AE2: ｻﾌﾞﾓｼﾞｭｰﾙ名 | AJ2: =表紙!$AX$64 -> 販売Webシステム | AS2: =表紙!$BL$64 -> M7-US-1140 | AZ2: =表紙!$BU$64 -> 7.0.2 | BF2: =表紙!$CB$64 -> 3
K3: =RIGHT(CELL("filename",$A$1),LEN(CELL("filename",$A$1))-FIND("]",CELL("filename",$A$1))) -> 更新入出力仕様 | U3: 表題 | Z3: =表紙!$AJ$65 -> MSBBPA060 | AE3: =表紙!$AQ$65 -> Web製品マスタ一覧照会
A5: No | G5: 1 | S5: ロジック名称 | AH5: 備考
A6: 処理分類 | E6: 更新
A7: No | C7: 転送先 | V7: 転送元 | AQ7: 説明
C8: 種 | D8: オブジェクト | K8: 項目名 | V8: 種 | W8: オブジェクト | AF8: 項目名

Sheet ファイル入出力仕様
A1: =表紙!A54 -> Webシステム | K1: 文書名 | U1: モジュールID | Z1: =表紙!$AJ$63 -> MS | AE1: モジュール名 | AJ1: =表紙!$AX$63 -> Webシステム | AS1: 文書番号 | AZ1: Version | BF1: Rev.
K2: =表紙!O64 -> アドオン設計書 | U2: ｻﾌﾞﾓｼﾞｭｰﾙID | Z2: =表紙!$AJ$64 -> MSBB | AE2: ｻﾌﾞﾓｼﾞｭｰﾙ名 | AJ2: =表紙!$AX$64 -> 販売Webシステム | AS2: =表紙!$BL$64 -> M7-US-1140 | AZ2: =表紙!$BU$64 -> 7.0.2 | BF2: =表紙!$CB$64 -> 3
K3: =RIGHT(CELL("filename",$A$1),LEN(CELL("filename",$A$1))-FIND("]",CELL("filename",$A$1))) -> ファイル入出力仕様 | U3: 表題 | Z3: =表紙!$AJ$65 -> MSBBPA060 | AE3: =表紙!$AQ$65 -> Web製品マスタ一覧照会
A5: No | G5: 1 | S5: ロジック名称 | Z5: ファイル出力 | AH5: 備考
A6: 処理分類 | E6: ファイル出力 | S6: ソート順
A7: No | C7: 転送先 | V7: 転送元 | AQ7: 説明
C8: 種 | D8: オブジェクト | K8: 項目名 | V8: 種 | W8: オブジェクト | AF8: 項目名
A9: 1 | C9: フ | D9: 製品マスタ一覧 | K9: NO | V9: 画 | W9: 製品マスタ一覧 | AF9: NO
A10: 2 | C10: フ | D10: 製品マスタ一覧 | K10: 案件NO | V10: 画 | W10: 製品マスタ一覧 | AF10: 案件NO
A11: 3 | C11: フ | D11: 製品マスタ一覧 | K11: 案件名 | V11: 画 | W11: 製品マスタ一覧 | AF11: 案件名
A12: 4 | C12: フ | D12: 製品マスタ一覧 | K12: 得意先 | V12: 画 | W12: 製品マスタ一覧 | AF12: 得意先
A13: 5 | C13: フ | D13: 製品マスタ一覧 | K13: 得意先名 | V13: 画 | W13: 製品マスタ一覧 | AF13: 得意先名
A14: 6 | C14: フ | D14: 製品マスタ一覧 | K14: 製品CD | V14: 画 | W14: 製品マスタ一覧 | AF14: 製品CD
A15: 7 | C15: フ | D15: 製品マスタ一覧 | K15: CP品名1 | V15: 画 | W15: 製品マスタ一覧 | AF15: CP品名1
A16: 8 | C16: フ | D16: 製品マスタ一覧 | K16: CP品名2 | V16: 画 | W16: 製品マスタ一覧 | AF16: CP品名2
A17: 9 | C17: フ | D17: 製品マスタ一覧 | K17: 顧客品番 | V17: 画 | W17: 製品マスタ一覧 | AF17: 顧客品番
A18: 10 | C18: フ | D18: 製品マスタ一覧 | K18: JANコード | V18: 画 | W18: 製品マスタ一覧 | AF18: JANコード
A19: 11 | C19: フ | D19: 製品マスタ一覧 | K19: 段 | V19: 画 | W19: 製品マスタ一覧 | AF19: 段
A20: 12 | C20: フ | D20: 製品マスタ一覧 | K20: 表 | V20: 画 | W20: 製品マスタ一覧 | AF20: 表
... A42: 34 | C42: 画 | D42: 製品マスタ一覧 | K42: 出荷検査 | V42: 画 | W42: 製品マスタ一覧 | AF42: 出荷検査
A43: 35 | C43: 画 | D43: 製品マスタ一覧 | K43: 高品質 | V43: 画 | W43: 製品マスタ一覧 | AF43: 高品質 | BM43: Rev2.0 項目削除(高品質 項目削除)
A44: 36 | C44: 画 | D44: 製品マスタ一覧 | K44: 製品形状 | V44: 画 | W44: 製品マスタ一覧 | AF44: 製品形状
A45: 37 | C45: 画 | D45: 製品マスタ一覧 | K45: ユネスコマーク | V45: 画 | W45: 製品マスタ一覧 | AF45: ユネスコマーク
A46: 38 | C46: 画 | D46: 製品マスタ一覧 | K46: 折鶴マーク | V46: 画 | W46: 製品マスタ一覧 | AF46: 折鶴マーク
A47: 39 | C47: 画 | D47: 製品マスタ一覧 | K47: 4M契約 | V47: 画 | W47: 製品マスタ一覧 | AF47: 4M契約
A48: 40 | C48: 画 | D48: 製品マスタ一覧 | K48: TKP折れシワ基準 | V48: 画 | W48: 製品マスタ一覧 | AF48: TKP折れシワ基準
A49: 41 | C49: 画 | D49: 製品マスタ一覧 | K49: 容リ支払 | V49: 画 | W49: 製品マスタ一覧 | AF49: 容リ支払
A50: 42 | C50: 画 | D50: 製品マスタ一覧 | K50: 識別表示 | V50: 画 | W50: 製品マスタ一覧 | AF50: 識別表示
A51: 43 | C51: 画 | D51: 製品マスタ一覧 | K51: 食品安全 | V51: 画 | W51: 製品マスタ一覧 | AF51: 食品安全
A52: 44 | C52: 画 | D52: 製品マスタ一覧 | K52: FSC製品区分 | V52: 画 | W52: 製品マスタ一覧 | AF52: FSC製品区分 | BM52: Rev2.0 項目統合(FSC認証製品＝FSC製品区分)
A53: 45 | C53: 画 | D53: 製品マスタ一覧 | K53: FSC材質区分 | V53: 画 | W53: 製品マスタ一覧 | AF53: FSC材質区分
A54: 46 | C54: 画 | D54: 製品マスタ一覧 | K54: 印刷備考 | V54: 画 | W54: 製品マスタ一覧 | AF54: 印刷備考
A55: 47 | C55: 画 | D55: 製品マスタ一覧 | K55: 製造備考 | V55: 画 | W55: 製品マスタ一覧 | AF55: 製造備考
A56: 48 | C56: 画 | D56: 製品マスタ一覧 | K56: 伝票備考 | V56: 画 | W56: 製品マスタ一覧 | AF56: 伝票備考
A57: 49 | C57: 画 | D57: 製品マスタ一覧 | K57: 納入備考 | V57: 画 | W57: 製品マスタ一覧 | AF57: 納入備考
A58: 50 | C58: 画 | D58: 製品マスタ一覧 | K58: 出荷備考１ | V58: 画 | W58: 製品マスタ一覧 | AF58: 出荷備考１
A59: 51 | C59: 画 | D59: 製品マスタ一覧 | K59: 出荷備考２ | V59: 画 | W59: 製品マスタ一覧 | AF59: 出荷備考２

Sheet 画面遷移
A1: =表紙!A54 -> Webシステム | K1: 文書名 | U1: モジュールID | Z1: =表紙!$AJ$63 -> MS | AE1: モジュール名 | AJ1: =表紙!$AX$63 -> Webシステム | AS1: 文書番号 | AZ1: Version | BF1: Rev.
K2: =表紙!O64 -> アドオン設計書 | U2: ｻﾌﾞﾓｼﾞｭｰﾙID | Z2: =表紙!$AJ$64 -> MSBB | AE2: ｻﾌﾞﾓｼﾞｭｰﾙ名 | AJ2: =表紙!$AX$64 -> 販売Webシステム | AS2: =表紙!$BL$64 -> M7-US-1140 | AZ2: =表紙!$BU$64 -> 7.0.2 | BF2: =表紙!$CB$64 -> 3
K3: =RIGHT(CELL("filename",$A$1),LEN(CELL("filename",$A$1))-FIND("]",CELL("filename",$A$1))) -> 画面遷移 | U3: 表題 | Z3: =表紙!$AJ$65 -> MSBBPA060 | AE3: =表紙!$AQ$65 -> Web製品マスタ一覧照会
A5: 画面遷移フロー図
A6: ＩＤ | C6: S01 | E6: Web製品マスタ一覧照会から他画面の画面遷移
D9: NO2
D10: Web取引先一覧照会 | AI10: NO1
AI11: Web製品マスタ
R12: Web製品マスタ一覧照会 | AI12: 1ページ目：メンテ対象選択画面
X13: 製品マスタ詳細ボタン押下
D15: NO3
D16: Web汎用検索(共通検索)
A22: ID | D22: 処理名
A23: S01 | D23: Web製品マスタ一覧照会から他画面の画面遷移
B25: NO | D25: 遷移元ＩＤ | H25: 遷移元画面名 | Q25: 遷移先ＩＤ | V25: 遷移先画面名 | AE25: 目的 | AJ25: 引継項目 | AS25: 遷移後のアクション(遷移先) | BC25: 戻り値 | BL25: 戻り値取得後のアクション(遷移元) | BV25: 備考
B26: 1 | D26: MSBBPA060 | H26: Web製品マスタ一覧照会 | Q26: MSBBPA050 | V26: Web製品マスタ | AE26: 参照 | AJ26: 製品CD(セット製品CD) | AS26: 検索 | BV26: 操作種別:参照、データ参照
B27: 2 | D27: MSBBPA060 | H27: Web製品マスタ一覧照会 | Q27: MSBBPA120 | V27: Web取引先一覧照会 | AE27: 検索結果取得 | AJ27: 得意先ＦＬＧ=1 | AS27: 検索 | BC27: 取引先選択データ(1行) | BL27: 対象データに値セット | BV27: 得意先CD、得意先名に値セット
B28: 3 | D28: MSBBPA060 | H28: Web製品マスタ一覧照会 | Q28: MSBBPA900 | V28: Web汎用検索(共通検索) | AE28: 検索結果取得 | AS28: 検索 | BC28: 各種検索画面の選択データ(1行) | BL28: 対象データに値セット | BV28: CD、名称に値セット
B29: 4
B30: 5
B31: 6
B32: 7
B33: 8

Sheet メッセージ一覧
A1: =表紙!A54 -> Webシステム | K1: 文書名 | U1: モジュールID | Z1: =表紙!$AJ$63 -> MS | AE1: モジュール名 | AJ1: =表紙!$AX$63 -> Webシステム | AS1: 文書番号 | AZ1: Version | BF1: Rev.
K2: =表紙!O64 -> アドオン設計書 | U2: ｻﾌﾞﾓｼﾞｭｰﾙID | Z2: =表紙!$AJ$64 -> MSBB | AE2: ｻﾌﾞﾓｼﾞｭｰﾙ名 | AJ2: =表紙!$AX$64 -> 販売Webシステム | AS2: =表紙!$BL$64 -> M7-US-1140 | AZ2: =表紙!$BU$64 -> 7.0.2 | BF2: =表紙!$CB$64 -> 3
K3: =RIGHT(CELL("filename",$A$1),LEN(CELL("filename",$A$1))-FIND("]",CELL("filename",$A$1))) -> メッセージ一覧 | U3: 表題 | Z3: =表紙!$AJ$65 -> MSBBPA060 | AE3: =表紙!$AQ$65 -> Web製品マスタ一覧照会
C4: ↓アドオン画面のため、基本全て[新]
A5: No | C5: 新/変 | E5: 種別 | G5: メッセージ内容 | AQ5: 備考（パラメータ等） | BG5: メッセージID
A6: 1 | C6: 新 | E6: W | G6: 「FROM≦の関係で指定してください。」 | AQ6: 更新日時 | BG6: E10036
AQ7: 刃渡り_巾、刃渡り_流れ
AQ8: シート寸法_巾、シート寸法_流れ
A9: 2 | C9: 新 | E9: W | G9: 「検索結果がありません。」 | BG9: E10008
A10: 3 | C10: 新 | E10: W | G10: 「選択行がありません。」 | BG10: E10009
A11: 4 | C11: 新 | E11: W | G11: 「検索件数の上限値を超えました。(設定値) \n 抽出条件を設定し、再度検索・照会を実施ください。」 | BG11: E10013
A12: 5 | C12: 新 | E12: I | G12: 「検索件数の上限値を超えました。(設定値) \n 処理を続ける場合は、[はい]を選択してください。」 | BG12: C00006

Sheet 補足説明資料
A1: =表紙!A54 -> Webシステム | O1: 文書名 | AC1: モジュールID | AJ1: =表紙!AJ64 -> MSBB | AQ1: モジュール名 | AX1: =表紙!AX64 -> 販売Webシステム | BL1: 文書番号 | BU1: Version | CB1: Rev.
O2: =表紙!O65 -> 表紙 | AC2: サブモジュールID | AJ2: =表紙!AJ65 -> MSBBPA060 | AQ2: サブモジュール名 | AX2: =表紙!AX65 -> 0 | BL2: =表紙!BL65 -> 0 | BU2: =表紙!BU65 -> 0 | CB2: =表紙!CB65 -> 0
O3: =RIGHT(CELL("filename",$A$1),LEN(CELL("filename",$A$1))-FIND("]",CELL("filename",$A$1))) -> 補足説明資料 | AC3: 表題 | AJ3: =表紙!AJ66 -> 0 | AQ3: =表紙!AQ66 -> 0
AO5: 補足説明
