Workbook
Name Rev.: 表紙!$U$22
Name Ver.: 表紙!$AE$26
Name ご確認者: 表紙!$AG$40
Name ご確認日: 表紙!$AG$42
Name サブシステム名: 表紙!$U$28
Name システム名: 表紙!$U$26
Name プロジェクト名: 表紙!$U$18
Name 開発区分: 表紙!$U$36
Name 機能ＩＤ: 表紙!$U$32
Name 機能区分: 表紙!$U$34
Name 機能名称: 表紙!$U$30
Name 顧客名: 表紙!$U$16
Name 最終更新者: 表紙!$AB$40
Name 最終更新日: 表紙!$AB$42
Name 作成者: 表紙!$W$40
Name 作成日: 表紙!$W$42
Name 章: 表紙!$M$10
Name 文書名: 表紙!$M$10

Sheet 目次
A1: アドオン設計書作成ガイド
C3: ■アドオン設計と成果物について
D4: ・システム設計フェーズとソフトウェア設計フェーズでアドオンの処理仕様を定義する
D5: ・システム設計フェーズとソフトウェア設計フェーズの成果物がアドオン設計書であり、ソフトウェア製作フェーズのインプットとなる
C7: ■各設計フェーズ毎のアドオン設計書作成範囲
D8: ・システム設計フェーズ：他機能との関連を定義するとともに、画面や帳票、ファイル入出力を中心とした外部入出力の設計を行う
D9: ・ソフトウェア設計フェーズ：内部処理を中心とした設計を行う
U11: ◎ | W11: … | X11: システム設計フェーズで作成
U12: ○ | W12: … | X12: システム設計フェーズで基本仕様を定義して、ソフトウェア設計フェーズで詳細化する
U13: △ | W13: … | X13: 必要に応じて（例えば標準仕様から変更がない場合は不要）
U14: ‐ | W14: … | X14: 不要
W15: … | X15: ソフトウェア設計フェーズで作成
D17: 各設計書と作成対象シートのマトリックス | S17: ※カスタマイズ：標準機能に機能を追加する アドオン：新規で機能を開発する
D18: EXCELシート | N18: 画面設計書 | W18: バッチ設計書 | AF18: 帳票設計書 | AO18: ＢＩ設計書 | AT18: .Net設計書 | BB18: EXCELシート | BL18: WebDB設計書 | BR18: 帳票設計書 | BX18: 汎用申請設計書
N19: カスタマイズ | S19: アドオン | W19: カスタマイズ | AB19: アドオン | AF19: カスタマイズ | AK19: アドオン | AO19: アドオン | AT19: アドオン | BL19: アドオン | BR19: アドオン | BX19: アドオン
D20: 概要 | N20: ◎ | O20: ※1 | S20: ◎ | W20: ◎ | X20: ※1 | AB20: ◎ | AF20: ◎ | AG20: ※1 | AK20: ◎ | AO20: ◎ | AT20: ◎ | BB20: 機能概要 | BL20: ◎ | BR20: ◎ | BX20: ◎
D21: レイアウト | N21: ◎ | O21: ※2 | S21: ◎ | W21: ‐ | AB21: ‐ | AF21: ◎ | AG21: ※2 | AK21: ◎ | AO21: ◎ | AT21: ◎ | BB21: アプリケーションフロー | BL21: ◎ | BR21: ー | BX21: ◎
D22: 項目説明 | N22: △ | S22: ○ | W22: ‐ | AB22: ‐ | AF22: △ | AK22: ○ | AO22: ○ | AT22: ○ | BB22: データベース設定 | BL22: ◎ | BR22: ー | BX22: ◎
D23: 引数説明 | N23: ‐ | S23: ‐ | W23: △ | AB23: ◎ | AF23: ‐ | AK23: ‐ | AO23: ‐ | AT23: ◎ | BB23: フィールド設定 | BL23: ◎ | BR23: ー | BX23: ◎
D24: 処理概要 | N24: ◎ | S24: ◎ | W24: ◎ | AB24: ◎ | AF24: ◎ | AK24: ◎ | AO24: ◎ | AT24: ◎ | BB24: 一覧表示画面設定 | BL24: ◎ | BR24: ー | BX24: ◎
D25: 処理詳細 | BB25: 表示編集画面設定 | BL25: ◎ | BR25: ー | BX25: ◎
D26: 処理・サービス関連図 | N26: △ | S26: ◎ | W26: △ | AB26: ◎ | AF26: ‐ | AK26: ‐ | AO26: ‐ | AT26: ◎ | BB26: 明細画面設定 | BL26: △ | BN26: ※3 | BR26: ー | BX26: △ | BZ26: ※3
D27: 検索入出力仕様 | N27: △ | S27: ○ | W27: △ | AB27: ○ | AF27: ‐ | AK27: ‐ | AO27: ‐ | AT27: ○ | BB27: 集計表示設定 | BL27: △ | BN27: ※4 | BR27: ー | BX27: △ | BZ27: ※4
D28: 更新入出力仕様 | N28: △ | S28: ○ | W28: △ | AB28: ○ | AF28: ‐ | AK28: ‐ | AO28: ‐ | AT28: ○ | BB28: 絞り込み条件設定 | BL28: △ | BN28: ※5 | BR28: ー | BX28: △ | BZ28: ※5
D29: ファイル入出力仕様 | N29: △ | S29: △ | W29: ‐ | AB29: ‐ | AF29: ‐ | AK29: ‐ | AO29: ‐ | AT29: △ | BB29: その他設定 | BR29: ー
D30: 画面遷移 | N30: △ | S30: ◎ | W30: ‐ | AB30: ‐ | AF30: ‐ | AK30: ‐ | AO30: ‐ | AT30: ◎ | BB30: 帳票イメージ | BL30: ー | BR30: ◎ | BX30: ー
D31: メッセージ一覧 | N31: △ | S31: △ | W31: △ | AB31: △ | AF31: ‐ | AK31: ‐ | AO31: ‐ | AT31: △ | BB31: 項目設計 | BL31: ー | BR31: ◎ | BX31: ー
D32: 補足説明 | N32: △ | S32: △ | W32: △ | AB32: △ | AF32: △ | AK32: △ | AO32: △ | AT32: △ | BB32: 補足説明 | BL32: △ | BR32: △ | BX32: △
D33: サービス呼出編集仕様 | N33: - | S33: - | W33: - | AB33: - | AF33: - | AK33: - | AO33: - | AT33: - | BB33: 補足説明(詳細)
D35: ※1 | G35: 別シートでカスタマイズ内容を記載する | BB35: ※3 | BE35: 単票画面は記載しない
D36: ※2 | G36: 吹き出しでカスタマイズ内容を記載する | BB36: ※4 | BE36: 集計・グラフ機能を使用する場合に記載する
BB37: ※5 | BE37: 共通設定のみ記載する(個別設定は、記載しない)

Sheet 表紙
AW2: サブモジュール
AW3: MA_マスタ管理
AW4: MB_業務共通
AW5: MG_原価管理
AW6: MSBA_需給管理
M7: 基本設計 | AW7: MSBB_販売管理
AW8: MSBC_生産管理
AW9: MSBD_購買管理
M10: アドオン設計書 | AW10: MSBE_在庫物流管理
AW11: MSBF_品質管理
AW12: MSBG_債権管理
AW13: MSBH_債務管理
AW14: MSBI_締処理
AW15: MSUA_リスト・入力補助
M16: 顧客 | U16: 株式会社クラウン・パッケージ | AW16: PF_ESBアダプタ
M18: プロジェクト名 | U18: 基幹システム刷新PJ | AW18: 機能区分
AW19: 画面
M20: 文書番号 | AW20: 帳票
AW21: バッチ
M22: Ｒｅｖ． | U22: {=MAX(_xlfn.NUMBERVALUE(改訂!A7:E44))} -> 1 | AW22: マスタ
M24: 機密性区分 | U24: 取扱注意（Ｃ） | AW24: 開発区分
AW25: カスタマイズ
M26: システム名 | U26: Webシステム | AC26: Ver. | AE26: 7.0.2 | AW26: アドオン
AW27: －
M28: サブモジュール | U28: MSBB_販売管理
M30: 機能名 | U30: =M50 -> FSC製品化チェックシート
M32: 機能ID | U32: =G50 -> MSBBRA040
M34: 機能区分 | U34: 帳票
M36: 開発区分 | U36: アドオン
W39: 作成 | AB39: 最終更新 | AG39: ご確認
W40: MDSOL
W42: 44824
A48: 文書番号 | G48: 画面ID | M48: 画面名 | V48: Version | AB48: Revision
A50: M7-US-1140 | G50: MSBBRA040 | M50: FSC製品化チェックシート | V50: 1.0.0 | AB50: r01.00
A53: 共通（元データ）
A54: Webシステム | K54: 文書名 | U54: モジュールID | Z54: MS | AE54: モジュール名 | AJ54: Webシステム | AS54: 文書番号 | AZ54: Version | BF54: Rev.
K55: 画面説明書 | U55: ｻﾌﾞﾓｼﾞｭｰﾙID | Z55: MSBB | AE55: ｻﾌﾞﾓｼﾞｭｰﾙ名 | AJ55: Web販売管理 | AS55: M7-US-1140 | AZ55: 1.0.0 | BF55: r00.00
K56: 表紙 | U56: 表題 | Z56: MSBBRA040 | AE56: FSC製品化チェックシート
A57: 共通（リンク用）
A58: =A54 -> Webシステム | K58: 文書名 | U58: モジュールID | Z58: =Z54 -> MS | AE58: モジュール名 | AJ58: =AJ54 -> Webシステム | AS58: 文書番号 | AZ58: Version | BF58: Rev.
...

Sheet 改訂
A1: 第7章 | K1: 改訂 | AU1: 作成者 | AZ1: MDSOL | BE1: 作成日 | BJ1: =表紙!W42 -> 44824 | BP1: Rev.
AU2: 修正者 | BE2: 改訂日 | BP2: =表紙!CB64 -> 1
A5: Rev. | F5: 改定内容 | BC5: 頁 | BM5: 変更日 変更者 | BR5: 確認日 確認者
A7: 1 | F7: 新規作成

Sheet 概要
A1: =表紙!A54 -> Webシステム | O1: 文書名 | AC1: モジュールID | AJ1: =表紙!AJ63 -> MS | AQ1: モジュール名 | AX1: =表紙!AX63 -> Webシステム | BL1: 文書番号 | BU1: Version | CB1: Rev.
O2: =表紙!O64 -> アドオン設計書 | AC2: サブモジュールID | AJ2: =表紙!AJ64 -> MSBB | AQ2: サブモジュール名 | AX2: =表紙!AX64 -> Web販売管理 | BL2: =表紙!BL64 -> M7-US-1140 | BU2: =表紙!BU64 -> 7.0.2 | CB2: =表紙!CB64 -> 1
O3: =RIGHT(CELL("filename",$A$1),LEN(CELL("filename",$A$1))-FIND("]",CELL("filename",$A$1))) -> 概要 | AC3: 表題 | AJ3: =表紙!AJ65 -> MSBBRA040 | AQ3: =表紙!AQ65 -> FSC製品化チェックシート
AO5: 概要
B7: 【業務要件】
C8: カスタマイズ | G8: 内容
C9: No.
C10: 54 | G10: FSC認証CD体系について
G11: FSC認証が必要な場合、FSC製品化チェックシートを作成し、報告用資料を作成する
G12: 見積・受注 FSCは見積内容を出力してチェックシートを出すだけとし、後はワークフローとする
B15: 【機能概要】
C16: 1. | D16: FSC製品化チェックシートを出力する | P16: CP指摘 20221018 伊藤広 FSC製品化には、オンプロ製品・生体製品・OEM購買品・オフプロ宣伝用の４つがあります。 | CJ16: MDSOL 野村 2022/10/25 出力フォーマットにて出力できるEXCELは選択できることを想定しています | DT16: CP指摘 20221026 伊藤広 先に挙げた４つの帳票イメージを追加してください。
S17: Excelシートも項目は共通ですが、印刷用のシートは4種類あります。 | CJ17: ※現状MAX10種類までを想定。(【MSBBPA000】_共通設計書_アドオン(Webシステム共通仕様) - webconfig追記) | DU17: MDSOL 野村 2022/10/31 イメージ追加しました。→ただし、新基幹システムでは、FSCの入力画面は存在しません。決定見積時のデータからFSC製品化チェックシートを出力することになります。
B18: 【前提条件】 | CK18: →指摘に記載いただいているとおり、項目共通が前提となります。(DATAシートは共通) | DV18: 2022/11/01 落合 「【MSBBPA100】_画面設計書_アドオン(WebFSC製品化チェックシート出力)_20221031_V01(指摘ナシ).xlsx」の指摘内容 参照
C19: 1. | D19: WebFSC製品化チェックシート出力画面で対象となったデータを発行対象とする | DW19: MDSOL 野村 2022/11/02 補足いただいた内容で相違ありません。
C20: ※【MSBBPA100】_画面設計書_アドオン(WebFSC製品化チェックシート出力)参照 | DW20: 2022/11/04 落合 問題なし
C21: 2. | D21: 単票形式とする(御見積書NO単位の帳票となる)
C22: 3. | D22: CP開発のヒアリングシート参照時の制約（サンプル依頼ID、デザイン担当の項目が存在すること。 デザイン担当名をmcframe7から取得する場合は、デザイン担当がmcframe7の担当者マスタに存在する担当者ＩＤで登録されている。）
B24: 【説明】
C25: FSC製品化チェックシート
B27: 【帳票分類】
C28: ・ | D28: 社内管理帳票
B30: 【帳票ツール】
C31: ・ | D31: ComponentOne Excel for .NETを使用する
B33: 【帳票出力条件】
C34: ・ | D34: 発行対象データは、FSC製品区分=1：社外、2：社内、3：マーク無し とする
C35: ・ | D35: WebFSC製品化チェックシート出力画面で対象となったデータを発行対象とする
B37: 【再発行時の印刷データ利用】
C38: ・ | D38: なし
C39: ※発行時のデータを保存しない
B41: 【改頁条件】
C42: ・ | D42: なし
B44: 【データのソート順】
C45: ・ | D45: なし
B47: 【自由記述】
C48: ・ | D48: なし

Sheet 帳票イメージ
A1: =表紙!A54 -> Webシステム | K1: 文書名 | U1: モジュールID | Z1: =表紙!$AJ$63 -> MS | AE1: モジュール名 | AJ1: =表紙!$AX$63 -> Webシステム | AS1: 文書番号 | AZ1: Version | BF1: Rev.
K2: =表紙!O64 -> アドオン設計書 | U2: ｻﾌﾞﾓｼﾞｭｰﾙID | Z2: =表紙!$AJ$64 -> MSBB | AE2: ｻﾌﾞﾓｼﾞｭｰﾙ名 | AJ2: =表紙!$AX$64 -> Web販売管理 | AS2: =表紙!$BL$64 -> M7-US-1140 | AZ2: =表紙!$BU$64 -> 7.0.2 | BF2: =表紙!$CB$64 -> 1
K3: =RIGHT(CELL("filename",$A$1),LEN(CELL("filename",$A$1))-FIND("]",CELL("filename",$A$1))) -> 帳票イメージ | U3: 表題 | Z3: =表紙!$AJ$65 -> MSBBRA040 | AE3: =表紙!$AQ$65 -> FSC製品化チェックシート
A5: 帳票イメージ
B7: オンプロ製品
B52: 製袋用
B103: OEM購買品
B154: オフプロ宣伝用

Sheet 項目説明
A1: =表紙!A54 -> Webシステム | K1: 文書名 | U1: モジュールID | Z1: =表紙!$AJ$63 -> MS | AE1: モジュール名 | AJ1: =表紙!$AX$63 -> Webシステム | AS1: 文書番号 | AZ1: Version | BF1: Rev.
K2: =表紙!O64 -> アドオン設計書 | U2: ｻﾌﾞﾓｼﾞｭｰﾙID | Z2: =表紙!$AJ$64 -> MSBB | AE2: ｻﾌﾞﾓｼﾞｭｰﾙ名 | AJ2: =表紙!$AX$64 -> Web販売管理 | AS2: =表紙!$BL$64 -> M7-US-1140 | AZ2: =表紙!$BU$64 -> 7.0.2 | BF2: =表紙!$CB$64 -> 1
K3: =RIGHT(CELL("filename",$A$1),LEN(CELL("filename",$A$1))-FIND("]",CELL("filename",$A$1))) -> 項目説明 | U3: 表題 | Z3: =表紙!$AJ$65 -> MSBBRA040 | AE3: =表紙!$AQ$65 -> FSC製品化チェックシート
C5: 共通項目エリア | M5: 表示 | Q5: 最大 | S5: 出力仕様 | BK5: O
S6: テーブル名 | AB6: 項目名 | AJ6: 備考
A7: 参照テーブル
S8: WEB御見積書
S9: WEB御見積書見積計算書 | AJ9: WEB御見積書.御見積書NO = WEB御見積書見積計算書.御見積書NO
S10: WEB見積計算書 | AJ10: WEB御見積書見積計算書.見積計算書NO = WEB見積計算書.見積計算書NO
S11: WEB取込先 | AJ11: WEB御見積書.得意先CDより取得
S12: 会社マスタ | AJ12: WEB御見積書.担当者CDより所属する会社/部門情報を取得
S13: 部門マスタ
S14: 担当者マスタ | AJ14: WEB御見積書.担当者CDより取得
S15: ヒアリングシート | AJ15: WEB見積計算書.案件NOより取得
A16: 明細
A17: 1 | C17: 登録日 | AB17: 発行日
A18: 2 | C18: 社員CD | AB18: 発行担当者 | AJ18: ログインユーザーCD
A19: 3 | C19: 社員名 | AB19: 発行担当者名 | AJ19: ログインユーザー名
A20: 4 | C20: ﾃﾞｨﾚｸﾀｰ更新日 | AJ20: ディレクター入力にて反映
A21: 5 | C21: ﾃﾞｨﾚｸﾀｰ入力者 | AJ21: ディレクター入力にて反映
A22: 6 | C22: 社員名 | AJ22: ディレクター入力にて反映
A23: 7 | C23: ｻｲﾄ 更新日 | AJ23: サイト事務局入力にて反映
A24: 8 | C24: ｻｲﾄ 入力者 | AJ24: サイト事務局入力にて反映
A25: 9 | C25: 社員名 | AJ25: サイト事務局入力にて反映
A26: 10 | C26: CoC 更新日 | AJ26: CoC事務局にて反映
A27: 11 | C27: CoC 入力者 | AJ27: CoC事務局にて反映
A28: 12 | C28: 社員名 | AJ28: CoC事務局にて反映
A29: 13 | C29: 管理№ | S29: 御見積書 | AB29: FSC管理NO | AJ29: ※WebFSC製品化チェックシート出力画面で自動採番
A30: 14 | C30: 承認日 | AJ30: サイト事務局にて反映
A32: 15 | C32: ﾃﾞｻﾞｲﾝ提案依頼№ | S32: ヒアリングシート | AB32: サンプル依頼ID
A33: 16 | C33: デザイン担当 | S33: ヒアリングシート | AB33: デザイン担当
A34: 17 | C34: 担当 | S34: 担当者マスタ | AB34: 担当者名
A35: 18 | C35: 所属拠点 | S35: 会社マスタ/部門マスタ | AB35: 事業所名
A36: 19 | C36: 得意先 | S36: WEB御見積書 | AB36: 得意先CD
S37: WEB取引先マスタ | AB37: 得意先名
A38: 20 | C38: 品名 | S38: WEB見積計算書 | AB38: 品名1、品名2 | AJ38: 御見積書に含まれる最初に取得できたWEB見積計算書データとなります。※代表
A39: 21 | C39: CP製品CD | S39: WEB見積計算書 | AB39: CP製品CD
A40: 22 | C40: 製品CD | BM40: CP指摘 20221027 伊藤広 岐阜事業所での製品CDをセット
A41: 23 | C41: 見積№ | S41: WEB見積計算書 | AB41: WEB見積計算書NO | BN41: MDSOL 野村 2022/10/31 今回の新基幹システムでは、FSCの入力画面は存在せず、決定見積時のデータからFSC製品化チェックシートを出力することになります。
A42: 24 | C42: 材質構成 表 | S42: WEB見積計算書 | AB42: 表構成 | AJ42: 表構成：原紙CD(表)、印刷CD(表)、ｴﾝﾎﾞｽCD(表) | BW42: 新基幹システムに無い項目は、手入力となります。
...

Sheet 処理概要
A1: =表紙!A54 -> Webシステム | K1: 文書名 | U1: モジュールID | Z1: =表紙!$AJ$63 -> MS | AE1: モジュール名 | AJ1: =表紙!$AX$63 -> Webシステム | AS1: 文書番号 | AZ1: Version | BF1: Rev.
K2: =表紙!O64 -> アドオン設計書 | U2: ｻﾌﾞﾓｼﾞｭｰﾙID | Z2: =表紙!$AJ$64 -> MSBB | AE2: ｻﾌﾞﾓｼﾞｭｰﾙ名 | AJ2: =表紙!$AX$64 -> Web販売管理 | AS2: =表紙!$BL$64 -> M7-US-1140 | AZ2: =表紙!$BU$64 -> 7.0.2 | BF2: =表紙!$CB$64 -> 1
K3: =RIGHT(CELL("filename",$A$1),LEN(CELL("filename",$A$1))-FIND("]",CELL("filename",$A$1))) -> 処理概要 | U3: 表題 | Z3: =表紙!$AJ$65 -> MSBBRA040 | AE3: =表紙!$AQ$65 -> FSC製品化チェックシート
A5: 帳票出力（処理概要）
A6: 1 | B6: 帳票出力（処理概要）
C8: ■EXCELのひな型ファイルを読込み
D10: 出力フォーマットで選択された、フォーマットをテンプレートとして開き、処理を開始する
C12: ■EXCELデータ転送に関して
D13: EXCELのひな型ファイルを読込み、必要データを転記し、ファイルダウンロードする
D14: →現行と同様にレイアウト・DATAシートを用意し、システムからのデータ転送は、DATAシートに転送するようにする(レイアウトは、データシートを参照する)
AG29: [DATA]シート
D34: [レイアウト]シート

Sheet 処理詳細
A1: =表紙!A54 -> Webシステム | K1: 文書名 | U1: モジュールID | Z1: =表紙!$AJ$63 -> MS | AE1: モジュール名 | AJ1: =表紙!$AX$63 -> Webシステム | AS1: 文書番号 | AZ1: Version | BF1: Rev.
K2: =表紙!O64 -> アドオン設計書 | U2: ｻﾌﾞﾓｼﾞｭｰﾙID | Z2: =表紙!$AJ$64 -> MSBB | AE2: ｻﾌﾞﾓｼﾞｭｰﾙ名 | AJ2: =表紙!$AX$64 -> Web販売管理 | AS2: =表紙!$BL$64 -> M7-US-1140 | AZ2: =表紙!$BU$64 -> 7.0.2 | BF2: =表紙!$CB$64 -> 1
K3: =RIGHT(CELL("filename",$A$1),LEN(CELL("filename",$A$1))-FIND("]",CELL("filename",$A$1))) -> 処理詳細 | U3: 表題 | Z3: =表紙!$AJ$65 -> MSBBRA040 | AE3: =表紙!$AQ$65 -> FSC製品化チェックシート
A5: No | B5: 入力 | J5: 処理 | BD5: 出力
A6: 1 | B6: 対象データの抽出
J7: 1．帳票明細項目抽出
K8: 下記の条件に従い、対象テーブルからデータを検索する。
K10: ・システム情報から帳票項目を設定する。
K11: 帳票項目 | W11: 項目名 | AE11: 取得条件、編集仕様
K12: 登録日 | W12: 発行日
K13: 社員CD | W13: 発行担当者 | AE13: ログインユーザーCD
K14: 社員名 | W14: 発行担当者名 | AE14: ログインユーザー名
K16: ・標準マスタをもとに検索する
C17: 会社マスタ | K17: 帳票項目 | W17: テーブル | AE17: 項目名 | AM17: 取得条件、編集仕様
C18: 部門マスタ | K18: 所属拠点 | W18: 会社マスタ | AE18: 会社名 | AM18: 会社名存在しない場合、部門名設定する。
K19: 所属拠点 | W19: 部門マスタ | AE19: 部門名
K21: ・WEB見積計算書をもとに検索する
C22: WEB御見積書 | K22: 帳票項目 | W22: テーブル | AE22: 項目名 | AM22: 取得条件、編集仕様
C23: ヒアリングシート | K23: 管理№ | W23: WEB御見積書 | AE23: FSC管理NO
C24: 担当者マスタ | K24: ﾃﾞｻﾞｲﾝ提案依頼№ | W24: ヒアリングシート | AE24: サンプル依頼ID
C25: WEB取引先マスタ | K25: デザイン担当 | W25: ヒアリングシート | AE25: デザイン担当
C26: WEB見積計算書 | K26: 担当 | W26: 担当者マスタ | AE26: 担当者名
K27: 得意先 | W27: WEB御見積書 | AE27: 得意先CD
K28: 得意先名 | W28: WEB取引先マスタ | AE28: 得意先名
K29: 品名 | W29: WEB見積計算書 | AE29: 品名1
AE30: 品名2
K31: CP製品CD | W31: WEB見積計算書 | AE31: CP製品CD
K32: 製品CD | W32: WEB見積計算書 | AE32: 製品CD
K33: 見積№ | W33: WEB見積計算書 | AE33: WEB見積計算書NO
K34: 材質構成 表 | W34: WEB見積計算書 | AE34: 表構成
K35: 表FSC 材質名 | W35: WEB見積計算書 | AE35: 表FSC 材質区分
K36: 材質構成 中 | W36: WEB見積計算書 | AE36: 中構成
K37: 中FSC 材質名 | W37: WEB見積計算書 | AE37: 中FSC 材質区分
K38: 材質構成 裏 | W38: WEB見積計算書 | AE38: 裏構成
K39: 裏FSC 材質名 | W39: WEB見積計算書 | AE39: 裏FSC 材質区分
K41: 【結合条件】
O42: WEB見積計算書 | Y42: 見積計算書ＮＯ | AE42: = | AG42: WEB御見積書見積計算書 | AP42: 見積計算書ＮＯ
M43: AND | O43: WEB御見積書見積計算書 | Y43: 御見積書ＮＯ | AE43: = | AG43: WEB御見積書 | AP43: 御見積書ＮＯ
M44: AND | O44: WEB見積計算書 | Y44: サンプル依頼ID | AE44: = | AG44: ヒアリングシート | AP44: サンプル依頼ID
M45: AND | O45: WEB見積計算書 | Y45: 担当者 | AE45: = | AG45: 担当者マスタ | AP45: 担当者
...

Sheet 出力元画面
A1: =表紙!A54 -> Webシステム | K1: 文書名 | U1: モジュールID | Z1: =表紙!$AJ$63 -> MS | AE1: モジュール名 | AJ1: =表紙!$AX$63 -> Webシステム | AS1: 文書番号 | AZ1: Version | BF1: Rev.
K2: =表紙!O64 -> アドオン設計書 | U2: ｻﾌﾞﾓｼﾞｭｰﾙID | Z2: =表紙!$AJ$64 -> MSBB | AE2: ｻﾌﾞﾓｼﾞｭｰﾙ名 | AJ2: =表紙!$AX$64 -> Web販売管理 | AS2: =表紙!$BL$64 -> M7-US-1140 | AZ2: =表紙!$BU$64 -> 7.0.2 | BF2: =表紙!$CB$64 -> 1
K3: =RIGHT(CELL("filename",$A$1),LEN(CELL("filename",$A$1))-FIND("]",CELL("filename",$A$1))) -> 出力元画面 | U3: 表題 | Z3: =表紙!$AJ$65 -> MSBBRA040 | AE3: =表紙!$AQ$65 -> FSC製品化チェックシート
AD5: 出力元画面
B7: 画面ＩＤ | I7: 画面名 | Y7: 備考
B8: MSBBPA100 | I8: WebFSC製品化チェックシート出力
