Workbook
Name Rev.: 表紙!$U$22
Name Ver.: 表紙!$AE$26
Name ご確認者: 表紙!$AG$40
Name ご確認日: 表紙!$AG$42
Name サブシステム名: 表紙!$U$28
Name システム名: 表紙!$U$26
Name プロジェクト名: 表紙!$U$18
Name 開発区分: 表紙!$U$36
Name 機能ＩＤ: 表紙!$U$32
Name 機能区分: 表紙!$U$34
Name 機能名称: 表紙!$U$30
Name 顧客名: 表紙!$U$16
Name 最終更新者: 表紙!$AB$40
Name 最終更新日: 表紙!$AB$42
Name 作成者: 表紙!$W$40
Name 作成日: 表紙!$W$42
Name 章: 表紙!$M$10
Name 文書名: 表紙!$M$10

Sheet 目次
A1: アドオン設計書作成ガイド
C3: ■アドオン設計と成果物について
D4: ・システム設計フェーズとソフトウェア設計フェーズでアドオンの処理仕様を定義する
D5: ・システム設計フェーズとソフトウェア設計フェーズの成果物がアドオン設計書であり、ソフトウェア製作フェーズのインプットとなる
C7: ■各設計フェーズ毎のアドオン設計書作成範囲
D8: ・システム設計フェーズ：他機能との関連を定義するとともに、画面や帳票、ファイル入出力を中心とした外部入出力の設計を行う
D9: ・ソフトウェア設計フェーズ：内部処理を中心とした設計を行う
U11: ◎ | W11: … | X11: システム設計フェーズで作成
U12: ○ | W12: … | X12: システム設計フェーズで基本仕様を定義して、ソフトウェア設計フェーズで詳細化する
U13: △ | W13: … | X13: 必要に応じて（例えば標準仕様から変更がない場合は不要）
U14: ‐ | W14: … | X14: 不要
W15: … | X15: ソフトウェア設計フェーズで作成
D17: 各設計書と作成対象シートのマトリックス | S17: ※カスタマイズ：標準機能に機能を追加する アドオン：新規で機能を開発する
D18: EXCELシート | N18: 画面設計書 | W18: バッチ設計書 | AF18: 帳票設計書 | AO18: ＢＩ設計書 | AT18: .Net設計書 | BB18: EXCELシート | BL18: WebDB設計書 | BR18: 帳票設計書 | BX18: 汎用申請設計書
N19: カスタマイズ | S19: アドオン | W19: カスタマイズ | AB19: アドオン | AF19: カスタマイズ | AK19: アドオン | AO19: アドオン | AT19: アドオン | BL19: アドオン | BR19: アドオン | BX19: アドオン
D20: 概要 | N20: ◎ | O20: ※1 | S20: ◎ | W20: ◎ | X20: ※1 | AB20: ◎ | AF20: ◎ | AG20: ※1 | AK20: ◎ | AO20: ◎ | AT20: ◎ | BB20: 機能概要 | BL20: ◎ | BR20: ◎ | BX20: ◎
D21: レイアウト | N21: ◎ | O21: ※2 | S21: ◎ | W21: ‐ | AB21: ‐ | AF21: ◎ | AG21: ※2 | AK21: ◎ | AO21: ◎ | AT21: ◎ | BB21: アプリケーションフロー | BL21: ◎ | BR21: ー | BX21: ◎
D22: 項目説明 | N22: △ | S22: ○ | W22: ‐ | AB22: ‐ | AF22: △ | AK22: ○ | AO22: ○ | AT22: ○ | BB22: データベース設定 | BL22: ◎ | BR22: ー | BX22: ◎
D23: 引数説明 | N23: ‐ | S23: ‐ | W23: △ | AB23: ◎ | AF23: ‐ | AK23: ‐ | AO23: ‐ | AT23: ◎ | BB23: フィールド設定 | BL23: ◎ | BR23: ー | BX23: ◎
D24: 処理概要 | N24: ◎ | S24: ◎ | W24: ◎ | AB24: ◎ | AF24: ◎ | AK24: ◎ | AO24: ◎ | AT24: ◎ | BB24: 一覧表示画面設定 | BL24: ◎ | BR24: ー | BX24: ◎
D25: 処理詳細 | BB25: 表示編集画面設定 | BL25: ◎ | BR25: ー | BX25: ◎
D26: 処理・サービス関連図 | N26: △ | S26: ◎ | W26: △ | AB26: ◎ | AF26: ‐ | AK26: ‐ | AO26: ‐ | AT26: ◎ | BB26: 明細画面設定 | BL26: △ | BN26: ※3 | BR26: ー | BX26: △ | BZ26: ※3
D27: 検索入出力仕様 | N27: △ | S27: ○ | W27: △ | AB27: ○ | AF27: ‐ | AK27: ‐ | AO27: ‐ | AT27: ○ | BB27: 集計表示設定 | BL27: △ | BN27: ※4 | BR27: ー | BX27: △ | BZ27: ※4
D28: 更新入出力仕様 | N28: △ | S28: ○ | W28: △ | AB28: ○ | AF28: ‐ | AK28: ‐ | AO28: ‐ | AT28: ○ | BB28: 絞り込み条件設定 | BL28: △ | BN28: ※5 | BR28: ー | BX28: △ | BZ28: ※5
D29: ファイル入出力仕様 | N29: △ | S29: △ | W29: ‐ | AB29: ‐ | AF29: ‐ | AK29: ‐ | AO29: ‐ | AT29: △ | BB29: その他設定 | BR29: ー
D30: 画面遷移 | N30: △ | S30: ◎ | W30: ‐ | AB30: ‐ | AF30: ‐ | AK30: ‐ | AO30: ‐ | AT30: ◎ | BB30: 帳票イメージ | BL30: ー | BR30: ◎ | BX30: ー
D31: メッセージ一覧 | N31: △ | S31: △ | W31: △ | AB31: △ | AF31: ‐ | AK31: ‐ | AO31: ‐ | AT31: △ | BB31: 項目設計 | BL31: ー | BR31: ◎ | BX31: ー
D32: 補足説明 | N32: △ | S32: △ | W32: △ | AB32: △ | AF32: △ | AK32: △ | AO32: △ | AT32: △ | BB32: 補足説明 | BL32: △ | BR32: △ | BX32: △
D33: サービス呼出編集仕様 | N33: - | S33: - | W33: - | AB33: - | AF33: - | AK33: - | AO33: - | AT33: - | BB33: 補足説明(詳細)
D35: ※1 | G35: 別シートでカスタマイズ内容を記載する | BB35: ※3 | BE35: 単票画面は記載しない
D36: ※2 | G36: 吹き出しでカスタマイズ内容を記載する | BB36: ※4 | BE36: 集計・グラフ機能を使用する場合に記載する
BB37: ※5 | BE37: 共通設定のみ記載する(個別設定は、記載しない)

Sheet 表紙
AW2: サブモジュール
AW3: MA_マスタ管理
AW4: MB_業務共通
AW5: MG_原価管理
AW6: MSBA_需給管理
M7: 基本設計 | AW7: MSBB_販売管理
AW8: MSBC_生産管理
AW9: MSBD_購買管理
M10: アドオン設計書 | AW10: MSBE_在庫物流管理
AW11: MSBF_品質管理
AW12: MSBG_債権管理
AW13: MSBH_債務管理
AW14: MSBI_締処理
AW15: MSUA_リスト・入力補助
M16: 顧客 | U16: 株式会社クラウン・パッケージ | AW16: PF_ESBアダプタ
M18: プロジェクト名 | U18: 基幹システム刷新PJ | AW18: 機能区分
AW19: 画面
M20: 文書番号 | AW20: 帳票
AW21: バッチ
M22: Ｒｅｖ． | U22: {=MAX(_xlfn.NUMBERVALUE(改訂!A7:E48))} -> 2 | AW22: マスタ
M24: 機密性区分 | U24: 取扱注意（Ｃ） | AW24: 開発区分
AW25: カスタマイズ
M26: システム名 | U26: Webシステム | AC26: Ver. | AE26: 7.0.2 | AW26: アドオン
AW27: －
M28: サブモジュール | U28: MSBB_販売管理
M30: 機能名 | U30: =M50 -> Web受注一覧照会
M32: 機能ID | U32: =G50 -> MSBBPA080
M34: 機能区分 | U34: 画面
M36: 開発区分 | U36: アドオン
W39: 作成 | AB39: 最終更新 | AG39: ご確認
W40: MDSOL
W42: 44805
A48: 文書番号 | G48: 画面ID | M48: 画面名 | V48: Version | AB48: Revision
A50: M7-US-1140 | G50: MSBBPA080 | M50: Web受注一覧照会 | V50: 1.0.0 | AB50: r01.00
A53: 共通（元データ）
A54: Webシステム | K54: 文書名 | U54: モジュールID | Z54: MS | AE54: モジュール名 | AJ54: Webシステム | AS54: 文書番号 | AZ54: Version | BF54: Rev.
K55: 画面説明書 | U55: ｻﾌﾞﾓｼﾞｭｰﾙID | Z55: MSBB | AE55: ｻﾌﾞﾓｼﾞｭｰﾙ名 | AJ55: 販売Webシステム | AS55: M7-US-1140 | AZ55: 1.0.0 | BF55: r00.00
K56: 表紙 | U56: 表題 | Z56: MSBBPA080 | AE56: Web受注一覧照会
A57: 共通（リンク用）
A58: =A54 -> Webシステム | K58: 文書名 | U58: モジュールID | Z58: =Z54 -> MS | AE58: モジュール名 | AJ58: =AJ54 -> Webシステム | AS58: 文書番号 | AZ58: Version | BF58: Rev.
...

Sheet 改訂
A1: 第7章 | K1: 改訂 | AU1: 作成者 | AZ1: MDSOL | BE1: 作成日 | BJ1: =表紙!W42 -> 44805 | BP1: Rev.
AU2: 修正者 | AZ2: =BM12 -> TBK徐 | BE2: 改訂日 | BJ2: =BM11 -> 44966 | BP2: =表紙!CB64 -> 2
A5: Rev. | F5: 改定内容 | BC5: 頁 | BM5: 変更日 変更者 | BR5: 確認日 確認者
A7: 1 | F7: 新規作成
A9: 2 | F9: 処理詳細の追加 | BC9: 処理詳細 | BM9: 44944
BM10: TBK徐
A11: 2 | F11: 画面項目制御追加 | BC11: 画面項目制御 | BM11: 44966
BM12: TBK徐

Sheet 概要
A1: =表紙!A54 -> Webシステム | O1: 文書名 | AC1: モジュールID | AJ1: =表紙!AJ63 -> MS | AQ1: モジュール名 | AX1: =表紙!AX63 -> Webシステム | BL1: 文書番号 | BU1: Version | CB1: Rev.
O2: =表紙!O64 -> アドオン設計書 | AC2: サブモジュールID | AJ2: =表紙!AJ64 -> MSBB | AQ2: サブモジュール名 | AX2: =表紙!AX64 -> 販売Webシステム | BL2: =表紙!BL64 -> M7-US-1140 | BU2: =表紙!BU64 -> 7.0.2 | CB2: =表紙!CB64 -> 2
O3: =RIGHT(CELL("filename",$A$1),LEN(CELL("filename",$A$1))-FIND("]",CELL("filename",$A$1))) -> 概要 | AC3: 表題 | AJ3: =表紙!AJ65 -> MSBBPA080 | AQ3: =表紙!AQ65 -> Web受注一覧照会
AO5: 概要
B7: 【説明】
C8: 受注の一覧照会画面
B10: 【目的】
C11: 受注を一覧照会する。受注画面へ遷移する。(参照・訂正)
C12: 受注伝票を一括発行する
B14: 【処理関連図/サービス関連図】
C15: ※処理・サービス関連図シートに詳細記載
B17: 【オペレーション一覧】
C18: 受注の検索・照会処理を行う
C19: 受注伝票の帳票発行を行う
C20: 受注のCSV出力を行う
B22: 【SQLID一覧】
C23: なし
B25: 【ソート順】
C26: 担当、得意先、手配NO(1～3)
B28: 【データアクセスコントロール】
C29: 拠点による制御
C30: ※詳細は、【MSBBPA000】_共通設計書_アドオン(Webシステム共通仕様)にて定義
B32: 【自由記述】
C33: なし

Sheet 画面イメージ
A1: =表紙!A54 -> Webシステム | K1: 文書名 | U1: モジュールID | Z1: =表紙!$AJ$63 -> MS | AE1: モジュール名 | AJ1: =表紙!$AX$63 -> Webシステム | AS1: 文書番号 | AZ1: Version | BF1: Rev.
K2: =表紙!O64 -> アドオン設計書 | U2: ｻﾌﾞﾓｼﾞｭｰﾙID | Z2: =表紙!$AJ$64 -> MSBB | AE2: ｻﾌﾞﾓｼﾞｭｰﾙ名 | AJ2: =表紙!$AX$64 -> 販売Webシステム | AS2: =表紙!$BL$64 -> M7-US-1140 | AZ2: =表紙!$BU$64 -> 7.0.2 | BF2: =表紙!$CB$64 -> 2
K3: =RIGHT(CELL("filename",$A$1),LEN(CELL("filename",$A$1))-FIND("]",CELL("filename",$A$1))) -> 画面イメージ | U3: 表題 | Z3: =表紙!$AJ$65 -> MSBBPA080 | AE3: =表紙!$AQ$65 -> Web受注一覧照会
A5: 画面イメージ
B7: ≫凡例
Q8: ・・・ | S8: ボタン
C9: 見積計算書NO | Q9: ・・・ | S9: 検索項目(検索画面表示選択) | AJ9: 参照情報
C10: 品名 | Q10: ・・・ | S10: 入力項目
C11: 得意先 | Q11: ・・・ | S11: 表示項目(得意先名称、原紙名等) | AJ11: 担当者
C12: 操作種別 | I12: ●登録 | M12: ○訂正 | Q12: ・・・ | S12: 選択項目(一つのみ選択可能)
C13: 受注区分 | Q13: ・・・ | S13: 選択項目(一つのみ選択可能)
C14: 作業順 | I14: ☑AAA | M14: ☑BBB | Q14: ・・・ | S14: 選択項目(複数選択可能) | DF14: MDSOL 野村 2022/10/25
CH15: 指摘ＣＰ 2022/10/18 玉置 抽出条件の確認 現行のシステムでは、製品の納入場所や品質の関係で、 以下の各部門（拠点：ＷＧ）に分かれています。 得意先の担当の部門（受注部門）と、 品物を製造・手配・出荷する部門（製造部門）と 工程の内、シ－ト製造だけを担当する部門（シ－ト製造部門）と の３種で、 現行の受注照会の一部では、抽出条件にもなっているのですが、 対応はいかがでしょうか？ | DF15: シ設計時に受注には製造部門を持たないことで決定しました | DT15: 2022/10/27 玉置 問題なし
C16: 見積作成日 | Q16: ・・・ | S16: カレンダー形式 | AD16: 指摘ＣＰ 2022/10/18 玉置 誤字 カレンダー←カンレンダー | AS16: MDSOL 野村 2022/10/25 修正しました(横展開対応も実施します) | BK16: 2022/10/27 玉置 問題なし | DF16: 工程毎にWG(拠点)は持っています
BX21: －
D23: 拠点 | BR23: * | BS23: あいまい検索可能
D24: 得意先 | J24: (得意先名:オートフィルタ) | AC24: 売上担当者
D25: 顧客品名 | AB25: * | AU25: *
D26: 受注日 | P26: ~ | AC26: 客先納期 | AO26: ~ | DE26: 事前指摘(MDSOL記載)
D27: 手配NO | P27: ~ | AC27: 受注区分 | AI27: 製品 | AO27: 製品区分 | AU27: 大 | BB27: 中 | BI27: 小 | DE27: CP指摘 2022/10/02 落合 受注入力から受注一覧照会を開いたときに、受注区分・得意先CD・受注日（当日から6か月の範囲）で自動検索し結果を表示する
DF28: MDSOL 野村 2022/10/25 初期条件に追加します | DW28: 2022/11/01 落合 問題なし
D29: 製品CD | AC29: セット製品CD
DE30: CP指摘 2022/10/02 落合 受注№はMCFの受注№？
R31: 原紙 | AK31: 印刷 | AY31: エンボス | BJ31: メーカ | DF31: MDSOL 野村 2022/10/25 WEB受注NO・受注明細NOとなります | EA31: 2022/11/01 落合 条件に受注NOがありますが、どちらを入れるのですか？ | EV31: MDSOL 野村 2022/11/02 WEB受注NOとなります。
D32: 段 | J32: E | N32: 表構成 | BJ32: (メーカ名:ｵｰﾄﾌｨﾙﾀ) | FD32: 申し訳ございません。WEB受注NO・WEB受注明細NOと明記統一します。 | FZ32: 2022/11/04 落合 手配№とweb受注№の関係性を教えてください。 ユーザーは何を見てweb受注№を入力するのでしょうか？
D33: シート寸法 | J33: 巾 | P33: 流れ | AC33: 刃渡り（mm) | AI33: 巾 | AO33: 流れ | DE33: CP指摘 2022/09/30 三宅 条件の部分だけでかなり画面占有しているので折り畳み可能に ・あるいは初期状態ではく使う条件のみ表示 | GA33: MDSOL 野村 2022/11/07 web受注・明細№は、DB上の一意となるキーになります。システム管理者用の項目として、条件+一覧に追加しておりました。不要であれば削除します。
DE34: してめったに使わない細かい絞込み用は非表示（配置も検討） | GA34: ※受注後、明細をコピーして一部を預り売上にした場合に同じ手配NOとなり、左記一覧では判断付かないため、預り売上の項目を追加しております。
D35: 詳細検索 | BW35: ー | DE35: 備考の「40byte」は40文字ではなくてバイト？検索ワードが長くなりすぎないように日本語で十数文字程度に(UTF-8)抑えたいという意図？ | FZ35: 2022/11/07 落合 問題なし
J36: 原紙 | AC36: 印刷 | AQ36: エンボス | BB36: メーカ
D37: 中構成 | BB37: (メーカ名:ｵｰﾄﾌｨﾙﾀ) | DE37: CP指摘 2022/10/02 落合 検索条件が多すぎる為、レイアウトを右記のようにする→
D38: 裏構成 | BB38: (メーカ名:ｵｰﾄﾌｨﾙﾀ) | DN38: 詳細検索は折りたたんだ状態で表示し、必要時のみ入力する
DN39: 見積検索も合わせてください
D40: 売価区分 | AC40: WEB受注NO | AO40: ~ | DF40: MDSOL 野村 2022/10/25 レイアウト修正→見積を合わせて修正します | EA40: 2022/11/01 落合 初期表示は折りたたんだ状態にして下さい | EV40: MDSOL 野村 2022/11/02 承知しました。(見積も合わせます) | FN40: 2022/11/04 落合 問題なし
D41: 注文書No | R41: * | AC41: 先方担当 | AQ41: *
D42: 製品形状 | R42: 物流区分 | AC42: 運送会社 | DE42: CP指摘 2022/09/30 木﨑 巾[From] ~ [To] 流れ[From] ~ [To] にした方がよいかと思います。[From][From]~[To][To] では違和感があります。
DF43: MDSOL 野村 2022/10/25 レイアウト修正により、巾[From] ~ [To] 流れ[From] ~ [To] は無しとなりました | EL43: 2022/11/01 落合 問題なし
D44: 印刷備考 | J44: 40byte | AB44: * | AC44: 製造備考 | AI44: 40byte | BA44: *
D45: 伝票備考 | J45: 40byte | AB45: * | AC45: 納入備考 | AI45: 40byte | BA45: * | DE45: CP指摘 2022/10/02 落合 範囲で指定する場合、toが未入力の場合はfromをtoへ自動セットする
D46: 出荷備考１ | J46: 40byte | AB46: * | AC46: 出荷備考２ | AI46: 40byte | BA46: * | DF46: MDSOL 野村 2022/10/25 共通仕様に明記します | DV46: 2022/11/01 落合 問題なし
AC47: 再製造備考 | AI47: 40byte | BA47: *
...

Sheet 項目説明
A1: =表紙!A54 -> Webシステム | K1: 文書名 | U1: モジュールID | Z1: =表紙!$AJ$63 -> MS | AE1: モジュール名 | AJ1: =表紙!$AX$63 -> Webシステム | AS1: 文書番号 | AZ1: Version | BF1: Rev.
K2: =表紙!O64 -> アドオン設計書 | U2: ｻﾌﾞﾓｼﾞｭｰﾙID | Z2: =表紙!$AJ$64 -> MSBB | AE2: ｻﾌﾞﾓｼﾞｭｰﾙ名 | AJ2: =表紙!$AX$64 -> 販売Webシステム | AS2: =表紙!$BL$64 -> M7-US-1140 | AZ2: =表紙!$BU$64 -> 7.0.2 | BF2: =表紙!$CB$64 -> 2
K3: =RIGHT(CELL("filename",$A$1),LEN(CELL("filename",$A$1))-FIND("]",CELL("filename",$A$1))) -> 項目説明 | U3: 表題 | Z3: =表紙!$AJ$65 -> MSBBPA080 | AE3: =表紙!$AQ$65 -> Web受注一覧照会
A5: 受注一覧照会
B6: 抽出条件 | N6: 説明 | BE6: Ｗ | BF6: 型 | BG6: 参 | BH6: 必 | BI6: 入 | BJ6: 非 | BK6: 検
A7: 〇 | B7: 拠点 | M7: 【MSBBPACOM】_共通設計書_アドオン(共通ロジック)にて定義 | BE7: C | BF7: S
A8: 〇 | B8: 得意先 | M8: 【MSBBPACOM】_共通設計書_アドオン(共通ロジック)にて定義 | BE8: A | BF8: S | BK8: 検
A9: 〇 | B9: 売上担当者 | M9: 【MSBBPACOM】_共通設計書_アドオン(共通ロジック)にて定義 | BE9: C | BF9: S
A10: 〇 | B10: 顧客品名1 | M10: 抽出条件として、顧客品名1を入力する | AZ10: あいまい検索可 | BE10: T | BF10: S
A11: 〇 | B11: 顧客品名2 | M11: 抽出条件として、顧客品名2を入力する | AZ11: あいまい検索可 | BE11: T | BF11: S
A12: 〇 | B12: 受注日(From) | M12: 抽出条件として、受注日(From)を入力する | BE12: カ | BF12: D
A13: 〇 | B13: 受注日(To) | M13: 抽出条件として、受注日(To)を入力する | BE13: カ | BF13: D
A14: 〇 | B14: 客先納期(From) | M14: 抽出条件として、客先納期(From)を入力する | BE14: カ | BF14: D
A15: 〇 | B15: 客先納期(To) | M15: 抽出条件として、客先納期(To)を入力する | BE15: カ | BF15: D
A16: 〇 | B16: 手配NO(From) | M16: 抽出条件として、手配NO(From)を入力する | BE16: T | BF16: S
A17: 〇 | B17: 手配NO(To) | M17: 抽出条件として、手配NO(To)を入力する | BE17: T | BF17: S | BM17: 事前指摘
A18: 〇 | B18: 受注区分 | M18: 【MSBBPACOM】_共通設計書_アドオン(共通ロジック)にて定義 | BE18: C | BF18: S | BM18: CP指摘 2022/09/28 木﨑 受注区分等のリストは未選択も可能ですか？ (念のためです)
A19: 〇 | B19: 製品区分_大 | M19: 【MSBBPACOM】_共通設計書_アドオン(共通ロジック)にて定義 | BE19: C | BF19: S | BN19: MDSOL 野村 2022/10/25 可能です。 | CB19: 2022/11/01 落合 問題なし
A20: 〇 | B20: 製品区分_中 | M20: 【MSBBPACOM】_共通設計書_アドオン(共通ロジック)にて定義 | BE20: C | BF20: S | BL20: 指摘CP 2022/10/18 玉置 項目の定義 現行のシステムでは「大」と「小」で区分していますので、「中」を使用するならば内訳を、使用しないならば使用しないことを明確にお願いします。 | CJ20: MDSOL 野村 2022/10/25 項目定義シートで定義している内容となります。内容は、汎用マスタとなります。設定値は、以下ファイルを確認ください | CW20: 2022/10/27 玉置 問題なし
A21: 〇 | B21: 製品区分_小 | M21: 【MSBBPACOM】_共通設計書_アドオン(共通ロジック)にて定義 | BE21: C | BF21: S | CJ21: https://crown-grp.backlog.com/alias/file/27383942
A22: 〇 | B22: セット製品CD | M22: 【MSBBPACOM】_共通設計書_アドオン(共通ロジック)にて定義 | BE22: A | BF22: S | BK22: 検
A23: 〇 | B23: 製品CD | M23: 【MSBBPACOM】_共通設計書_アドオン(共通ロジック)にて定義 | BE23: T | BF23: S | BK23: 検
A24: 〇 | B24: シート段 | M24: 【MSBBPACOM】_共通設計書_アドオン(共通ロジック)にて定義 | BE24: C | BF24: S
A25: 〇 | B25: 原紙コード(表) | M25: 【MSBBPACOM】_共通設計書_アドオン(共通ロジック)にて定義 | BE25: A | BF25: S | BK25: 検
A26: 〇 | B26: 印刷コード(表) | M26: 【MSBBPACOM】_共通設計書_アドオン(共通ロジック)にて定義 | BE26: A | BF26: S | BK26: 検
A27: 〇 | B27: エンボスコード(表) | M27: 【MSBBPACOM】_共通設計書_アドオン(共通ロジック)にて定義 | BE27: A | BF27: S | BK27: 検
A28: 〇 | B28: メーカコード(表) | M28: 【MSBBPACOM】_共通設計書_アドオン(共通ロジック)にて定義 | BE28: A | BF28: S | BK28: 検
A29: 〇 | B29: 刃渡り_巾 | M29: 抽出条件として、刃渡り_巾を入力する | BE29: T | BF29: N
A30: 〇 | B30: 刃渡り_流れ | M30: 抽出条件として、刃渡り_流れを入力する | BE30: T | BF30: N | BL30: 指摘CP 2022/10/18 玉置 シ－ト寸法は全判になりますか？ スリッタ後の寸法になりますか？ 明記すべきと考えます。 | CJ30: MDSOL 野村 2022/10/25
A31: 〇 | B31: シート寸法_巾 | M31: 抽出条件として、シート寸法_巾を入力する | BE31: T | BF31: N | CJ31: 受注入力で指定したシート寸法となります | CR31: 2022/10/27 玉置 問題なし
A32: 〇 | B32: シート寸法_流れ | M32: 抽出条件として、シート寸法_流れを入力する | BE32: T | BF32: N | CJ32: ※刃渡りに咥えを足したシート寸法が該当します
B34: 抽出条件 - 詳細検索 | N34: 説明 | BE34: Ｗ | BF34: 型 | BG34: 参 | BH34: 必 | BI34: 入 | BJ34: 非 | BK34: 検
A35: 〇 | B35: 詳細検索(+/-) | M35: 詳細検索領域を+時…開く、-時…閉じる | AS35: ※初期は閉じた状態(折り畳み)とする
A36: 〇 | B36: 原紙コード(中) | M36: 【MSBBPACOM】_共通設計書_アドオン(共通ロジック)にて定義 | BE36: A | BF36: S | BK36: 検
A37: 〇 | B37: 印刷コード(中) | M37: 【MSBBPACOM】_共通設計書_アドオン(共通ロジック)にて定義 | BE37: A | BF37: S | BK37: 検
A38: 〇 | B38: エンボスコード(中) | M38: 【MSBBPACOM】_共通設計書_アドオン(共通ロジック)にて定義 | BE38: A | BF38: S | BK38: 検
A39: 〇 | B39: メーカコード(中) | M39: 【MSBBPACOM】_共通設計書_アドオン(共通ロジック)にて定義 | BE39: A | BF39: S | BK39: 検
A40: 〇 | B40: 原紙コード(裏) | M40: 【MSBBPACOM】_共通設計書_アドオン(共通ロジック)にて定義 | BE40: A | BF40: S | BK40: 検
A41: 〇 | B41: 印刷コード(裏) | M41: 【MSBBPACOM】_共通設計書_アドオン(共通ロジック)にて定義 | BE41: A | BF41: S | BK41: 検
A42: 〇 | B42: エンボスコード(裏) | M42: 【MSBBPACOM】_共通設計書_アドオン(共通ロジック)にて定義 | BE42: A | BF42: S | BK42: 検
...

Sheet 引数説明
A1: =表紙!A54 -> Webシステム | K1: 文書名 | U1: モジュールID | Z1: =表紙!$AJ$63 -> MS | AE1: モジュール名 | AJ1: =表紙!$AX$63 -> Webシステム | AS1: 文書番号 | AZ1: Version | BF1: Rev.
K2: =表紙!O64 -> アドオン設計書 | U2: ｻﾌﾞﾓｼﾞｭｰﾙID | Z2: =表紙!$AJ$64 -> MSBB | AE2: ｻﾌﾞﾓｼﾞｭｰﾙ名 | AJ2: =表紙!$AX$64 -> 販売Webシステム | AS2: =表紙!$BL$64 -> M7-US-1140 | AZ2: =表紙!$BU$64 -> 7.0.2 | BF2: =表紙!$CB$64 -> 2
K3: =RIGHT(CELL("filename",$A$1),LEN(CELL("filename",$A$1))-FIND("]",CELL("filename",$A$1))) -> 引数説明 | U3: 表題 | Z3: =表紙!$AJ$65 -> MSBBPA080 | AE3: =表紙!$AQ$65 -> Web受注一覧照会
B5: オペレーションＩＤ/名称：SloRecvIfImp_Upd01/取込
A6: 必 | B6: 項目名 | N6: 説明 | AS6: 未設定時の振る舞い

Sheet 処理概要
A1: =表紙!A54 -> Webシステム | K1: 文書名 | U1: モジュールID | Z1: =表紙!$AJ$63 -> MS | AE1: モジュール名 | AJ1: =表紙!$AX$63 -> Webシステム | AS1: 文書番号 | AZ1: Version | BF1: Rev.
K2: =表紙!O64 -> アドオン設計書 | U2: ｻﾌﾞﾓｼﾞｭｰﾙID | Z2: =表紙!$AJ$64 -> MSBB | AE2: ｻﾌﾞﾓｼﾞｭｰﾙ名 | AJ2: =表紙!$AX$64 -> 販売Webシステム | AS2: =表紙!$BL$64 -> M7-US-1140 | AZ2: =表紙!$BU$64 -> 7.0.2 | BF2: =表紙!$CB$64 -> 2
K3: =RIGHT(CELL("filename",$A$1),LEN(CELL("filename",$A$1))-FIND("]",CELL("filename",$A$1))) -> 処理概要 | U3: 表題 | Z3: =表紙!$AJ$65 -> MSBBPA080 | AE3: =表紙!$AQ$65 -> Web受注一覧照会
A5: NO | B5: 入力 | J5: 処理 | BD5: 出力
A6: 1 | B6: 初期表示
J7: 1.処理概要
K8: 初期表示
L9: 拠点 | Q9: ： | R9: ログインに紐づく拠点CDを表示する
R10: ログイン.管理者区分 = 0(一般ユーザー時)、変更不可とする
L11: 担当者 | Q11: ： | R11: ログイン担当者CDを表示する
L12: 受注日 | Q12: ： | R12: 受注日Fromに当日 - ログインマスタ.初期表示をセット、Toに当日をセットする
L13: 表示処理 | Q13: ： | R13: 抽出条件をもとに受注一覧に結果を表示する | BD13: 検索入出力仕様.NO1
L15: フッターボタン表示・非表示切替
M16: メニューから呼び出された場合(照会画面モード) | AC16: ・・・ | AE16: 受注詳細ボタンを表示、選択ボタンを非表示とする
M17: 検索画面として呼び出された場合(検索画面モード) | AC17: ・・・ | AE17: 受注詳細ボタンを非表示、選択ボタンを表示とする
M18: 例)検索画面モード:Web受注入力から検索画面として呼び出され、選択行を呼出元に返す
N20: 受注入力から受注一覧照会を開いたときに、受注区分・得意先CD・受注日（当日から6か月の範囲）で検索し結果を表示する | BN20: CP指摘 2022/10/02 落合 受注入力から受注一覧照会を開いたときに、受注区分・得意先CD・受注日（当日から6か月の範囲）で自動検索し結果を表示する
N21: ※受注区分・得意先CDの入力値がある場合、初期抽出条件とする | BO21: MDSOL 野村 2022/10/31 初期条件に追加します | CF21: 2022/11/01 落合 問題なし
A23: 2 | B23: 画面操作
J24: 1.処理概要
K25: ボタン処理
L26: クリアボタン押下 | U26: ： | V26: 画面を初期化する(起動時の状態とする)
L28: 表示ボタン押下 | U28: ： | V28: チェック処理にてエラーとなった場合、後続処理をキャンセルする
L29: (チェック処理) | W29: FROM～TOの整合性チェック | AH29: … | AI29: エラーメッセージ：FROM≦TOの関係で指定してください。 | BD29: メッセージID.001
L31: 表示ボタン押下 | U31: ： | V31: 抽出条件をもとに受注計算書一覧に結果を表示する | BD31: 検索入出力仕様.NO1
W32: データ取得できなかった場合、下記メッセージを表示
W33: エラーメッセージ：検索結果がありません。 | BD33: メッセージID.002
L35: 受注伝票ボタン押下 | U35: ： | V35: 受注一覧の発行にチェックされたデータを帳票「受注伝票」として出力する
W36: 発行☑が1行もチェックされていない場合、下記メッセージを表示
W37: エラーメッセージ：発行対象がありません。 | BD37: メッセージID.003
U38: ※帳票出力は、【MSBBRA050】_帳票設計書_アドオン(受注伝票)を参照
L40: CSV出力 | U40: ： | V40: 受注一覧のデータをCSV出力する | BD40: ファイル入出力仕様.NO1
U41: ※1 CSV出力定義とファイル名は、【MSBBPACOM】_共通設計書_アドオン(共通ロジック)にて定義
U42: ※2 画面に表示されたデータがCSVとして出力される | BM42: 事前指摘
BN43: CP指摘 2022/09/28 木﨑 選択した受注の詳細画面へ遷移なら一覧にチェックボックス等の選択用項目が必要かと思います。(何を選択中か分からない。選択した行はハイライト表示ですか？)また[選択]→[詳細表示]ですと２ステップの操作になるので、各行の先頭に受注詳細ボタを設けた方が操作性は良いかと思います。
L44: 受注詳細ボタン押下 | U44: ： | V44: 受注入力画面に遷移する(操作種別:参照で遷移する) | BO44: MDSOL 野村 2022/10/25 選択行となります。初期想定は、一覧にて選択ボタンを設けておりましたが、打合せによりフッターにボタンを集約することになりました。
W45: 一覧にデータが無いもしくは対象行が選択されてない場合、下記メッセージを表示
W46: エラーメッセージ：選択行がありません。 | BD46: メッセージID.004 | BN46: CP指摘 2022/09/28 木﨑 受注詳細ボタンと同様になります。選択ボタンは各行の先頭に設けた方が操作性は良くなると思います。
U47: → 選択行のWEB受注NO/WEB受注明細NOをキーに受注データを参照する | BD47: 画面遷移.S01.NO1
L49: 選択 | U49: ： | V49: 検索モードで開いた場合に選択結果(1行)を遷移元画面に返す
...

Sheet 処理・サービス関連図
A1: =表紙!A54 -> Webシステム | K1: 文書名 | U1: モジュールID | Z1: =表紙!$AJ$63 -> MS | AE1: モジュール名 | AJ1: =表紙!$AX$63 -> Webシステム | AS1: 文書番号 | AZ1: Version | BF1: Rev.
K2: =表紙!O64 -> アドオン設計書 | U2: ｻﾌﾞﾓｼﾞｭｰﾙID | Z2: =表紙!$AJ$64 -> MSBB | AE2: ｻﾌﾞﾓｼﾞｭｰﾙ名 | AJ2: =表紙!$AX$64 -> 販売Webシステム | AS2: =表紙!$BL$64 -> M7-US-1140 | AZ2: =表紙!$BU$64 -> 7.0.2 | BF2: =表紙!$CB$64 -> 2
K3: =RIGHT(CELL("filename",$A$1),LEN(CELL("filename",$A$1))-FIND("]",CELL("filename",$A$1))) -> 処理・サービス関連図 | U3: 表題 | Z3: =表紙!$AJ$65 -> MSBBPA080 | AE3: =表紙!$AQ$65 -> Web受注一覧照会
C7: 検索処理

Sheet 処理詳細
A1: =表紙!A54 -> Webシステム | K1: 文書名 | U1: モジュールID | Z1: =表紙!$AJ$63 -> MS | AE1: モジュール名 | AJ1: =表紙!$AX$63 -> Webシステム | AS1: 文書番号 | AZ1: Version | BF1: Rev.
K2: =表紙!O64 -> アドオン設計書 | U2: ｻﾌﾞﾓｼﾞｭｰﾙID | Z2: =表紙!$AJ$64 -> MSBB | AE2: ｻﾌﾞﾓｼﾞｭｰﾙ名 | AJ2: =表紙!$AX$64 -> 販売Webシステム | AS2: =表紙!$BL$64 -> M7-US-1140 | AZ2: =表紙!$BU$64 -> 7.0.2 | BF2: =表紙!$CB$64 -> 2
K3: =RIGHT(CELL("filename",$A$1),LEN(CELL("filename",$A$1))-FIND("]",CELL("filename",$A$1))) -> 処理詳細 | U3: 表題 | Z3: =表紙!$AJ$65 -> MSBBPA080 | AE3: =表紙!$AQ$65 -> Web受注一覧照会
A5: No | B5: 入力 | J5: 処理 | BD5: 出力
A6: 1 | B6: 初期表示
J7: 1.1 | L7: 処理概要参照
A10: 2 | B10: 画面操作
J11: 2.1 | L11: 処理概要参照
J13: 2.2 | L13: [抽出条件 - 詳細検索].詳細検索(+/-)押す
L14: 2.2.1 | O14: 初期は閉じた状態(折り畳み)とする
L16: 2.2.2 | O16: 詳細検索領域を+時…開く、-時…閉じる
A19: 3 | B19: 検索
J20: 3.1 | L20: コンボボックスの初期化
L21: 拠点コンボボックスの初期化
M22: ※ | N22: 拠点検索_SQLリソースの検索仕様
N23: 【MSBBPACOM】_共通設計書_アドオン(Web共通ロジック)の「処理詳細(共通検索)」シート」を参照する。
L25: 売上担当者コンボボックスの初期化
M26: ※ | N26: 売上担当者検索_SQLリソースの検索仕様
N27: 【MSBBPACOM】_共通設計書_アドオン(Web共通ロジック)の「処理詳細(共通検索)」シート」を参照する。
L29: 受注区分コンボボックスの初期化
M30: ※ | N30: 受注区分検索_SQLリソースの検索仕様
N31: 【MSBBPACOM】_共通設計書_アドオン(Web共通ロジック)の「処理詳細(共通検索)」シート」を参照する。
L33: 製品区分_大コンボボックスの初期化
M34: ※ | N34: 製品区分_大検索_SQLリソースの検索仕様
N35: 【MSBBPACOM】_共通設計書_アドオン(Web共通ロジック)の「処理詳細(共通検索)」シート」を参照する。
L37: 製品区分_中コンボボックスの初期化
M38: ※ | N38: 製品区分_中検索_SQLリソースの検索仕様
N39: 【MSBBPACOM】_共通設計書_アドオン(Web共通ロジック)の「処理詳細(共通検索)」シート」を参照する。
L41: 製品区分_小コンボボックスの初期化
M42: ※ | N42: 製品区分_小検索_SQLリソースの検索仕様
N43: 【MSBBPACOM】_共通設計書_アドオン(Web共通ロジック)の「処理詳細(共通検索)」シート」を参照する。
L45: シート段コンボボックスの初期化
M46: ※ | N46: シート段検索_SQLリソースの検索仕様
N47: 【MSBBPACOM】_共通設計書_アドオン(Web共通ロジック)の「処理詳細(共通検索)」シート」を参照する。
L49: 売価区分コンボボックスの初期化
M50: ※ | N50: 売価区分検索_SQLリソースの検索仕様
N51: 【MSBBPACOM】_共通設計書_アドオン(Web共通ロジック)の「処理詳細(共通検索)」シート」を参照する。
L53: 製品形状コンボボックスの初期化
M54: ※ | N54: 製品形状検索_SQLリソースの検索仕様
N55: 【MSBBPACOM】_共通設計書_アドオン(Web共通ロジック)の「処理詳細(共通検索)」シート」を参照する。
...

Sheet 画面項目制御
J2: 操作種別 | O2: 検索 | S2: R | U2: 有効(必須)
B3: 画面項目 | S3: E | U3: 有効
B4: 抽出条件 | G4: 拠点 | O4: RO/R | S4: RO | U4: 読取のみ
G5: 得意先 | O5: E | S5: D | U5: 無効
G6: 売上担当者 | O6: E | S6: I | U6: 非表示
G7: 顧客品名1 | O7: E
G8: 顧客品名2 | O8: E
G9: 受注日(From) | O9: E
G10: 受注日(To) | O10: E
G11: 客先納期(From) | O11: E
G12: 客先納期(To) | O12: E
G13: 手配NO(From) | O13: E
G14: 手配NO(To) | O14: E
G15: 受注区分 | O15: E
G16: 製品区分_大 | O16: E
G17: 製品区分_中 | O17: E
G18: 製品区分_小 | O18: E
... G29: シート寸法_流れ | O29: E
B30: 抽出条件 - 詳細検索 | G30: 詳細検索(+/-) | O30: E
G31: 原紙コード(中) | O31: E
G32: 印刷コード(中) | O32: E
G33: エンボスコード(中) | O33: E
G34: メーカコード(中) | O34: E
G35: 原紙コード(裏) | O35: E
G36: 印刷コード(裏) | O36: E
G37: エンボスコード(裏) | O37: E
G38: メーカコード(裏) | O38: E
G39: 売価区分 | O39: E
G40: WEB受注NO(From) | O40: E
G41: WEB受注NO(To) | O41: E
G42: 注文書NO | O42: E
... G53: 再製造備考 | O53: E
B54: 受注一覧 | G54: NO | O54: RO
G55: 得意先 | O55: RO
G56: 担当 | O56: RO
G57: 得意先名 | O57: RO
G58: 担当者名 | O58: RO
G59: 注文書NO | O59: RO
G60: 手配NO1 | O60: RO
G61: 不適合手配NO1 | O61: RO
...

Sheet 検索入出力仕様
A1: =表紙!A54 -> Webシステム | K1: 文書名 | U1: モジュールID | Z1: =表紙!$AJ$63 -> MS | AE1: モジュール名 | AJ1: =表紙!$AX$63 -> Webシステム | AS1: 文書番号 | AZ1: Version | BF1: Rev.
K2: =表紙!O64 -> アドオン設計書 | U2: ｻﾌﾞﾓｼﾞｭｰﾙID | Z2: =表紙!$AJ$64 -> MSBB | AE2: ｻﾌﾞﾓｼﾞｭｰﾙ名 | AJ2: =表紙!$AX$64 -> 販売Webシステム | AS2: =表紙!$BL$64 -> M7-US-1140 | AZ2: =表紙!$BU$64 -> 7.0.2 | BF2: =表紙!$CB$64 -> 2
K3: =RIGHT(CELL("filename",$A$1),LEN(CELL("filename",$A$1))-FIND("]",CELL("filename",$A$1))) -> 検索入出力仕様 | U3: 表題 | Z3: =表紙!$AJ$65 -> MSBBPA080 | AE3: =表紙!$AQ$65 -> Web受注一覧照会
A5: NO | G5: 1 | S5: ボタン | Z5: 表示 | AH5: 備考 | AK5: 表示ボタンクリック時処理
A6: 処理分類 | E6: 検索 | S6: ソート順 | Z6: 担当、得意先、手配NO1、手配NO2、手配NO3
A7: NO | C7: 転送先 | V7: 転送元 | AQ7: 説明
C8: 種 | D8: オブジェクト | K8: 項目名 | V8: 種 | W8: オブジェクト | AF8: 項目名
A9: 1 | C9: 画 | D9: 受注一覧 | K9: NO | AF9: 行番
A10: 2 | C10: 画 | D10: 受注一覧 | K10: 得意先 | V10: T | W10: Web受注明細 | AF10: 得意先 | AI10: (手配NO2)
A11: 3 | C11: 画 | D11: 受注一覧 | K11: 担当 | V11: T | W11: 得意先担当 | AF11: 担当 | AQ11: 受注時点の得意先担当
A12: 4 | C12: 画 | D12: 受注一覧 | K12: 得意先名 | V12: T | W12: 得意先 | Z12: Web取引先マスタ | AF12: 得意先名 | AJ12: 取引先名
A13: 5 | C13: 画 | D13: 受注一覧 | K13: 担当者名 | V13: T | W13: 担当 | AF13: 担当者名
A14: 6 | C14: 画 | D14: 受注一覧 | K14: 注文書NO | V14: T | W14: Web受注明細 | AF14: 注文書NO
A15: 7 | C15: 画 | D15: 受注一覧 | K15: 手配NO1 | V15: T | W15: Web受注明細 | AF15: 手配NO1
A16: 8 | C16: 画 | D16: 受注一覧 | K16: 不適合手配NO1 | V16: T | W16: Web受注明細 | AF16: 不適合手配NO1
A17: 9 | C17: 画 | D17: 受注一覧 | K17: 注文№ | V17: T | W17: Web受注明細 | AF17: 注文№
A18: 10 | C18: 画 | D18: 受注一覧 | K18: 受注日 | V18: T | W18: Web受注明細 | AF18: 受注日
A19: 11 | C19: 画 | D19: 受注一覧 | K19: 客先納期 | V19: T | W19: Web受注明細 | AF19: 客先納期
A20: 12 | C20: 画 | D20: 受注一覧 | K20: 製品CD/品目CD | V20: T | W20: Web受注明細 | AF20: 製品CD/品目CD
A21: 13 | C21: 画 | D21: 受注一覧 | K21: 製品区分（大） | V21: T | W21: Web受注明細 | AF21: 製品区分（大）
A22: 14 | C22: 画 | D22: 受注一覧 | K22: CP品名／構成 | AF22: CP品名／構成 | AQ22: 受注区分=シート受注:構成名を表示、受注区分=シート受注以外:品名を表示
A23: 15 | C23: 画 | D23: 受注一覧 | K23: 段 | V23: T | W23: Web受注明細 | AF23: 段
A24: 16 | C24: 画 | D24: 受注一覧 | K24: 表 | V24: T | W24: Web受注明細 | AF24: 表 | AQ24: 原紙コード(表)+印刷コード(表)+エンボスコード(表)
A25: 17 | C25: 画 | D25: 受注一覧 | K25: 中 | V25: T | W25: Web受注明細 | AF25: 中 | AQ25: 原紙コード(中)+印刷コード(中)+エンボスコード(中)
A26: 18 | C26: 画 | D26: 受注一覧 | K26: 裏 | V26: T | W26: Web受注明細 | AF26: 裏 | AQ26: 原紙コード(裏)+印刷コード(裏)+エンボスコード(裏)
A27: 19 | C27: 画 | D27: 受注一覧 | K27: (構成名) | V27: T | W27: Web受注明細 | AB27: MC品目マスタ | AF27: (構成名) | AJ27: 品目名 | AQ27: 原紙名(構成名)は原紙CD+印刷CD+ｴﾝﾎﾞｽCDで品目マスタを参照した品名を表示 | BL27: 製品CDから品目名取る。
A28: 20 | C28: 画 | D28: 受注一覧 | K28: 全判寸法（巾・流れ） | V28: T | W28: Web受注明細 | AF28: 全判寸法（巾・流れ）
A29: 21 | C29: 画 | D29: 受注一覧 | K29: ｽﾘｯﾀｰ寸法（巾・流れ） | V29: T | W29: Web受注明細 | AF29: ｽﾘｯﾀｰ寸法（巾・流れ）
A30: 22 | C30: 画 | D30: 受注一覧 | K30: 数量単位 | V30: T | W30: Web受注明細 | AF30: 数量単位
A31: 23 | C31: 画 | D31: 受注一覧 | K31: 数量 | V31: T | W31: Web受注明細 | AF31: 数量
A32: 24 | C32: 画 | D32: 受注一覧 | K32: 個別単価 | V32: T | W32: Web受注明細 | AF32: 個別単価
A33: 25 | C33: 画 | D33: 受注一覧 | K33: セット単価 | V33: T | W33: Web受注明細 | AF33: セット単価
A34: 26 | C34: 画 | D34: 受注一覧 | K34: 単価単位 | V34: T | W34: Web受注明細 | AF34: 単価単位
A35: 27 | C35: 画 | D35: 受注一覧 | K35: 受注金額 | V35: T | W35: Web受注明細 | AF35: 受注金額
A36: 28 | C36: 画 | D36: 受注一覧 | K36: 預り売上 | V36: T | W36: Web受注明細 | AF36: 預り売上
A37: 29 | C37: 画 | D37: 受注一覧 | K37: 伝票備考 | V37: T | W37: Web受注明細 | AF37: 伝票備考
A38: 30 | C38: 画 | D38: 受注一覧 | K38: 納入備考 | V38: T | W38: Web受注明細 | AF38: 納入備考
A39: 31 | C39: 画 | D39: 受注一覧 | K39: WEB受注NO/WEB受注明細NO | V39: T | W39: Web受注明細 | AF39: WEB受注NO/WEB受注明細NO

Sheet 更新入出力仕様
A1: =表紙!A54 -> Webシステム | K1: 文書名 | U1: モジュールID | Z1: =表紙!$AJ$63 -> MS | AE1: モジュール名 | AJ1: =表紙!$AX$63 -> Webシステム | AS1: 文書番号 | AZ1: Version | BF1: Rev.
K2: =表紙!O64 -> アドオン設計書 | U2: ｻﾌﾞﾓｼﾞｭｰﾙID | Z2: =表紙!$AJ$64 -> MSBB | AE2: ｻﾌﾞﾓｼﾞｭｰﾙ名 | AJ2: =表紙!$AX$64 -> 販売Webシステム | AS2: =表紙!$BL$64 -> M7-US-1140 | AZ2: =表紙!$BU$64 -> 7.0.2 | BF2: =表紙!$CB$64 -> 2
K3: =RIGHT(CELL("filename",$A$1),LEN(CELL("filename",$A$1))-FIND("]",CELL("filename",$A$1))) -> 更新入出力仕様 | U3: 表題 | Z3: =表紙!$AJ$65 -> MSBBPA080 | AE3: =表紙!$AQ$65 -> Web受注一覧照会
A5: No | G5: 1 | S5: ロジック名称 | AH5: 備考
A6: 処理分類 | E6: 更新
A7: No | C7: 転送先 | V7: 転送元 | AQ7: 説明
C8: 種 | D8: オブジェクト | K8: 項目名 | V8: 種 | W8: オブジェクト | AF8: 項目名

Sheet ファイル入出力仕様
A1: =表紙!A54 -> Webシステム | K1: 文書名 | U1: モジュールID | Z1: =表紙!$AJ$63 -> MS | AE1: モジュール名 | AJ1: =表紙!$AX$63 -> Webシステム | AS1: 文書番号 | AZ1: Version | BF1: Rev.
K2: =表紙!O64 -> アドオン設計書 | U2: ｻﾌﾞﾓｼﾞｭｰﾙID | Z2: =表紙!$AJ$64 -> MSBB | AE2: ｻﾌﾞﾓｼﾞｭｰﾙ名 | AJ2: =表紙!$AX$64 -> 販売Webシステム | AS2: =表紙!$BL$64 -> M7-US-1140 | AZ2: =表紙!$BU$64 -> 7.0.2 | BF2: =表紙!$CB$64 -> 2
K3: =RIGHT(CELL("filename",$A$1),LEN(CELL("filename",$A$1))-FIND("]",CELL("filename",$A$1))) -> ファイル入出力仕様 | U3: 表題 | Z3: =表紙!$AJ$65 -> MSBBPA080 | AE3: =表紙!$AQ$65 -> Web受注一覧照会
A5: NO | G5: 1 | S5: ロジック名称 | Z5: ファイル出力 | AH5: 備考
A6: 処理分類 | E6: ファイル出力 | S6: ソート順
A7: NO | C7: 転送先 | V7: 転送元 | AQ7: 説明
C8: 種 | D8: オブジェクト | K8: 項目名 | V8: 種 | W8: オブジェクト | AF8: 項目名
A9: 1 | C9: フ | D9: 受注一覧 | K9: NO | V9: 画 | W9: 受注一覧 | AF9: NO
A10: 2 | C10: フ | D10: 受注一覧 | K10: 得意先 | V10: 画 | W10: 受注一覧 | AF10: 得意先
A11: 3 | C11: フ | D11: 受注一覧 | K11: 担当 | V11: 画 | W11: 受注一覧 | AF11: 担当
A12: 4 | C12: フ | D12: 受注一覧 | K12: 得意先名 | V12: 画 | W12: 受注一覧 | AF12: 得意先名
A13: 5 | C13: フ | D13: 受注一覧 | K13: 担当者名 | V13: 画 | W13: 受注一覧 | AF13: 担当者名
A14: 6 | C14: フ | D14: 受注一覧 | K14: 注文書NO | V14: 画 | W14: 受注一覧 | AF14: 注文書NO
A15: 7 | C15: フ | D15: 受注一覧 | K15: 手配NO1 | V15: 画 | W15: 受注一覧 | AF15: 手配NO1
A16: 8 | C16: フ | D16: 受注一覧 | K16: 不適合手配NO1 | V16: 画 | W16: 受注一覧 | AF16: 不適合手配NO1
A17: 9 | C17: フ | D17: 受注一覧 | K17: 注文№ | V17: 画 | W17: 受注一覧 | AF17: 注文№
A18: 10 | C18: フ | D18: 受注一覧 | K18: 受注日 | V18: 画 | W18: 受注一覧 | AF18: 受注日
A19: 11 | C19: フ | D19: 受注一覧 | K19: 客先納期 | V19: 画 | W19: 受注一覧 | AF19: 客先納期
A20: 12 | C20: フ | D20: 受注一覧 | K20: 製品CD/品目CD | V20: 画 | W20: 受注一覧 | AF20: 製品CD/品目CD
... A22: 14 | C22: フ | D22: 受注一覧 | K22: CP品名／構成 | V22: 画 | W22: 受注一覧 | AF22: CP品名／構成
A23: 15 | C23: フ | D23: 受注一覧 | K23: 段 | V23: 画 | W23: 受注一覧 | AF23: 段 | BL23: 指摘ＣＰ 2022/10/18 玉置 項目の確認 項目長が問題ですがコードと構成名の 併記がベストと考えます。 | CM23: MDSOL 野村 2022/10/25 原紙コード+印刷コード+エンボスコード、原紙構成名を出力します | DQ23: 2022/10/27 玉置 問題なし
A24: 16 | C24: フ | D24: 受注一覧 | K24: 表 | V24: 画 | W24: 受注一覧 | AF24: 表 | CM24: ※レイアウト変更しております
A25: 17 | C25: フ | D25: 受注一覧 | K25: 中 | V25: 画 | W25: 受注一覧 | AF25: 中
A26: 18 | C26: フ | D26: 受注一覧 | K26: 裏 | V26: 画 | W26: 受注一覧 | AF26: 裏
A27: 19 | C27: フ | D27: 受注一覧 | K27: (構成名) | V27: 画 | W27: 受注一覧 | AF27: (構成名)
A28: 20 | C28: フ | D28: 受注一覧 | K28: 全判寸法（巾・流れ） | V28: 画 | W28: 受注一覧 | AF28: 全判寸法（巾・流れ）
A29: 21 | C29: フ | D29: 受注一覧 | K29: ｽﾘｯﾀｰ寸法（巾・流れ） | V29: 画 | W29: 受注一覧 | AF29: ｽﾘｯﾀｰ寸法（巾・流れ）
A30: 22 | C30: フ | D30: 受注一覧 | K30: 数量単位 | V30: 画 | W30: 受注一覧 | AF30: 数量単位
A31: 23 | C31: フ | D31: 受注一覧 | K31: 数量 | V31: 画 | W31: 受注一覧 | AF31: 数量
A32: 24 | C32: フ | D32: 受注一覧 | K32: 個別単価 | V32: 画 | W32: 受注一覧 | AF32: 個別単価
A33: 25 | C33: フ | D33: 受注一覧 | K33: セット単価 | V33: 画 | W33: 受注一覧 | AF33: セット単価
A34: 26 | C34: フ | D34: 受注一覧 | K34: 単価単位 | V34: 画 | W34: 受注一覧 | AF34: 単価単位
A35: 27 | C35: フ | D35: 受注一覧 | K35: 受注金額 | V35: 画 | W35: 受注一覧 | AF35: 受注金額
A36: 28 | C36: フ | D36: 受注一覧 | K36: 預り売上 | V36: 画 | W36: 受注一覧 | AF36: 預り売上
... A39: 31 | C39: フ | D39: 受注一覧 | K39: WEB受注NO/WEB受注明細NO | V39: 画 | W39: 受注一覧 | AF39: WEB受注NO/WEB受注明細NO

Sheet 画面遷移
A1: =表紙!A54 -> Webシステム | K1: 文書名 | U1: モジュールID | Z1: =表紙!$AJ$63 -> MS | AE1: モジュール名 | AJ1: =表紙!$AX$63 -> Webシステム | AS1: 文書番号 | AZ1: Version | BF1: Rev.
K2: =表紙!O64 -> アドオン設計書 | U2: ｻﾌﾞﾓｼﾞｭｰﾙID | Z2: =表紙!$AJ$64 -> MSBB | AE2: ｻﾌﾞﾓｼﾞｭｰﾙ名 | AJ2: =表紙!$AX$64 -> 販売Webシステム | AS2: =表紙!$BL$64 -> M7-US-1140 | AZ2: =表紙!$BU$64 -> 7.0.2 | BF2: =表紙!$CB$64 -> 2
K3: =RIGHT(CELL("filename",$A$1),LEN(CELL("filename",$A$1))-FIND("]",CELL("filename",$A$1))) -> 画面遷移 | U3: 表題 | Z3: =表紙!$AJ$65 -> MSBBPA080 | AE3: =表紙!$AQ$65 -> Web受注一覧照会
A5: 画面遷移フロー図
A6: ＩＤ | C6: S01 | E6: Web受注一覧照会から他画面の画面遷移
D9: NO2
D10: Web製品マスタ一覧照会 | AI10: NO1
AI11: Web受注入力
R12: Web受注一覧照会 | AI12: 1ページ目
X13: 受注詳細ボタン押下
D15: NO3
D16: Web取引先一覧照会
D20: NO4
D21: Web汎用検索(共通検索)
A27: ID | D27: 処理名
A28: S01 | D28: Web受注一覧照会から他画面の画面遷移
B30: NO | D30: 遷移元ＩＤ | H30: 遷移元画面名 | Q30: 遷移先ＩＤ | V30: 遷移先画面名 | AE30: 目的 | AJ30: 引継項目 | AS30: 遷移後のアクション(遷移先) | BC30: 戻り値 | BL30: 戻り値取得後のアクション(遷移元) | BV30: 備考
B31: 1 | D31: MSBBPA080 | H31: Web受注一覧照会 | Q31: MSBBPA070 | V31: Web受注入力 | AE31: 参照 | AJ31: WEB受注NO/WEB受注明細NO | AS31: 検索 | BV31: 操作種別:参照、データ参照
B32: 2 | D32: MSBBPA080 | H32: Web受注一覧照会 | Q32: MSBBPA060 | V32: Web製品マスタ一覧照会 | AE32: 検索結果取得 | AS32: 検索 | BC32: 製品マスタ選択データ(1行) | BL32: 対象データに値セット | BV32: セット製品CD、セット品名に値セット
B33: 2' | D33: MSBBPA080 | H33: Web受注一覧照会 | Q33: MSBBPA060 | V33: Web製品マスタ一覧照会 | AE33: 検索結果取得 | AS33: 検索 | BC33: 製品マスタ選択データ(1行) | BL33: 対象データに値セット | BV33: 製品CD、製品名(CP品名1+2)に値セット
B34: 3 | D34: MSBBPA080 | H34: Web受注一覧照会 | Q34: MSBBPA120 | V34: Web取引先一覧照会 | AE34: 検索結果取得 | AJ34: 得意先ＦＬＧ=1 | AS34: 検索 | BC34: 取引先選択データ(1行) | BL34: 対象データに値セット | BV34: 得意先CD、得意先名に値セット
B35: 4 | D35: MSBBPA080 | H35: Web受注一覧照会 | Q35: MSBBPA900 | V35: Web汎用検索(共通検索) | AE35: 検索結果取得 | AS35: 検索 | BC35: 各種検索画面の選択データ(1行) | BL35: 対象データに値セット | BV35: CD、名称に値セット
B36: 5
B37: 6
B38: 7
B39: 8

Sheet メッセージ一覧
A1: =表紙!A54 -> Webシステム | K1: 文書名 | U1: モジュールID | Z1: =表紙!$AJ$63 -> MS | AE1: モジュール名 | AJ1: =表紙!$AX$63 -> Webシステム | AS1: 文書番号 | AZ1: Version | BF1: Rev.
K2: =表紙!O64 -> アドオン設計書 | U2: ｻﾌﾞﾓｼﾞｭｰﾙID | Z2: =表紙!$AJ$64 -> MSBB | AE2: ｻﾌﾞﾓｼﾞｭｰﾙ名 | AJ2: =表紙!$AX$64 -> 販売Webシステム | AS2: =表紙!$BL$64 -> M7-US-1140 | AZ2: =表紙!$BU$64 -> 7.0.2 | BF2: =表紙!$CB$64 -> 2
K3: =RIGHT(CELL("filename",$A$1),LEN(CELL("filename",$A$1))-FIND("]",CELL("filename",$A$1))) -> メッセージ一覧 | U3: 表題 | Z3: =表紙!$AJ$65 -> MSBBPA080 | AE3: =表紙!$AQ$65 -> Web受注一覧照会
C4: ↓アドオン画面のため、基本全て[新]
A5: No | C5: 新/変 | E5: 種別 | G5: メッセージ内容 | AQ5: 備考（パラメータ等） | BG5: メッセージID
A6: 1 | C6: 新 | E6: W | G6: 「FROM≦TOの関係で指定してください。」 | AQ6: 受注日、客先納期、手配NO、WEB受注NO | BG6: E10036
AQ7: 数量、金額
A10: 2 | C10: 新 | E10: W | G10: 「検索結果がありません。」 | BG10: E10008
A11: 3 | C11: 新 | E11: W | G11: 「発行対象がありません。」 | BG11: E10010
A12: 4 | C12: 新 | E12: W | G12: 「選択行がありません。」 | BG12: E10009
A13: 5 | C13: 新 | E13: W | G13: 「検索件数の上限値を超えました。(設定値) \n 抽出条件を設定し、再度検索・照会を実施ください。」 | BG13: E10013
A14: 6 | C14: 新 | E14: I | G14: 「検索件数の上限値を超えました。(設定値) \n 処理を続ける場合は、[はい]を選択してください。」 | BG14: C00006

Sheet 補足説明資料
A1: =表紙!A54 -> Webシステム | O1: 文書名 | AC1: モジュールID | AJ1: =表紙!AJ64 -> MSBB | AQ1: モジュール名 | AX1: =表紙!AX64 -> 販売Webシステム | BL1: 文書番号 | BU1: Version | CB1: Rev.
O2: =表紙!O65 -> 表紙 | AC2: サブモジュールID | AJ2: =表紙!AJ65 -> MSBBPA080 | AQ2: サブモジュール名 | AX2: =表紙!AX65 -> 0 | BL2: =表紙!BL65 -> 0 | BU2: =表紙!BU65 -> 0 | CB2: =表紙!CB65 -> 0
O3: =RIGHT(CELL("filename",$A$1),LEN(CELL("filename",$A$1))-FIND("]",CELL("filename",$A$1))) -> 補足説明資料 | AC3: 表題 | AJ3: =表紙!AJ66 -> 0 | AQ3: =表紙!AQ66 -> 0
AO5: 補足説明
