Workbook
Name Rev.: 表紙!$U$22
Name Revision: [2]表紙!$AP$5
Name Ver.: 表紙!$AE$26
Name ご確認者: 表紙!$AG$40
Name ご確認日: 表紙!$AG$42
Name サブシステム名: 表紙!$U$28
Name システム名: 表紙!$U$26
Name プロジェクト名: 表紙!$U$18
Name 開発区分: 表紙!$U$36
Name 機能ＩＤ: 表紙!$U$32
Name 機能区分: 表紙!$U$34
Name 機能名称: 表紙!$U$30
Name 顧客名: 表紙!$U$16
Name 最終更新者: 表紙!$AB$40
Name 最終更新日: 表紙!$AB$42
Name 作成者: 表紙!$W$40
Name 作成日: 表紙!$W$42
Name 章: 表紙!$M$10
Name 発行日: [2]表紙!$W$42
Name 文書番号: [2]表紙!$O$5
Name 文書名: 表紙!$M$10

Sheet 目次
A1: アドオン設計書作成ガイド
C3: ■アドオン設計と成果物について
D4: ・システム設計フェーズとソフトウェア設計フェーズでアドオンの処理仕様を定義する
D5: ・システム設計フェーズとソフトウェア設計フェーズの成果物がアドオン設計書であり、ソフトウェア製作フェーズのインプットとなる
C7: ■各設計フェーズ毎のアドオン設計書作成範囲
D8: ・システム設計フェーズ：他機能との関連を定義するとともに、画面や帳票、ファイル入出力を中心とした外部入出力の設計を行う
D9: ・ソフトウェア設計フェーズ：内部処理を中心とした設計を行う
U11: ◎ | W11: … | X11: システム設計フェーズで作成
U12: ○ | W12: … | X12: システム設計フェーズで基本仕様を定義して、ソフトウェア設計フェーズで詳細化する
U13: △ | W13: … | X13: 必要に応じて（例えば標準仕様から変更がない場合は不要）
U14: ‐ | W14: … | X14: 不要
W15: … | X15: ソフトウェア設計フェーズで作成
D17: 各設計書と作成対象シートのマトリックス | S17: ※カスタマイズ：標準機能に機能を追加する アドオン：新規で機能を開発する
D18: EXCELシート | N18: 画面設計書 | W18: バッチ設計書 | AF18: 帳票設計書 | AO18: ＢＩ設計書 | AT18: .Net設計書 | BB18: EXCELシート | BL18: WebDB設計書 | BR18: 帳票設計書 | BX18: 汎用申請設計書
N19: カスタマイズ | S19: アドオン | W19: カスタマイズ | AB19: アドオン | AF19: カスタマイズ | AK19: アドオン | AO19: アドオン | AT19: アドオン | BL19: アドオン | BR19: アドオン | BX19: アドオン
D20: 概要 | N20: ◎ | O20: ※1 | S20: ◎ | W20: ◎ | X20: ※1 | AB20: ◎ | AF20: ◎ | AG20: ※1 | AK20: ◎ | AO20: ◎ | AT20: ◎ | BB20: 機能概要 | BL20: ◎ | BR20: ◎ | BX20: ◎
D21: レイアウト | N21: ◎ | O21: ※2 | S21: ◎ | W21: ‐ | AB21: ‐ | AF21: ◎ | AG21: ※2 | AK21: ◎ | AO21: ◎ | AT21: ◎ | BB21: アプリケーションフロー | BL21: ◎ | BR21: ー | BX21: ◎
D22: 項目説明 | N22: △ | S22: ○ | W22: ‐ | AB22: ‐ | AF22: △ | AK22: ○ | AO22: ○ | AT22: ○ | BB22: データベース設定 | BL22: ◎ | BR22: ー | BX22: ◎
D23: 引数説明 | N23: ‐ | S23: ‐ | W23: △ | AB23: ◎ | AF23: ‐ | AK23: ‐ | AO23: ‐ | AT23: ◎ | BB23: フィールド設定 | BL23: ◎ | BR23: ー | BX23: ◎
D24: 処理概要 | N24: ◎ | S24: ◎ | W24: ◎ | AB24: ◎ | AF24: ◎ | AK24: ◎ | AO24: ◎ | AT24: ◎ | BB24: 一覧表示画面設定 | BL24: ◎ | BR24: ー | BX24: ◎
D25: 処理詳細 | BB25: 表示編集画面設定 | BL25: ◎ | BR25: ー | BX25: ◎
D26: 処理・サービス関連図 | N26: △ | S26: ◎ | W26: △ | AB26: ◎ | AF26: ‐ | AK26: ‐ | AO26: ‐ | AT26: ◎ | BB26: 明細画面設定 | BL26: △ | BN26: ※3 | BR26: ー | BX26: △ | BZ26: ※3
D27: 検索入出力仕様 | N27: △ | S27: ○ | W27: △ | AB27: ○ | AF27: ‐ | AK27: ‐ | AO27: ‐ | AT27: ○ | BB27: 集計表示設定 | BL27: △ | BN27: ※4 | BR27: ー | BX27: △ | BZ27: ※4
D28: 更新入出力仕様 | N28: △ | S28: ○ | W28: △ | AB28: ○ | AF28: ‐ | AK28: ‐ | AO28: ‐ | AT28: ○ | BB28: 絞り込み条件設定 | BL28: △ | BN28: ※5 | BR28: ー | BX28: △ | BZ28: ※5
D29: ファイル入出力仕様 | N29: △ | S29: △ | W29: ‐ | AB29: ‐ | AF29: ‐ | AK29: ‐ | AO29: ‐ | AT29: △ | BB29: その他設定 | BR29: ー
D30: 画面遷移 | N30: △ | S30: ◎ | W30: ‐ | AB30: ‐ | AF30: ‐ | AK30: ‐ | AO30: ‐ | AT30: ◎ | BB30: 帳票イメージ | BL30: ー | BR30: ◎ | BX30: ー
D31: メッセージ一覧 | N31: △ | S31: △ | W31: △ | AB31: △ | AF31: ‐ | AK31: ‐ | AO31: ‐ | AT31: △ | BB31: 項目設計 | BL31: ー | BR31: ◎ | BX31: ー
D32: 補足説明 | N32: △ | S32: △ | W32: △ | AB32: △ | AF32: △ | AK32: △ | AO32: △ | AT32: △ | BB32: 補足説明 | BL32: △ | BR32: △ | BX32: △
D33: サービス呼出編集仕様 | N33: - | S33: - | W33: - | AB33: - | AF33: - | AK33: - | AO33: - | AT33: - | BB33: 補足説明(詳細)
D35: ※1 | G35: 別シートでカスタマイズ内容を記載する | BB35: ※3 | BE35: 単票画面は記載しない
D36: ※2 | G36: 吹き出しでカスタマイズ内容を記載する | BB36: ※4 | BE36: 集計・グラフ機能を使用する場合に記載する
BB37: ※5 | BE37: 共通設定のみ記載する(個別設定は、記載しない)

Sheet 表紙
AW2: サブモジュール
AW3: MA_マスタ管理
AW4: MB_業務共通
AW5: MG_原価管理
AW6: MSBA_需給管理
M7: 基本設計 | AW7: MSBB_販売管理
AW8: MSBC_生産管理
AW9: MSBD_購買管理
M10: アドオン設計書 | AW10: MSBE_在庫物流管理
AW11: MSBF_品質管理
AW12: MSBG_債権管理
AW13: MSBH_債務管理
AW14: MSBI_締処理
AW15: MSUA_リスト・入力補助
M16: 顧客 | U16: 株式会社クラウン・パッケージ | AW16: PF_ESBアダプタ
M18: プロジェクト名 | U18: 基幹システム刷新PJ | AW18: 機能区分
AW19: 画面
M20: 文書番号 | AW20: 帳票
AW21: バッチ
M22: Ｒｅｖ． | U22: {=MAX(_xlfn.NUMBERVALUE(改訂!A7:E48))} -> 2 | AW22: マスタ
M24: 機密性区分 | U24: 取扱注意（Ｃ） | AW24: 開発区分
AW25: カスタマイズ
M26: システム名 | U26: Webシステム | AC26: Ver. | AE26: 7.0.2 | AW26: アドオン
AW27: －
M28: サブモジュール | U28: MSBB_販売管理
M30: 機能名 | U30: =M50 -> Web版型・木型マスタ一覧照会
M32: 機能ID | U32: =G50 -> MSBBPA150
M34: 機能区分 | U34: 画面
M36: 開発区分 | U36: アドオン
W39: 作成 | AB39: 最終更新 | AG39: ご確認
W40: MDSOL
W42: 44805
A48: 文書番号 | G48: 画面ID | M48: 画面名 | V48: Version | AB48: Revision
A50: M7-US-1140 | G50: MSBBPA150 | M50: Web版型・木型マスタ一覧照会 | V50: 1.0.0 | AB50: r01.00
A53: 共通（元データ）
A54: Webシステム | K54: 文書名 | U54: モジュールID | Z54: MS | AE54: モジュール名 | AJ54: Webシステム | AS54: 文書番号 | AZ54: Version | BF54: Rev.
K55: 画面説明書 | U55: ｻﾌﾞﾓｼﾞｭｰﾙID | Z55: MSBB | AE55: ｻﾌﾞﾓｼﾞｭｰﾙ名 | AJ55: 販売Webシステム | AS55: M7-US-1140 | AZ55: 1.0.0 | BF55: r00.00
K56: 表紙 | U56: 表題 | Z56: MSBBPA150 | AE56: Web版型・木型マスタ一覧照会
A57: 共通（リンク用）
A58: =A54 -> Webシステム | K58: 文書名 | U58: モジュールID | Z58: =Z54 -> MS | AE58: モジュール名 | AJ58: =AJ54 -> Webシステム | AS58: 文書番号 | AZ58: Version | BF58: Rev.
...

Sheet 改訂
K1: 改訂 | AU1: 作成者 | AZ1: MDSOL | BE1: 作成日 | BJ1: =表紙!W42 -> 44805 | BP1: Rev.
AU2: 修正者 | AZ2: MDSOL | BE2: 改訂日 | BJ2: 44894 | BP2: =表紙!CB64 -> 2
A5: Rev. | F5: 改定内容 | BC5: 頁 | BM5: 変更日 変更者 | BR5: 確認日 確認者
A7: 1 | F7: 新規作成 | BM7: 44865
BM8: MDSOL
A9: 2 | F9: 最終使用実績日の追加 | BC9: 画面イメージ、項目説明 処理・サービス関連図 検索・ファイル入出力仕様 | BM9: 44894
BM10: MDSOL
A11: 2 | F11: 案件NOをDBの項目は、案件NO(親)＋案件NO(子)＋案件NO(部材)に分割する ※画面項目は、1つとする | BC11: 検索入出力仕様 | BM11: 44894
BM12: MDSOL
A13: 2 | F13: 詳細設計の追加 | BC13: 画面遷移 処理詳細 | BM13: 44902
BM14: TBK華
A15: 2 | F15: メッセージIDの採番 | BC15: メッセージ一覧 | BM15: 44931
BM16: TBK華
A17: 2 | F17: 画面項目制御シート追加 | BC17: 画面項目制御 | BM17: 44966
BM18: TBK徐

Sheet 概要
A1: =表紙!A54 -> Webシステム | O1: 文書名 | AC1: モジュールID | AJ1: =表紙!AJ63 -> MS | AQ1: モジュール名 | AX1: =表紙!AX63 -> Webシステム | BL1: 文書番号 | BU1: Version | CB1: Rev.
O2: =表紙!O64 -> アドオン設計書 | AC2: サブモジュールID | AJ2: =表紙!AJ64 -> MSBB | AQ2: サブモジュール名 | AX2: =表紙!AX64 -> 販売Webシステム | BL2: =表紙!BL64 -> M7-US-1140 | BU2: =表紙!BU64 -> 1.0.0 | CB2: =表紙!CB64 -> 2
O3: =RIGHT(CELL("filename",$A$1),LEN(CELL("filename",$A$1))-FIND("]",CELL("filename",$A$1))) -> 概要 | AC3: 表題 | AJ3: =表紙!AJ65 -> MSBBPA150 | AQ3: =表紙!AQ65 -> Web版型・木型マスタ一覧照会
AO5: 概要
B7: 【説明】
C8: 版型・木型マスタ一覧照会画面
B10: 【目的】
C11: 版型・木型マスタを一覧照会する
B13: 【処理関連図/サービス関連図】
C14: ※処理・サービス関連図シートに詳細記載
B16: 【オペレーション一覧】
C17: 版型・木型マスタの検索・照会処理を行う
C18: 版型・木型ラベルの帳票発行(ラベル発行)を行う
C19: 版型・木型マスタのCSV出力を行う
B21: 【SQLID一覧】
C22: なし
B24: 【ソート順】
C25: 版型・木型NO、Rev
B27: 【データアクセスコントロール】
C28: 拠点による制御
C29: ※詳細は、【MSBBPA000】_共通設計書_アドオン(Webシステム共通仕様)にて定義
B31: 【自由記述】
C32: なし

Sheet 画面イメージ
A1: =表紙!A54 -> Webシステム | K1: 文書名 | U1: モジュールID | Z1: =表紙!$AJ$63 -> MS | AE1: モジュール名 | AJ1: =表紙!$AX$63 -> Webシステム | AS1: 文書番号 | AZ1: Version | BF1: Rev.
K2: =表紙!O64 -> アドオン設計書 | U2: ｻﾌﾞﾓｼﾞｭｰﾙID | Z2: =表紙!$AJ$64 -> MSBB | AE2: ｻﾌﾞﾓｼﾞｭｰﾙ名 | AJ2: =表紙!$AX$64 -> 販売Webシステム | AS2: =表紙!$BL$64 -> M7-US-1140 | AZ2: =表紙!$BU$64 -> 1.0.0 | BF2: =表紙!$CB$64 -> 2
K3: =RIGHT(CELL("filename",$A$1),LEN(CELL("filename",$A$1))-FIND("]",CELL("filename",$A$1))) -> 画面イメージ | U3: 表題 | Z3: =表紙!$AJ$65 -> MSBBPA150 | AE3: =表紙!$AQ$65 -> Web版型・木型マスタ一覧照会
A5: 画面イメージ
B7: ≫凡例
Q8: ・・・ | S8: ボタン
C9: 見積計算書NO | Q9: ・・・ | S9: 検索項目(検索画面表示選択) | AJ9: 参照情報
C10: 品名 | Q10: ・・・ | S10: 入力項目
C11: 得意先 | Q11: ・・・ | S11: 表示項目(得意先名称、原紙名等) | AJ11: 担当者
C12: 操作種別 | I12: ●登録 | M12: ○訂正 | Q12: ・・・ | S12: 選択項目(一つのみ選択可能)
C13: 受注区分 | Q13: ・・・ | S13: 選択項目(一つのみ選択可能)
C14: 作業順 | I14: ☑AAA | M14: ☑BBB | Q14: ・・・ | S14: 選択項目(複数選択可能)
C16: 見積作成日 | Q16: ・・・ | S16: カレンダー形式
BO21: －
BW22: CP指摘事項 2022/09/21 土屋 案件Noで検索出来ると良いお思います | DT22: MDSOL 野村 2022/10/25 見積計算書NOに紐づく案件NOを抽出条件として、追加します。 | EU22: 2022/10/27 落合 問題なし
D23: 拠点 | AC23: 担当者 | BB23: * | BC23: あいまい検索可能
BW24: CP指摘事項 2022/09/22 三宅 検索条件が多すぎて一覧表示画面が小さくなるのである程度絞っても良いかも またはよく使うものを表示して細かい条件は折り畳み表示が必要かも | DT24: MDSOL 野村 2022/10/25 あいまい検索は、部分一致の検索となります。(文字の全角と半角、大文字と小文字は区別されます。スペース区切りの複数指定はできません。)
D25: 適用開始日 | O25: ~ | AC25: 手配NO | AN25: * | AP25: 案件No | AV25: 9999999-999-999 | BC25: (案件No親/子/部材) | BX25: この「* あいまい検索可能」とはどういう意味でしょうか | EB25: 版型名と手配NOがあいまい検索対象です
D26: 版型NO | O26: ~ | AC26: 版型名称 | AN26: * | BX26: 一般的な用法の、文字列の全角と半角、大文字と小文字などの表記ゆれを区別せずに検索できるという理解で正しいでしょうか？ | EB26: 対象は、項目説明に「あいまい検索可」をつけるようにしています。 | EU26: CP指摘 2022/10/27 落合 大文字・小文字は区別せず検索できないか？ その他は問題なし
D27: 版型分類 | AC27: 新版区分 | BX27: Elasticsearch等全文検索エンジンを使用？Oracleの機能プラス形態素解析やN-gram併用？ | EV27: MDSOL 野村 2022/10/31 WEBだけの変更であれば可能です。ただし、mcframe7でも大文字と小文字は区別されます。挙動をmcframe7と合わせたいと思いますが、いかがでしょうか。
D28: 得意先 | BX28: 実装方法は不明ですが追加の仕様策定が必要ではないでしょうか？
D29: 代表製品CD | BX29: そもそも検索対象に版型名や備考欄が無いのであいまい検索を適用する箇所が無いのでは | FE29: mcframe7：メニュー検索等の一部を除いて基本大文字と小文字は区別されます。
FF30: 2022/11/01 落合 webだけでもやってください
D31: 工程 | AC31: 通し数 | AN31: ~ | BW31: CP指摘事項 2022/09/22 三宅 | FG31: MDSOL 野村 2022/11/02 承知しました。 | FX31: 2022/11/04 落合 問題なし
D32: 発注先 | AC32: 限界通し数 | AN32: ~ | BX32: ものすごい幅の長いテーブルになりそうだと心配しましたが、ComponentOneを使うらしいので、コンポーネントの一種 FlexGrid のデモを見たところ列の表示非表示の切替えや折り畳み表示列が作れるので適宜調整可能で見づらい問題はなさそうです | FO32: 共通仕様に明記します。
D33: 場所 | AC33: 棚・ライン | BX33: https://demo.grapecity.com/c1/aspnet/MvcExplorer/FlexGrid/ShowCase
BX34: FlexGrid はかなり高度なことが出来るので、機能のどこまでを実装するかについては版型一覧画面に限らず決めておく必要がありそうです | DT34: MDSOL 野村 2022/10/25
D35: 最終使用実績日 | O35: ~ | X35: Rev2.0 追加
D36: 入荷日 | O36: ~ | AC36: 廃棄予定日 | AN36: ~ | BX36: 可能なら列の表示非表示切替・ソート・フィルター・エクスポートはどの一覧画面にも実装してほしいです | DU36: 現行想定は、一覧照会はMultiRowを使用する想定です。 | EU36: CP指摘 2022/10/27 落合 Multirowの標準機能でソート・エクスポートは可能と思います。
D37: 返却予定日 | O37: ~ | AC37: 返却日 | AN37: ~ | DU37: 基本は全項目ソート可能としたいですが、開発時、レスポンスなどを加味したうえで相談させてください。 | EW37: MDSOL 野村 2022/10/31 エクスポート追加します。
FE38: CSV出力と機能重複しますが、両方必要でしょうか。
D39: 対象 | J39: ☑最新Revのみ表示 | DU39: 列の表示非表示の切替えや折り畳み表示列の機能に関して | EX39: 2022/11/01 csv出力のみで結構です。
DV40: 現行は、実装を想定していないです。 | EY40: MDSOL 野村 2022/11/02 承知しました。
AY41: Rev2.0 追加 | DV41: プラスで条件の保存機能が必要になるのではと考えます。 | EY41: 2022/11/04 落合 問題なし
D42: NO | F42: 発行 | H42: 版型NO | M42: 版型名 | T42: Rev | V42: 版型分類 | Y42: 得意先 | AB42: 得意先名 | AF42: 製品コード | AK42: 製品名 | AQ42: 通し数 | AU42: 限界通し数 | AY42: 最終使用実績日 | BD42: 発注先 | BG42: 発注先名 | BK42: 入荷日 | BP42: 廃棄予定日 | BU42: 返却予定日 | BZ42: 返却日 | CE42: 返却理由
D44: 1 | F44: ☑ | H44: X/999991 | M44: XXXXXXX8XXXXXXX8 | U44: 1 | V44: 木型 | Y44: 12345 | AB44: XXXXXXX8 | AF44: 99999999-01 | AK44: 品名１＋品名２ | AQ44: 1000 | AU44: 1000 | AY44: 2022/07/01 | BD44: 12345 | BG44: XXXXXXX8 | BK44: 2022/07/01 | BP44: 2022/07/01 | BU44: 2022/07/01 | BZ44: 2022/07/01 | DJ44: CP指摘 2022/10/27 落合 版型名までを固定表示し、以降の項目をスクロールにして欲しい
D45: 2 | F45: ☑ | H45: X/999992 | M45: XXXXXXX8XXXXXXX8 | U45: 2 | V45: 木型 | Y45: 12345 | AB45: XXXXXXX8 | AF45: 99999999-02 | AK45: 品名１＋品名２ | AQ45: 1000 | AU45: 1000 | AY45: 2022/07/01 | BD45: 12345 | BG45: XXXXXXX8 | BK45: 2022/07/01 | BP45: 2022/07/01 | BU45: 2022/07/01 | BZ45: 2022/07/01 | DK45: MDSOL 野村 2022/10/31 セル固定をレイアウトに明記しました。
D46: 3 | F46: ☑ | H46: X/999993 | M46: XXXXXXX8XXXXXXX8 | U46: 3 | V46: 木型 | Y46: 12345 | AB46: XXXXXXX8 | AF46: 99999999-03 | AK46: 品名１＋品名２ | AQ46: 1000 | AU46: 1000 | AY46: 2022/07/01 | BD46: 12345 | BG46: XXXXXXX8 | BK46: 2022/07/01 | BP46: 2022/07/01 | BU46: 2022/07/01 | BZ46: 2022/07/01 | DL46: 2022/11/01 csv出力のみで結構です。
D47: 4 | F47: □ | H47: X/999994 | M47: XXXXXXX8XXXXXXX8 | U47: 4 | V47: 木型 | Y47: 12345 | AB47: XXXXXXX8 | AF47: 99999999-04 | AK47: 品名１＋品名２ | AQ47: 2000 | AU47: 2000 | AY47: 2022/07/01 | BD47: 12345 | BG47: XXXXXXX8 | BK47: 2022/07/01 | BP47: 2022/07/01 | BU47: 2022/07/01 | BZ47: 2022/07/01
D48: 5 | F48: □ | H48: X/999995 | M48: XXXXXXX8XXXXXXX8 | U48: 5 | V48: 木型 | Y48: 12345 | AB48: XXXXXXX8 | AF48: 99999999-05 | AK48: 品名１＋品名２ | AQ48: 2000 | AU48: 2000 | AY48: 2022/07/01 | BD48: 12345 | BG48: XXXXXXX8 | BK48: 2022/07/01 | BP48: 2022/07/01 | BU48: 2022/07/01 | BZ48: 2022/07/01
...

Sheet 項目説明
A1: =表紙!A54 -> Webシステム | K1: 文書名 | U1: モジュールID | Z1: =表紙!$AJ$63 -> MS | AE1: モジュール名 | AJ1: =表紙!$AX$63 -> Webシステム | AS1: 文書番号 | AZ1: Version | BF1: Rev.
K2: =表紙!O64 -> アドオン設計書 | U2: ｻﾌﾞﾓｼﾞｭｰﾙID | Z2: =表紙!$AJ$64 -> MSBB | AE2: ｻﾌﾞﾓｼﾞｭｰﾙ名 | AJ2: =表紙!$AX$64 -> 販売Webシステム | AS2: =表紙!$BL$64 -> M7-US-1140 | AZ2: =表紙!$BU$64 -> 1.0.0 | BF2: =表紙!$CB$64 -> 2
K3: =RIGHT(CELL("filename",$A$1),LEN(CELL("filename",$A$1))-FIND("]",CELL("filename",$A$1))) -> 項目説明 | U3: 表題 | Z3: =表紙!$AJ$65 -> MSBBPA150 | AE3: =表紙!$AQ$65 -> Web版型・木型マスタ一覧照会
A5: Web版型・木型マスタ一覧照会
B6: 抽出条件 | N6: 説明 | BE6: Ｗ | BF6: 型 | BG6: 参 | BH6: 必 | BI6: 入 | BJ6: 非 | BK6: 検
A7: 〇 | B7: 拠点 | M7: 【MSBBPACOM】_共通設計書_アドオン(共通ロジック)にて定義 | BE7: C | BF7: S
A8: 〇 | B8: 担当者 | M8: 【MSBBPACOM】_共通設計書_アドオン(共通ロジック)にて定義 | BE8: C | BF8: S
A9: 〇 | B9: 適用開始日(From) | M9: 抽出条件として、適用開始日(From)を入力する | BE9: カ | BF9: D
A10: 〇 | B10: 適用開始日(To) | M10: 抽出条件として、適用開始日(To)を入力する | BE10: カ | BF10: D
A11: 〇 | B11: 手配NO | M11: 抽出条件として、手配NOを入力する | AZ11: あいまい検索可 | BE11: T | BF11: S
A12: 〇 | B12: 案件NO | M12: 【MSBBPACOM】_共通設計書_アドオン(共通ロジック)にて定義 | BE12: A | BF12: S | BK12: 検
A13: 〇 | B13: 版型NO(From) | M13: 抽出条件として、版型NO(From)を入力する | BE13: T | BF13: S
A14: 〇 | B14: 版型NO(To) | M14: 抽出条件として、版型NO(To)を入力する | BE14: T | BF14: S
A15: 〇 | B15: 版型名称 | M15: 抽出条件として、版型名称を入力する | AZ15: あいまい検索可 | BE15: T | BF15: S
A16: 〇 | B16: 版型分類 | M16: 【MSBBPACOM】_共通設計書_アドオン(共通ロジック)にて定義 | BF16: S
A17: 〇 | B17: 新版区分 | M17: 【MSBBPACOM】_共通設計書_アドオン(共通ロジック)にて定義 | BF17: S
A18: 〇 | B18: 得意先 | M18: 【MSBBPACOM】_共通設計書_アドオン(共通ロジック)にて定義 | BE18: A | BF18: S | BK18: 検
A19: 〇 | B19: 代表製品CD | M19: 【MSBBPACOM】_共通設計書_アドオン(共通ロジック)にて定義 | BF19: S | BK19: 検
A20: 〇 | B20: 工程 | M20: 【MSBBPACOM】_共通設計書_アドオン(共通ロジック)にて定義 | BE20: C | BF20: S
A21: 〇 | B21: 通し数(From) | M21: 抽出条件として、通し数(From)を入力する | BE21: T | BF21: N
A22: 〇 | B22: 通し数(To) | M22: 抽出条件として、通し数(To)を入力する | BE22: T | BF22: N
A23: 〇 | B23: 発注先 | M23: 【MSBBPACOM】_共通設計書_アドオン(共通ロジック)にて定義 | BF23: S | BK23: 検
A24: 〇 | B24: 限界通し数(From) | M24: 抽出条件として、限界通し数(From)を入力する | BE24: T | BF24: N
A25: 〇 | B25: 限界通し数(To) | M25: 抽出条件として、限界通し数(To)を入力する | BE25: T | BF25: N
A26: 〇 | B26: 場所 | M26: 【MSBBPACOM】_共通設計書_アドオン(共通ロジック)にて定義 | BF26: S | BK26: 検
A27: 〇 | B27: 棚・ライン | M27: 【MSBBPACOM】_共通設計書_アドオン(共通ロジック)にて定義 | BF27: S | BK27: 検
A28: 〇 | B28: 最終使用実績日(From) | M28: 抽出条件として、最終使用実績日(From)を入力する | BE28: カ | BF28: D | BN28: Rev2.0 項目追加
A29: 〇 | B29: 最終使用実績日(To) | M29: 抽出条件として、最終使用実績日(To)を入力する | BE29: カ | BF29: D | BN29: Rev2.0 項目追加
A30: 〇 | B30: 入荷日(From) | M30: 抽出条件として、入荷日(From)を入力する | BE30: カ | BF30: D
A31: 〇 | B31: 入荷日(To) | M31: 抽出条件として、入荷日(To)を入力する | BE31: カ | BF31: D
A32: 〇 | B32: 廃棄予定日(From) | M32: 抽出条件として、廃棄予定日(From)を入力する | BE32: カ | BF32: D
A33: 〇 | B33: 廃棄予定日(To) | M33: 抽出条件として、廃棄予定日(To)を入力する | BE33: カ | BF33: D
A34: 〇 | B34: 返却予定日(From) | M34: 抽出条件として、返却予定日(From)を入力する | BE34: カ | BF34: D
A35: 〇 | B35: 返却予定日(To) | M35: 抽出条件として、返却予定日(To)を入力する | BE35: カ | BF35: D
A36: 〇 | B36: 返却日(From) | M36: 抽出条件として、返却日(From)を入力する | BE36: カ | BF36: D
A37: 〇 | B37: 返却日(To) | M37: 抽出条件として、返却日(To)を入力する | BE37: カ | BF37: D
A38: 〇 | B38: 最新Revのみ表示 | M38: 最新Revのみ抽出条件とする場合に、チェックする | AS38: 初期値☑有 | BE38: チ | BF38: F
B40: Web版型・木型マスタ一覧 | N40: 説明 | BE40: Ｗ | BF40: 型 | BG40: 参 | BH40: 必 | BI40: 入 | BJ40: 非 | BK40: 検
B41: NO | M41: 行番を表示 | BE41: T | BF41: N
A42: ● | B42: 発行 | M42: 発行を表示 | BE42: チ | BF42: F
...

Sheet 引数説明
A1: =表紙!A54 -> Webシステム | K1: 文書名 | U1: モジュールID | Z1: =表紙!$AJ$63 -> MS | AE1: モジュール名 | AJ1: =表紙!$AX$63 -> Webシステム | AS1: 文書番号 | AZ1: Version | BF1: Rev.
K2: =表紙!O64 -> アドオン設計書 | U2: ｻﾌﾞﾓｼﾞｭｰﾙID | Z2: =表紙!$AJ$64 -> MSBB | AE2: ｻﾌﾞﾓｼﾞｭｰﾙ名 | AJ2: =表紙!$AX$64 -> 販売Webシステム | AS2: =表紙!$BL$64 -> M7-US-1140 | AZ2: =表紙!$BU$64 -> 1.0.0 | BF2: =表紙!$CB$64 -> 2
K3: =RIGHT(CELL("filename",$A$1),LEN(CELL("filename",$A$1))-FIND("]",CELL("filename",$A$1))) -> 引数説明 | U3: 表題 | Z3: =表紙!$AJ$65 -> MSBBPA150 | AE3: =表紙!$AQ$65 -> Web版型・木型マスタ一覧照会
B5: オペレーションＩＤ/名称：SloRecvIfImp_Upd01/取込
A6: 必 | B6: 項目名 | N6: 説明 | AS6: 未設定時の振る舞い

Sheet 画面遷移
A1: =表紙!A54 -> Webシステム | K1: 文書名 | U1: モジュールID | Z1: =表紙!$AJ$63 -> MS | AE1: モジュール名 | AJ1: =表紙!$AX$63 -> Webシステム | AS1: 文書番号 | AZ1: Version | BF1: Rev.
K2: =表紙!O64 -> アドオン設計書 | U2: ｻﾌﾞﾓｼﾞｭｰﾙID | Z2: =表紙!$AJ$64 -> MSBB | AE2: ｻﾌﾞﾓｼﾞｭｰﾙ名 | AJ2: =表紙!$AX$64 -> 販売Webシステム | AS2: =表紙!$BL$64 -> M7-US-1140 | AZ2: =表紙!$BU$64 -> 1.0.0 | BF2: =表紙!$CB$64 -> 2
K3: =RIGHT(CELL("filename",$A$1),LEN(CELL("filename",$A$1))-FIND("]",CELL("filename",$A$1))) -> 画面遷移 | U3: 表題 | Z3: =表紙!$AJ$65 -> MSBBPA150 | AE3: =表紙!$AQ$65 -> Web版型・木型マスタ一覧照会
A5: 画面遷移フロー図
A6: ＩＤ | C6: S01 | E6: Web版型・木型マスタ一覧照会から他画面の画面遷移
D9: NO1
D10: Web取引先一覧照会
R12: Web版型・木型マスタ一覧照会
D15: NO2
D16: Web製品マスタ一覧照会
AI18: ※Web版型・木型マスタ側で記述
AI19: Web版型・木型マスタ(検索)
D20: NO3
D21: Web汎用検索(共通検索)
A27: ID | D27: 処理名
A28: S01 | D28: メニューから本画面遷移
B30: 遷移処理
B31: 遷移元画面ＩＤ | I31: なし
B32: 遷移元画面名 | I32: メニュー
B33: 遷移先画面ＩＤ | I33: MSBBPA120
B34: 遷移先画面名 | I34: Web取引先一覧照会
B35: 遷移条件 | I35: なし
B36: 引継項目・種別 | I36: 遷移元画面項目 | AJ36: 遷移先画面項目
B40: 遷移後のアクション | I40: 検索
B41: 備考

Sheet 処理概要
A1: =表紙!A54 -> Webシステム | K1: 文書名 | U1: モジュールID | Z1: =表紙!$AJ$63 -> MS | AE1: モジュール名 | AJ1: =表紙!$AX$63 -> Webシステム | AS1: 文書番号 | AZ1: Version | BF1: Rev.
K2: =表紙!O64 -> アドオン設計書 | U2: ｻﾌﾞﾓｼﾞｭｰﾙID | Z2: =表紙!$AJ$64 -> MSBB | AE2: ｻﾌﾞﾓｼﾞｭｰﾙ名 | AJ2: =表紙!$AX$64 -> 販売Webシステム | AS2: =表紙!$BL$64 -> M7-US-1140 | AZ2: =表紙!$BU$64 -> 1.0.0 | BF2: =表紙!$CB$64 -> 2
K3: =RIGHT(CELL("filename",$A$1),LEN(CELL("filename",$A$1))-FIND("]",CELL("filename",$A$1))) -> 処理概要 | U3: 表題 | Z3: =表紙!$AJ$65 -> MSBBPA150 | AE3: =表紙!$AQ$65 -> Web版型・木型マスタ一覧照会
A5: NO | B5: 入力 | J5: 処理 | BD5: 出力
A6: 1 | B6: 初期表示
J7: 1.処理概要
K8: 初期表示
L9: 拠点 | Q9: ： | R9: ログインに紐づく拠点CDを表示する
R10: ログイン.管理者区分 = 0(一般ユーザー時)、変更不可とする
L11: 担当者 | Q11: ： | R11: ログイン担当者CDを表示する
L12: 適用開始日 | Q12: ： | R12: 適用開始日Fromに当日 - ログインマスタ.初期表示をセット、Toに当日をセットする
L13: 表示処理 | Q13: ： | R13: 抽出条件をもとにWeb版型・木型マスタ一覧に結果を表示する | BD13: 検索入出力仕様.NO1
L15: フッターボタン表示・非表示切替
M16: メニューから呼び出された場合(照会画面モード) | AC16: ・・・ | AE16: 発行ラベルを表示する、選択ボタンを非表示する
M17: 検索画面として呼び出された場合(検索画面モード) | AC17: ・・・ | AE17: 発行ラベルを非表示する、選択ボタンを表示する
M18: 例)検索画面モード:Web版型・木型マスタから検索画面として呼び出され、選択行を返す場合
A20: 2 | B20: 画面操作
J21: 1.処理概要
K22: ボタン処理
L23: クリアボタン押下 | U23: ： | V23: 画面を初期化する(起動時の状態とする)
L24: 表示ボタン押下 | U24: ： | V24: チェック処理にてエラーとなった場合、後続処理をキャンセルする
L25: (チェック処理) | W25: FROM～TOの整合性チェック | AH25: … | AI25: エラーメッセージ：FROM≦TOの関係で指定してください。 | BD25: メッセージNo.001
L26: 表示 | U26: ： | V26: 抽出条件をもとにWeb版型・木型マスタ一覧に結果を表示する | BD26: 検索入出力仕様.NO1
W27: データ取得できなかった場合、下記メッセージを表示
W28: エラーメッセージ：検索結果がありません。 | BD28: メッセージNo.002
L29: ラベル発行 | U29: ： | V29: 一覧の発行にチェックされたデータを「版型ラベル」として出力する
W30: 発行☑が1行もチェックされていない場合、下記メッセージを表示
W31: エラーメッセージ：発行対象がありません。 | BD31: メッセージNo.003
V32: →発行☑された行のラベル発行用のCSVファイルを出力する | BD32: ファイル入出力仕様.NO2
W33: ※1回の操作での複数行指定時は、1ファイルに出力する
W34: 複数回ラベル発行をクリックすると、クリック分ファイル出力されます
L35: CSV出力 | U35: ： | V35: Web版型・木型マスタ一覧のデータをCSV出力する | BD35: ファイル入出力仕様.NO1
U36: ※1 CSV出力定義とファイル名は、【MSBBPACOM】_共通設計書_アドオン(共通ロジック)にて定義
U37: ※2 画面に表示されたデータがCSVとして出力される
L38: 選択 | U38: ： | V38: 検索モードで開いた場合に選択結果(1行)を遷移元画面に返す
W39: 一覧にデータが無いもしくは対象行が選択されてない場合、下記メッセージを表示
W40: エラーメッセージ：選択行がありません。 | BD40: メッセージNo.004
U41: ※1 選択された版型・木型マスタの1レコードを呼出元に返す
U42: ※2 複数選択は許可しない

Sheet 処理詳細2
A1: =表紙!A54 -> Webシステム | K1: 文書名 | U1: モジュールID | Z1: =表紙!$AJ$63 -> MS | AE1: モジュール名 | AJ1: =表紙!$AX$63 -> Webシステム | AS1: 文書番号 | AZ1: Version | BF1: Rev.
K2: =表紙!O64 -> アドオン設計書 | U2: ｻﾌﾞﾓｼﾞｭｰﾙID | Z2: =表紙!$AJ$64 -> MSBB | AE2: ｻﾌﾞﾓｼﾞｭｰﾙ名 | AJ2: =表紙!$AX$64 -> 販売Webシステム | AS2: =表紙!$BL$64 -> M7-US-1140 | AZ2: =表紙!$BU$64 -> 1.0.0 | BF2: =表紙!$CB$64 -> 2
K3: =RIGHT(CELL("filename",$A$1),LEN(CELL("filename",$A$1))-FIND("]",CELL("filename",$A$1))) -> 処理詳細2 | U3: 表題 | Z3: =表紙!$AJ$65 -> MSBBPA150 | AE3: =表紙!$AQ$65 -> Web版型・木型マスタ一覧照会
A5: No | B5: 入力 | J5: 処理 | BD5: 出力
A6: 1 | B6: 初期表示
A12: 2 | B12: 画面操作
A18: 3 | B18: 検索【F1】

Sheet 処理・サービス関連図
A1: =表紙!A54 -> Webシステム | K1: 文書名 | U1: モジュールID | Z1: =表紙!$AJ$63 -> MS | AE1: モジュール名 | AJ1: =表紙!$AX$63 -> Webシステム | AS1: 文書番号 | AZ1: Version | BF1: Rev.
K2: =表紙!O64 -> アドオン設計書 | U2: ｻﾌﾞﾓｼﾞｭｰﾙID | Z2: =表紙!$AJ$64 -> MSBB | AE2: ｻﾌﾞﾓｼﾞｭｰﾙ名 | AJ2: =表紙!$AX$64 -> 販売Webシステム | AS2: =表紙!$BL$64 -> M7-US-1140 | AZ2: =表紙!$BU$64 -> 1.0.0 | BF2: =表紙!$CB$64 -> 2
K3: =RIGHT(CELL("filename",$A$1),LEN(CELL("filename",$A$1))-FIND("]",CELL("filename",$A$1))) -> 処理・サービス関連図 | U3: 表題 | Z3: =表紙!$AJ$65 -> MSBBPA150 | AE3: =表紙!$AQ$65 -> Web版型・木型マスタ一覧照会
C7: 検索処理
BM9: Rev2.0 記述追加 (木型・版型管理情報)

Sheet 処理詳細
A1: =表紙!A54 -> Webシステム | K1: 文書名 | U1: モジュールID | Z1: =表紙!$AJ$63 -> MS | AE1: モジュール名 | AJ1: =表紙!$AX$63 -> Webシステム | AS1: 文書番号 | AZ1: Version | BF1: Rev.
K2: =表紙!O64 -> アドオン設計書 | U2: ｻﾌﾞﾓｼﾞｭｰﾙID | Z2: =表紙!$AJ$64 -> MSBB | AE2: ｻﾌﾞﾓｼﾞｭｰﾙ名 | AJ2: =表紙!$AX$64 -> 販売Webシステム | AS2: =表紙!$BL$64 -> M7-US-1140 | AZ2: =表紙!$BU$64 -> 1.0.0 | BF2: =表紙!$CB$64 -> 2
K3: =RIGHT(CELL("filename",$A$1),LEN(CELL("filename",$A$1))-FIND("]",CELL("filename",$A$1))) -> 処理詳細 | U3: 表題 | Z3: =表紙!$AJ$65 -> MSBBPA150 | AE3: =表紙!$AQ$65 -> Web版型・木型マスタ一覧照会
A5: NO | B5: 入力 | J5: 処理 | BD5: 出力
A6: 1 | B6: 初期表示
J7: 1.1 | L7: 処理概要参照
A10: 2 | B10: 画面操作
J11: 2.1 | L11: 処理概要参照
A14: 3 | B14: 検索
J15: 3.1 | L15: コンボボックスの初期化
L16: 拠点コンボボックスの初期化
M17: ※ | N17: 拠点検索_SQLリソースの検索仕様
N18: 【MSBBPACOM】_共通設計書_アドオン(Web共通ロジック)の「処理詳細(共通検索)」シート」を参照する。
L20: 担当者NOコンボボックスの初期化
M21: ※ | N21: 担当者NO検索_SQLリソースの検索仕様
N22: 【MSBBPACOM】_共通設計書_アドオン(Web共通ロジック)の「処理詳細(共通検索)」シート」を参照する。
L24: 版型分類コンボボックスの初期化
M25: ※ | N25: 版型分類検索_SQLリソースの検索仕様
N26: 【MSBBPACOM】_共通設計書_アドオン(Web共通ロジック)の「処理詳細(共通検索)」シート」を参照する。
L28: 新版区分コンボボックスの初期化
M29: ※ | N29: 新版区分検索_SQLリソースの検索仕様
N30: 【MSBBPACOM】_共通設計書_アドオン(Web共通ロジック)の「処理詳細(共通検索)」シート」を参照する。
L32: 工程コンボボックスの初期化
M33: ※ | N33: 工程検索_SQLリソースの検索仕様
N34: 【MSBBPACOM】_共通設計書_アドオン(Web共通ロジック)の「処理詳細(共通検索)」シート」を参照する。
J36: 3.2 | L36: 案件NOの検索ボタン処理
L37: 案件NO検索のポップアップ画面へを遷移して、抽出条件をもとに結果を表示したところ、結果を表示したところ、
L38: 選択結果(1行)を遷移元画面（本画面の案件NO、案件名を設定）に返す
J40: 3.3 | L40: 得意先の検索ボタン処理
L41: 取引先マスタ検索のポップアップ画面へを遷移して、抽出条件＜取引先コード＞あるいは、＜取引先名＞をもとに結果を表示したところ、
L42: 選択結果(1行)を遷移元画面（本画面の得意先コード、得意先名を設定）に返す
M44: ※ | N44: 得意先NO検索_SQLリソースの検索仕様
N45: 【MSBBPACOM】_共通設計書_アドオン(Web共通ロジック)の「処理詳細(共通検索)」シート」を参照する。
J47: 3.4 | L47: 製品コードの検索ボタン処理
L48: 製品検索のポップアップ画面へを遷移して、抽出条件をもとに結果を表示したところ、
L49: 選択結果(1行)を遷移元画面（本画面の製品コード、製品名を設定）に返す
L50: 木型・版型Noを用いて製品マスタを検索し製品コード、および製品名１・２を取得する
M52: ※ | N52: 製品コード検索_SQLリソースの検索仕様
N53: 【MSBBPACOM】_共通設計書_アドオン(Web共通ロジック)の「処理詳細(共通検索)」シート」を参照する。
J55: 3.5 | L55: 発注先コードの検索ボタン処理
...

Sheet 画面項目制御
J2: 操作種別 | O2: 検索 | S2: R | U2: 有効(必須)
B3: 画面項目 | S3: E | U3: 有効
B4: 検索条件 | G4: 拠点 | O4: E | S4: RO | U4: 読取のみ
G5: 担当者 | O5: E | S5: D | U5: 無効
G6: 適用開始日(From) | O6: E | S6: I | U6: 非表示
G7: 適用開始日(To) | O7: E
G8: 手配NO | O8: E
G9: 案件NO | O9: E
G10: 版型NO(From) | O10: E
G11: 版型NO(To) | O11: E
G12: 版型名称 | O12: E
G13: 版型分類 | O13: E
G14: 新版区分 | O14: E
G15: 得意先 | O15: E
G16: 代表製品CD | O16: E
G17: 工程 | O17: E
G18: 通し数(From) | O18: E
... G35: 最新Revのみ表示 | O35: E
B36: 取引先マスタ一覧 | G36: NO | O36: RO
G37: 発行 | O37: E
G38: 版型NO | O38: RO
G39: 版型名 | O39: RO
G40: Rev | O40: RO
G41: 版型分類 | O41: RO
G42: 得意先 | O42: RO
G43: 得意先名 | O43: RO
G44: 製品コード | O44: RO
G45: 製品名 | O45: RO
G46: 通し数 | O46: RO
G47: 限界通し数 | O47: RO
G48: 最終使用実績日 | O48: RO
... G78: 全解除 | O78: E
B79: フッター | G79: クリア | O79: E
G80: 表示 | O80: E
G81: 発行 | O81: E/I
G82: CSV出力 | O82: E
G83: 選択 | O83: I/E

Sheet 検索入出力仕様
A1: =表紙!A54 -> Webシステム | K1: 文書名 | U1: モジュールID | Z1: =表紙!$AJ$63 -> MS | AE1: モジュール名 | AJ1: =表紙!$AX$63 -> Webシステム | AS1: 文書番号 | AZ1: Version | BF1: Rev.
K2: =表紙!O64 -> アドオン設計書 | U2: ｻﾌﾞﾓｼﾞｭｰﾙID | Z2: =表紙!$AJ$64 -> MSBB | AE2: ｻﾌﾞﾓｼﾞｭｰﾙ名 | AJ2: =表紙!$AX$64 -> 販売Webシステム | AS2: =表紙!$BL$64 -> M7-US-1140 | AZ2: =表紙!$BU$64 -> 1.0.0 | BF2: =表紙!$CB$64 -> 2
K3: =RIGHT(CELL("filename",$A$1),LEN(CELL("filename",$A$1))-FIND("]",CELL("filename",$A$1))) -> 検索入出力仕様 | U3: 表題 | Z3: =表紙!$AJ$65 -> MSBBPA150 | AE3: =表紙!$AQ$65 -> Web版型・木型マスタ一覧照会
A5: NO | G5: 1 | S5: ボタン | Z5: 表示 | AH5: 備考 | AK5: 表示ボタンクリック時処理
A6: 処理分類 | E6: 検索 | S6: ソート順 | Z6: 版型NO、Rev
A7: NO | C7: 転送先 | V7: 転送元 | AQ7: 説明
C8: 種 | D8: オブジェクト | K8: 項目名 | V8: 種 | W8: オブジェクト | AF8: 項目名
A9: 1 | C9: 画 | D9: Web版型・木型マスタ一覧 | K9: NO | AF9: 行番
A10: 2 | C10: 画 | D10: Web版型・木型マスタ一覧 | K10: 発行 | AF10: [固定値:0] ※チェック無し
A11: 3 | C11: 画 | D11: Web版型・木型マスタ一覧 | K11: 版型NO | V11: T | W11: 版型・木型管理マスタ | AF11: 版型NO
A12: 4 | C12: 画 | D12: Web版型・木型マスタ一覧 | K12: 版型名 | V12: T | W12: 版型・木型管理マスタ | AF12: 版型名
A13: 5 | C13: 画 | D13: Web版型・木型マスタ一覧 | K13: Rev | V13: T | W13: 版型・木型管理マスタ | AF13: Rev
A14: 6 | C14: 画 | D14: Web版型・木型マスタ一覧 | K14: 版型分類 | V14: T | W14: 版型・木型管理マスタ | AF14: 版型分類
A15: 7 | C15: 画 | D15: Web版型・木型マスタ一覧 | K15: 得意先 | V15: T | W15: 版型・木型管理マスタ | AF15: 得意先
A16: 8 | C16: 画 | D16: Web版型・木型マスタ一覧 | K16: 得意先名 | V16: T | W16: 得意先 | AF16: 得意先名
A17: 9 | C17: 画 | D17: Web版型・木型マスタ一覧 | K17: 製品コード | V17: T | W17: 版型・木型管理マスタ | AF17: 製品コード
A18: 10 | C18: 画 | D18: Web版型・木型マスタ一覧 | K18: 製品名 | V18: T | W18: 製品マスタ | AF18: 品名1 + 品名2
A19: 11 | C19: 画 | D19: Web版型・木型マスタ一覧 | K19: 通し数 | V19: T | W19: 版型・木型管理マスタ | AF19: 通し数
A20: 12 | C20: 画 | D20: Web版型・木型マスタ一覧 | K20: 限界通し数 | V20: T | W20: 版型・木型管理マスタ | AF20: 限界通し数
A21: 13 | C21: 画 | D21: Web版型・木型マスタ一覧 | K21: 最終使用実績日 | V21: T | W21: 木型・版型管理情報 | AF21: 実績日(最終使用実績日) | BN21: Rev2.0 項目追加
A22: 14 | C22: 画 | D22: Web版型・木型マスタ一覧 | K22: 発注先 | V22: T | W22: 版型・木型管理マスタ | AF22: 発注先
A23: 15 | C23: 画 | D23: Web版型・木型マスタ一覧 | K23: 発注先名 | V23: T | W23: 発注先 | AF23: 発注先名
A24: 16 | C24: 画 | D24: Web版型・木型マスタ一覧 | K24: 入荷日 | V24: T | W24: 版型・木型管理マスタ | AF24: 入荷日
A25: 17 | C25: 画 | D25: Web版型・木型マスタ一覧 | K25: 廃棄予定日 | V25: T | W25: 版型・木型管理マスタ | AF25: 廃棄予定日
A26: 18 | C26: 画 | D26: Web版型・木型マスタ一覧 | K26: 返却予定日 | V26: T | W26: 版型・木型管理マスタ | AF26: 返却予定日
A27: 19 | C27: 画 | D27: Web版型・木型マスタ一覧 | K27: 返却日 | V27: T | W27: 版型・木型管理マスタ | AF27: 返却日
A28: 20 | C28: 画 | D28: Web版型・木型マスタ一覧 | K28: 返却理由 | V28: T | W28: 版型・木型管理マスタ | AF28: 返却理由
A29: 21 | C29: 画 | D29: Web版型・木型マスタ一覧 | K29: 案件NO | V29: T | W29: 見積計算書 | AF29: 案件NO(親)、(子)、(部材) | AQ29: 表示形式：案件NO(親)+ '-' + 案件NO(子)+ '-' + 案件NO(部材) | BN29: Rev2.0 変更
A30: 22 | C30: 画 | D30: Web版型・木型マスタ一覧 | K30: 案件名 | V30: T | W30: 見積計算書 | AF30: 案件名
A31: 23 | C31: 画 | D31: Web版型・木型マスタ一覧 | K31: 工程 | V31: T | W31: 版型・木型管理マスタ | AF31: 工程
A32: 24 | C32: 画 | D32: Web版型・木型マスタ一覧 | K32: 工程名 | V32: T | W32: 工程 | AF32: 工程名
A33: 25 | C33: 画 | D33: Web版型・木型マスタ一覧 | K33: 場所 | V33: T | W33: 版型・木型管理マスタ | AF33: 場所
A34: 26 | C34: 画 | D34: Web版型・木型マスタ一覧 | K34: 場所名 | V34: T | W34: 場所 | AF34: 場所名
A35: 27 | C35: 画 | D35: Web版型・木型マスタ一覧 | K35: 棚・ライン | V35: T | W35: 版型・木型管理マスタ | AF35: 棚・ライン
A36: 28 | C36: 画 | D36: Web版型・木型マスタ一覧 | K36: 棚・ライン名 | V36: T | W36: 棚・ライン | AF36: 棚・ライン名
A37: 29 | C37: 画 | D37: Web版型・木型マスタ一覧 | K37: 新版区分 | V37: T | W37: 版型・木型管理マスタ | AF37: 新版区分
A38: 30 | C38: 画 | D38: Web版型・木型マスタ一覧 | K38: 最終加工先 | V38: T | W38: 版型・木型管理マスタ | AF38: 最終加工先
A39: 31 | C39: 画 | D39: Web版型・木型マスタ一覧 | K39: 最終加工先名 | V39: T | W39: 場所マスタ | AF39: 最終加工先名
A40: 32 | C40: 画 | D40: Web版型・木型マスタ一覧 | K40: 刃渡り寸法(巾) | V40: T | W40: 版型・木型管理マスタ | AF40: 刃渡り寸法(巾)
A41: 33 | C41: 画 | D41: Web版型・木型マスタ一覧 | K41: 刃渡り寸法(流れ) | V41: T | W41: 版型・木型管理マスタ | AF41: 刃渡り寸法(流れ)
...

Sheet 更新入出力仕様
A1: =表紙!A54 -> Webシステム | K1: 文書名 | U1: モジュールID | Z1: =表紙!$AJ$63 -> MS | AE1: モジュール名 | AJ1: =表紙!$AX$63 -> Webシステム | AS1: 文書番号 | AZ1: Version | BF1: Rev.
K2: =表紙!O64 -> アドオン設計書 | U2: ｻﾌﾞﾓｼﾞｭｰﾙID | Z2: =表紙!$AJ$64 -> MSBB | AE2: ｻﾌﾞﾓｼﾞｭｰﾙ名 | AJ2: =表紙!$AX$64 -> 販売Webシステム | AS2: =表紙!$BL$64 -> M7-US-1140 | AZ2: =表紙!$BU$64 -> 1.0.0 | BF2: =表紙!$CB$64 -> 2
K3: =RIGHT(CELL("filename",$A$1),LEN(CELL("filename",$A$1))-FIND("]",CELL("filename",$A$1))) -> 更新入出力仕様 | U3: 表題 | Z3: =表紙!$AJ$65 -> MSBBPA150 | AE3: =表紙!$AQ$65 -> Web版型・木型マスタ一覧照会
A5: No | G5: 1 | S5: ロジック名称 | AH5: 備考
A6: 処理分類 | E6: 更新
A7: No | C7: 転送先 | V7: 転送元 | AQ7: 説明
C8: 種 | D8: オブジェクト | K8: 項目名 | V8: 種 | W8: オブジェクト | AF8: 項目名

Sheet ファイル入出力仕様
A1: =表紙!A54 -> Webシステム | K1: 文書名 | U1: モジュールID | Z1: =表紙!$AJ$63 -> MS | AE1: モジュール名 | AJ1: =表紙!$AX$63 -> Webシステム | AS1: 文書番号 | AZ1: Version | BF1: Rev.
K2: =表紙!O64 -> アドオン設計書 | U2: ｻﾌﾞﾓｼﾞｭｰﾙID | Z2: =表紙!$AJ$64 -> MSBB | AE2: ｻﾌﾞﾓｼﾞｭｰﾙ名 | AJ2: =表紙!$AX$64 -> 販売Webシステム | AS2: =表紙!$BL$64 -> M7-US-1140 | AZ2: =表紙!$BU$64 -> 1.0.0 | BF2: =表紙!$CB$64 -> 2
K3: =RIGHT(CELL("filename",$A$1),LEN(CELL("filename",$A$1))-FIND("]",CELL("filename",$A$1))) -> ファイル入出力仕様 | U3: 表題 | Z3: =表紙!$AJ$65 -> MSBBPA150 | AE3: =表紙!$AQ$65 -> Web版型・木型マスタ一覧照会
A5: NO | G5: 1 | S5: ロジック名称 | Z5: ファイル出力 | AH5: 備考
A6: 処理分類 | E6: ファイル出力 | S6: ソート順 | Z6: 版型NO、Rev
A7: NO | C7: 転送先 | X7: 転送元 | AS7: 説明
C8: 種 | D8: オブジェクト | M8: 項目名 | X8: 種 | Y8: オブジェクト | AH8: 項目名
A9: 1 | C9: フ | D9: Web版型・木型マスタ一覧 | M9: NO | X9: 画 | Y9: Web版型・木型マスタ一覧 | AH9: 行番
A10: 2 | C10: フ | D10: Web版型・木型マスタ一覧 | M10: 版型NO | X10: 画 | Y10: Web版型・木型マスタ一覧 | AH10: 版型NO
A11: 3 | C11: フ | D11: Web版型・木型マスタ一覧 | M11: 版型名 | X11: 画 | Y11: Web版型・木型マスタ一覧 | AH11: 版型名
A12: 4 | C12: フ | D12: Web版型・木型マスタ一覧 | M12: Rev | X12: 画 | Y12: Web版型・木型マスタ一覧 | AH12: Rev
A13: 5 | C13: フ | D13: Web版型・木型マスタ一覧 | M13: 版型分類 | X13: 画 | Y13: Web版型・木型マスタ一覧 | AH13: 版型分類
A14: 6 | C14: フ | D14: Web版型・木型マスタ一覧 | M14: 得意先 | X14: 画 | Y14: Web版型・木型マスタ一覧 | AH14: 得意先
A15: 7 | C15: フ | D15: Web版型・木型マスタ一覧 | M15: 得意先名 | X15: 画 | Y15: Web版型・木型マスタ一覧 | AH15: 得意先名
A16: 8 | C16: フ | D16: Web版型・木型マスタ一覧 | M16: 製品コード | X16: 画 | Y16: Web版型・木型マスタ一覧 | AH16: 製品コード
A17: 9 | C17: フ | D17: Web版型・木型マスタ一覧 | M17: 製品名 | X17: 画 | Y17: Web版型・木型マスタ一覧 | AH17: 製品名
A18: 10 | C18: フ | D18: Web版型・木型マスタ一覧 | M18: 通し数 | X18: 画 | Y18: Web版型・木型マスタ一覧 | AH18: 通し数
A19: 11 | C19: フ | D19: Web版型・木型マスタ一覧 | M19: 限界通し数 | X19: 画 | Y19: Web版型・木型マスタ一覧 | AH19: 限界通し数
A20: 12 | C20: フ | D20: Web版型・木型マスタ一覧 | M20: 最終使用実績日 | X20: 画 | Y20: Web版型・木型マスタ一覧 | AH20: 最終使用実績日 | BN20: Rev2.0 項目追加
A21: 13 | C21: フ | D21: Web版型・木型マスタ一覧 | M21: 発注先 | X21: 画 | Y21: Web版型・木型マスタ一覧 | AH21: 発注先
A22: 14 | C22: フ | D22: Web版型・木型マスタ一覧 | M22: 発注先名 | X22: 画 | Y22: Web版型・木型マスタ一覧 | AH22: 発注先名
A23: 15 | C23: フ | D23: Web版型・木型マスタ一覧 | M23: 入荷日 | X23: 画 | Y23: Web版型・木型マスタ一覧 | AH23: 入荷日
A24: 16 | C24: フ | D24: Web版型・木型マスタ一覧 | M24: 廃棄予定日 | X24: 画 | Y24: Web版型・木型マスタ一覧 | AH24: 廃棄予定日
A25: 17 | C25: フ | D25: Web版型・木型マスタ一覧 | M25: 返却予定日 | X25: 画 | Y25: Web版型・木型マスタ一覧 | AH25: 返却予定日
A26: 18 | C26: フ | D26: Web版型・木型マスタ一覧 | M26: 返却日 | X26: 画 | Y26: Web版型・木型マスタ一覧 | AH26: 返却日
A27: 19 | C27: フ | D27: Web版型・木型マスタ一覧 | M27: 返却理由 | X27: 画 | Y27: Web版型・木型マスタ一覧 | AH27: 返却理由
A28: 20 | C28: フ | D28: Web版型・木型マスタ一覧 | M28: 案件NO | X28: 画 | Y28: Web版型・木型マスタ一覧 | AH28: 案件NO
A29: 21 | C29: フ | D29: Web版型・木型マスタ一覧 | M29: 案件名 | X29: 画 | Y29: Web版型・木型マスタ一覧 | AH29: 案件名
A30: 22 | C30: フ | D30: Web版型・木型マスタ一覧 | M30: 工程 | X30: 画 | Y30: Web版型・木型マスタ一覧 | AH30: 工程
A31: 23 | C31: フ | D31: Web版型・木型マスタ一覧 | M31: 工程名 | X31: 画 | Y31: Web版型・木型マスタ一覧 | AH31: 工程名
A32: 24 | C32: フ | D32: Web版型・木型マスタ一覧 | M32: 場所 | X32: 画 | Y32: Web版型・木型マスタ一覧 | AH32: 場所
... A48: 40 | C48: フ | D48: Web版型・木型マスタ一覧 | M48: 備考 | X48: 画 | Y48: Web版型・木型マスタ一覧 | AH48: 備考
A50: NO | G50: 2 | V50: ロジック名称 | AC50: ラベル発行 | AK50: 備考 | AN50: 版・型管理ラベル発行用のCSVファイルの出力
A51: 処理分類 | E51: ファイル出力 | V51: ソート順 | AC51: 版型NO、Rev
A52: NO | C52: 転送先 | X52: 転送元 | AS52: 説明
C53: 種 | D53: オブジェクト | O53: 項目名 | X53: 種 | Y53: オブジェクト | AH53: 項目名
A54: 1 | C54: フ | D54: 版・型管理ラベル出力用CSVファイル | O54: 版型NO | X54: 画 | Y54: Web版型・木型マスタ一覧 | AH54: 版型NO
A55: 2 | C55: フ | D55: 版・型管理ラベル出力用CSVファイル | O55: 版型名 | X55: 画 | Y55: Web版型・木型マスタ一覧 | AH55: 版型名
A56: 3 | C56: フ | D56: 版・型管理ラベル出力用CSVファイル | O56: Rev | X56: 画 | Y56: Web版型・木型マスタ一覧 | AH56: Rev
A57: 4 | C57: フ | D57: 版・型管理ラベル出力用CSVファイル | O57: 版型分類 | X57: 画 | Y57: Web版型・木型マスタ一覧 | AH57: 版型分類
...

Sheet メッセージ一覧
A1: =表紙!A54 -> Webシステム | K1: 文書名 | U1: モジュールID | Z1: =表紙!$AJ$63 -> MS | AE1: モジュール名 | AJ1: =表紙!$AX$63 -> Webシステム | AS1: 文書番号 | AZ1: Version | BF1: Rev.
K2: =表紙!O64 -> アドオン設計書 | U2: ｻﾌﾞﾓｼﾞｭｰﾙID | Z2: =表紙!$AJ$64 -> MSBB | AE2: ｻﾌﾞﾓｼﾞｭｰﾙ名 | AJ2: =表紙!$AX$64 -> 販売Webシステム | AS2: =表紙!$BL$64 -> M7-US-1140 | AZ2: =表紙!$BU$64 -> 1.0.0 | BF2: =表紙!$CB$64 -> 2
K3: =RIGHT(CELL("filename",$A$1),LEN(CELL("filename",$A$1))-FIND("]",CELL("filename",$A$1))) -> メッセージ一覧 | U3: 表題 | Z3: =表紙!$AJ$65 -> MSBBPA150 | AE3: =表紙!$AQ$65 -> Web版型・木型マスタ一覧照会
C4: ↓アドオン画面のため、基本全て[新]
A5: NO | C5: 新/変 | E5: 種別 | G5: メッセージ内容 | AQ5: 備考（パラメータ等） | BG5: メッセージID
A6: 1 | C6: 新 | E6: W | G6: 「FROM≦TOの関係で指定してください。項目名：{1} 」 | AQ6: 適用開始日、版型NO、通し数、限界通し数 | BG6: E10036
AQ7: 入荷日、廃棄予定日、返却予定日、返却日
A9: 2 | C9: 新 | E9: W | G9: 「検索結果がありません。」 | BG9: E10008
A10: 3 | C10: 新 | E10: W | G10: 「発行対象がありません。」 | BG10: E10010
A11: 4 | C11: 新 | E11: W | G11: 「選択行がありません。」 | BG11: E10009
A12: 5 | C12: 新 | E12: W | G12: 「検索件数の上限値を超えました。(設定値) \n 抽出条件を設定し、再度検索・照会を実施ください。」 | BG12: E10013
A13: 6 | C13: 新 | E13: I | G13: 「検索件数の上限値を超えました。(設定値) \n 処理を続ける場合は、[はい]を選択してください。」 | BG13: C00006

Sheet 補足説明資料
A1: =表紙!A54 -> Webシステム | O1: 文書名 | AC1: モジュールID | AJ1: =表紙!$AJ$63 -> MS | AQ1: モジュール名 | AX1: =表紙!$AX$63 -> Webシステム | BL1: 文書番号 | BU1: Version | CB1: Rev.
O2: =表紙!O64 -> アドオン設計書 | AC2: サブモジュールID | AJ2: =表紙!$AJ$64 -> MSBB | AQ2: サブモジュール名 | AX2: =表紙!$AX$64 -> 販売Webシステム | BL2: =表紙!$BL$64 -> M7-US-1140 | BU2: =表紙!$BU$64 -> 1.0.0 | CB2: =表紙!$CB$64 -> 2
O3: =RIGHT(CELL("filename",$A$1),LEN(CELL("filename",$A$1))-FIND("]",CELL("filename",$A$1))) -> 補足説明資料 | AC3: 表題 | AJ3: =表紙!$AJ$65 -> MSBBPA150 | AQ3: =表紙!$AQ$65 -> Web版型・木型マスタ一覧照会
AO5: 補足説明
