Workbook
Name Rev.: 表紙!$U$22
Name Revision: 表紙!$AP$5
Name Ver.: 表紙!$AE$26
Name ご確認日: 表紙!$AG$42
Name ご確認者: 表紙!$AG$40
Name サブシステム名: 表紙!$U$28
Name システム名: 表紙!$U$26
Name プロジェクト名: 表紙!$U$18
Name 発行日: 表紙!$W$42
Name 顧客名: 表紙!$U$16
Name 機能ＩＤ: 表紙!$U$32
Name 機能名称: 表紙!$U$30
Name 機能区分: 表紙!$U$34
Name 開発区分: 表紙!$U$36
Name 文書番号: 表紙!$O$5
Name 文書名: 表紙!$M$10
Name 章: 表紙!$M$10
Name 最終更新日: 表紙!$AB$42
Name 最終更新者: 表紙!$AB$40
Name 作成日: 表紙!$W$42
Name 作成者: 表紙!$W$40

Sheet 表紙
AW2: サブモジュール
AW3: MA_マスタ管理
AW4: MB_業務共通
AW5: MG_原価管理
AW6: MSBA_需給管理
M7: 基本設計 | AW7: MSBB_販売管理
AW8: MSBC_生産管理
AW9: MSBD_購買管理
M10: 画面機能 | AW10: MSBE_在庫物流管理
AW11: MSBF_品質管理
AW12: MSBG_債権管理
AW13: MSBH_債務管理
AW14: MSBI_締処理
AW15: MSUA_リスト・入力補助
M16: 顧客 | U16: 株式会社クラウン・パッケージ | AW16: PF_ESBアダプタ
M18: プロジェクト名 | U18: 新基幹システム導入 | AW18: 機能区分
AW19: 画面
M20: 文書番号 | U20: =A50 -> M7-US-1140 | AW20: 帳票
AW21: バッチ
M22: Ｒｅｖ． | U22: {=MAX(_xlfn.NUMBERVALUE(改訂!A7:E52))} -> 4 | AW22: マスタ
M24: 機密性区分 | U24: 取扱注意（Ｃ） | AW24: 開発区分
AW25: カスタマイズ
M26: システム名 | U26: Webシステム | AC26: Ver. | AE26: 7.0.2 | AW26: アドオン
AW27: －
M28: サブモジュール | U28: MSBB_販売管理
M30: 機能名 | U30: =M50 -> Web版型・木型マスタ
M32: 機能ID | U32: =G50 -> MSBBPA140
M34: 機能区分 | U34: 画面
M36: 開発区分 | U36: アドオン
W39: 作成 | AB39: 最終更新 | AG39: ご確認
W40: MDSOL | AB40: =改訂!AZ2 -> MDSOL 野村
W42: 44643 | AB42: =改訂!BJ2 -> 44963
A48: 文書番号 | G48: 画面ID | M48: 画面名 | V48: Version | AB48: Revision
A50: M7-US-1140 | G50: MSBBPA140 | M50: Web版型・木型マスタ | V50: 1.0.0 | AB50: =改訂!BP2 -> 4
A53: 共通（元データ）
A54: Webシステム | K54: 文書名 | U54: モジュールID | Z54: MS | AE54: モジュール名 | AJ54: 見積管理 | AS54: 文書番号 | AZ54: Version | BF54: Rev.
K55: 画面説明書 | U55: ｻﾌﾞﾓｼﾞｭｰﾙID | Z55: MSBB | AE55: ｻﾌﾞﾓｼﾞｭｰﾙ名 | AJ55: Webシステム | AS55: M7-US-1140 | AZ55: 1.0.0 | BF55: r00.00
K56: 表紙 | U56: 表題 | Z56: アドオン画面 | AE56: Web版型・木型マスタ
A57: 共通（リンク用）
A58: =A54 -> Webシステム | K58: 文書名 | U58: モジュールID | Z58: =IF(Z54="","",Z54) -> MS | AE58: モジュール名 | AJ58: =IF(AJ54="","",AJ54) -> 見積管理 | AS58: 文書番号 | AZ58: Version | BF58: Rev.
...

Sheet 改訂
K1: 改訂 | AU1: 作成者 | AZ1: MDSOL | BE1: 作成日 | BJ1: =表紙!W42 -> 44643 | BP1: Rev.
AU2: 修正者 | AZ2: =BM14 -> MDSOL 野村 | BE2: 改訂日 | BJ2: =MAX(改訂!BM7:BQ50) -> 44963 | BP2: {=MAX(_xlfn.NUMBERVALUE(改訂!A7:E50))} -> 4
A5: Rev. | F5: 改定内容 | BC5: 頁 | BM5: 変更日 変更者 | BR5: 確認日 確認者
A7: 1 | F7: 新規作成 | BM7: 44865
BM8: MDSOL
A9: 2 | F9: 処理関連図/サービス関連図 ・・・ 実績テーブルを追加、詳細記述 検索入出力仕様 ・・・ 転送元のテーブル名不正を訂正(通し数の実績テーブルの名称不正の訂正) | BC9: 概要、検索入出力仕様 処理・サービス関連図 | BM9: 44894 | BR9: 44895
BM10: MDSOL | BR10: MDSOL 奥本
A11: 2 | F11: 案件NOをDBの項目は、案件NO(親)＋案件NO(子)＋案件NO(部材)に分割する ※画面項目は、1つとする | BC11: 検索入出力仕様 | BM11: 44894 | BR11: 44895
BM12: MDSOL | BR12: MDSOL 奥本
A13: 3 | F13: RCS-1147に伴う下記改定を実施 ①項目に段～原紙構成（表・中・裏）をもっているが、製品マスタが変更された際に連携が取れないため、web製品マスタの参照で良い ②面付け(From)、面付け(To)の項目があるが、恐らく付け数・個数の項目とダブっていると思われる ③廃棄実績日が画面上にはあるが、テーブルに無い | BC13: 画面イメージ、項目説明、処理概要、検索入出力仕様、更新入出力仕様、更新入出力仕様(PE) | BM13: 44936 | BR13: 44936
BM14: MDSOL 野村 | BR14: MDSOL 奥本
A15: 3 | F15: 詳細設計の追加、メッセージIDの採番 | BC15: 画面遷移 処理詳細 | BM15: 44896
BM16: TBK華
A17: 4 | F17: シ設計集中見直し①（RCS-1229）:版型マスタ登録時の版型受注登録連携 | BC17: 処理概要(登録) 更新入出力仕様(版型受注) | BM17: 44963 | BR17: 44964
BM18: MDSOL野村 | BR18: MDSOL 奥本

Sheet 概要
A1: =表紙!A54 -> Webシステム | O1: 文書名 | AC1: モジュールID | AJ1: =表紙!$AJ$63 -> MS | AQ1: モジュール名 | AX1: =表紙!$AX$63 -> 見積管理 | BL1: 文書番号 | BU1: Version | CB1: Rev.
O2: =表紙!O64 -> 画面機能 | AC2: サブモジュールID | AJ2: =表紙!$AJ$64 -> MSBB | AQ2: サブモジュール名 | AX2: =表紙!$AX$64 -> Webシステム | BL2: =表紙!$BL$64 -> M7-US-1140 | BU2: =表紙!$BU$64 -> 1.0.0 | CB2: =表紙!$CB$64 -> 4
O3: =RIGHT(CELL("filename",$A$1),LEN(CELL("filename",$A$1))-FIND("]",CELL("filename",$A$1))) -> 概要 | AC3: 表題 | AJ3: =表紙!$AJ$65 -> アドオン画面 | AQ3: =表紙!$AQ$65 -> Web版型・木型マスタ
AO5: 概要
B8: 【業務要件】
C9: カスタマイズ | G9: 内容
C10: No.
C11: 98 | G11: 管理している木型・版型のマスタをメンテナンスする画面
G12: 製造時に使用した木型、版型の通し数の管理が必要
G13: →通し数のカウントアップは、通し数集計バッチにて実施する
B16: 【機能概要】
C17: 1. | D17: 見積確定WFを確認し、木型・版型の情報を登録する、新規登録時は決定見積NOを入力し初期情報を表示する
D18: 木型・版型Noや品目で検索を行い、木型・版型の情報を参照する
C19: 2. | D19: 木型・版型管理マスタの情報についてメンテナンスを行う
D20: 廃棄予定日や適用期間の調整、使用不可(論理削除)の設定を行う
B23: 【前提条件】
C24: 1. | D24: 場所・棚ライン、通し数に関しては画面より変更しない、発注先・加工予定先は本画面のみに使用する情報となる。(発注登録等に連携はしない。)
C25: 2. | D25: ファイル取込によるデータ更新は行わない
B27: 【説明】
C28: 木型・版型情報のメンテナンス及び参照を行う画面
B30: 【目的】
C32: 目的（レベル１） | Q32: 目的（レベル２） | AT32: 利用シーン/補足 | BV32: 操作種別/検索モード
C33: 木型・版型管理マスタを | BV33: 登録
C34: 登録する。
C35: 木型・版型管理マスタを | BV35: 改定
C36: 改定する。
C37: 木型・版型管理マスタを | BV37: 訂正
C38: 訂正する。
C39: 木型・版型管理マスタを | BV39: 削除
C40: 削除する（管理者のみ）。
C41: 木型・版型管理マスタを | BV41: 参照
C42: 参照する。
B45: 【処理関連図/サービス関連図】
C46: ■訂正する
C47: 検索処理
CK48: Rev2.0 記述追加
C57: 更新処理
B64: 【オペレーション一覧】
C66: ID | L66: 処理名 | Y66: 処理概要
C67: Srch01 | L67: 検索 | Y67: 木型・版型管理マスタの検索処理を行う。
...

Sheet 画面イメージ
A1: =表紙!A54 -> Webシステム | K1: 文書名 | U1: モジュールID | Z1: =表紙!$AJ$63 -> MS | AE1: モジュール名 | AJ1: =表紙!$AX$63 -> 見積管理 | AS1: 文書番号 | AZ1: Version | BF1: Rev.
K2: =表紙!O64 -> 画面機能 | U2: ｻﾌﾞﾓｼﾞｭｰﾙID | Z2: =表紙!$AJ$64 -> MSBB | AE2: ｻﾌﾞﾓｼﾞｭｰﾙ名 | AJ2: =表紙!$AX$64 -> Webシステム | AS2: =表紙!$BL$64 -> M7-US-1140 | AZ2: =表紙!$BU$64 -> 1.0.0 | BF2: =表紙!$CB$64 -> 4
K3: =RIGHT(CELL("filename",$A$1),LEN(CELL("filename",$A$1))-FIND("]",CELL("filename",$A$1))) -> 画面イメージ | U3: 表題 | Z3: =表紙!$AJ$65 -> アドオン画面 | AE3: =表紙!$AQ$65 -> Web版型・木型マスタ
A5: 画面イメージ
B7: ≫凡例
Q8: ・・・ | S8: ボタン
C9: 見積計算書№ | Q9: ・・・ | S9: 検索項目(検索画面表示選択)
C10: 品名 | Q10: ・・・ | S10: 入力項目
C11: 得意先 | Q11: ・・・ | S11: 表示項目(得意先名称、原紙名等)
C12: 操作種別 | I12: ●登録 | M12: ○訂正 | Q12: ・・・ | S12: 選択項目(一つのみ選択可能)
C13: 受注区分 | Q13: ・・・ | S13: 選択項目(一つのみ選択可能)
C14: 作業順 | I14: ☑AAA | M14: ☑BBB | Q14: ・・・ | S14: 選択項目(複数選択可能)
BM17: CP指摘 2022/11/09 落合 版型発注書はPOWEREGGから手動で発行でしたでしょうか？ | CO17: MDSOL回答 2022/11/10 石田 手動で発行となります。POWEREGGへのリンクボタンをつけました。
BM18: CP指摘 2022/11/09 落合 売上可否区分＝売上可の時のみ、版型受注を作成して欲しいです | CO18: MDSOL回答 2022/11/10 石田 会議にて売上可以外も受注を作成するとなりました。
BM21: CP指摘 2022/09/21 土屋 版型No1つで一意となるのであれば、版型名称とRevが表示項目かと思われます | CP21: MDSOL回答 2022/10/31 石田 検索欄について版型名に関しては表示項目になります。REVに関しては過去のデータを参照することもあるため入力としています。入力欄については、当画面で版型名を編集するため入力欄でREVは自動採番のため表示項目です。 | FI21: 2022/11/01 落合 問題なし
D22: 操作種別 | J22: ●登録 | N22: ○改定 | R22: ○訂正 | V22: ○削除 | Z22: ○参照 | BM22: CP指摘 2022/09/21 土屋 改定の入力方法の説明がツールチップあると良いと思います | CP22: MDSOL回答 2022/10/31 石田 マニュアルで対応願います。 | DI22: 2022/11/01 落合 問題なし
N24: 版型No | AN24: Rev
BM26: CP指摘 2022/09/21 土屋 添付ファイルを確認したくなる為、案件Noが表示されるていると良いお思います | CP26: MDSOL回答 2022/10/31 石田 案件NO項目を追加しました。見積計算書NOに紐づく案件NOを表示します。 | DV26: 2022/11/01 落合 問題なし
D27: 拠点
D29: 基本情報
D30: 決定見積NO | J30: X/999999 | W30: 案件NO | BM30: CP指摘 2022/09/22 三宅 | CA30: MDSOL回答 2022/10/31 石田 mcframeに操作感を合わせラジオボタンで切替になります。初期は登録になります。 | DI30: 2022/11/01 落合 問題なし
D31: 版型名 | W31: 売上可否区分 | AC31: (売上可否区分) | AI31: 手配NO | BN31: 操作種別 ○登録 ○訂正 ○削除 ○参照
D32: 版型No | J32: (自動採番) | W32: Rev | AI32: 適用開始日 | BN32: ラジオボタンで切替？初期値は登録？
D33: 得意先
D34: 代表製品CD | AI34: 新版区分 | BN34: 一般的なWebシステムのような、URL別に
BN35: /patterns 一覧 詳細表示へ
D36: 工程 | AI36: 版型分類 | BN36: /patterns/create 登録 完了したら詳細表示へ
D37: 最終加工場所 | AI37: 実績日(最終使用日) | BN37: /patterns/1234567 現行詳細表示 編集・削除へ
BN38: /patterns/1234567/1 詳細表示 Rev
BN39: /patterns/1234567/edit 編集 完了したら詳細表示へ
D40: 構成情報 | BN40: で
D41: シート 段 | J41: E | O41: 原紙 | X41: 印刷 | AI41: エンボス | AT41: メーカ | BN41: 新規登録画面で「登録」、登録後は「参照」画面に遷移
F42: 表 | BN42: 「参照」で開いて「訂正」「削除」に切替可能
F43: 中 | BN43: というような動線ではなくて、mcframeやオフコンの画面をそのまま再現したような
F44: 裏 | BN44: /patterns 一画面に全部詰め込むようなイメージ?
BN45: mcframeと似たような操作性にしたいという想定と考えられるので反対はしないが
D46: 抜方向 | J46: リスト選択 | AD46: 複版 | AI46: リスト選択 | BN46: 適切に切り分けて開発していただきたい
D47: シート寸法 | M47: ×
D48: 刃渡り寸法 | M48: × | R48: 付数 | AD48: 個数 | AO48: 色数 | AW48: 本数
D49: フレキソ版厚 | R49: シリンダーサイズ
...

Sheet mcf画面イメージ
A1: mcframe 7 | K1: 文書名 | U1: モジュールID | Z1: =表紙!$AJ$63 -> MS | AE1: モジュール名 | AJ1: =表紙!$AX$63 -> 見積管理 | AS1: 文書番号 | AZ1: Version | BF1: Rev.
K2: =表紙!O64 -> 画面機能 | U2: ｻﾌﾞﾓｼﾞｭｰﾙID | Z2: =表紙!$AJ$64 -> MSBB | AE2: ｻﾌﾞﾓｼﾞｭｰﾙ名 | AJ2: =表紙!$AX$64 -> Webシステム | AS2: =表紙!$BL$64 -> M7-US-1140 | AZ2: =表紙!$BU$64 -> 1.0.0 | BF2: =表紙!$CB$64 -> 4
K3: =RIGHT(CELL("filename",$A$1),LEN(CELL("filename",$A$1))-FIND("]",CELL("filename",$A$1))) -> mcf画面イメージ | U3: 表題 | Z3: =表紙!$AJ$65 -> アドオン画面 | AE3: =表紙!$AQ$65 -> Web版型・木型マスタ
A5: 画面イメージ

Sheet 検索画面
D2: 〇参照
D4: 版型№ | J4: コード | O4: 名称 | AE4: Rev | AJ4: Rev番号 | AQ4: 適用開始日 | AW4: 44756
D5: 版型分類
D6: 得意先 | J6: コード | O6: 名称 | AE6: 新版区分
D7: 製品品目 | J7: コード | O7: 品名１ | AD7: 品名２
D9: 工程 | J9: コード | O9: 名称 | AE9: 通し数 | AQ9: 以上
D10: 発注先 | J10: コード | O10: 名称
D11: 入荷日 | O11: ～
D13: 棚・ライン | J13: コード | O13: 名称
D14: 廃棄予定日 | J14: 44756 | P14: 返却予定日 | U14: 44756 | AA14: 返却日 | AD14: 44756
BI15: 検索
D17: 版型№ | I17: 名称 | Y17: Rev番号 | AE17: 版型分類 | AJ17: 製品品目 | AO17: 名称 | BH17: 通し数 | BL17: 入荷日 | BR17: 返却予定日 | BX17: 返却日 | CD17: 工程 | CG17: 棚 | CI17: 最終加工先 | CN17: 新版区分 | CS17: 刃渡り | CV17: 色数 | CY17: ・・・・・ | DB17: その他登録されている項目
D18: コード | I18: 名称 | Y18: Rev番号 | AE18: 木型 | AJ18: コード | AO18: 品名１＋品名２ | BL18: 44756 | BR18: 44756 | BX18: 44756
D19: コード | I19: 名称 | Y19: Rev番号 | AE19: 木型 | AJ19: コード | AO19: 品名１＋品名２ | BL19: 44756 | BR19: 44756 | BX19: 44756
D20: コード | I20: 名称 | Y20: Rev番号 | AE20: 木型 | AJ20: コード | AO20: 品名１＋品名２ | BL20: 44756 | BR20: 44756 | BX20: 44756
D21: コード | I21: 名称 | Y21: Rev番号 | AE21: 木型 | AJ21: コード | AO21: 品名１＋品名２ | BL21: 44756 | BR21: 44756 | BX21: 44756
D22: コード | I22: 名称 | Y22: Rev番号 | AE22: ゴム版 | AJ22: コード | AO22: 品名１＋品名２ | BL22: 44756 | BR22: 44756 | BX22: 44756
D23: コード | I23: 名称 | Y23: Rev番号 | AE23: オフ版 | AJ23: コード | AO23: 品名１＋品名２ | BL23: 44756 | BR23: 44756 | BX23: 44756
D24: コード | I24: 名称 | Y24: Rev番号 | AE24: オフ版 | AJ24: コード | AO24: 品名１＋品名２ | BL24: 44756 | BR24: 44756 | BX24: 44756
D25: コード | I25: 名称 | Y25: Rev番号 | AE25: ゴム版 | AJ25: コード | AO25: 品名１＋品名２ | BL25: 44756 | BR25: 44756 | BX25: 44756
D26: コード | I26: 名称 | Y26: Rev番号 | AE26: オフ版 | AJ26: コード | AO26: 品名１＋品名２ | BL26: 44756 | BR26: 44756 | BX26: 44756
D27: コード | I27: 名称 | Y27: Rev番号 | AE27: 見落とし | AJ27: コード | AO27: 品名１＋品名２ | BL27: 44756 | BR27: 44756 | BX27: 44756
D28: コード | I28: 名称 | Y28: Rev番号 | AE28: 窓開け | AJ28: コード | AO28: 品名１＋品名２ | BL28: 44756 | BR28: 44756 | BX28: 44756
D29: コード | I29: 名称 | Y29: Rev番号 | AE29: 箔版 | AJ29: コード | AO29: 品名１＋品名２ | BL29: 44756 | BR29: 44756 | BX29: 44756
D30: コード | I30: 名称 | Y30: Rev番号 | AJ30: コード | AO30: 品名１＋品名２ | BL30: 44756 | BR30: 44756 | BX30: 44756
D31: コード | I31: 名称 | Y31: Rev番号 | AJ31: コード | AO31: 品名１＋品名２ | BL31: 44756 | BR31: 44756 | BX31: 44756
D32: コード | I32: 名称 | Y32: Rev番号 | AJ32: コード | AO32: 品名１＋品名２ | BL32: 44756 | BR32: 44756 | BX32: 44756
D33: コード | I33: 名称 | Y33: Rev番号 | AJ33: コード | AO33: 品名１＋品名２ | BL33: 44756 | BR33: 44756 | BX33: 44756
D36: 版型メンテ

Sheet 登録画面
D2: ◎登録 | I2: 〇訂正 | N2: 〇削除
D4: 版型№ | J4: コード | O4: 名称 | AE4: 適用開始日 | AK4: 44756
E5: Rev | J5: Rev番号
D6: 得意先 | J6: コード | O6: 名称 | AE6: 新版区分
D7: 製品品目 | J7: コード | O7: 品名１ | AD7: 品名２
D9: 工程 | J9: コード | O9: 名称 | AE9: 版型分類
D10: 最終加工場所 | J10: コード | O10: 名称 | AE10: 実績日 | AJ10: 44756
D12: 刃渡り寸法 | J12: コード | O12: × | P12: コード | Z12: 付数 | AG12: 個数 | AN12: 色数
D13: 落丁型 | P13: 置き版 | T13: リスト選択 | Z13: ハンマー | AD13: リスト選択 | AJ13: 見落とし型 | AO13: リスト選択
D15: 備考
D17: 発注先 | J17: コード | O17: 名称 | AE17: 入荷実績日 | AK17: 44756 | AR17: 金額
D19: 棚・ライン | J19: コード | O19: 名称
D20: 廃棄予定日 | J20: 44756 | P20: 返却予定日 | U20: 44756 | AA20: 返却日 | AD20: 44756 | AJ20: 返却理由
D23: ■過去履歴
D25: 適用開始日 | J25: Rev | M25: 発注先 | AH25: 通し数 | AO25: 廃棄予定日 | AU25: 返却予定日 | BA25: 返却日 | BG25: 返却理由
D26: 40404 | J26: 1 | M26: コード | R26: 名称 | AO26: 44756 | AU26: 44756 | BA26: 44756
D27: 41348 | J27: 2 | M27: コード | R27: 名称 | AO27: 44756 | AU27: 44756 | BA27: 44756
D28: 42445 | J28: 3 | M28: コード | R28: 名称 | AO28: 44756 | AU28: 44756 | BA28: 44756
D29: 43175 | J29: 4 | M29: コード | R29: 名称 | AO29: 44756 | AU29: 44756 | BA29: 44756
D30: 44271 | J30: 5 | M30: コード | R30: 名称 | AO30: 44756 | AU30: 44756 | BA30: 44756

Sheet 項目説明
A1: =表紙!A54 -> Webシステム | K1: 文書名 | U1: モジュールID | Z1: =表紙!$AJ$63 -> MS | AE1: モジュール名 | AJ1: =表紙!$AX$63 -> 見積管理 | AS1: 文書番号 | AZ1: Version | BF1: Rev.
K2: =表紙!O64 -> 画面機能 | U2: ｻﾌﾞﾓｼﾞｭｰﾙID | Z2: =表紙!$AJ$64 -> MSBB | AE2: ｻﾌﾞﾓｼﾞｭｰﾙ名 | AJ2: =表紙!$AX$64 -> Webシステム | AS2: =表紙!$BL$64 -> M7-US-1140 | AZ2: =表紙!$BU$64 -> 1.0.0 | BF2: =表紙!$CB$64 -> 4
K3: =RIGHT(CELL("filename",$A$1),LEN(CELL("filename",$A$1))-FIND("]",CELL("filename",$A$1))) -> 項目説明 | U3: 表題 | Z3: =表紙!$AJ$65 -> アドオン画面 | AE3: =表紙!$AQ$65 -> Web版型・木型マスタ
B5: 操作種別 | N5: 説明 | BE5: Ｗ | BF5: 型 | BG5: 参 | BH5: 必 | BI5: 入 | BJ5: 非 | BK5: 検 | BM5: CP指摘 2022/09/22 三宅 | CM5: MDSOL回答 2022/10/31 石田 WEB画面説明書（共通）.xlsxの挿絵_画面説明書の見方に記載致しました
A6: ● | B6: 登録 | M6: 登録モード 初期選択 | BE6: R | BM6: 左端の● 〇 や [リ 型 参 コ 入 非 Ｏ] | CZ6: 2022/11/01 落合 問題なし
A7: ● | B7: 改定 | M7: 改定モード 改定は最大REV＋１にREVが更新される | BE7: R | BM7: リのCB などと見ても各項目の内容が分からないのですが凡例はどこかに無いのでしょうか
A8: ● | B8: 訂正 | M8: 訂正モード 訂正はREVそのまま | BE8: R | BM8: 読み解いた範囲では「型」がデータ型とUIの種類がごちゃまぜになっているようで意味不明です
A9: ● | B9: 削除 | M9: 削除モード | BE9: R | BM9: Bは boolean ではなく button のようですが Sは stirng? のようで textarea と input type="text" の違いとかは考慮されていない様子です
A10: ● | B10: 参照 | M10: 参照モード | BE10: R | BM10: (ただしこの表を詳細に埋める必要性は感じないのでわざわざ変える必要はないと考えます)
B12: 検索項目 | N12: 説明 | BE12: Ｗ | BF12: 型 | BG12: 参 | BH12: 必 | BI12: 入 | BJ12: 非 | BK12: 検
A13: 〇 | B13: 版型No | M13: 入力後(Selected)、検索処理を行う。 | Z13: ※操作種別が登録以外の場合、入力可能 | BE13: A | BF13: S | BG13: 参 | BK13: 検
B14: Rev | Z14: ※操作種別が改定・参照時、入力可能(訂正・削除時は、版型No毎の最大値を表示) | BE14: T | BF14: S | BG14: 参
B16: 登録項目 | N16: 説明 | BE16: Ｗ | BF16: 型 | BG16: 参 | BH16: 必 | BI16: 入 | BJ16: 非 | BK16: 検
A17: ● | B17: 拠点 | M17: 事業所 | BE17: C | BF17: S | BG17: 参 | BH17: 必
B19: 登録項目 - 基本情報 | N19: 説明 | BE19: Ｗ | BF19: 型 | BG19: 参 | BH19: 必 | BI19: 入 | BJ19: 非 | BK19: 検
A20: ● | B20: 決定見積NO | M20: 見積計算書の決定見積NO | BE20: A | BF20: S | BH20: 必 | BK20: 検
B21: 案件NO | M21: 見積計算書NOに対応する案件NO | BE21: T | BF21: S | BG21: 参
A22: ● | B22: 版型名 | M22: 版型名称 | BE22: T | BF22: S | BH22: 必
B23: 売上可否区分 | M23: 売上できるかどうかの区分 | BE23: C | BF23: S
B24: 手配NO | M24: 手配NO1 | BE24: T | BF24: S
B25: 版型No | M25: 版型の番号 | BE25: T | BF25: S
B26: Rev | M26: Rev＝最大Rev＋１ 検索後の表示時、自動設定。※操作種別が改定の場合、登録レコードの最大REVデータを表示する。 | BE26: T | BF26: S
A27: ● | B27: 適用開始日 | M27: マスタの適用開始日 | BE27: カ | BF27: D | BH27: 必
A28: ● | B28: 得意先 | M28: 決定見積NOから得意先を表示する。 | BE28: A | BF28: S | BG28: 参 | BH28: 必 | BK28: 検
A29: ● | B29: 代表製品CD | M29: 版型NOを最初に設定した製品CDを製品マスタから設定する。 | BE29: A | BF29: S | BG29: 参 | BH29: 必 | BK29: 検
B30: 新版区分 | M30: 操作種別=新規時は、「新版」をセット、改定時は「再販」をセットする | BE30: C | BF30: S
A31: ● | B31: 工程 | M31: 入力後※操作種別が登録の場合 工程:300フレキソの時、ゴム型 工程:450オフセットの時、オフ型 工程:600トムソンの時、木型 工程:650箔押の時、箔版 版型分類を初期値セット | BE31: A | BF31: S
A32: ● | B32: 版型分類 | M32: 版型の分類 | BE32: C | BF32: S
A33: ● | B33: 最終加工場所 | M33: 最終の加工場所 | BE33: C | BF33: S
B34: 実績日（最終使用日） | M34: 最終使用日を表示する | BE34: カ | BF34: D
BM35: CP指摘 2022/09/21 土屋 複版：1：有、0：無し は不要でしたでしょうか | CO35: MDSOL回答 2022/10/31 石田 追加致しました。 | DK35: 2022/11/01 落合 問題なし
B36: 登録項目 - 構成情報 | N36: 説明 | BE36: Ｗ | BF36: 型 | BG36: 参 | BH36: 必 | BI36: 入 | BJ36: 非 | BK36: 検
B37: シート段 | M37: 段を表示する | BE37: T | BF37: S | BM37: Rev3.0 シート段 ～ メーカ(裏)は表示項目
B38: 原紙コード(表) | M38: 原紙コード(表)を表示する | BE38: T | BF38: S
B39: 印刷コード(表) | M39: 印刷コード(表)を表示する | BE39: T | BF39: S
B40: エンボスコード(表) | M40: エンボスコード(表)を表示する | BE40: T | BF40: S
B41: メーカ(表) | M41: メーカ(表)を表示する | BE41: T | BF41: S
B42: 原紙コード(中) | M42: 原紙コード(中)を表示する | BE42: T | BF42: S
B43: 印刷コード(中) | M43: 印刷コード(中)を表示する | BE43: T | BF43: S
B44: エンボスコード(中) | M44: エンボスコード(中)を表示する | BE44: T | BF44: S
...

Sheet 画面遷移
A1: =表紙!A54 -> Webシステム | K1: 文書名 | U1: モジュールID | Z1: =表紙!$AJ$63 -> MS | AE1: モジュール名 | AJ1: =表紙!$AX$63 -> 見積管理 | AS1: 文書番号 | AZ1: Version | BF1: Rev.
K2: =表紙!O64 -> 画面機能 | U2: ｻﾌﾞﾓｼﾞｭｰﾙID | Z2: =表紙!$AJ$64 -> MSBB | AE2: ｻﾌﾞﾓｼﾞｭｰﾙ名 | AJ2: =表紙!$AX$64 -> Webシステム | AS2: =表紙!$BL$64 -> M7-US-1140 | AZ2: =表紙!$BU$64 -> 1.0.0 | BF2: =表紙!$CB$64 -> 4
K3: =RIGHT(CELL("filename",$A$1),LEN(CELL("filename",$A$1))-FIND("]",CELL("filename",$A$1))) -> 画面遷移 | U3: 表題 | Z3: =表紙!$AJ$65 -> アドオン画面 | AE3: =表紙!$AQ$65 -> Web版型・木型マスタ
A5: ID | D5: 処理名 | Y5: ダブルクリック対象 | AH5: ダブルクリック処理条件
A6: S01 | D6: なし
BL7: CP指摘 2022/09/21 土屋 版型Noの検索画面など虫眼鏡が付いている検索画面への記載が必要かと思います | BU7: MDSOL回答 2022/10/31 石田 検索に関しては、【MSBBPA000】_共通設計書_アドオン(Webシステム共通仕様)にて定義しております。
B8: 遷移処理 | BU8: 2022/11/01 落合 問題なし
B9: 遷移元画面ＩＤ | I9: MSBBPA150
B10: 遷移元画面名 | I10: Web版型・木型マスタ一覧照会
B11: 遷移先画面ＩＤ | I11: MSBBPA140
B12: 遷移先画面名 | I12: Web版型・木型マスタ
B13: 遷移条件 | I13: Web版型・木型マスタ一覧照会画面の一覧表示部データから一つのみ選択の後、選択ボタンをクリックします
B14: 引継項目・種別 | I14: 遷移元画面項目 | AJ14: 遷移先画面項目
I15: 版号Rev | AJ15: 版号Rev
I16: 版型NO | AJ16: 版型NO
B18: 遷移後のアクション | I18: 操作種別が「参照」をします
A20: ID | D20: 処理名 | Y20: ダブルクリック対象 | AH20: ダブルクリック処理条件
A21: S02 | D21: なし
B23: 遷移処理
B24: 遷移元画面ＩＤ | I24: なし
B25: 遷移元画面名 | I25: メニュー
B26: 遷移先画面ＩＤ | I26: MSBBPA140
B27: 遷移先画面名 | I27: Web版型・木型マスタ
B28: 遷移条件 | I28: なし
B29: 引継項目・種別 | I29: 遷移元画面項目 | AJ29: 遷移先画面項目
I30: メンニュー一覧のkey | AJ30: なし
B32: 遷移後のアクション | I32: 画面を初期化して、操作種別が「登録」をします

Sheet 処理概要
A1: =表紙!A54 -> Webシステム | K1: 文書名 | U1: モジュールID | Z1: =表紙!$AJ$63 -> MS | AE1: モジュール名 | AJ1: =表紙!$AX$63 -> 見積管理 | AS1: 文書番号 | AZ1: Version | BF1: Rev.
K2: =表紙!O64 -> 画面機能 | U2: ｻﾌﾞﾓｼﾞｭｰﾙID | Z2: =表紙!$AJ$64 -> MSBB | AE2: ｻﾌﾞﾓｼﾞｭｰﾙ名 | AJ2: =表紙!$AX$64 -> Webシステム | AS2: =表紙!$BL$64 -> M7-US-1140 | AZ2: =表紙!$BU$64 -> 1.0.0 | BF2: =表紙!$CB$64 -> 4
K3: =RIGHT(CELL("filename",$A$1),LEN(CELL("filename",$A$1))-FIND("]",CELL("filename",$A$1))) -> 処理概要 | U3: 表題 | Z3: =表紙!$AJ$65 -> アドオン画面 | AE3: =表紙!$AQ$65 -> Web版型・木型マスタ
A5: No | B5: 入力 | J5: 処理 | BD5: 出力
A6: 1 | B6: 検索 | J6: 木型・版型管理マスタを検索する | BN6: CP指摘 2022/09/21 三宅 | CT6: MDSOL回答 2022/10/31 石田 検索に関しては、【MSBBPA000】_共通設計書_アドオン(Webシステム共通仕様)にて定義しております。遷移ではないので表現を変更しました。
C7: 操作種別=登録 | J7: 1. | K7: 決定見積NOを検索する | BO7: モーダルウインドウではなく「遷移」なのでしょうか
K8: 見積計算書一覧照会を表示する | BO8: 別ページに遷移して取得データを保持して元ページに戻ってくる制御は問題無く可能なのでしょうか
K9: →見積計算書一覧照会の選択後、結果を返す | BD9: 検索入出力仕様.No1 | BO9: 「画面遷移」シートは空のようです
A12: 2 | B12: 検索 | J12: 木型・版型管理マスタを検索する
C13: 操作種別 | J13: 1. | K13: 木型・版型管理マスタを検索する | BD13: 検索入出力仕様.No2 | BN13: CP指摘 2022/09/21 土屋 入力された検索条件とは何をさしていますでしょうか？この画面は他の版型検索画面があって、そこで版型Noが一意に特定された後に表示されるものではないのでしょうか | DY13: MDSOL回答 2022/10/31 石田 登録は、この画面からスタートになります。入力された検索条件とは版型Noを指します。 | FP13: 2022/11/04 土屋 問題なし(版型Noのみ検索対象であれば一意になる為問題なし。版型名が入力候補となると複数ヒットする可能性がある為NGの認識です)
D14: 改定・訂正・削除 | K14: 入力された検索条件で木型・版型管理マスタを検索し、画面に表示する
K15: 検索結果が0件の場合、メッセージを表示する | BD15: メッセージNo.1
J17: 2. | K17: 木型・版型管理の格納されている場所を検索する
K18: 取得した木型・版型の品目CDを用いて、現状在庫を検索し、格納されている場所を取得する
J20: 3. | K20: 製品CDを検索する
K21: 木型・版型Noを用いて製品マスタを検索し製品CD、および製品名１・２を取得する | BD21: 検索入出力仕様.No3 | BN21: Rev3.0 製品CDの検索入出力仕様.No3追加記載
A24: 3 | B24: 登録 | J24: 木型・版型管理マスタを登録する
B25: 登録前チェック | J25: 1. | K25: 必須項目のチェックを行う
K26: 必須項目に入力されているかチェックを行う | BN26: CP指摘 2022/09/21 三宅 「処理を終了する」とは？ メッセージを出して登録を確定させないだけでは？ | CW26: MDSOL回答 2022/10/31 石田 後続処理を終了することを指します。
K27: エラーの場合メッセージを表示し、処理を終了する | BD27: メッセージNo.3
BN28: CP指摘 2022/09/22 三宅 売上可でないのに見積価格 決定価格 が入っている、フレキソ工程でないのにフレキソ版厚の値を持っている、等は許容するか否か要検討 | DO28: MDSOL回答 2022/10/31 石田 現仕様では、フリーです。チェック要望があれば追記します。
J29: 2 | K29: 適用開始日と適用終了日の前後関係のチェックを行う
K30: 適用終了日が適用開始日より前になっていないかチェックを行う
K31: エラーの場合メッセージを表示し、処理を終了する | BD31: メッセージNo.4
J33: 3 | K33: 適用開始日と廃棄予定日の前後関係のチェックを行う
K34: 廃棄予定日が適用開始日より前になっていないかチェックを行う
K35: エラーの場合メッセージを表示し、処理を終了する | BD35: メッセージNo.5
J37: 4 | K37: 適用終了日と廃棄予定日の前後関係のチェックを行う
K38: 廃棄予定日が適用終了日より前になっていないかチェックを行う
K39: エラーの場合メッセージを表示し、処理を終了する | BD39: メッセージNo.6
B41: 登録処理 | J41: 5 | K41: 対象データを登録する
L42: 詳細は、処理概要(登録)参照
A45: 3 | B45: 改定 | J45: 木型・版型管理マスタを登録する
B46: 登録前チェック | J46: 1 | K46: 必須項目のチェックを行う
K47: 必須項目に入力されているかチェックを行う | BD47: メッセージNo.3
K48: エラーの場合メッセージを表示し、処理を終了する | BN48: CP指摘 2022/09/22 三宅 新Revの適用開始日が前Revの適用終了日の翌日かどうかのチェックが必要だと思います(入力ミスで重複期間や適用されない期間が存在しないように) あるいは改定時は開始日は自動でセットされ変更不可にするなど | EN48: MDSOL回答 2022/10/31 石田 適用終了日を自動セットとなります。適用開始日をセットし、追加で(現在日～適用開始日)のデータをセットすると動きが不正となるため。未来日程を１つしか入れれない制御を追加します。+以前の日付はセットできないようにします。
J50: 2 | K50: 適用開始日と適用終了日の前後関係のチェックを行う
K51: 適用開始日を元に前REVの適用終了日をー1日で自動設定する。
K52: 未来日は一つしか入れれないように既存版
K53: エラーの場合メッセージを表示し、処理を終了する | BD53: メッセージNo.4
...

Sheet 処理詳細
A1: =表紙!A54 -> Webシステム | K1: 文書名 | U1: モジュールID | Z1: =表紙!$AJ$63 -> MS | AE1: モジュール名 | AJ1: =表紙!$AX$63 -> 見積管理 | AS1: 文書番号 | AZ1: Version | BF1: Rev.
K2: =表紙!O64 -> 画面機能 | U2: ｻﾌﾞﾓｼﾞｭｰﾙID | Z2: =表紙!$AJ$64 -> MSBB | AE2: ｻﾌﾞﾓｼﾞｭｰﾙ名 | AJ2: =表紙!$AX$64 -> Webシステム | AS2: =表紙!$BL$64 -> M7-US-1140 | AZ2: =表紙!$BU$64 -> 1.0.0 | BF2: =表紙!$CB$64 -> 4
K3: =RIGHT(CELL("filename",$A$1),LEN(CELL("filename",$A$1))-FIND("]",CELL("filename",$A$1))) -> 処理詳細 | U3: 表題 | Z3: =表紙!$AJ$65 -> アドオン画面 | AE3: =表紙!$AQ$65 -> Web版型・木型マスタ
A5: No | B5: 入力 | J5: 処理 | BD5: 出力
A6: 1 | B6: 初期表示
J7: 1.1 | L7: 遷移元メニューから
L8: 操作種別 | P8: ： | Q8: 「登録」を設定する
L9: 版型No | P9: ： | Q9: 版型NoとRev、変更不可とする 、Revが「１」を設定
L10: その他 | P10: ： | Q10: 活性とする、各項目のクリア処理と初期値設定を行う
J12: 1.2 | L12: 遷移元【MSBBPA150】_木型マスタ一覧照会から
L13: 操作種別 | P13: ： | Q13: 「参照」を設定する | FP13: 2022/11/04 土屋 問題なし(版型Noのみ検索対象であれば一意になる為問題なし。版型名が入力候補となると複数ヒットする可能性がある為NGの認識です)
L14: 全画面が非活性とする
A16: 2 | B16: 画面操作
J17: 2.1 | L17: 操作種別ボタンの制御処理
K18: 2.1.1 | N18: [操作種別]ラジオが「改定」の場合、
N19: 版型名は編集不可、または 版型発注書、ラベル発行ボタンが非活性。その他、編集可、ボタンが活性。
K20: 2.1.2 | N20: [操作種別]が「訂正」の場合、
N21: 「改定」と同じ
K22: 2.1.3 | N22: [操作種別]が「削除」の場合、
N23: 版型No検索ボタンと登録ボタンが活性
K24: 2.1.4 | N24: [操作種別]が「参照」の場合、
N25: 全画面が非活性とする
N27: ※操作種別切り替え処理は、以下の通りです。
A39: 3 | B39: 検索
J40: 3.1 | L40: 版型Noの検索ボタン処理
L41: 版型No検索のポップアップ画面へを遷移して、抽出条件をもとに結果を表示したところ、
L42: 選択結果(1行)を遷移元画面（WEB版型・木型情報）に返す
L44: 版型No検索_SQLリソースの検索仕様
L45: 【MSBBPACOM】_共通設計書_アドオン(Web共通ロジック)の「処理詳細(共通検索)」シート」を参照する。
J47: 3.2 | L47: 決定見積NOの検索ボタン処理
L48: 決定見積No検索のポップアップ画面へを遷移して、抽出条件をもとに結果を表示したところ、
L49: 選択結果(1行)を遷移元画面（本画面の基本情報と構成情報を設定）に返す
L51: 決定見積NO検索_SQLリソースの検索仕様
L52: 【MSBBPACOM】_共通設計書_アドオン(Web共通ロジック)の「処理詳細(共通検索)」シート」を参照する。
J54: 3.3 | L54: 得意先の検索ボタン処理
L55: 取引先マスタ検索のポップアップ画面へを遷移して、抽出条件＜取引先コード＞あるいは、＜取引先名＞をもとに結果を表示したところ、
L56: 選択結果(1行)を遷移元画面（本画面の得意先コード、得意先名を設定）に返す
L58: 取引先マスタ検索_SQLリソースの検索仕様
L59: 【MSBBPACOM】_共通設計書_アドオン(Web共通ロジック)の「処理詳細(共通検索)」シート」を参照する。
L61: 製品コードの検索ボタン処理
...

Sheet 画面項目制御
J2: 操作種別 | O2: 登録 | R2: 改定 | U2: 訂正 | X2: 削除 | AA2: 参照 | AD2: 登録後 | AG2: 改定後 | AJ2: 訂正後/削除後 | AN2: R | AP2: 有効(必須)
B3: 画面項目 | AN3: E | AP3: 有効
B4: 検索条件 | G4: 版型No | O4: D | R4: E | U4: E | X4: E | AA4: E | AD4: D | AG4: E | AJ4: E | AN4: RO | AP4: 読取のみ
G5: Rev | O5: D | R5: E | U5: RO | X5: RO | AA5: E | AD5: D | AG5: E | AJ5: RO | AN5: D | AP5: 無効
B6: 登録項目 | G6: 拠点 | O6: R | R6: R | U6: R | X6: RO | AA6: RO | AD6: RO | AG6: RO | AJ6: RO | AN6: I | AP6: 非表示
B7: 登録項目 - 基本情報 | G7: 決定見積NO | O7: R | R7: R | U7: R | X7: RO | AA7: RO | AD7: RO | AG7: RO | AJ7: RO
G8: 案件NO | O8: RO | R8: RO | U8: RO | X8: RO | AA8: RO | AD8: RO | AG8: RO | AJ8: RO
G9: 版型名 | O9: R | R9: R | U9: R | X9: RO | AA9: RO | AD9: RO | AG9: RO | AJ9: RO
G10: 売上可否区分 | O10: RO | R10: RO | U10: RO | X10: RO | AA10: RO | AD10: RO | AG10: RO | AJ10: RO
G11: 手配NO | O11: RO | R11: RO | U11: RO | X11: RO | AA11: RO | AD11: RO | AG11: RO | AJ11: RO
G12: 版型No | O12: RO | R12: RO | U12: RO | X12: RO | AA12: RO | AD12: RO | AG12: RO | AJ12: RO
G13: Rev | O13: RO | R13: RO | U13: RO | X13: RO | AA13: RO | AD13: RO | AG13: RO | AJ13: RO
G14: 適用開始日 | O14: R | R14: R | U14: R | X14: RO | AA14: RO | AD14: RO | AG14: RO | AJ14: RO
G15: 得意先 | O15: R | R15: R | U15: R | X15: RO | AA15: RO | AD15: RO | AG15: RO | AJ15: RO
G16: 代表製品CD | O16: R | R16: R | U16: R | X16: RO | AA16: RO | AD16: RO | AG16: RO | AJ16: RO
G17: 新版区分 | O17: RO | R17: RO | U17: RO | X17: RO | AA17: RO | AD17: RO | AG17: RO | AJ17: RO
G18: 工程 | O18: E | R18: E | U18: E | X18: RO | AA18: RO | AD18: RO | AG18: RO | AJ18: RO
G19: 版型分類 | O19: E | R19: E | U19: E | X19: RO | AA19: RO | AD19: RO | AG19: RO | AJ19: RO
... G21: 実績日（最終使用日） | O21: RO | R21: RO | U21: RO | X21: RO | AA21: RO | AD21: RO | AG21: RO | AJ21: RO
B22: 登録項目 - 構成情報 | G22: シート段 | O22: RO | R22: RO | U22: RO | X22: RO | AA22: RO | AD22: RO | AG22: RO | AJ22: RO
G23: 原紙コード(表) | O23: RO | R23: RO | U23: RO | X23: RO | AA23: RO | AD23: RO | AG23: RO | AJ23: RO
G24: 印刷コード(表) | O24: RO | R24: RO | U24: RO | X24: RO | AA24: RO | AD24: RO | AG24: RO | AJ24: RO
G25: エンボスコード(表) | O25: RO | R25: RO | U25: RO | X25: RO | AA25: RO | AD25: RO | AG25: RO | AJ25: RO
G26: メーカ(表) | O26: RO | R26: RO | U26: RO | X26: RO | AA26: RO | AD26: RO | AG26: RO | AJ26: RO
G27: 原紙コード(中) | O27: RO | R27: RO | U27: RO | X27: RO | AA27: RO | AD27: RO | AG27: RO | AJ27: RO
G28: 印刷コード(中) | O28: RO | R28: RO | U28: RO | X28: RO | AA28: RO | AD28: RO | AG28: RO | AJ28: RO
G29: エンボスコード(中) | O29: RO | R29: RO | U29: RO | X29: RO | AA29: RO | AD29: RO | AG29: RO | AJ29: RO
G30: メーカ(中) | O30: RO | R30: RO | U30: RO | X30: RO | AA30: RO | AD30: RO | AG30: RO | AJ30: RO
G31: 原紙コード(裏) | O31: RO | R31: RO | U31: RO | X31: RO | AA31: RO | AD31: RO | AG31: RO | AJ31: RO
G32: 印刷コード(裏) | O32: RO | R32: RO | U32: RO | X32: RO | AA32: RO | AD32: RO | AG32: RO | AJ32: RO
G33: エンボスコード(裏) | O33: RO | R33: RO | U33: RO | X33: RO | AA33: RO | AD33: RO | AG33: RO | AJ33: RO
G34: メーカ(裏) | O34: RO | R34: RO | U34: RO | X34: RO | AA34: RO | AD34: RO | AG34: RO | AJ34: RO
... G70: 備考 | O70: E | R70: E | U70: E | X70: RO | AA70: RO | AD70: RO | AG70: RO | AJ70: RO
B71: 登録項目 - 添付情報 | G71: 表図面 | O71: E | R71: E | U71: E | X71: RO | AA71: RO | AD71: RO | AG71: RO | AJ71: RO
G72: 裏図面 | O72: E | R72: E | U72: E | X72: RO | AA72: RO | AD72: RO | AG72: RO | AJ72: RO
G73: 現物 | O73: E | R73: E | U73: E | X73: RO | AA73: RO | AD73: RO | AG73: RO | AJ73: RO
G74: 版下 | O74: E | R74: E | U74: E | X74: RO | AA74: RO | AD74: RO | AG74: RO | AJ74: RO
G75: ポジ | O75: E | R75: E | U75: E | X75: RO | AA75: RO | AD75: RO | AG75: RO | AJ75: RO
G76: ネガ | O76: E | R76: E | U76: E | X76: RO | AA76: RO | AD76: RO | AG76: RO | AJ76: RO
G77: MO | O77: E | R77: E | U77: E | X77: RO | AA77: RO | AD77: RO | AG77: RO | AJ77: RO
...

Sheet 処理概要(登録)
A1: =表紙!A54 -> Webシステム | K1: 文書名 | U1: モジュールID | Z1: =表紙!$AJ$63 -> MS | AE1: モジュール名 | AJ1: =表紙!$AX$63 -> 見積管理 | AS1: 文書番号 | AZ1: Version | BF1: Rev.
K2: =表紙!O64 -> 画面機能 | U2: ｻﾌﾞﾓｼﾞｭｰﾙID | Z2: =表紙!$AJ$64 -> MSBB | AE2: ｻﾌﾞﾓｼﾞｭｰﾙ名 | AJ2: =表紙!$AX$64 -> Webシステム | AS2: =表紙!$BL$64 -> M7-US-1140 | AZ2: =表紙!$BU$64 -> 1.0.0 | BF2: =表紙!$CB$64 -> 4
K3: =RIGHT(CELL("filename",$A$1),LEN(CELL("filename",$A$1))-FIND("]",CELL("filename",$A$1))) -> 処理概要(登録) | U3: 表題 | Z3: =表紙!$AJ$65 -> アドオン画面 | AE3: =表紙!$AQ$65 -> Web版型・木型マスタ
A5: No | B5: 入力 | J5: 処理 | BD5: 出力
A6: 1 | B6: 登録 | J6: 木型・版型管理マスタを登録する
K8: 登録処理に関して、以下の処理を実施する
K9: 登録・改定・訂正・削除処理フロー
BM13: CP指摘 2022/09/22 三宅 これを見ると版型マスタ以外も更新がかかるようですが概要の関連図や処理・サービス関連図は版型マスタ単独にしか影響しないような記述です | DP13: MDSOL回答 2022/10/31 石田 品目マスタ連携、受注連携の更新内容についてはそれぞれの機能で記載しております。PEについては当機能で行うため更新入出力仕様（PE）に記載しております。
DQ14: 2022/11/01 落合 問題なし
AA17: 版型受注登録：WEB受注、WEB受注明細に新規登録する | BM17: Rev4.0 版型マスタ登録時の版型受注登録連携
L36: No | N36: 操作種別 | R36: 版型マスタ登録 | X36: 品目マスタ連携 | AD36: 受注連携 | AJ36: PE API連携
L37: 1 | N37: 登録 | R37: 新規 | X37: 新規 | AD37: 新規 | AJ37: 新規
L38: 2 | N38: 改定 | R38: 改定 | X38: 更新 | AD38: 新規 | AJ38: 新規 | BM38: CP指摘 2022/09/21 版型マスタ登録の操作種別が改定時について、データの作り上を詳しく記載して下さい | CY38: MDSOL回答 2022/10/31 石田 更新入出力仕様（改定）で記載しております。
L39: 3 | N39: 訂正 | R39: 更新 | X39: 更新 | AD39: 更新 | AJ39: 更新 | BM39: CP指摘 2022/09/21 版型マスタ登録の操作種別が訂正時の訂正は更新ではないでしょうか | CY39: MDSOL回答 2022/10/31 石田 訂正致しました。
L40: 4 | N40: 削除 | R40: 更新(論理削除) | X40: 更新(論理削除) | AD40: 更新(論理削除) | AJ40: 削除
R41: ※更新入出力仕様

Sheet 処理・サービス関連図
A1: =表紙!A54 -> Webシステム | K1: 文書名 | U1: モジュールID | Z1: =表紙!$AJ$63 -> MS | AE1: モジュール名 | AJ1: =表紙!$AX$63 -> 見積管理 | AS1: 文書番号 | AZ1: Version | BF1: Rev.
K2: =表紙!O64 -> 画面機能 | U2: ｻﾌﾞﾓｼﾞｭｰﾙID | Z2: =表紙!$AJ$64 -> MSBB | AE2: ｻﾌﾞﾓｼﾞｭｰﾙ名 | AJ2: =表紙!$AX$64 -> Webシステム | AS2: =表紙!$BL$64 -> M7-US-1140 | AZ2: =表紙!$BU$64 -> 1.0.0 | BF2: =表紙!$CB$64 -> 4
K3: =RIGHT(CELL("filename",$A$1),LEN(CELL("filename",$A$1))-FIND("]",CELL("filename",$A$1))) -> 処理・サービス関連図 | U3: 表題 | Z3: =表紙!$AJ$65 -> アドオン画面 | AE3: =表紙!$AQ$65 -> Web版型・木型マスタ
AT6: 凡例 | BN6: CP指摘 2022/09/22 POWEREGG連携は概要シートでは版型データ参照は取り消し線で消され、見積ワークフローを参照するとなっている「木型・版型発注」は古い記述では？ | DQ6: MDSOL回答 2022/10/31 石田 停止絵致しました。
BE7: 画面
AX9: 外部システムサービス | BE9: サービス
AX11: アドオンテーブル | BE11: テーブル
BE13: サービス・テーブルのグループ
BE15: ファイル
BE17: 帳票
AV24: 木型・版型管理情報
AV25: 通し数、最終使用実績日を参照 | BN25: CP指摘 2022/09/22 三宅 「現状在庫」から「通し数集計バッチ」のようななんらかの処理を挟んだ「木型・版型管理マスタ」への矢印が必要ではないでしょうか(版マスタに在庫情報持たせるなら) | DU25: MDSOL回答 2022/10/31 石田 停止絵致しました。
BN27: Rev2.0 記述訂正(木型・版型管理情報を参照するように変更)

Sheet 検索入出力仕様
A1: =表紙!A54 -> Webシステム | K1: 文書名 | U1: モジュールID | Z1: =表紙!$AJ$63 -> MS | AE1: モジュール名 | AJ1: =表紙!$AX$63 -> 見積管理 | AS1: 文書番号 | AZ1: Version | BF1: Rev.
K2: =表紙!O64 -> 画面機能 | U2: ｻﾌﾞﾓｼﾞｭｰﾙID | Z2: =表紙!$AJ$64 -> MSBB | AE2: ｻﾌﾞﾓｼﾞｭｰﾙ名 | AJ2: =表紙!$AX$64 -> Webシステム | AS2: =表紙!$BL$64 -> M7-US-1140 | AZ2: =表紙!$BU$64 -> 1.0.0 | BF2: =表紙!$CB$64 -> 4
K3: =RIGHT(CELL("filename",$A$1),LEN(CELL("filename",$A$1))-FIND("]",CELL("filename",$A$1))) -> 検索入出力仕様 | U3: 表題 | Z3: =表紙!$AJ$65 -> アドオン画面 | AE3: =表紙!$AQ$65 -> Web版型・木型マスタ
A5: No | G5: 1 | H5: ボタン | L5: 検索 | S5: ロジック名称 | AH5: 備考 | AK5: 木型・版型管理マスタの検索
A6: 処理分類 | E6: 検索 | H6: ソート順
A7: No | C7: 転送先 | S7: 転送元 | AK7: 説明
C8: 種 | D8: オブジェクト | H8: 項目名 | S8: 種 | T8: オブジェクト | Z8: 項目名
A9: 1 | C9: 画 | D9: 基本情報 | H9: 決定見積NO | S9: T | T9: 見積計算書 | Z9: 見積計算書NO
A10: 2 | C10: 画 | D10: 基本情報 | H10: 案件NO | S10: T | T10: 見積計算書 | Z10: 案件NO(親)、(子)、(部材) | AK10: 表示形式：案件NO(親)+ '-' + 案件NO(子)+ '-' + 案件NO(部材) | BM10: Rev2.0 変更 (親)、(子)、(部材)の記述追加
A11: 3 | C11: 画 | D11: 基本情報 | H11: 版型名 | S11: T | T11: 見積計算書 | Z11: 顧客品名 | BM11: CP指摘 2022/09/21 土屋 顧客品名＋版型分類名にするとわかりやすいと思います | CP11: MDSOL回答 2022/10/31 石田 見積参照時には、分類はセットされておりません。 | DR11: 2022/11/04 土屋 問題なし(当該ページNo1は見積参照時の検索される記載内容と認識しました。No1とNo2の違いがヘッダーの備考に書かれているとわかりやすいかと思いました)
A12: 4 | C12: 画 | D12: 基本情報 | H12: 得意先 | S12: T | T12: 見積計算書 | Z12: 得意先
A13: 5 | C13: 画 | D13: 基本情報 | H13: 得意先名 | S13: T | T13: 取引先 | Z13: 得意先名
A14: 6 | C14: 画 | D14: 構成情報 | H14: シート段 | S14: T | T14: 見積計算書 | Z14: シート段 | BM14: Rev3.0 シート段 ～ メーカ(裏)は、製品マスタ参照
A15: 7 | C15: 画 | D15: 構成情報 | H15: 原紙コード(表) | S15: T | T15: 見積計算書 | Z15: 原紙コード(表)
A16: 8 | C16: 画 | D16: 構成情報 | H16: 原紙コード(表)名 | S16: T | T16: 原紙 | Z16: 原紙コード(表)名
A17: 9 | C17: 画 | D17: 構成情報 | H17: 印刷コード(表) | S17: T | T17: 見積計算書 | Z17: 印刷コード(表)
A18: 10 | C18: 画 | D18: 構成情報 | H18: 印刷コード(表)名 | S18: T | T18: 印刷 | Z18: 印刷コード(表)名
A19: 11 | C19: 画 | D19: 構成情報 | H19: エンボスコード(表) | S19: T | T19: 見積計算書 | Z19: エンボスコード(表)
A20: 12 | C20: 画 | D20: 構成情報 | H20: エンボスコード(表)名 | S20: T | T20: エンボス | Z20: エンボスコード(表)名
A21: 13 | C21: 画 | D21: 構成情報 | H21: メーカ(表) | S21: T | T21: 見積計算書 | Z21: メーカ(表)
A22: 14 | C22: 画 | D22: 構成情報 | H22: メーカ(表)名 | S22: T | T22: 取引先 | Z22: メーカ(表)名
A23: 15 | C23: 画 | D23: 構成情報 | H23: 原紙コード(中) | S23: T | T23: 見積計算書 | Z23: 原紙コード(中)
A24: 16 | C24: 画 | D24: 構成情報 | H24: 原紙コード(中)名 | S24: T | T24: 原紙 | Z24: 原紙コード(中)名
A25: 17 | C25: 画 | D25: 構成情報 | H25: 印刷コード(中) | S25: T | T25: 見積計算書 | Z25: 印刷コード(中)
A26: 18 | C26: 画 | D26: 構成情報 | H26: 印刷コード(中)名 | S26: T | T26: 印刷 | Z26: 印刷コード(中)名
... A43: 35 | C43: 画 | D43: 構成情報 | H43: 付数 | S43: T | T43: 見積計算書 | Z43: 付数
A46: No | G46: 2 | H46: ボタン | L46: 検索 | S46: ロジック名称 | AH46: 備考 | AK46: 木型・版型管理マスタの検索
A47: 処理分類 | E47: 検索 | H47: ソート順
A48: No | C48: 転送先 | S48: 転送元 | AK48: 説明
C49: 種 | D49: オブジェクト | H49: 項目名 | S49: 種 | T49: オブジェクト | Z49: 項目名
A50: 1 | C50: 画 | H50: 拠点 | S50: T | T50: 木型・版型管理マスタ | Z50: 拠点
A51: 2 | C51: 画 | H51: 拠点名 | S51: T | T51: 拠点マスタ | Z51: 拠点名
A52: 3 | C52: 画 | D52: 基本情報 | H52: 決定見積NO | S52: T | T52: 木型・版型管理マスタ | Z52: 決定見積NO
A53: 3 | C53: 画 | D53: 基本情報 | H53: 案件NO | S53: T | T53: 見積計算書 | Z53: 案件NO(親)、(子)、(部材) | AK53: 表示形式：案件NO(親)+ '-' + 案件NO(子)+ '-' + 案件NO(部材) | BM53: Rev2.0 変更 (親)、(子)、(部材)の記述追加
A54: 4 | C54: 画 | D54: 基本情報 | H54: 版型名 | S54: T | T54: 木型・版型管理マスタ | Z54: 版型名
A55: 5 | C55: 画 | D55: 基本情報 | H55: 売上可否区分 | S55: T | T55: 木型・版型管理マスタ | Z55: 売上可否区分
A56: 6 | C56: 画 | D56: 基本情報 | H56: 手配NO | S56: T | T56: 木型・版型管理マスタ | Z56: 手配NO | AK56: 受注連携後の後処理で手配NOを更新する
A57: 7 | C57: 画 | D57: 基本情報 | H57: 版型No | S57: T | T57: 木型・版型管理マスタ | Z57: 木型・版型No
A58: 8 | C58: 画 | D58: 基本情報 | H58: Rev | S58: T | T58: 木型・版型管理マスタ | Z58: Rev
A59: 9 | C59: 画 | D59: 基本情報 | H59: 適用開始日 | S59: T | T59: 木型・版型管理マスタ | Z59: 適用開始日
...

Sheet 更新入出力仕様
A1: =表紙!A54 -> Webシステム | K1: 文書名 | U1: モジュールID | Z1: =表紙!$AJ$63 -> MS | AE1: モジュール名 | AJ1: =表紙!$AX$63 -> 見積管理 | AS1: 文書番号 | AZ1: Version | BF1: Rev.
K2: =表紙!O64 -> 画面機能 | U2: ｻﾌﾞﾓｼﾞｭｰﾙID | Z2: =表紙!$AJ$64 -> MSBB | AE2: ｻﾌﾞﾓｼﾞｭｰﾙ名 | AJ2: =表紙!$AX$64 -> Webシステム | AS2: =表紙!$BL$64 -> M7-US-1140 | AZ2: =表紙!$BU$64 -> 1.0.0 | BF2: =表紙!$CB$64 -> 4
K3: =RIGHT(CELL("filename",$A$1),LEN(CELL("filename",$A$1))-FIND("]",CELL("filename",$A$1))) -> 更新入出力仕様 | U3: 表題 | Z3: =表紙!$AJ$65 -> アドオン画面 | AE3: =表紙!$AQ$65 -> Web版型・木型マスタ
A5: No | G5: 1 | H5: ボタン | L5: 登録する | S5: ロジック名称 | AH5: 備考 | AK5: 木型・版型管理マスタの登録
A6: 処理分類 | E6: 登録 | H6: ソート順
A7: No | C7: 転送先 | S7: 転送元 | AK7: 説明
C8: 種 | D8: オブジェクト | H8: 項目名 | S8: 種 | T8: オブジェクト | Z8: 項目名
A9: 1 | C9: T | D9: 木型・版型管理マスタ | H9: 拠点 | S9: 画 | T9: 版型マスタメンテ | Z9: 拠点
A10: 2 | C10: T | D10: 木型・版型管理マスタ | H10: 決定見積NO | S10: 画 | T10: 版型マスタメンテ | Z10: 決定見積NO
A11: 3 | C11: T | D11: 木型・版型管理マスタ | H11: 品目CD | S11: 画 | T11: 版型マスタメンテ | Z11: 品名
A12: 4 | C12: T | D12: 木型・版型管理マスタ | H12: 売上可否区分 | S12: 画 | T12: 版型マスタメンテ | Z12: 売上可否区分
A13: 5 | C13: T | D13: 木型・版型管理マスタ | H13: 手配NO | S13: 画 | T13: 版型マスタメンテ | Z13: 手配NO
A14: 6 | C14: T | D14: 木型・版型管理マスタ | H14: 版型No | S14: 画 | T14: 版型マスタメンテ | Z14: 版型No
A15: 7 | C15: T | D15: 木型・版型管理マスタ | H15: Rev | S15: 画 | T15: 版型マスタメンテ | Z15: Rev
A16: 8 | C16: T | D16: 木型・版型管理マスタ | H16: 適用開始日 | S16: 画 | T16: 版型マスタメンテ | Z16: 適用開始日
A17: 9 | C17: T | D17: 木型・版型管理マスタ | H17: 得意先 | S17: 画 | T17: 版型マスタメンテ | Z17: 得意先
A18: 10 | C18: T | D18: 木型・版型管理マスタ | H18: 代表製品CD | S18: 画 | T18: 版型マスタメンテ | Z18: 代表製品CD
A19: 11 | C19: T | D19: 木型・版型管理マスタ | H19: 新版区分 | S19: 画 | T19: 版型マスタメンテ | Z19: 新版区分
A20: 12 | C20: T | D20: 木型・版型管理マスタ | H20: 工程 | S20: 画 | T20: 版型マスタメンテ | Z20: 工程
... A23: 15 | C23: T | D23: 木型・版型管理マスタ | H23: 実績日 | S23: 画 | T23: 版型マスタメンテ | Z23: 実績日
A24: 16 | C24: T | D24: 木型・版型管理マスタ | H24: シート段 | S24: 画 | T24: 版型マスタメンテ | Z24: シート段 | BM24: Rev3.0 シート段 ～ メーカ(裏) 項目削除
A25: 17 | C25: T | D25: 木型・版型管理マスタ | H25: 原紙コード(表) | S25: 画 | T25: 版型マスタメンテ | Z25: 原紙コード(表) | BN25: DB項目→参照項目
A26: 18 | C26: T | D26: 木型・版型管理マスタ | H26: 印刷コード(表) | S26: 画 | T26: 版型マスタメンテ | Z26: 印刷コード(表)
A27: 19 | C27: T | D27: 木型・版型管理マスタ | H27: エンボスコード(表) | S27: 画 | T27: 版型マスタメンテ | Z27: エンボスコード(表)
A28: 20 | C28: T | D28: 木型・版型管理マスタ | H28: メーカ(表) | S28: 画 | T28: 版型マスタメンテ | Z28: メーカ(表)
A29: 21 | C29: T | D29: 木型・版型管理マスタ | H29: 原紙コード(中) | S29: 画 | T29: 版型マスタメンテ | Z29: 原紙コード(中)
A30: 22 | C30: T | D30: 木型・版型管理マスタ | H30: 印刷コード(中) | S30: 画 | T30: 版型マスタメンテ | Z30: 印刷コード(中)
A31: 23 | C31: T | D31: 木型・版型管理マスタ | H31: エンボスコード(中) | S31: 画 | T31: 版型マスタメンテ | Z31: エンボスコード(中)
A32: 24 | C32: T | D32: 木型・版型管理マスタ | H32: メーカ(中) | S32: 画 | T32: 版型マスタメンテ | Z32: メーカ(中)
A33: 25 | C33: T | D33: 木型・版型管理マスタ | H33: 原紙コード(裏) | S33: 画 | T33: 版型マスタメンテ | Z33: 原紙コード(裏)
A34: 26 | C34: T | D34: 木型・版型管理マスタ | H34: 印刷コード(裏) | S34: 画 | T34: 版型マスタメンテ | Z34: 印刷コード(裏)
A35: 27 | C35: T | D35: 木型・版型管理マスタ | H35: エンボスコード(裏) | S35: 画 | T35: 版型マスタメンテ | Z35: エンボスコード(裏)
A36: 28 | C36: T | D36: 木型・版型管理マスタ | H36: メーカ(裏) | S36: 画 | T36: 版型マスタメンテ | Z36: メーカ(裏)
A37: 29 | C37: T | D37: 木型・版型管理マスタ | H37: 抜方向 | S37: 画 | T37: 版型マスタメンテ | Z37: 抜方向
A38: 30 | C38: T | D38: 木型・版型管理マスタ | H38: 面付け(From) | S38: 画 | T38: 版型マスタメンテ | Z38: 面付け(From) | BM38: Rev3.0 面付け From ～ To 項目削除
A39: 31 | C39: T | D39: 木型・版型管理マスタ | H39: 面付け(To) | S39: 画 | T39: 版型マスタメンテ | Z39: 面付け(To)
A40: 32 | C40: T | D40: 木型・版型管理マスタ | H40: シート寸法(巾) | S40: 画 | T40: 版型マスタメンテ | Z40: シート寸法(巾)
A41: 33 | C41: T | D41: 木型・版型管理マスタ | H41: シート寸法(流れ) | S41: 画 | T41: 版型マスタメンテ | Z41: シート寸法(流れ)
A42: 34 | C42: T | D42: 木型・版型管理マスタ | H42: 刃渡り寸法(巾) | S42: 画 | T42: 版型マスタメンテ | Z42: 刃渡り寸法(巾)
A43: 35 | C43: T | D43: 木型・版型管理マスタ | H43: 刃渡り寸法(流れ) | S43: 画 | T43: 版型マスタメンテ | Z43: 刃渡り寸法(流れ)
...

Sheet 更新入出力仕様(版型受注)
A1: =表紙!A54 -> Webシステム | K1: 文書名 | U1: モジュールID | Z1: =表紙!$AJ$63 -> MS | AE1: モジュール名 | AJ1: =表紙!$AX$63 -> 見積管理 | AS1: 文書番号 | AZ1: Version | BF1: Rev.
K2: =表紙!O64 -> 画面機能 | U2: ｻﾌﾞﾓｼﾞｭｰﾙID | Z2: =表紙!$AJ$64 -> MSBB | AE2: ｻﾌﾞﾓｼﾞｭｰﾙ名 | AJ2: =表紙!$AX$64 -> Webシステム | AS2: =表紙!$BL$64 -> M7-US-1140 | AZ2: =表紙!$BU$64 -> 1.0.0 | BF2: =表紙!$CB$64 -> 4
K3: =RIGHT(CELL("filename",$A$1),LEN(CELL("filename",$A$1))-FIND("]",CELL("filename",$A$1))) -> 更新入出力仕様(版型受注) | U3: 表題 | Z3: =表紙!$AJ$65 -> アドオン画面 | AE3: =表紙!$AQ$65 -> Web版型・木型マスタ
A5: No | G5: 1 | H5: ボタン | L5: 更新する | S5: ロジック名称 | AH5: 備考 | AK5: WEB受注 | BM5: Rev4.0 版型マスタ登録時の版型受注登録連携
A6: 処理分類 | E6: 登録 | H6: ソート順
A7: No | C7: 転送先 | S7: 転送元 | AK7: 説明
C8: 種 | D8: オブジェクト | H8: 項目名 | S8: 種 | T8: オブジェクト | Z8: 項目名
A9: 1 | C9: T | D9: WEB受注 | H9: Web受注NO | Z9: 自動採番
A10: 2 | C10: T | D10: WEB受注 | H10: 得意先ＣＤ | S10: 画 | T10: 版型マスタメンテ | Z10: 得意先
A11: 3 | C11: T | D11: WEB受注 | H11: 受注区分 | AK11: 30：購買品
A12: 4 | C12: T | D12: WEB受注 | H12: 受注部門 | AK12: 登録ユーザの所属部門
A13: 5 | C13: T | D13: WEB受注 | H13: 受注日 | AK13: 処理日
A14: 6 | C14: T | D14: WEB受注 | H14: 客先納期 | S14: 画 | T14: 版型マスタメンテ | Z14: 納期
A15: 7 | C15: T | D15: WEB受注 | H15: 数量 | AK15: 固定:1
A16: 8 | C16: T | D16: WEB受注 | H16: 注文書NO | AK16: NULL
A17: 9 | C17: T | D17: WEB受注 | H17: 先方担当 | AK17: NULL
A18: 10 | C18: T | D18: WEB受注 | H18: 宛名 | AK18: NULL
A19: 11 | C19: T | D19: WEB受注 | H19: 運送会社 | AK19: NULL
A20: 12 | C20: T | D20: WEB受注 | H20: 出荷日時 | AK20: NULL
A21: 13 | C21: T | D21: WEB受注 | H21: 売価区分 | AK21: 個別単価
A22: 14 | C22: T | D22: WEB受注 | H22: 受注ＮＯ | AK22: NULL：mcframe7転送時採番
A23: 15 | C23: T | D23: WEB受注 | H23: ステータス | AK23: 0:未転送
A24: 16 | C24: T | D24: WEB受注 | H24: mcframe7転送ＦＬＧ | AK24: FALSE
A25: 17 | C25: T | D25: WEB受注 | H25: データ更新区分 | AK25: 固定:1
A26: 18 | C26: T | D26: WEB受注明細 | H26: Web受注NO | Z26: 自動採番
A27: 19 | C27: T | D27: WEB受注明細 | H27: Web受注明細ＮＯ | Z27: 自動採番
A28: 20 | C28: T | D28: WEB受注明細 | H28: 手配ＮＯ１ | Z28: 自動採番
A29: 21 | C29: T | D29: WEB受注明細 | H29: 手配ＮＯ２ | Z29: 案件NO
A30: 22 | C30: T | D30: WEB受注明細 | H30: 手配ＮＯ３ | Z30: 得意先CD
A31: 23 | C31: T | D31: WEB受注明細 | H31: 手配ＮＯ４ | AK31: NULL
A32: 24 | C32: T | D32: WEB受注明細 | H32: 製品コード | Z32: 自動採番
A33: 25 | C33: T | D33: WEB受注明細 | H33: 品目ＣＤ | Z33: 版型NO
A34: 26 | C34: T | D34: WEB受注明細 | H34: 枝番１ | AK34: NULL
A35: 27 | C35: T | D35: WEB受注明細 | H35: 枝番２ | AK35: NULL
A36: 28 | C36: T | D36: WEB受注明細 | H36: 枝番３ | AK36: NULL
A37: 29 | C37: T | D37: WEB受注明細 | H37: 製品区分_大 | AK37: 61:版・型
A38: 30 | C38: T | D38: WEB受注明細 | H38: 製品区分_中 | AK38: NULL
A39: 31 | C39: T | D39: WEB受注明細 | H39: 製品区分_小 | AK39: NULL
A40: 32 | C40: T | D40: WEB受注明細 | H40: 顧客品名１ | S40: 画 | T40: 版型マスタメンテ | Z40: 版型名
A41: 33 | C41: T | D41: WEB受注明細 | H41: 顧客品名２ | AK41: NULL
...

Sheet 更新入出力仕様(版型受注)_OLD
A1: =表紙!A54 -> Webシステム | K1: 文書名 | U1: モジュールID | Z1: =表紙!$AJ$63 -> MS | AE1: モジュール名 | AJ1: =表紙!$AX$63 -> 見積管理 | AS1: 文書番号 | AZ1: Version | BF1: Rev.
K2: =表紙!O64 -> 画面機能 | U2: ｻﾌﾞﾓｼﾞｭｰﾙID | Z2: =表紙!$AJ$64 -> MSBB | AE2: ｻﾌﾞﾓｼﾞｭｰﾙ名 | AJ2: =表紙!$AX$64 -> Webシステム | AS2: =表紙!$BL$64 -> M7-US-1140 | AZ2: =表紙!$BU$64 -> 1.0.0 | BF2: =表紙!$CB$64 -> 4
K3: =RIGHT(CELL("filename",$A$1),LEN(CELL("filename",$A$1))-FIND("]",CELL("filename",$A$1))) -> 更新入出力仕様(版型受注)_OLD | U3: 表題 | Z3: =表紙!$AJ$65 -> アドオン画面 | AE3: =表紙!$AQ$65 -> Web版型・木型マスタ
A5: No | G5: 1 | H5: ボタン | L5: 更新する | S5: ロジック名称 | AH5: 備考 | AK5: WEB受注
A6: 処理分類 | E6: 登録 | H6: ソート順
A7: No | C7: 転送先 | S7: 転送元 | AK7: 説明
C8: 種 | D8: オブジェクト | H8: 項目名 | S8: 種 | T8: オブジェクト | Z8: 項目名
A9: 1 | C9: T | D9: 受注 | H9: 受注部門 | S9: 画 | T9: 部門マスタ | Z9: 部門 | AK9: 起票者の部門
A10: 2 | C10: T | D10: 受注 | H10: 受注日 | S10: 画 | AK10: 起票日
A11: 3 | C11: T | D11: 受注 | H11: 受注区分 | S11: 画 | AK11: 商品
A12: 4 | C12: T | D12: 受注 | H12: 得意先 | S12: 画 | T12: 版型発注書 | Z12: 得意先
A13: 5 | C13: T | D13: 受注 | H13: 客先納期 | S13: 画 | T13: 版型発注書 | Z13: 納期
A14: 6 | C14: T | D14: 受注 | H14: 数量 | S14: 画 | AK14: 固定:1
A15: 7 | C15: T | D15: 受注 | H15: 注文書No | S15: 画 | AK15: NULL
A16: 8 | C16: T | D16: 受注 | H16: 先方担当 | S16: 画 | AK16: NULLNULL
A17: 9 | C17: T | D17: 受注 | H17: 宛名 | S17: 画 | AK17: NULL
A18: 10 | C18: T | D18: 受注 | H18: 運送会社 | S18: 画
A19: 11 | C19: T | D19: 受注 | H19: 出荷時間 | S19: 画
A20: 12 | C20: T | D20: 受注 | H20: 売価区分 | S20: 画 | T20: 版型発注書 | Z20: 売価区分
A21: 13 | C21: T | D21: 受注明細 | H21: № | S21: 画 | AK21: 自動採番
A22: 14 | C22: T | D22: 受注明細 | H22: 手配NO1 | S22: 画
A23: 15 | C23: T | D23: 受注明細 | H23: 手配NO2 | S23: 画 | Z23: 案件NO
A24: 16 | C24: T | D24: 受注明細 | H24: 手配NO3 | S24: 画 | Z24: 得意先CD
A25: 17 | C25: T | D25: 受注明細 | H25: 製品CD/品目CD | S25: 画 | T25: 品目マスタ | Z25: 品目CD
A26: 18 | C26: T | D26: 受注明細 | H26: 製品名 | S26: 画 | T26: 品目マスタ | Z26: 品名
A27: 19 | C27: T | D27: 受注明細 | H27: 版型NO | S27: 画 | T27: 版型発注書 | Z27: 版型NO
A28: 20 | C28: T | D28: 受注明細 | H28: 単位 | S28: 画 | T28: 品目マスタ | Z28: 単位
A29: 21 | C29: T | D29: 受注明細 | H29: 数量 | S29: 画 | AK29: 固定：１
A30: 22 | C30: T | D30: 受注明細 | H30: 特値 | S30: 画 | AK30: 固定：0 OFF
A31: 23 | C31: T | D31: 受注明細 | H31: 個別単価 | S31: 画 | T31: 版型発注書 | Z31: 決定価格
A32: 24 | C32: T | D32: 受注明細 | H32: ｾｯﾄ単価 | S32: 画
A33: 25 | C33: T | D33: 受注明細 | H33: 金額 | S33: 画 | T33: 版型発注書 | Z33: 決定価格
A34: 26 | C34: T | D34: 受注明細 | H34: 手配区分 | S34: 画 | AK34: 在庫引当
A35: 27 | C35: T | D35: 受注明細 | H35: 納品先 | S35: 画 | T35: 取引先マスタ | Z35: 納品先CD
A36: 28 | C36: T | D36: 受注明細 | H36: 納品先名 | S36: 画 | T36: 取引先マスタ | Z36: 取引先名
A37: 29 | C37: T | D37: 受注明細 | H37: 物流グループ | S37: 画
A38: 30 | C38: T | D38: 受注明細 | H38: 預り売上 | S38: 画 | AK38: 売上可の場合、１：ON それ以外０:OFF
A39: 31 | C39: T | D39: 受注明細 | H39: 売上理由 | S39: 画 | AK39: 0円時設定
A40: 32 | C40: T | D40: 受注明細 | H40: 受注№ || 受注明細№ | S40: 画
A41: 33 | C41: T | D41: 受注明細 | H41: 受注区分 | S41: 画 | AK41: 商品
...

Sheet 更新入出力仕様(PE)
A1: =表紙!A54 -> Webシステム | K1: 文書名 | U1: モジュールID | Z1: =表紙!$AJ$63 -> MS | AE1: モジュール名 | AJ1: =表紙!$AX$63 -> 見積管理 | AS1: 文書番号 | AZ1: Version | BF1: Rev.
K2: =表紙!O64 -> 画面機能 | U2: ｻﾌﾞﾓｼﾞｭｰﾙID | Z2: =表紙!$AJ$64 -> MSBB | AE2: ｻﾌﾞﾓｼﾞｭｰﾙ名 | AJ2: =表紙!$AX$64 -> Webシステム | AS2: =表紙!$BL$64 -> M7-US-1140 | AZ2: =表紙!$BU$64 -> 1.0.0 | BF2: =表紙!$CB$64 -> 4
K3: =RIGHT(CELL("filename",$A$1),LEN(CELL("filename",$A$1))-FIND("]",CELL("filename",$A$1))) -> 更新入出力仕様(PE) | U3: 表題 | Z3: =表紙!$AJ$65 -> アドオン画面 | AE3: =表紙!$AQ$65 -> Web版型・木型マスタ
A5: No | G5: 1 | H5: ボタン | L5: PE API連携 | S5: ロジック名称 | AH5: 備考 | AK5: PE API連携
A6: 処理分類 | E6: 登録/更新 | H6: ソート順
A7: No | C7: 転送先 | S7: 転送元 | AK7: 説明 | CU7: CP指摘 2022/10/20 本多 起票者は営業担当者ではなく、出力操作時の社員で出力されますでしょうか？ | ED7: MDSOL回答 2022/10/31 石田 営業担当者になります。
C8: 種 | D8: オブジェクト | H8: 項目名 | S8: 種 | T8: オブジェクト | Z8: 項目名 | EE8: 2022/11/01 落合 出力したユーザーで印字して下さい
A9: 1 | C9: T | D9: PE木型・版型管理マスタ | H9: 拠点 | S9: T | T9: 木型・版型管理マスタ | Z9: 拠点 | EF9: MDSOL回答 2022/11/02 野村 出力したユーザーで印字します。PE標準機能で対応可能です。
A10: 2 | C10: T | D10: PE木型・版型管理マスタ | H10: 部門CD | S10: T | T10: 木型・版型管理マスタ | Z10: 部門CD | EF10: 2022/11/04 落合 問題なし
A11: 3 | C11: T | D11: PE木型・版型管理マスタ | H11: 営業担当CD | S11: T | T11: 木型・版型管理マスタ | Z11: 営業担当CD
A12: 4 | C12: T | D12: PE木型・版型管理マスタ | H12: 営業担当名 | S12: T | T12: 木型・版型管理マスタ | Z12: 営業担当名
A13: 5 | C13: T | D13: PE木型・版型管理マスタ | H13: 得意先CD | S13: T | T13: 木型・版型管理マスタ | Z13: 得意先CD
A14: 6 | C14: T | D14: PE木型・版型管理マスタ | H14: 得意先名 | S14: T | T14: 木型・版型管理マスタ | Z14: 得意先名
A15: 7 | C15: T | D15: PE木型・版型管理マスタ | H15: 発注先CD | S15: T | T15: 木型・版型管理マスタ | Z15: 発注先CD
A16: 8 | C16: T | D16: PE木型・版型管理マスタ | H16: 発注先名 | S16: T | T16: 木型・版型管理マスタ | Z16: 発注先名
A17: 9 | C17: T | D17: PE木型・版型管理マスタ | H17: 納期 | S17: T | T17: 木型・版型管理マスタ | Z17: 納期
A18: 10 | C18: T | D18: PE木型・版型管理マスタ | H18: 発注品目 | S18: T | T18: 木型・版型管理マスタ | Z18: 版型分類
A19: 11 | C19: T | D19: PE木型・版型管理マスタ | H19: 発注品目_その他 | S19: T | T19: 木型・版型管理マスタ | Z19: 版型分類
A20: 12 | C20: T | D20: PE木型・版型管理マスタ | H20: 発注内容 | S20: T | T20: 木型・版型管理マスタ | Z20: 新版区分
A21: 13 | C21: T | D21: PE木型・版型管理マスタ | H21: 発注内容_その他 | S21: T | T21: 木型・版型管理マスタ | Z21: 新版区分
A22: 14 | C22: T | D22: PE木型・版型管理マスタ | H22: 加工予定先 | S22: T | T22: 木型・版型管理マスタ | Z22: 加工予定先
... A25: 17 | C25: T | D25: PE木型・版型管理マスタ | H25: 抜方向 | S25: T | T25: 木型・版型管理マスタ | Z25: 抜方向
A26: 18 | C26: T | D26: PE木型・版型管理マスタ | H26: 面付 | S26: T | T26: 木型・版型管理マスタ | Z26: 付数、個数 | DB26: Rev3.0 面付け From ～ To 項目削除→付数 個数に変更
A27: 19 | C27: T | D27: PE木型・版型管理マスタ | H27: シート寸法1 | S27: T | T27: 木型・版型管理マスタ | Z27: シート寸法1
A28: 20 | C28: T | D28: PE木型・版型管理マスタ | H28: シート寸法2 | S28: T | T28: 木型・版型管理マスタ | Z28: シート寸法2
A29: 21 | C29: T | D29: PE木型・版型管理マスタ | H29: 本数 | S29: T | T29: 木型・版型管理マスタ | Z29: 本数
A30: 22 | C30: T | D30: PE木型・版型管理マスタ | H30: 色数 | S30: T | T30: 木型・版型管理マスタ | Z30: 色数
A31: 23 | C31: T | D31: PE木型・版型管理マスタ | H31: 刃渡り寸法 | S31: T | T31: 木型・版型管理マスタ | Z31: 刃渡り寸法
A32: 24 | C32: T | D32: PE木型・版型管理マスタ | H32: フレキソ版厚 | S32: T | T32: 木型・版型管理マスタ | Z32: フレキソ版厚
A33: 25 | C33: T | D33: PE木型・版型管理マスタ | H33: シリンダーサイズ | S33: T | T33: 木型・版型管理マスタ | Z33: シリンダーサイズ
A34: 26 | C34: T | D34: PE木型・版型管理マスタ | H34: 見積価格 | S34: T | T34: 木型・版型管理マスタ | Z34: 見積価格
A35: 27 | C35: T | D35: PE木型・版型管理マスタ | H35: 仕入価格 | S35: T | T35: 木型・版型管理マスタ | Z35: 仕入価格
A36: 28 | C36: T | D36: PE木型・版型管理マスタ | H36: 決定価格 | S36: T | T36: 木型・版型管理マスタ | Z36: 決定価格
A37: 29 | C37: T | D37: PE木型・版型管理マスタ | H37: 売上日 | S37: T | T37: 木型・版型管理マスタ | Z37: 売上日
A38: 30 | C38: T | D38: PE木型・版型管理マスタ | H38: 添付資料_表図面 | S38: T | T38: 木型・版型管理マスタ | Z38: 添付情報_表図面
... A61: 53 | C61: T | D61: PE木型・版型管理マスタ | H61: 備考欄_注意事項 | S61: T | T61: 木型・版型管理マスタ | Z61: 備考

Sheet ファイル入出力仕様
A1: =表紙!A54 -> Webシステム | K1: 文書名 | U1: モジュールID | Z1: =表紙!$AJ$63 -> MS | AE1: モジュール名 | AJ1: =表紙!$AX$63 -> 見積管理 | AS1: 文書番号 | AZ1: Version | BF1: Rev.
K2: =表紙!O64 -> 画面機能 | U2: ｻﾌﾞﾓｼﾞｭｰﾙID | Z2: =表紙!$AJ$64 -> MSBB | AE2: ｻﾌﾞﾓｼﾞｭｰﾙ名 | AJ2: =表紙!$AX$64 -> Webシステム | AS2: =表紙!$BL$64 -> M7-US-1140 | AZ2: =表紙!$BU$64 -> 1.0.0 | BF2: =表紙!$CB$64 -> 4
K3: =RIGHT(CELL("filename",$A$1),LEN(CELL("filename",$A$1))-FIND("]",CELL("filename",$A$1))) -> ファイル入出力仕様 | U3: 表題 | Z3: =表紙!$AJ$65 -> アドオン画面 | AE3: =表紙!$AQ$65 -> Web版型・木型マスタ
A5: No | G5: 1 | H5: ボタン | L5: ラベル発行 | S5: ロジック名称 | Z5: Prnt01 | AH5: 備考 | AK5: 版・型管理ラベル発行用のCSVファイルの出力
A6: 処理分類 | E6: 出力 | H6: ソート順
A7: No | C7: 転送先 | S7: 転送元 | AK7: 説明
C8: 種 | D8: オブジェクト | H8: 項目名 | S8: 種 | T8: オブジェクト | Z8: 項目名
A9: 1 | C9: フ | D9: 版・型管理ラベル出力用CSVファイル | H9: 版型No | S9: T | T9: 木型・版型管理マスタ | Z9: 版型No
A10: 2 | C10: フ | D10: 版・型管理ラベル出力用CSVファイル | H10: 版型名 | S10: T | T10: 木型・版型管理マスタ | Z10: 版型名
A11: 3 | C11: フ | D11: 版・型管理ラベル出力用CSVファイル | H11: Rev | S11: T | T11: 木型・版型管理マスタ | Z11: Rev
A12: 4 | C12: フ | D12: 版・型管理ラベル出力用CSVファイル | H12: 版型分類 | S12: T | T12: 木型・版型管理マスタ | Z12: 版型分類
A13: 5 | C13: フ | D13: 版・型管理ラベル出力用CSVファイル | H13: 得意先 | S13: T | T13: 木型・版型管理マスタ | Z13: 得意先
A14: 6 | C14: フ | D14: 版・型管理ラベル出力用CSVファイル | H14: 得意先名 | S14: T | T14: 取引先 | Z14: 得意先名
A15: 7 | C15: フ | D15: 版・型管理ラベル出力用CSVファイル | H15: 製品コード | S15: T | T15: 木型・版型管理マスタ | Z15: 製品コード
A16: 8 | C16: フ | D16: 版・型管理ラベル出力用CSVファイル | H16: 製品名 | S16: T | T16: 木型・版型管理マスタ | Z16: 製品名
A17: 9 | C17: フ | D17: 版・型管理ラベル出力用CSVファイル | H17: 通し数 | S17: T | T17: 木型・版型管理マスタ | Z17: 通し数
A18: 10 | C18: フ | D18: 版・型管理ラベル出力用CSVファイル | H18: 限界通し数 | S18: T | T18: 木型・版型管理マスタ | Z18: 限界通し数
A19: 11 | C19: フ | D19: 版・型管理ラベル出力用CSVファイル | H19: 発注先 | S19: T | T19: 木型・版型管理マスタ | Z19: 発注先
A20: 12 | C20: フ | D20: 版・型管理ラベル出力用CSVファイル | H20: 発注先名 | S20: T | T20: 木型・版型管理マスタ | Z20: 発注先名
... A44: 36 | C44: フ | D44: 版・型管理ラベル出力用CSVファイル | H44: 備考 | S44: T | T44: 木型・版型管理マスタ | Z44: 備考
A45: 37 | C45: フ | D45: 版・型管理ラベル出力用CSVファイル | H45: 手配NO | S45: T | T45: 木型・版型管理マスタ | Z45: 手配NO | AK45: 手配NO追加

Sheet メッセージ一覧
A1: =表紙!A54 -> Webシステム | K1: 文書名 | U1: モジュールID | Z1: =表紙!$AJ$63 -> MS | AE1: モジュール名 | AJ1: =表紙!$AX$63 -> 見積管理 | AS1: 文書番号 | AZ1: Version | BF1: Rev.
K2: =表紙!O64 -> 画面機能 | U2: ｻﾌﾞﾓｼﾞｭｰﾙID | Z2: =表紙!$AJ$64 -> MSBB | AE2: ｻﾌﾞﾓｼﾞｭｰﾙ名 | AJ2: =表紙!$AX$64 -> Webシステム | AS2: =表紙!$BL$64 -> M7-US-1140 | AZ2: =表紙!$BU$64 -> 1.0.0 | BF2: =表紙!$CB$64 -> 4
K3: =RIGHT(CELL("filename",$A$1),LEN(CELL("filename",$A$1))-FIND("]",CELL("filename",$A$1))) -> メッセージ一覧 | U3: 表題 | Z3: =表紙!$AJ$65 -> アドオン画面 | AE3: =表紙!$AQ$65 -> Web版型・木型マスタ
A5: No | C5: 新/変 | E5: 種別 | G5: メッセージ内容 | AQ5: 備考（パラメータ等） | BG5: メッセージID
A6: 1 | E6: I | G6: 検索結果がありません。 | BG6: E10008
A7: 2 | C7: 新 | E7: W | G7: すでに更新済みです。再検索してください。 木型・版型No：{1}、Rev：{2} | AQ7: {1}：対象明細行の木型・版型No {2}：対象明細行のRev | BG7: E10023
A8: 3 | E8: W | G8: 必須項目に値が指定されていません。行：{1} 列名：{2} | AQ8: {1}：対象明細行番号 {2}：対象明細行の項目名 | BG8: E10021
A9: 4 | C9: 新 | E9: W | G9: 適用開始日と適用終了日の前後関係が不正です。 行：{1} 適用開始日：{2}、適用終了日：{3} | AQ9: {1}：対象明細行番号 {2}：対象明細行の適用開始日 {3}：対象明細行の適用終了日 | BG9: E10024
A10: 5 | C10: 新 | E10: W | G10: 適用開始日と廃棄予定日の前後関係が不正です。 行：{1} 適用開始日：{2}、廃棄予定日：{3} | AQ10: {1}：対象明細行番号 {2}：対象明細行の適用開始日 {3}：対象明細行の廃棄予定日 | BG10: E10025
A11: 6 | C11: 新 | E11: W | G11: 適用終了日と廃棄予定日の前後関係が不正です。 行：{1} 適用終了日：{2}、廃棄予定日：{3} | AQ11: {1}：対象明細行番号 {2}：対象明細行の適用終了日 {3}：対象明細行の廃棄予定日 | BG11: E10026
A12: 7 | C12: 新 | E12: W | G12: 「発行対象がありません。」 | BG12: E10010
A13: 8 | C13: 新 | E13: W | G13: 「入力形式」、「桁数」と「型」に誤りがあります｡ 項目名：{1} | AQ13: {1}：項目名 | BG13: E00001
A14: 9 | C14: 新 | E14: W | G14: 必須項目に値が指定されていません。項目名：{1} | AQ14: {1}：項目名 | BG14: E10022
A15: 10 | C15: 新 | E15: W | G15: 適用開始日と適用終了日の前後関係が不正です。 適用開始日：{1}、適用終了日：{2} | AQ15: {1}：対象明細行の適用開始日 {2}：対象明細行の適用終了日 | BG15: E10027
A16: 11 | C16: 新 | E16: W | G16: 適用開始日と廃棄予定日の前後関係が不正です。 適用開始日：{1}、廃棄予定日：{2} | AQ16: {1}：対象明細行の適用開始日 {2}：対象明細行の廃棄予定日 | BG16: E10028
A17: 12 | C17: 新 | E17: W | G17: 適用終了日と廃棄予定日の前後関係が不正です。 適用終了日：{1}、廃棄予定日：{2} | AQ17: {1}：対象明細行の適用終了日 {2}：対象明細行の廃棄予定日 | BG17: E10029

Sheet 補足資料
A1: =表紙!A54 -> Webシステム | O1: 文書名 | AC1: モジュールID | AJ1: =表紙!$AJ$63 -> MS | AQ1: モジュール名 | AX1: =表紙!$AX$63 -> 見積管理 | BL1: 文書番号 | BU1: Version | CB1: Rev.
O2: =表紙!O64 -> 画面機能 | AC2: サブモジュールID | AJ2: =表紙!$AJ$64 -> MSBB | AQ2: サブモジュール名 | AX2: =表紙!$AX$64 -> Webシステム | BL2: =表紙!$BL$64 -> M7-US-1140 | BU2: =表紙!$BU$64 -> 1.0.0 | CB2: =表紙!$CB$64 -> 4
O3: =RIGHT(CELL("filename",$A$1),LEN(CELL("filename",$A$1))-FIND("]",CELL("filename",$A$1))) -> 補足資料 | AC3: 表題 | AJ3: =表紙!$AJ$65 -> アドオン画面 | AQ3: =表紙!$AQ$65 -> Web版型・木型マスタ
AO5: 概要
C7: マスタの位置づけ
C8: 品目系マスタ
B48: 【説明】
C49: 木型・版型の情報を管理するマスタ
C50: 夜間に一度製造実績の通し数を集計し更新する

Sheet テーブル説明
A1: =表紙!A54 -> Webシステム | O1: 文書名 | AC1: モジュールID | AJ1: =表紙!$AJ$63 -> MS | AQ1: モジュール名 | AX1: =表紙!$AX$63 -> 見積管理 | BL1: 文書番号 | BU1: Version | CB1: Rev.
O2: =表紙!O64 -> 画面機能 | AC2: サブモジュールID | AJ2: =表紙!$AJ$64 -> MSBB | AQ2: サブモジュール名 | AX2: =表紙!$AX$64 -> Webシステム | BL2: =表紙!$BL$64 -> M7-US-1140 | BU2: =表紙!$BU$64 -> 1.0.0 | CB2: =表紙!$CB$64 -> 4
O3: =RIGHT(CELL("filename",$A$1),LEN(CELL("filename",$A$1))-FIND("]",CELL("filename",$A$1))) -> テーブル説明 | AC3: 表題 | AJ3: =表紙!$AJ$65 -> アドオン画面 | AQ3: =表紙!$AQ$65 -> Web版型・木型マスタ
A5: テーブル名 | O5: 日本語名
A6: MAM_ | O6: 木型・版型管理マスタ
A8: 主キー | D8: 項目名 | O8: 日本語名 | AE8: 型 | AG8: 桁 | AI8: Null | AK8: 説明 | BL8: 値の制限 | CF8: 設定仕様 | CZ8: 未設定時の振る舞い
A9: ○ | D9: WD_PTN_NO | O9: 木型・版型No | AE9: C | AG9: 40 | AI9: N | AK9: 木型・版型を特定するNo | CF9: 自動採番
A10: ○ | D10: WD_REV | O10: Rev | AE10: N | AG10: 10 | AI10: N | AK10: 木型・版型Noに対する連番 | BL10: 「0」以上の整数 | CF10: ※改定はRev＝最大Rev＋１ 画面表示時、自動設定
D11: POSITION_CD | O11: 拠点 | AE11: C | AG11: 20 | AI11: N
D12: DECISION_ESTIMATE_NO | O12: 決定見積NO | AE12: C | AG12: 20 | AI12: N
D13: VRSN_NAME | O13: 版型名 | AE13: C | AG13: 100 | AI13: N
D14: EARNINGS_CD | O14: 売上可否区分 | AE14: C | AG14: 20 | AI14: Y | AK14: 1:可,2:不可,3:商品込,4:社内処理,5:後報
D15: ARRANGE_NO | O15: 手配NO | AE15: C | AG15: 20 | AI15: Y
D16: ST_DT | O16: 適用開始日 | AE16: D | AI16: N | AK16: 当該レコードを有効にする日 | BL16: 適用開始日≦適用終了日 適用開始日以外のキー項目が同一となる場合に、期間が重なるようなデータは登録できない
D17: END_DT | O17: 適用終了日 | AE17: D | AI17: N | AK17: 当該レコードが有効となる最終日 | BL17: 適用開始日≦適用終了日 適用開始日以外のキー項目が同一となる場合に、期間が重なるようなデータは登録できない
D18: CST_CD | O18: 得意先CD | AE18: C | AG18: 20 | AI18: N | AK18: 得意先を表す取引先CD | BL18: 取引先マスタで得意先ＦＬＧが設定されている取引先ＣＤ
D19: PRODUCT_CD | O19: 代表製品CD | AE19: C | AG19: 20 | AI19: N
D20: NEW_VER_CD | O20: 新版区分 | AE20: C | AG20: 20 | AI20: Y
D21: PROCESS_CD | O21: 工程 | AE21: C | AG21: 20 | AI21: Y
D22: TYPE_CLASS | O22: 版型分類 | AE22: C | AG22: 20 | AI22: Y
D23: END_PLACE_CD | O23: 最終加工場所 | AE23: C | AG23: 20 | AI23: Y
D24: ACHIEVE_DT | O24: 実績日 | AE24: D | AI24: Y
D25: SHEET_CD | O25: シート段 | AE25: C | AG25: 20 | AI25: N
D26: PAPER_CD_OUT | O26: 原紙コード(表) | AE26: C | AG26: 20 | AI26: Y
D27: PRINT_CD_OUT | O27: 印刷コード(表) | AE27: C | AG27: 20 | AI27: Y
D28: EMBOSS_CD_OUT | O28: エンボスコード(表) | AE28: C | AG28: 20 | AI28: Y
D29: MAKER_CD_OUT | O29: メーカ(表) | AE29: C | AG29: 20 | AI29: Y
D30: PAPER_CD_MID | O30: 原紙コード(中) | AE30: C | AG30: 20 | AI30: Y
D31: PRINT_CD_MID | O31: 印刷コード(中) | AE31: C | AG31: 20 | AI31: Y
D32: EMBOSS_CD_MID | O32: エンボスコード(中) | AE32: C | AG32: 20 | AI32: Y
D33: MAKER_CD_MID | O33: メーカ(中) | AE33: C | AG33: 20 | AI33: Y
D34: PAPER_CD_IN | O34: 原紙コード(裏) | AE34: C | AG34: 20 | AI34: Y
D35: PRINT_CD_IN | O35: 印刷コード(裏) | AE35: C | AG35: 20 | AI35: Y
D36: EMBOSS_CD_IN | O36: エンボスコード(裏) | AE36: C | AG36: 20 | AI36: Y
... D38: EXTRACTION_DIRECT | O38: 抜方向 | AE38: C | AG38: 20 | AI38: Y
D39: IMPOSITION_FROM | O39: 面付け(From) | AE39: N | AG39: 9,0 | AI39: N
D40: IMPOSITION_TO | O40: 面付け(To) | AE40: N | AG40: 9,0 | AI40: N
D41: SHEET_WIDTH | O41: シート寸法(巾) | AE41: N | AG41: 9,0 | AI41: N
D42: SHEET_FLOW | O42: シート寸法(流れ) | AE42: N | AG42: 9,0 | AI42: N
D43: BLADE_WIDTH | O43: 刃渡り寸法(巾) | AE43: N | AG43: 9,0 | AI43: N
...
