Workbook
Name Rev.: 表紙!$U$22
Name Ver.: 表紙!$AE$26
Name ご確認者: 表紙!$AG$40
Name ご確認日: 表紙!$AG$42
Name サブシステム名: 表紙!$U$28
Name システム名: 表紙!$U$26
Name プロジェクト名: 表紙!$U$18
Name 開発区分: 表紙!$U$36
Name 機能ＩＤ: 表紙!$U$32
Name 機能区分: 表紙!$U$34
Name 機能名称: 表紙!$U$30
Name 顧客名: 表紙!$U$16
Name 最終更新者: 表紙!$AB$40
Name 最終更新日: 表紙!$AB$42
Name 作成者: 表紙!$W$40
Name 作成日: 表紙!$W$42
Name 章: 表紙!$M$10
Name 文書名: 表紙!$M$10

Sheet 目次
A1: アドオン設計書作成ガイド
C3: ■アドオン設計と成果物について
D4: ・システム設計フェーズとソフトウェア設計フェーズでアドオンの処理仕様を定義する
D5: ・システム設計フェーズとソフトウェア設計フェーズの成果物がアドオン設計書であり、ソフトウェア製作フェーズのインプットとなる
C7: ■各設計フェーズ毎のアドオン設計書作成範囲
D8: ・システム設計フェーズ：他機能との関連を定義するとともに、画面や帳票、ファイル入出力を中心とした外部入出力の設計を行う
D9: ・ソフトウェア設計フェーズ：内部処理を中心とした設計を行う
U11: ◎ | W11: … | X11: システム設計フェーズで作成
U12: ○ | W12: … | X12: システム設計フェーズで基本仕様を定義して、ソフトウェア設計フェーズで詳細化する
U13: △ | W13: … | X13: 必要に応じて（例えば標準仕様から変更がない場合は不要）
U14: ‐ | W14: … | X14: 不要
W15: … | X15: ソフトウェア設計フェーズで作成
D17: 各設計書と作成対象シートのマトリックス | S17: ※カスタマイズ：標準機能に機能を追加する アドオン：新規で機能を開発する
D18: EXCELシート | N18: 画面設計書 | W18: バッチ設計書 | AF18: 帳票設計書 | AO18: ＢＩ設計書 | AT18: .Net設計書 | BB18: EXCELシート | BL18: WebDB設計書 | BR18: 帳票設計書 | BX18: 汎用申請設計書
N19: カスタマイズ | S19: アドオン | W19: カスタマイズ | AB19: アドオン | AF19: カスタマイズ | AK19: アドオン | AO19: アドオン | AT19: アドオン | BL19: アドオン | BR19: アドオン | BX19: アドオン
D20: 概要 | N20: ◎ | O20: ※1 | S20: ◎ | W20: ◎ | X20: ※1 | AB20: ◎ | AF20: ◎ | AG20: ※1 | AK20: ◎ | AO20: ◎ | AT20: ◎ | BB20: 機能概要 | BL20: ◎ | BR20: ◎ | BX20: ◎
D21: レイアウト | N21: ◎ | O21: ※2 | S21: ◎ | W21: ‐ | AB21: ‐ | AF21: ◎ | AG21: ※2 | AK21: ◎ | AO21: ◎ | AT21: ◎ | BB21: アプリケーションフロー | BL21: ◎ | BR21: ー | BX21: ◎
D22: 項目説明 | N22: △ | S22: ○ | W22: ‐ | AB22: ‐ | AF22: △ | AK22: ○ | AO22: ○ | AT22: ○ | BB22: データベース設定 | BL22: ◎ | BR22: ー | BX22: ◎
D23: 引数説明 | N23: ‐ | S23: ‐ | W23: △ | AB23: ◎ | AF23: ‐ | AK23: ‐ | AO23: ‐ | AT23: ◎ | BB23: フィールド設定 | BL23: ◎ | BR23: ー | BX23: ◎
D24: 処理概要 | N24: ◎ | S24: ◎ | W24: ◎ | AB24: ◎ | AF24: ◎ | AK24: ◎ | AO24: ◎ | AT24: ◎ | BB24: 一覧表示画面設定 | BL24: ◎ | BR24: ー | BX24: ◎
D25: 処理詳細 | BB25: 表示編集画面設定 | BL25: ◎ | BR25: ー | BX25: ◎
D26: 処理・サービス関連図 | N26: △ | S26: ◎ | W26: △ | AB26: ◎ | AF26: ‐ | AK26: ‐ | AO26: ‐ | AT26: ◎ | BB26: 明細画面設定 | BL26: △ | BN26: ※3 | BR26: ー | BX26: △ | BZ26: ※3
D27: 検索入出力仕様 | N27: △ | S27: ○ | W27: △ | AB27: ○ | AF27: ‐ | AK27: ‐ | AO27: ‐ | AT27: ○ | BB27: 集計表示設定 | BL27: △ | BN27: ※4 | BR27: ー | BX27: △ | BZ27: ※4
D28: 更新入出力仕様 | N28: △ | S28: ○ | W28: △ | AB28: ○ | AF28: ‐ | AK28: ‐ | AO28: ‐ | AT28: ○ | BB28: 絞り込み条件設定 | BL28: △ | BN28: ※5 | BR28: ー | BX28: △ | BZ28: ※5
D29: ファイル入出力仕様 | N29: △ | S29: △ | W29: ‐ | AB29: ‐ | AF29: ‐ | AK29: ‐ | AO29: ‐ | AT29: △ | BB29: その他設定 | BR29: ー
D30: 画面遷移 | N30: △ | S30: ◎ | W30: ‐ | AB30: ‐ | AF30: ‐ | AK30: ‐ | AO30: ‐ | AT30: ◎ | BB30: 帳票イメージ | BL30: ー | BR30: ◎ | BX30: ー
D31: メッセージ一覧 | N31: △ | S31: △ | W31: △ | AB31: △ | AF31: ‐ | AK31: ‐ | AO31: ‐ | AT31: △ | BB31: 項目設計 | BL31: ー | BR31: ◎ | BX31: ー
D32: 補足説明 | N32: △ | S32: △ | W32: △ | AB32: △ | AF32: △ | AK32: △ | AO32: △ | AT32: △ | BB32: 補足説明 | BL32: △ | BR32: △ | BX32: △
D33: サービス呼出編集仕様 | N33: - | S33: - | W33: - | AB33: - | AF33: - | AK33: - | AO33: - | AT33: - | BB33: 補足説明(詳細)
D35: ※1 | G35: 別シートでカスタマイズ内容を記載する | BB35: ※3 | BE35: 単票画面は記載しない
D36: ※2 | G36: 吹き出しでカスタマイズ内容を記載する | BB36: ※4 | BE36: 集計・グラフ機能を使用する場合に記載する
BB37: ※5 | BE37: 共通設定のみ記載する(個別設定は、記載しない)

Sheet 表紙
AW2: サブモジュール
AW3: MA_マスタ管理
AW4: MB_業務共通
AW5: MG_原価管理
AW6: MSBA_需給管理
M7: 基本設計 | AW7: MSBB_販売管理
AW8: MSBC_生産管理
AW9: MSBD_購買管理
M10: アドオン設計書 | AW10: MSBE_在庫物流管理
AW11: MSBF_品質管理
AW12: MSBG_債権管理
AW13: MSBH_債務管理
AW14: MSBI_締処理
AW15: MSUA_リスト・入力補助
M16: 顧客 | U16: 株式会社クラウン・パッケージ | AW16: PF_ESBアダプタ
M18: プロジェクト名 | U18: 基幹システム刷新PJ | AW18: 機能区分
AW19: 画面
M20: 文書番号 | AW20: 帳票
AW21: バッチ
M22: Ｒｅｖ． | U22: {=MAX(_xlfn.NUMBERVALUE(改訂!A7:E44))} -> 1 | AW22: マスタ
M24: 機密性区分 | U24: 取扱注意（Ｃ） | AW24: 開発区分
AW25: カスタマイズ
M26: システム名 | U26: Webシステム | AC26: Ver. | AE26: 7.0.2 | AW26: アドオン
AW27: －
M28: サブモジュール | U28: MSBB_販売管理
M30: 機能名 | U30: =M50 -> 御見積書
M32: 機能ID | U32: =G50 -> MSBBRA030
M34: 機能区分 | U34: 帳票
M36: 開発区分 | U36: アドオン
W39: 作成 | AB39: 最終更新 | AG39: ご確認
W40: MDSOL
W42: 44824
A48: 文書番号 | G48: 画面ID | M48: 画面名 | V48: Version | AB48: Revision
A50: M7-US-1140 | G50: MSBBRA030 | M50: 御見積書 | V50: 1.0.0 | AB50: r01.00
A53: 共通（元データ）
A54: Webシステム | K54: 文書名 | U54: モジュールID | Z54: MS | AE54: モジュール名 | AJ54: Webシステム | AS54: 文書番号 | AZ54: Version | BF54: Rev.
K55: 画面説明書 | U55: ｻﾌﾞﾓｼﾞｭｰﾙID | Z55: MSBB | AE55: ｻﾌﾞﾓｼﾞｭｰﾙ名 | AJ55: 販売Webシステム | AS55: M7-US-1140 | AZ55: 1.0.0 | BF55: r00.00
K56: 表紙 | U56: 表題 | Z56: MSBBRA030 | AE56: 御見積書
A57: 共通（リンク用）
A58: =A54 -> Webシステム | K58: 文書名 | U58: モジュールID | Z58: =Z54 -> MS | AE58: モジュール名 | AJ58: =AJ54 -> Webシステム | AS58: 文書番号 | AZ58: Version | BF58: Rev.
...

Sheet 改訂
A1: 第7章 | K1: 改訂 | AU1: 作成者 | AZ1: MDSOL | BE1: 作成日 | BJ1: =表紙!W42 -> 44824 | BP1: Rev.
AU2: 修正者 | BE2: 改訂日 | BP2: =表紙!CB64 -> 1
A5: Rev. | F5: 改定内容 | BC5: 頁 | BM5: 変更日 変更者 | BR5: 確認日 確認者
A7: 1 | F7: 新規作成

Sheet 概要
A1: =表紙!A54 -> Webシステム | O1: 文書名 | AC1: モジュールID | AJ1: =表紙!AJ63 -> MS | AQ1: モジュール名 | AX1: =表紙!AX63 -> Webシステム | BL1: 文書番号 | BU1: Version | CB1: Rev.
O2: =表紙!O64 -> アドオン設計書 | AC2: サブモジュールID | AJ2: =表紙!AJ64 -> MSBB | AQ2: サブモジュール名 | AX2: =表紙!AX64 -> 販売Webシステム | BL2: =表紙!BL64 -> M7-US-1140 | BU2: =表紙!BU64 -> 7.0.2 | CB2: =表紙!CB64 -> 1
O3: =RIGHT(CELL("filename",$A$1),LEN(CELL("filename",$A$1))-FIND("]",CELL("filename",$A$1))) -> 概要 | AC3: 表題 | AJ3: =表紙!AJ65 -> MSBBRA030 | AQ3: =表紙!AQ65 -> 御見積書
AO5: 概要
B7: 【業務要件】
C8: カスタマイズ | G8: 内容
C9: No.
C10: 4 | G10: 見積Webシステムを構築する。
H11: 主要機能
H12: ①見積(見積計算書)入力・発行
H13: ②御見積書入力・発行
B15: 【機能概要】
C16: 1. | D16: 御見積書を発行する。
C17: 2. | D17: Web御見積書登録・発行
D18: Web御見積書一覧照会 | L18: 画面から発行する
B20: 【前提条件】
C21: 1. | D21: 御見積書NO単位の帳票となる
B23: 【説明】
C24: ・ | D24: 御見積書の内容を出力する帳票
B26: 【帳票分類】
C27: ・ | D27: 社外取引帳票
B29: 【帳票ツール】
C30: ・ | D30: PrintProを利用した仕組み(CSVをログインユーザー単位にサーの所定フォルダへ出力する)
B32: 【帳票出力条件】
C33: ・ | D33: 承認済みの御見積書を出力対象とする。
B35: 【再発行時の印刷データ利用】
C36: ・ | D36: なし
C37: ※発行時のデータを保存しない
B39: 【改頁条件】
C40: ・ | D40: 得意先CD
C41: ・ | D41: 御見積書NO
C42: ・ | D42: 固定行(7行で改ページ)
B44: 【データのソート順】
C45: ・ | D45: 得意先CD | K45: (WEB御見積書)
C46: ・ | D46: 御見積書NO | K46: (WEB御見積書)
C47: ・ | D47: 明細NO | K47: (WEB御見積書明細(印字用))
B49: 【自由記述】
C50: ・ | D50: なし

Sheet 帳票イメージ
A1: =表紙!A54 -> Webシステム | K1: 文書名 | U1: モジュールID | Z1: =表紙!$AJ$63 -> MS | AE1: モジュール名 | AJ1: =表紙!$AX$63 -> Webシステム | AS1: 文書番号 | AZ1: Version | BF1: Rev.
K2: =表紙!O64 -> アドオン設計書 | U2: ｻﾌﾞﾓｼﾞｭｰﾙID | Z2: =表紙!$AJ$64 -> MSBB | AE2: ｻﾌﾞﾓｼﾞｭｰﾙ名 | AJ2: =表紙!$AX$64 -> 販売Webシステム | AS2: =表紙!$BL$64 -> M7-US-1140 | AZ2: =表紙!$BU$64 -> 7.0.2 | BF2: =表紙!$CB$64 -> 1
K3: =RIGHT(CELL("filename",$A$1),LEN(CELL("filename",$A$1))-FIND("]",CELL("filename",$A$1))) -> 帳票イメージ | U3: 表題 | Z3: =表紙!$AJ$65 -> MSBBRA030 | AE3: =表紙!$AQ$65 -> 御見積書
A5: 帳票イメージ

Sheet 項目説明
A1: =表紙!A54 -> Webシステム | K1: 文書名 | U1: モジュールID | Z1: =表紙!$AJ$63 -> MS | AE1: モジュール名 | AJ1: =表紙!$AX$63 -> Webシステム | AS1: 文書番号 | AZ1: Version | BF1: Rev.
K2: =表紙!O64 -> アドオン設計書 | U2: ｻﾌﾞﾓｼﾞｭｰﾙID | Z2: =表紙!$AJ$64 -> MSBB | AE2: ｻﾌﾞﾓｼﾞｭｰﾙ名 | AJ2: =表紙!$AX$64 -> 販売Webシステム | AS2: =表紙!$BL$64 -> M7-US-1140 | AZ2: =表紙!$BU$64 -> 7.0.2 | BF2: =表紙!$CB$64 -> 1
K3: =RIGHT(CELL("filename",$A$1),LEN(CELL("filename",$A$1))-FIND("]",CELL("filename",$A$1))) -> 項目説明 | U3: 表題 | Z3: =表紙!$AJ$65 -> MSBBRA030 | AE3: =表紙!$AQ$65 -> 御見積書
C5: 共通項目エリア | M5: 表示 | Q5: 最大 | S5: 出力仕様 | BK5: O
S6: テーブル名 | AB6: 項目名 | AJ6: 備考
A7: 参照テーブル
S8: WEB御見積書
S9: WEB御見積書明細(印字用) | AJ9: WEB御見積書.御見積書NO = WEB御見積書明細(印字用).御見積書NO
S10: WEB御見積書見積計算書 | AJ10: WEB御見積書.御見積書NO = WEB御見積書見積計算書.御見積書NO
S11: WEB取引先マスタ | AJ11: 御見積書の得意先CDから取引先情報を取得する。
S12: WEB担当者マスタ | AB12: WEBログインマスタ | AJ12: WEB御見積書.担当者CDより、担当者情報を取得する
S13: 会社マスタ | AJ13: 御見積書の会社CDから会社情報を取得する。
S14: 部門マスタ | AJ14: 御見積書の部門CDから部門情報を取得する。
A16: ヘッダー
A17: 1 | C17: タイトル | AJ17: 「御見積書」と表示する。
A19: 2 | C19: ≫先方担当入力有り
C20: 得意先名 | S20: WEB取引先マスタ | AB20: 取引先名
C21: 先方担当 | S21: WEB御見積書 | AB21: 先方担当
C22: 様(ラベル) | AJ22: 「様」と表示する。
C24: ≫先方担当入力無し
C25: 得意先名 | S25: WEB取引先マスタ | AB25: 取引先名
C26: 御中(ラベル) | AJ26: 「御中」と表示する。
A27: 3 | C27: 納入場所(ラベル) | AJ27: 固定「納入場所」と表示する。
C28: 納入場所 | S28: WEB御見積書 | AB28: 納入場所
A29: 4 | C29: 納入期限(ラベル) | AJ29: 固定「納入期限」と表示する。
C30: 納入期限 | S30: WEB御見積書 | AB30: 納入期限
A31: 5 | C31: 配送運賃(ラベル) | AJ31: 固定「配送運賃」と表示する。
C32: 配送運賃 | S32: WEB御見積書 | AB32: 配送運賃
A33: 6 | C33: お支払い条件(ラベル) | AJ33: 固定「お支払い条件」と表示する。
C34: お支払い条件 | S34: WEB御見積書 | AB34: お支払い条件
A35: 7 | C35: 見積有効期限(ラベル) | AJ35: 固定「見積有効期限」と表示する。
C36: 見積有効期限 | S36: WEB御見積書 | AB36: 見積有効期限
A37: 8 | C37: 注意書き | AJ37: 固定「いつもお世話になっております。」と表示する。
AJ38: 固定「下記の通り御見積申し上げます。」と表示する。
A39: 9 | C39: 発行年月日 | AJ39: システム自動(発行年月日)を表示する。
AJ40: ※YYYY年MM月DD日
A41: 10 | C41: 見積書NO | S41: WEB御見積書 | AB41: 御見積書NO
A43: 11 | C43: 株式会社(ラベル) | AJ43: 固定「株式会社」と表示する。
C44: 社名 | S44: 会社マスタ | AB44: 会社別名1
C45: 事業所名 | S45: 部門マスタ(上位部門) | AB45: 部門名
...

Sheet 帳票イメージ(御見積書)
J2: 御見積書 | Z2: 2022 | AB2: 年 | AC2: 7 | AD2: 月 | AE2: 1 | AF2: 日
Z3: 見積書№ | AA3: 10952387-01
AF4: 株式会社 クラウンパッケージ
B5: ＸＸＸＸＸＸＸＸＸ１ＸＸＸＸＸＸＸＸＸ２ | AF5: 東京事務所
B6: ＸＸＸＸＸＸＸ８ 様 | X6: 〒123-1234
X7: ○○○県○○○市○○○○○
B8: 納入場所 | X8: ○○○○○○○○○○ 99999-99999
B10: 納入期限 | AF10: TEL 01-1234-1234
AF11: FAX 01-1234-9999
B12: 配送運賃 | AF12: 担当 〇〇 〇〇
B14: お支払条件
B16: 見積有効期限
B18: いつもお世話になっております。
B19: 下記の通り御見積申し上げます。
B21: 商品名 | U21: 数量 | Y21: 単価 | AC21: 金額
B22: XXXXXXXXX1XXXXXXXXX2XXXXXXXXX3XXXXXXXXX4XXXXXXX8 XXXXXXXXX1XXXXXXXXX2 | U22: 1000 | Y22: 45.19 | AC22: 45190
AB23: 個
B43: 合計金額 (金額には消費税は含まれておりません) | Y43: =SUM(AC22:AF42) -> 45190
B44: 備考

Sheet 帳票イメージ(御見積書②)
A1: =表紙!A54 -> Webシステム | K1: 文書名 | U1: モジュールID | Z1: =表紙!$AJ$63 -> MS | AE1: モジュール名 | AJ1: =表紙!$AX$63 -> Webシステム | AS1: 文書番号 | AZ1: Version | BF1: Rev.
K2: =表紙!O64 -> アドオン設計書 | U2: ｻﾌﾞﾓｼﾞｭｰﾙID | Z2: =表紙!$AJ$64 -> MSBB | AE2: ｻﾌﾞﾓｼﾞｭｰﾙ名 | AJ2: =表紙!$AX$64 -> 販売Webシステム | AS2: =表紙!$BL$64 -> M7-US-1140 | AZ2: =表紙!$BU$64 -> 7.0.2 | BF2: =表紙!$CB$64 -> 1
K3: =RIGHT(CELL("filename",$A$1),LEN(CELL("filename",$A$1))-FIND("]",CELL("filename",$A$1))) -> 帳票イメージ(御見積書②) | U3: 表題 | Z3: =表紙!$AJ$65 -> MSBBRA030 | AE3: =表紙!$AQ$65 -> 御見積書
A5: 帳票イメージ

Sheet 項目説明(御見積書②)
A1: =表紙!A54 -> Webシステム | K1: 文書名 | U1: モジュールID | Z1: =表紙!$AJ$63 -> MS | AE1: モジュール名 | AJ1: =表紙!$AX$63 -> Webシステム | AS1: 文書番号 | AZ1: Version | BF1: Rev.
K2: =表紙!O64 -> アドオン設計書 | U2: ｻﾌﾞﾓｼﾞｭｰﾙID | Z2: =表紙!$AJ$64 -> MSBB | AE2: ｻﾌﾞﾓｼﾞｭｰﾙ名 | AJ2: =表紙!$AX$64 -> 販売Webシステム | AS2: =表紙!$BL$64 -> M7-US-1140 | AZ2: =表紙!$BU$64 -> 7.0.2 | BF2: =表紙!$CB$64 -> 1
K3: =RIGHT(CELL("filename",$A$1),LEN(CELL("filename",$A$1))-FIND("]",CELL("filename",$A$1))) -> 項目説明(御見積書②) | U3: 表題 | Z3: =表紙!$AJ$65 -> MSBBRA030 | AE3: =表紙!$AQ$65 -> 御見積書
C5: 共通項目エリア | N5: 表示 | R5: 最大 | T5: 出力仕様 | BK5: O
T6: テーブル名 | AB6: 項目名 | AJ6: 備考
A7: 参照テーブル
T8: 御見積書HED
T9: 御見積書DTL
T10: 御見積書見積計算書
T11: 御見積書文言 | AJ11: 御見積書のフッター文言
T12: 見積計算書
T13: 工程仕様ラベル | AJ13: 汎用マスタ
T14: 得意先マスタ | AJ14: 御見積書HEDの得意先ＣＤから取引先情報を取得する。
T15: 会社マスタ | AJ15: 御見積書HEDの会社ＣＤから会社情報を取得する。
T16: 部門マスタ | AJ16: 御見積書HEDの部門ＣＤから部門情報を取得する。
A18: ヘッダー
A19: 1
A21: 2 | T21: 御見積書DTL | AB21: 見積計算書NO
A25: データ部
A26: 1 | C26: 商品名/構成(ラベル) | AJ26: 固定「商品名/構成」と表示する。
C27: 商品名/構成 | T27: 御見積書DTL | AB27: 品名1
T28: 御見積書DTL | AB28: 品名2
A30: 2 | C30: 数量(ラベル) | AJ30: 固定「数量」と表示する。
C31: 数量 | T31: 御見積書DTL | AB31: 数量
A32: 3 | C32: 単価(ラベル) | AJ32: 固定「単価」と表示する。
C33: 単価 | T33: 御見積書DTL | AB33: 単価
A34: 4 | C34: 金額(ラベル) | AJ34: 固定「金額」と表示する。
C35: 金額 | T35: 御見積書DTL | AB35: 金額
A36: データ部2
A37: 5-1 | C37: シート構成(ラベル) | AJ37: 固定「シート構成」と表示する。
T38: 見積計算書 | AB38: 段
T39: 見積計算書 | AB39: 構成(表 中 裏)
A41: 5-2 | C41: シート寸法(ラベル) | AJ41: 固定「シート寸法」と表示する。
T42: 見積計算書 | AB42: 全版寸法_巾
T43: 見積計算書 | AB43: 全版寸法_流れ
T44: 見積計算書 | AB44: スリッター寸法_巾
T45: 見積計算書 | AB45: スリッター寸法_流れ
A47: 5-3 | C47: 工程名 | T47: 見積計算書加工 | AB47: 工程名称
C48: 工程仕様 | T48: 工程仕様ラベル | AB48: 工程仕様1～10
T49: 見積計算書加工 | AB49: 工程仕様1～10
...

Sheet 帳票イメージ(御見積書③)
A1: =表紙!A54 -> Webシステム | K1: 文書名 | U1: モジュールID | Z1: =表紙!$AJ$63 -> MS | AE1: モジュール名 | AJ1: =表紙!$AX$63 -> Webシステム | AS1: 文書番号 | AZ1: Version | BF1: Rev.
K2: =表紙!O64 -> アドオン設計書 | U2: ｻﾌﾞﾓｼﾞｭｰﾙID | Z2: =表紙!$AJ$64 -> MSBB | AE2: ｻﾌﾞﾓｼﾞｭｰﾙ名 | AJ2: =表紙!$AX$64 -> 販売Webシステム | AS2: =表紙!$BL$64 -> M7-US-1140 | AZ2: =表紙!$BU$64 -> 7.0.2 | BF2: =表紙!$CB$64 -> 1
K3: =RIGHT(CELL("filename",$A$1),LEN(CELL("filename",$A$1))-FIND("]",CELL("filename",$A$1))) -> 帳票イメージ(御見積書③) | U3: 表題 | Z3: =表紙!$AJ$65 -> MSBBRA030 | AE3: =表紙!$AQ$65 -> 御見積書
A5: 帳票イメージ

Sheet 帳票イメージ(価格表)_7月8日打合せ前
J2: 受注数量別単価表 | Z2: 2022 | AB2: 年 | AC2: 7 | AD2: 月 | AE2: 1 | AF2: 日
Z3: 見積書№ | AA3: 10952387-01
AF4: 株式会社 クラウンパッケージ
B5: ＸＸＸＸＸＸＸＸＸ１ＸＸＸＸＸＸＸＸＸ２ | P5: 御中 | AF5: 東京事務所
X6: 〒123-1234
X7: ○○○県○○○市○○○○○
X8: ○○○○○○○○○○ 99999-99999
AF9: TEL 01-1234-1234
AF10: FAX 01-1234-9999
AF11: 担当 〇〇 〇〇
B17: 段 高 | F17: 構成
B18: E | G18: 表 | H18: BSK100
G19: 中 | H19: BSK100
G20: 裏 | H20: BSK100
B21: 商品名 | U21: 数量 | Y21: 単価 | AC21: 金額
B22: XXXXXXXXX1XXXXXXXXX2XXXXXXXXX3XXXXXXXXX4XXXXXXX8 XXXXXXXXX1XXXXXXXXX2 | U22: 1000 | Y22: 45.19 | AC22: 45190
B25: XXXXXXXXX1XXXXXXXXX2XXXXXXXXX3XXXXXXXXX4XXXXXXX8 XXXXXXXXX1XXXXXXXXX2 | U25: 2000 | Y25: 44.01 | AC25: 88020
B28: XXXXXXXXX1XXXXXXXXX2XXXXXXXXX3XXXXXXXXX4XXXXXXX8 XXXXXXXXX1XXXXXXXXX2 | U28: 3000 | Y28: 43.81 | AC28: 131430
B31: XXXXXXXXX1XXXXXXXXX2XXXXXXXXX3XXXXXXXXX4XXXXXXX8 XXXXXXXXX1XXXXXXXXX2 | U31: 4000 | Y31: 43.57 | AC31: 174280
B34: XXXXXXXXX1XXXXXXXXX2XXXXXXXXX3XXXXXXXXX4XXXXXXX8 XXXXXXXXX1XXXXXXXXX2 | U34: 6000 | Y34: 42.57 | AC34: 255420
B37: XXXXXXXXX1XXXXXXXXX2XXXXXXXXX3XXXXXXXXX4XXXXXXX8 XXXXXXXXX1XXXXXXXXX2 | U37: 8000 | Y37: 41.07 | AC37: 328560

Sheet 処理概要
A1: =表紙!A54 -> Webシステム | K1: 文書名 | U1: モジュールID | Z1: =表紙!$AJ$63 -> MS | AE1: モジュール名 | AJ1: =表紙!$AX$63 -> Webシステム | AS1: 文書番号 | AZ1: Version | BF1: Rev.
K2: =表紙!O64 -> アドオン設計書 | U2: ｻﾌﾞﾓｼﾞｭｰﾙID | Z2: =表紙!$AJ$64 -> MSBB | AE2: ｻﾌﾞﾓｼﾞｭｰﾙ名 | AJ2: =表紙!$AX$64 -> 販売Webシステム | AS2: =表紙!$BL$64 -> M7-US-1140 | AZ2: =表紙!$BU$64 -> 7.0.2 | BF2: =表紙!$CB$64 -> 1
K3: =RIGHT(CELL("filename",$A$1),LEN(CELL("filename",$A$1))-FIND("]",CELL("filename",$A$1))) -> 処理概要 | U3: 表題 | Z3: =表紙!$AJ$65 -> MSBBRA030 | AE3: =表紙!$AQ$65 -> 御見積書
A5: 帳票出力（処理概要）
A6: 1 | B6: 帳票出力（処理概要）
C8: ■合計金額印字
D12: WEB御見積書.合計金額印字 = 0(非表示)
E13: 合計金額欄を印字しない
D15: WEB御見積書.合計金額印字 = 1(表示)
E16: 合計金額欄を印字する

Sheet 処理詳細
A1: =表紙!A54 -> Webシステム | K1: 文書名 | U1: モジュールID | Z1: =表紙!$AJ$63 -> MS | AE1: モジュール名 | AJ1: =表紙!$AX$63 -> Webシステム | AS1: 文書番号 | AZ1: Version | BF1: Rev.
K2: =表紙!O64 -> アドオン設計書 | U2: ｻﾌﾞﾓｼﾞｭｰﾙID | Z2: =表紙!$AJ$64 -> MSBB | AE2: ｻﾌﾞﾓｼﾞｭｰﾙ名 | AJ2: =表紙!$AX$64 -> 販売Webシステム | AS2: =表紙!$BL$64 -> M7-US-1140 | AZ2: =表紙!$BU$64 -> 7.0.2 | BF2: =表紙!$CB$64 -> 1
K3: =RIGHT(CELL("filename",$A$1),LEN(CELL("filename",$A$1))-FIND("]",CELL("filename",$A$1))) -> 処理詳細 | U3: 表題 | Z3: =表紙!$AJ$65 -> MSBBRA030 | AE3: =表紙!$AQ$65 -> 御見積書
A5: No | B5: 入力 | J5: 処理 | BD5: 出力
A6: 1 | B6: 対象データの抽出
J7: 1．帳票ヘッダとフッター項目抽出
K8: 下記の条件に従い、対象テーブルからデータを検索する。
K10: ・標準マスタをもとに検索する
K11: 帳票項目 | W11: テーブル | AE11: 項目名 | AM11: 取得条件、編集仕様
C12: 会社マスタ | K12: 社名 | W12: 会社マスタ | AE12: 会社別名1
C13: 部門マスタ(上位部門) | K13: 事業所名 | W13: 部門マスタ(上位部門) | AE13: 部門名 | AM13: キー：上位部門⇒部門⇒部門名
C14: 部門マスタ | K14: 事業所郵便番号 | W14: 会社マスタ | AE14: 郵便番号
K15: 事業所住所 | W15: 会社マスタ | AE15: 住所1
K16: 電話番号 | W16: 部門マスタ | AE16: ＴＥＬ
K17: FAX | W17: 部門マスタ | AE17: ＦＡＸ
K19: ・WEB御見積書をもとに検索する
K21: ヘッダ項目
K22: 帳票項目 | W22: テーブル | AE22: 項目名 | AM22: 取得条件、編集仕様
K23: 得意先名 | W23: WEB取引先マスタ | AE23: 取引先名
K24: 先方担当 | W24: WEB御見積書 | AE24: 先方担当 | AM24: 先方担当入力有り
K25: 納入場所 | W25: WEB御見積書 | AE25: 納入場所
K26: 納入期限 | W26: WEB御見積書 | AE26: 納入期限
K27: 配送運賃 | W27: WEB御見積書 | AE27: 配送運賃
K28: お支払い条件 | W28: WEB御見積書 | AE28: お支払い条件
K29: 見積有効期限 | W29: WEB御見積書 | AE29: 見積有効期限
K30: 見積書NO | W30: WEB御見積書 | AE30: 御見積書NO
K31: 営業担当名 | W31: WEB担当者マスタ | AE31: 営業担当名
K32: 合計金額印字 | W32: WEB御見積書 | AE32: 合計金額印字 | AM32: 非表示項目、合計金額印字有無判断用
K34: フッター項目
K35: 帳票項目 | W35: テーブル | AE35: 項目名 | AM35: 取得条件、編集仕様
K36: 見積書備考01 | W36: WEB御見積書 | AE36: 見積書備考01
K37: 見積書備考02 | W37: WEB御見積書 | AE37: 見積書備考02
K38: 見積書備考03 | W38: WEB御見積書 | AE38: 見積書備考03
K39: 見積書備考04 | W39: WEB御見積書 | AE39: 見積書備考04
K40: 見積書備考05 | W40: WEB御見積書 | AE40: 見積書備考05
K41: 見積書備考06 | W41: WEB御見積書 | AE41: 見積書備考06
K42: 見積書備考07 | W42: WEB御見積書 | AE42: 見積書備考07
K43: 見積書備考08 | W43: WEB御見積書 | AE43: 見積書備考08
K44: 見積書備考09 | W44: WEB御見積書 | AE44: 見積書備考09
K45: 見積書備考10 | W45: WEB御見積書 | AE45: 見積書備考10
...

Sheet 出力元画面
A1: =表紙!A54 -> Webシステム | K1: 文書名 | U1: モジュールID | Z1: =表紙!$AJ$63 -> MS | AE1: モジュール名 | AJ1: =表紙!$AX$63 -> Webシステム | AS1: 文書番号 | AZ1: Version | BF1: Rev.
K2: =表紙!O64 -> アドオン設計書 | U2: ｻﾌﾞﾓｼﾞｭｰﾙID | Z2: =表紙!$AJ$64 -> MSBB | AE2: ｻﾌﾞﾓｼﾞｭｰﾙ名 | AJ2: =表紙!$AX$64 -> 販売Webシステム | AS2: =表紙!$BL$64 -> M7-US-1140 | AZ2: =表紙!$BU$64 -> 7.0.2 | BF2: =表紙!$CB$64 -> 1
K3: =RIGHT(CELL("filename",$A$1),LEN(CELL("filename",$A$1))-FIND("]",CELL("filename",$A$1))) -> 出力元画面 | U3: 表題 | Z3: =表紙!$AJ$65 -> MSBBRA030 | AE3: =表紙!$AQ$65 -> 御見積書
AD5: 出力元画面
B7: 画面ＩＤ | I7: 画面名 | Y7: 備考
B8: MSBBPA030 | I8: Web御見積書登録・発行
B9: MSBBPA040 | I9: Web御見積書一覧照会

Sheet →補足シート

Sheet 対象外(不要)_帳票イメージ(価格表)
H2: 受注数量別単価表 | Z2: 2022 | AB2: 年 | AC2: 7 | AD2: 月 | AE2: 1 | AF2: 日
Z3: 見積書№ | AA3: 10952387-01
AF4: 株式会社 クラウンパッケージ
B5: ＸＸＸＸＸＸＸＸＸ１ＸＸＸＸＸＸＸＸＸ２ | AF5: 東京事務所
B6: ＸＸＸＸＸＸＸ８ 様 | X6: 〒123-1234
X7: ○○○県○○○市○○○○○
X8: ○○○○○○○○○○ 99999-99999
AF9: TEL 01-1234-1234
AF10: FAX 01-1234-9999
AF11: 担当 〇〇 〇〇
B17: 商品名 | U17: 数量 | Y17: 単価 | AC17: 金額
B18: XXXXXXXXX1XXXXXXXXX2XXXXXXXXX3XXXXXXXXX4XXXXXXX8 XXXXXXXXX1XXXXXXXXX2 | U18: 1000 | Y18: 45.19 | AC18: 45190
B21: XXXXXXXXX1XXXXXXXXX2XXXXXXXXX3XXXXXXXXX4XXXXXXX8 XXXXXXXXX1XXXXXXXXX2 | U21: 2000 | Y21: 44.01 | AC21: 88020
B24: XXXXXXXXX1XXXXXXXXX2XXXXXXXXX3XXXXXXXXX4XXXXXXX8 XXXXXXXXX1XXXXXXXXX2 | U24: 3000 | Y24: 43.81 | AC24: 131430
B27: XXXXXXXXX1XXXXXXXXX2XXXXXXXXX3XXXXXXXXX4XXXXXXX8 XXXXXXXXX1XXXXXXXXX2 | U27: 4000 | Y27: 43.57 | AC27: 174280
B30: XXXXXXXXX1XXXXXXXXX2XXXXXXXXX3XXXXXXXXX4XXXXXXX8 XXXXXXXXX1XXXXXXXXX2 | U30: 6000 | Y30: 42.57 | AC30: 255420
B33: XXXXXXXXX1XXXXXXXXX2XXXXXXXXX3XXXXXXXXX4XXXXXXX8 XXXXXXXXX1XXXXXXXXX2 | U33: 8000 | Y33: 41.07 | AC33: 328560
