Workbook
Name _____________a1: {"'Sheet1'!$A$3:$I$11"}
Name _____________a1: {"'Sheet1'!$A$3:$I$11"}
Name _____________a1: {"'Sheet1'!$A$3:$I$11"}
Name ____________a1: {"'Sheet1'!$A$3:$I$11"}
Name ____________a1: {"'Sheet1'!$A$3:$I$11"}
Name ____________a1: {"'Sheet1'!$A$3:$I$11"}
Name ___________a1: {"'Sheet1'!$A$3:$I$11"}
Name ___________a1: {"'Sheet1'!$A$3:$I$11"}
Name ___________a1: {"'Sheet1'!$A$3:$I$11"}
Name _________a1: {"'Sheet1'!$A$3:$I$11"}
Name _________a1: {"'Sheet1'!$A$3:$I$11"}
Name _________a1: {"'Sheet1'!$A$3:$I$11"}
Name ________a1: {"'Sheet1'!$A$3:$I$11"}
Name ________a1: {"'Sheet1'!$A$3:$I$11"}
Name ________a1: {"'Sheet1'!$A$3:$I$11"}
Name ______a1: {"'Sheet1'!$A$3:$I$11"}
Name ______a1: {"'Sheet1'!$A$3:$I$11"}
Name ______a1: {"'Sheet1'!$A$3:$I$11"}
Name _____a1: {"'Sheet1'!$A$3:$I$11"}
Name _____a1: {"'Sheet1'!$A$3:$I$11"}
Name _____a1: {"'Sheet1'!$A$3:$I$11"}
Name ____a1: {"'Sheet1'!$A$3:$I$11"}
Name ____a1: {"'Sheet1'!$A$3:$I$11"}
Name ____a1: {"'Sheet1'!$A$3:$I$11"}
Name ___a1: {"'Sheet1'!$A$3:$I$11"}
Name ___a1: {"'Sheet1'!$A$3:$I$11"}
Name ___a1: {"'Sheet1'!$A$3:$I$11"}
Name __a1: {"'Sheet1'!$A$3:$I$11"}
Name __a1: {"'Sheet1'!$A$3:$I$11"}
Name __a1: {"'Sheet1'!$A$3:$I$11"}
Name _Order1: 255
Name _Table2_In1: [1]LIST!#REF!
Name _Table2_In1: [1]LIST!#REF!
Name _Table2_In1: [1]LIST!#REF!
Name _Table2_In2: [1]LIST!#REF!
Name A: #REF!
Name A: #REF!
Name A: #REF!
Name aa: {"'その他費用'!$B$3:$J$22"}
Name aa: {"'その他費用'!$B$3:$J$22"}
Name aa: {"'その他費用'!$B$3:$J$22"}
Name AB: #REF!
Name Access_Button: "価格H_hard_諸元___2__List"
Name AccessDatabase: "C:\MTAKAHAS\価格H.mdb"
Name ADDON: {"'その他費用'!$B$3:$J$22"}
Name ADDON: {"'その他費用'!$B$3:$J$22"}
Name ADDON: {"'その他費用'!$B$3:$J$22"}
Name ADDON_2: {"'その他費用'!$B$3:$J$22"}
Name ADDON_2: {"'その他費用'!$B$3:$J$22"}
Name ADDON_2: {"'その他費用'!$B$3:$J$22"}
Name B: {"'その他費用'!$B$3:$J$22"}
Name B: {"'その他費用'!$B$3:$J$22"}
Name B: {"'その他費用'!$B$3:$J$22"}
Name cc: {"'その他費用'!$B$3:$J$22"}
Name cc: {"'その他費用'!$B$3:$J$22"}
Name cc: {"'その他費用'!$B$3:$J$22"}
Name dd: {"'その他費用'!$B$3:$J$22"}
Name dd: {"'その他費用'!$B$3:$J$22"}
Name dd: {"'その他費用'!$B$3:$J$22"}
Name ee: {"'その他費用'!$B$3:$J$22"}

Sheet 目次
A1: アドオン設計書作成ガイド
C3: ■アドオン設計と成果物について
D4: ・システム設計フェーズとソフトウェア設計フェーズでアドオンの処理仕様を定義する
D5: ・システム設計フェーズとソフトウェア設計フェーズの成果物がアドオン設計書であり、ソフトウェア製作フェーズのインプットとなる
C7: ■各設計フェーズ毎のアドオン設計書作成範囲
D8: ・システム設計フェーズ：他機能との関連を定義するとともに、画面や帳票、ファイル入出力を中心とした外部入出力の設計を行う
D9: ・ソフトウェア設計フェーズ：内部処理を中心とした設計を行う
U11: ◎ | W11: … | X11: システム設計フェーズで作成
U12: ○ | W12: … | X12: システム設計フェーズで基本仕様を定義して、ソフトウェア設計フェーズで詳細化する
U13: △ | W13: … | X13: 必要に応じて（例えば標準仕様から変更がない場合は不要）
U14: ‐ | W14: … | X14: 不要
W15: … | X15: ソフトウェア設計フェーズで作成
D17: 各設計書と作成対象シートのマトリックス | S17: ※カスタマイズ：標準機能に機能を追加する アドオン：新規で機能を開発する
D18: EXCELシート | N18: 画面設計書 | W18: バッチ設計書 | AF18: 帳票設計書 | AO18: ＢＩ設計書 | AT18: .Net設計書 | BB18: EXCELシート | BL18: WebDB設計書 | BR18: 帳票設計書 | BX18: 汎用申請設計書
N19: カスタマイズ | S19: アドオン | W19: カスタマイズ | AB19: アドオン | AF19: カスタマイズ | AK19: アドオン | AO19: アドオン | AT19: アドオン | BL19: アドオン | BR19: アドオン | BX19: アドオン
D20: 概要 | N20: ◎ | O20: ※1 | S20: ◎ | W20: ◎ | X20: ※1 | AB20: ◎ | AF20: ◎ | AG20: ※1 | AK20: ◎ | AO20: ◎ | AT20: ◎ | BB20: 機能概要 | BL20: ◎ | BR20: ◎ | BX20: ◎
D21: レイアウト | N21: ◎ | O21: ※2 | S21: ◎ | W21: ‐ | AB21: ‐ | AF21: ◎ | AG21: ※2 | AK21: ◎ | AO21: ◎ | AT21: ◎ | BB21: アプリケーションフロー | BL21: ◎ | BR21: ー | BX21: ◎
D22: 項目説明 | N22: △ | S22: ○ | W22: ‐ | AB22: ‐ | AF22: △ | AK22: ○ | AO22: ○ | AT22: ○ | BB22: データベース設定 | BL22: ◎ | BR22: ー | BX22: ◎
D23: 引数説明 | N23: ‐ | S23: ‐ | W23: △ | AB23: ◎ | AF23: ‐ | AK23: ‐ | AO23: ‐ | AT23: ◎ | BB23: フィールド設定 | BL23: ◎ | BR23: ー | BX23: ◎
D24: 処理概要 | N24: ◎ | S24: ◎ | W24: ◎ | AB24: ◎ | AF24: ◎ | AK24: ◎ | AO24: ◎ | AT24: ◎ | BB24: 一覧表示画面設定 | BL24: ◎ | BR24: ー | BX24: ◎
D25: 処理詳細 | BB25: 表示編集画面設定 | BL25: ◎ | BR25: ー | BX25: ◎
D26: 処理・サービス関連図 | N26: △ | S26: ◎ | W26: △ | AB26: ◎ | AF26: ‐ | AK26: ‐ | AO26: ‐ | AT26: ◎ | BB26: 明細画面設定 | BL26: △ | BN26: ※3 | BR26: ー | BX26: △ | BZ26: ※3
D27: 検索入出力仕様 | N27: △ | S27: ○ | W27: △ | AB27: ○ | AF27: ‐ | AK27: ‐ | AO27: ‐ | AT27: ○ | BB27: 集計表示設定 | BL27: △ | BN27: ※4 | BR27: ー | BX27: △ | BZ27: ※4
D28: 更新入出力仕様 | N28: △ | S28: ○ | W28: △ | AB28: ○ | AF28: ‐ | AK28: ‐ | AO28: ‐ | AT28: ○ | BB28: 絞り込み条件設定 | BL28: △ | BN28: ※5 | BR28: ー | BX28: △ | BZ28: ※5
D29: ファイル入出力仕様 | N29: △ | S29: △ | W29: ‐ | AB29: ‐ | AF29: ‐ | AK29: ‐ | AO29: ‐ | AT29: △ | BB29: その他設定 | BR29: ー
D30: 画面遷移 | N30: △ | S30: ◎ | W30: ‐ | AB30: ‐ | AF30: ‐ | AK30: ‐ | AO30: ‐ | AT30: ◎ | BB30: 帳票イメージ | BL30: ー | BR30: ◎ | BX30: ー
D31: メッセージ一覧 | N31: △ | S31: △ | W31: △ | AB31: △ | AF31: ‐ | AK31: ‐ | AO31: ‐ | AT31: △ | BB31: 項目設計 | BL31: ー | BR31: ◎ | BX31: ー
D32: 補足説明 | N32: △ | S32: △ | W32: △ | AB32: △ | AF32: △ | AK32: △ | AO32: △ | AT32: △ | BB32: 補足説明 | BL32: △ | BR32: △ | BX32: △
D33: サービス呼出編集仕様 | N33: - | S33: - | W33: - | AB33: - | AF33: - | AK33: - | AO33: - | AT33: - | BB33: 補足説明(詳細)
D35: ※1 | G35: 別シートでカスタマイズ内容を記載する | BB35: ※3 | BE35: 単票画面は記載しない
D36: ※2 | G36: 吹き出しでカスタマイズ内容を記載する | BB36: ※4 | BE36: 集計・グラフ機能を使用する場合に記載する
BB37: ※5 | BE37: 共通設定のみ記載する(個別設定は、記載しない)

Sheet 表紙
AW2: サブモジュール
AW3: MA_マスタ管理
AW4: MB_業務共通
AW5: MG_原価管理
AW6: MSBA_需給管理
M7: 基本設計 | AW7: MSBB_販売管理
AW8: MSBC_生産管理
AW9: MSBD_購買管理
M10: アドオン設計書 | AW10: MSBE_在庫物流管理
AW11: MSBF_品質管理
AW12: MSBG_債権管理
AW13: MSBH_債務管理
AW14: MSBI_締処理
AW15: MSUA_リスト・入力補助
M16: 顧客 | U16: 株式会社クラウン・パッケージ | AW16: PF_ESBアダプタ
M18: プロジェクト名 | U18: 基幹システム刷新PJ | AW18: 機能区分
AW19: 画面
M20: 文書番号 | AW20: 帳票
AW21: バッチ
M22: Ｒｅｖ． | U22: {=MAX(_xlfn.NUMBERVALUE(改訂!A7:E44))} -> 2 | AW22: マスタ
M24: 機密性区分 | U24: 取扱注意（Ｃ） | AW24: 開発区分
AW25: カスタマイズ
M26: システム名 | U26: Webシステム | AC26: Ver. | AE26: 7.0.2 | AW26: アドオン
AW27: －
M28: サブモジュール | U28: MSBB_販売管理
M30: 機能名 | U30: =M50 -> Web受注一覧登録(単価訂正)
M32: 機能ID | U32: =G50 -> MSBBPA090
M34: 機能区分 | U34: 画面
M36: 開発区分 | U36: アドオン
W39: 作成 | AB39: 最終更新 | AG39: ご確認
W40: MDSOL
W42: 44824
A48: 文書番号 | G48: 画面ID | M48: 画面名 | V48: Version | AB48: Revision
A50: M7-US-1140 | G50: MSBBPA090 | M50: Web受注一覧登録(単価訂正) | V50: 1.0.0 | AB50: r01.00
A53: 共通（元データ）
A54: Webシステム | K54: 文書名 | U54: モジュールID | Z54: MS | AE54: モジュール名 | AJ54: Webシステム | AS54: 文書番号 | AZ54: Version | BF54: Rev.
K55: 画面説明書 | U55: ｻﾌﾞﾓｼﾞｭｰﾙID | Z55: MSBB | AE55: ｻﾌﾞﾓｼﾞｭｰﾙ名 | AJ55: Web販売管理 | AS55: M7-US-1140 | AZ55: 1.0.0 | BF55: r00.00
K56: 表紙 | U56: 表題 | Z56: MSBBPA090 | AE56: Web受注一覧登録（単価変更）
A57: 共通（リンク用）
A58: =A54 -> Webシステム | K58: 文書名 | U58: モジュールID | Z58: =Z54 -> MS | AE58: モジュール名 | AJ58: =AJ54 -> Webシステム | AS58: 文書番号 | AZ58: Version | BF58: Rev.
...

Sheet 改訂
A1: 第7章 | K1: 改訂 | AU1: 作成者 | AZ1: MDSOL | BE1: 作成日 | BJ1: =表紙!W42 -> 44824 | BP1: Rev.
AU2: 修正者 | AZ2: =BM10 -> TBK徐 | BE2: 改訂日 | BJ2: =BM9 -> 44957 | BP2: =表紙!CB64 -> 2
A5: Rev. | F5: 改定内容 | BC5: 頁 | BM5: 変更日 変更者 | BR5: 確認日 確認者
A7: 1 | F7: 新規作成
A9: 2 | F9: 詳細設計追加 | BC9: 処理詳細 | BM9: 44957
BM10: TBK徐

Sheet 概要
A1: =表紙!A54 -> Webシステム | O1: 文書名 | AC1: モジュールID | AJ1: =表紙!AJ63 -> MS | AQ1: モジュール名 | AX1: =表紙!AX63 -> Webシステム | BL1: 文書番号 | BU1: Version | CB1: Rev.
O2: =表紙!O64 -> アドオン設計書 | AC2: サブモジュールID | AJ2: =表紙!AJ64 -> MSBB | AQ2: サブモジュール名 | AX2: =表紙!AX64 -> Web販売管理 | BL2: =表紙!BL64 -> M7-US-1140 | BU2: =表紙!BU64 -> 7.0.2 | CB2: =表紙!CB64 -> 2
O3: =RIGHT(CELL("filename",$A$1),LEN(CELL("filename",$A$1))-FIND("]",CELL("filename",$A$1))) -> 概要 | AC3: 表題 | AJ3: =表紙!AJ65 -> MSBBPA090 | AQ3: =表紙!AQ65 -> Web受注一覧登録（単価変更）
AO5: 概要
B7: 【説明】
C8: 仮単価、金額を更新・確定しWFを起票する
B10: 【目的】
C11: 受注の仮単価を一覧で確認し、本単価へ変更する
B13: 【処理関連図/サービス関連図】
C14: ※処理・サービス関連図シートに詳細記載
B16: 【オペレーション一覧】
C17: 受注(仮単価)データの検索・照会処理を行う
C18: 仮単価を訂正し、WFを起票する(WF起票は自動)
C19: 本単価への更新する
B21: 【POWER EGG WF(汎用申請連携)に関して】
C22: 単価変更するデータに対して、POWER EGG WF(汎用申請連携)を起票する
C23: 受注明細の選択☑分、POWER EGG WF(汎用申請連携)を起票する
C24: 例)3件の単価訂正時、3件の単価訂正WFの申請が起票される
B26: 【SQLID一覧】
C27: なし
B29: 【ソート順】
C30: 売上担当CD、得意先CD、手配NO1、手配NO2、手配NO3、WEB受注NO、WEB受注明細NO
B32: 【データアクセスコントロール】
C33: 拠点による制御
C34: ※詳細は、【MSBBPA000】_共通設計書_アドオン(Webシステム共通仕様)にて定義
B36: 【自由記述】
C37: なし

Sheet 画面イメージ
A1: =表紙!A54 -> Webシステム | K1: 文書名 | U1: モジュールID | Z1: =表紙!$AJ$63 -> MS | AE1: モジュール名 | AJ1: =表紙!$AX$63 -> Webシステム | AS1: 文書番号 | AZ1: Version | BF1: Rev.
K2: =表紙!O64 -> アドオン設計書 | U2: ｻﾌﾞﾓｼﾞｭｰﾙID | Z2: =表紙!$AJ$64 -> MSBB | AE2: ｻﾌﾞﾓｼﾞｭｰﾙ名 | AJ2: =表紙!$AX$64 -> Web販売管理 | AS2: =表紙!$BL$64 -> M7-US-1140 | AZ2: =表紙!$BU$64 -> 7.0.2 | BF2: =表紙!$CB$64 -> 2
K3: =RIGHT(CELL("filename",$A$1),LEN(CELL("filename",$A$1))-FIND("]",CELL("filename",$A$1))) -> 画面イメージ | U3: 表題 | Z3: =表紙!$AJ$65 -> MSBBPA090 | AE3: =表紙!$AQ$65 -> Web受注一覧登録（単価変更）
A5: 画面イメージ
B7: ≫凡例
Q8: ・・・ | S8: ボタン
C9: 見積計算書NO | Q9: ・・・ | S9: 検索項目(検索画面表示選択) | AJ9: 参照情報
C10: 品名 | Q10: ・・・ | S10: 入力項目
C11: 得意先 | Q11: ・・・ | S11: 表示項目(得意先名称、原紙名等) | AJ11: 担当者
C12: 操作種別 | I12: ●登録 | M12: ○訂正 | Q12: ・・・ | S12: 選択項目(一つのみ選択可能)
C13: 受注区分 | Q13: ・・・ | S13: 選択項目(一つのみ選択可能)
C14: 作業順 | I14: ☑AAA | M14: ☑BBB | Q14: ・・・ | S14: 選択項目(複数選択可能)
C16: 見積作成日 | Q16: ・・・ | S16: カレンダー形式
BX21: －
D23: 拠点 | AC23: 売上担当者 | BR23: * | BS23: あいまい検索可能
D24: 受注日 | P24: ~ | AC24: 客先納期 | AO24: ~ | CE24: CP指摘 2022/10/19 本多 受注NOでの絞り込み条件はないのでしょうか？ | DQ24: MDSOL 野村 2022/11/02 WEB受注NO・WEB受注明細NOと明記統一します。(横展開)
CF25: MDSOL 野村 2022/10/25 追加しました。 | CU25: 2022/10/29 落合 問題なし | DQ25: 2022/11/04 落合 手配№とweb受注№の関係性を教えてください。 ユーザーは何を見てweb受注№を入力するのでしょうか？
D26: 基本情報 | DR26: MDSOL 野村 2022/11/07 web受注・明細№は、DB上の一意となるキーになります。システム管理者用の項目として、条件+一覧に追加しておりました。不要であれば削除します。
D27: 手配NO | DR27: ※受注後、明細をコピーして一部を預り売上にした場合に同じ手配NOとなり、左記一覧では判断付かないため、預り売上の項目を追加しております。
D28: 得意先 | DR28: 2022/11/07 落合 問題なし
D29: セット製品CD | AC29: 製品CD
D30: 顧客品名 | AB30: * | AU30: *
D31: 注文書NO | R31: * | AC31: 先方担当 | AQ31: * | CE31: 事前指摘
D32: 運送会社 | AC32: 売価区分 | CF32: CP指摘 2022/10/02 落合 表示項目が多く横スクロールが発生すると思われるので、以下のように2段表示に変更願います。 csv出力は1行出力
D33: 数量 | P33: ~ | AC33: 金額 | AO33: ~ | CO33: 得意先～段までを表示固定
D34: WEB受注NO | P34: ~ | CF34: MDSOL 野村 2022/10/25 レイアウト変更しました | CU34: 2022/10/29 落合 問題なし
D36: 仮単価のみ | J36: ☑
D40: № | F40: 選 | G40: 承認 状況 | J40: 得意先 | M40: 得意先名 | S40: 手配NO1 | X40: 受注日 | AB40: 製品CD/品目CD | AH40: CP品名／構成 | AS40: 段 | AT40: 全判寸法 | AY40: 受注数量 | BC40: 数量 | BE40: 個別単価 | BI40: 単価 | BK40: 個別単価 | BO40: 特値 | BQ40: 仮単価 FLG | BT40: 単価変更理由 | CB40: 金額 | CF40: 預 | CG40: 伝票備考 | CR40: WEB受注NO
F41: 択 | J41: 担当CD | M41: 売上担当名 | S41: 不適合手配NO | X41: 客先納期 | AB41: 製品区分（大） | AT41: スリッター寸法 | BC41: 単位 | BE41: セット単価 | BI41: 単位 | BK41: セット単価 | CF41: 売 | CG41: 納入備考 | CR41: WEB受注明細NO
D42: 1 | F42: ☑ | G42: 未承認 | J42: 12345 | M42: XXXXXXX8 | S42: 123456 | X42: 2022/7/1 | AB42: A9999999-01 | AH42: XXXXXXXXX1XXXXX6 | AS42: E | AT42: 700 X 490 | AY42: 9999999 | BC42: XXX | BE42: 99999.99 | BI42: XXX | BK42: 99999.99 | BO42: ☑ | BQ42: ☑ | CB42: 99999.99 | CF42: □
J43: 1234 | M43: XXXXX6 | S43: 123456 | X43: 2022/7/31 | AB43: 加工 | AT43: 690 X 490 | BE43: 99999.99 | BK43: 99999.99
D44: 2 | F44: ☑ | G44: 未承認 | J44: 12345 | M44: XXXXXXX8 | S44: 123456 | X44: 2022/7/1 | AB44: A9999999-01 | AH44: XXXXXXXXX1XXXXX6 | AS44: E | AT44: 700 X 490 | AY44: 9999999 | BC44: XXX | BE44: 99999.99 | BI44: XXX | BK44: 99999.99 | BO44: ☑ | BQ44: ☑ | CB44: 99999.99 | CF44: □
J45: 1234 | M45: XXXXX6 | S45: 123456 | X45: 2022/7/31 | AB45: 加工 | AT45: 690 X 490 | BE45: 99999.99 | BK45: 99999.99
D46: 3 | F46: ☑ | G46: 未承認 | J46: 12345 | M46: XXXXXXX8 | S46: 123456 | X46: 2022/7/1 | AB46: A9999999-01 | AH46: XXXXXXXXX1XXXXX6 | AS46: E | AT46: 700 X 490 | AY46: 9999999 | BC46: XXX | BE46: 99999.99 | BI46: XXX | BK46: 99999.99 | BO46: ☑ | BQ46: ☑ | CB46: 99999.99 | CF46: □
J47: 1234 | M47: XXXXX6 | S47: 123456 | X47: 2022/7/31 | AB47: 加工 | AT47: 690 X 490 | BE47: 99999.99 | BK47: 99999.99
D48: ◁ | CY48: ▷
AB49: ※品名／構成はシートの時、構成を表示
AB50: シート以外なら品名を表示
AB51: 折り返し表示
D53: NO | F53: 選 | G53: ステータス | J53: 売上 | L53: 売上 | O53: 得意先 | R53: 得意先名 | V53: 注文書NO | AA53: 手配NO1 | AD53: NO2 | AG53: NO3 | AJ53: 製品CD/品目CD | AO53: CP品名 | AZ53: 受注日 | BD53: 客先納期 | BH53: 数量 | BL53: 単位 | BN53: 仮単価 | BP53: 特値 | BR53: 単価 | BV53: 単価変更理由 | BZ53: 個別単価 | CD53: セット単価 | CH53: 金額 | CL53: 構成情報 | CW53: WEB受注NO/WEB受注明細NO
...

Sheet 現行画面
A1: =表紙!A54 -> Webシステム | K1: 文書名 | U1: モジュールID | Z1: =表紙!$AJ$63 -> MS | AE1: モジュール名 | AJ1: =表紙!$AX$63 -> Webシステム | AS1: 文書番号 | AZ1: Version | BF1: Rev.
K2: =表紙!O64 -> アドオン設計書 | U2: ｻﾌﾞﾓｼﾞｭｰﾙID | Z2: =表紙!$AJ$64 -> MSBB | AE2: ｻﾌﾞﾓｼﾞｭｰﾙ名 | AJ2: =表紙!$AX$64 -> Web販売管理 | AS2: =表紙!$BL$64 -> M7-US-1140 | AZ2: =表紙!$BU$64 -> 7.0.2 | BF2: =表紙!$CB$64 -> 2
K3: =RIGHT(CELL("filename",$A$1),LEN(CELL("filename",$A$1))-FIND("]",CELL("filename",$A$1))) -> 現行画面 | U3: 表題 | Z3: =表紙!$AJ$65 -> MSBBPA090 | AE3: =表紙!$AQ$65 -> Web受注一覧登録（単価変更）
A5: 画面イメージ

Sheet 項目説明
A1: =表紙!A54 -> Webシステム | K1: 文書名 | U1: モジュールID | Z1: =表紙!$AJ$63 -> MS | AE1: モジュール名 | AJ1: =表紙!$AX$63 -> Webシステム | AS1: 文書番号 | AZ1: Version | BF1: Rev.
K2: =表紙!O64 -> アドオン設計書 | U2: ｻﾌﾞﾓｼﾞｭｰﾙID | Z2: =表紙!$AJ$64 -> MSBB | AE2: ｻﾌﾞﾓｼﾞｭｰﾙ名 | AJ2: =表紙!$AX$64 -> Web販売管理 | AS2: =表紙!$BL$64 -> M7-US-1140 | AZ2: =表紙!$BU$64 -> 7.0.2 | BF2: =表紙!$CB$64 -> 2
K3: =RIGHT(CELL("filename",$A$1),LEN(CELL("filename",$A$1))-FIND("]",CELL("filename",$A$1))) -> 項目説明 | U3: 表題 | Z3: =表紙!$AJ$65 -> MSBBPA090 | AE3: =表紙!$AQ$65 -> Web受注一覧登録（単価変更）
A5: Web受注一覧登録(単価訂正)
B6: 抽出条件 | N6: 説明 | BE6: Ｗ | BF6: 型 | BG6: 参 | BH6: 必 | BI6: 入 | BJ6: 非 | BK6: 検 | BL6: 指摘ＣＰ 2022/10/18 玉置 項目名の確認 売上担当者となっていますが、出来れば 現行の通り「営業担当者」にしては如何でしょうか？ 売上入力担当と誤認しそうにも思えます。 | CI6: MDSOL 野村 2022/10/25 web側の修正は可能ですがmcframe7側では売上担当者となり不一致となるため、受注入力画面では、「売上担当者」とさせてください。 | CM6: 2022/11/04 玉置 承知しました。 問題なし | EE6: 2022/10/29 落合 売上担当者で問題なし
A7: 〇 | B7: 拠点 | M7: 【MSBBPACOM】_共通設計書_アドオン(共通ロジック)にて定義 | BE7: C | BF7: S | BH7: 必
A8: 〇 | B8: 売上担当者 | M8: 【MSBBPACOM】_共通設計書_アドオン(共通ロジック)にて定義 | BE8: C | BF8: S | BL8: 指摘ＣＰ 2022/10/18 玉置 項目名の確認 売上担当者となっていますが、出来れば 現行の通り「営業担当者」にしては如何でしょうか？ 売上入力担当と誤認しそうにも思えます。 | CI8: MDSOL 野村 2022/10/25 web側の修正は可能ですがmcframe7側では売上担当者となり不一致となるため、受注入力画面では、「売上担当者」とさせてください。 | CM8: 2022/11/04 玉置 承知しました。 問題なし | EE8: 2022/10/29 落合 売上担当者で問題なし
A9: 〇 | B9: 受注日(From) | M9: 抽出条件として、受注日(From)を入力する | BE9: カ | BF9: D
A10: 〇 | B10: 受注日(To) | M10: 抽出条件として、受注日(To)を入力する | BE10: カ | BF10: D
A11: 〇 | B11: 客先納期(From) | M11: 抽出条件として、客先納期(From)を入力する | BE11: カ | BF11: D
A12: 〇 | B12: 客先納期(To) | M12: 抽出条件として、客先納期(To)を入力する | BE12: カ | BF12: D
A13: 〇 | B13: 手配NO | M13: 【MSBBPACOM】_共通設計書_アドオン(共通ロジック)にて定義 | BE13: A | BF13: S | BK13: 検
A14: 〇 | B14: 得意先 | M14: 【MSBBPACOM】_共通設計書_アドオン(共通ロジック)にて定義 | BE14: A | BF14: S | BK14: 検
A15: 〇 | B15: セット製品CD | M15: 【MSBBPACOM】_共通設計書_アドオン(共通ロジック)にて定義 | BE15: A | BF15: S | BK15: 検
A16: 〇 | B16: 製品CD | M16: 【MSBBPACOM】_共通設計書_アドオン(共通ロジック)にて定義 | BE16: A | BF16: S | BK16: 検
A17: 〇 | B17: 顧客品名1 | M17: 抽出条件として、顧客品名1を入力する | AZ17: あいまい検索可 | BE17: T | BF17: S
A18: 〇 | B18: 顧客品名2 | M18: 抽出条件として、顧客品名2を入力する | AZ18: あいまい検索可 | BE18: T | BF18: S
A19: 〇 | B19: 注文書NO | M19: 抽出条件として、注文書NOを入力する | AZ19: あいまい検索可 | BE19: T | BF19: S
A20: 〇 | B20: 先方担当 | M20: 抽出条件として、先方担当を入力する | AZ20: あいまい検索可 | BE20: T | BF20: S
A21: 〇 | B21: 運送会社 | M21: 【MSBBPACOM】_共通設計書_アドオン(共通ロジック)にて定義 | BE21: C | BF21: S
A22: 〇 | B22: 売価区分 | M22: 【MSBBPACOM】_共通設計書_アドオン(共通ロジック)にて定義 | BE22: C | BF22: S
A23: 〇 | B23: 数量(From) | M23: 抽出条件として、数量(From)を入力する | BE23: T | BF23: N
A24: 〇 | B24: 数量(To) | M24: 抽出条件として、数量(To)を入力する | BE24: T | BF24: N
A25: 〇 | B25: 金額(From) | M25: 抽出条件として、金額(From)を入力する | BE25: T | BF25: N
A26: 〇 | B26: 金額(To) | M26: 抽出条件として、金額(To)を入力する | BE26: T | BF26: N
A27: 〇 | B27: WEB受注NO(From) | M27: 抽出条件として、WEB受注NO(From)を入力する | BE27: T | BF27: S
A28: 〇 | B28: WEB受注NO(To) | M28: 抽出条件として、WEB受注NO(To)を入力する | BE28: T | BF28: S
A29: 〇 | B29: 仮単価のみ | M29: 仮単価のみのデータ表示する場合にチェックする | BE29: チ | BF29: F
B30: 単価変更一覧 | N30: 説明 | BE30: Ｗ | BF30: 型 | BG30: 参 | BH30: 必 | BI30: 入 | BJ30: 非 | BK30: 検
B31: NO | M31: 行番を表示 | BE31: T | BF31: N | BL31: 指摘ＣＰ 2022/10/18 玉置 項目名の確認 行ＮＯ←NOとした方が判りやすいのでははないかと 考えます。 | CI31: MDSOL 野村 2022/10/28 NOに統一する | CX31: 2022/10/29 落合 問題なし
A32: ● | B32: 選択 | M32: 単価を更新するデータに対してチェックする | BE32: チ | BF32: F
B33: ステータス | M33: ステータスを表示 | BE33: T | BF33: S
B34: 得意先 | M34: 得意先を表示 | BE34: T | BF34: S
B35: 売上担当 | M35: 売上担当を表示 | BE35: T | BF35: S
B36: 得意先名 | M36: 得意先名を表示 | BE36: T | BF36: S
B37: 売上担当者名 | M37: 売上担当者名を表示 | BE37: T | BF37: S
B38: 注文書NO | M38: 注文書NOを表示 | BE38: T | BF38: S
B39: 手配NO1 | M39: 手配NO1を表示 | BE39: T | BF39: S
B40: 不適合手配NO | M40: 不適合手配NOを表示 | BE40: T | BF40: S
B41: 受注日 | M41: 受注日を表示 | BE41: T | BF41: D
...

Sheet 引数説明
A1: =表紙!A54 -> Webシステム | K1: 文書名 | U1: モジュールID | Z1: =表紙!$AJ$63 -> MS | AE1: モジュール名 | AJ1: =表紙!$AX$63 -> Webシステム | AS1: 文書番号 | AZ1: Version | BF1: Rev.
K2: =表紙!O64 -> アドオン設計書 | U2: ｻﾌﾞﾓｼﾞｭｰﾙID | Z2: =表紙!$AJ$64 -> MSBB | AE2: ｻﾌﾞﾓｼﾞｭｰﾙ名 | AJ2: =表紙!$AX$64 -> Web販売管理 | AS2: =表紙!$BL$64 -> M7-US-1140 | AZ2: =表紙!$BU$64 -> 7.0.2 | BF2: =表紙!$CB$64 -> 2
K3: =RIGHT(CELL("filename",$A$1),LEN(CELL("filename",$A$1))-FIND("]",CELL("filename",$A$1))) -> 引数説明 | U3: 表題 | Z3: =表紙!$AJ$65 -> MSBBPA090 | AE3: =表紙!$AQ$65 -> Web受注一覧登録（単価変更）
B5: オペレーションＩＤ/名称：SloRecvIfImp_Upd01/取込
A6: 必 | B6: 項目名 | N6: 説明 | AS6: 未設定時の振る舞い

Sheet 処理概要
A1: =表紙!A54 -> Webシステム | K1: 文書名 | U1: モジュールID | Z1: =表紙!$AJ$63 -> MS | AE1: モジュール名 | AJ1: =表紙!$AX$63 -> Webシステム | AS1: 文書番号 | AZ1: Version | BF1: Rev.
K2: =表紙!O64 -> アドオン設計書 | U2: ｻﾌﾞﾓｼﾞｭｰﾙID | Z2: =表紙!$AJ$64 -> MSBB | AE2: ｻﾌﾞﾓｼﾞｭｰﾙ名 | AJ2: =表紙!$AX$64 -> Web販売管理 | AS2: =表紙!$BL$64 -> M7-US-1140 | AZ2: =表紙!$BU$64 -> 7.0.2 | BF2: =表紙!$CB$64 -> 2
K3: =RIGHT(CELL("filename",$A$1),LEN(CELL("filename",$A$1))-FIND("]",CELL("filename",$A$1))) -> 処理概要 | U3: 表題 | Z3: =表紙!$AJ$65 -> MSBBPA090 | AE3: =表紙!$AQ$65 -> Web受注一覧登録（単価変更）
A5: NO | B5: 入力 | J5: 処理 | BD5: 出力
A6: 1 | B6: 初期表示
J7: 1.初期設定
K8: 初期表示 | BN8: 事前指摘
N9: 拠点 | T9: ： | U9: ログインに紐づく拠点CDを表示する
U10: ログイン.管理者区分 = 0(一般ユーザー時)、変更不可とする
N11: 売上担当者 | T11: ： | U11: ログイン担当者CDを表示する
N12: 仮単価のみ | T12: ： | U12: チェック有り
J14: 2.表示処理
L15: 抽出条件をもと一覧に結果を表示する
L16: ※検索結果が0件の場合、メッセージを表示する | AC16: エラーメッセージ：検索結果がありません。 | BD16: メッセージID.001
A18: 2 | B18: クリア
J19: 1.画面を初期化する(起動時の状態とする)
BO20: MDSOL 野村 2022/10/25
A21: 3 | B21: 表示 | BO21: >POWEREGGから開いた場合、Webシステム側でグイン無していなかった場合の制御は？
J22: 1.表示チェック処理 | BO22: WEBシステムにログインしていることが前提となります。(WEBシステムにログインされていない場合、ログイン画面が表示されます)
L23: チェック処理にてエラーとなった場合、後続処理をキャンセルする
N24: 必須チェック | AC24: エラーメッセージ：必須項目に値が指定されていません。項目名：パラメータ | BD24: メッセージID.002 | BO24: PE→単価訂正画面への遷移は、記載誤りです
N25: FROM～TOの整合性チェック | AC25: エラーメッセージ：FROM≦TOの関係で指定してください。 | BD25: メッセージID.003 | BP25: 本画面の情報をPE側(汎用申請)に送信することを想定しています。
BO26: 2022/11/01 落合 問題なし
J27: 1.抽出条件をもとに一覧に結果を表示する | BD27: 検索入出力仕様.NO1
K28: ※検索結果が0件の場合、メッセージを表示する | AC28: エラーメッセージ：検索結果がありません。 | BD28: メッセージID.001
A30: 4 | B30: 単価変更一覧
J31: 1.選択チェックON/OFF
K33: 選択チェック=ON時、特値・単価・単価変更理由を入力可能とする
K34: 選択チェック=OFF時、特値・単価・単価変更理由を入力不可とする
J41: 2.単価変更時
K42: 金額を再計算する
K43: ※計算仕様は、【MSBBPAMCF】_共通設計書_アドオン(共通ロジック)にて定義(売上計算)
A45: 5 | B45: 更新
J46: 1.選択された受注明細分、下記内容を繰り返し実行する。
L47: ①更新入出力仕様を実行する | BD47: 更新入出力仕様.NO1
L48: ②POWEREGGの単価訂正ワークフローを作成 | BD48: PE更新入出力仕様.NO1
L49: ※PE更新入出力仕様で定義された汎用申請WF項目に値をセットする
L51: 汎用申請WF完了後の処理に関して
L52: →単価訂正のWF承認後に受注連携処理が実施される
L53: ※受注連携仕様は、【MSLAB0020】_バッチ設計書_カスタマイズ(受注受信ＩＦ取込)にて定義

Sheet 処理詳細
A1: =表紙!A54 -> Webシステム | K1: 文書名 | U1: モジュールID | Z1: =表紙!$AJ$63 -> MS | AE1: モジュール名 | AJ1: =表紙!$AX$63 -> Webシステム | AS1: 文書番号 | AZ1: Version | BF1: Rev.
K2: =表紙!O64 -> アドオン設計書 | U2: ｻﾌﾞﾓｼﾞｭｰﾙID | Z2: =表紙!$AJ$64 -> MSBB | AE2: ｻﾌﾞﾓｼﾞｭｰﾙ名 | AJ2: =表紙!$AX$64 -> Web販売管理 | AS2: =表紙!$BL$64 -> M7-US-1140 | AZ2: =表紙!$BU$64 -> 7.0.2 | BF2: =表紙!$CB$64 -> 2
K3: =RIGHT(CELL("filename",$A$1),LEN(CELL("filename",$A$1))-FIND("]",CELL("filename",$A$1))) -> 処理詳細 | U3: 表題 | Z3: =表紙!$AJ$65 -> MSBBPA090 | AE3: =表紙!$AQ$65 -> Web受注一覧登録（単価変更）
A5: No | B5: 入力 | J5: 処理 | BD5: 出力
A6: 1 | B6: 初期表示
J7: 1.1 | L7: 処理概要参照
A10: 2 | B10: 画面操作
J11: 2.1 | L11: [抽出条件].検索(+/-)押す
L12: 検索領域を+時…開く、-時…閉じる
J14: 2.2 | L14: 選択チェックON/OFF
L15: 選択チェック=ON時、特値・単価・単価変更理由を入力可能とする
L16: 選択チェック=OFF時、特値・単価・単価変更理由を入力不可とする
J24: 2.3 | L24: 単価変更時
L25: 金額を再計算する
L26: ※計算仕様は、【MSBBPAMCF】_共通設計書_アドオン(共通ロジック)にて定義(売上計算)
A29: 3 | B29: 検索【F1】
J30: 3.1 | L30: コンボボックスの初期化
L31: 拠点コンボボックスの初期化
M32: ※ | N32: 拠点検索_SQLリソースの検索仕様
N33: 【MSBBPACOM】_共通設計書_アドオン(Web共通ロジック)の「処理詳細(共通検索)」シート」を参照する。
L35: 売上担当者コンボボックスの初期化
M36: ※ | N36: 売上担当者検索_SQLリソースの検索仕様
N37: 【MSBBPACOM】_共通設計書_アドオン(Web共通ロジック)の「処理詳細(共通検索)」シート」を参照する。
L39: 運送会社コンボボックスの初期化
M40: ※ | N40: 運送会社検索_SQLリソースの検索仕様
N41: 【MSBBPACOM】_共通設計書_アドオン(Web共通ロジック)の「処理詳細(共通検索)」シート」を参照する。
L43: 売価区分コンボボックスの初期化
M44: ※ | N44: 売価区分検索_SQLリソースの検索仕様
N45: 【MSBBPACOM】_共通設計書_アドオン(Web共通ロジック)の「処理詳細(共通検索)」シート」を参照する。
J47: 3.2 | L47: 手配NOの検索ボタン処理
L48: 手配NO検索のポップアップ画面へを遷移して、抽出条件をもとに結果を表示したところ、結果を表示したところ、
L49: 選択結果(1行)を遷移元画面（本画面の手配NO、手配NO名を設定）に返す
M51: ※ | N51: 手配NO検索_SQLリソースの検索仕様
N52: 【MSBBPACOM】_共通設計書_アドオン(Web共通ロジック)の「処理詳細(共通検索)」シート」を参照する。
J54: 3.3 | L54: 得意先の検索ボタン処理
L55: 得意先検索のポップアップ画面へを遷移して、抽出条件をもとに結果を表示したところ、結果を表示したところ、
L56: 選択結果(1行)を遷移元画面（本画面の得意先NO、得意先名を設定）に返す
M58: ※ | N58: 得意先検索_SQLリソースの検索仕様
N59: 【MSBBPACOM】_共通設計書_アドオン(Web共通ロジック)の「処理詳細(共通検索)」シート」を参照する。
J61: 3.4 | L61: セット製品CDの検索ボタン処理
...

Sheet 画面項目制御
J2: 操作種別 | O2: 登録 | R2: 登録後 | V2: R | X2: 有効(必須)
B3: 画面項目 | V3: E | X3: 有効
B4: 抽出条件 | G4: 拠点 | O4: R/RO | R4: R/RO | V4: RO | X4: 読取のみ
G5: 売上担当者 | O5: E | R5: E | V5: D | X5: 無効
G6: 受注日(From) | O6: E | R6: E | V6: I | X6: 非表示
G7: 受注日(To) | O7: E | R7: E
G8: 客先納期(From) | O8: E | R8: E
G9: 客先納期(To) | O9: E | R9: E
G10: 手配NO | O10: E | R10: E
G11: 得意先 | O11: E | R11: E
G12: セット製品CD | O12: E | R12: E
G13: 製品CD | O13: E | R13: E
G14: 顧客品名1 | O14: E | R14: E
G15: 顧客品名2 | O15: E | R15: E
G16: 注文書NO | O16: E | R16: E
G17: 先方担当 | O17: E | R17: E
G18: 運送会社 | O18: E | R18: E
... G26: 仮単価のみ | O26: E | R26: E
B27: 単価変更一覧 | G27: NO | O27: RO | R27: RO
G28: 選択 | O28: E | R28: RO
G29: ステータス | O29: RO | R29: RO
G30: 得意先 | O30: RO | R30: RO
G31: 売上担当 | O31: RO | R31: RO
G32: 得意先名 | O32: RO | R32: RO
G33: 売上担当者名 | O33: RO | R33: RO
G34: 注文書NO | O34: RO | R34: RO
G35: 手配NO1 | O35: RO | R35: RO
G36: 不適合手配NO | O36: RO | R36: RO
G37: 受注日 | O37: RO | R37: RO
G38: 客先納期 | O38: RO | R38: RO
G39: 製品CD/品目CD | O39: RO | R39: RO
... G59: WEB受注NO/WEB受注明細NO | O59: RO | R59: RO
B60: フッタ | G60: クリア | O60: E | R60: RO
G61: 表示 | O61: E | R61: E
G62: 更新 | O62: E | R62: RO

Sheet 処理・サービス関連図
A1: =表紙!A54 -> Webシステム | K1: 文書名 | U1: モジュールID | Z1: =表紙!$AJ$63 -> MS | AE1: モジュール名 | AJ1: =表紙!$AX$63 -> Webシステム | AS1: 文書番号 | AZ1: Version | BF1: Rev.
K2: =表紙!O64 -> アドオン設計書 | U2: ｻﾌﾞﾓｼﾞｭｰﾙID | Z2: =表紙!$AJ$64 -> MSBB | AE2: ｻﾌﾞﾓｼﾞｭｰﾙ名 | AJ2: =表紙!$AX$64 -> Web販売管理 | AS2: =表紙!$BL$64 -> M7-US-1140 | AZ2: =表紙!$BU$64 -> 7.0.2 | BF2: =表紙!$CB$64 -> 2
K3: =RIGHT(CELL("filename",$A$1),LEN(CELL("filename",$A$1))-FIND("]",CELL("filename",$A$1))) -> 処理・サービス関連図 | U3: 表題 | Z3: =表紙!$AJ$65 -> MSBBPA090 | AE3: =表紙!$AQ$65 -> Web受注一覧登録（単価変更）
C7: 検索処理
AU14: 指摘ＣＰ 2022/10/18 玉置 ワークフローについて記述がありません。 powerEggとワークフローについて、どのように連携するのか記述をお願いします
CB16: MDSOL 野村 2022/10/25 | DE16: 2022/11/01 落合 問題なし
CC17: PEに関して追記しました、APIの呼び出しを実装するイメージとなります。※サンプルコード(VB)
C19: 更新処理 | AI19: PE API連携

Sheet 検索入出力仕様
A1: =表紙!A54 -> Webシステム | K1: 文書名 | U1: モジュールID | Z1: =表紙!$AJ$63 -> MS | AE1: モジュール名 | AJ1: =表紙!$AX$63 -> Webシステム | AS1: 文書番号 | AZ1: Version | BF1: Rev.
K2: =表紙!O64 -> アドオン設計書 | U2: ｻﾌﾞﾓｼﾞｭｰﾙID | Z2: =表紙!$AJ$64 -> MSBB | AE2: ｻﾌﾞﾓｼﾞｭｰﾙ名 | AJ2: =表紙!$AX$64 -> Web販売管理 | AS2: =表紙!$BL$64 -> M7-US-1140 | AZ2: =表紙!$BU$64 -> 7.0.2 | BF2: =表紙!$CB$64 -> 2
K3: =RIGHT(CELL("filename",$A$1),LEN(CELL("filename",$A$1))-FIND("]",CELL("filename",$A$1))) -> 検索入出力仕様 | U3: 表題 | Z3: =表紙!$AJ$65 -> MSBBPA090 | AE3: =表紙!$AQ$65 -> Web受注一覧登録（単価変更）
A5: NO | G5: 1 | S5: ボタン | Z5: 検索 | AH5: 備考
A6: 処理分類 | E6: 検索 | S6: ソート順
A7: NO | C7: 転送先 | V7: 転送元 | AQ7: 説明
C8: 種 | D8: オブジェクト | K8: 項目名 | V8: 種 | W8: オブジェクト | AF8: 項目名
A9: 1 | C9: 画 | D9: 単価変更一覧 | K9: NO | AF9: 行番
A10: 2 | C10: 画 | D10: 単価変更一覧 | K10: ステータス | V10: T | W10: Web受注明細 | AF10: 承認状況
A11: 3 | C11: 画 | D11: 単価変更一覧 | K11: 得意先 | V11: T | W11: Web受注明細 | AF11: 得意先CD | AK11: 手配NO2
A12: 4 | C12: 画 | D12: 単価変更一覧 | K12: 得意先名 | V12: T | W12: 得意先マスタ | AA12: WEB取引先マスタ | AF12: 得意先名 | AK12: 取引先名
A13: 5 | C13: 画 | D13: 単価変更一覧 | K13: 売上担当 | V13: T | W13: ＭＣ受注 | AF13: 売上担当者ＣＤ | AQ13: ＭＣ受注が登録済の場合、ＭＣ受注の売上担当者ＣＤを優先表示
W14: WEB取引先マスタ | AF14: 営業担当ＣＤ
A15: 6 | C15: 画 | D15: 単価変更一覧 | K15: 売上担当者名 | V15: T | W15: 担当マスタ | AF15: 担当者名
A16: 7 | C16: 画 | D16: 単価変更一覧 | K16: 注文書NO | V16: T | W16: Web受注明細 | AF16: 注文書NO
A17: 8 | C17: 画 | D17: 単価変更一覧 | K17: 手配NO1 | V17: T | W17: Web受注明細 | AF17: 手配NO1
A18: 9 | C18: 画 | D18: 単価変更一覧 | K18: 手配NO2 | V18: T | W18: Web受注明細 | AF18: 手配NO2
A19: 10 | C19: 画 | D19: 単価変更一覧 | K19: 手配NO3 | V19: T | W19: Web受注明細 | AF19: 手配NO3
A20: 9 | C20: 画 | D20: 単価変更一覧 | K20: 不適合手配NO1 | V20: T | W20: Web受注明細 | AF20: 不適合手配NO1
A21: 10 | C21: 画 | D21: 単価変更一覧 | K21: 製品CD/品目CD | V21: T | W21: Web受注明細 | AF21: 製品CD/品目CD
A22: 11 | C22: 画 | D22: 単価変更一覧 | K22: 品名1 | V22: T | W22: Web受注明細 | AF22: CP品名1
A23: 12 | C23: 画 | D23: 単価変更一覧 | K23: 品名2 | V23: T | W23: Web受注明細 | AF23: CP品名2
A24: 13 | C24: 画 | D24: 単価変更一覧 | K24: 受注日 | V24: T | W24: Web受注明細 | AF24: 受注日
A25: 14 | C25: 画 | D25: 単価変更一覧 | K25: 客先納期 | V25: T | W25: Web受注明細 | AF25: 客先納期
A26: 15 | C26: 画 | D26: 単価変更一覧 | K26: 単位 | V26: T | W26: Web受注明細 | AF26: 単位 | AJ26: 発注単位
A27: 16 | C27: 画 | D27: 単価変更一覧 | K27: CP品名／構成 | AF27: CP品名／構成 | AQ27: 受注区分=シート受注:構成名を表示、受注区分=シート受注以外:品名を表示
A28: 17 | C28: 画 | D28: 単価変更一覧 | K28: 表(構成情報) | V28: T | W28: Web受注明細 | AQ28: 原紙コード(表)+印刷コード(表)+エンボスコード(表)
A29: 18 | C29: 画 | D29: 単価変更一覧 | K29: 中(構成情報) | V29: T | W29: Web受注明細 | AQ29: 原紙コード(中)+印刷コード(中)+エンボスコード(中)
A30: 19 | C30: 画 | D30: 単価変更一覧 | K30: 裏(構成情報) | V30: T | W30: Web受注明細 | AQ30: 原紙コード(裏)+印刷コード(裏)+エンボスコード(裏)
A31: 20 | C31: 画 | D31: 単価変更一覧 | K31: 段(構成情報) | V31: T | W31: Web受注明細 | AF31: 段
A32: 21 | C32: 画 | D32: 単価変更一覧 | K32: 全判寸法（巾・流れ） | V32: T | W32: Web受注明細 | AF32: 全判寸法（巾・流れ）
A33: 22 | C33: 画 | D33: 単価変更一覧 | K33: ｽﾘｯﾀｰ寸法（巾・流れ） | V33: T | W33: Web受注明細 | AF33: ｽﾘｯﾀｰ寸法（巾・流れ）
A34: 23 | C34: 画 | D34: 単価変更一覧 | K34: 受注数量 | V34: T | W34: Web受注明細 | AF34: 受注数量
A35: 24 | C35: 画 | D35: 単価変更一覧 | K35: 数量単位 | V35: T | W35: Web受注明細 | AF35: 数量単位
A36: 25 | C36: 画 | D36: 単価変更一覧 | K36: 個別単価(変更前) | V36: T | W36: Web受注明細 | AF36: 個別単価(変更前)
A37: 26 | C37: 画 | D37: 単価変更一覧 | K37: セット単価(変更前) | V37: T | W37: Web受注明細 | AF37: セット単価(変更前)
A38: 27 | C38: 画 | D38: 単価変更一覧 | K38: 単価単位 | V38: T | W38: Web受注明細 | AF38: 単価単位
A39: 28 | C39: 画 | D39: 単価変更一覧 | K39: 個別単価 | V39: T | W39: Web受注明細 | AF39: 個別単価
A40: 29 | C40: 画 | D40: 単価変更一覧 | K40: セット単価 | V40: T | W40: Web受注明細 | AF40: セット単価
A41: 30 | C41: 画 | D41: 単価変更一覧 | K41: 特値 | V41: T | W41: Web受注明細 | AF41: 特値FLG
...

Sheet 更新入出力仕様
A1: =表紙!A54 -> Webシステム | K1: 文書名 | U1: モジュールID | Z1: =表紙!$AJ$63 -> MS | AE1: モジュール名 | AJ1: =表紙!$AX$63 -> Webシステム | AS1: 文書番号 | AZ1: Version | BF1: Rev.
K2: =表紙!O64 -> アドオン設計書 | U2: ｻﾌﾞﾓｼﾞｭｰﾙID | Z2: =表紙!$AJ$64 -> MSBB | AE2: ｻﾌﾞﾓｼﾞｭｰﾙ名 | AJ2: =表紙!$AX$64 -> Web販売管理 | AS2: =表紙!$BL$64 -> M7-US-1140 | AZ2: =表紙!$BU$64 -> 7.0.2 | BF2: =表紙!$CB$64 -> 2
K3: =RIGHT(CELL("filename",$A$1),LEN(CELL("filename",$A$1))-FIND("]",CELL("filename",$A$1))) -> 更新入出力仕様 | U3: 表題 | Z3: =表紙!$AJ$65 -> MSBBPA090 | AE3: =表紙!$AQ$65 -> Web受注一覧登録（単価変更）
A5: NO | G5: 1 | S5: ロジック名称 | Z5: Upd01 | AH5: 備考
A6: 処理分類 | E6: 更新
A7: NO | C7: 転送先 | V7: 転送元 | AQ7: 説明
C8: 種 | D8: オブジェクト | K8: 項目名 | V8: 種 | W8: オブジェクト | AF8: 項目名
A9: 1 | C9: T | D9: Web受注明細 | K9: 個別単価 | V9: 画 | W9: 単価変更一覧 | AF9: 個別単価 | BL9: 指摘ＣＰ 2022/10/18 玉置 「単価」の扱いの確認。 区分でセット売はセット単価、個別は個別単価とされていますが、 セット売でも各部材に個別単価は持っており、 セット単価と個別単価は連動しますので 売価区分で分けずに、セット単価はセット単価に、個別単価は個別単価に、 項目分けして入れるべきではと考えます。
A10: 2 | C10: T | D10: Web受注明細 | K10: セット単価 | V10: 画 | W10: 単価変更一覧 | AF10: セット単価
A11: 3 | C11: T | D11: Web受注明細 | K11: 特値フラグ | V11: 画 | W11: 単価変更一覧 | AF11: 特値フラグ | BM11: MDSOL 野村 2022/10/28 項目を分けました。またセット単価の更新について、同一の受注NOのセット単価に対して、セット単価の更新を行う記述を追加しました。
A12: 4 | C12: T | D12: Web受注明細 | K12: 単価変更理由 | V12: 画 | W12: 単価変更一覧 | AF12: 単価変更理由 | BM12: 2022/11/01 落合 問題なし
A13: 5 | C13: T | D13: Web受注明細 | K13: 承認状況 | AQ13: 受注明細.単価と受注明細.変更前単価が異なる場合、 承認依頼を設定
A14: 6 | C14: T | D14: Web受注明細 | K14: 仮単価フラグ | AF14: False | AQ14: 単価を変えなくても選択行を更新で本単価になります。 仮単価：業務部が入力したもの。 本単価：営業が確認し確定したもの。
A15: 7
A16: 8
A17: 9
A18: 10
A20: NO | G20: 1' | S20: ロジック名称 | Z20: Upd01' | AH20: 備考
A21: 処理分類 | E21: 更新
A22: NO | C22: 転送先 | V22: 転送元 | AQ22: 説明
C23: 種 | D23: オブジェクト | K23: 項目名 | V23: 種 | W23: オブジェクト | AF23: 項目名
A24: 1 | C24: T | D24: Web受注明細 | K24: セット単価 | V24: 画 | W24: 単価変更一覧 | AF24: セット単価
C29: セット単価の更新に関して
D30: 同一のWEB受注NOのセット単価に対して、セット単価の更新を行う
C32: 補足
D33: 参照テーブル | W33: 結合条件
D34: Web受注明細 | W34: Web受注明細.WEB受注NO = 画面.WEB受注NO

Sheet テーブル項目
A1: =表紙!A54 -> Webシステム | K1: 文書名 | U1: モジュールID | Z1: =表紙!$AJ$63 -> MS | AE1: モジュール名 | AJ1: =表紙!$AX$63 -> Webシステム | AS1: 文書番号 | AZ1: Version | BF1: Rev.
K2: =表紙!O64 -> アドオン設計書 | U2: ｻﾌﾞﾓｼﾞｭｰﾙID | Z2: =表紙!$AJ$64 -> MSBB | AE2: ｻﾌﾞﾓｼﾞｭｰﾙ名 | AJ2: =表紙!$AX$64 -> Web販売管理 | AS2: =表紙!$BL$64 -> M7-US-1140 | AZ2: =表紙!$BU$64 -> 7.0.2 | BF2: =表紙!$CB$64 -> 2
K3: =RIGHT(CELL("filename",$A$1),LEN(CELL("filename",$A$1))-FIND("]",CELL("filename",$A$1))) -> テーブル項目 | U3: 表題 | Z3: =表紙!$AJ$65 -> MSBBPA090 | AE3: =表紙!$AQ$65 -> Web受注一覧登録（単価変更）
A5: テーブル名 | O5: 日本語名
A8: 主キー | D8: 項目名 | O8: 日本語名 | AE8: 型 | AG8: 桁 | AI8: Null | AK8: 説明 | BL8: 値の制限 | BM8: 設定仕様 | BN8: 未設定時の振る舞い | CZ8: 未設定時の振る舞い
D20: MEMO1 | O20: メモ１ | AE20: C | AG20: 100 | AI20: Y
D21: MEMO2 | O21: メモ２ | AE21: C | AG21: 100 | AI21: Y
D22: MEMO3 | O22: メモ３ | AE22: C | AG22: 100 | AI22: Y
D23: DEL_FLG | O23: 論理削除ＦＬＧ | AE23: F | AI23: N | AK23: 論理削除を示すフラグ
D24: DEL_USR_ID | O24: 論理削除ユーザＩＤ | AE24: C | AG24: 500 | AI24: Y
D25: DEL_USR_NM | O25: 論理削除ユーザ名 | AE25: C | AG25: 100 | AI25: Y
D26: DEL_TS | O26: 論理削除日時 | AE26: TS | AG26: 0 | AI26: Y
D27: INS_USR_ID | O27: 登録ユーザＩＤ | AE27: C | AG27: 500 | AI27: Y
D28: INS_USR_NM | O28: 登録ユーザ名 | AE28: C | AG28: 100 | AI28: Y
D29: INS_TS | O29: 登録日時 | AE29: TS | AG29: 0 | AI29: Y
D30: INS_FUNC_ID | O30: 登録機能ＩＤ | AE30: C | AG30: 50 | AI30: Y
D31: UPD_CNTR | O31: 更新カウンタ | AE31: N | AG31: 9,0 | AI31: Y
D32: UPD_USR_ID | O32: 更新ユーザＩＤ | AE32: C | AG32: 500 | AI32: Y
D33: UPD_USR_NM | O33: 更新ユーザ名 | AE33: C | AG33: 100 | AI33: Y
D34: UPD_TS | O34: 更新日時 | AE34: TS | AG34: 0 | AI34: Y
D35: UPD_FUNC_ID | O35: 更新機能ＩＤ | AE35: C | AG35: 50 | AI35: Y
D36: UPD_SRV_REQ_NO | O36: 更新リクエストＮＯ | AE36: C | AG36: 50 | AI36: Y

Sheet PE更新入出力仕様
A1: =表紙!A54 -> Webシステム | K1: 文書名 | U1: モジュールID | Z1: =表紙!$AJ$63 -> MS | AE1: モジュール名 | AJ1: =表紙!$AX$63 -> Webシステム | AS1: 文書番号 | AZ1: Version | BF1: Rev.
K2: =表紙!O64 -> アドオン設計書 | U2: ｻﾌﾞﾓｼﾞｭｰﾙID | Z2: =表紙!$AJ$64 -> MSBB | AE2: ｻﾌﾞﾓｼﾞｭｰﾙ名 | AJ2: =表紙!$AX$64 -> Web販売管理 | AS2: =表紙!$BL$64 -> M7-US-1140 | AZ2: =表紙!$BU$64 -> 7.0.2 | BF2: =表紙!$CB$64 -> 2
K3: =RIGHT(CELL("filename",$A$1),LEN(CELL("filename",$A$1))-FIND("]",CELL("filename",$A$1))) -> PE更新入出力仕様 | U3: 表題 | Z3: =表紙!$AJ$65 -> MSBBPA090 | AE3: =表紙!$AQ$65 -> Web受注一覧登録（単価変更）
A5: NO | G5: 1 | S5: ロジック名称 | Z5: PE API連携 | AH5: 備考
A6: 処理分類 | E6: 汎用申請API連携
A7: NO | C7: 転送先 | V7: 転送元 | AQ7: 説明
C8: 種 | D8: オブジェクト | K8: 項目名 | V8: 種 | W8: オブジェクト | AF8: 項目名
A9: 1 | C9: T | D9: 単価訂正(PE) | K9: 申請者 | V9: 画 | W9: 単価変更一覧 | AF9: 売上担当
A10: 2 | C10: T | D10: 単価訂正(PE) | K10: 申請日 | AF10: [本日日付]
A11: 3 | C11: T | D11: 単価訂正(PE) | K11: 件名 | AQ11: web.config定義(MSBBPA090_PE_Title)
AQ12: & 手配NO1 + 手配NO2 + 手配NO3
A13: 4 | C13: T | D13: 単価訂正(PE) | K13: 優先度 | AF13: [通常]
A14: 5 | C14: T | D14: 単価訂正(PE) | K14: 手配NO1 | V14: 画 | W14: 単価変更一覧 | AF14: 手配NO1
A15: 6 | C15: T | D15: 単価訂正(PE) | K15: 手配NO2 | V15: 画 | W15: 単価変更一覧 | AF15: 手配NO2
A16: 7 | C16: T | D16: 単価訂正(PE) | K16: 手配NO3 | V16: 画 | W16: 単価変更一覧 | AF16: 手配NO3
A17: 8 | C17: T | D17: 単価訂正(PE) | K17: 不適合手配NO | V17: 画 | W17: 単価変更一覧 | AF17: 不適合手配NO
A18: 9 | C18: T | D18: 単価訂正(PE) | K18: 得意先 | V18: 画 | W18: 単価変更一覧 | AF18: 得意先
A19: 10 | C19: T | D19: 単価訂正(PE) | K19: 得意先名 | V19: 画 | W19: WEB取引先マスタ | AF19: 得意先名
A20: 11 | C20: T | D20: 単価訂正(PE) | K20: 売上担当 | V20: 画 | W20: Web受注明細 | AF20: 担当
A21: 12 | C21: T | D21: 単価訂正(PE) | K21: 売上担当者名 | V21: 画 | W21: 担当マスタ | AF21: 担当者名
A22: 13 | C22: T | D22: 単価訂正(PE) | K22: 注文書NO | V22: 画 | W22: 単価変更一覧 | AF22: 注文書NO
A23: 14 | C23: T | D23: 単価訂正(PE) | K23: 製品CD/品目CD | V23: 画 | W23: 単価変更一覧 | AF23: 製品CD/品目CD
A24: 15 | C24: T | D24: 単価訂正(PE) | K24: 品名1 | V24: 画 | W24: 単価変更一覧 | AF24: 品名1
A25: 16 | C25: T | D25: 単価訂正(PE) | K25: 品名2 | V25: 画 | W25: 単価変更一覧 | AF25: 品名2
... A50: 41 | C50: T | D50: 単価訂正(PE) | K50: WEB受注NO/WEB受注明細NO | V50: 画 | W50: 単価変更一覧 | AF50: WEB受注NO/WEB受注明細NO
A51: 42 | C51: T | D51: 単価訂正(PE) | K51: 納品先CD | V51: T | W51: WEB受注明細 | AF51: 納品先CD | AQ51: WEB受注明細に関して
A52: 43 | C52: T | D52: 単価訂正(PE) | K52: 納品先名 | V52: T | W52: WEB受注明細 | AF52: 納品先名 | AR52: 画.受注明細.WEB受注NO/WEB受注明細NOから
A53: 44 | C53: T | D53: 単価訂正(PE) | K53: 製品区分_大 | V53: T | W53: WEB受注明細 | AF53: 製品区分_大 | AR53: WEB受注明細をキーにデータを取得する
A54: 45 | C54: T | D54: 単価訂正(PE) | K54: 製品区分_中 | V54: T | W54: WEB受注明細 | AF54: 製品区分_中
A55: 46 | C55: T | D55: 単価訂正(PE) | K55: 製品区分_小 | V55: T | W55: WEB受注明細 | AF55: 製品区分_小
A56: 33 | C56: T | D56: 単価訂正(PE) | K56: 段(構成情報) | V56: 画 | W56: 単価変更一覧 | AF56: 段(構成情報)
A57: 34 | C57: T | D57: 単価訂正(PE) | K57: 表(構成情報) | V57: 画 | W57: 単価変更一覧 | AF57: 表(構成情報)
A58: 35 | C58: T | D58: 単価訂正(PE) | K58: 中(構成情報) | V58: 画 | W58: 単価変更一覧 | AF58: 中(構成情報)
A59: 36 | C59: T | D59: 単価訂正(PE) | K59: 裏(構成情報) | V59: 画 | W59: 単価変更一覧 | AF59: 裏(構成情報)

Sheet 画面遷移
A1: =表紙!A54 -> Webシステム | K1: 文書名 | U1: モジュールID | Z1: =表紙!$AJ$63 -> MS | AE1: モジュール名 | AJ1: =表紙!$AX$63 -> Webシステム | AS1: 文書番号 | AZ1: Version | BF1: Rev.
K2: =表紙!O64 -> アドオン設計書 | U2: ｻﾌﾞﾓｼﾞｭｰﾙID | Z2: =表紙!$AJ$64 -> MSBB | AE2: ｻﾌﾞﾓｼﾞｭｰﾙ名 | AJ2: =表紙!$AX$64 -> Web販売管理 | AS2: =表紙!$BL$64 -> M7-US-1140 | AZ2: =表紙!$BU$64 -> 7.0.2 | BF2: =表紙!$CB$64 -> 2
K3: =RIGHT(CELL("filename",$A$1),LEN(CELL("filename",$A$1))-FIND("]",CELL("filename",$A$1))) -> 画面遷移 | U3: 表題 | Z3: =表紙!$AJ$65 -> MSBBPA090 | AE3: =表紙!$AQ$65 -> Web受注一覧登録（単価変更）
A5: 画面遷移フロー図
A6: ＩＤ | C6: S01 | E6: Web受注一覧登録(単価訂正)から他画面の画面遷移
D9: NO1
D10: Web受注一覧照会
D14: NO2
D15: Web製品マスタ一覧照会
Y17: Web受注一覧登録(単価訂正)
D20: NO3
D21: Web取引先一覧照会
D25: NO4
D26: Web汎用検索(共通検索)
A32: ID | D32: 処理名
A33: S01 | D33: Web受注一覧登録(単価訂正)から他画面の画面遷移 | CJ33: 画面遷移実装仕様不明、画面どこから画面を遷移します。
B35: NO | D35: 遷移元ＩＤ | H35: 遷移元画面名 | Q35: 遷移先ＩＤ | V35: 遷移先画面名 | AE35: 目的 | AJ35: 引継項目 | AS35: 遷移後のアクション(遷移先) | BC35: 戻り値 | BL35: 戻り値取得後のアクション(遷移元) | BV35: 備考
B36: 1 | D36: MSBBPA090 | H36: Web受注一覧登録(単価訂正) | Q36: MSBBPA080 | V36: Web受注一覧照会 | AE36: 検索結果取得 | AS36: 検索 | BC36: 受注明細選択データ(1行) | BL36: 対象データに値セット | BV36: 手配NOに値セット
B37: 2 | D37: MSBBPA090 | H37: Web受注一覧登録(単価訂正) | Q37: MSBBPA060 | V37: Web製品マスタ一覧照会 | AE37: 検索結果取得 | AS37: 検索 | BC37: 製品マスタ選択データ(1行) | BL37: 対象データに値セット | BV37: セット製品CD、セット品名に値セット
B38: 2' | D38: MSBBPA091 | H38: Web受注一覧登録(単価訂正) | Q38: MSBBPA060 | V38: Web製品マスタ一覧照会 | AE38: 検索結果取得 | AS38: 検索 | BC38: 製品マスタ選択データ(1行) | BL38: 対象データに値セット | BV38: 製品CD、製品名(CP品名1+2)に値セット
B39: 3 | D39: MSBBPA090 | H39: Web受注一覧登録(単価訂正) | Q39: MSBBPA120 | V39: Web取引先一覧照会 | AE39: 検索結果取得 | AJ39: 得意先ＦＬＧ=1 | AS39: 検索 | BC39: 取引先選択データ(1行) | BL39: 対象データに値セット | BV39: 得意先CD、得意先名に値セット
B40: 4 | D40: MSBBPA090 | H40: Web受注一覧登録(単価訂正) | Q40: MSBBPA900 | V40: Web汎用検索(共通検索) | AE40: 検索結果取得 | AS40: 検索 | BC40: 各種検索画面の選択データ(1行) | BL40: 対象データに値セット | BV40: CD、名称に値セット
B41: 5
B42: 6
B43: 7
B44: 8

Sheet メッセージ一覧
A1: =表紙!A54 -> Webシステム | K1: 文書名 | U1: モジュールID | Z1: =表紙!$AJ$63 -> MS | AE1: モジュール名 | AJ1: =表紙!$AX$63 -> Webシステム | AS1: 文書番号 | AZ1: Version | BF1: Rev.
K2: =表紙!O64 -> アドオン設計書 | U2: ｻﾌﾞﾓｼﾞｭｰﾙID | Z2: =表紙!$AJ$64 -> MSBB | AE2: ｻﾌﾞﾓｼﾞｭｰﾙ名 | AJ2: =表紙!$AX$64 -> Web販売管理 | AS2: =表紙!$BL$64 -> M7-US-1140 | AZ2: =表紙!$BU$64 -> 7.0.2 | BF2: =表紙!$CB$64 -> 2
K3: =RIGHT(CELL("filename",$A$1),LEN(CELL("filename",$A$1))-FIND("]",CELL("filename",$A$1))) -> メッセージ一覧 | U3: 表題 | Z3: =表紙!$AJ$65 -> MSBBPA090 | AE3: =表紙!$AQ$65 -> Web受注一覧登録（単価変更）
C4: ↓アドオン画面のため、基本全て[新]
A5: NO | C5: 新/変 | E5: 種別 | G5: メッセージ内容 | AQ5: 備考（パラメータ等） | BG5: メッセージID
A6: 1 | C6: 新 | E6: W | G6: 「検索結果がありません。」 | BG6: E10008
A7: 2 | C7: 新 | E7: W | G7: 「必須項目に値が指定されていません。」 | AQ7: 拠点 | BG7: E10022
A8: 3 | C8: 新 | E8: W | G8: 「FROM≦TOの関係で指定してください。」 | AQ8: 受注日、客先納期、数量、金額 | BG8: E10036
A10: 4 | E10: W | G10: 更新対象が、他の処理によって更新されています。最新情報を取得してください。 | BG10: W10002
A11: 5 | C11: 新 | E11: W | G11: 「検索件数の上限値を超えました。(設定値) \n 抽出条件を設定し、再度検索・照会を実施ください。」 | BG11: E10013
A12: 6 | C12: 新 | E12: I | G12: 「検索件数の上限値を超えました。(設定値) \n 処理を続ける場合は、[はい]を選択してください。」 | BG12: C00006
