Workbook
Name Rev.: [2]表紙!$U$22
Name Rev.: 表紙!$U$22
Name Revision: #REF!
Name Ver.: #REF!
Name Ver.: 表紙!$AE$26
Name Version: #REF!
Name Version: #REF!
Name ご確認者: #REF!
Name ご確認者: 表紙!$AG$40
Name ご確認日: #REF!
Name ご確認日: 表紙!$AG$42
Name サブシステム名: #REF!
Name サブシステム名: 表紙!$U$28
Name システム名: #REF!
Name システム名: 表紙!$U$26
Name プロジェクト名: #REF!
Name プロジェクト名: 表紙!$U$18
Name 開発区分: #REF!
Name 開発区分: 表紙!$U$36
Name 機能ＩＤ: #REF!
Name 機能ＩＤ: 表紙!$U$32
Name 機能区分: #REF!
Name 機能区分: 表紙!$U$34
Name 機能名称: #REF!
Name 機能名称: 表紙!$U$30
Name 顧客名: #REF!
Name 顧客名: 表紙!$U$16
Name 最終更新者: #REF!
Name 最終更新者: 表紙!$AB$40
Name 最終更新日: #REF!
Name 最終更新日: 表紙!$AB$42
Name 作成者: #REF!
Name 作成者: 表紙!$W$40
Name 作成日: #REF!
Name 作成日: 表紙!$W$42
Name 章: #REF!
Name 章: 表紙!$M$10
Name 発行日: #REF!
Name 文書番号: #REF!
Name 文書番号_カスタマイズ: '[3]表紙（カスタマイズ）'!$U$20
Name 文書名: #REF!
Name 文書名: 表紙!$M$10
Name 文書名: #REF!
Name 文書名_カスタマイズ: '[3]表紙（カスタマイズ）'!$M$10

Sheet 目次
A1: アドオン設計書作成ガイド
C3: ■アドオン設計と成果物について
D4: ・システム設計フェーズとソフトウェア設計フェーズでアドオンの処理仕様を定義する
D5: ・システム設計フェーズとソフトウェア設計フェーズの成果物がアドオン設計書であり、ソフトウェア製作フェーズのインプットとなる
C7: ■各設計フェーズ毎のアドオン設計書作成範囲
D8: ・システム設計フェーズ：他機能との関連を定義するとともに、画面や帳票、ファイル入出力を中心とした外部入出力の設計を行う
D9: ・ソフトウェア設計フェーズ：内部処理を中心とした設計を行う
U11: ◎ | W11: … | X11: システム設計フェーズで作成
U12: ○ | W12: … | X12: システム設計フェーズで基本仕様を定義して、ソフトウェア設計フェーズで詳細化する
U13: △ | W13: … | X13: 必要に応じて（例えば標準仕様から変更がない場合は不要）
U14: ‐ | W14: … | X14: 不要
W15: … | X15: ソフトウェア設計フェーズで作成
D17: 各設計書と作成対象シートのマトリックス | S17: ※カスタマイズ：標準機能に機能を追加する アドオン：新規で機能を開発する
D18: EXCELシート | N18: 画面設計書 | W18: バッチ設計書 | AF18: 帳票設計書 | AO18: ＢＩ設計書 | AT18: .Net設計書 | BB18: EXCELシート | BL18: WebDB設計書 | BR18: 帳票設計書 | BX18: 汎用申請設計書
N19: カスタマイズ | S19: アドオン | W19: カスタマイズ | AB19: アドオン | AF19: カスタマイズ | AK19: アドオン | AO19: アドオン | AT19: アドオン | BL19: アドオン | BR19: アドオン | BX19: アドオン
D20: 概要 | N20: ◎ | O20: ※1 | S20: ◎ | W20: ◎ | X20: ※1 | AB20: ◎ | AF20: ◎ | AG20: ※1 | AK20: ◎ | AO20: ◎ | AT20: ◎ | BB20: 機能概要 | BL20: ◎ | BR20: ◎ | BX20: ◎
D21: レイアウト | N21: ◎ | O21: ※2 | S21: ◎ | W21: ‐ | AB21: ‐ | AF21: ◎ | AG21: ※2 | AK21: ◎ | AO21: ◎ | AT21: ◎ | BB21: アプリケーションフロー | BL21: ◎ | BR21: ー | BX21: ◎
D22: 項目説明 | N22: △ | S22: ○ | W22: ‐ | AB22: ‐ | AF22: △ | AK22: ○ | AO22: ○ | AT22: ○ | BB22: データベース設定 | BL22: ◎ | BR22: ー | BX22: ◎
D23: 引数説明 | N23: ‐ | S23: ‐ | W23: △ | AB23: ◎ | AF23: ‐ | AK23: ‐ | AO23: ‐ | AT23: ◎ | BB23: フィールド設定 | BL23: ◎ | BR23: ー | BX23: ◎
D24: 処理概要 | N24: ◎ | S24: ◎ | W24: ◎ | AB24: ◎ | AF24: ◎ | AK24: ◎ | AO24: ◎ | AT24: ◎ | BB24: 一覧表示画面設定 | BL24: ◎ | BR24: ー | BX24: ◎
D25: 処理詳細 | BB25: 表示編集画面設定 | BL25: ◎ | BR25: ー | BX25: ◎
D26: 処理・サービス関連図 | N26: △ | S26: ◎ | W26: △ | AB26: ◎ | AF26: ‐ | AK26: ‐ | AO26: ‐ | AT26: ◎ | BB26: 明細画面設定 | BL26: △ | BN26: ※3 | BR26: ー | BX26: △ | BZ26: ※3
D27: 検索入出力仕様 | N27: △ | S27: ○ | W27: △ | AB27: ○ | AF27: ‐ | AK27: ‐ | AO27: ‐ | AT27: ○ | BB27: 集計表示設定 | BL27: △ | BN27: ※4 | BR27: ー | BX27: △ | BZ27: ※4
D28: 更新入出力仕様 | N28: △ | S28: ○ | W28: △ | AB28: ○ | AF28: ‐ | AK28: ‐ | AO28: ‐ | AT28: ○ | BB28: 絞り込み条件設定 | BL28: △ | BN28: ※5 | BR28: ー | BX28: △ | BZ28: ※5
D29: ファイル入出力仕様 | N29: △ | S29: △ | W29: ‐ | AB29: ‐ | AF29: ‐ | AK29: ‐ | AO29: ‐ | AT29: △ | BB29: その他設定 | BR29: ー
D30: 画面遷移 | N30: △ | S30: ◎ | W30: ‐ | AB30: ‐ | AF30: ‐ | AK30: ‐ | AO30: ‐ | AT30: ◎ | BB30: 帳票イメージ | BL30: ー | BR30: ◎ | BX30: ー
D31: メッセージ一覧 | N31: △ | S31: △ | W31: △ | AB31: △ | AF31: ‐ | AK31: ‐ | AO31: ‐ | AT31: △ | BB31: 項目設計 | BL31: ー | BR31: ◎ | BX31: ー
D32: 補足説明 | N32: △ | S32: △ | W32: △ | AB32: △ | AF32: △ | AK32: △ | AO32: △ | AT32: △ | BB32: 補足説明 | BL32: △ | BR32: △ | BX32: △
D33: サービス呼出編集仕様 | N33: - | S33: - | W33: - | AB33: - | AF33: - | AK33: - | AO33: - | AT33: - | BB33: 補足説明(詳細)
D35: ※1 | G35: 別シートでカスタマイズ内容を記載する | BB35: ※3 | BE35: 単票画面は記載しない
D36: ※2 | G36: 吹き出しでカスタマイズ内容を記載する | BB36: ※4 | BE36: 集計・グラフ機能を使用する場合に記載する
BB37: ※5 | BE37: 共通設定のみ記載する(個別設定は、記載しない)

Sheet 表紙
AW2: サブモジュール
AW3: MA_マスタ管理
AW4: MB_業務共通
AW5: MG_原価管理
AW6: MSBA_需給管理
M7: 基本設計 | AW7: MSBB_販売管理
AW8: MSBC_生産管理
AW9: MSBD_購買管理
M10: アドオン設計書 | AW10: MSBE_在庫物流管理
AW11: MSBF_品質管理
AW12: MSBG_債権管理
AW13: MSBH_債務管理
AW14: MSBI_締処理
AW15: MSUA_リスト・入力補助
M16: 顧客 | U16: 株式会社クラウン・パッケージ | AW16: PF_ESBアダプタ
M18: プロジェクト名 | U18: 基幹システム刷新PJ | AW18: 機能区分
AW19: 画面
M20: 文書番号 | AW20: 帳票
AW21: バッチ
M22: Ｒｅｖ． | U22: {=MAX(_xlfn.NUMBERVALUE(改訂!A7:E56))} -> 7 | AW22: マスタ
M24: 機密性区分 | U24: 取扱注意（Ｃ） | AW24: 開発区分
AW25: カスタマイズ
M26: システム名 | U26: mcframe7 | AC26: Ver. | AE26: 7.0.2 | AW26: アドオン
AW27: －
M28: サブモジュール | U28: MSBB_販売管理
M30: 機能名 | U30: =M50 -> Web受注入力
M32: 機能ID | U32: =G50 -> MSBBPA070
M34: 機能区分 | U34: 画面
M36: 開発区分 | U36: アドオン
W39: 作成 | AB39: 最終更新 | AG39: ご確認
W40: MDSOL | AB40: =改訂!AZ2 -> MDSOL 石田
W42: 44846 | AB42: =改訂!BJ2 -> 44965
A48: 文書番号 | G48: 画面ID | M48: 画面名 | V48: Version | AB48: Revision
A50: M7-US-1140 | G50: MSBBPA070 | M50: Web受注入力 | V50: 1.0.0 | AB50: r01.00
A53: 共通（元データ）
A54: Webシステム | K54: 文書名 | U54: モジュールID | Z54: MS | AE54: モジュール名 | AJ54: 見積管理 | AS54: 文書番号 | AZ54: Version | BF54: Rev.
K55: 画面説明書 | U55: ｻﾌﾞﾓｼﾞｭｰﾙID | Z55: MSBB | AE55: ｻﾌﾞﾓｼﾞｭｰﾙ名 | AJ55: Webシステム | AS55: M7-US-1140 | AZ55: 1.0.0 | BF55: r00.00
K56: 表紙 | U56: 表題 | Z56: MSBBPA070 | AE56: Web受注入力
A57: 共通（リンク用）
A58: =A54 -> Webシステム | K58: 文書名 | U58: モジュールID | Z58: =Z54 -> MS | AE58: モジュール名 | AJ58: =AJ54 -> 見積管理 | AS58: 文書番号 | AZ58: Version | BF58: Rev.
...

Sheet 改訂
A1: 第7章 | K1: 改訂 | AU1: 作成者 | AZ1: MDSOL | BE1: 作成日 | BJ1: =表紙!W42 -> 44846 | BP1: Rev.
AU2: 修正者 | AZ2: =BM18 -> MDSOL 石田 | BE2: 改訂日 | BJ2: =MAX(改訂!BM7:BQ58) -> 44965 | BP2: {=MAX(_xlfn.NUMBERVALUE(改訂!A7:E56))} -> 7
A5: Rev. | F5: 改定内容 | BC5: 頁 | BM5: 変更日 変更者 | BR5: 確認日 確認者
A7: 1 | F7: 新規作成 | BM7: 44865
BM8: MDSOL
A9: 2 | F9: 仕様連絡書：RCS-1062に伴う下記改定を実施 案件NOをDBの項目は、案件NO(親)＋案件NO(子)＋案件NO(部材)に分割する ※画面項目は、1つとする | BC9: 項目説明、更新入出力仕様 | BM9: 44894 | BR9: 44895
BM10: MDSOL | BR10: MDSOL 奥本
A11: 2 | F11: 仕様連絡書：RCS-1062に伴う下記改定を実施 FSC製品区分に統合(FSC認証製品＝FSC製品区分) | BC11: レイアウト、項目説明、検索入出力仕様、更新入出力仕様、ファイル入出力仕様 | BM11: 44894 | BR11: 44895
BM12: MDSOL | BR12: MDSOL 奥本
A13: 2 | F13: 仕様連絡書：RCS-1062に伴う下記改定を実施 高品質→高管理、各画面から項目削除、DB項目としては残す | BC13: 更新入出力仕様 | BM13: 44896 | BR13: 44896
BM14: MDSOL | BR14: MDSOL 奥本
A15: 3 | F15: 仕様連絡書：RCS-1073に伴う下記改定を実施 購買品受注の時に、発注単価が必要 | BC15: レイアウト、項目説明、検索入出力仕様、更新入出力仕様 | BM15: 44909 | BR15: 44909
BM16: MDSOL 石田 | BR16: MDSOL 奥本
A17: 3 | F17: 仕様連絡書：RCS-1073に伴う下記改定を実施 過去受注をコピーした時に、セットしたくない項目がある | BC17: 処理概要 | BM17: 44909 | BR17: 44909
BM18: MDSOL 石田 | BR18: MDSOL 奥本
A19: 4 | F19: 仕様連絡書：RCS-1158に伴う下記改定を実施 WEB受注明細、mcf受注明細の関係を明記。 | BC19: 概要、補足説明資料 | BM19: 44937 | BR19: 44939
BM20: MDSOL 石田 | BR20: MDSOL 奥本
A21: 4 | F21: 仕様連絡書：RCS-1158に伴う下記改定を実施 預り売上数の項目追加と入力チェック | BC21: 処理概要、レイアウト、項目説明、処理概要、検索入出力仕様、更新入出力仕様、メッセージ一覧 | BM21: 44937 | BR21: 44939
BM22: MDSOL 石田 | BR22: MDSOL 奥本
A23: 4 | F23: 仕様連絡書：RCS-1158に伴う下記改定を実施 仕掛チェックの追加 | BC23: 処理概要、補足説明資料_仕掛チェック | BM23: 44937 | BR23: 44939
BM24: MDSOL 石田 | BR24: MDSOL 奥本
A25: 4 | F25: 仕様連絡書：RCS-1158に伴う下記改定を実施 行コピーの有効条件追加 | BC25: 処理概要 | BM25: 44937 | BR25: 44939
BM26: MDSOL 石田 | BR26: MDSOL 奥本
A27: 4 | F27: メッセージ一覧にメッセージを追加する。 | BC27: メッセージ一覧 | BM27: 44909
BM28: TBK徐
A29: 4 | F29: 処理詳細の追加 | BC29: 処理詳細 | BM29: 44909
BM30: TBK徐
A31: 4 | F31: メッセージ一覧の採番 | BC31: メッセージ一覧 | BM31: 44931
BM32: TBK徐
A33: 5 | F33: 仕様連絡書：RCS-1115に伴う下記改定を実施 項目説明に画面レイアウト項目の不足分を追加 | BC33: 項目説明 | BM33: 44959 | BR33: 44960
BM34: MDSOL 石田 | BR34: MDSOL 奥本
A35: 5 | F35: 仕様連絡書：RCS-1115に伴う下記改定を実施 処理概要とメッセージ一覧の紐づけ見直し | BC35: 処理概要 | BM35: 44959 | BR35: 44960
BM36: MDSOL 石田 | BR36: MDSOL 奥本
A37: 5 | F37: 仕様連絡書：RCS-1115に伴う下記改定を実施 処理・サービス関連図のテーブル名修正 | BC37: 処理・サービス関連図 検索入出力仕様 | BM37: 44959 | BR37: 44960
BM38: MDSOL 石田 | BR38: MDSOL 奥本
A39: 6 | F39: シ設計集中見直し（RCS-1229）:参照元_見積計算書ＮＯ 項目削除／項目見直し(見積計算書ＮＯ) | BC39: 更新入出力仕様 | BM39: 44964 | BR39: 44964
BM40: MDSOL野村 | BR40: MDSOL 奥本
A41: 6 | F41: シ設計集中見直し（RCS-1229）:製品CD桁数見直し(15桁に変更) | BC41: 項目説明 | BM41: 44964 | BR41: 44965
BM42: MDSOL野村 | BR42: MDSOL 奥本
A43: 7 | F43: シ設計集中見直し（RCS-1229）:受注画面表示制御の追加 | BC43: レイアウト、処理概要、 補足説明資料_受注画面制御、受発注パタン詳細 | BM43: 44965 | BR43: 44966
...

Sheet 概要
A1: =表紙!A54 -> Webシステム | O1: 文書名 | AC1: モジュールID | AJ1: =表紙!AJ63 -> MS | AQ1: モジュール名 | AX1: =表紙!AX63 -> 見積管理 | BL1: 文書番号 | BU1: Version | CB1: Rev.
O2: =表紙!O64 -> アドオン設計書 | AC2: サブモジュールID | AJ2: =表紙!AJ64 -> MSBB | AQ2: サブモジュール名 | AX2: =表紙!AX64 -> Webシステム | BL2: =表紙!BL64 -> M7-US-1140 | BU2: =表紙!BU64 -> 7.0.2 | CB2: =表紙!CB64 -> 7
O3: =RIGHT(CELL("filename",$A$1),LEN(CELL("filename",$A$1))-FIND("]",CELL("filename",$A$1))) -> 概要 | AC3: 表題 | AJ3: =表紙!AJ65 -> MSBBPA070 | AQ3: =表紙!AQ65 -> Web受注入力
AO5: 概要
B7: 【業務要件】
C8: カスタマイズ | G8: 内容
C9: No.
C10: 4 | G10: 見積WEBシステムを構築する。
G11: 見積Webシステム：主要機能 ①見積(見積計算書)入力・発行②御見積書入力・発行③見積確定④受注入力⑤受注一覧(単価訂正)⑥製品マスタ⑦得意先マスタ⑧シート単価マスタ
C12: 126 | G12: 売上計算方法がmcframe7の数量＊単価ではなく数量＊単価＊寸法など異なっている。現行の売上計算方法をmcframe7で実現する。
G13: 既存単価とは別に単価項目を追加しユーザーはそこに単価を登録する。
G14: 売上計算方法の計算根拠項目を追加し売上計算を行い1数量辺りの単価をmcframe既存単価に自動設定して金額を合わせる。
C15: 146 | G15: 当初想定は、1画面で明細形式での画面構成を想定していたが、製品マスタと同等のテーブル構造を持ち、受注入力でも工程仕様画面を表示(仕様の変更可はシート受注のみ)するように変更する
B19: 【説明】
C20: 製品マスタ、過去受注より受注入力を行う。
B22: 【目的】
C23: ・受注を登録・訂正・参照する。
B25: 【オペレーション一覧】
C26: WEB受注の登録・更新処理を行う
C27: WEB受注の検索・照会処理を行う
B30: 【SQLID一覧】
C31: なし
B33: 【ソート順】
C34: なし
B36: 【データアクセスコントロール】
C37: 拠点による制御
C38: ※詳細は、【MSBBPA000】_共通設計書_アドオン(Webシステム共通仕様)にて定義
B40: 【自由記述】
C41: 前提条件として予備、サンプル、預かりは本体のWEB受注明細に含まれ独立したWEB受注明細としては持たない。mcframe受注明細では独立し本体の受注明細とは分割する。 | CJ41: REV4.0 WEB受注明細、mcf受注明細の関係を明記
C42: 詳細は「補足説明資料」シート参照。 | CJ42: REV4.0 WEB受注明細、mcf受注明細の関係を明記

Sheet 概要 (セッション用)
A1: =表紙!A54 -> Webシステム | O1: 文書名 | AC1: モジュールID | AJ1: =表紙!AJ63 -> MS | AQ1: モジュール名 | AX1: =表紙!AX63 -> 見積管理 | BL1: 文書番号 | BU1: Version | CB1: Rev.
O2: =表紙!O64 -> アドオン設計書 | AC2: サブモジュールID | AJ2: =表紙!AJ64 -> MSBB | AQ2: サブモジュール名 | AX2: =表紙!AX64 -> Webシステム | BL2: =表紙!BL64 -> M7-US-1140 | BU2: =表紙!BU64 -> 7.0.2 | CB2: =表紙!CB64 -> 7
O3: =RIGHT(CELL("filename",$A$1),LEN(CELL("filename",$A$1))-FIND("]",CELL("filename",$A$1))) -> 概要 (セッション用) | AC3: 表題 | AJ3: =表紙!AJ65 -> MSBBPA070 | AQ3: =表紙!AQ65 -> Web受注入力
AO5: 概要

Sheet WEBテーブル関連図
A1: =表紙!A54 -> Webシステム | O1: 文書名 | AC1: モジュールID | AJ1: =表紙!AJ63 -> MS | AQ1: モジュール名 | AX1: =表紙!AX63 -> 見積管理 | BL1: 文書番号 | BU1: Version | CB1: Rev.
O2: =表紙!O64 -> アドオン設計書 | AC2: サブモジュールID | AJ2: =表紙!AJ64 -> MSBB | AQ2: サブモジュール名 | AX2: =表紙!AX64 -> Webシステム | BL2: =表紙!BL64 -> M7-US-1140 | BU2: =表紙!BU64 -> 7.0.2 | CB2: =表紙!CB64 -> 7
O3: =RIGHT(CELL("filename",$A$1),LEN(CELL("filename",$A$1))-FIND("]",CELL("filename",$A$1))) -> WEBテーブル関連図 | AC3: 表題 | AJ3: =表紙!AJ65 -> MSBBPA070 | AQ3: =表紙!AQ65 -> Web受注入力
AO5: WEBテーブル関連図

Sheet レイアウト
A1: =表紙!A54 -> Webシステム | K1: 文書名 | U1: モジュールID | Z1: =表紙!$AJ$63 -> MS | AE1: モジュール名 | AJ1: =表紙!$AX$63 -> 見積管理 | AS1: 文書番号 | AZ1: Version | BF1: Rev.
K2: =表紙!O64 -> アドオン設計書 | U2: ｻﾌﾞﾓｼﾞｭｰﾙID | Z2: =表紙!$AJ$64 -> MSBB | AE2: ｻﾌﾞﾓｼﾞｭｰﾙ名 | AJ2: =表紙!$AX$64 -> Webシステム | AS2: =表紙!$BL$64 -> M7-US-1140 | AZ2: =表紙!$BU$64 -> 7.0.2 | BF2: =表紙!$CB$64 -> 7
K3: =RIGHT(CELL("filename",$A$1),LEN(CELL("filename",$A$1))-FIND("]",CELL("filename",$A$1))) -> レイアウト | U3: 表題 | Z3: =表紙!$AJ$65 -> MSBBPA070 | AE3: =表紙!$AQ$65 -> Web受注入力
A5: 画面イメージ
B7: ≫凡例
Q8: ・・・ | S8: ボタン
C9: 見積計算書№ | Q9: ・・・ | S9: 検索項目(検索画面表示選択)
C10: 品名 | Q10: ・・・ | S10: 入力項目
C11: 得意先 | Q11: ・・・ | S11: 表示項目(得意先名称、原紙名等)
C12: 操作種別 | I12: ●登録 | M12: ○訂正 | Q12: ・・・ | S12: 選択項目(一つのみ選択可能)
C13: 受注区分 | Q13: ・・・ | S13: 選択項目(一つのみ選択可能)
C14: 作業順 | I14: ☑AAA | M14: ☑BBB | Q14: ・・・ | S14: 選択項目(複数選択可能)
C23: TOP画面
BZ24: CP指摘 2022/10/02 落合 コピーの操作種別が必要か疑問。 登録で手配№を指定されたらコピーで良いように思うが？ | DJ24: MDSOL回答 石田 2022/10/27 コピーの操作種別をなくしました。 | EE24: 2022/10/29 落合 問題なし
D25: 操作種別 | J25: ●登録 | N25: ○訂正 | R25: ○削除 | V25: ○参照 | BZ25: CP指摘 2022/10/02 落合 手配№オートコンプリート。 得意先指定がある事を条件に過去3か月の受注を対象に検索をかける。 表示項目（品名１・２、段 構成名 シート寸法）2段表示が可能か確認願います。 | EG25: MDSOL回答 石田 2022/10/27 共通ロジック（【MSBBPACOM】_共通設計書_アドオン(Web共通ロジック)）_の方で記載致しました。 | FT25: 2022/10/29 落合 記載箇所が不明 | GG25: MDSOL回答 2022/10/31 手配NOの表示条件に追加しました。 2段表示は難しいとのことです。 | HI25: 2022/11/01 落合 問題なし
D26: 受注区分 | S26: 得意先 | AO26: 手配NO | BK26: ←「訂正」「削除」「参照」の時、初期フォーカス | CA26: 品名もしくはシート寸法でほぼ検索可能な想定
BZ27: CP指摘 2022/9/30 落合 製品区分（大）は第2画面へ移動。 代わりに得意先を製品区分（大）の位置に移動 | DQ27: MDSOL回答 石田 2022/10/27 対応しました | EF27: 2022/10/29 落合 問題なし
BZ28: 部材ごとに製品区分が変わる為
D29: 受注部門 | AD29: 受注日 | AO29: 受注区分 | BZ29: 製品区分の吹き出しに記載の画面遷移は、受注区分にて判断する
D30: 得意先 | AD30: 客先納期 | AO30: 数量 | BZ30: CP指摘 2022/10/02 落合 受注一覧照会を開いたときに、受注区分・得意先CD・受注日（当日から6か月の範囲）で | DQ30: MDSOL回答 石田 2022/10/27 共通ロジック（【MSBBPACOM】_共通設計書_アドオン(Web共通ロジック)）_の方で記載致しました。 | FE30: 2022/10/29 落合 記載箇所が不明 | FR30: MDSOL回答 2022/10/31 WEB受注一覧照会の設計書に追記しました。 | GN30: 2022/11/01 落合 問題なし
BZ31: CP指摘 2022/9/30 落合 得意先指定時、与信限度額超えていたらアラート「与信限度額を超えています。受注継続するか要確認！」 | DQ31: MDSOL回答 石田 2022/10/27 金額が未定のため、登録時では駄目でしょうか？登録時には与信チェックを入れています。取引先指定のタイミングの場合は既に与信限度額を超えている場合になります。 | FU31: 2022/10/29 落合 入力中の受注を除いて既に超えている場合です。 | GQ31: MDSOL回答 2022/10/31 石田 承知しました。処理概要に得意先指定時（TOP画面、基本画面）を記載致しました。 | HY31: 2022/11/01 落合 問題なし
D32: 注文書No | W32: 先方担当 | AO32: 宛名 | BC32: 様 | BZ32: CP指摘 2022/10/27 落合 出荷日時ですが、1時間刻みの時間指定＋昼積み＋夜積みになっていると思いますが、出荷予定の時間にセットすることで可能でしょうか？ | DQ32: MDSOL回答 石田 2022/10/28 可能です。昼積みと夜積みについては00：00：00でそれ以外は時間を設定します。 | EY32: 2022/10/29 落合 問題なし
D33: 運送会社 | W33: 出荷日時 | BZ33: CP指摘 2022/9/30 落合 得意先のオートコンプリート表示項目（管轄拠点・得意先CD・得意先名・住所１・２・電話番号） | DQ33: MDSOL回答 石田 2022/10/27 共通ロジック（【MSBBPACOM】_共通設計書_アドオン(Web共通ロジック)）_の方で記載致しました。 | FD33: 2022/11/01 落合 問題なし
D35: 売価区分 | BZ35: CP指摘 2022/9/30 落合 客納期が標準リードタイムを下回っているときアラート「納期まで製造必要日数を下回っています。要調整！」 | DQ35: MDSOL回答 石田 2022/10/27 処理概要に記載致しました。 | EJ35: 2022/10/29 落合 問題なし
BZ36: CP指摘 2022/9/30 落合 客納期・出荷日が非稼働日の時アラート「客納期が非稼働日です。」「出荷日が非稼働日です。」 | DQ36: MDSOL回答 石田 2022/10/27 処理概要に記載致しました。 | EJ36: 2022/10/29 落合 問題なし
D37: 受注明細
D38: 製品CD | J38: (件名:オートフィルタ) | AC38: ← ｾｯﾄ品目指定することで、以下の一覧に部材品目表示
D41: № | F41: 手配NO1 | I41: 手配NO2 | L41: 手配NO3 | O41: 製品CD/品目CD | T41: CP品名1 | Y41: CP品名2 | AB41: 単位 | AD41: 数量 | AG41: 特値 | AJ41: 個別単価 | AM41: ｾｯﾄ単価 | AP41: 客先納期 | AT41: 手配区分 | AW41: 納品先 | BA41: 納品先名 | BE41: 物流グループ | BH41: 預り売上 | BL41: 売上理由 | BP41: 受注№/受注明細№
E42: 1 | I42: 得意先CD | L42: 案件№ | T42: 味比べ3P箱 身 | AG42: □ | BI42: □
E43: 2 | I43: 得意先CD | L43: 案件№ | T43: 味比べ3P箱 蓋 | AG43: □ | BI43: □ | BZ43: CP指摘 2022/9/30 落合 受注明細単位の納期が必要。預かり売上する為に分割したときに、売上日を指定するため。 製造前に納期を分けた時に、製造予定が分割される懸念がある。 | DQ43: MDSOL回答 石田 2022/10/27 対応しました | EG43: 2022/11/01 落合 問題なし
E44: 3 | I44: 得意先CD | L44: 案件№ | T44: 味比べ3P箱 仕切り | AG44: □ | AT44: 仕入直送 | BI44: □ | DQ44: CP指摘 2022/10/29 落合 受注時に納期分割して登録した場合は、生産予定が分割される認識ですが合っていますか？ | FD44: MDSOL回答 2022/10/31 コピー行追加で納期を変更した場合は、手配NOが同一となるため、まとめ期間内ならまとまります。行追加の場合は分割されます。 | GV44: 2022/11/01 落合 問題なし
F46: ※メニュー「シート受注入力」を選択した場合は、第２画面からスタート
F47: ※メニュー「購買品受注入力」を選択した場合は、第２画面からスタート。 工程情報登録はなし。 入力項目の追加あり。
C53: 第２画面 | H53: ※部材の種類分、第２画面が連続して表示される
D54: 基本情報
D56: 納品先 | O56: 手配区分 | AA56: 預り売上 □ | AJ56: 出荷日時
D58: 売上WG | H58: 30 名古屋 | O58: 受注区分 | AC58: 製品区分 | AE58: 大 | AL58: 中 | AS58: 小 | BZ58: CP指摘 2022/10/27 落合 手配№２の表示は不要（得意先CDと同じため） 手配№３は見出しを「案件NO」にする | DH58: MDSOL回答 石田 2022/10/28 修正しました | DX58: 2022/10/29 落合 問題なし
D59: 手配NO | O59: 案件NO
D60: 得意先 | X60: 客先納期 | BZ60: CP指摘 2022/09/30 落合 購買品受注入力の時に、製品CD・版型№の入力が必要 | DA60: MDSOL回答 石田 2022/10/27 追加致しました | DR60: 2022/10/29 落合 問題なし
D61: 製品CD/品目CD | O61: 顧客品名1 | AI61: 顧客品名2 | CF61: 未入力時アラート表示 「未入力」
...

Sheet レイアウト(CP案_0518)
A1: =表紙!A54 -> Webシステム | K1: 文書名 | U1: モジュールID | Z1: =表紙!$AJ$63 -> MS | AE1: モジュール名 | AJ1: =表紙!$AX$63 -> 見積管理 | AS1: 文書番号 | AZ1: Version | BF1: Rev.
K2: =表紙!O64 -> アドオン設計書 | U2: ｻﾌﾞﾓｼﾞｭｰﾙID | Z2: =表紙!$AJ$64 -> MSBB | AE2: ｻﾌﾞﾓｼﾞｭｰﾙ名 | AJ2: =表紙!$AX$64 -> Webシステム | AS2: =表紙!$BL$64 -> M7-US-1140 | AZ2: =表紙!$BU$64 -> 7.0.2 | BF2: =表紙!$CB$64 -> 7
K3: =RIGHT(CELL("filename",$A$1),LEN(CELL("filename",$A$1))-FIND("]",CELL("filename",$A$1))) -> レイアウト(CP案_0518) | U3: 表題 | Z3: =表紙!$AJ$65 -> MSBBPA070 | AE3: =表紙!$AQ$65 -> Web受注入力
A5: 画面イメージ
B7: ≫凡例
Q8: ・・・ | S8: ボタン
C9: 見積計算書№ | Q9: ・・・ | S9: 検索項目(検索画面表示選択)
C10: 品名 | Q10: ・・・ | S10: 入力項目
C11: 得意先 | Q11: ・・・ | S11: 表示項目(得意先名称、原紙名等)
C12: 操作種別 | I12: ●登録 | M12: ○訂正 | Q12: ・・・ | S12: 選択項目(一つのみ選択可能)
C13: 受注区分 | Q13: ・・・ | S13: 選択項目(一つのみ選択可能)
C14: 作業順 | I14: ☑AAA | M14: ☑BBB | Q14: ・・・ | S14: 選択項目(複数選択可能)
C16: 第1画面
D21: 操作種別 | J21: ●登録 | N21: ○訂正 | R21: ○削除 | V21: ○参照
D23: 受注部門 | AD23: 受注日
D24: 得意先 | AD24: 客納期 | AO24: 数量
D26: 注文書No | W26: 先方担当 | AO26: 宛名 | BB26: 様
D27: 運送会社 | W27: 出荷時間
D29: 手配NO | AD29: ← 「登録」時、コピー元手配№。 「訂正」「削除」「参照」の時、初期フォーカス
D31: 受注明細
D32: 製品CD | J32: (件名:オートフィルタ) | AC32: ← ｾｯﾄ品目指定することで、以下の一覧に部材品目表示
D34: № | F34: 手配NO1 | J34: 手配NO2 | N34: 手配NO3 | R34: 製品CD | Z34: 製品名 | AJ34: 単位 | AN34: 数量 | AS34: 特値 | AV34: 単価 | AZ34: 金額 | BD34: 手配区分 | BH34: 納入先 | BL34: 納入先名 | BP34: 物流グループ | BT34: 預り売上 | BX34: 売上理由 | CB34: 受注明細№
E35: 1 | J35: 得意先CD | N35: 案件№ | Z35: 味比べ3P箱 身 | AS35: □ | BU35: □
E36: 2 | J36: 得意先CD | N36: 案件№ | Z36: 味比べ3P箱 身 | AS36: □ | BU36: □ | BX36: 製造予備
E37: 3 | J37: 得意先CD | N37: 案件№ | Z37: 味比べ3P箱 蓋 | AS37: □ | BU37: □
E38: 4 | J38: 得意先CD | N38: 案件№ | Z38: 味比べ3P箱 仕切り | AS38: □ | BD38: 仕入直送 | BU38: □
F40: ※メニュー「シート受注入力」を選択した場合は、第２画面からスタート
F41: ※メニュー「購買品受注入力」を選択した場合は、第２画面からスタート。 工程情報登録はなし。 入力項目の追加あり。
C46: 第２画面 | H46: ※部材の種類分、第２画面が連続して表示される
D47: 基本情報
F48: 手配NO | O48: 得意先 | AI48: 客納期 | AS48: 数量 | BC48: 単位
F49: 製品CD | O49: 顧客品名
O50: CP品名1 | AI50: CP品名2
F51: 顧客注文№ | O51: 顧客品番
F52: FSC認証 | O52: 食品安全
D54: 予備 | H54: 納入予備 | P54: 製造予備 | X54: 営業サンプル
D55: 備考
D60: ↓ 段・原紙構成・寸法などは、全て工程情報として入力を行う。 工程画面にて工程に対して材料指定を行う。 作業順別の材料指定は不可。 工程の下にツリービューにて材料をぶら下げる
BQ93: 第３画面 ロット別単価設定画面へ

Sheet レイアウト旧
A1: =表紙!A54 -> Webシステム | K1: 文書名 | U1: モジュールID | Z1: =表紙!$AJ$63 -> MS | AE1: モジュール名 | AJ1: =表紙!$AX$63 -> 見積管理 | AS1: 文書番号 | AZ1: Version | BF1: Rev.
K2: =表紙!O64 -> アドオン設計書 | U2: ｻﾌﾞﾓｼﾞｭｰﾙID | Z2: =表紙!$AJ$64 -> MSBB | AE2: ｻﾌﾞﾓｼﾞｭｰﾙ名 | AJ2: =表紙!$AX$64 -> Webシステム | AS2: =表紙!$BL$64 -> M7-US-1140 | AZ2: =表紙!$BU$64 -> 7.0.2 | BF2: =表紙!$CB$64 -> 7
K3: =RIGHT(CELL("filename",$A$1),LEN(CELL("filename",$A$1))-FIND("]",CELL("filename",$A$1))) -> レイアウト旧 | U3: 表題 | Z3: =表紙!$AJ$65 -> MSBBPA070 | AE3: =表紙!$AQ$65 -> Web受注入力
A5: 画面イメージ
B7: ≫凡例
Q8: ・・・ | S8: ボタン
C9: 見積計算書№ | Q9: ・・・ | S9: 検索項目(検索画面表示選択)
C10: 品名 | Q10: ・・・ | S10: 入力項目
C11: 得意先 | Q11: ・・・ | S11: 表示項目(得意先名称、原紙名等)
C12: 操作種別 | I12: ●登録 | M12: ○訂正 | Q12: ・・・ | S12: 選択項目(一つのみ選択可能)
C13: 受注区分 | Q13: ・・・ | S13: 選択項目(一つのみ選択可能)
C14: 作業順 | I14: ☑AAA | M14: ☑BBB | Q14: ・・・ | S14: 選択項目(複数選択可能)
C16: TOP画面
D21: 操作種別 | J21: ●登録 | N21: ○訂正 | R21: ○削除 | V21: ○参照 | Z21: ○コピー
D23: 製品CD | J23: (件名:オートフィルタ) | AD23: 手配NO | BE23: 得意先
D25: ↑新規時 有効 | AD25: ↑訂正、削除、参照時 有効
D29: 基本情報
D31: 案件№ | AD31: 受注№
D33: 受注部門 | V33: 最終製造部門 | AN33: シート部門
D34: 受注日 | V34: 運送会社 | AN34: 夜積区分 | AX34: (1:夜、0:昼)
D36: 得意先 | J36: (得意先名:オートフィルタ) | AH36: 先方担当
AH37: 宛名 | AX37: 様
D39: 注文書No
D45: 受注明細
D47: № | F47: 受注明細№ | N47: 製品CD | V47: 製品名 | AF47: 単位 | AJ47: 数量 | AN47: 平米 | AS47: 特値 | AV47: 単価 | AZ47: 金額 | BD47: 手配NO1 | BH47: 手配NO2 | BL47: 手配NO3 | BP47: 手配区分 | BT47: 納入先 | BX47: 納入先名 | CB47: 物流グループ | CF47: 預り売上 | CJ47: 売上理由
E48: 1 | V48: 味比べ3P箱 身 | AS48: □ | CG48: □
E49: 2 | V49: 味比べ3P箱 身 | AS49: □ | CG49: □ | CJ49: 製造予備
E50: 3 | V50: 味比べ3P箱 蓋 | AS50: □ | CG50: □
E51: 4 | V51: 味比べ3P箱 仕切り | AS51: □ | BP51: 仕入直送 | CG51: □
D57: 基本情報
D60: シート 段 | V60: メーカー
D61: 構成 | F61: 表 | J61: C5R | O61: Ｃ５（Ｆリサイクル）
F62: 中 | J62: 001R | O62: 中芯（Ｆリサイクル)
F63: 裏 | J63: C5R | O63: Ｃ５（Ｆリサイクル）
D65: 33:コート | J65: 表幅 | M65: 幅 | Q65: 流れ | V65: コルスリ | AA65: 割数 | AE65: 断裁区分
D66: シート寸法 | P66: × | V66: 4 | X66: 化半 | AH66: (1:外注)
D67: スリッター | P67: ×
D69: 予備必要 | J69: 納入予備 | S69: 製造予備 | AB69: 営業サンプル
D71: 定数出荷 | N71: (1:定数出荷)
D73: 貼合日 | P73: 課長立会有無 | AA73: コルゲータ反転有無 | AN73: エッジプレス | AX73: 協力会社指示 | BJ73: シート荷姿指示 | BU73: 協力会社指示
...

Sheet レイアウト (シート)
A1: =表紙!A54 -> Webシステム | K1: 文書名 | U1: モジュールID | Z1: =表紙!$AJ$63 -> MS | AE1: モジュール名 | AJ1: =表紙!$AX$63 -> 見積管理 | AS1: 文書番号 | AZ1: Version | BF1: Rev.
K2: =表紙!O64 -> アドオン設計書 | U2: ｻﾌﾞﾓｼﾞｭｰﾙID | Z2: =表紙!$AJ$64 -> MSBB | AE2: ｻﾌﾞﾓｼﾞｭｰﾙ名 | AJ2: =表紙!$AX$64 -> Webシステム | AS2: =表紙!$BL$64 -> M7-US-1140 | AZ2: =表紙!$BU$64 -> 7.0.2 | BF2: =表紙!$CB$64 -> 7
K3: =RIGHT(CELL("filename",$A$1),LEN(CELL("filename",$A$1))-FIND("]",CELL("filename",$A$1))) -> レイアウト (シート) | U3: 表題 | Z3: =表紙!$AJ$65 -> MSBBPA070 | AE3: =表紙!$AQ$65 -> Web受注入力
A5: 画面イメージ
B7: ≫凡例
Q8: ・・・ | S8: ボタン
C9: 見積計算書№ | Q9: ・・・ | S9: 検索項目(検索画面表示選択)
C10: 品名 | Q10: ・・・ | S10: 入力項目
C11: 得意先 | Q11: ・・・ | S11: 表示項目(得意先名称、原紙名等)
C12: 操作種別 | I12: ●登録 | M12: ○訂正 | Q12: ・・・ | S12: 選択項目(一つのみ選択可能)
C13: 受注区分 | Q13: ・・・ | S13: 選択項目(一つのみ選択可能)
C14: 作業順 | I14: ☑AAA | M14: ☑BBB | Q14: ・・・ | S14: 選択項目(複数選択可能)
C16: TOP画面
D21: 操作種別 | J21: ●登録 | N21: ○訂正 | R21: ○削除 | V21: ○参照 | Z21: ○コピー
D23: 製品CD | J23: (件名:オートフィルタ) | AD23: 手配NO | BE23: 得意先
D25: ↑新規時 有効 | AD25: ↑訂正、削除、参照時 有効
D31: 基本情報
D33: 案件№
D35: 受注部門 | V35: 最終製造部門 | AN35: シート部門
D36: 受注日 | V36: 運送会社 | AN36: 夜積区分 | AX36: (1:夜、0:昼)
D38: 得意先 | J38: (得意先名:オートフィルタ) | AH38: 先方担当
AH39: 宛名 | AX39: 様
D41: 注文書No
D52: 受注明細
D54: № | F54: 製品CD | N54: 製品名 | X54: 単位 | AB54: 数量 | AF54: 平米 | AK54: 特値 | AN54: 単価 | AR54: 金額 | AV54: 手配NO1 | AZ54: 手配NO2 | BD54: 手配NO3 | BH54: 手配区分 | BL54: 納入先 | BP54: 納入先名 | BT54: 物流グループ | BX54: 預り売上 | CB54: 売上理由
E55: 1 | N55: シート | AK55: □ | BY55: □
E56: 2 | N56: シート | AK56: □ | AN56: 0 | BY56: □ | CB56: 納入予備
D61: 基本情報
D63: 受注区分 | J63: 1 | L63: 製品 | T63: 製品区分 | Z63: 11:シート
D65: 客品名 | AD65: 客先品番
D66: CP品名 | AD66: 部材名 | AU66: JANコード
D68: シート 段 | V68: メーカー
D69: 構成 | F69: 表 | J69: C5R | O69: Ｃ５（Ｆリサイクル）
F70: 中 | J70: 001R | O70: 中芯（Ｆリサイクル)
F71: 裏 | J71: C5R | O71: Ｃ５（Ｆリサイクル）
J73: 表幅 | M73: 幅 | Q73: 流れ | V73: コルスリ | AA73: 割数 | AE73: 断裁区分 | AM73: スコアラ寸法
D74: シート寸法 | P74: × | V74: 4 | X74: 化半 | AH74: (1:外注) | AP74: ＋ | AT74: ＋ | AX74: ＋ | BB74: ＋
D75: 受注寸法１ | P75: ×
D76: 受注寸法２ | P76: × | V76: 売上巾
D78: 予備必要 | J78: 納入予備 | S78: 製造予備 | AB78: 営業サンプル
...

Sheet レイアウト (商品購買) 
A1: =表紙!A54 -> Webシステム | K1: 文書名 | U1: モジュールID | Z1: =表紙!$AJ$63 -> MS | AE1: モジュール名 | AJ1: =表紙!$AX$63 -> 見積管理 | AS1: 文書番号 | AZ1: Version | BF1: Rev.
K2: =表紙!O64 -> アドオン設計書 | U2: ｻﾌﾞﾓｼﾞｭｰﾙID | Z2: =表紙!$AJ$64 -> MSBB | AE2: ｻﾌﾞﾓｼﾞｭｰﾙ名 | AJ2: =表紙!$AX$64 -> Webシステム | AS2: =表紙!$BL$64 -> M7-US-1140 | AZ2: =表紙!$BU$64 -> 7.0.2 | BF2: =表紙!$CB$64 -> 7
K3: =RIGHT(CELL("filename",$A$1),LEN(CELL("filename",$A$1))-FIND("]",CELL("filename",$A$1))) -> レイアウト (商品購買) | U3: 表題 | Z3: =表紙!$AJ$65 -> MSBBPA070 | AE3: =表紙!$AQ$65 -> Web受注入力
A5: 画面イメージ
B7: ≫凡例
Q8: ・・・ | S8: ボタン
C9: 見積計算書№ | Q9: ・・・ | S9: 検索項目(検索画面表示選択)
C10: 品名 | Q10: ・・・ | S10: 入力項目
C11: 得意先 | Q11: ・・・ | S11: 表示項目(得意先名称、原紙名等)
C12: 操作種別 | I12: ●登録 | M12: ○訂正 | Q12: ・・・ | S12: 選択項目(一つのみ選択可能)
C13: 受注区分 | Q13: ・・・ | S13: 選択項目(一つのみ選択可能)
C14: 作業順 | I14: ☑AAA | M14: ☑BBB | Q14: ・・・ | S14: 選択項目(複数選択可能)
C16: TOP画面
D21: 操作種別 | J21: ●登録 | N21: ○訂正 | R21: ○削除 | V21: ○参照 | Z21: ○コピー
D23: 製品CD | J23: (件名:オートフィルタ) | AD23: 手配NO | BE23: 得意先
D25: ↑新規時 有効 | AD25: ↑訂正、削除、参照時 有効
D31: 基本情報
D33: 案件№
D35: 受注部門 | V35: 最終製造部門 | AN35: シート部門
D36: 受注日 | V36: 運送会社 | AN36: 夜積区分 | AX36: (1:夜、0:昼)
D38: 得意先 | J38: (得意先名:オートフィルタ) | AH38: 先方担当
AH39: 宛名 | AX39: 様
D41: 注文書No
D52: 受注明細
D54: № | F54: 製品CD | N54: 製品名 | X54: 単位 | AB54: 数量 | AF54: 平米 | AK54: 特値 | AN54: 単価 | AR54: 金額 | AV54: 手配NO1 | AZ54: 手配NO2 | BD54: 手配NO3 | BH54: 手配区分 | BL54: 発注先 | BP54: 発注先名 | BT54: 納入先 | BX54: 納入先名 | CB54: 物流グループ | CF54: 預り売上 | CJ54: 売上理由
E55: 1 | N55: 商品 | AK55: □ | CG55: □
D61: 基本情報
D63: 客品名 | AD63: 客先品番
D64: CP品名 | AD64: 部材名 | AU64: JANコード
D66: 版型NO
D68: シート 段 | V68: メーカー
D69: 構成 | F69: 表 | J69: C5R | O69: Ｃ５（Ｆリサイクル）
F70: 中 | J70: 001R | O70: 中芯（Ｆリサイクル)
F71: 裏 | J71: C5R | O71: Ｃ５（Ｆリサイクル）
J73: 表幅 | M73: 幅 | Q73: 流れ | V73: コルスリ | AA73: 割数 | AE73: 断裁区分
D74: シート寸法 | P74: × | V74: 4 | X74: 化半 | AH74: (1:外注)
D75: スリッター | P75: ×
D77: 予備必要 | J77: 納入予備 | S77: 製造予備 | AB77: 営業サンプル
D79: 定数出荷 | N79: (1:定数出荷)
D81: 貼合日 | P81: 課長立会有無 | AA81: コルゲータ反転有無 | AN81: エッジプレス | AX81: 協力会社指示 | BJ81: シート荷姿指示 | BU81: 協力会社指示
...

Sheet レイアウト_bk01
A1: =表紙!A54 -> Webシステム | K1: 文書名 | U1: モジュールID | Z1: =表紙!$AJ$63 -> MS | AE1: モジュール名 | AJ1: =表紙!$AX$63 -> 見積管理 | AS1: 文書番号 | AZ1: Version | BF1: Rev.
K2: =表紙!O64 -> アドオン設計書 | U2: ｻﾌﾞﾓｼﾞｭｰﾙID | Z2: =表紙!$AJ$64 -> MSBB | AE2: ｻﾌﾞﾓｼﾞｭｰﾙ名 | AJ2: =表紙!$AX$64 -> Webシステム | AS2: =表紙!$BL$64 -> M7-US-1140 | AZ2: =表紙!$BU$64 -> 7.0.2 | BF2: =表紙!$CB$64 -> 7
K3: =RIGHT(CELL("filename",$A$1),LEN(CELL("filename",$A$1))-FIND("]",CELL("filename",$A$1))) -> レイアウト_bk01 | U3: 表題 | Z3: =表紙!$AJ$65 -> MSBBPA070 | AE3: =表紙!$AQ$65 -> Web受注入力
A5: 画面イメージ
B7: ≫凡例
Q8: ・・・ | S8: ボタン
C9: 見積計算書№ | Q9: ・・・ | S9: 検索項目(検索画面表示選択)
C10: 品名 | Q10: ・・・ | S10: 入力項目
C11: 得意先 | Q11: ・・・ | S11: 表示項目(得意先名称、原紙名等)
C12: 操作種別 | I12: ●登録 | M12: ○訂正 | Q12: ・・・ | S12: 選択項目(一つのみ選択可能)
C13: 受注区分 | Q13: ・・・ | S13: 選択項目(一つのみ選択可能)
C14: 作業順 | I14: ☑AAA | M14: ☑BBB | Q14: ・・・ | S14: 選択項目(複数選択可能)
C21: 第1画面
D23: 操作種別 | J23: ●登録 | N23: ○訂正 | R23: ○削除 | V23: ○参照 | Z23: ○コピー
AO24: 手配NO | BK24: ← 「コピー」時、元手配№。 「訂正」「削除」「参照」の時、初期フォーカス
D27: 受注部門 | AD27: 受注日 | AO27: 受注区分
D28: 得意先 | AD28: 客納納期 | AO28: 数量
D30: 注文書No | W30: 先方担当 | AO30: 宛名 | BC30: 様
D31: 運送会社 | W31: 出荷時間
D33: 売価区分
D35: 受注明細
D36: 製品CD | J36: (件名:オートフィルタ) | AC36: ← ｾｯﾄ品目指定することで、以下の一覧に部材品目表示
D39: № | F39: 手配NO1 | I39: 手配NO2 | L39: 手配NO3 | O39: 製品CD/品目CD | T39: 製品名 | AB39: 単位 | AD39: 数量 | AG39: 特値 | AJ39: 個別単価 | AM39: ｾｯﾄ単価 | AP39: 金額 | AT39: 手配区分 | AW39: 納品先 | BA39: 納品先名 | BE39: 物流グループ | BH39: 預り売上 | BL39: 売上理由 | BP39: 受注№/受注明細№
E40: 1 | I40: 得意先CD | L40: 案件№ | T40: 味比べ3P箱 身 | AG40: □ | BI40: □
E41: 3 | I41: 得意先CD | L41: 案件№ | T41: 味比べ3P箱 蓋 | AG41: □ | BI41: □
E42: 4 | I42: 得意先CD | L42: 案件№ | T42: 味比べ3P箱 仕切り | AG42: □ | AT42: 仕入直送 | BI42: □
F44: ※メニュー「シート受注入力」を選択した場合は、第２画面からスタート
F45: ※メニュー「購買品受注入力」を選択した場合は、第２画面からスタート。 工程情報登録はなし。 入力項目の追加あり。
C53: 第２画面 | H53: ※部材の種類分、第２画面が連続して表示される
D54: 基本情報
F56: 受注区分 | Q56: 製品区分 | S56: 大 | Z56: 中 | AG56: 小
F57: 手配NO | O57: 得意先 | AI57: 客納納期 | AS57: 数量 | BC57: 単位
F58: 製品CD | O58: 顧客品名
O59: CP品名1 | AI59: CP品名2
F60: 顧客注文№ | O60: 顧客品番
F61: FSC認証 | O61: 食品安全
D64: 予備 | H64: 納入予備 | P64: 製造予備 | X64: 営業サンプル
D67: 定数出荷 | P67: 号機指定 | AC67: 不適合受注NO
D69: 売上可否
D71: 構成情報
...

Sheet レイアウト (プリフル入力)
A1: =表紙!A54 -> Webシステム | K1: 文書名 | U1: モジュールID | Z1: =表紙!$AJ$63 -> MS | AE1: モジュール名 | AJ1: =表紙!$AX$63 -> 見積管理 | AS1: 文書番号 | AZ1: Version | BF1: Rev.
K2: =表紙!O64 -> アドオン設計書 | U2: ｻﾌﾞﾓｼﾞｭｰﾙID | Z2: =表紙!$AJ$64 -> MSBB | AE2: ｻﾌﾞﾓｼﾞｭｰﾙ名 | AJ2: =表紙!$AX$64 -> Webシステム | AS2: =表紙!$BL$64 -> M7-US-1140 | AZ2: =表紙!$BU$64 -> 7.0.2 | BF2: =表紙!$CB$64 -> 7
K3: =RIGHT(CELL("filename",$A$1),LEN(CELL("filename",$A$1))-FIND("]",CELL("filename",$A$1))) -> レイアウト (プリフル入力) | U3: 表題 | Z3: =表紙!$AJ$65 -> MSBBPA070 | AE3: =表紙!$AQ$65 -> Web受注入力
A5: 画面イメージ
B7: ≫凡例
Q8: ・・・ | S8: ボタン
C9: 見積計算書№ | Q9: ・・・ | S9: 検索項目(検索画面表示選択)
C10: 品名 | Q10: ・・・ | S10: 入力項目
C11: 得意先 | Q11: ・・・ | S11: 表示項目(得意先名称、原紙名等)
C12: 操作種別 | I12: ●登録 | M12: ○訂正 | Q12: ・・・ | S12: 選択項目(一つのみ選択可能)
C13: 受注区分 | Q13: ・・・ | S13: 選択項目(一つのみ選択可能)
C14: 作業順 | I14: ☑AAA | M14: ☑BBB | Q14: ・・・ | S14: 選択項目(複数選択可能)
C21: 第1画面 | CL21: 在庫情報
D23: 操作種別 | J23: ●登録 | N23: ○訂正 | R23: ○削除 | V23: ○参照 | Z23: ○コピー
AO24: 手配NO | BK24: ← 「コピー」時、元手配№。 「訂正」「削除」「参照」の時、初期フォーカス | CM24: ワーキンググループ
CM26: 品目CD
D27: 受注部門 | J27: 9110 | O27: 九州営業 | AD27: 受注日 | AH27: 2022/7/15 | AO27: 受注区分 | AS27: 製品
D28: 得意先 | J28: 095439 | Q28: 福岡パッケージ | AD28: 客納納期 | AH28: 2022/7/31 | AO28: 数量 | AS28: 5000 | CM28: 手配NO
D30: 注文書No | J30: 328-133-01-1 | W30: 先方担当 | AO30: 宛名 | BC30: 様
D31: 運送会社 | W31: 出荷時間
CL32: ワーキンググループＣＤ | CM32: ワーキンググループ名 | CN32: 品目ＣＤ | CO32: 枝番１ | CP32: 枝番２ | CQ32: 枝番３ | CR32: 品名 | CS32: 在庫数量 | CT32: 入庫予定数量 | CU32: 引当数量 | CV32: 保留数量 | CW32: 引当可能数量 | CX32: 場所ＣＤ | CY32: 場所名 | CZ32: 棚・ラインＣＤ | DA32: 棚・ライン名 | DB32: 棚・ライン無 | DC32: 物流グループＣＤ | DD32: 物流グループ名 | DE32: 手配ＮＯ１ | DF32: 手配ＮＯ２ | DG32: 手配ＮＯ３
D33: 売価区分 | J33: 単品売り | CL33: 30 | CM33: 名古屋 | CN33: 00221088 | CO33: 01 | CS33: 500 | CT33: 300 | CU33: 300 | CV33: 0 | CW33: 500
CL34: 30 | CM34: 名古屋 | CN34: 00221088 | CO34: 01 | CS34: 200 | CT34: 0 | CU34: 0 | CV34: 0 | CW34: 200
D35: 受注明細
D36: 製品CD | J36: (件名:オートフィルタ) | AC36: ← ｾｯﾄ品目指定することで、以下の一覧に部材品目表示
D39: № | F39: 手配NO1 | I39: 手配NO2 | L39: 手配NO3 | O39: 製品CD/品目CD | T39: 製品名 | AB39: 単位 | AD39: 数量 | AG39: 特値 | AJ39: 個別単価 | AM39: ｾｯﾄ単価 | AP39: 金額 | AT39: 手配区分 | AW39: 客先納期 | BA39: 納品先 | BE39: 納品先名 | BI39: 物流グループ | BL39: 預り売上 | BP39: 売上理由 | BT39: 受注№/受注明細№
E40: 1 | I40: 095439 | L40: 00001 | O40: 0022108801 | T40: もつ鍋化粧箱（海千様） 身 | AB40: 個 | AD40: 5000 | AG40: □ | AJ40: 114 | AT40: 在庫引当 | AW40: 2022/7/31 | BA40: 094258 | BE40: アスパック | BM40: □
E41: 2 | AG41: □ | BM41: □
E42: 3 | AG42: □ | BM42: □
C51: 第２画面 | H51: ※部材の種類分、第２画面が連続して表示される
D52: 基本情報
F54: 受注区分 | H54: 製品 | Q54: 製品区分 | S54: 大 | T54: 31プリフル | Z54: 中 | AG54: 小
F55: 手配NO | H55: 000001:095439:00001 | O55: 得意先 | S55: 95439 | W55: 福岡パッケージ | AI55: 客納納期 | AM55: 2022/07/31 | AS55: 数量 | AV55: 5,000 | BC55: 単位 | BE55: 個
F56: 製品CD | H56: 0022108801 | O56: 顧客品名
O57: CP品名1 | S57: もつ鍋化粧箱（海千様） | AI57: CP品名2
F58: 顧客注文№ | H58: 328-133-01-1 | O58: 顧客品番
F59: FSC認証 | O59: 食品安全
D62: 予備 | H62: 納入予備 | P62: 製造予備 | T62: 80 | X62: 営業サンプル
D65: 定数出荷 | P65: 号機指定 | AC65: 不適合受注NO
D67: 売上可否
...

Sheet Popupレイアウト
A1: =表紙!A54 -> Webシステム | K1: 文書名 | U1: モジュールID | Z1: =表紙!$AJ$63 -> MS | AE1: モジュール名 | AJ1: =表紙!$AX$63 -> 見積管理 | AS1: 文書番号 | AZ1: Version | BF1: Rev.
K2: =表紙!O64 -> アドオン設計書 | U2: ｻﾌﾞﾓｼﾞｭｰﾙID | Z2: =表紙!$AJ$64 -> MSBB | AE2: ｻﾌﾞﾓｼﾞｭｰﾙ名 | AJ2: =表紙!$AX$64 -> Webシステム | AS2: =表紙!$BL$64 -> M7-US-1140 | AZ2: =表紙!$BU$64 -> 7.0.2 | BF2: =表紙!$CB$64 -> 7
K3: =RIGHT(CELL("filename",$A$1),LEN(CELL("filename",$A$1))-FIND("]",CELL("filename",$A$1))) -> Popupレイアウト | U3: 表題 | Z3: =表紙!$AJ$65 -> MSBBPA070 | AE3: =表紙!$AQ$65 -> Web受注入力
A5: 画面イメージ
C9: 加工品の場合
CF11: CP指摘 2022/09/30 落合 シート受注用の工程選択ポップアップ画面イメージが必要 | DH11: MDSOL回答 石田 2022/10/27 対応致しました。
D12: 製品CD | G12: 0022108801 | N12: 得意先 | Q12: 095439 | AA12: 顧客品名 | AG12: もつ鍋化粧箱（海千様） | CF12: 対象工程のみに絞り込みされること | DI12: 工程一覧でシートの工程のみ選択できるように記載しております。
D13: 工程 | G13: 0110:片面コルゲータ | DH13: CP指摘 2022/10/29 落合 指摘内容は、製品マスタと同じ、工程選択のポップアップが必要という内容です。 | ER13: MDSOL回答 2022/10/31 | FC13: 承知しました。
ER14: 2022/11/01 落合 未対応
D15: WG／号機／発注先 | L15: 10 | P15: 5362：●●工業 | Z15: 号機変更不可 | AI15: □ | AK15: CP配送区分 | ER15: MDSOL回答 2022/11/04
ES16: 本シートの46行目より、シートの場合を記述足しております。
D17: ﾁｪｯｸ | F17: 作業 | N17: 仕様 | AP17: 版型 | AV17: 消耗品 | ES17: レイアウト シートには以下記述を記載しております。
N18: 仕様1 | R18: 仕様2 | V18: 仕様3 | Z18: 仕様4 | AD18: 仕様5 | AH18: 仕様6 | AL18: 仕様7 | ET18: ３ページ目：工程情報画面
N19: 工程備考１ | AD19: 工程備考２ | ET19: シート受注時のみ編集可能 工程選択は汎用マスタ.工程マスタのシート受注使用フラグが設定されているもののみ表示
D20: ☑ | F20: 1 | H20: 貼合 | R20: 全判巾 | V20: 全判流れ | Z20: 巾変更 | ET20: 行挿入・行削除ボタンは、シート受注時のみ表示
Z21: 1:不可 | ER21: 2022/11/07 落合
N22: 工程備考AAA | AD22: 工程備考BBB | ES22: 工程追加方法のイメージが大きく違っていたようです。
D23: ☑ | F23: 2 | H23: コルスリ | N23: 表巾 | R23: ｽﾘｯﾀｰ1巾 | V23: ｽﾘｯﾀｰ1流れ | Z23: ｽﾘｯﾀｰ2巾 | AD23: ｽﾘｯﾀｰ2流れ | AH23: ｺﾙｽﾘ | AL23: 割り数 | ES23: 以下の手順で良かったでしょうか？
ES24: １．工程情報画面の「行挿入」で空白行が出来る
N25: 工程備考AAA | AD25: 工程備考123456 | ES25: ２．「詳細入力」ボタン押下により、ポップアップ表示される
ES26: ３．工程を選択する
D27: 製造 | AD27: 外注 | AL27: 本支店 | ES27: ４．仕様を入力して「工程へ反映」で追加される
D28: ﾛｽ率(%) | I28: 10 | M28: 台数(枚) | Q28: 10 | U28: LT(日) | Y28: 10 | AD28: 仕入単価 | AH28: 2000 | AL28: 指値 | AP28: 1000 | ES28: 工程を選択するときに、工程の一覧表示はないのでしょうか？
ER29: MDSOL回答 2022/11/08 工程追加の手順は下記を想定しています。
ES30: １．工程情報画面の「行挿入」で空白行が出来る
D31: 入庫先 | H31: 名古屋合紙置き場 | ES31: ２．工程情報画面で工程を選択する(コンボボックスより選択)
ES32: ３．「詳細入力」ボタン押下により、ポップアップ表示される ※対象工程
D33: № | F33: 連産品 | P33: 数量比率 | S33: 次工程 | ES33: ４．作業選択、仕様を入力して「工程へ反映」で追加される
E34: 1 | F34: 連産品① | P34: 4 | ES34: 工程の一覧表示から選択するオペレーションでなく、上記手順１・２をする手順を想定しています。
E35: 2 | F35: 連産品② | P35: 2 | ER35: 2022/11/09 落合 問題ありませんが、POPUP内で工程を選択した方がユーザーにとっては使いやすいように思います。
E36: 3 | EX36: 工程と工程仕様はセットなので、入力する画面が分かれるのは違和感があります。
E37: 4 | EX37: POPUP内の工程表示がコンボボックスになっており、選択した工程の作業に切り替わるでは難しいでしょうか？
E38: 5 | ES38: MDSOL回答 2022/11/10
E39: 6 | ET39: 工程変更分の情報を保持・反映する必要が有り、難易度・作業ボリュームが変わるため、今回はこの形で進めさせてください。
ET40: ※上記を修正する場合、製品マスタも同修正が必要になるかと思います。
ER42: 2022/11/10 落合 打ち合わせ内でお伝えした通り、1工程ごとにポップアップを確定するという方法であれば可能と思います。
EX43: 再度ご確認をお願い致します。
ER45: MDSOL回答 2022/11/11
C46: シートの場合 | ET46: 開発元に確認中のためお待ちください。
D47: 製品CD | G47: 0022108801 | N47: 得意先 | Q47: 095439 | AA47: 顧客品名 | AG47: もつ鍋化粧箱（海千様）
...

Sheet 現行画面
A1: =表紙!A54 -> Webシステム | K1: 文書名 | U1: モジュールID | Z1: =表紙!$AJ$63 -> MS | AE1: モジュール名 | AJ1: =表紙!$AX$63 -> 見積管理 | AS1: 文書番号 | AZ1: Version | BF1: Rev.
K2: =表紙!O64 -> アドオン設計書 | U2: ｻﾌﾞﾓｼﾞｭｰﾙID | Z2: =表紙!$AJ$64 -> MSBB | AE2: ｻﾌﾞﾓｼﾞｭｰﾙ名 | AJ2: =表紙!$AX$64 -> Webシステム | AS2: =表紙!$BL$64 -> M7-US-1140 | AZ2: =表紙!$BU$64 -> 7.0.2 | BF2: =表紙!$CB$64 -> 7
K3: =RIGHT(CELL("filename",$A$1),LEN(CELL("filename",$A$1))-FIND("]",CELL("filename",$A$1))) -> 現行画面 | U3: 表題 | Z3: =表紙!$AJ$65 -> MSBBPA070 | AE3: =表紙!$AQ$65 -> Web受注入力
A5: 画面イメージ

Sheet 項目説明
A1: =表紙!A54 -> Webシステム | K1: 文書名 | U1: モジュールID | Z1: =表紙!$AJ$63 -> MS | AE1: モジュール名 | AJ1: =表紙!$AX$63 -> 見積管理 | AS1: 文書番号 | AZ1: Version | BF1: Rev.
K2: =表紙!O64 -> アドオン設計書 | U2: ｻﾌﾞﾓｼﾞｭｰﾙID | Z2: =表紙!$AJ$64 -> MSBB | AE2: ｻﾌﾞﾓｼﾞｭｰﾙ名 | AJ2: =表紙!$AX$64 -> Webシステム | AS2: =表紙!$BL$64 -> M7-US-1140 | AZ2: =表紙!$BU$64 -> 7.0.2 | BF2: =表紙!$CB$64 -> 7
K3: =RIGHT(CELL("filename",$A$1),LEN(CELL("filename",$A$1))-FIND("]",CELL("filename",$A$1))) -> 項目説明 | U3: 表題 | Z3: =表紙!$AJ$65 -> MSBBPA070 | AE3: =表紙!$AQ$65 -> Web受注入力
A5: 第1画面（TOP画面）
B6: 操作種別 | N6: 説明 | BE6: Ｗ | BF6: 型 | BG6: 参 | BH6: 必 | BI6: 入 | BJ6: 非 | BK6: 検 | BN6: 操作種別 | BY6: 最大入力文字数 | CK6: DB文字数 | CS6: mcframe項目名 | DB6: mcframeDB文字数
A7: ● | B7: 登録 | M7: 新規登録するモード。初期状態 | BE7: R | BN7: 登録
A8: ● | B8: 訂正 | M8: 訂正するモード | BE8: R | BN8: 訂正
A9: ● | B9: 削除 | M9: 削除するモード | BE9: R | BN9: 削除
A10: ● | B10: 参照 | M10: 参照するモード | BE10: R | BN10: 参照
B11: 検索 | N11: 説明 | BE11: Ｗ | BF11: 型 | BG11: 参 | BH11: 必 | BI11: 入 | BJ11: 非 | BK11: 検 | BN11: 検索 | BY11: 最大入力文字数 | CK11: DB文字数 | CS11: mcframe項目名 | DB11: mcframeDB文字数
A12: 〇 | B12: 受注区分 | M12: 【MSBBPACOM】_共通設計書_アドオン(共通ロジック)にて定義 | BE12: C | BF12: S | BH12: 必 | BN12: 受注区分
A13: 〇 | B13: 得意先 | M13: 【MSBBPACOM】_共通設計書_アドオン(共通ロジック)にて定義 | BE13: C | BF13: S | BH13: 必 | BN13: 製品区分(大)
A14: 〇 | B14: 手配NO | M14: 「登録」時、元手配№。 「訂正」「削除」「参照」の時、初期フォーカス 【MSBBPACOM】_共通設計書_アドオン(共通ロジック)にて定義 | BE14: A | BF14: S | BK14: 検 | BN14: 手配NO
B15: 基本情報 | N15: 説明 | BE15: Ｗ | BF15: 型 | BG15: 参 | BH15: 必 | BI15: 入 | BJ15: 非 | BK15: 検 | BN15: 基本情報 | BY15: 最大入力文字数 | CK15: DB文字数 | CS15: mcframe項目名 | DB15: mcframeDB文字数
A16: ● | B16: 受注部門 | M16: 受注部門を設定する※【MSBBPACOM】_共通設計書_アドオン(共通ロジック)にて定義 | BE16: C | BF16: S | BH16: 必 | BK16: 検 | BN16: 受注部門
A17: ● | B17: 受注日 | M17: 受注日を設定する | BE17: カ | BF17: D | BH17: 必 | BN17: 受注日
A18: ● | B18: 受注区分 | M18: 加工製品、加工商品、シート製品、購買品、原紙 ※【MSBBPACOM】_共通設計書_アドオン(共通ロジック)にて定義 | BE18: C | BF18: S | BN18: 受注区分
A19: ● | B19: 得意先 | M19: 得意先CDを設定する※【MSBBPACOM】_共通設計書_アドオン(共通ロジック)にて定義 | BE19: A | BF19: S | BH19: 必 | BK19: 検 | BN19: 得意先
A20: ● | B20: 客先納期 | M20: 客先納期を設定する | BE20: カ | BF20: D | BH20: 必 | BN20: 客先納期
A21: ● | B21: 数量 | M21: 受注数量を設定する | BE21: T | BF21: N | BN21: 数量 | BY21: 10,2 | CK21: 21,8 | DB21: 21,8
A22: ● | B22: 注文書No | M22: 顧客の注文書番号 | BE22: T | BF22: S | BN22: 注文書No | BY22: 20文字 | CK22: 20文字 | CS22: 得意先注文明細ＮＯ | DB22: 20文字
A23: ● | B23: 先方担当 | M23: 顧客の担当者 | BE23: T | BF23: S | BN23: 先方担当
A24: ● | B24: 宛名 | M24: 宛名 | BE24: T | BF24: S | BN24: 宛名
A25: ● | B25: 運送会社 | M25: 運送会社を設定する※【MSBBPACOM】_共通設計書_アドオン(共通ロジック)にて定義 | BE25: C | BF25: S | BK25: 検 | BN25: 運送会社
A26: ● | B26: 出荷日時 | M26: 出荷日を設定する※M：日付時分（フォーマットが「YYYY/MM/DD 」のデータ） | BE26: カ | BF26: D | BN26: 出荷日
A27: ● | B27: 出荷条件 | M27: 昼積み、夜積み、時間指定を設定する※【MSBBPACOM】_共通設計書_アドオン(共通ロジック)にて定義 | BE27: C | BF27: S | BN27: 出荷条件
A28: ● | B28: 売価区分 | M28: 売価区分を設定する※【MSBBPACOM】_共通設計書_アドオン(共通ロジック)にて定義 | BE28: C | BF28: S | BN28: 売価区分
B29: 検索(受注明細) | N29: 説明 | BE29: Ｗ | BF29: 型 | BG29: 参 | BH29: 必 | BI29: 入 | BJ29: 非 | BK29: 検 | BN29: 検索(受注明細) | BY29: 最大入力文字数 | CK29: DB文字数 | CS29: mcframe項目名 | DB29: mcframeDB文字数
A30: ● | B30: 製品CD | M30: ｾｯﾄ品目指定することで、以下の一覧に部材品目表示※【MSBBPACOM】_共通設計書_アドオン(共通ロジック)にて定義 | BE30: A | BF30: S | BK30: 検 | BN30: 製品CD
B31: 受注明細 | N31: 説明 | BE31: Ｗ | BF31: 型 | BG31: 参 | BH31: 必 | BI31: 入 | BJ31: 非 | BK31: 検 | BN31: 受注明細 | BY31: 最大入力文字数 | CK31: DB文字数 | CS31: mcframe項目名 | DB31: mcframeDB文字数
B32: № | M32: 行番号 | BF32: N | BN32: №
B33: 手配NO | M33: 自動設定 連番※【MSBBPACOM】_共通設計書_アドオン(共通ロジック)にて定義 | BF33: S | BN33: 手配NO | BY33: 8文字 | CK33: 15文字 | CS33: 手配NO1 | DB33: 15文字
A34: ● | B34: 製品CD/品目CD | M34: 製品CD OR 経費品目を設定する。購買受注の際に必須※【MSBBPACOM】_共通設計書_アドオン(共通ロジック)にて定義 | BE34: A | BF34: S | BN34: 製品CD/品目CD | BY34: 15文字 | CK34: 15文字 | DY34: Rev6.0 製品CD桁数見直し(15桁に変更)
B35: CP品名1 | M35: CP品名1を設定する。 | BF35: S | BN35: CP品名1
B36: CP品名2 | M36: CP品名2を設定する。 | BF36: S | BN36: CP品名2
A37: ● | B37: 数量 | M37: 数量を設定する | BE37: T | BF37: N | BN37: 数量 | BY37: 10,2 | CK37: 21,8 | CS37: 受注明細.取引単位数量 | DB37: 21,8
A38: ● | B38: 単位 | M38: 数量単位を設定する | BE38: C | BF38: S | BN38: 単位
B39: 特値 | M39: 単価が特値かどうか設定する | BE39: チ | BF39: F | BN39: 特値
A40: ● | B40: 個別単価 | M40: 個別の単価 | BE40: T | BF40: N | BN40: 個別単価 | BY40: 10,2 | CK40: 21,8 | CS40: 受注明細.単価 | DB40: 21,8
A41: ● | B41: ｾｯﾄ単価 | M41: セット売りでの単価。売価区分＝セットでかつ親部材の時のみ入力可とする。 子の場合はゼロ。 | BE41: T | BF41: N | BN41: ｾｯﾄ単価 | BY41: 10,2 | CK41: 21,8 | CS41: 受注明細.単価 | DB41: 21,8
...

Sheet 引数説明
A1: =表紙!A54 -> Webシステム | K1: 文書名 | U1: モジュールID | Z1: =表紙!$AJ$63 -> MS | AE1: モジュール名 | AJ1: =表紙!$AX$63 -> 見積管理 | AS1: 文書番号 | AZ1: Version | BF1: Rev.
K2: =表紙!O64 -> アドオン設計書 | U2: ｻﾌﾞﾓｼﾞｭｰﾙID | Z2: =表紙!$AJ$64 -> MSBB | AE2: ｻﾌﾞﾓｼﾞｭｰﾙ名 | AJ2: =表紙!$AX$64 -> Webシステム | AS2: =表紙!$BL$64 -> M7-US-1140 | AZ2: =表紙!$BU$64 -> 7.0.2 | BF2: =表紙!$CB$64 -> 7
K3: =RIGHT(CELL("filename",$A$1),LEN(CELL("filename",$A$1))-FIND("]",CELL("filename",$A$1))) -> 引数説明 | U3: 表題 | Z3: =表紙!$AJ$65 -> MSBBPA070 | AE3: =表紙!$AQ$65 -> Web受注入力
B5: オペレーションＩＤ/名称：SloRecvIfImp_Upd01/取込
A6: 必 | B6: 項目名 | N6: 説明 | AS6: 未設定時の振る舞い
B7: 得意先ＣＤ | M7: 受注受信ＩＦの検索条件

Sheet 画面遷移
A1: =表紙!A54 -> Webシステム | K1: 文書名 | U1: モジュールID | Z1: =表紙!$AJ$63 -> MS | AE1: モジュール名 | AJ1: =表紙!$AX$63 -> 見積管理 | AS1: 文書番号 | AZ1: Version | BF1: Rev.
K2: =表紙!O64 -> アドオン設計書 | U2: ｻﾌﾞﾓｼﾞｭｰﾙID | Z2: =表紙!$AJ$64 -> MSBB | AE2: ｻﾌﾞﾓｼﾞｭｰﾙ名 | AJ2: =表紙!$AX$64 -> Webシステム | AS2: =表紙!$BL$64 -> M7-US-1140 | AZ2: =表紙!$BU$64 -> 7.0.2 | BF2: =表紙!$CB$64 -> 7
K3: =RIGHT(CELL("filename",$A$1),LEN(CELL("filename",$A$1))-FIND("]",CELL("filename",$A$1))) -> 画面遷移 | U3: 表題 | Z3: =表紙!$AJ$65 -> MSBBPA070 | AE3: =表紙!$AQ$65 -> Web受注入力
A5: ID | D5: 処理名 | Y5: ダブルクリック対象 | AH5: ダブルクリック処理条件
A6: S01 | D6: Web受注一覧照会から本画面遷移
B8: 遷移処理
B9: 遷移元画面ＩＤ | I9: MSBBPA080
B10: 遷移元画面名 | I10: Web受注一覧照会
B11: 遷移先画面ＩＤ | I11: MSBBPA070
B12: 遷移先画面名 | I12: Web受注入力
B13: 遷移条件 | I13: Web受注一覧照会画面の一覧表示部データから一つのみ選択の後、選択ボタンをクリックします
B14: 引継項目・種別 | I14: 遷移元画面項目 | AJ14: 遷移先画面項目
I15: WEB受注NO | AJ15: WEB受注NO
I16: WEB受注明細NO | AJ16: WEB受注明細NO
B18: 遷移後のアクション | I18: 操作種別が「参照」をします
B19: 備考
A21: ID | D21: 処理名
A22: S02 | D22: メニューから本画面遷移
B24: 遷移処理
B25: 遷移元画面ＩＤ | I25: なし
B26: 遷移元画面名 | I26: メニュー
B27: 遷移先画面ＩＤ | I27: MSBBPA070
B28: 遷移先画面名 | I28: Web受注入力
B29: 遷移条件 | I29: なし
B30: 引継項目・種別 | I30: 遷移元画面項目 | AJ30: 遷移先画面項目
I31: メンニュー一覧のkey | AJ31: なし
B34: 遷移後のアクション | I34: 画面を初期化して、操作種別が「登録」をします
B35: 備考

Sheet 処理概要
A1: =表紙!A54 -> Webシステム | K1: 文書名 | U1: モジュールID | Z1: =表紙!$AJ$63 -> MS | AE1: モジュール名 | AJ1: =表紙!$AX$63 -> 見積管理 | AS1: 文書番号 | AZ1: Version | BF1: Rev.
K2: =表紙!O64 -> アドオン設計書 | U2: ｻﾌﾞﾓｼﾞｭｰﾙID | Z2: =表紙!$AJ$64 -> MSBB | AE2: ｻﾌﾞﾓｼﾞｭｰﾙ名 | AJ2: =表紙!$AX$64 -> Webシステム | AS2: =表紙!$BL$64 -> M7-US-1140 | AZ2: =表紙!$BU$64 -> 7.0.2 | BF2: =表紙!$CB$64 -> 7
K3: =RIGHT(CELL("filename",$A$1),LEN(CELL("filename",$A$1))-FIND("]",CELL("filename",$A$1))) -> 処理概要 | U3: 表題 | Z3: =表紙!$AJ$65 -> MSBBPA070 | AE3: =表紙!$AQ$65 -> Web受注入力
A5: No | B5: 入力 | J5: 処理 | BD5: 出力
A6: ０ | B6: 構成・工程編集可の判定処理
J7: １．構成・工程編集可の判定処理は以下の形で判定する。 | BM7: REV7.0 受注画面制御の追加
N8: 補足受注画面制御で構成・工程が編集可となっている受注区分、製品区分、品目採番の組合せの場合 | BM8: REV7.0 受注画面制御の追加
O9: 構成・工程編集可 | BM9: REV7.0 受注画面制御の追加
N10: それ以外の場合 | BM10: REV7.0 受注画面制御の追加
O11: 構成・工程編集不可 | BM11: REV7.0 受注画面制御の追加
K12: 以後、設計書内では構成・工程編集可の場合、構成・工程編集可以外の場合と記する。 | BM12: REV7.0 受注画面制御の追加
BM13: REV7.0 受注画面制御の追加
A14: 1 | B14: 検索（手配NO）
J15: １．検索処理
K16: 検索入出力仕様に従い検索を行う | BD16: 検索入出力仕様２
N17: 検索条件
N18: 項目名 | W18: 設定値
N19: 手配NO１ | W19: 画面.手配NO１
N20: 手配NO２ | W20: 画面.手配NO２
N21: 手配NO３ | W21: 画面.手配NO３
K23: 登録モードで検索した場合、参照モード→登録モードに切り替えた場合に以下項目をクリアする。 | BM23: REV3.0 過去受注をコピーした時に、セットしたくない項目がある
K24: 受注日・客納期・出荷時間・個別単価・セット単価・得値区分・金額・預り売上・預り理由・顧客注文№・不適合受注№・再製造備考 | BM24: REV3.0 過去受注をコピーした時に、セットしたくない項目がある
A26: ２ | B26: 検索（製品CD）
J28: １．検索処理
K29: 検索入出力仕様に従い検索を行う
BD30: 検索入出力仕様1
N31: 検索条件
N32: 項目名 | W32: 設定値
N33: 製品CD | W33: 画面.製品CD
L34: OR | N34: セット品CD | W34: 画面.製品CD
A36: ３ | B36: 受注区分変更処理
J38: １．受注区分変更処理
K39: 受注区分が変更された場合以下処理を行う。
K40: 1-1)受注区分が加工製品、加工商品、原紙の場合 | BM40: REV4.0 行コピーの有効条件追加
L41: 受注明細欄を表示する | BM41: REV4.0 行コピーの有効条件追加
L42: 行コピーを無効にする。 | BM42: REV4.0 行コピーの有効条件追加
L43: 1-1-1)受注区分：原紙の場合 | BM43: REV4.0 行コピーの有効条件追加
M44: 行コピーを有効にする。 | BM44: REV4.0 行コピーの有効条件追加
K45: 1-2)受注区分がそれ以外
L46: 受注明細欄を非表示にする
...

Sheet 処理詳細
A1: =表紙!A54 -> Webシステム | K1: 文書名 | U1: モジュールID | Z1: =表紙!$AJ$63 -> MS | AE1: モジュール名 | AJ1: =表紙!$AX$63 -> 見積管理 | AS1: 文書番号 | AZ1: Version | BF1: Rev.
K2: =表紙!O64 -> アドオン設計書 | U2: ｻﾌﾞﾓｼﾞｭｰﾙID | Z2: =表紙!$AJ$64 -> MSBB | AE2: ｻﾌﾞﾓｼﾞｭｰﾙ名 | AJ2: =表紙!$AX$64 -> Webシステム | AS2: =表紙!$BL$64 -> M7-US-1140 | AZ2: =表紙!$BU$64 -> 7.0.2 | BF2: =表紙!$CB$64 -> 7
K3: =RIGHT(CELL("filename",$A$1),LEN(CELL("filename",$A$1))-FIND("]",CELL("filename",$A$1))) -> 処理詳細 | U3: 表題 | Z3: =表紙!$AJ$65 -> MSBBPA070 | AE3: =表紙!$AQ$65 -> Web受注入力
A5: No | B5: 入力 | J5: 処理 | BD5: 出力
A6: 0 | B6: 構成・工程編集可の判定処理
J7: 0．構成・工程編集可の判定処理は以下の形で判定する。
N8: 補足受注画面制御で構成・工程が編集可となっている受注区分、製品区分、品目採番の組合せの場合
O9: 構成・工程編集可
N10: それ以外の場合
O11: 構成・工程編集不可
K12: 以後、設計書内では構成・工程編集可の場合、構成・工程編集可以外の場合と記する。
K14: ※ | L14: ファンクション作成、画面項目入力し、調用する。
A16: １ | B16: 初期表示 | J16: TOP画面
J17: 1.1 | L17: 遷移元メニューから
L18: 操作種別 | P18: ： | Q18: 「登録」を設定する
L19: その他 | P19: ： | Q19: 活性とする、各項目のクリア処理と初期値設定を行う
J21: 1.2 | L21: 遷移元【MSBBPA080】_Web受注一覧照会から
L22: 操作種別 | P22: ： | Q22: 「参照」を設定する
L23: 操作種別以外、全画面が非活性とする
A25: 2 | B25: 画面操作 | J25: TOP画面
J26: 2.1 | L26: 操作種別ボタンの制御処理
K27: 2.1.1 | N27: [操作種別]ラジオが「登録」の場合、
N28: 受注区分、得意先、手配NOは編集不可、 受注伝票ボタンが非活性を設定する。その以外、編集可、ボタンが活性を設定する。
N30: 参照モード→登録モードに切り替えた場合に以下項目をクリアする。
N31: 受注日・客納期・出荷時間・個別単価・セット単価・得値区分・金額・預り売上・預り理由・顧客注文№・不適合受注№・再製造備考
K33: 2.1.2 | N33: [操作種別]が「訂正」の場合、
N34: 受注伝票発行ボタンが非活性を設定する。その以外、編集可、ボタンが活性を設定する。
K36: 2.1.3 | N36: [操作種別]が「削除」の場合、
N37: 受注区分、得意先、手配NOは編集可、次画面ボタン、登録ボタンが活性を設定する。その以外、編集不可、ボタンが非活性を設定する。
K39: 2.1.4 | N39: [操作種別]が「参照」の場合、
N40: 受注区分、得意先、手配NOは編集可、次画面ボタン、受注伝票ボタンが活性を設定する。その以外、編集不可、ボタンが非活性を設定する。
N42: ※操作種別切り替え処理は、以下の通りです。
N53: ※ | O53: 手配NOが「訂正」「削除」「参照」の時、初期フォーカスを設定する。
J55: 2.2 | L55: 受注区分変更処理
L56: 受注区分が変更された場合以下処理を行う。
L58: 2.2.1 | N58: 受注区分が加工製品、加工商品、原紙の場合
N59: 基本情報.受注明細欄を表示する
N60: 行コピーを無効にする。
N61: 1-1-1)受注区分：原紙の場合
O62: 行コピーを有効にする。
...

Sheet 画面項目制御
B2: 第1画面（TOP画面）
J3: 操作種別 | O3: 登録 | R3: 訂正 | U3: 削除 | X3: 参照 | AA3: 登録後 | AD3: 削除後 | AH3: R | AJ3: 有効(必須)
B4: 画面項目 | AA4: 訂正後 | AH4: E | AJ4: 有効
B5: 検索 | G5: 受注区分 | O5: R | R5: R | U5: R | X5: R | AA5: R | AD5: R | AH5: RO | AJ5: 読取のみ
G6: 得意先 | O6: R | R6: R | U6: R | X6: R | AA6: R | AD6: R | AH6: D | AJ6: 無効
G7: 手配NO | O7: E | R7: E | U7: E | X7: E | AA7: E | AD7: E | AH7: I | AJ7: 非表示
B8: 基本情報 | G8: 受注部門 | O8: R | R8: R | U8: RO | X8: RO | AA8: RO | AD8: RO
G9: 受注日 | O9: R | R9: R | U9: RO | X9: RO | AA9: RO | AD9: RO
G10: 受注区分 | O10: E | R10: E | U10: RO | X10: RO | AA10: RO | AD10: RO
G11: 得意先 | O11: R | R11: R | U11: RO | X11: RO | AA11: RO | AD11: RO
G12: 客先納期 | O12: R | R12: R | U12: RO | X12: RO | AA12: RO | AD12: RO
G13: 数量 | O13: E | R13: E | U13: RO | X13: RO | AA13: RO | AD13: RO
G14: 注文書No | O14: E | R14: E | U14: RO | X14: RO | AA14: RO | AD14: RO
G15: 先方担当 | O15: E | R15: E | U15: RO | X15: RO | AA15: RO | AD15: RO
G16: 宛名 | O16: E | R16: E | U16: RO | X16: RO | AA16: RO | AD16: RO
G17: 運送会社 | O17: E | R17: E | U17: RO | X17: RO | AA17: RO | AD17: RO
G18: 出荷日時 | O18: E | R18: E | U18: RO | X18: RO | AA18: RO | AD18: RO
G19: 出荷条件 | O19: E | R19: E | U19: RO | X19: RO | AA19: RO | AD19: RO
G20: 売価区分 | O20: E | R20: E | U20: RO | X20: RO | AA20: RO | AD20: RO
B21: 検索(受注明細) | G21: 製品CD | O21: E | R21: E | U21: D | X21: D | AA21: D | AD21: D
B22: 受注明細 | G22: № | O22: RO | R22: RO | U22: RO | X22: RO | AA22: RO | AD22: RO
G23: 手配NO | O23: RO | R23: RO | U23: RO | X23: RO | AA23: RO | AD23: RO
G24: 案件NO | O24: RO | R24: RO | U24: RO | X24: RO | AA24: RO | AD24: RO
G25: 製品CD/品目CD | O25: E/R | R25: E/R | U25: RO | X25: RO | AA25: RO | AD25: RO
G26: CP品名1 | O26: RO | R26: RO | U26: RO | X26: RO | AA26: RO | AD26: RO
G27: CP品名2 | O27: RO | R27: RO | U27: RO | X27: RO | AA27: RO | AD27: RO
G28: 数量 | O28: E | R28: E | U28: RO | X28: RO | AA28: RO | AD28: RO
G29: 単位 | O29: E | R29: E | U29: RO | X29: RO | AA29: RO | AD29: RO
G30: 特値 | O30: RO | R30: RO | U30: RO | X30: RO | AA30: RO | AD30: RO
G31: 個別単価 | O31: E | R31: E | U31: RO | X31: RO | AA31: RO | AD31: RO
G32: ｾｯﾄ単価 | O32: E | R32: E | U32: RO | X32: RO | AA32: RO | AD32: RO
G33: 単価単位 | O33: E | R33: E | U33: RO | X33: RO | AA33: RO | AD33: RO
G34: 客先納期 | O34: E | R34: E | U34: RO | X34: RO | AA34: RO | AD34: RO
... G41: 受注№/受注明細№ | O41: RO | R41: RO | U41: RO | X41: RO | AA41: RO | AD41: RO
B42: フッター | G42: クリア | O42: E | R42: E | U42: RO | X42: RO | AA42: RO | AD42: RO
G43: 行コピー | O43: E | R43: E | U43: RO | X43: RO | AA43: RO | AD43: RO
G44: 行追加 | O44: E | R44: E | U44: RO | X44: RO | AA44: RO | AD44: RO
G45: 行削除 | O45: E | R45: RO | U45: RO | X45: RO | AA45: RO | AD45: RO
G46: ▲ | O46: E | R46: E | U46: RO | X46: RO | AA46: RO | AD46: RO
G47: ▼ | O47: E | R47: E | U47: RO | X47: RO | AA47: RO | AD47: RO
...

Sheet 処理・サービス関連図
A1: =表紙!A54 -> Webシステム | K1: 文書名 | U1: モジュールID | Z1: =表紙!$AJ$63 -> MS | AE1: モジュール名 | AJ1: =表紙!$AX$63 -> 見積管理 | AS1: 文書番号 | AZ1: Version | BF1: Rev.
K2: =表紙!O64 -> アドオン設計書 | U2: ｻﾌﾞﾓｼﾞｭｰﾙID | Z2: =表紙!$AJ$64 -> MSBB | AE2: ｻﾌﾞﾓｼﾞｭｰﾙ名 | AJ2: =表紙!$AX$64 -> Webシステム | AS2: =表紙!$BL$64 -> M7-US-1140 | AZ2: =表紙!$BU$64 -> 7.0.2 | BF2: =表紙!$CB$64 -> 7
K3: =RIGHT(CELL("filename",$A$1),LEN(CELL("filename",$A$1))-FIND("]",CELL("filename",$A$1))) -> 処理・サービス関連図 | U3: 表題 | Z3: =表紙!$AJ$65 -> MSBBPA070 | AE3: =表紙!$AQ$65 -> Web受注入力
C7: 検索処理
BM9: REV5.0 製品基本マスタ重複削除
C26: 更新処理
C36: ファイル出力処理
C46: シート受注、原紙工程ありの場合
C51: ファイル出力処理
BM58: REV5.0 品目単位マスタ追加

Sheet 検索入出力仕様
A1: =表紙!A54 -> Webシステム | K1: 文書名 | U1: モジュールID | Z1: =表紙!$AJ$63 -> MS | AE1: モジュール名 | AJ1: =表紙!$AX$63 -> 見積管理 | AS1: 文書番号 | AZ1: Version | BF1: Rev.
K2: =表紙!O64 -> アドオン設計書 | U2: ｻﾌﾞﾓｼﾞｭｰﾙID | Z2: =表紙!$AJ$64 -> MSBB | AE2: ｻﾌﾞﾓｼﾞｭｰﾙ名 | AJ2: =表紙!$AX$64 -> Webシステム | AS2: =表紙!$BL$64 -> M7-US-1140 | AZ2: =表紙!$BU$64 -> 7.0.2 | BF2: =表紙!$CB$64 -> 7
K3: =RIGHT(CELL("filename",$A$1),LEN(CELL("filename",$A$1))-FIND("]",CELL("filename",$A$1))) -> 検索入出力仕様 | U3: 表題 | Z3: =表紙!$AJ$65 -> MSBBPA070 | AE3: =表紙!$AQ$65 -> Web受注入力
A5: No | G5: 1 | S5: ボタン | Z5: 製品CD | AH5: 備考 | AK5: セット製品CD選択時の部材一覧へのセット処理
A6: 処理分類 | E6: 検索 | S6: ソート順
A7: No | C7: 転送先 | V7: 転送元 | AQ7: 説明
C8: 種 | D8: オブジェクト | K8: 項目名 | V8: 種 | W8: オブジェクト | AF8: 項目名
C9: 画 | D9: 第1画面 | G9: 部材一覧 | K9: 製品CD | V9: T | W9: 製品基本マスタ | AF9: 製品コード | BM9: REV5.0 製品マスタ → 製品基本マスタ
C10: 画 | D10: 第1画面 | G10: 部材一覧 | K10: 製品名 | V10: T | W10: 製品基本マスタ | AF10: 顧客品名 | BM10: REV5.0 製品マスタ → 製品基本マスタ
C11: 画 | D11: 第1画面 | G11: 部材一覧 | K11: 単位 | V11: T | W11: 製品基本マスタ | AF11: 数量単位 | BM11: REV5.0 製品マスタ → 製品基本マスタ
C12: 画 | D12: 第1画面 | G12: 部材一覧 | K12: 個別単価 | V12: T | W12: 製品基本マスタ | AF12: 現_セット単価 | BM12: REV5.0 製品マスタ → 製品基本マスタ
C13: 画 | D13: 第1画面 | G13: 部材一覧 | K13: ｾｯﾄ単価 | V13: T | W13: 製品基本マスタ | AF13: 現_個別単価 | BM13: REV5.0 製品マスタ → 製品基本マスタ
A15: No | G15: 2 | S15: ボタン | Z15: 手配NO | AH15: 備考 | AK15: 登録、訂正・削除・参照時の画面セット処理
A16: 処理分類 | E16: 検索 | S16: ソート順
A17: No | C17: 転送先 | V17: 転送元 | AQ17: 説明
C18: 種 | D18: オブジェクト | K18: 項目名 | V18: 種 | W18: オブジェクト | AF18: 項目名
C19: 画 | D19: 第1画面 | G19: 基本情報 | K19: 受注部門 | V19: T | W19: 受注 | AF19: 受注部門
C20: 画 | D20: 第1画面 | G20: 基本情報 | K20: 受注日 | V20: T | W20: 受注 | AF20: 受注日
C21: 画 | D21: 第1画面 | G21: 基本情報 | K21: 受注区分 | V21: T | W21: 受注 | AF21: 受注区分
C22: 画 | D22: 第1画面 | G22: 基本情報 | K22: 得意先 | V22: T | W22: 受注 | AF22: 得意先
C23: 画 | D23: 第1画面 | G23: 基本情報 | K23: 客納納期 | V23: T | W23: 受注 | AF23: 客納納期
C24: 画 | D24: 第1画面 | G24: 基本情報 | K24: 数量 | V24: T | W24: 受注 | AF24: 数量
C25: 画 | D25: 第1画面 | G25: 基本情報 | K25: 注文書No | V25: T | W25: 受注 | AF25: 注文書No
C26: 画 | D26: 第1画面 | G26: 基本情報 | K26: 先方担当 | V26: T | W26: 受注 | AF26: 先方担当
C27: 画 | D27: 第1画面 | G27: 基本情報 | K27: 宛名 | V27: T | W27: 受注 | AF27: 宛名
C28: 画 | D28: 第1画面 | G28: 基本情報 | K28: 運送会社 | V28: T | W28: 受注 | AF28: 運送会社
C29: 画 | D29: 第1画面 | G29: 基本情報 | K29: 出荷時間 | V29: T | W29: 受注 | AF29: 出荷時間
C30: 画 | D30: 第1画面 | G30: 基本情報 | K30: 出荷条件 | V30: T | W30: 受注 | AF30: 出荷条件
... C50: 画 | D50: 第1画面 | G50: 部材一覧 | K50: 受注№/受注明細№ | V50: T | W50: 受注明細 | AF50: 受注№ || 受注明細№
A53: No | G53: 3 | S53: ボタン | AH53: 備考
A54: 処理分類 | E54: 検索(製品基本マスタ) | S54: ソート順
A55: No | C55: 転送先 | V55: 転送元 | AQ55: 説明
C56: 種 | D56: オブジェクト | K56: 項目名 | V56: 種 | W56: オブジェクト | AF56: 項目名
A57: 1 | C57: 画 | D57: ２ページ目：基本情報画面 | K57: 納品先 | V57: 画 | W57: 第1画面 部材一覧
A58: 2 | C58: 画 | D58: ２ページ目：基本情報画面 | K58: 手配区分 | V58: 画 | W58: 第1画面 部材一覧 | AF58: 手配区分
A59: 3 | C59: 画 | D59: ２ページ目：基本情報画面 | K59: 預り売上 | V59: 画 | W59: 第1画面 部材一覧 | AF59: 預り売上
A60: 4 | C60: 画 | D60: ２ページ目：基本情報画面 | K60: 受注区分 | V60: 画 | W60: 第1画面 部材一覧 | AF60: 受注区分
A61: 5 | C61: 画 | D61: ２ページ目：基本情報画面 | K61: 製品区分_大 | V61: 画 | W61: 第1画面 部材一覧 | AF61: 製品区分_大
A62: 6 | C62: 画 | D62: ２ページ目：基本情報画面 | K62: 製品区分_中 | V62: 画 | W62: 第1画面 部材一覧 | AF62: 製品区分_中
A63: 7 | C63: 画 | D63: ２ページ目：基本情報画面 | K63: 製品区分_小 | V63: 画 | W63: 第1画面 部材一覧 | AF63: 製品区分_小
...

Sheet 更新入出力仕様
A1: =表紙!A54 -> Webシステム | K1: 文書名 | U1: モジュールID | Z1: =表紙!$AJ$63 -> MS | AE1: モジュール名 | AJ1: =表紙!$AX$63 -> 見積管理 | AS1: 文書番号 | AZ1: Version | BF1: Rev.
K2: =表紙!O64 -> アドオン設計書 | U2: ｻﾌﾞﾓｼﾞｭｰﾙID | Z2: =表紙!$AJ$64 -> MSBB | AE2: ｻﾌﾞﾓｼﾞｭｰﾙ名 | AJ2: =表紙!$AX$64 -> Webシステム | AS2: =表紙!$BL$64 -> M7-US-1140 | AZ2: =表紙!$BU$64 -> 7.0.2 | BF2: =表紙!$CB$64 -> 7
K3: =RIGHT(CELL("filename",$A$1),LEN(CELL("filename",$A$1))-FIND("]",CELL("filename",$A$1))) -> 更新入出力仕様 | U3: 表題 | Z3: =表紙!$AJ$65 -> MSBBPA070 | AE3: =表紙!$AQ$65 -> Web受注入力
A5: No | G5: 1 | S5: ロジック名称 | Z5: 受注更新処理 | AH5: 備考
A6: 処理分類 | E6: 追加
A7: No | C7: 転送先 | V7: 転送元 | AQ7: 説明
C8: 種 | D8: オブジェクト | K8: 項目名 | V8: 種 | W8: オブジェクト | AF8: 項目名
A9: 1 | C9: T | D9: 受注 | K9: Web受注NO | V9: 画 | AQ9: シーケンスにより自動採番
A10: 2 | C10: T | D10: 受注 | K10: 得意先コード | V10: 画 | W10: 第1画面 | AA10: 基本情報 | AF10: 得意先コード
A11: 3 | C11: T | D11: 受注 | K11: 受注区分 | V11: 画 | W11: 第1画面 | AA11: 基本情報 | AF11: 受注区分
A12: 4 | C12: T | D12: 受注 | K12: 受注部門 | V12: 画 | W12: 第1画面 | AA12: 基本情報 | AF12: 受注部門
A13: 5 | C13: T | D13: 受注 | K13: 受注日 | V13: 画 | W13: 第1画面 | AA13: 基本情報 | AF13: 受注日
A14: 6 | C14: T | D14: 受注 | K14: 客納納期 | V14: 画 | W14: 第1画面 | AA14: 基本情報 | AF14: 客納納期
A15: 7 | C15: T | D15: 受注 | K15: 数量 | V15: 画 | W15: 第1画面 | AA15: 基本情報 | AF15: 数量
A16: 8 | C16: T | D16: 受注 | K16: 注文書NO | V16: 画 | W16: 第1画面 | AA16: 基本情報 | AF16: 注文書NO
A17: 9 | C17: T | D17: 受注 | K17: 先方担当 | V17: 画 | W17: 第1画面 | AA17: 基本情報 | AF17: 先方担当
A18: 10 | C18: T | D18: 受注 | K18: 宛名 | V18: 画 | W18: 第1画面 | AA18: 基本情報 | AF18: 宛名
A19: 11 | C19: T | D19: 受注 | K19: 運送会社 | V19: 画 | W19: 第1画面 | AA19: 基本情報 | AF19: 運送会社
A20: 12 | C20: T | D20: 受注 | K20: 出荷日時 | V20: 画 | W20: 第1画面 | AA20: 基本情報 | AF20: 出荷日時
A21: 13 | C21: T | D21: 受注 | K21: 売価区分 | V21: 画 | W21: 第1画面 | AA21: 基本情報 | AF21: 売価区分
A22: 14 | C22: T | D22: 受注 | K22: 受注ＮＯ | V22: 画 | AQ22: 承認済 | AU22: 新規：* 更新：変更しない
A23: 15 | C23: T | D23: 受注 | K23: ステータス | V23: 画 | AQ23: 承認固定 | AU23: 新規：0 更新：変更しない
A24: 16 | C24: T | D24: 受注 | K24: mcframe7転送FLG | V24: 画 | AQ24: FALSE固定
A25: 17
A26: 18
A27: No | G27: 2 | H27: 受注明細追加更新 | S27: ロジック名称 | AH27: 備考
A28: 処理分類 | E28: 追加・更新
A29: No | C29: 転送先 | V29: 転送元 | AQ29: 説明
C30: 種 | D30: オブジェクト | K30: 項目名 | V30: 種 | W30: オブジェクト | AF30: 項目名
A31: 1 | C31: T | D31: 受注明細 | K31: Web受注NO | V31: T | W31: 受注 | AF31: Web受注NO
A32: 2 | C32: T | D32: 受注明細 | K32: Web受注明細NO | AF32: 明細行 | AQ32: WEB受注NO＋明細行
A33: 3 | C33: T | D33: 受注明細 | K33: 手配ＮＯ１ | AQ33: シーケンスにより自動採番
A34: 4 | C34: T | D34: 受注明細 | K34: 手配ＮＯ２ | W34: 1ページ目：得意先コード | AF34: 得意先コード
A35: 5 | C35: T | D35: 受注明細 | K35: 手配ＮＯ３ | W35: 製品基本マスタ | AF35: 案件NO(親) | BN35: Rev2.0 変更
A36: 6 | C36: T | D36: 受注明細 | K36: 手配ＮＯ４ | AQ36: NULL
A37: 7 | C37: T | D37: 受注明細 | K37: 製品コード | V37: 画 | W37: 2ページ目：基本情報画面 | AF37: 製品コード
A38: 8 | C38: T | D38: 受注明細 | K38: 品目コード | V38: 画 | W38: 2ページ目：基本情報画面 | AF38: 品目コード
A39: 9 | C39: T | D39: 受注明細 | K39: 枝番１ | V39: 画 | W39: 2ページ目：基本情報画面 | AF39: 枝番１
A40: 10 | C40: T | D40: 受注明細 | K40: 枝番２ | V40: 画 | W40: 2ページ目：基本情報画面 | AF40: 枝番２
A41: 11 | C41: T | D41: 受注明細 | K41: 枝番３ | V41: 画 | W41: 2ページ目：基本情報画面 | AF41: 枝番３
...

Sheet テーブル項目_受注
A1: =表紙!A54 -> Webシステム | K1: 文書名 | U1: モジュールID | Z1: =表紙!$AJ$63 -> MS | AE1: モジュール名 | AJ1: =表紙!$AX$63 -> 見積管理 | AS1: 文書番号 | AZ1: Version | BF1: Rev.
K2: =表紙!O64 -> アドオン設計書 | U2: ｻﾌﾞﾓｼﾞｭｰﾙID | Z2: =表紙!$AJ$64 -> MSBB | AE2: ｻﾌﾞﾓｼﾞｭｰﾙ名 | AJ2: =表紙!$AX$64 -> Webシステム | AS2: =表紙!$BL$64 -> M7-US-1140 | AZ2: =表紙!$BU$64 -> 7.0.2 | BF2: =表紙!$CB$64 -> 7
K3: =RIGHT(CELL("filename",$A$1),LEN(CELL("filename",$A$1))-FIND("]",CELL("filename",$A$1))) -> テーブル項目_受注 | U3: 表題 | Z3: =表紙!$AJ$65 -> MSBBPA070 | AE3: =表紙!$AQ$65 -> Web受注入力
A5: テーブル名 | O5: 日本語名 | AE5: 種別
O6: 受注 | AE6: アドオン(新規)
A8: 主キー | D8: 項目名 | O8: 日本語名 | AE8: 型 | AG8: 桁 | AI8: Null | AK8: 説明 | BL8: 値の制限 | BM8: 設定仕様 | BN8: 未設定時の振る舞い | BO8: 受注画面
A9: 〇 | O9: Web受注NO | AE9: N | AI9: N
O10: 得意先コード | AE10: C | AI10: N | BL10: 得意先マスタ(mcframe7)
O11: 受注区分 | AE11: C | AI11: N | AK11: 受注区分：加工製品、加工商品、シート製品、購買品 | BL11: 汎用マスタ(mcframe7)
O12: 受注部門 | AE12: C | BL12: 部門マスタ(mcframe7)
O13: 受注日 | AE13: D
O14: 客納納期 | AE14: D
O15: 数量 | AE15: N
O16: 注文書NO | AE16: C
O17: 先方担当 | AE17: C
O18: 宛名 | AE18: C
O19: 運送会社 | AE19: C
O20: 出荷日時 | AE20: C
O21: 売価区分 | AE21: C | AK21: 売価区分：個別単価、セット単価
O22: 受注ＮＯ | AK22: mcframe7側の連携キー
O23: ステータス | AE23: N | AI23: N | AK23: 0:未転送、9:mcframe7転送済
O24: mcframe7転送FLG | AE24: F | AI24: N | AK24: mcframe7転送を示すフラグ
D25: MEMO1 | O25: メモ１ | AE25: C | AG25: 100 | AI25: Y
D26: MEMO2 | O26: メモ２ | AE26: C | AG26: 100 | AI26: Y
D27: MEMO3 | O27: メモ３ | AE27: C | AG27: 100 | AI27: Y
D28: DEL_FLG | O28: 論理削除ＦＬＧ | AE28: F | AI28: N | AK28: 論理削除を示すフラグ
D29: DEL_USR_ID | O29: 論理削除ユーザＩＤ | AE29: C | AG29: 500 | AI29: Y
D30: DEL_USR_NM | O30: 論理削除ユーザ名 | AE30: C | AG30: 100 | AI30: Y
D31: DEL_TS | O31: 論理削除日時 | AE31: TS | AG31: 0 | AI31: Y
D32: INS_USR_ID | O32: 登録ユーザＩＤ | AE32: C | AG32: 500 | AI32: Y
D33: INS_USR_NM | O33: 登録ユーザ名 | AE33: C | AG33: 100 | AI33: Y
D34: INS_TS | O34: 登録日時 | AE34: TS | AG34: 0 | AI34: Y
D35: INS_FUNC_ID | O35: 登録機能ＩＤ | AE35: C | AG35: 50 | AI35: Y
D36: UPD_CNTR | O36: 更新カウンタ | AE36: N | AG36: 9,0 | AI36: Y
D37: UPD_USR_ID | O37: 更新ユーザＩＤ | AE37: C | AG37: 500 | AI37: Y
D38: UPD_USR_NM | O38: 更新ユーザ名 | AE38: C | AG38: 100 | AI38: Y
D39: UPD_TS | O39: 更新日時 | AE39: TS | AG39: 0 | AI39: Y
D40: UPD_FUNC_ID | O40: 更新機能ＩＤ | AE40: C | AG40: 50 | AI40: Y
D41: UPD_SRV_REQ_NO | O41: 更新リクエストＮＯ | AE41: C | AG41: 50 | AI41: Y

Sheet テーブル項目_受注明細
A1: =表紙!A54 -> Webシステム | K1: 文書名 | U1: モジュールID | Z1: =表紙!$AJ$63 -> MS | AE1: モジュール名 | AJ1: =表紙!$AX$63 -> 見積管理 | AS1: 文書番号 | AZ1: Version | BF1: Rev.
K2: =表紙!O64 -> アドオン設計書 | U2: ｻﾌﾞﾓｼﾞｭｰﾙID | Z2: =表紙!$AJ$64 -> MSBB | AE2: ｻﾌﾞﾓｼﾞｭｰﾙ名 | AJ2: =表紙!$AX$64 -> Webシステム | AS2: =表紙!$BL$64 -> M7-US-1140 | AZ2: =表紙!$BU$64 -> 7.0.2 | BF2: =表紙!$CB$64 -> 7
K3: =RIGHT(CELL("filename",$A$1),LEN(CELL("filename",$A$1))-FIND("]",CELL("filename",$A$1))) -> テーブル項目_受注明細 | U3: 表題 | Z3: =表紙!$AJ$65 -> MSBBPA070 | AE3: =表紙!$AQ$65 -> Web受注入力
A5: テーブル名 | O5: 日本語名 | AE5: 種別
O6: 受注明細 | AE6: アドオン(新規)
A8: 主キー | D8: 項目名 | O8: 日本語名 | AE8: 型 | AG8: 桁 | AI8: Null | AK8: 説明 | BL8: 値の制限 | BM8: 設定仕様 | BN8: 未設定時の振る舞い | BO8: 受注画面
A9: 〇 | O9: Web受注NO | AE9: N | AI9: N
A10: 〇 | O10: Web受注明細NO | AE10: N | AI10: N
O11: 手配ＮＯ１ | AE11: C | AI11: Y
O12: 手配ＮＯ２ | AE12: C | AI12: Y
O13: 手配ＮＯ３ | AE13: C | AI13: Y
O14: 手配ＮＯ４ | AE14: C | AI14: Y
O15: 製品コード | AE15: C | AI15: N | BL15: 製品マスタ
O16: 品目コード | AE16: C | AI16: N | AK16: mcframe7連携用 | BL16: システム自動 | BO16: 画面表示無し
O17: 枝番１ | AE17: C | AI17: N | AK17: mcframe7連携用 | AR17: 部材一覧の行番(00) | BL17: システム自動 | BO17: 画面表示無し
O18: 枝番２ | AE18: C | AI18: N | AK18: mcframe7連携用 | BL18: システム自動 | BO18: 画面表示無し
O19: 枝番３ | AE19: C | AI19: N | AK19: mcframe7連携用 | BL19: システム自動 | BO19: 画面表示無し
O20: 製品区分_大 | AE20: C | AI20: N
O21: 製品区分_中 | AE21: C | AI21: N
O22: 製品区分_小 | AE22: C | AI22: N
O23: 顧客品名１ | AE23: C | AI23: Y
O24: 顧客品名２ | AE24: C | AI24: Y
O25: 顧客品番 | AE25: C | AI25: Y
O26: CP品名1 | AE26: C | AI26: Y
O27: CP品名2 | AE27: C | AI27: Y
O28: 数量単位 | AE28: C | AI28: N
O29: 数量 | AE29: N | AI29: N
O30: 特値FLG | AE30: C | AI30: N
O31: 単価単位
O32: セット単価 | AE32: N | AI32: N
O33: 個別単価 | AE33: N | AI33: N
O34: 金額 | AE34: N | AI34: N
O35: 納品先コード | AE35: C | AI35: N | BL35: 納品先マスタ(mcframe7)
O36: 客先納期 | AE36: D | AI36: N
O37: 物流グループ | AE37: C | AI37: N | BL37: 物流グループマスタ(mcframe7)
O38: 手配区分 | AE38: C | AI38: N | AK38: 選択項目は、汎用マスタで管理
O39: 預り売上FLG | AE39: C | AI39: N
O40: 売上理由 | AE40: C
O41: 出荷検査 | AE41: C | AL41: 〃
O42: FSC認証製品 | AE42: C | AL42: 〃
...

Sheet テーブル項目_受注加工工程
A1: =表紙!A54 -> Webシステム | K1: 文書名 | U1: モジュールID | Z1: =表紙!$AJ$63 -> MS | AE1: モジュール名 | AJ1: =表紙!$AX$63 -> 見積管理 | AS1: 文書番号 | AZ1: Version | BF1: Rev.
K2: =表紙!O64 -> アドオン設計書 | U2: ｻﾌﾞﾓｼﾞｭｰﾙID | Z2: =表紙!$AJ$64 -> MSBB | AE2: ｻﾌﾞﾓｼﾞｭｰﾙ名 | AJ2: =表紙!$AX$64 -> Webシステム | AS2: =表紙!$BL$64 -> M7-US-1140 | AZ2: =表紙!$BU$64 -> 7.0.2 | BF2: =表紙!$CB$64 -> 7
K3: =RIGHT(CELL("filename",$A$1),LEN(CELL("filename",$A$1))-FIND("]",CELL("filename",$A$1))) -> テーブル項目_受注加工工程 | U3: 表題 | Z3: =表紙!$AJ$65 -> MSBBPA070 | AE3: =表紙!$AQ$65 -> Web受注入力
A5: テーブル名 | O5: 日本語名 | AE5: 種別
O6: 受注加工工程 | AE6: アドオン(新規)
A8: 主キー | D8: 項目名 | O8: 日本語名 | AE8: 型 | AG8: 桁 | AI8: Null | AK8: 説明 | BL8: 値の制限 | BM8: 設定仕様 | BN8: 未設定時の振る舞い | BO8: 受注画面
A9: 〇 | O9: Web受注NO | AE9: N | AI9: N
A10: 〇 | O10: Web受注明細NO | AE10: N | AI10: N
A11: 〇 | O11: 製品コード | AE11: C | AI11: N | AK11: 製品コードを自動採番する。 コード体系参照。 | BO11: １ページ目：メンテ対象選択画面
A12: 〇 | O12: 作業コード | AE12: C | AI12: N | AK12: mcの工程コードに当たる。製品マスタで設定 | BL12: 作業マスタ(条件=作業CD) | BO12: ３ページ目：工程情報画面 | BP12: 〇
O13: 工程コード | AE13: C | AI13: N | AK13: mcの品目コードに当たる。製品マスタで設定
O14: TOP品目コード | AE14: C | AI14: N | AK14: 製品の品目CD
O15: TOP品目_枝番1 | AE15: C | AI15: N | AK15: 製品の品目枝番１
O16: TOP品目_枝番2 | AE16: C | AI16: N | AK16: 製品の品目枝番２
O17: TOP品目_枝番3 | AE17: C | AI17: N | AK17: 製品の品目枝番３
O18: 品目コード | AE18: C | AI18: N | AK18: 工程の品目CD
O19: 枝番1 | AE19: C | AI19: N | AK19: 工程の品目枝番１
O20: 枝番2 | AE20: C | AI20: N | AK20: 工程の品目枝番２
O21: 枝番3 | AE21: C | AI21: N | AK21: 工程の品目枝番３
O22: ワーキンググループＣＤ | AE22: C | AG22: 10 | AI22: Y | AK22: 号機・発注先に紐づくワーキンググループCD | BO22: ３ページ目：工程情報画面 | BP22: 〇
O23: 号機・発注先 | AE23: C | AI23: Y | AK23: 作業場所として号機か発注先が入る | BL23: 取引先マスタ、場所マスタ | BO23: ３ページ目：工程情報画面 | BP23: △ | BQ23: 発注先時は、引き継ぐ
O24: 号機指定 | AE24: F | AI24: N | AK24: 号機・発注先が固定かどうか | BO24: ３ページ目：工程情報画面
O25: CP配送区分 | AE25: C | AI25: Y | AK25: 引取出荷、移送、売上出荷、WG間依頼 | BO25: ３ページ目：工程情報画面
O26: 工程仕様01 | AE26: C | AI26: Y | AK26: 作業の仕様情報が入る | BL26: 汎用マスタ(工程仕様) | BO26: ３ページ目：工程情報画面 | BP26: 〇
O27: 工程仕様02 | AE27: C | AI27: Y | AK27: 作業の仕様情報が入る | BL27: 汎用マスタ(工程仕様) | BO27: ３ページ目：工程情報画面 | BP27: 〇
O28: 工程仕様03 | AE28: C | AI28: Y | AK28: 作業の仕様情報が入る | BL28: 汎用マスタ(工程仕様) | BO28: ３ページ目：工程情報画面 | BP28: 〇
O29: 工程仕様04 | AE29: C | AI29: Y | AK29: 作業の仕様情報が入る | BL29: 汎用マスタ(工程仕様) | BO29: ３ページ目：工程情報画面 | BP29: 〇
O30: 工程仕様05 | AE30: C | AI30: Y | AK30: 作業の仕様情報が入る | BL30: 汎用マスタ(工程仕様) | BO30: ３ページ目：工程情報画面 | BP30: 〇
O31: 工程仕様06 | AE31: C | AI31: Y | AK31: 作業の仕様情報が入る | BL31: 汎用マスタ(工程仕様) | BO31: ３ページ目：工程情報画面 | BP31: 〇
O32: 工程仕様07 | AE32: C | AI32: Y | AK32: 作業の仕様情報が入る | BL32: 汎用マスタ(工程仕様) | BO32: ３ページ目：工程情報画面 | BP32: 〇
O33: 工程仕様08 | AE33: C | AI33: Y | AK33: 作業の仕様情報が入る | BL33: 汎用マスタ(工程仕様) | BO33: ３ページ目：工程情報画面 | BP33: 〇
O34: 工程仕様09 | AE34: C | AI34: Y | AK34: 作業の仕様情報が入る | BL34: 汎用マスタ(工程仕様) | BO34: ３ページ目：工程情報画面 | BP34: 〇
O35: 工程仕様10 | AE35: C | AI35: Y | AK35: 作業の仕様情報が入る | BL35: 汎用マスタ(工程仕様) | BO35: ３ページ目：工程情報画面 | BP35: 〇
O36: 数量単位 | AE36: N | AI36: Y | AK36: 仕様設定された単位を転記する
O37: 版型NO１ | AE37: C | AI37: Y | AK37: 工程で使用する版型 | BO37: ３ページ目：工程情報画面
O38: 版型NO２ | AE38: C | AI38: Y | AK38: 工程で使用する版型 | BO38: ３ページ目：工程情報画面
O39: 版型NO３ | AE39: C | AI39: Y | AK39: 工程で使用する版型 | BO39: ３ページ目：工程情報画面
O40: 消耗品１ | AE40: C | AI40: Y | AK40: 工程で使用する消耗品 | BO40: ３ページ目：工程情報画面
O41: 消耗品２ | AE41: C | AI41: Y | AK41: 工程で使用する消耗品 | BO41: ３ページ目：工程情報画面
O42: 消耗品３ | AE42: C | AI42: Y | AK42: 工程で使用する消耗品 | BO42: ３ページ目：工程情報画面
...

Sheet テーブル項目_受注工程備考
A1: =表紙!A54 -> Webシステム | K1: 文書名 | U1: モジュールID | Z1: =表紙!$AJ$63 -> MS | AE1: モジュール名 | AJ1: =表紙!$AX$63 -> 見積管理 | AS1: 文書番号 | AZ1: Version | BF1: Rev.
K2: =表紙!O64 -> アドオン設計書 | U2: ｻﾌﾞﾓｼﾞｭｰﾙID | Z2: =表紙!$AJ$64 -> MSBB | AE2: ｻﾌﾞﾓｼﾞｭｰﾙ名 | AJ2: =表紙!$AX$64 -> Webシステム | AS2: =表紙!$BL$64 -> M7-US-1140 | AZ2: =表紙!$BU$64 -> 7.0.2 | BF2: =表紙!$CB$64 -> 7
