Workbook
Name Rev.: 表紙!$U$22
Name Ver.: 表紙!$AE$26
Name ご確認者: 表紙!$AG$40
Name ご確認日: 表紙!$AG$42
Name サブシステム名: 表紙!$U$28
Name システム名: 表紙!$U$26
Name プロジェクト名: 表紙!$U$18
Name 開発区分: 表紙!$U$36
Name 機能ＩＤ: 表紙!$U$32
Name 機能区分: 表紙!$U$34
Name 機能名称: 表紙!$U$30
Name 顧客名: 表紙!$U$16
Name 最終更新者: 表紙!$AB$40
Name 最終更新日: 表紙!$AB$42
Name 作成者: 表紙!$W$40
Name 作成日: 表紙!$W$42
Name 章: 表紙!$M$10
Name 文書名: 表紙!$M$10

Sheet 目次
A1: アドオン設計書作成ガイド
C3: ■アドオン設計と成果物について
D4: ・システム設計フェーズとソフトウェア設計フェーズでアドオンの処理仕様を定義する
D5: ・システム設計フェーズとソフトウェア設計フェーズの成果物がアドオン設計書であり、ソフトウェア製作フェーズのインプットとなる
C7: ■各設計フェーズ毎のアドオン設計書作成範囲
D8: ・システム設計フェーズ：他機能との関連を定義するとともに、画面や帳票、ファイル入出力を中心とした外部入出力の設計を行う
D9: ・ソフトウェア設計フェーズ：内部処理を中心とした設計を行う
U11: ◎ | W11: … | X11: システム設計フェーズで作成
U12: ○ | W12: … | X12: システム設計フェーズで基本仕様を定義して、ソフトウェア設計フェーズで詳細化する
U13: △ | W13: … | X13: 必要に応じて（例えば標準仕様から変更がない場合は不要）
U14: ‐ | W14: … | X14: 不要
W15: … | X15: ソフトウェア設計フェーズで作成
D17: 各設計書と作成対象シートのマトリックス | S17: ※カスタマイズ：標準機能に機能を追加する アドオン：新規で機能を開発する
D18: EXCELシート | N18: 画面設計書 | W18: バッチ設計書 | AF18: 帳票設計書 | AO18: ＢＩ設計書 | AT18: .Net設計書 | BB18: EXCELシート | BL18: WebDB設計書 | BR18: 帳票設計書 | BX18: 汎用申請設計書
N19: カスタマイズ | S19: アドオン | W19: カスタマイズ | AB19: アドオン | AF19: カスタマイズ | AK19: アドオン | AO19: アドオン | AT19: アドオン | BL19: アドオン | BR19: アドオン | BX19: アドオン
D20: 概要 | N20: ◎ | O20: ※1 | S20: ◎ | W20: ◎ | X20: ※1 | AB20: ◎ | AF20: ◎ | AG20: ※1 | AK20: ◎ | AO20: ◎ | AT20: ◎ | BB20: 機能概要 | BL20: ◎ | BR20: ◎ | BX20: ◎
D21: レイアウト | N21: ◎ | O21: ※2 | S21: ◎ | W21: ‐ | AB21: ‐ | AF21: ◎ | AG21: ※2 | AK21: ◎ | AO21: ◎ | AT21: ◎ | BB21: アプリケーションフロー | BL21: ◎ | BR21: ー | BX21: ◎
D22: 項目説明 | N22: △ | S22: ○ | W22: ‐ | AB22: ‐ | AF22: △ | AK22: ○ | AO22: ○ | AT22: ○ | BB22: データベース設定 | BL22: ◎ | BR22: ー | BX22: ◎
D23: 引数説明 | N23: ‐ | S23: ‐ | W23: △ | AB23: ◎ | AF23: ‐ | AK23: ‐ | AO23: ‐ | AT23: ◎ | BB23: フィールド設定 | BL23: ◎ | BR23: ー | BX23: ◎
D24: 処理概要 | N24: ◎ | S24: ◎ | W24: ◎ | AB24: ◎ | AF24: ◎ | AK24: ◎ | AO24: ◎ | AT24: ◎ | BB24: 一覧表示画面設定 | BL24: ◎ | BR24: ー | BX24: ◎
D25: 処理詳細 | BB25: 表示編集画面設定 | BL25: ◎ | BR25: ー | BX25: ◎
D26: 処理・サービス関連図 | N26: △ | S26: ◎ | W26: △ | AB26: ◎ | AF26: ‐ | AK26: ‐ | AO26: ‐ | AT26: ◎ | BB26: 明細画面設定 | BL26: △ | BN26: ※3 | BR26: ー | BX26: △ | BZ26: ※3
D27: 検索入出力仕様 | N27: △ | S27: ○ | W27: △ | AB27: ○ | AF27: ‐ | AK27: ‐ | AO27: ‐ | AT27: ○ | BB27: 集計表示設定 | BL27: △ | BN27: ※4 | BR27: ー | BX27: △ | BZ27: ※4
D28: 更新入出力仕様 | N28: △ | S28: ○ | W28: △ | AB28: ○ | AF28: ‐ | AK28: ‐ | AO28: ‐ | AT28: ○ | BB28: 絞り込み条件設定 | BL28: △ | BN28: ※5 | BR28: ー | BX28: △ | BZ28: ※5
D29: ファイル入出力仕様 | N29: △ | S29: △ | W29: ‐ | AB29: ‐ | AF29: ‐ | AK29: ‐ | AO29: ‐ | AT29: △ | BB29: その他設定 | BR29: ー
D30: 画面遷移 | N30: △ | S30: ◎ | W30: ‐ | AB30: ‐ | AF30: ‐ | AK30: ‐ | AO30: ‐ | AT30: ◎ | BB30: 帳票イメージ | BL30: ー | BR30: ◎ | BX30: ー
D31: メッセージ一覧 | N31: △ | S31: △ | W31: △ | AB31: △ | AF31: ‐ | AK31: ‐ | AO31: ‐ | AT31: △ | BB31: 項目設計 | BL31: ー | BR31: ◎ | BX31: ー
D32: 補足説明 | N32: △ | S32: △ | W32: △ | AB32: △ | AF32: △ | AK32: △ | AO32: △ | AT32: △ | BB32: 補足説明 | BL32: △ | BR32: △ | BX32: △
D33: サービス呼出編集仕様 | N33: - | S33: - | W33: - | AB33: - | AF33: - | AK33: - | AO33: - | AT33: - | BB33: 補足説明(詳細)
D35: ※1 | G35: 別シートでカスタマイズ内容を記載する | BB35: ※3 | BE35: 単票画面は記載しない
D36: ※2 | G36: 吹き出しでカスタマイズ内容を記載する | BB36: ※4 | BE36: 集計・グラフ機能を使用する場合に記載する
BB37: ※5 | BE37: 共通設定のみ記載する(個別設定は、記載しない)

Sheet 表紙
AW2: サブモジュール
AW3: MA_マスタ管理
AW4: MB_業務共通
AW5: MG_原価管理
AW6: MSBA_需給管理
M7: 基本設計 | AW7: MSBB_販売管理
AW8: MSBC_生産管理
AW9: MSBD_購買管理
M10: アドオン設計書 | AW10: MSBE_在庫物流管理
AW11: MSBF_品質管理
AW12: MSBG_債権管理
AW13: MSBH_債務管理
AW14: MSBI_締処理
AW15: MSUA_リスト・入力補助
M16: 顧客 | U16: 株式会社クラウン・パッケージ | AW16: PF_ESBアダプタ
M18: プロジェクト名 | U18: 基幹システム刷新PJ | AW18: 機能区分
AW19: 画面
M20: 文書番号 | AW20: 帳票
AW21: バッチ
M22: Ｒｅｖ． | U22: {=MAX(_xlfn.NUMBERVALUE(改訂!A7:E44))} -> 1 | AW22: マスタ
M24: 機密性区分 | U24: 取扱注意（Ｃ） | AW24: 開発区分
AW25: カスタマイズ
M26: システム名 | U26: Webシステム | AC26: Ver. | AE26: 7.0.2 | AW26: アドオン
AW27: －
M28: サブモジュール | U28: MSBB_販売管理
M30: 機能名 | U30: =M50 -> WebFSC製品化チェックシート出力
M32: 機能ID | U32: =G50 -> MSBBPA100
M34: 機能区分 | U34: 画面
M36: 開発区分 | U36: アドオン
W39: 作成 | AB39: 最終更新 | AG39: ご確認
W40: MDSOL
W42: 44824
A48: 文書番号 | G48: 画面ID | M48: 画面名 | V48: Version | AB48: Revision
A50: M7-US-1140 | G50: MSBBPA100 | M50: WebFSC製品化チェックシート出力 | V50: 1.0.0 | AB50: r01.00
A53: 共通（元データ）
A54: Webシステム | K54: 文書名 | U54: モジュールID | Z54: MS | AE54: モジュール名 | AJ54: Webシステム | AS54: 文書番号 | AZ54: Version | BF54: Rev.
K55: 画面説明書 | U55: ｻﾌﾞﾓｼﾞｭｰﾙID | Z55: MSBB | AE55: ｻﾌﾞﾓｼﾞｭｰﾙ名 | AJ55: Web販売管理 | AS55: M7-US-1140 | AZ55: 1.0.0 | BF55: r00.00
K56: 表紙 | U56: 表題 | Z56: MSBBPA100 | AE56: WebFSC製品化チェックシート出力
A57: 共通（リンク用）
A58: =A54 -> Webシステム | K58: 文書名 | U58: モジュールID | Z58: =Z54 -> MS | AE58: モジュール名 | AJ58: =AJ54 -> Webシステム | AS58: 文書番号 | AZ58: Version | BF58: Rev.
...

Sheet 改訂
A1: 第7章 | K1: 改訂 | AU1: 作成者 | AZ1: MDSOL | BE1: 作成日 | BJ1: =表紙!W42 -> 44824 | BP1: Rev.
AU2: 修正者 | BE2: 改訂日 | BP2: =表紙!CB64 -> 1
A5: Rev. | F5: 改定内容 | BC5: 頁 | BM5: 変更日 変更者 | BR5: 確認日 確認者
A7: 1 | F7: 新規作成

Sheet 概要
A1: =表紙!A54 -> Webシステム | O1: 文書名 | AC1: モジュールID | AJ1: =表紙!AJ63 -> MS | AQ1: モジュール名 | AX1: =表紙!AX63 -> Webシステム | BL1: 文書番号 | BU1: Version | CB1: Rev.
O2: =表紙!O64 -> アドオン設計書 | AC2: サブモジュールID | AJ2: =表紙!AJ64 -> MSBB | AQ2: サブモジュール名 | AX2: =表紙!AX64 -> Web販売管理 | BL2: =表紙!BL64 -> M7-US-1140 | BU2: =表紙!BU64 -> 7.0.2 | CB2: =表紙!CB64 -> 1
O3: =RIGHT(CELL("filename",$A$1),LEN(CELL("filename",$A$1))-FIND("]",CELL("filename",$A$1))) -> 概要 | AC3: 表題 | AJ3: =表紙!AJ65 -> MSBBPA100 | AQ3: =表紙!AQ65 -> WebFSC製品化チェックシート出力
AO5: 概要
B7: 【業務要件】
C8: カスタマイズ | G8: 内容
C9: No.
C10: 54 | G10: FSC認証コード体系について
G11: FSC認証が必要な場合、FSC製品化チェックシートを作成し、報告用資料を作成する
G12: 見積・受注 FSCは見積内容を出力してチェックシートを出すだけとし、後はワークフローとする
B15: 【機能概要】
C16: 1. | D16: FSC製品化チェックシートを出力する | X16: CP指摘 20221018 伊藤広 FSC製品化には、オンプロ製品・生体製品・OEM購買品・オフプロ宣伝用の４つがあります。 | CJ16: MDSOL 野村 2022/10/25 出力フォーマットにて出力できるEXCELは選択できることを想定しています | CM16: CP指摘 20221026 伊藤広 入力画面は現状のオフコンでは４つの製品化登録画面のほか、FSデザイナー入力画面・サイト事務局入力画面・CoC事務局入力画面が
AA17: Excelシートも項目は共通ですが、印刷用のシートは4種類あります。 | CJ17: ※現状MAX10種類までを想定。(【MSBBPA000】_共通設計書_アドオン(Webシステム共通仕様) - webconfig追記) | CV17: FSCデザイナー入力以降の処理で、製品化Excelシートの右側をメンテしていく手順になります
B18: 【前提条件】 | X18: CP指摘 2022/10/18 玉置 区分名の表記について 「マークナシ」の表記は表示スペースの関係で半角ｶﾅで表示しなければならなかった結果で、 スペースに問題が無ければ、この設計書の他のシートも含めて「マーク無し」と記述すべきと考えます。 | CK18: →指摘に記載いただいているとおり、項目共通が前提となります。(DATAシートは共通) | CV18: よって現状では入力した4つの画面に即した４パターンのExcel出力となります。
C19: 1. | D19: 発行対象データは、見積確認済みの御見積書データから作成する | CW19: MDSOL 野村 2022/10/31 今回の新基幹システムでは、FSCの入力画面は存在せず、決定見積時のデータからFSC製品化チェックシートを出力することになります。
C20: 2. | D20: 発行対象データは、FSC製品区分≠0：非該当とする | CJ20: MDSOL 野村 2022/10/25 「マーク無し」に変更します。(横展開対応も実施します) | CW20: デザイナー・サイト事務などの追加入力は、出力したEXCELに行う想定となります。(ファイルサーバやPEの添付ファイルで出力したFSC製品化チェックシートEXCELを管理する。)
D21: FSC製品区分=0：非該当、1：社外、2：社内、3：マーク無し | CJ21: →実値は、【MSBBPACOM】_共通設計書_アドオン(Web共通ロジック)の定数一覧にて管理しています | CW21: ※入力チェックは、EXCELマクロ等で実施していただくことを想定しています。
C22: 3. | D22: FSC製品化チェックシートは、EXCEL帳票とする | CL22: 2022/10/27 玉置 問題なし | CX22: 2022/11/01 落合 補足。 出力されたエクセルをワークフローで流す。
C23: 4. | D23: FSCの対象は身、蓋、仕切りの部材の内代表の部材とする→見積計算書単位でなく、御見積書単位に出力する | DD23: デザイナー→サイト事務局→CoC事務局の順。各々がエクセルに入力しワークフローに添付を行う。
C24: 5. | D24: FSCチェックシートの出力フォーマットを選択可能とするが、データ転送(DATAシートへの転送)は共通とする | DB24: エクセルでうまく運用が難しい場合は、クラウン側で入力画面→エクセル出力の機能を作成する
C25: 6. | D25: FSCチェックシートは、WEBサーバ上から参照可能なフォルダで管理する | DC25: MDSOL 野村 2022/11/02 補足いただいた内容で相違ありません。
D26: また、FSCチェックシートのひな型は、CPにて作成・修正し所定場所に配置する | DC26: 2022/11/04 落合 問題なし
C27: 7. | D27: FSCチェックシートのフォーマット・出力するEXCELファイルは、[.xls、xlsx形式]とする | AC27: CP指摘 2022/10/18 玉置 機能の確認 xlsとxlsxは違う形式と認識していますが？（ＣＳＶではないという意味？） １択ならば、.xlsxが良いと考えます。 | CJ27: MDSOL 野村 2022/10/25 Excel for .NETで読み取り可能な拡張子となります
CJ28: テンプレートを読み取りデータを書き込み保存・DLすることを想定しています
B29: 【FSC製品化チェックシート発行フロー】 | CJ29: 出力後にマクロでのチェックが必要な場合、「xls」になるかと思います。(テンプレートはCP様にて用意いただく想定)
CJ30: ※マクロ付きXLSがExcel for .NETでの読み取りやDL時にセキュリティでエラーにならないかは、開発時に検証が必要になります
CL31: 2022/10/27 玉置 問題なし
B64: 【説明】
C65: FSC製品化チェックシートの発行画面
B67: 【目的】
C68: 目的（レベル１） | Q68: 目的（レベル２） | AT68: 利用シーン/補足 | BV68: 操作種別/検索モード
C69: FSC製品化チェックシートの出力対象を | AT69: 【利用シーン】 | BV69: 参照する
C70: 一覧形式で照会する | AT70: FSC製品化チェックシートを発行するためにFSC製品化チェックシート情報を一覧照会する
C71: FSC製品化チェックシートを発行する | Q71: 未発行のFSC製品化チェックシートを新規発行する | AT71: 【利用シーン】 | BV71: 帳票発行
AT72: ・FSC製品化チェックシートを発行する、FSC管理NOが自動採番される
Q73: 発行済のFSC製品化チェックシートを再発行する | AT73: 【利用シーン】 | BV73: 帳票発行
AT74: ・FSC製品化チェックシートの内容を変更した場合などに、
AT75: 本画面でFSC製品化チェックシートを再発行する
B77: 【処理関連図/サービス関連図】
C78: ※処理・サービス関連図シートに詳細記載
...

Sheet 画面イメージ
A1: =表紙!A54 -> Webシステム | K1: 文書名 | U1: モジュールID | Z1: =表紙!$AJ$63 -> MS | AE1: モジュール名 | AJ1: =表紙!$AX$63 -> Webシステム | AS1: 文書番号 | AZ1: Version | BF1: Rev.
K2: =表紙!O64 -> アドオン設計書 | U2: ｻﾌﾞﾓｼﾞｭｰﾙID | Z2: =表紙!$AJ$64 -> MSBB | AE2: ｻﾌﾞﾓｼﾞｭｰﾙ名 | AJ2: =表紙!$AX$64 -> Web販売管理 | AS2: =表紙!$BL$64 -> M7-US-1140 | AZ2: =表紙!$BU$64 -> 7.0.2 | BF2: =表紙!$CB$64 -> 1
K3: =RIGHT(CELL("filename",$A$1),LEN(CELL("filename",$A$1))-FIND("]",CELL("filename",$A$1))) -> 画面イメージ | U3: 表題 | Z3: =表紙!$AJ$65 -> MSBBPA100 | AE3: =表紙!$AQ$65 -> WebFSC製品化チェックシート出力
A5: 画面イメージ
B7: ≫凡例
Q8: ・・・ | S8: ボタン
C9: 見積計算書NO | Q9: ・・・ | S9: 検索項目(検索画面表示選択) | AJ9: 参照情報
C10: 品名 | Q10: ・・・ | S10: 入力項目
C11: 得意先 | Q11: ・・・ | S11: 表示項目(得意先名称、原紙名等) | AJ11: 担当者
C12: 操作種別 | I12: ●登録 | M12: ○訂正 | Q12: ・・・ | S12: 選択項目(一つのみ選択可能)
C13: 受注区分 | Q13: ・・・ | S13: 選択項目(一つのみ選択可能)
C14: 作業順 | I14: ☑AAA | M14: ☑BBB | Q14: ・・・ | S14: 選択項目(複数選択可能)
C16: 見積作成日 | Q16: ・・・ | S16: カレンダー形式 | AF16: CP指摘 2022/10/18 玉置 誤記の連絡 カレンダー←カンレンダー | CN16: MDSOL 野村 2022/10/25 修正しました(横展開対応も実施します) | DI16: 2022/10/27 玉置 問題なし
AP19: CP指摘 2022/10/18 玉置 区分名の表記について 「マークナシ」の表記は表示スペースの関係で半角ｶﾅで表示しなければならなかった結果で、 スペースに問題が無ければ、この設計書の他のシートも含めて「マーク無し」と記述すべきと考えます。
CN20: MDSOL 野村 2022/10/25 「マーク無し」に変更します。(横展開対応も実施します)
CN21: →実値は、【MSBBPACOM】_共通設計書_アドオン(Web共通ロジック)の定数一覧にて管理しています | DN21: 2022/10/27 玉置 問題なし
BX26: －
D28: 拠点 | AB28: 担当者
D30: 基本情報
D31: 御見積書作成日 | P31: ~
D32: 御見積書NO | P32: ~
D33: 得意先 | J33: (得意先名:オートフィルタ)
D34: 案件No | J34: 9999999-999 | Q34: (案件No親/子)
D36: ステータス | J36: ☑未発行 | N36: ☑発行済
D40: NO | F40: 担当 | H40: 担当者名 | K40: 得意先 | N40: 得意先名 | R40: 案件NO | W40: 案件名 | AA40: 御見積書NO | AF40: 御見積書 | AJ40: 1行目 | BG40: 合計金額 | BK40: ステータス | BN40: 発行 | BP40: FSC管理NO | BT40: 発行済
AF41: 発行日 | AJ41: 顧客品名 | AU41: 見積数 | AY41: 単価 | BC41: 金額
D42: 1 | F42: 1234 | H42: XXXXX6 | K42: 12345 | N42: XXXXXXX8 | R42: 1234567-001 | W42: XXXXXXX8 | AA42: M-12345678 | AF42: 2022/7/1 | AJ42: XXXXXXXXX1XXXXX6 | AQ42: XXXXXXX8 | AU42: 9999999 | AY42: 9999999 | BC42: 9999999 | BG42: 9999999 | BK42: 承認済 | BN42: ☑ | BP42: XXXXXXX8 | BT42: 発行済
D43: 2 | F43: 1234 | H43: XXXXX6 | K43: 12345 | N43: XXXXXXX8 | R43: 1234567-001 | W43: XXXXXXX8 | AA43: M-12345679 | AF43: 2022/7/1 | AJ43: XXXXXXXXX1XXXXX6 | AQ43: XXXXXXX8 | AU43: 9999999 | AY43: 9999999 | BC43: 9999999 | BG43: 9999999 | BK43: 承認済 | BN43: ☑ | BP43: XXXXXXX8 | BT43: 発行済
D44: 3 | F44: 1234 | H44: XXXXX6 | K44: 12345 | N44: XXXXXXX8 | R44: 1234567-001 | W44: XXXXXXX8 | AA44: M-12345680 | AF44: 2022/7/1 | AJ44: XXXXXXXXX1XXXXX6 | AQ44: XXXXXXX8 | AU44: 9999999 | AY44: 9999999 | BC44: 9999999 | BG44: 9999999 | BK44: 承認済 | BN44: ☑ | BP44: XXXXXXX8 | BT44: 発行済
D45: 4 | F45: 1234 | H45: XXXXX6 | K45: 12345 | N45: XXXXXXX8 | R45: 1234567-001 | W45: XXXXXXX8 | AA45: M-12345681 | AF45: 2022/7/1 | AJ45: XXXXXXXXX1XXXXX6 | AQ45: XXXXXXX8 | AU45: 9999999 | AY45: 9999999 | BC45: 9999999 | BG45: 9999999 | BK45: 承認済 | BN45: □ | BT45: 未発行
D46: 5 | F46: 1234 | H46: XXXXX6 | K46: 12345 | N46: XXXXXXX8 | R46: 1234567-001 | W46: XXXXXXX8 | AA46: M-12345682 | AF46: 2022/7/1 | AJ46: XXXXXXXXX1XXXXX6 | AQ46: XXXXXXX8 | AU46: 9999999 | AY46: 9999999 | BC46: 9999999 | BG46: 9999999 | BK46: 承認済 | BN46: ☑ | BT46: 未発行
D47: 6 | F47: 1234 | H47: XXXXX6 | K47: 12345 | N47: XXXXXXX8 | R47: 1234567-001 | W47: XXXXXXX8 | AA47: M-12345683 | AF47: 2022/7/1 | AJ47: YYYYYYYYY1XXXXX6 | AQ47: XXXXXX01 | AU47: 9999999 | AY47: 9999999 | BC47: 9999999 | BG47: 9999999 | BK47: 未承認 | BN47: ☑ | BT47: 未発行
D48: 7 | F48: 1234 | H48: XXXXX6 | K48: 12345 | N48: XXXXXXX8 | R48: 1234567-001 | W48: XXXXXXX8 | AA48: M-12345684 | AF48: 2022/7/1 | AJ48: YYYYYYYYY1XXXXX6 | AQ48: XXXXXX02 | AU48: 9999999 | AY48: 9999999 | BC48: 9999999 | BG48: 9999999 | BK48: 未承認 | BN48: ☑ | BT48: 未発行
D49: 8 | F49: 1234 | H49: XXXXX6 | K49: 12345 | N49: XXXXXXX8 | R49: 1234567-001 | W49: XXXXXXX8 | AA49: M-12345685 | AF49: 2022/7/1 | AJ49: YYYYYYYYY1XXXXX6 | AQ49: XXXXXX03 | AU49: 9999999 | AY49: 9999999 | BC49: 9999999 | BG49: 9999999 | BK49: 未承認 | BN49: □ | BT49: 未発行
D50: 9 | F50: 1234 | H50: XXXXX6 | K50: 12345 | N50: XXXXXXX8 | R50: 1234567-001 | W50: XXXXXXX8 | AA50: M-12345686 | AF50: 2022/7/1 | AJ50: YYYYYYYYY1XXXXX6 | AQ50: XXXXXX04 | AU50: 9999999 | AY50: 9999999 | BC50: 9999999 | BG50: 9999999 | BK50: 未承認 | BN50: □ | BT50: 未発行
D51: 10 | F51: 1234 | H51: XXXXX6 | K51: 12345 | N51: XXXXXXX8 | R51: 1234567-001 | W51: XXXXXXX8 | AA51: M-12345687 | AF51: 2022/7/1 | AJ51: YYYYYYYYY1XXXXX6 | AQ51: XXXXXX05 | AU51: 9999999 | AY51: 9999999 | BC51: 9999999 | BG51: 9999999 | BK51: 未承認 | BN51: □ | BT51: 未発行
D52: ◁ | BV52: ▷
BC55: 出力フォーマット
C60: 発行 | F60: ・・・ | H60: 発行対象に☑する。
C61: ☑
...

Sheet 項目説明
A1: =表紙!A54 -> Webシステム | K1: 文書名 | U1: モジュールID | Z1: =表紙!$AJ$63 -> MS | AE1: モジュール名 | AJ1: =表紙!$AX$63 -> Webシステム | AS1: 文書番号 | AZ1: Version | BF1: Rev.
K2: =表紙!O64 -> アドオン設計書 | U2: ｻﾌﾞﾓｼﾞｭｰﾙID | Z2: =表紙!$AJ$64 -> MSBB | AE2: ｻﾌﾞﾓｼﾞｭｰﾙ名 | AJ2: =表紙!$AX$64 -> Web販売管理 | AS2: =表紙!$BL$64 -> M7-US-1140 | AZ2: =表紙!$BU$64 -> 7.0.2 | BF2: =表紙!$CB$64 -> 1
K3: =RIGHT(CELL("filename",$A$1),LEN(CELL("filename",$A$1))-FIND("]",CELL("filename",$A$1))) -> 項目説明 | U3: 表題 | Z3: =表紙!$AJ$65 -> MSBBPA100 | AE3: =表紙!$AQ$65 -> WebFSC製品化チェックシート出力
A5: WebFSC製品化チェックシート出力
B6: 抽出条件 | N6: 説明 | BE6: Ｗ | BF6: 型 | BG6: 参 | BH6: 必 | BI6: 入 | BJ6: 非 | BK6: 検
A7: 〇 | B7: 拠点 | M7: 【MSBBPACOM】_共通設計書_アドオン(共通ロジック)にて定義 | BE7: C | BF7: S | BH7: 必
A8: 〇 | B8: 担当者 | M8: 【MSBBPACOM】_共通設計書_アドオン(共通ロジック)にて定義 | BE8: C | BF8: S
A9: 〇 | B9: 御見積書作成日(From) | M9: 抽出条件として、御見積書発行日(From)を入力する | BE9: カ | BF9: D
A10: 〇 | B10: 御見積書作成日(To) | M10: 抽出条件として、御見積書発行日(To)を入力する | BE10: カ | BF10: D
A11: 〇 | B11: 御見積書NO(From) | M11: 抽出条件として、御見積書NO(From)を入力する | BE11: T | BF11: S
A12: 〇 | B12: 御見積書NO(To) | M12: 抽出条件として、御見積書NO(To)を入力する | BE12: T | BF12: S
A13: 〇 | B13: 得意先 | M13: 【MSBBPACOM】_共通設計書_アドオン(共通ロジック)にて定義 | BE13: A | BF13: S | BK13: 検
A14: 〇 | B14: 案件No | M14: 【MSBBPACOM】_共通設計書_アドオン(共通ロジック)にて定義 | BE14: A | BF14: S | BK14: 検
A15: 〇 | B15: ステータス | M15: □未発行、□発行済 | AJ15: ※初期値：☑未発行、□発行済 | BE15: チ | BF15: F
B17: 出力一覧 | N17: 説明 | BE17: Ｗ | BF17: 型 | BG17: 参 | BH17: 必 | BI17: 入 | BJ17: 非 | BK17: 検
B18: NO | M18: 行番を表示 | BE18: T | BF18: N
B19: 担当 | M19: 担当を表示 | BE19: T | BF19: S
B20: 担当者名 | M20: 担当者名を表示 | BE20: T | BF20: S
B21: 得意先 | M21: 得意先を表示 | BE21: T | BF21: S
B22: 得意先名 | M22: 得意先名を表示 | BE22: T | BF22: S
B23: 案件NO | M23: 案件NOを表示 | BE23: T | BF23: S
B24: 案件名 | M24: 案件名を表示 | BE24: T | BF24: S
B25: 御見積書NO | M25: 御見積書NOを表示 | BE25: T | BF25: S
B26: 御見積書発行日 | M26: 御見積書発行日を表示 | BE26: T | BF26: D
B27: 顧客品名1 | I27: (1行目) | M27: 顧客品名1を表示 | BE27: T | BF27: S
B28: 顧客品名2 | I28: (1行目) | M28: 顧客品名2を表示 | BE28: T | BF28: S
B29: 見積数 | I29: (1行目) | M29: 見積数を表示 | BE29: T | BF29: N
B30: 単価 | I30: (1行目) | M30: 単価を表示 | BE30: T | BF30: N
B31: 金額 | I31: (1行目) | M31: 金額を表示 | BE31: T | BF31: N
B32: 合計金額 | M32: 合計金額を表示 | BE32: T | BF32: N
B33: ステータス | M33: ステータスを表示 | BE33: T | BF33: S
A34: ● | B34: 発行 | M34: 帳票を出力する場合にチェックする | BE34: チ | BF34: N
B35: FSC管理NO | M35: FSC管理NOを表示 | BE35: T | BF35: S
B36: 発行済 | M36: 未発行・発行済を表示 | BE36: T | BF36: S
B37: 共通項目 | BE37: Ｗ | BF37: 型 | BG37: 参 | BH37: 必 | BI37: 入 | BJ37: 非 | BK37: 検
B38: 全選択 | M38: FSCチェックシート一覧の発行チェックを全てチェック=ONとする | BE38: チ | BF38: F
B39: 全解除 | M39: FSCチェックシート一覧の発行チェックを全てチェック=OFFとする | BE39: チ | BF39: F
A40: ● | B40: 出力フォーマット | M40: 出力フォーマットを選択する | BE40: C | BF40: S
B42: フッター | N42: 説明 | BE42: Ｗ | BF42: 型 | BG42: 参 | BH42: 必 | BI42: 入 | BJ42: 非 | BK42: 検
B43: クリア | M43: 画面を初期化する | BE43: B
...

Sheet 処理概要
A1: =表紙!A54 -> Webシステム | K1: 文書名 | U1: モジュールID | Z1: =表紙!$AJ$63 -> MS | AE1: モジュール名 | AJ1: =表紙!$AX$63 -> Webシステム | AS1: 文書番号 | AZ1: Version | BF1: Rev.
K2: =表紙!O64 -> アドオン設計書 | U2: ｻﾌﾞﾓｼﾞｭｰﾙID | Z2: =表紙!$AJ$64 -> MSBB | AE2: ｻﾌﾞﾓｼﾞｭｰﾙ名 | AJ2: =表紙!$AX$64 -> Web販売管理 | AS2: =表紙!$BL$64 -> M7-US-1140 | AZ2: =表紙!$BU$64 -> 7.0.2 | BF2: =表紙!$CB$64 -> 1
K3: =RIGHT(CELL("filename",$A$1),LEN(CELL("filename",$A$1))-FIND("]",CELL("filename",$A$1))) -> 処理概要 | U3: 表題 | Z3: =表紙!$AJ$65 -> MSBBPA100 | AE3: =表紙!$AQ$65 -> WebFSC製品化チェックシート出力
A5: No | B5: 入力 | J5: 処理 | BD5: 出力
A6: 1 | B6: 初期表示
J7: 1.初期設定
L8: 拠点 | R8: ： | S8: ログインに紐づく拠点CDを表示する
S9: ログイン.管理者区分 = 0(一般ユーザー時)、変更不可とする
L10: 担当者 | R10: ： | S10: ログイン担当者CDを表示する
L11: ステータス | R11: ： | S11: 未発行にチェック(発行済みはチェックなし)
L12: 出力フォーマット | R12: ： | S12: web.config定義(MSBBPA100_ExcelFormat01～10)まで読込み設定分(入力分)
S13: 出力フォーマット コンボボックスに名称をセットする
L14: 設定例
L15: web.config定義 | S15: key | AC15: value(名称,ひな型保存パス(サーバパス))
S16: MSBBPA100_ExcelFormat01 | AC16: 製品用チェックシート,C:\temp\A.xls
S17: MSBBPA100_ExcelFormat02 | AC17: ○○用チェックシート,C:\temp\b.xlsx
S19: 出力フォーマット | Y19: 製品用チェックシート
Y20: 製品用チェックシート | AN20: ←コンボボックスの中身
Y21: ○○用チェックシート
S22: ※ひな型保存パス(サーバパス)は、FSC製品化チェックシート出力時に使用する
J24: 2.表示処理
L25: 抽出条件をもと一覧に結果を表示する
L26: ※検索結果が0件の場合、メッセージを表示する | AC26: エラーメッセージ：検索結果がありません。 | BD26: メッセージID.001
A28: 2 | B28: クリア
J29: 1.画面を初期化する(起動時の状態とする)
A31: 3 | B31: 表示
J32: 1.表示チェック処理
L33: チェック処理にてエラーとなった場合、後続処理をキャンセルする
N34: 必須チェック | AC34: エラーメッセージ：必須項目に値が指定されていません。項目名：パラメータ | BD34: メッセージID.002
N35: FROM～TOの整合性チェック | AC35: エラーメッセージ：FROM≦TOの関係で指定してください。 | BD35: メッセージID.003
N36: チェックボックスチェック有無 | AC36: エラーメッセージ：いずれかを選択してください。 | BD36: メッセージID.004
J38: 2.抽出条件をもとに一覧に結果を表示する | BD38: 検索入出力仕様.NO1
L39: ※検索結果が0件の場合、メッセージを表示する | AC39: エラーメッセージ：検索結果がありません。 | BD39: メッセージID.001
A41: 4 | B41: FSC製品化チェックシート帳票発行
J42: 1.FSC製品化チェックシート帳票発行 チェック処理
L43: チェック処理にてエラーとなった場合、後続処理をキャンセルする
N44: 必須チェック(出力フォーマット) | AC44: エラーメッセージ：必須項目に値が指定されていません。 | BD44: メッセージID.005
M45: 一覧にデータが無いもしくは発行対象行が選択されてない場合、下記メッセージを表示
AC46: エラーメッセージ：選択行がありません。 | BD46: メッセージID.006
J48: 2.チェックされた対象分、チェックシートを繰り返し発行する。
...

Sheet 処理詳細
A1: =表紙!A54 -> Webシステム | K1: 文書名 | U1: モジュールID | Z1: =表紙!$AJ$63 -> MS | AE1: モジュール名 | AJ1: =表紙!$AX$63 -> Webシステム | AS1: 文書番号 | AZ1: Version | BF1: Rev.
K2: =表紙!O64 -> アドオン設計書 | U2: ｻﾌﾞﾓｼﾞｭｰﾙID | Z2: =表紙!$AJ$64 -> MSBB | AE2: ｻﾌﾞﾓｼﾞｭｰﾙ名 | AJ2: =表紙!$AX$64 -> Web販売管理 | AS2: =表紙!$BL$64 -> M7-US-1140 | AZ2: =表紙!$BU$64 -> 7.0.2 | BF2: =表紙!$CB$64 -> 1
K3: =RIGHT(CELL("filename",$A$1),LEN(CELL("filename",$A$1))-FIND("]",CELL("filename",$A$1))) -> 処理詳細 | U3: 表題 | Z3: =表紙!$AJ$65 -> MSBBPA100 | AE3: =表紙!$AQ$65 -> WebFSC製品化チェックシート出力
A5: No | B5: 入力 | J5: 処理 | BD5: 出力
A6: 1 | B6: 初期表示
J7: 1.1 | L7: 初期設定
L8: 拠点 | R8: ： | S8: ログインに紐づく拠点CDを表示する
S9: ログイン.管理者区分 = 0(一般ユーザー時)、変更不可とする
L10: 担当者 | R10: ： | S10: ログイン担当者CDを表示する
L11: ステータス | R11: ： | S11: 未発行にチェック、発行済みはチェックなし
L12: 出力フォーマット | R12: ： | S12: web.config定義(MSBBPA100_ExcelFormat01～10)まで読込み設定分(入力分)
S13: 出力フォーマット コンボボックスに名称をセットする
L14: 設定例
L15: web.config定義 | S15: key | AC15: value(名称,ひな型保存パス(サーバパス))
S16: MSBBPA100_ExcelFormat01 | AC16: 製品用チェックシート,C:\temp\A.xls
S17: MSBBPA100_ExcelFormat02 | AC17: ○○用チェックシート,C:\temp\b.xlsx
S19: 出力フォーマット | Y19: 製品用チェックシート
Y20: 製品用チェックシート | AN20: ←コンボボックスの中身
Y21: ○○用チェックシート
S22: ※ひな型保存パス(サーバパス)は、FSC製品化チェックシート出力時に使用する
J24: 1.2 | L24: 表示処理
L25: 抽出条件をもと一覧に結果を表示する
L26: ※検索結果が0件の場合、メッセージを表示する | AC26: エラーメッセージ：検索結果がありません。 | BD26: メッセージID.001
A28: 2 | B28: 画面操作
J29: 2.1 | L29: [抽出条件].検索(+/-)押す
L30: 検索領域を+時…開く、-時…閉じる
J32: 2.2 | L32: 表示ボタン押す、検索処理を実行する。
J34: 2.3 | L34: チェックシート発行ボタン押す、伝票発行処理を実行する。
J36: 2.4 | L36: 共通項目変更
L37: 全選択をチェックする場合、FSCチェックシート一覧の発行チェックを全てチェック=ONとする
L38: 全解除をチェックする場合、FSCチェックシート一覧の発行チェックを全てチェック=OFFとする
J40: 2.5 | L40: 出力フォーマット押す、出力フォーマットのコンボボックスを表示する。
L41: ※ | M41: web.config定義(MSBBPA100_ExcelFormat01～10)が設定しない場合、コンボボックスの中身を表示できない。
A44: 3 | B44: 検索【F1】
J45: 3.１ | L45: コンボボックスの初期化
L46: 拠点コンボボックスの初期化
M47: ※ | N47: 拠点検索_SQLリソースの検索仕様
N48: 【MSBBPACOM】_共通設計書_アドオン(Web共通ロジック)の「処理詳細(共通検索)」シート」を参照する。
L50: 担当者コンボボックスの初期化
M51: ※ | N51: 担当者検索_SQLリソースの検索仕様
...

Sheet 画面項目制御
J2: 操作種別 | O2: 検索 | S2: R | U2: 有効(必須)
B3: 画面項目 | S3: E | U3: 有効
B4: 抽出条件 | G4: 拠点 | O4: R/RO | S4: RO | U4: 読取のみ
G5: 担当者 | O5: E | S5: D | U5: 無効
G6: 御見積書作成日(From) | O6: E | S6: I | U6: 非表示
G7: 御見積書作成日(To) | O7: E
G8: 御見積書NO(From) | O8: E
G9: 御見積書NO(To) | O9: E
G10: 得意先 | O10: E
G11: 案件No | O11: E
G12: ステータス | O12: E
B13: 出力一覧 | G13: NO | O13: RO
G14: 担当 | O14: RO
G15: 担当者名 | O15: RO
G16: 得意先 | O16: RO
G17: 得意先名 | O17: RO
G18: 案件NO | O18: RO
G19: 案件名 | O19: RO
G20: 御見積書NO | O20: RO
G21: 御見積書発行日 | O21: RO
G22: 顧客品名1 | O22: RO
G23: 顧客品名2 | O23: RO
G24: 見積数 | O24: RO
G25: 単価 | O25: RO
... G31: 発行済 | O31: RO
B32: 共通項目 | G32: 全選択 | O32: E
G33: 全解除 | O33: E
G34: 出力フォーマット | O34: E
B35: フッター | G35: クリア | O35: E
G36: 表示 | O36: E
G37: チェックシート発行 | O37: E

Sheet 処理・サービス関連図
A1: =表紙!A54 -> Webシステム | K1: 文書名 | U1: モジュールID | Z1: =表紙!$AJ$63 -> MS | AE1: モジュール名 | AJ1: =表紙!$AX$63 -> Webシステム | AS1: 文書番号 | AZ1: Version | BF1: Rev.
K2: =表紙!O64 -> アドオン設計書 | U2: ｻﾌﾞﾓｼﾞｭｰﾙID | Z2: =表紙!$AJ$64 -> MSBB | AE2: ｻﾌﾞﾓｼﾞｭｰﾙ名 | AJ2: =表紙!$AX$64 -> Web販売管理 | AS2: =表紙!$BL$64 -> M7-US-1140 | AZ2: =表紙!$BU$64 -> 7.0.2 | BF2: =表紙!$CB$64 -> 1
K3: =RIGHT(CELL("filename",$A$1),LEN(CELL("filename",$A$1))-FIND("]",CELL("filename",$A$1))) -> 処理・サービス関連図 | U3: 表題 | Z3: =表紙!$AJ$65 -> MSBBPA100 | AE3: =表紙!$AQ$65 -> WebFSC製品化チェックシート出力
C7: 検索処理

Sheet 検索入出力仕様
A1: =表紙!A54 -> Webシステム | K1: 文書名 | U1: モジュールID | Z1: =表紙!$AJ$63 -> MS | AE1: モジュール名 | AJ1: =表紙!$AX$63 -> Webシステム | AS1: 文書番号 | AZ1: Version | BF1: Rev.
K2: =表紙!O64 -> アドオン設計書 | U2: ｻﾌﾞﾓｼﾞｭｰﾙID | Z2: =表紙!$AJ$64 -> MSBB | AE2: ｻﾌﾞﾓｼﾞｭｰﾙ名 | AJ2: =表紙!$AX$64 -> Web販売管理 | AS2: =表紙!$BL$64 -> M7-US-1140 | AZ2: =表紙!$BU$64 -> 7.0.2 | BF2: =表紙!$CB$64 -> 1
K3: =RIGHT(CELL("filename",$A$1),LEN(CELL("filename",$A$1))-FIND("]",CELL("filename",$A$1))) -> 検索入出力仕様 | U3: 表題 | Z3: =表紙!$AJ$65 -> MSBBPA100 | AE3: =表紙!$AQ$65 -> WebFSC製品化チェックシート出力
A5: No | G5: 1 | S5: ボタン | Z5: 表示 | AH5: 備考 | AK5: 表示ボタンクリック時処理
A6: 処理分類 | E6: 検索 | S6: ソート順 | Z6: 担当、得意先、案件NO、見積計算書NO、
A7: No | C7: 転送先 | X7: 転送元 | AU7: 説明
C8: 種 | D8: オブジェクト | M8: 項目名 | X8: 種 | Y8: オブジェクト | AH8: 項目名
A9: 1 | C9: 画 | D9: FSC製品化チェックシート | M9: NO | AH9: 行番
A10: 2 | C10: 画 | D10: FSC製品化チェックシート | M10: 担当者 | X10: T | Y10: 御見積書 | AH10: 担当者
X11: T | Y11: 担当 | AH11: 担当者名
A12: 3 | C12: 画 | D12: FSC製品化チェックシート | M12: 得意先 | X12: T | Y12: 御見積書 | AH12: 得意先
X13: T | Y13: 得意先 | AC13: WEB取引先マスタ | AH13: 得意先名 | AL13: 取引先名
A14: 4 | C14: 画 | D14: FSC製品化チェックシート | M14: 案件NO | X14: T | Y14: 御見積書 | AH14: 案件NO | AU14: キー：案件ＮＯ_親,案件ＮＯ_子,案件ＮＯ_部材⇒案件NO
X15: T | Y15: ヒアリングシート | AC15: 案件管理トラン | AH15: 案件名
A16: 5 | C16: 画 | D16: FSC製品化チェックシート | M16: 御見積書NO | X16: T | Y16: 見積計算書 | AC16: WEB御見積書見積計算書 | AH16: 御見積書NO
A17: 6 | C17: 画 | D17: FSC製品化チェックシート | M17: 御見積書発行日 | X17: T | Y17: 見積計算書 | AC17: WEB御見積書 | AH17: 御見積書発行日
A18: 7 | C18: 画 | D18: FSC製品化チェックシート | M18: 顧客品名 | X18: T | Y18: 御見積書明細(印字用) | AH18: 顧客品名 | AL18: (商品名１,商品名２) | AU18: 御見積書明細(印字用).明細NO=1
A19: 8 | C19: 画 | D19: FSC製品化チェックシート | M19: 見積数 | X19: T | Y19: 御見積書明細(印字用) | AH19: 見積数 | AL19: 数量 | AU19: 御見積書明細(印字用).明細NO=1
A20: 9 | C20: 画 | D20: FSC製品化チェックシート | M20: 単価 | X20: T | Y20: 御見積書明細(印字用) | AH20: 単価 | AU20: 御見積書明細(印字用).明細NO=1
A21: 10 | C21: 画 | D21: FSC製品化チェックシート | M21: 金額 | X21: T | Y21: 御見積書明細(印字用) | AH21: 金額 | AU21: 御見積書明細(印字用).明細NO=1
A22: 11 | C22: 画 | D22: FSC製品化チェックシート | M22: 合計金額 | X22: T | Y22: 見積計算書 | AH22: 合計金額 | AL22: 見積金額(見積合計金額)
A23: 12 | C23: 画 | D23: FSC製品化チェックシート | M23: ステータス | X23: T | Y23: 見積計算書 | AH23: ステータス
A24: 13 | C24: 画 | D24: FSC製品化チェックシート | M24: 発行 | AH24: [固定値:0] ※チェック無し
A25: 14 | C25: 画 | D25: FSC製品化チェックシート | M25: FSC管理NO | X25: T | Y25: 御見積書 | AH25: FSC管理NO
A26: 15 | C26: 画 | D26: FSC製品化チェックシート | M26: 発行済 | AH26: FSC管理NOあり：発行済、以外空白。

Sheet ファイル入出力仕様
A1: =表紙!A54 -> Webシステム | K1: 文書名 | U1: モジュールID | Z1: =表紙!$AJ$63 -> MS | AE1: モジュール名 | AJ1: =表紙!$AX$63 -> Webシステム | AS1: 文書番号 | AZ1: Version | BF1: Rev.
K2: =表紙!O64 -> アドオン設計書 | U2: ｻﾌﾞﾓｼﾞｭｰﾙID | Z2: =表紙!$AJ$64 -> MSBB | AE2: ｻﾌﾞﾓｼﾞｭｰﾙ名 | AJ2: =表紙!$AX$64 -> Web販売管理 | AS2: =表紙!$BL$64 -> M7-US-1140 | AZ2: =表紙!$BU$64 -> 7.0.2 | BF2: =表紙!$CB$64 -> 1
K3: =RIGHT(CELL("filename",$A$1),LEN(CELL("filename",$A$1))-FIND("]",CELL("filename",$A$1))) -> ファイル入出力仕様 | U3: 表題 | Z3: =表紙!$AJ$65 -> MSBBPA100 | AE3: =表紙!$AQ$65 -> WebFSC製品化チェックシート出力
A5: No | G5: 1 | S5: ロジック名称 | Z5: ファイル出力 | AH5: 備考
A6: 処理分類 | E6: ファイル出力 | S6: ソート順
A7: No | C7: 転送先 | X7: 転送元 | AS7: 説明
C8: 種 | D8: オブジェクト | M8: 項目名 | X8: 種 | Y8: オブジェクト | AI8: 項目名
A9: 1 | C9: フ | D9: FSC製品化チェックシート | M9: 行番 | X9: 画 | Y9: FSC製品化チェックシート | AI9: 行番
A10: 2 | C10: フ | D10: FSC製品化チェックシート | M10: 担当者 | X10: 画 | Y10: FSC製品化チェックシート | AI10: 担当者
C11: フ | D11: FSC製品化チェックシート | M11: 担当者名 | AI11: 担当者名
A12: 3 | C12: フ | D12: FSC製品化チェックシート | M12: 得意先 | X12: 画 | Y12: FSC製品化チェックシート | AI12: 得意先
C13: フ | D13: FSC製品化チェックシート | M13: 得意先名 | AI13: 得意先名
A14: 4 | C14: フ | D14: FSC製品化チェックシート | M14: 案件NO | X14: 画 | Y14: FSC製品化チェックシート | AI14: 案件NO
C15: フ | D15: FSC製品化チェックシート | M15: 案件名 | AI15: 案件名
A16: 5 | C16: フ | D16: FSC製品化チェックシート | M16: 御見積書NO | X16: 画 | Y16: FSC製品化チェックシート | AI16: 御見積書NO
A17: 6 | C17: フ | D17: FSC製品化チェックシート | M17: 御見積書発行日 | X17: 画 | Y17: FSC製品化チェックシート | AI17: 御見積書発行日
A18: 7 | C18: フ | D18: FSC製品化チェックシート | M18: 顧客品名 | X18: 画 | Y18: FSC製品化チェックシート | AI18: 顧客品名
A19: 8 | C19: フ | D19: FSC製品化チェックシート | M19: 見積数 | X19: 画 | Y19: FSC製品化チェックシート | AI19: 見積数
A20: 9 | C20: フ | D20: FSC製品化チェックシート | M20: 単価 | X20: 画 | Y20: FSC製品化チェックシート | AI20: 単価
A21: 10 | C21: フ | D21: FSC製品化チェックシート | M21: 金額 | X21: 画 | Y21: FSC製品化チェックシート | AI21: 金額
A22: 11 | C22: フ | D22: FSC製品化チェックシート | M22: 合計金額 | X22: 画 | Y22: FSC製品化チェックシート | AI22: 合計金額
A23: 12 | C23: フ | D23: FSC製品化チェックシート | M23: ステータス | X23: 画 | Y23: FSC製品化チェックシート | AI23: ステータス
A24: 13 | C24: フ | D24: FSC製品化チェックシート | M24: FSC管理NO | X24: 画 | Y24: FSC製品化チェックシート | AI24: FSC管理NO
A25: 14 | C25: フ | D25: FSC製品化チェックシート | M25: 発行済 | X25: 画 | Y25: FSC製品化チェックシート | AI25: 発行済

Sheet 更新入出力仕様
A1: =表紙!A54 -> Webシステム | K1: 文書名 | U1: モジュールID | Z1: =表紙!$AJ$63 -> MS | AE1: モジュール名 | AJ1: =表紙!$AX$63 -> Webシステム | AS1: 文書番号 | AZ1: Version | BF1: Rev.
K2: =表紙!O64 -> アドオン設計書 | U2: ｻﾌﾞﾓｼﾞｭｰﾙID | Z2: =表紙!$AJ$64 -> MSBB | AE2: ｻﾌﾞﾓｼﾞｭｰﾙ名 | AJ2: =表紙!$AX$64 -> Web販売管理 | AS2: =表紙!$BL$64 -> M7-US-1140 | AZ2: =表紙!$BU$64 -> 7.0.2 | BF2: =表紙!$CB$64 -> 1
K3: =RIGHT(CELL("filename",$A$1),LEN(CELL("filename",$A$1))-FIND("]",CELL("filename",$A$1))) -> 更新入出力仕様 | U3: 表題 | Z3: =表紙!$AJ$65 -> MSBBPA100 | AE3: =表紙!$AQ$65 -> WebFSC製品化チェックシート出力
A5: No | G5: 1 | S5: ロジック名称 | Z5: Upd01 | AH5: 備考
A6: 処理分類 | E6: 更新
A7: No | C7: 転送先 | V7: 転送元 | AQ7: 説明
C8: 種 | D8: オブジェクト | K8: 項目名 | V8: 種 | W8: オブジェクト | AF8: 項目名
A9: 1 | C9: T | D9: WEB御見積書 | K9: FSC管理NO | AF9: FSC管理NO | AQ9: 採番
A10: 2 | C10: T | D10: WEB御見積書 | K10: FSCチェックシート発行日 | AF10: [本日日付]
A12: No | G12: 2 | S12: ロジック名称 | Z12: Upd02 | AH12: 備考
A13: 処理分類 | E13: 更新
A14: No | C14: 転送先 | V14: 転送元 | AQ14: 説明
C15: 種 | D15: オブジェクト | K15: 項目名 | V15: 種 | W15: オブジェクト | AF15: 項目名
A16: 1 | C16: T | D16: WEB見積計算書 | K16: FSC管理NO | AF16: FSC管理NO | AQ16: 採番
C19: FSC管理NO：採番に関して
D20: 頭文字(web.config定義(MSBBPA100_FSCNO_INITIAL)) + ORACLEシーケンスを使用する(数値のみ)
D21: 頭文字は空白設定可能
D22: ※FSC管理NO：ORACLEシーケンスのため、空き番は発生する (御見積書のデータ削除等の操作等)
C24: 補足
D25: 参照テーブル | W25: 結合条件
D26: WEB御見積書見積計算書 | W26: WEB御見積書.御見積書NO = WEB御見積書見積計算書.御見積書NO
W27: AND WEB御見積書見積計算書.確定FLG = 1
D28: →WEB御見積書見積計算書を結合条件を条件に取得し、取得分のWEB見積計算書.見積計算書NOに対して、FSC管理NOを更新する

Sheet 画面遷移
A1: =表紙!A54 -> Webシステム | K1: 文書名 | U1: モジュールID | Z1: =表紙!$AJ$63 -> MS | AE1: モジュール名 | AJ1: =表紙!$AX$63 -> Webシステム | AS1: 文書番号 | AZ1: Version | BF1: Rev.
K2: =表紙!O64 -> アドオン設計書 | U2: ｻﾌﾞﾓｼﾞｭｰﾙID | Z2: =表紙!$AJ$64 -> MSBB | AE2: ｻﾌﾞﾓｼﾞｭｰﾙ名 | AJ2: =表紙!$AX$64 -> Web販売管理 | AS2: =表紙!$BL$64 -> M7-US-1140 | AZ2: =表紙!$BU$64 -> 7.0.2 | BF2: =表紙!$CB$64 -> 1
K3: =RIGHT(CELL("filename",$A$1),LEN(CELL("filename",$A$1))-FIND("]",CELL("filename",$A$1))) -> 画面遷移 | U3: 表題 | Z3: =表紙!$AJ$65 -> MSBBPA100 | AE3: =表紙!$AQ$65 -> WebFSC製品化チェックシート出力
A5: 画面遷移フロー図
A6: ＩＤ | C6: S01 | E6: WebFSC製品化チェックシート出力から他画面の画面遷移
D9: NO1
D10: Web取引先一覧照会
K12: 検索 | R12: WebFSC製品化チェックシート出力
D15: NO2 | K15: 検索
D16: Web汎用検索(共通検索)
A22: ID | D22: 処理名
A23: S01 | D23: WebFSC製品化チェックシート出力から他画面の画面遷移
B25: NO | D25: 遷移元ＩＤ | H25: 遷移元画面名 | R25: 遷移先ＩＤ | W25: 遷移先画面名 | AF25: 目的 | AK25: 引継項目 | AT25: 遷移後のアクション(遷移先) | BD25: 戻り値 | BM25: 戻り値取得後のアクション(遷移元) | BW25: 備考
B26: 1 | D26: MSBBPA020 | H26: WebFSC製品化チェックシート出力 | R26: MSBBPA120 | W26: Web取引先一覧照会 | AF26: 検索結果取得 | AK26: 得意先ＦＬＧ=1 | AT26: 検索 | BD26: 取引先選択データ(1行) | BM26: 対象データに値セット | BW26: 得意先CD、得意先名に値セット
B27: 2 | D27: MSBBPA020 | H27: WebFSC製品化チェックシート出力 | R27: MSBBPA900 | W27: Web汎用検索(共通検索) | AF27: 検索結果取得 | AT27: 検索 | BD27: 各種検索画面の選択データ(1行) | BM27: 対象データに値セット | BW27: CD、名称に値セット
B28: 3
B29: 4
B30: 5
B31: 6
B32: 7
B33: 8

Sheet メッセージ一覧
A1: =表紙!A54 -> Webシステム | K1: 文書名 | U1: モジュールID | Z1: =表紙!$AJ$63 -> MS | AE1: モジュール名 | AJ1: =表紙!$AX$63 -> Webシステム | AS1: 文書番号 | AZ1: Version | BF1: Rev.
K2: =表紙!O64 -> アドオン設計書 | U2: ｻﾌﾞﾓｼﾞｭｰﾙID | Z2: =表紙!$AJ$64 -> MSBB | AE2: ｻﾌﾞﾓｼﾞｭｰﾙ名 | AJ2: =表紙!$AX$64 -> Web販売管理 | AS2: =表紙!$BL$64 -> M7-US-1140 | AZ2: =表紙!$BU$64 -> 7.0.2 | BF2: =表紙!$CB$64 -> 1
K3: =RIGHT(CELL("filename",$A$1),LEN(CELL("filename",$A$1))-FIND("]",CELL("filename",$A$1))) -> メッセージ一覧 | U3: 表題 | Z3: =表紙!$AJ$65 -> MSBBPA100 | AE3: =表紙!$AQ$65 -> WebFSC製品化チェックシート出力
C4: ↓アドオン画面のため、基本全て[新]
A5: No | C5: 新/変 | E5: 種別 | G5: メッセージ内容 | AQ5: 備考（パラメータ等） | BG5: メッセージID
A6: 1 | C6: 新 | E6: W | G6: 「検索結果がありません。」 | BG6: E10008
A7: 2 | C7: 新 | E7: W | G7: 「必須項目に値が指定されていません。」 | AQ7: 拠点、出力フォーマット | BG7: E10022
A8: 3 | C8: 新 | E8: W | G8: 「FROM≦TOの関係で指定してください。」 | AQ8: 御見積書作成日 | BG8: E10036
AQ9: 御見積書NO
A10: 4 | C10: 新 | E10: W | G10: 「いずれかを選択してください。」 | AQ10: ステータス | BG10: E10030
A11: 5 | C11: 新 | E11: W | G11: 「必須項目に値が指定されていません。」 | AQ11: 出力フォーマット | BG11: E10022
A12: 6 | C12: 新 | E12: W | G12: 「選択行がありません。」 | BG12: メッセージID.006
A13: 7 | C13: 新 | E13: W | G13: 「検索件数の上限値を超えました。(設定値) \n 抽出条件を設定し、再度検索・照会を実施ください。」 | BG13: E10013
A14: 8 | C14: 新 | E14: I | G14: 「検索件数の上限値を超えました。(設定値) \n 処理を続ける場合は、[はい]を選択してください。」 | BG14: C00006
