Workbook
Name Rev.: 表紙!$U$22
Name Revision: [2]表紙!$AP$5
Name Ver.: 表紙!$AE$26
Name Version: [2]表紙!$AJ$5
Name ご確認者: 表紙!$AG$40
Name ご確認日: 表紙!$AG$42
Name サブシステム名: 表紙!$U$28
Name システム名: 表紙!$U$26
Name プロジェクト名: 表紙!$U$18
Name 開発区分: 表紙!$U$36
Name 機能ＩＤ: 表紙!$U$32
Name 機能区分: 表紙!$U$34
Name 機能名称: 表紙!$U$30
Name 顧客名: 表紙!$U$16
Name 最終更新者: 表紙!$AB$40
Name 最終更新日: 表紙!$AB$42
Name 作成者: 表紙!$W$40
Name 作成日: 表紙!$W$42
Name 章: 表紙!$M$10
Name 文書番号: [2]表紙!$O$5
Name 文書名: 表紙!$M$10
Name 文書名: [2]表紙!$M$15

Sheet 目次
A1: アドオン設計書作成ガイド
C3: ■アドオン設計と成果物について
D4: ・システム設計フェーズとソフトウェア設計フェーズでアドオンの処理仕様を定義する
D5: ・システム設計フェーズとソフトウェア設計フェーズの成果物がアドオン設計書であり、ソフトウェア製作フェーズのインプットとなる
C7: ■各設計フェーズ毎のアドオン設計書作成範囲
D8: ・システム設計フェーズ：他機能との関連を定義するとともに、画面や帳票、ファイル入出力を中心とした外部入出力の設計を行う
D9: ・ソフトウェア設計フェーズ：内部処理を中心とした設計を行う
U11: ◎ | W11: … | X11: システム設計フェーズで作成
U12: ○ | W12: … | X12: システム設計フェーズで基本仕様を定義して、ソフトウェア設計フェーズで詳細化する
U13: △ | W13: … | X13: 必要に応じて（例えば標準仕様から変更がない場合は不要）
U14: ‐ | W14: … | X14: 不要
W15: … | X15: ソフトウェア設計フェーズで作成
D17: 各設計書と作成対象シートのマトリックス | S17: ※カスタマイズ：標準機能に機能を追加する アドオン：新規で機能を開発する
D18: EXCELシート | N18: 画面設計書 | W18: バッチ設計書 | AF18: 帳票設計書 | AO18: ＢＩ設計書 | AT18: .Net設計書 | BB18: EXCELシート | BL18: WebDB設計書 | BR18: 帳票設計書 | BX18: 汎用申請設計書
N19: カスタマイズ | S19: アドオン | W19: カスタマイズ | AB19: アドオン | AF19: カスタマイズ | AK19: アドオン | AO19: アドオン | AT19: アドオン | BL19: アドオン | BR19: アドオン | BX19: アドオン
D20: 概要 | N20: ◎ | O20: ※1 | S20: ◎ | W20: ◎ | X20: ※1 | AB20: ◎ | AF20: ◎ | AG20: ※1 | AK20: ◎ | AO20: ◎ | AT20: ◎ | BB20: 機能概要 | BL20: ◎ | BR20: ◎ | BX20: ◎
D21: レイアウト | N21: ◎ | O21: ※2 | S21: ◎ | W21: ‐ | AB21: ‐ | AF21: ◎ | AG21: ※2 | AK21: ◎ | AO21: ◎ | AT21: ◎ | BB21: アプリケーションフロー | BL21: ◎ | BR21: ー | BX21: ◎
D22: 項目説明 | N22: △ | S22: ○ | W22: ‐ | AB22: ‐ | AF22: △ | AK22: ○ | AO22: ○ | AT22: ○ | BB22: データベース設定 | BL22: ◎ | BR22: ー | BX22: ◎
D23: 引数説明 | N23: ‐ | S23: ‐ | W23: △ | AB23: ◎ | AF23: ‐ | AK23: ‐ | AO23: ‐ | AT23: ◎ | BB23: フィールド設定 | BL23: ◎ | BR23: ー | BX23: ◎
D24: 処理概要 | N24: ◎ | S24: ◎ | W24: ◎ | AB24: ◎ | AF24: ◎ | AK24: ◎ | AO24: ◎ | AT24: ◎ | BB24: 一覧表示画面設定 | BL24: ◎ | BR24: ー | BX24: ◎
D25: 処理詳細 | BB25: 表示編集画面設定 | BL25: ◎ | BR25: ー | BX25: ◎
D26: 処理・サービス関連図 | N26: △ | S26: ◎ | W26: △ | AB26: ◎ | AF26: ‐ | AK26: ‐ | AO26: ‐ | AT26: ◎ | BB26: 明細画面設定 | BL26: △ | BN26: ※3 | BR26: ー | BX26: △ | BZ26: ※3
D27: 検索入出力仕様 | N27: △ | S27: ○ | W27: △ | AB27: ○ | AF27: ‐ | AK27: ‐ | AO27: ‐ | AT27: ○ | BB27: 集計表示設定 | BL27: △ | BN27: ※4 | BR27: ー | BX27: △ | BZ27: ※4
D28: 更新入出力仕様 | N28: △ | S28: ○ | W28: △ | AB28: ○ | AF28: ‐ | AK28: ‐ | AO28: ‐ | AT28: ○ | BB28: 絞り込み条件設定 | BL28: △ | BN28: ※5 | BR28: ー | BX28: △ | BZ28: ※5
D29: ファイル入出力仕様 | N29: △ | S29: △ | W29: ‐ | AB29: ‐ | AF29: ‐ | AK29: ‐ | AO29: ‐ | AT29: △ | BB29: その他設定 | BR29: ー
D30: 画面遷移 | N30: △ | S30: ◎ | W30: ‐ | AB30: ‐ | AF30: ‐ | AK30: ‐ | AO30: ‐ | AT30: ◎ | BB30: 帳票イメージ | BL30: ー | BR30: ◎ | BX30: ー
D31: メッセージ一覧 | N31: △ | S31: △ | W31: △ | AB31: △ | AF31: ‐ | AK31: ‐ | AO31: ‐ | AT31: △ | BB31: 項目設計 | BL31: ー | BR31: ◎ | BX31: ー
D32: 補足説明 | N32: △ | S32: △ | W32: △ | AB32: △ | AF32: △ | AK32: △ | AO32: △ | AT32: △ | BB32: 補足説明 | BL32: △ | BR32: △ | BX32: △
D33: サービス呼出編集仕様 | N33: - | S33: - | W33: - | AB33: - | AF33: - | AK33: - | AO33: - | AT33: - | BB33: 補足説明(詳細)
D35: ※1 | G35: 別シートでカスタマイズ内容を記載する | BB35: ※3 | BE35: 単票画面は記載しない
D36: ※2 | G36: 吹き出しでカスタマイズ内容を記載する | BB36: ※4 | BE36: 集計・グラフ機能を使用する場合に記載する
BB37: ※5 | BE37: 共通設定のみ記載する(個別設定は、記載しない)

Sheet 表紙
AW2: サブモジュール
AW3: MA_マスタ管理
AW4: MB_業務共通
AW5: MG_原価管理
AW6: MSBA_需給管理
M7: 基本設計 | AW7: MSBB_販売管理
AW8: MSBC_生産管理
AW9: MSBD_購買管理
M10: アドオン設計書 | AW10: MSBE_在庫物流管理
AW11: MSBF_品質管理
AW12: MSBG_債権管理
AW13: MSBH_債務管理
AW14: MSBI_締処理
AW15: MSUA_リスト・入力補助
M16: 顧客 | U16: 株式会社クラウン・パッケージ | AW16: PF_ESBアダプタ
M18: プロジェクト名 | U18: 基幹システム刷新PJ | AW18: 機能区分
AW19: 画面
M20: 文書番号 | AW20: 帳票
AW21: バッチ
M22: Ｒｅｖ． | U22: {=MAX(_xlfn.NUMBERVALUE(改訂!A7:E44))} -> 3 | AW22: マスタ
M24: 機密性区分 | U24: 取扱注意（Ｃ） | AW24: 開発区分
AW25: カスタマイズ
M26: システム名 | U26: Webシステム | AC26: Ver. | AE26: 7.0.2 | AW26: アドオン
AW27: －
M28: サブモジュール | U28: MSBB_販売管理
M30: 機能名 | U30: =M50 -> Web御見積書登録
M32: 機能ID | U32: =G50 -> MSBBPA030
M34: 機能区分 | U34: 画面
M36: 開発区分 | U36: アドオン
W39: 作成 | AB39: 最終更新 | AG39: ご確認
W40: MDSOL | AB40: MDSOL
W42: 44805 | AB42: 44894
A48: 文書番号 | G48: 画面ID | M48: 画面名 | V48: Version | AB48: Revision
A50: M7-US-1140 | G50: MSBBPA030 | M50: Web御見積書登録 | V50: 1.0.0 | AB50: r01.00
A53: 共通（元データ）
A54: Webシステム | K54: 文書名 | U54: モジュールID | Z54: MS | AE54: モジュール名 | AJ54: Webシステム | AS54: 文書番号 | AZ54: Version | BF54: Rev.
K55: 画面説明書 | U55: ｻﾌﾞﾓｼﾞｭｰﾙID | Z55: MSBB | AE55: ｻﾌﾞﾓｼﾞｭｰﾙ名 | AJ55: 販売Webシステム | AS55: M7-US-1140 | AZ55: 1.0.0 | BF55: r00.00
K56: 表紙 | U56: 表題 | Z56: MSBBPA030 | AE56: Web御見積書登録
A57: 共通（リンク用）
A58: =A54 -> Webシステム | K58: 文書名 | U58: モジュールID | Z58: =Z54 -> MS | AE58: モジュール名 | AJ58: =AJ54 -> Webシステム | AS58: 文書番号 | AZ58: Version | BF58: Rev.
...

Sheet 改訂
A1: 第7章 | K1: 改訂 | AU1: 作成者 | AZ1: MDSOL | BE1: 作成日 | BJ1: =表紙!W42 -> 44805 | BP1: Rev.
AU2: 修正者 | AZ2: =BM12 -> TBK徐 | BE2: 改訂日 | BJ2: =BM11 -> 44954 | BP2: =表紙!CB64 -> 3
A5: Rev. | F5: 改定内容 | BC5: 頁 | BM5: 変更日 変更者 | BR5: 確認日 確認者
A7: 1 | F7: 新規作成 | BM7: 44865
BM8: MDSOL
A9: 2 | F9: 仕様連絡書：RCS-1062に伴う下記改定を実施 案件NOをDBの項目は、案件NO(親)＋案件NO(子)＋案件NO(部材)に分割する ※画面項目は、1つとする | BC9: 検索入出力仕様 更新入出力仕様 | BM9: 44894 | BR9: 44895
BM10: MDSOL | BR10: MDSOL 奥本
A11: 3 | F11: 処理詳細追加 | BC11: 処理詳細 | BM11: 44954
BM12: TBK徐

Sheet 概要
A1: =表紙!A54 -> Webシステム | O1: 文書名 | AC1: モジュールID | AJ1: =表紙!AJ63 -> MS | AQ1: モジュール名 | AX1: =表紙!AX63 -> Webシステム | BL1: 文書番号 | BU1: Version | CB1: Rev.
O2: =表紙!O64 -> アドオン設計書 | AC2: サブモジュールID | AJ2: =表紙!AJ64 -> MSBB | AQ2: サブモジュール名 | AX2: =表紙!AX64 -> 販売Webシステム | BL2: =表紙!BL64 -> M7-US-1140 | BU2: =表紙!BU64 -> 7.0.2 | CB2: =表紙!CB64 -> 3
O3: =RIGHT(CELL("filename",$A$1),LEN(CELL("filename",$A$1))-FIND("]",CELL("filename",$A$1))) -> 概要 | AC3: 表題 | AJ3: =表紙!AJ65 -> MSBBPA030 | AQ3: =表紙!AQ65 -> Web御見積書登録
AO5: 概要
B7: 【業務要件】
C8: カスタマイズ | G8: 内容
C9: No.
C10: 4 | G10: 見積Webシステムを構築する
H11: 主要機能
H12: ①見積(見積計算書)入力・発行
H13: ②御見積書入力・発行
B15: 【機能概要】
C16: ・御見積書を発行する
B18: 【前提条件】
C19: ・Web御見積書登録は、WEBシステムの機能とする(WEBシステムに機能構築する)
C20: Web見積計算書のデータから御見積書を作成・登録する
B22: 【説明】
C23: 御見積書を登録する、御見積書を発行する
B25: 【目的】
C26: ・御見積書を登録・訂正する
C27: ・御見積書を発行する
C28: ・見積確定登録を行う
B30: 【処理関連図/サービス関連図】
C31: ※処理・サービス関連図シートに詳細記載
B33: 【オペレーション一覧】
C34: 操作種別による制御(登録、訂正、削除、参照、コピー、確定、確定取消)
B36: 【SQLID一覧】
C37: なし
B39: 【ソート順】
C40: なし
B42: 【データアクセスコントロール】
C43: ・拠点による制御
C44: ※詳細は、【MSBBPA000】_共通設計書_アドオン(Webシステム共通仕様)にて定義
B46: 【自由記述】
C47: なし

Sheet 画面イメージ
A1: =表紙!A54 -> Webシステム | K1: 文書名 | U1: モジュールID | Z1: =表紙!$AJ$63 -> MS | AE1: モジュール名 | AJ1: =表紙!$AX$63 -> Webシステム | AS1: 文書番号 | AZ1: Version | BF1: Rev.
K2: =表紙!O64 -> アドオン設計書 | U2: ｻﾌﾞﾓｼﾞｭｰﾙID | Z2: =表紙!$AJ$64 -> MSBB | AE2: ｻﾌﾞﾓｼﾞｭｰﾙ名 | AJ2: =表紙!$AX$64 -> 販売Webシステム | AS2: =表紙!$BL$64 -> M7-US-1140 | AZ2: =表紙!$BU$64 -> 7.0.2 | BF2: =表紙!$CB$64 -> 3
K3: =RIGHT(CELL("filename",$A$1),LEN(CELL("filename",$A$1))-FIND("]",CELL("filename",$A$1))) -> 画面イメージ | U3: 表題 | Z3: =表紙!$AJ$65 -> MSBBPA030 | AE3: =表紙!$AQ$65 -> Web御見積書登録
A5: 画面イメージ
B7: ≫凡例
Q8: ・・・ | S8: ボタン
C9: 見積計算書NO | Q9: ・・・ | S9: 検索項目(検索画面表示選択)
C10: 品名 | Q10: ・・・ | S10: 入力項目
C11: 得意先 | Q11: ・・・ | S11: 表示項目(得意先名称、原紙名等)
C12: 操作種別 | I12: ●登録 | M12: ○訂正 | Q12: ・・・ | S12: 選択項目(一つのみ選択可能)
C13: 受注区分 | Q13: ・・・ | S13: 選択項目(一つのみ選択可能)
C14: 作業順 | I14: ☑AAA | M14: ☑BBB | Q14: ・・・ | S14: 選択項目(複数選択可能)
C16: １ページ目
D18: 操作種別 | J18: ●登録 | N18: ○訂正 | R18: ○削除 | V18: ○参照 | Z18: ○コピー
R20: ○確定 | V20: ○確定取消 | CT20: 事前指摘
N22: 御見積書No
D25: 御見積書No | J25: 自動採番 | AQ25: 見積確認ステータス | BD25: サイドバー領域
D26: 拠点 | W26: 担当者 | AQ26: マスタ確定ステータス
D29: 見積情報
D30: 得意先
D31: 案件NO | J31: 9999999-999-001 | Q31: (案件NO親/子/部材、案件名) | CU31: MDSOL 野村 2022/10/25 チェックロジック追加します。(データ参照は、操作種別：参照を選択してください。) | EA31: 2022/10/27 落合 問題なし
D33: 見積計算書一覧 | CU33: CP指摘 2022/09/28 木﨑 一覧の各行にチェック項目がある場合は「全選択」「全選択解除」があると便利かと思います。特に[全選択解除]はあるとよいかと。
D35: № | F35: 使用 | H35: 見積計算書NO | M35: 見積作成日 | R35: 品名1 | X35: 品名2 | AD35: 見積数 | AH35: 単価 | AL35: 単位 | AN35: 金額 | AR35: 確定 | CU35: MDSOL 野村 2022/10/25 チェック分御見積書明細となるため、確実にエンドユーザーに選択させたい意図があります。 | EB35: 2022/10/27 落合 問題なし
D36: 1 | F36: □ | H36: 12345678-01 | M36: 2022/07/01 | R36: ○○○○○ | X36: 身 | AD36: 1000 | AH36: 72 | AL36: 個 | AN36: =AD36*AH36 -> 72000
D37: 2 | F37: □ | H37: 12345679-01 | M37: 2022/07/01 | R37: ○○○○○ | X37: 蓋 | AD37: 1000 | AH37: 65 | AL37: 個 | AN37: =AD37*AH37 -> 65000 | CU37: CP指摘 2022/09/28 木﨑 [確定取消]の場合はヘッダーを[確定取消]に表示を変えた方がよいかと思います。画面上部の操作種別を見ればわかるかと思いますが、ぱっと見でどちらかハッキリ認識したいため。 | EK37: MDSOL 野村 2022/10/25 ボタンは操作種別によって切り替わるようにしました | FH37: 2022/10/27 落合 問題なし
D38: 3 | F38: □ | H38: 12345680-01 | M38: 2022/07/01 | R38: ○○○○○ | X38: 仕切り | AD38: 1000 | AH38: 63 | AL38: 個 | AN38: =AD38*AH38 -> 63000 | CU38: CP指摘 2022/10/02 落合 見積仕様書を発行する見積を選択するチェックボックスを追加する | EK38: MDSOL 野村 2022/10/25 見積計算書のチェック追加しました。 | FH38: CP指摘 2022/10/27 落合 計算書ではなく仕様書を出すチェックボックスです
D39: 4 | F39: ☑ | H39: 12345678-02 | M39: 2022/07/01 | R39: ○○○○○ | X39: 身 | AD39: 2000 | AH39: 71 | AL39: 個 | AN39: =AD39*AH39 -> 142000 | AR39: □ | FI39: MDSOL 野村 2022/10/31 見積仕様書のチェックに変更しました。
D40: 5 | F40: ☑ | H40: 12345679-02 | M40: 2022/07/01 | R40: ○○○○○ | X40: 蓋 | AD40: 2000 | AH40: 64 | AL40: 個 | AN40: =AD40*AH40 -> 128000 | AR40: □ | FJ40: 見積仕様書=提出用 見積計算書と認識しています。
D41: 6 | F41: ☑ | H41: 12345680-02 | M41: 2022/07/01 | R41: ○○○○○ | X41: 仕切り | AD41: 2000 | AH41: 62 | AL41: 個 | AN41: =AD41*AH41 -> 124000 | AR41: □
D42: 7 | F42: □ | H42: 12345678-03 | M42: 2022/07/01 | R42: ○○○○○ | X42: 身 | AD42: 3000 | AH42: 71 | AL42: 個 | AN42: =AD42*AH42 -> 213000 | CU42: CP指摘 2022/09/27 木﨑 御見積書明細にも見積計算書Noがあった方がよいかと思います。見積計算書№を複数選択して品名１と２が重複した場合に元がどの見積計算書Noか分かり難いため。(あくまで入力補助的な視点)
D43: 8 | F43: □ | H43: 12345679-03 | M43: 2022/07/01 | R43: ○○○○○ | X43: 蓋 | AD43: 3000 | AH43: 64 | AL43: 個 | AN43: =AD43*AH43 -> 192000
CV44: → 2022/10/02 落合 別枠として表示する。 №の左側に初期セット時の見積№を表示する。
D45: 御見積書明細 | CV45: 明細編集の影響は無視する
D47: 見積計算書NO | I47: № | K47: 品名1 | W47: 品名2 | AI47: 数量 | AM47: 単価 | AQ47: 単位 | AS47: 金額 | CV47: MDSOL 野村 2022/10/31 見積計算書Noレイアウト・項目追加しています。
D48: 12345678-02 | I48: 1 | K48: ○○○○○ | W48: 身 | AI48: 2000 | AM48: 71 | AQ48: 個 | AS48: =AI48*AM48 -> 142000
D49: 12345679-02 | I49: 2 | K49: ○○○○○ | W49: 蓋 | AI49: 2000 | AM49: 64 | AQ49: 個 | AS49: =AI49*AM49 -> 128000
D50: 12345680-02 | I50: 3 | K50: ○○○○○ | W50: 仕切り | AI50: 2000 | AM50: 62 | AQ50: 個 | AS50: =AI50*AM50 -> 124000
I51: 4 | AS51: 0
I52: 5 | AS52: 0
I53: 6 | AS53: 0
...

Sheet レイアウト(20220523)
A1: =表紙!A54 -> Webシステム | K1: 文書名 | U1: モジュールID | Z1: =表紙!$AJ$63 -> MS | AE1: モジュール名 | AJ1: =表紙!$AX$63 -> Webシステム | AS1: 文書番号 | AZ1: Version | BF1: Rev.
K2: =表紙!O64 -> アドオン設計書 | U2: ｻﾌﾞﾓｼﾞｭｰﾙID | Z2: =表紙!$AJ$64 -> MSBB | AE2: ｻﾌﾞﾓｼﾞｭｰﾙ名 | AJ2: =表紙!$AX$64 -> 販売Webシステム | AS2: =表紙!$BL$64 -> M7-US-1140 | AZ2: =表紙!$BU$64 -> 7.0.2 | BF2: =表紙!$CB$64 -> 3
K3: =RIGHT(CELL("filename",$A$1),LEN(CELL("filename",$A$1))-FIND("]",CELL("filename",$A$1))) -> レイアウト(20220523) | U3: 表題 | Z3: =表紙!$AJ$65 -> MSBBPA030 | AE3: =表紙!$AQ$65 -> Web御見積書登録
A5: 画面イメージ
B7: ≫凡例 | AG7: 全体画面構成
Q8: ・・・ | S8: ボタン | AG8: ボタン | AP8: … | AQ8: ボタン処理
C9: 見積計算書№ | Q9: ・・・ | S9: 検索項目(検索画面表示選択) | AG9: 操作種別
C10: 品名 | Q10: ・・・ | S10: 入力項目 | AG10: 案件NO選択
C11: 得意先 | Q11: ・・・ | S11: 表示項目(得意先名称、原紙名等)
C12: 操作種別 | I12: ●登録 | M12: ○訂正 | Q12: ・・・ | S12: 選択項目(一つのみ選択可能) | AG12: 見積計算書一覧
C13: 受注区分 | Q13: ・・・ | S13: 選択項目(一つのみ選択可能)
C14: 作業順 | I14: ☑AAA | M14: ☑BBB | Q14: ・・・ | S14: 選択項目(複数選択可能) | AG14: 御見積書明細入力 | AP14: … | AQ14: 御見積書の明細部分に該当
C16: １ページ目
D21: 操作種別 | J21: ●登録 | N21: ○訂正 | R21: ○削除 | V21: ○参照
D23: 御見積書№ | J23: 自動採番 | AD23: 参考御見積書№ | AJ23: 1234567890
D25: 案件№ | J25: (案件名:オートフィルタ)
D26: 得意先
D29: 御見積書ヘッダー
D31: 拠点
D32: 担当者
D34: 納入場所 | X34: お支払条件
D35: 納入期限 | X35: 見積有効期限
D36: 別途運賃
D38: 見積計算書一覧
D40: № | F40: 使用 | H40: 見積計算書№ | L40: 見積作成日 | P40: 製品区分 | T40: 品名 | Z40: 見積り数 | AD40: 見積平米 | AH40: ㎡単価 | AL40: 金額
D41: 1 | F41: □ | H41: 12345-001 | P41: 加工 | T41: ○○身 | Z41: 1000 | AH41: 72 | AL41: =Z41*AH41 -> 72000
D42: 2 | F42: □ | H42: 12345-002 | T42: ○○蓋 | Z42: 1000 | AH42: 65 | AL42: =Z42*AH42 -> 65000
D43: 3 | F43: □ | H43: 12345-003 | T43: ○○仕切り | Z43: 1000 | AH43: 63 | AL43: =Z43*AH43 -> 63000
D44: 4 | F44: ☑ | H44: 12345-004 | T44: ○○身 | Z44: 2000 | AH44: 71 | AL44: =Z44*AH44 -> 142000
D45: 5 | F45: ☑ | H45: 12345-005 | T45: ○○蓋 | Z45: 2000 | AH45: 64 | AL45: =Z45*AH45 -> 128000
D46: 6 | F46: ☑ | H46: 12345-006 | T46: ○○仕切り | Z46: 2000 | AH46: 62 | AL46: =Z46*AH46 -> 124000
D47: 7 | F47: □ | H47: 12345-007 | T47: ○○身 | Z47: 3000 | AH47: 71 | AL47: =Z47*AH47 -> 213000
D48: 8 | F48: □ | H48: 12345-008 | T48: ○○蓋 | Z48: 3000 | AH48: 64 | AL48: =Z48*AH48 -> 192000
D50: 御見積書明細
D52: № | F52: 見積計算書№ | J52: 品名1 | V52: 品名2 | AH52: 数量 | AL52: 単価 | AP52: 金額 | AT52: 行追加 | AV52: 行削除
D53: 1 | F53: 12345-004 | J53: ○○身 | V53: 品名2 | AH53: 2000 | AL53: 71 | AP53: =AH53*AL53 -> 142000
D54: 2 | F54: 12345-005 | J54: ○○蓋 | V54: 品名2 | AH54: 2000 | AL54: 64 | AP54: =AH54*AL54 -> 128000
D55: 3 | F55: 12345-006 | J55: ○○仕切り | V55: 品名2 | AH55: 2000 | AL55: 62 | AP55: =AH55*AL55 -> 124000
D56: 4 | J56: 紐 | AH56: 1 | AL56: 200 | AP56: =AH56*AL56 -> 200
D57: 5 | J57: その他 | AH57: 1 | AL57: 1200 | AP57: =AH57*AL57 -> 1200
...

Sheet レイアウト旧
A1: =表紙!A54 -> Webシステム | K1: 文書名 | U1: モジュールID | Z1: =表紙!$AJ$63 -> MS | AE1: モジュール名 | AJ1: =表紙!$AX$63 -> Webシステム | AS1: 文書番号 | AZ1: Version | BF1: Rev.
K2: =表紙!O64 -> アドオン設計書 | U2: ｻﾌﾞﾓｼﾞｭｰﾙID | Z2: =表紙!$AJ$64 -> MSBB | AE2: ｻﾌﾞﾓｼﾞｭｰﾙ名 | AJ2: =表紙!$AX$64 -> 販売Webシステム | AS2: =表紙!$BL$64 -> M7-US-1140 | AZ2: =表紙!$BU$64 -> 7.0.2 | BF2: =表紙!$CB$64 -> 3
K3: =RIGHT(CELL("filename",$A$1),LEN(CELL("filename",$A$1))-FIND("]",CELL("filename",$A$1))) -> レイアウト旧 | U3: 表題 | Z3: =表紙!$AJ$65 -> MSBBPA030 | AE3: =表紙!$AQ$65 -> Web御見積書登録
A5: 画面イメージ
B7: ≫凡例 | AG7: 全体画面構成
Q8: ・・・ | S8: ボタン | AG8: ボタン | AP8: … | AQ8: ボタン処理
C9: 見積計算書№ | Q9: ・・・ | S9: 検索項目(検索画面表示選択) | AG9: 操作種別
C10: 品名 | Q10: ・・・ | S10: 入力項目 | AG10: 案件NO選択
C11: 得意先 | Q11: ・・・ | S11: 表示項目(得意先名称、原紙名等)
C12: 操作種別 | I12: ●登録 | M12: ○訂正 | Q12: ・・・ | S12: 選択項目(一つのみ選択可能) | AG12: 見積計算書一覧
C13: 受注区分 | Q13: ・・・ | S13: 選択項目(一つのみ選択可能)
C14: 作業順 | I14: ☑AAA | M14: ☑BBB | Q14: ・・・ | S14: 選択項目(複数選択可能) | AG14: 御見積書明細入力 | AP14: … | AQ14: 御見積書の明細部分に該当
C16: １ページ目
D21: 操作種別 | J21: ●登録 | N21: ○訂正 | R21: ○削除 | V21: ○参照
D23: 御見積書№ | J23: 自動採番 | AD23: 参考御見積書№ | AJ23: 1234567890
D25: 案件№ | J25: (案件名:オートフィルタ)
D26: 得意先
D31: 御見積書ヘッダー
D33: 拠点
D34: 担当者
D36: 納入場所 | X36: お支払条件
D37: 納入期限 | X37: 見積有効期限
D38: 別途運賃
D41: 見積計算書一覧
D43: № | F43: 使用 | H43: 明細反映 | J43: 見積計算書№ | O43: 見積作成日 | S43: 製品区分 | W43: 品名 | AC43: 見積り数 | AG43: 見積平米 | AK43: ㎡単価 | AO43: 金額
D44: 1 | F44: □ | S44: 加工 | W44: ○○身 | AC44: 1000 | AK44: 72 | AO44: =AC44*AK44 -> 72000
D45: 2 | F45: □ | W45: ○○蓋 | AC45: 1000 | AK45: 65 | AO45: =AC45*AK45 -> 65000
D46: 3 | F46: □ | W46: ○○仕切り | AC46: 1000 | AK46: 63 | AO46: =AC46*AK46 -> 63000
D47: 4 | F47: ☑ | W47: ○○身 | AC47: 2000 | AK47: 71 | AO47: =AC47*AK47 -> 142000
D48: 5 | F48: ☑ | W48: ○○蓋 | AC48: 2000 | AK48: 64 | AO48: =AC48*AK48 -> 128000
D49: 6 | F49: ☑ | W49: ○○仕切り | AC49: 2000 | AK49: 62 | AO49: =AC49*AK49 -> 124000
D50: 7 | F50: □ | W50: ○○身 | AC50: 3000 | AK50: 71 | AO50: =AC50*AK50 -> 213000
D51: 8 | F51: □ | W51: ○○蓋 | AC51: 3000 | AK51: 64 | AO51: =AC51*AK51 -> 192000
D54: 御見積書明細
D56: № | F56: 品名1 | R56: 品名2 | AD56: 数量 | AH56: 単価 | AL56: 金額 | AP56: 行追加 | AR56: 行削除
D57: 1 | AL57: 0
D59: 合計 | AL59: =SUM(AL57) -> 0

Sheet 現行画面
A1: =表紙!A54 -> Webシステム | K1: 文書名 | U1: モジュールID | Z1: =表紙!$AJ$63 -> MS | AE1: モジュール名 | AJ1: =表紙!$AX$63 -> Webシステム | AS1: 文書番号 | AY1: Version | BE1: Rev.
K2: =表紙!O64 -> アドオン設計書 | U2: ｻﾌﾞﾓｼﾞｭｰﾙID | Z2: =表紙!$AJ$64 -> MSBB | AE2: ｻﾌﾞﾓｼﾞｭｰﾙ名 | AJ2: =表紙!$AX$64 -> 販売Webシステム | AS2: =表紙!$BL$64 -> M7-US-1140 | AY2: =表紙!$BU$64 -> 7.0.2 | BE2: =表紙!$CB$64 -> 3
K3: =RIGHT(CELL("filename",$A$1),LEN(CELL("filename",$A$1))-FIND("]",CELL("filename",$A$1))) -> 現行画面 | U3: 表題 | Z3: =表紙!$AJ$65 -> MSBBPA030 | AE3: =表紙!$AQ$65 -> Web御見積書登録
A5: 画面イメージ

Sheet 処理イメージ
A1: =表紙!A54 -> Webシステム | K1: 文書名 | U1: モジュールID | Z1: =表紙!$AJ$63 -> MS | AE1: モジュール名 | AJ1: =表紙!$AX$63 -> Webシステム | AS1: 文書番号 | AZ1: Version | BF1: Rev.
K2: =表紙!O64 -> アドオン設計書 | U2: ｻﾌﾞﾓｼﾞｭｰﾙID | Z2: =表紙!$AJ$64 -> MSBB | AE2: ｻﾌﾞﾓｼﾞｭｰﾙ名 | AJ2: =表紙!$AX$64 -> 販売Webシステム | AS2: =表紙!$BL$64 -> M7-US-1140 | AZ2: =表紙!$BU$64 -> 7.0.2 | BF2: =表紙!$CB$64 -> 3
K3: =RIGHT(CELL("filename",$A$1),LEN(CELL("filename",$A$1))-FIND("]",CELL("filename",$A$1))) -> 処理イメージ | U3: 表題 | Z3: =表紙!$AJ$65 -> MSBBPA030 | AE3: =表紙!$AQ$65 -> Web御見積書登録
A5: 画面イメージ
B7: ≫凡例 | AG7: 全体画面構成
Q8: ・・・ | S8: ボタン | AG8: ボタン | AP8: … | AQ8: ボタン処理
C9: 見積計算書№ | Q9: ・・・ | S9: 検索項目(検索画面表示選択) | AG9: 操作種別
C10: 品名 | Q10: ・・・ | S10: 入力項目 | AG10: 案件NO選択
C11: 得意先 | Q11: ・・・ | S11: 表示項目(得意先名称、原紙名等)
C12: 操作種別 | I12: ●登録 | M12: ○訂正 | Q12: ・・・ | S12: 選択項目(一つのみ選択可能) | AG12: 見積計算書一覧
C13: 受注区分 | Q13: ・・・ | S13: 選択項目(一つのみ選択可能)
C14: 作業順 | I14: ☑AAA | M14: ☑BBB | Q14: ・・・ | S14: 選択項目(複数選択可能) | AG14: 御見積書明細入力 | AP14: … | AQ14: 御見積書の明細部分に該当
D21: 操作種別 | J21: ●登録 | N21: ○訂正 | R21: ○削除 | V21: ○参照
D23: 御見積書№
D25: 案件№
D26: 得意先
D31: ≫見積計算書一覧
D32: № | F32: 明細反映 | H32: 見積計算書№ | M32: 見積作成日 | Q32: 製品区分 | U32: 品名 | AA32: 見積り数 | AE32: 見積平米 | AI32: ㎡単価 | AM32: 金額
D33: 1 | Q33: 加工 | U33: ○○身 | AA33: 1000 | AI33: 72 | AM33: =AA33*AI33 -> 72000
D34: 2 | U34: ○○蓋 | AA34: 1000 | AI34: 65 | AM34: =AA34*AI34 -> 65000
D35: 3 | U35: ○○仕切り | AA35: 1000 | AI35: 63 | AM35: =AA35*AI35 -> 63000
D36: 4 | U36: ○○身 | AA36: 2000 | AI36: 71 | AM36: =AA36*AI36 -> 142000
D37: 5 | U37: ○○蓋 | AA37: 2000 | AI37: 64 | AM37: =AA37*AI37 -> 128000
D38: 6 | U38: ○○仕切り | AA38: 2000 | AI38: 62 | AM38: =AA38*AI38 -> 124000
D39: 7 | U39: ○○身 | AA39: 3000 | AI39: 71 | AM39: =AA39*AI39 -> 213000
D40: 8 | U40: ○○蓋 | AA40: 3000 | AI40: 64 | AM40: =AA40*AI40 -> 192000
D43: ≫御見積書ヘッダー
D44: 納入場所 | X44: お支払条件
D45: 納入期限 | X45: 見積有効期限
D46: 別途運賃
D49: ≫御見積書明細(初期)
D50: № | F50: 品名 | R50: 数量 | V50: 単価 | Z50: 金額 | AD50: 行追加 | AF50: 行削除
D51: 1 | Z51: 0
D53: 合計 | Z53: =SUM(Z51) -> 0
D57: ≫御見積書明細(明細反映クリック後)
D58: № | F58: 品名 | R58: 数量 | V58: 単価 | Z58: 金額 | AD58: 行追加 | AF58: 行削除
D59: 1 | F59: ○○身 | R59: 2000 | V59: 71 | Z59: =R59*V59 -> 142000
D60: 2 | F60: ○○蓋 | R60: 2000 | V60: 64 | Z60: =R60*V60 -> 128000
D61: 3 | F61: ○○仕切り | R61: 2000 | V61: 62 | Z61: =R61*V61 -> 124000
D63: 合計 | Z63: =SUM(Z59:AC61) -> 394000
...

Sheet 項目説明
A1: =表紙!A54 -> Webシステム | K1: 文書名 | U1: モジュールID | Z1: =表紙!$AJ$63 -> MS | AE1: モジュール名 | AJ1: =表紙!$AX$63 -> Webシステム | AS1: 文書番号 | AZ1: Version | BF1: Rev.
K2: =表紙!O64 -> アドオン設計書 | U2: ｻﾌﾞﾓｼﾞｭｰﾙID | Z2: =表紙!$AJ$64 -> MSBB | AE2: ｻﾌﾞﾓｼﾞｭｰﾙ名 | AJ2: =表紙!$AX$64 -> 販売Webシステム | AS2: =表紙!$BL$64 -> M7-US-1140 | AZ2: =表紙!$BU$64 -> 7.0.2 | BF2: =表紙!$CB$64 -> 3
K3: =RIGHT(CELL("filename",$A$1),LEN(CELL("filename",$A$1))-FIND("]",CELL("filename",$A$1))) -> 項目説明 | U3: 表題 | Z3: =表紙!$AJ$65 -> MSBBPA030 | AE3: =表紙!$AQ$65 -> Web御見積書登録
B5: 操作種別 | N5: 説明 | BE5: Ｗ | BF5: 型 | BG5: 参 | BH5: 必 | BI5: 入 | BJ5: 非 | BK5: 検
A6: ● | B6: 登録 | M6: 【MSBBPA000】_共通設計書_アドオン(Webシステム共通仕様)にて定義 | BE6: R
A7: ● | B7: 訂正 | M7: 【MSBBPA000】_共通設計書_アドオン(Webシステム共通仕様)にて定義 | BE7: R
A8: ● | B8: 削除 | M8: 【MSBBPA000】_共通設計書_アドオン(Webシステム共通仕様)にて定義 | BE8: R
A9: ● | B9: 参照 | M9: 【MSBBPA000】_共通設計書_アドオン(Webシステム共通仕様)にて定義 | BE9: R
A10: ● | B10: コピー | M10: 【MSBBPA000】_共通設計書_アドオン(Webシステム共通仕様)にて定義 | BE10: R
A11: ● | B11: 確定 | M11: 御見積書を確定登録する場合に使用する | BE11: R
A12: ● | B12: 確定取消 | M12: 御見積書を確定取消する場合に使用する | BE12: R
B14: 検索項目 | N14: 説明 | BE14: Ｗ | BF14: 型 | BG14: 参 | BH14: 必 | BI14: 入 | BJ14: 非 | BK14: 検
A15: 〇 | B15: 御見積書NO | M15: 【MSBBPACOM】_共通設計書_アドオン(共通ロジック)にて定義 | BE15: A | BF15: S | BK15: 検
B17: 項目 | N17: 説明 | BE17: Ｗ | BF17: 型 | BG17: 参 | BH17: 必 | BI17: 入 | BJ17: 非 | BK17: 検
B18: 御見積書NO | M18: 御見積書を特定する番号 自動採番 | BE18: T | BF18: S
A19: ● | B19: 見積確認ステータス | M19: 見積確認WFのステータスを表示(0:未承認、9:承認済) | AQ19: 移行時を想定し変更可能とする | BE19: C | BF19: S | BG19: 参
B20: マスタ確定ステータス | M20: 見積確定(マスタ確定)WFのステータスを表示(0:未承認、1:承認処理中、9:承認済) | BE20: T | BF20: S
A21: ● | B21: 拠点 | M21: 事業所の拠点コードを登録する項目※【MSBBPACOM】_共通設計書_アドオン(共通ロジック)にて定義 | BE21: C | BF21: S | BH21: 必
B22: 拠点名 | M22: 拠点コードに対する拠点名を表示する | BE22: T | BF22: S
A23: ● | B23: 担当者 | M23: 御見積の担当者を登録する項目※【MSBBPACOM】_共通設計書_アドオン(共通ロジック)にて定義 | BE23: C | BF23: S | BH23: 必
B24: 担当者名 | M24: 担当者の名称を表示する | BE24: T | BF24: S
B26: 見積情報 | N26: 説明 | BE26: Ｗ | BF26: 型 | BG26: 参 | BH26: 必 | BI26: 入 | BJ26: 非 | BK26: 検
A27: ● | B27: 得意先 | M27: 得意先コードを登録する項目※【MSBBPACOM】_共通設計書_アドオン(共通ロジック)にて定義 | BE27: A | BF27: S | BG27: 参 | BH27: 必 | BK27: 検
A28: ● | B28: 得意先名 | M28: 得意先コードに対する得意先名称を表示する | BE28: T | BF28: S
A29: ● | B29: 案件NO | M29: 【MSBBPACOM】_共通設計書_アドオン(共通ロジック)にて定義 | BE29: A | BF29: S | BG29: 参 | BH29: 必 | BK29: 検
B30: 案件名 | M30: 【MSBBPACOM】_共通設計書_アドオン(共通ロジック)にて定義 | BE30: T | BF30: S
B32: 見積計算書一覧 | N32: 説明 | BE32: Ｗ | BF32: 型 | BG32: 参 | BH32: 必 | BI32: 入 | BJ32: 非 | BK32: 検
B33: № | M33: 行番 | BE33: T | BF33: N
A34: ● | B34: 使用 | M34: 御見積書に採用する見積計算書NOのデータを選択する | BE34: チ | BF34: F
B35: 見積計算書NO | M35: 見積計算書NOが表示される | BE35: T | BF35: S
B36: 見積作成日 | M36: 見積作成日が表示される | BE36: T | BF36: S
B37: 品名1 | M37: 品名1が表示される | BE37: T | BF37: S
B38: 品名2 | M38: 品名2が表示される | BE38: T | BF38: S
B39: 見積数 | M39: 見積数が表示される | BE39: T | BF39: N
B40: 単価 | M40: 単価が表示される | BE40: T | BF40: N
B41: 単位 | M41: 単位が表示される | BE41: T | BF41: S
B42: 金額 | M42: 金額が表示される | BE42: T | BF42: N
A43: ● | B43: 確定 | M43: 操作種別：●確定／●確定取消時に使用可能 | AS43: 初期値☑無 | BE43: チ | BF43: F
B45: 御見積書明細 | N45: 説明 | P45: →御見積書に印字される内容となる | BE45: Ｗ | BF45: 型 | BG45: 参 | BH45: 必 | BI45: 入 | BJ45: 非 | BK45: 検
B46: 見積計算書NO | M46: 見積計算書一覧で選択した見積計算書NOがセットされる | BE46: T | BF46: S
...

Sheet 引数説明
A1: =表紙!A54 -> Webシステム | K1: 文書名 | U1: モジュールID | Z1: =表紙!$AJ$63 -> MS | AE1: モジュール名 | AJ1: =表紙!$AX$63 -> Webシステム | AS1: 文書番号 | AZ1: Version | BF1: Rev.
K2: =表紙!O64 -> アドオン設計書 | U2: ｻﾌﾞﾓｼﾞｭｰﾙID | Z2: =表紙!$AJ$64 -> MSBB | AE2: ｻﾌﾞﾓｼﾞｭｰﾙ名 | AJ2: =表紙!$AX$64 -> 販売Webシステム | AS2: =表紙!$BL$64 -> M7-US-1140 | AZ2: =表紙!$BU$64 -> 7.0.2 | BF2: =表紙!$CB$64 -> 3
K3: =RIGHT(CELL("filename",$A$1),LEN(CELL("filename",$A$1))-FIND("]",CELL("filename",$A$1))) -> 引数説明 | U3: 表題 | Z3: =表紙!$AJ$65 -> MSBBPA030 | AE3: =表紙!$AQ$65 -> Web御見積書登録
B5: オペレーションＩＤ/名称：SloRecvIfImp_Upd01/取込
A6: 必 | B6: 項目名 | N6: 説明 | AS6: 未設定時の振る舞い
B7: 得意先ＣＤ | M7: 受注受信ＩＦの検索条件

Sheet 処理概要
A1: =表紙!A54 -> Webシステム | K1: 文書名 | U1: モジュールID | Z1: =表紙!$AJ$63 -> MS | AE1: モジュール名 | AJ1: =表紙!$AX$63 -> Webシステム | AS1: 文書番号 | AZ1: Version | BF1: Rev.
K2: =表紙!O64 -> アドオン設計書 | U2: ｻﾌﾞﾓｼﾞｭｰﾙID | Z2: =表紙!$AJ$64 -> MSBB | AE2: ｻﾌﾞﾓｼﾞｭｰﾙ名 | AJ2: =表紙!$AX$64 -> 販売Webシステム | AS2: =表紙!$BL$64 -> M7-US-1140 | AZ2: =表紙!$BU$64 -> 7.0.2 | BF2: =表紙!$CB$64 -> 3
K3: =RIGHT(CELL("filename",$A$1),LEN(CELL("filename",$A$1))-FIND("]",CELL("filename",$A$1))) -> 処理概要 | U3: 表題 | Z3: =表紙!$AJ$65 -> MSBBPA030 | AE3: =表紙!$AQ$65 -> Web御見積書登録
A5: No | B5: 入力 | J5: 処理 | BD5: 出力
A6: 1 | B6: 初期表示
J7: １．初期処理
K8: 種別：新規の際、ログイン者の拠点、と担当者CDを初期設定する
L10: 御見積書明細の初期表示
M11: 初期表示行をweb.config定義(MSBBPA030_Details2_Init_Row)より取得し、初期表示行をセットする
M12: 例：web.config定義(MSBBPA030_Details2_Init_Row) = 8 の場合、8行初期行をセットする
L14: 御見積書ヘッダーの初期表示:web.config定義より、初期値を取得しセットする
M15: 納入場所 | S15: … | U15: web.config定義(MSBBPA030_Init_納入場所)
M16: 納入期限 | S16: … | U16: web.config定義(MSBBPA030_Init_納入期限)
M17: 別途運賃 | S17: … | U17: web.config定義(MSBBPA030_Init_見積有効期限)
M18: 見積有効期限 | S18: … | U18: web.config定義(MSBBPA030_Init_別途運賃)
L20: 御見積書フッターの初期表示:汎用マスタ(M064)より、初期値を取得しセットする
M21: 初期FLG=1のデータを初期表示順にセットする
L23: 見積計算書(提出用)フッターの初期表示:汎用マスタ(M065)より、初期値を取得しセットする
M24: 初期FLG=1のデータを初期表示順にセットする
A26: 2 | B26: 案件NO設定後処理
J27: １．案件NO設定後処理
K28: 指定した案件NOを元に見積計算書一覧のデータを取得する。
K29: 検索入出力仕様．検索２参照 | BD29: 検索入出力仕様.検索２
A31: 3 | B31: 御見積書NO検索処理
J32: １．御見積書検索処理
K33: 検索条件：御見積書NOを指定したら以下の検索処理を実行する。
K34: チェック処理 | BM34: MDSOL 野村 2022/10/25 チェックロジック追加します。 | CE34: 2022/10/27 落合 問題なし
L35: 操作種別：訂正、削除かつ確定済みの御見積書NOデータを選択した場合、エラーとする(後続処理をキャンセルする)
M36: エラーメッセージ：確定登録済のデータとなります。編集する場合は、確定取消を実施ください。 | BD36: メッセージID.004
K38: １）項目・ヘッダ検索
L39: 御見積書NOを条件に項目・見積情報・ヘッダ・フッタのデータを取得する。
L40: 検索入出力仕様.検索１参照 | BD40: 検索入出力仕様.検索1
K41: ２）見積計算一覧検索
L42: 案件NOを条件に見積計算書のデータを取得する。
L43: 検索入出力仕様.検索2参照 | BD43: 検索入出力仕様.検索2
K44: 御見積書NOを条件に御見積書見積計算書のデータを取得する。
L45: 検索入出力仕様.検索３参照 | BD45: 検索入出力仕様.検索3
L46: 取得した御見積書見積計算書のデータと見積計算書のデータをマッチングさせ
L47: 使用フラグ、完了フラグを設定する。
K48: ３）御見積書明細検索
...

Sheet 処理詳細
A1: =表紙!A54 -> Webシステム | K1: 文書名 | U1: モジュールID | Z1: =表紙!$AJ$63 -> MS | AE1: モジュール名 | AJ1: =表紙!$AX$63 -> Webシステム | AS1: 文書番号 | AZ1: Version | BF1: Rev.
K2: =表紙!O64 -> アドオン設計書 | U2: ｻﾌﾞﾓｼﾞｭｰﾙID | Z2: =表紙!$AJ$64 -> MSBB | AE2: ｻﾌﾞﾓｼﾞｭｰﾙ名 | AJ2: =表紙!$AX$64 -> 販売Webシステム | AS2: =表紙!$BL$64 -> M7-US-1140 | AZ2: =表紙!$BU$64 -> 7.0.2 | BF2: =表紙!$CB$64 -> 3
K3: =RIGHT(CELL("filename",$A$1),LEN(CELL("filename",$A$1))-FIND("]",CELL("filename",$A$1))) -> 処理詳細 | U3: 表題 | Z3: =表紙!$AJ$65 -> MSBBPA030 | AE3: =表紙!$AQ$65 -> Web御見積書登録
A5: No | B5: 入力 | J5: 処理 | BD5: 出力
A6: 1 | B6: 初期表示 | J6: 新規表示時のページ生成
J7: １． | K7: 操作種別
T8: 操作種別 | X8: 状態
K9: ・ | T9: 登録 | X9: オン
T10: 訂正 | X10: 以下はオフに設定する
T11: 削除
T12: コピー
T13: 確定
T14: 確定取消
J16: 2. | K16: 検索条件
L17: ・ | M17: 御見積書No： | S17: コンボボックスデータをセットする。
T18: 下記の条件でリストデータを検索し、リストボックスを生成する。
T19: テーブル名 | Z19: 項目名 | AF19: 検索条件等
T20: WEB御見積書 | Z20: 御見積書ＮＯ | AF20: なし
L21: ・ | M21: 御見積書No検索： | S21: 検索ボタン（虫眼鏡）を常に押下可能状態にする。
J23: ３． | K23: ヘッダ項目
L24: ・ | M24: 御見積書No： | S24: ブランク表示
L25: ・ | M25: 拠点： | S25: ログインユーザの所属拠点を表示する。
S26: ログインユーザの管理者区分＝0の場合、変更不可に設定する。
S27: コンボボックスデータをセットする。
T28: 下記の条件でリストデータを検索し、リストボックスを生成する。
T29: テーブル名 | Z29: 項目名 | AH29: 検索条件等
T30: 汎用マスタ | Z30: キー１ | AC30: ／ | AD30: 拠点ＣＤ | AH30: 汎用分類ＣＤ＝M044
Z31: 文字列１ | AC31: ／ | AD31: 拠点名称
L33: ・ | M33: 担当者： | S33: ログインユーザの担当者CD、名前を表示する。
S34: コンボボックスデータをセットする。
T35: 下記の条件でリストデータを検索し、リストボックスを生成する。
T36: テーブル名 | Z36: 項目名 | AH36: 検索条件等
T37: ログイン | Z37: 担当者CD | AH37: ログイン.ユーザID＝HT2_EMPLOYEE.ユーザID
T38: HT2_EMPLOYEE | Z38: 名前
L40: ・ | M40: 見積確認ステータス： | T40: ブランク表示
T41: コンボボックスデータをセットする。
T42: テーブル名 | Z42: 項目名 | AH42: 検索条件等
T43: 定数名 | Z43: 値（文字列） | AD43: V_S | AH43: 定数グループＣＤ='MAC_QTN_CNF_STTS'
T44: FCM_CONST_NM | Z44: 定数名 | AD44: C_NAME
L45: ・ | M45: マスタ確定ステータス： | T45: ブランク表示
...

Sheet ステータス管理補足
A1: =表紙!A54 -> Webシステム | O1: 文書名 | AC1: モジュールID | AJ1: =表紙!AJ63 -> MS | AQ1: モジュール名 | AX1: =表紙!AX63 -> Webシステム | BL1: 文書番号 | BU1: Version | CB1: Rev.
O2: =表紙!O64 -> アドオン設計書 | AC2: サブモジュールID | AJ2: =表紙!AJ64 -> MSBB | AQ2: サブモジュール名 | AX2: =表紙!AX64 -> 販売Webシステム | BL2: =表紙!BL64 -> M7-US-1140 | BU2: =表紙!BU64 -> 7.0.2 | CB2: =表紙!CB64 -> 3
O3: =RIGHT(CELL("filename",$A$1),LEN(CELL("filename",$A$1))-FIND("]",CELL("filename",$A$1))) -> ステータス管理補足 | AC3: 表題 | AJ3: =表紙!AJ65 -> MSBBPA030 | AQ3: =表紙!AQ65 -> Web御見積書登録
A5: 見積確認ステータス管理補足
K7: 見積確認ステータス
K8: 登録から承認されるまでが、ステータス=未承認 | AD8: 承認済み
A36: 見積確定ステータ(マスタ確定)管理補足
C38: マスタ確定ステータス
C39: 未承認 | K39: 見積確定から承認されるまでが、ステータス=承認処理中 | CI39: 承認済み

Sheet 処理・サービス関連図
A1: =表紙!A54 -> Webシステム | K1: 文書名 | U1: モジュールID | Z1: =表紙!$AJ$63 -> MS | AE1: モジュール名 | AJ1: =表紙!$AX$63 -> Webシステム | AS1: 文書番号 | AZ1: Version | BF1: Rev.
K2: =表紙!O64 -> アドオン設計書 | U2: ｻﾌﾞﾓｼﾞｭｰﾙID | Z2: =表紙!$AJ$64 -> MSBB | AE2: ｻﾌﾞﾓｼﾞｭｰﾙ名 | AJ2: =表紙!$AX$64 -> 販売Webシステム | AS2: =表紙!$BL$64 -> M7-US-1140 | AZ2: =表紙!$BU$64 -> 7.0.2 | BF2: =表紙!$CB$64 -> 3
K3: =RIGHT(CELL("filename",$A$1),LEN(CELL("filename",$A$1))-FIND("]",CELL("filename",$A$1))) -> 処理・サービス関連図 | U3: 表題 | Z3: =表紙!$AJ$65 -> MSBBPA030 | AE3: =表紙!$AQ$65 -> Web御見積書登録
C7: 検索処理
C19: 更新処理

Sheet 検索入出力仕様
A1: =表紙!A54 -> Webシステム | K1: 文書名 | U1: モジュールID | Z1: =表紙!$AJ$63 -> MS | AE1: モジュール名 | AJ1: =表紙!$AX$63 -> Webシステム | AS1: 文書番号 | AZ1: Version | BF1: Rev.
K2: =表紙!O64 -> アドオン設計書 | U2: ｻﾌﾞﾓｼﾞｭｰﾙID | Z2: =表紙!$AJ$64 -> MSBB | AE2: ｻﾌﾞﾓｼﾞｭｰﾙ名 | AJ2: =表紙!$AX$64 -> 販売Webシステム | AS2: =表紙!$BL$64 -> M7-US-1140 | AZ2: =表紙!$BU$64 -> 7.0.2 | BF2: =表紙!$CB$64 -> 3
K3: =RIGHT(CELL("filename",$A$1),LEN(CELL("filename",$A$1))-FIND("]",CELL("filename",$A$1))) -> 検索入出力仕様 | U3: 表題 | Z3: =表紙!$AJ$65 -> MSBBPA030 | AE3: =表紙!$AQ$65 -> Web御見積書登録
A5: No | G5: 1 | S5: ボタン | AH5: 備考
A6: 処理分類 | E6: 検索 | S6: ソート順
A7: No | C7: 転送先 | V7: 転送元 | AQ7: 説明
C8: 種 | D8: オブジェクト | K8: 項目名 | V8: 種 | W8: オブジェクト | AF8: 項目名
A9: 1 | C9: 画 | D9: 項目 | K9: 御見積書NO | V9: T | W9: WEB御見積書 | AF9: 御見積書NO
A10: 2 | C10: 画 | D10: 項目 | K10: 見積確認ステータス | V10: T | W10: WEB御見積書 | AF10: 見積確認ステータス
A11: 3 | C11: 画 | D11: 項目 | K11: マスタ確定ステータス | V11: T | W11: WEB御見積書 | AF11: マスタ確定ステータス
A12: 4 | C12: 画 | D12: 項目 | K12: 拠点 | V12: T | W12: WEB御見積書 | AF12: 拠点CD
A13: 5 | C13: 画 | D13: 項目 | K13: 拠点名 | V13: T | W13: WEB拠点マスタ(汎用マスタ) | AF13: 拠点名
A14: 6 | C14: 画 | D14: 項目 | K14: 担当者 | V14: T | W14: WEB御見積書 | AF14: 担当者CD
A15: 7 | C15: 画 | D15: 項目 | K15: 担当者名 | V15: T | W15: WEB担当者マスタ(ログイン) | AF15: 担当者名
A16: 8 | C16: 画 | D16: 見積情報 | K16: 得意先 | V16: T | W16: WEB御見積書 | AF16: 得意先CD
A17: 9 | C17: 画 | D17: 見積情報 | K17: 得意先名 | V17: T | W17: WEB取引先マスタ | AF17: 得意先名
A18: 10 | C18: 画 | D18: 見積情報 | K18: 案件NO | V18: T | W18: WEB御見積書 | AF18: 案件NO(親)、(子)、(部材) | AQ18: 表示形式：案件NO(親)+ '-' + 案件NO(子)+ '-' + 案件NO(部材) | BN18: Rev2.0 変更
A19: 11 | C19: 画 | D19: 見積情報 | K19: 案件名 | V19: T | W19: WEB見積計算書 | AF19: 案件名
A20: 12 | C20: 画 | D20: 御見積書ヘッダ | K20: 先方担当 | V20: T | W20: WEB御見積書 | AF20: 先方担当
A21: 13 | C21: 画 | D21: 御見積書ヘッダ | K21: 納入場所 | V21: T | W21: WEB御見積書 | AF21: 納入場所
A22: 14 | C22: 画 | D22: 御見積書ヘッダ | K22: 納入期限 | V22: T | W22: WEB御見積書 | AF22: 納入期限
A23: 15 | C23: 画 | D23: 御見積書ヘッダ | K23: 別途運賃 | V23: T | W23: WEB御見積書 | AF23: 配送運賃
A24: 16 | C24: 画 | D24: 御見積書ヘッダ | K24: お支払条件 | V24: T | W24: WEB御見積書 | AF24: お支払条件
A25: 17 | C25: 画 | D25: 御見積書ヘッダ | K25: 見積有効期限 | V25: T | W25: WEB御見積書 | AF25: 見積有効期限
A26: 18 | C26: 画 | D26: 御見積書フッタ | K26: 備考 | V26: T | W26: WEB御見積書 | AF26: 見積書備考01～15
A27: 19 | C27: 画 | D27: 見積計算書(提出用) | K27: 寸法印字 | V27: T | W27: WEB御見積書 | AF27: 寸法印字
A28: 20 | C28: 画 | D28: 見積計算書(提出用) | K28: 備考 | V28: T | W28: WEB御見積書 | AF28: 見積計算書備考01～08
A29: No | G29: 2 | S29: ボタン | AH29: 備考
A30: 処理分類 | E30: 検索 | S30: ソート順
A31: No | C31: 転送先 | V31: 転送元 | AQ31: 説明
C32: 種 | D32: オブジェクト | K32: 項目名 | V32: 種 | W32: オブジェクト | AF32: 項目名
A33: 1 | C33: 画 | D33: 見積計算書一覧 | K33: № | AQ33: 行番号
A34: 2 | C34: 画 | D34: 見積計算書一覧 | K34: 使用 | AQ34: 御見積書見積計算書テーブルに存在するデータにチェックを立てる
A35: 3 | C35: 画 | D35: 見積計算書一覧 | K35: 見積計算書NO | V35: T | W35: WEB見積計算書 | AF35: 見積計算書NO
A36: 4 | C36: 画 | D36: 見積計算書一覧 | K36: 見積作成日 | V36: T | W36: WEB見積計算書 | AF36: 見積作成日
A37: 5 | C37: 画 | D37: 見積計算書一覧 | K37: 品名1 | V37: T | W37: WEB見積計算書 | AF37: 品名1
A38: 6 | C38: 画 | D38: 見積計算書一覧 | K38: 品名2 | V38: T | W38: WEB見積計算書 | AF38: 品名2
A39: 7 | C39: 画 | D39: 見積計算書一覧 | K39: 見積数 | V39: T | W39: WEB見積計算書 | AF39: 見積数
A40: 8 | C40: 画 | D40: 見積計算書一覧 | K40: 単価 | V40: T | W40: WEB見積計算書 | AF40: 単価
A41: 9 | C41: 画 | D41: 見積計算書一覧 | K41: 単位 | V41: T | W41: WEB見積計算書 | AF41: 単位
...

Sheet 更新入出力仕様
A1: =表紙!A54 -> Webシステム | K1: 文書名 | U1: モジュールID | Z1: =表紙!$AJ$63 -> MS | AE1: モジュール名 | AJ1: =表紙!$AX$63 -> Webシステム | AS1: 文書番号 | AZ1: Version | BF1: Rev.
K2: =表紙!O64 -> アドオン設計書 | U2: ｻﾌﾞﾓｼﾞｭｰﾙID | Z2: =表紙!$AJ$64 -> MSBB | AE2: ｻﾌﾞﾓｼﾞｭｰﾙ名 | AJ2: =表紙!$AX$64 -> 販売Webシステム | AS2: =表紙!$BL$64 -> M7-US-1140 | AZ2: =表紙!$BU$64 -> 7.0.2 | BF2: =表紙!$CB$64 -> 3
K3: =RIGHT(CELL("filename",$A$1),LEN(CELL("filename",$A$1))-FIND("]",CELL("filename",$A$1))) -> 更新入出力仕様 | U3: 表題 | Z3: =表紙!$AJ$65 -> MSBBPA030 | AE3: =表紙!$AQ$65 -> Web御見積書登録
A5: No | G5: 1 | S5: ロジック名称 | AH5: 備考 | AK5: 登録・訂正・削除・コピー
A6: 処理分類 | E6: 登録・更新
A7: No | C7: 転送先 | V7: 転送元 | AQ7: 説明
C8: 種 | D8: オブジェクト | K8: 項目名 | V8: 種 | W8: オブジェクト | AF8: 項目名
C9: T | D9: WEB御見積書 | K9: 御見積書NO | V9: 画 | W9: 項目 | AF9: 御見積書NO | AQ9: KEY項目
C10: T | D10: WEB御見積書 | K10: 拠点CD | V10: 画 | W10: 項目 | AF10: 拠点
C11: T | D11: WEB御見積書 | K11: 担当者CD | V11: 画 | W11: 項目 | AF11: 担当者
C12: T | D12: WEB御見積書 | K12: 得意先CD | V12: 画 | W12: 見積情報 | AF12: 得意先
C13: T | D13: WEB御見積書 | K13: 案件NO(親)、(子)、(部材) | V13: 画 | W13: 見積情報 | AF13: 案件NO | AQ13: 案件NO(親)、(子)、(部材)に分割して登録する | BN13: Rev2.0 変更
C14: T | D14: WEB御見積書 | K14: 得意先名 | V14: 画 | W14: 見積情報 | AF14: 得意先名
C15: T | D15: WEB御見積書 | K15: 先方担当 | V15: 画 | W15: 御見積書ヘッダ | AF15: 先方担当
C16: T | D16: WEB御見積書 | K16: 納入場所 | V16: 画 | W16: 御見積書ヘッダ | AF16: 納入場所
C17: T | D17: WEB御見積書 | K17: 納入期限 | V17: 画 | W17: 御見積書ヘッダ | AF17: 納入期限
C18: T | D18: WEB御見積書 | K18: 配送運賃 | V18: 画 | W18: 御見積書ヘッダ | AF18: 別途運賃
C19: T | D19: WEB御見積書 | K19: お支払い条件 | V19: 画 | W19: 御見積書ヘッダ | AF19: お支払条件
C20: T | D20: WEB御見積書 | K20: 見積有効期限 | V20: 画 | W20: 御見積書ヘッダ | AF20: 見積有効期限
C21: T | D21: WEB御見積書 | K21: 構成表示FLG | V21: 画
C22: T | D22: WEB御見積書 | K22: 見積書備考01 | V22: 画 | W22: 御見積書ヘッダ | AF22: 備考(行1)
C23: T | D23: WEB御見積書 | K23: 見積書備考02 | V23: 画 | W23: 御見積書ヘッダ | AF23: 備考(行2)
C24: T | D24: WEB御見積書 | K24: 見積書備考03 | V24: 画 | W24: 御見積書ヘッダ | AF24: 備考(行3)
C25: T | D25: WEB御見積書 | K25: 見積書備考04 | V25: 画 | W25: 御見積書ヘッダ | AF25: 備考(行4)
C26: T | D26: WEB御見積書 | K26: 見積書備考05 | V26: 画 | W26: 御見積書ヘッダ | AF26: 備考(行5)
C27: T | D27: WEB御見積書 | K27: 見積書備考06 | V27: 画 | W27: 御見積書ヘッダ | AF27: 備考(行6)
C28: T | D28: WEB御見積書 | K28: 見積書備考07 | V28: 画 | W28: 御見積書ヘッダ | AF28: 備考(行7)
C29: T | D29: WEB御見積書 | K29: 見積書備考08 | V29: 画 | W29: 御見積書ヘッダ | AF29: 備考(行8)
C30: T | D30: WEB御見積書 | K30: 見積書備考09 | V30: 画 | W30: 御見積書ヘッダ | AF30: 備考(行9)
C31: T | D31: WEB御見積書 | K31: 見積書備考10 | V31: 画 | W31: 御見積書ヘッダ | AF31: 備考(行10)
C32: T | D32: WEB御見積書 | K32: 見積書備考11 | V32: 画 | W32: 御見積書ヘッダ | AF32: 備考(行11)
C33: T | D33: WEB御見積書 | K33: 見積書備考12 | V33: 画 | W33: 御見積書ヘッダ | AF33: 備考(行12)
... C45: T | D45: WEB御見積書 | K45: 見積計算書備考08 | V45: 画 | W45: 見積計算書(提出用) | AF45: 備考(行8)
C46: T | D46: WEB御見積書 | K46: 御見積書発行日 | AQ46: システム自動(年月日) | AY46: ☑御見積書 チェック時更新
C47: T | D47: WEB御見積書 | K47: 見積計算書発行日 | AQ47: システム自動(年月日) | AY47: ☑見積仕様書チェック時更新
C48: T | D48: WEB御見積書 | K48: 合計金額 | V48: 画 | W48: 御見積書 | AF48: 合計金額
C49: T | D49: WEB御見積書 | K49: 合計金額印字 | V49: 画 | W49: 御見積書 | AF49: 合計金額印字
C50: T | D50: WEB御見積書 | K50: 見積確認FLG | V50: 画 | W50: 項目 | AF50: 見積確認ステータス | AQ50: 0:未承認、9:承認済
C51: T | D51: WEB御見積書 | K51: マスタ確定FLG | AQ51: [0]固定 | AY51: ※登録時
A53: No | G53: 2 | S53: ロジック名称 | AH53: 備考 | AK53: 登録・訂正・削除・コピー
...

Sheet ファイル入出力仕様
A1: =表紙!A54 -> Webシステム | K1: 文書名 | U1: モジュールID | Z1: =表紙!$AJ$63 -> MS | AE1: モジュール名 | AJ1: =表紙!$AX$63 -> Webシステム | AS1: 文書番号 | AZ1: Version | BF1: Rev.
K2: =表紙!O64 -> アドオン設計書 | U2: ｻﾌﾞﾓｼﾞｭｰﾙID | Z2: =表紙!$AJ$64 -> MSBB | AE2: ｻﾌﾞﾓｼﾞｭｰﾙ名 | AJ2: =表紙!$AX$64 -> 販売Webシステム | AS2: =表紙!$BL$64 -> M7-US-1140 | AZ2: =表紙!$BU$64 -> 7.0.2 | BF2: =表紙!$CB$64 -> 3
K3: =RIGHT(CELL("filename",$A$1),LEN(CELL("filename",$A$1))-FIND("]",CELL("filename",$A$1))) -> ファイル入出力仕様 | U3: 表題 | Z3: =表紙!$AJ$65 -> MSBBPA030 | AE3: =表紙!$AQ$65 -> Web御見積書登録
A5: No | G5: 1 | S5: ロジック名称 | AH5: 備考
A6: 処理分類 | E6: 更新
A7: No | C7: 転送先 | V7: 転送元 | AQ7: 説明
C8: 種 | D8: オブジェクト | K8: 項目名 | V8: 種 | W8: オブジェクト | AF8: 項目名

Sheet 画面遷移
A1: =表紙!A54 -> Webシステム | K1: 文書名 | U1: モジュールID | Z1: =表紙!$AJ$63 -> MS | AE1: モジュール名 | AJ1: =表紙!$AX$63 -> Webシステム | AS1: 文書番号 | AZ1: Version | BF1: Rev.
K2: =表紙!O64 -> アドオン設計書 | U2: ｻﾌﾞﾓｼﾞｭｰﾙID | Z2: =表紙!$AJ$64 -> MSBB | AE2: ｻﾌﾞﾓｼﾞｭｰﾙ名 | AJ2: =表紙!$AX$64 -> 販売Webシステム | AS2: =表紙!$BL$64 -> M7-US-1140 | AZ2: =表紙!$BU$64 -> 7.0.2 | BF2: =表紙!$CB$64 -> 3
K3: =RIGHT(CELL("filename",$A$1),LEN(CELL("filename",$A$1))-FIND("]",CELL("filename",$A$1))) -> 画面遷移 | U3: 表題 | Z3: =表紙!$AJ$65 -> MSBBPA030 | AE3: =表紙!$AQ$65 -> Web御見積書登録
A5: 画面遷移フロー図
A6: ＩＤ | C6: S01 | E6: Web御見積書登録の画面遷移
C8: なし：Web御見積書登録は、1画面の機能
A11: ＩＤ | C11: S02 | E11: Web御見積書登録から他画面の画面遷移
D13: NO1
D14: Web見積計算書一覧照会(検索モード)
W19: NO4
W20: Web見積計算書入力
K21: Web御見積書登録 | W21: 3ページ目：計算結果画面
W26: NO5
W27: Web見積計算書入力
D28: NO2 | L28: NO3 | W28: 3ページ目：計算結果画面
D29: Web取引先一覧照会 | L29: 簡易検索
A34: ID | D34: 処理名
A35: S02 | D35: Web御見積書登録から他画面の画面遷移
B37: NO | D37: 遷移元ＩＤ | H37: 遷移元画面名 | P37: 遷移先ＩＤ | U37: 遷移先画面名 | AD37: 目的 | AI37: 引継項目 | AR37: 遷移後のアクション(遷移先) | BB37: 戻り値 | BK37: 戻り値取得後のアクション(遷移元) | BU37: 備考
B38: 1 | D38: MSBBPA030 | H38: Web御見積書登録 | P38: MSBBPA040 | U38: Web御見積書一覧照会 | AD38: 検索結果取得 | AR38: 検索 | BB38: 御見積書選択データ(1行) | BK38: 検索入出力仕様.NO1～4
B39: 2 | D39: MSBBPA030 | H39: Web御見積書登録 | P39: MSBBPA120 | U39: Web取引先一覧照会 | AD39: 検索結果取得 | AR39: 検索 | BB39: 取引先選択データ(1行) | BK39: 対象データに値セット | BU39: 得意先CD、得意先名に値セット
B40: 3 | D40: MSBBPA030 | H40: Web御見積書登録 | P40: MSBBPA900 | U40: Web汎用検索(共通検索) | AD40: 検索結果取得 | AR40: 検索 | BB40: 各種検索画面の選択データ(1行) | BK40: 対象データに値セット | BU40: CD、名称に値セット
B41: 4 | D41: MSBBPA030 | H41: Web御見積書登録 | P41: MSBBPA010 | U41: Web見積計算入力(計算結果) | AD41: 決定見積 | AI41: 見積計算書NO | AR41: 検索 | BU41: 操作種別:訂正、データ参照
BU42: 見積区分:決定をセット
B43: 5 | D43: MSBBPA030 | H43: Web御見積書登録 | P43: MSBBPA010 | U43: Web見積計算入力(計算結果) | AD43: 参照 | AI43: 見積計算書NO | AR43: 検索 | BU43: 操作種別:参照、データ参照
B44: 6
B45: 7
B46: 8

Sheet メッセージ一覧
A1: =表紙!A54 -> Webシステム | K1: 文書名 | U1: モジュールID | Z1: =表紙!$AJ$63 -> MS | AE1: モジュール名 | AJ1: =表紙!$AX$63 -> Webシステム | AS1: 文書番号 | AZ1: Version | BF1: Rev.
K2: =表紙!O64 -> アドオン設計書 | U2: ｻﾌﾞﾓｼﾞｭｰﾙID | Z2: =表紙!$AJ$64 -> MSBB | AE2: ｻﾌﾞﾓｼﾞｭｰﾙ名 | AJ2: =表紙!$AX$64 -> 販売Webシステム | AS2: =表紙!$BL$64 -> M7-US-1140 | AZ2: =表紙!$BU$64 -> 7.0.2 | BF2: =表紙!$CB$64 -> 3
K3: =RIGHT(CELL("filename",$A$1),LEN(CELL("filename",$A$1))-FIND("]",CELL("filename",$A$1))) -> メッセージ一覧 | U3: 表題 | Z3: =表紙!$AJ$65 -> MSBBPA030 | AE3: =表紙!$AQ$65 -> Web御見積書登録
C4: ↓アドオン画面のため、基本全て[新]
A5: No | C5: 新/変 | E5: 種別 | G5: メッセージ内容 | AQ5: 備考（パラメータ等） | BG5: メッセージID
A6: 1 | C6: 新 | E6: W | G6: 「必須項目に値が指定されていません。」 | AQ6: 拠点、担当者、得意先、案件NO | BG6: E10022
AQ7: 見積確認ステータス
A8: 2 | C8: 新 | E8: W | G8: 「確定登録するデータが1件もありません。」 | BG8: E10102
A9: 3 | C9: 新 | E9: W | G9: 「決定見積登録されていないデータが含まれます。」 | BG9: E10103
A10: 4 | C10: 新 | E10: W | G10: 「確定登録済のデータとなります。編集する場合は、確定取消を実施ください。」 | BG10: E10104
A11: 5 | C11: 新 | E11: W | G11: 「登録対象の御見積書明細が指定されていません。」 | BG11: E10116
A12: 6 | C12: 新 | E12: W | G12: 「画面をクリアしてよろしいですか？」 | BG12: C00004
A13: 7 | C13: 新 | E13: W | G13: 「確定取消するデータが1件もありません。」 | BG13: E10117 | BL13: 追加
A14: 8 | C14: 新 | E14: W | G14: 「確定登録可能のデータが存在しません。」 | BG14: E10125 | BL14: 追加
A15: 9 | C15: 新 | E15: W | G15: 「確定取消可能のデータが存在しません。」 | BG15: E10126 | BL15: 追加

Sheet テーブル項目_御見積書
A1: =表紙!A54 -> Webシステム | K1: 文書名 | U1: モジュールID | Z1: =表紙!$AJ$63 -> MS | AE1: モジュール名 | AJ1: =表紙!$AX$63 -> Webシステム | AS1: 文書番号 | AZ1: Version | BF1: Rev.
K2: =表紙!O64 -> アドオン設計書 | U2: ｻﾌﾞﾓｼﾞｭｰﾙID | Z2: =表紙!$AJ$64 -> MSBB | AE2: ｻﾌﾞﾓｼﾞｭｰﾙ名 | AJ2: =表紙!$AX$64 -> 販売Webシステム | AS2: =表紙!$BL$64 -> M7-US-1140 | AZ2: =表紙!$BU$64 -> 7.0.2 | BF2: =表紙!$CB$64 -> 3
K3: =RIGHT(CELL("filename",$A$1),LEN(CELL("filename",$A$1))-FIND("]",CELL("filename",$A$1))) -> テーブル項目_御見積書 | U3: 表題 | Z3: =表紙!$AJ$65 -> MSBBPA030 | AE3: =表紙!$AQ$65 -> Web御見積書登録
A5: テーブル名 | O5: 日本語名 | AE5: 種別
O6: WEB御見積書 | AE6: アドオン(新規)
A8: 主キー | D8: 項目名 | O8: 日本語名 | AE8: 型 | AG8: 桁 | AI8: Null | AK8: 説明 | BL8: 値の制限 | BM8: 設定仕様 | BN8: 未設定時の振る舞い | BO8: 御見積書登録
A9: 〇 | O9: 御見積書NO | AE9: C | AI9: N
O10: 拠点コード | AE10: C | AI10: N | BL10: 拠点マスタ
O11: 担当者コード | AE11: C | AI11: N | BL11: 担当者マスタ
O12: 得意先コード | AE12: C | AI12: N | BL12: 得意先マスタ
O13: 得意先名 | AE13: C | AI13: N
O14: 案件NO | AE14: C | AI14: N | BL14: ヒアリングシート
O15: FSC管理NO | AE15: C | AI15: Y | AK15: FSCチェックシート出力画面より更新
O16: FSCチェックシート発行日 | AE16: D | AI16: Y | AK16: FSCチェックシート出力画面より更新
O17: 得意先名 | AE17: C | AI17: Y
O18: 先方担当 | AE18: C | AI18: Y
O19: 納入場所 | AE19: C | AI19: Y
O20: 納入期限 | AE20: C | AI20: Y
O21: 配送運賃 | AE21: C | AI21: Y
O22: お支払い条件 | AE22: C | AI22: Y
O23: 見積有効期限 | AE23: C | AI23: Y
O24: 見積書備考01 | AE24: C | AI24: Y
O25: 見積書備考02 | AE25: C | AI25: Y
O26: 見積書備考03 | AE26: C | AI26: Y
O27: 見積書備考04 | AE27: C | AI27: Y
O28: 見積書備考05 | AE28: C | AI28: Y
... O51: 合計金額印字 | AE51: F | AI51: Y
O52: 見積確認FLG | AE52: N | AI52: N | AK52: 0:未承認、9:承認済
O53: 見積確認日 | AE53: D | AI53: Y
O54: 見積確認ステータス | AE54: N | AI54: N | AK54: 未承認、承認済
O55: マスタ確定FLG | AE55: N | AI55: N | AK55: 0:未承認、1:承認処理中、9:承認済
O56: マスタ確定日 | AE56: D | AI56: Y
O57: マスタ確定ステータス | AE57: N | AI57: N | AK57: 未承認、承認処理中、承認済
D58: MEMO1 | O58: メモ１ | AE58: C | AG58: 100 | AI58: Y
D59: MEMO2 | O59: メモ２ | AE59: C | AG59: 100 | AI59: Y
D60: MEMO3 | O60: メモ３ | AE60: C | AG60: 100 | AI60: Y
D61: DEL_FLG | O61: 論理削除ＦＬＧ | AE61: F | AI61: N | AK61: 論理削除を示すフラグ
D62: DEL_USR_ID | O62: 論理削除ユーザＩＤ | AE62: C | AG62: 500 | AI62: Y
D63: DEL_USR_NM | O63: 論理削除ユーザ名 | AE63: C | AG63: 100 | AI63: Y
D64: DEL_TS | O64: 論理削除日時 | AE64: TS | AG64: 0 | AI64: Y
...

Sheet テーブル項目_御見積書見積計算書
A1: =表紙!A54 -> Webシステム | K1: 文書名 | U1: モジュールID | Z1: =表紙!$AJ$63 -> MS | AE1: モジュール名 | AJ1: =表紙!$AX$63 -> Webシステム | AS1: 文書番号 | AZ1: Version | BF1: Rev.
K2: =表紙!O64 -> アドオン設計書 | U2: ｻﾌﾞﾓｼﾞｭｰﾙID | Z2: =表紙!$AJ$64 -> MSBB | AE2: ｻﾌﾞﾓｼﾞｭｰﾙ名 | AJ2: =表紙!$AX$64 -> 販売Webシステム | AS2: =表紙!$BL$64 -> M7-US-1140 | AZ2: =表紙!$BU$64 -> 7.0.2 | BF2: =表紙!$CB$64 -> 3
K3: =RIGHT(CELL("filename",$A$1),LEN(CELL("filename",$A$1))-FIND("]",CELL("filename",$A$1))) -> テーブル項目_御見積書見積計算書 | U3: 表題 | Z3: =表紙!$AJ$65 -> MSBBPA030 | AE3: =表紙!$AQ$65 -> Web御見積書登録
A5: テーブル名 | O5: 日本語名 | AE5: 種別
O6: WEB御見積書見積計算書 | AE6: アドオン(新規)
A8: 主キー | D8: 項目名 | O8: 日本語名 | AE8: 型 | AG8: 桁 | AI8: Null | AK8: 説明 | BL8: 値の制限 | BM8: 設定仕様 | BN8: 未設定時の振る舞い | BO8: 御見積書登録
A9: 〇 | O9: 御見積書NO | AE9: C | AI9: N
A10: 〇 | O10: 見積計算書NO | AE10: N | AI10: N | AK10: 枝番含む
O11: 見積確認FLG | AE11: N | AI11: N | AK11: 0:未承認、9:承認済
O12: 見積確認日 | AE12: D | AI12: Y
O13: マスタ確定FLG | AE13: N | AI13: N | AK13: 0:未承認、1:承認処理中、9:承認済
O14: マスタ確定日 | AE14: D | AI14: Y
D15: MEMO1 | O15: メモ１ | AE15: C | AG15: 100 | AI15: Y
D16: MEMO2 | O16: メモ２ | AE16: C | AG16: 100 | AI16: Y
D17: MEMO3 | O17: メモ３ | AE17: C | AG17: 100 | AI17: Y
D18: DEL_FLG | O18: 論理削除ＦＬＧ | AE18: F | AI18: N | AK18: 論理削除を示すフラグ
D19: DEL_USR_ID | O19: 論理削除ユーザＩＤ | AE19: C | AG19: 500 | AI19: Y
D20: DEL_USR_NM | O20: 論理削除ユーザ名 | AE20: C | AG20: 100 | AI20: Y
D21: DEL_TS | O21: 論理削除日時 | AE21: TS | AG21: 0 | AI21: Y
D22: INS_USR_ID | O22: 登録ユーザＩＤ | AE22: C | AG22: 500 | AI22: Y
D23: INS_USR_NM | O23: 登録ユーザ名 | AE23: C | AG23: 100 | AI23: Y
D24: INS_TS | O24: 登録日時 | AE24: TS | AG24: 0 | AI24: Y
D25: INS_FUNC_ID | O25: 登録機能ＩＤ | AE25: C | AG25: 50 | AI25: Y
D26: UPD_CNTR | O26: 更新カウンタ | AE26: N | AG26: 9,0 | AI26: Y
D27: UPD_USR_ID | O27: 更新ユーザＩＤ | AE27: C | AG27: 500 | AI27: Y
D28: UPD_USR_NM | O28: 更新ユーザ名 | AE28: C | AG28: 100 | AI28: Y
D29: UPD_TS | O29: 更新日時 | AE29: TS | AG29: 0 | AI29: Y
D30: UPD_FUNC_ID | O30: 更新機能ＩＤ | AE30: C | AG30: 50 | AI30: Y
D31: UPD_SRV_REQ_NO | O31: 更新リクエストＮＯ | AE31: C | AG31: 50 | AI31: Y

Sheet テーブル項目_御見積書明細(印字用)
A1: =表紙!A54 -> Webシステム | K1: 文書名 | U1: モジュールID | Z1: =表紙!$AJ$63 -> MS | AE1: モジュール名 | AJ1: =表紙!$AX$63 -> Webシステム | AS1: 文書番号 | AZ1: Version | BF1: Rev.
K2: =表紙!O64 -> アドオン設計書 | U2: ｻﾌﾞﾓｼﾞｭｰﾙID | Z2: =表紙!$AJ$64 -> MSBB | AE2: ｻﾌﾞﾓｼﾞｭｰﾙ名 | AJ2: =表紙!$AX$64 -> 販売Webシステム | AS2: =表紙!$BL$64 -> M7-US-1140 | AZ2: =表紙!$BU$64 -> 7.0.2 | BF2: =表紙!$CB$64 -> 3
K3: =RIGHT(CELL("filename",$A$1),LEN(CELL("filename",$A$1))-FIND("]",CELL("filename",$A$1))) -> テーブル項目_御見積書明細(印字用) | U3: 表題 | Z3: =表紙!$AJ$65 -> MSBBPA030 | AE3: =表紙!$AQ$65 -> Web御見積書登録
A5: テーブル名 | O5: 日本語名 | AE5: 種別
O6: WEB御見積書明細(印字用) | AE6: アドオン(新規)
A8: 主キー | D8: 項目名 | O8: 日本語名 | AE8: 型 | AG8: 桁 | AI8: Null | AK8: 説明 | BL8: 値の制限 | BM8: 設定仕様 | BN8: 未設定時の振る舞い | BO8: 御見積書登録
A9: 〇 | O9: 御見積書NO | AE9: C | AI9: N
A10: 〇 | O10: 明細NO | AE10: N | AI10: N | AK10: 行番
O11: 見積計算書NO | AE11: C | AI11: N | AK11: 枝番含む
O12: 商品名1 | AE12: N | AI12: Y
O13: 商品名2 | AE13: N | AI13: Y
O14: 数量 | AE14: N | AI14: Y
O15: 単価 | AE15: N | AI15: Y
O16: 単位 | AE16: C | AI16: Y
O17: 金額 | AE17: N | AI17: Y
D18: MEMO1 | O18: メモ１ | AE18: C | AG18: 100 | AI18: Y
D19: MEMO2 | O19: メモ２ | AE19: C | AG19: 100 | AI19: Y
D20: MEMO3 | O20: メモ３ | AE20: C | AG20: 100 | AI20: Y
D21: DEL_FLG | O21: 論理削除ＦＬＧ | AE21: F | AI21: N | AK21: 論理削除を示すフラグ
D22: DEL_USR_ID | O22: 論理削除ユーザＩＤ | AE22: C | AG22: 500 | AI22: Y
D23: DEL_USR_NM | O23: 論理削除ユーザ名 | AE23: C | AG23: 100 | AI23: Y
D24: DEL_TS | O24: 論理削除日時 | AE24: TS | AG24: 0 | AI24: Y
D25: INS_USR_ID | O25: 登録ユーザＩＤ | AE25: C | AG25: 500 | AI25: Y
D26: INS_USR_NM | O26: 登録ユーザ名 | AE26: C | AG26: 100 | AI26: Y
D27: INS_TS | O27: 登録日時 | AE27: TS | AG27: 0 | AI27: Y
D28: INS_FUNC_ID | O28: 登録機能ＩＤ | AE28: C | AG28: 50 | AI28: Y
D29: UPD_CNTR | O29: 更新カウンタ | AE29: N | AG29: 9,0 | AI29: Y
D30: UPD_USR_ID | O30: 更新ユーザＩＤ | AE30: C | AG30: 500 | AI30: Y
D31: UPD_USR_NM | O31: 更新ユーザ名 | AE31: C | AG31: 100 | AI31: Y
D32: UPD_TS | O32: 更新日時 | AE32: TS | AG32: 0 | AI32: Y
D33: UPD_FUNC_ID | O33: 更新機能ＩＤ | AE33: C | AG33: 50 | AI33: Y
D34: UPD_SRV_REQ_NO | O34: 更新リクエストＮＯ | AE34: C | AG34: 50 | AI34: Y

Sheet 補足説明資料
A1: =表紙!A54 -> Webシステム | O1: 文書名 | AC1: モジュールID | AJ1: =表紙!AJ63 -> MS | AQ1: モジュール名 | AX1: =表紙!AX63 -> Webシステム | BL1: 文書番号 | BU1: Version | CB1: Rev.
O2: =表紙!O64 -> アドオン設計書 | AC2: サブモジュールID | AJ2: =表紙!AJ64 -> MSBB | AQ2: サブモジュール名 | AX2: =表紙!AX64 -> 販売Webシステム | BL2: =表紙!BL64 -> M7-US-1140 | BU2: =表紙!BU64 -> 7.0.2 | CB2: =表紙!CB64 -> 3
O3: =RIGHT(CELL("filename",$A$1),LEN(CELL("filename",$A$1))-FIND("]",CELL("filename",$A$1))) -> 補足説明資料 | AC3: 表題 | AJ3: =表紙!AJ65 -> MSBBPA030 | AQ3: =表紙!AQ65 -> Web御見積書登録
AO5: 補足説明
