Workbook
Name Rev.: 表紙!$U$22
Name Ver.: 表紙!$AE$26
Name ご確認者: 表紙!$AG$40
Name ご確認日: 表紙!$AG$42
Name サブシステム名: 表紙!$U$28
Name システム名: 表紙!$U$26
Name プロジェクト名: 表紙!$U$18
Name 開発区分: 表紙!$U$36
Name 機能ＩＤ: 表紙!$U$32
Name 機能区分: 表紙!$U$34
Name 機能名称: 表紙!$U$30
Name 顧客名: 表紙!$U$16
Name 最終更新者: 表紙!$AB$40
Name 最終更新日: 表紙!$AB$42
Name 作成者: 表紙!$W$40
Name 作成日: 表紙!$W$42
Name 章: 表紙!$M$10
Name 文書名: 表紙!$M$10

Sheet 目次
A1: アドオン設計書作成ガイド
C3: ■アドオン設計と成果物について
D4: ・システム設計フェーズとソフトウェア設計フェーズでアドオンの処理仕様を定義する
D5: ・システム設計フェーズとソフトウェア設計フェーズの成果物がアドオン設計書であり、ソフトウェア製作フェーズのインプットとなる
C7: ■各設計フェーズ毎のアドオン設計書作成範囲
D8: ・システム設計フェーズ：他機能との関連を定義するとともに、画面や帳票、ファイル入出力を中心とした外部入出力の設計を行う
D9: ・ソフトウェア設計フェーズ：内部処理を中心とした設計を行う
U11: ◎ | W11: … | X11: システム設計フェーズで作成
U12: ○ | W12: … | X12: システム設計フェーズで基本仕様を定義して、ソフトウェア設計フェーズで詳細化する
U13: △ | W13: … | X13: 必要に応じて（例えば標準仕様から変更がない場合は不要）
U14: ‐ | W14: … | X14: 不要
W15: … | X15: ソフトウェア設計フェーズで作成
D17: 各設計書と作成対象シートのマトリックス | S17: ※カスタマイズ：標準機能に機能を追加する アドオン：新規で機能を開発する
D18: EXCELシート | N18: 画面設計書 | W18: バッチ設計書 | AF18: 帳票設計書 | AO18: ＢＩ設計書 | AT18: .Net設計書 | BB18: EXCELシート | BL18: WebDB設計書 | BR18: 帳票設計書 | BX18: 汎用申請設計書
N19: カスタマイズ | S19: アドオン | W19: カスタマイズ | AB19: アドオン | AF19: カスタマイズ | AK19: アドオン | AO19: アドオン | AT19: アドオン | BL19: アドオン | BR19: アドオン | BX19: アドオン
D20: 概要 | N20: ◎ | O20: ※1 | S20: ◎ | W20: ◎ | X20: ※1 | AB20: ◎ | AF20: ◎ | AG20: ※1 | AK20: ◎ | AO20: ◎ | AT20: ◎ | BB20: 機能概要 | BL20: ◎ | BR20: ◎ | BX20: ◎
D21: レイアウト | N21: ◎ | O21: ※2 | S21: ◎ | W21: ‐ | AB21: ‐ | AF21: ◎ | AG21: ※2 | AK21: ◎ | AO21: ◎ | AT21: ◎ | BB21: アプリケーションフロー | BL21: ◎ | BR21: ー | BX21: ◎
D22: 項目説明 | N22: △ | S22: ○ | W22: ‐ | AB22: ‐ | AF22: △ | AK22: ○ | AO22: ○ | AT22: ○ | BB22: データベース設定 | BL22: ◎ | BR22: ー | BX22: ◎
D23: 引数説明 | N23: ‐ | S23: ‐ | W23: △ | AB23: ◎ | AF23: ‐ | AK23: ‐ | AO23: ‐ | AT23: ◎ | BB23: フィールド設定 | BL23: ◎ | BR23: ー | BX23: ◎
D24: 処理概要 | N24: ◎ | S24: ◎ | W24: ◎ | AB24: ◎ | AF24: ◎ | AK24: ◎ | AO24: ◎ | AT24: ◎ | BB24: 一覧表示画面設定 | BL24: ◎ | BR24: ー | BX24: ◎
D25: 処理詳細 | BB25: 表示編集画面設定 | BL25: ◎ | BR25: ー | BX25: ◎
D26: 処理・サービス関連図 | N26: △ | S26: ◎ | W26: △ | AB26: ◎ | AF26: ‐ | AK26: ‐ | AO26: ‐ | AT26: ◎ | BB26: 明細画面設定 | BL26: △ | BN26: ※3 | BR26: ー | BX26: △ | BZ26: ※3
D27: 検索入出力仕様 | N27: △ | S27: ○ | W27: △ | AB27: ○ | AF27: ‐ | AK27: ‐ | AO27: ‐ | AT27: ○ | BB27: 集計表示設定 | BL27: △ | BN27: ※4 | BR27: ー | BX27: △ | BZ27: ※4
D28: 更新入出力仕様 | N28: △ | S28: ○ | W28: △ | AB28: ○ | AF28: ‐ | AK28: ‐ | AO28: ‐ | AT28: ○ | BB28: 絞り込み条件設定 | BL28: △ | BN28: ※5 | BR28: ー | BX28: △ | BZ28: ※5
D29: ファイル入出力仕様 | N29: △ | S29: △ | W29: ‐ | AB29: ‐ | AF29: ‐ | AK29: ‐ | AO29: ‐ | AT29: △ | BB29: その他設定 | BR29: ー
D30: 画面遷移 | N30: △ | S30: ◎ | W30: ‐ | AB30: ‐ | AF30: ‐ | AK30: ‐ | AO30: ‐ | AT30: ◎ | BB30: 帳票イメージ | BL30: ー | BR30: ◎ | BX30: ー
D31: メッセージ一覧 | N31: △ | S31: △ | W31: △ | AB31: △ | AF31: ‐ | AK31: ‐ | AO31: ‐ | AT31: △ | BB31: 項目設計 | BL31: ー | BR31: ◎ | BX31: ー
D32: 補足説明 | N32: △ | S32: △ | W32: △ | AB32: △ | AF32: △ | AK32: △ | AO32: △ | AT32: △ | BB32: 補足説明 | BL32: △ | BR32: △ | BX32: △
D33: サービス呼出編集仕様 | N33: - | S33: - | W33: - | AB33: - | AF33: - | AK33: - | AO33: - | AT33: - | BB33: 補足説明(詳細)
D35: ※1 | G35: 別シートでカスタマイズ内容を記載する | BB35: ※3 | BE35: 単票画面は記載しない
D36: ※2 | G36: 吹き出しでカスタマイズ内容を記載する | BB36: ※4 | BE36: 集計・グラフ機能を使用する場合に記載する
BB37: ※5 | BE37: 共通設定のみ記載する(個別設定は、記載しない)

Sheet 表紙
AW2: サブモジュール
AW3: MA_マスタ管理
AW4: MB_業務共通
AW5: MG_原価管理
AW6: MSBA_需給管理
M7: 基本設計 | AW7: MSBB_販売管理
AW8: MSBC_生産管理
AW9: MSBD_購買管理
M10: アドオン設計書 | AW10: MSBE_在庫物流管理
AW11: MSBF_品質管理
AW12: MSBG_債権管理
AW13: MSBH_債務管理
AW14: MSBI_締処理
AW15: MSUA_リスト・入力補助
M16: 顧客 | U16: 株式会社クラウン・パッケージ | AW16: PF_ESBアダプタ
M18: プロジェクト名 | U18: 基幹システム刷新PJ | AW18: 機能区分
AW19: 画面
M20: 文書番号 | AW20: 帳票
AW21: バッチ
M22: Ｒｅｖ． | U22: {=MAX(_xlfn.NUMBERVALUE(改訂!A7:E48))} -> 1 | AW22: マスタ
M24: 機密性区分 | U24: 取扱注意（Ｃ） | AW24: 開発区分
AW25: カスタマイズ
M26: システム名 | U26: Webシステム | AC26: Ver. | AE26: 7.0.2 | AW26: アドオン
AW27: －
M28: サブモジュール | U28: MSBB_販売管理
M30: 機能名 | U30: =M50 -> Web見積計算書一覧照会
M32: 機能ID | U32: =G50 -> MSBBPA020
M34: 機能区分 | U34: 画面
M36: 開発区分 | U36: アドオン
W39: 作成 | AB39: 最終更新 | AG39: ご確認
W40: MDSOL
W42: 44805
A48: 文書番号 | G48: 画面ID | M48: 画面名 | V48: Version | AB48: Revision
A50: M7-US-1140 | G50: MSBBPA020 | M50: Web見積計算書一覧照会 | V50: 1.0.0 | AB50: r01.00
A53: 共通（元データ）
A54: Webシステム | K54: 文書名 | U54: モジュールID | Z54: MS | AE54: モジュール名 | AJ54: Webシステム | AS54: 文書番号 | AZ54: Version | BF54: Rev.
K55: 画面説明書 | U55: ｻﾌﾞﾓｼﾞｭｰﾙID | Z55: MSBB | AE55: ｻﾌﾞﾓｼﾞｭｰﾙ名 | AJ55: 販売Webシステム | AS55: M7-US-1140 | AZ55: 1.0.0 | BF55: r00.00
K56: 表紙 | U56: 表題 | Z56: MSBBPA020 | AE56: Web見積計算書一覧照会
A57: 共通（リンク用）
A58: =A54 -> Webシステム | K58: 文書名 | U58: モジュールID | Z58: =Z54 -> MS | AE58: モジュール名 | AJ58: =AJ54 -> Webシステム | AS58: 文書番号 | AZ58: Version | BF58: Rev.
...

Sheet 改訂
A1: 第7章 | K1: 改訂 | AU1: 作成者 | AZ1: MDSOL | BE1: 作成日 | BJ1: =表紙!W42 -> 44805 | BP1: Rev.
AU2: 修正者 | BE2: 改訂日 | BP2: =表紙!CB64 -> 1
A5: Rev. | F5: 改定内容 | BC5: 頁 | BM5: 変更日 変更者 | BR5: 確認日 確認者
A7: 1 | F7: 新規作成

Sheet 概要
A1: =表紙!A54 -> Webシステム | O1: 文書名 | AC1: モジュールID | AJ1: =表紙!AJ63 -> MS | AQ1: モジュール名 | AX1: =表紙!AX63 -> Webシステム | BL1: 文書番号 | BU1: Version | CB1: Rev.
O2: =表紙!O64 -> アドオン設計書 | AC2: サブモジュールID | AJ2: =表紙!AJ64 -> MSBB | AQ2: サブモジュール名 | AX2: =表紙!AX64 -> 販売Webシステム | BL2: =表紙!BL64 -> M7-US-1140 | BU2: =表紙!BU64 -> 7.0.2 | CB2: =表紙!CB64 -> 1
O3: =RIGHT(CELL("filename",$A$1),LEN(CELL("filename",$A$1))-FIND("]",CELL("filename",$A$1))) -> #VALUE! | AC3: 表題 | AJ3: =表紙!AJ65 -> MSBBPA020 | AQ3: =表紙!AQ65 -> Web見積計算書一覧照会
AO5: 概要
B7: 【説明】
C8: 見積計算書の一覧照会画面
B10: 【目的】
C11: 見積計算書を一覧照会する、見積計算書画面へ遷移する(参照・訂正)
C12: 見積計算書を一括発行する
B14: 【処理関連図/サービス関連図】
C15: ※処理・サービス関連図シートに詳細記載
B17: 【オペレーション一覧】
C18: 見積計算書の検索・照会処理を行う
C19: 見積計算書の帳票発行を行う
C20: 見積計算書のCSV出力を行う
B22: 【SQLID一覧】
C23: なし
B25: 【ソート順】
C26: 担当、得意先、案件NO、見積計算書NO
B28: 【データアクセスコントロール】
C29: 拠点による制御
C30: ※詳細は、【MSBBPA000】_共通設計書_アドオン(Webシステム共通仕様)にて定義
B32: 【自由記述】
C33: なし

Sheet 画面イメージ
A1: =表紙!A54 -> Webシステム | K1: 文書名 | U1: モジュールID | Z1: =表紙!$AJ$63 -> MS | AE1: モジュール名 | AJ1: =表紙!$AX$63 -> Webシステム | AS1: 文書番号 | AZ1: Version | BF1: Rev.
K2: =表紙!O64 -> アドオン設計書 | U2: ｻﾌﾞﾓｼﾞｭｰﾙID | Z2: =表紙!$AJ$64 -> MSBB | AE2: ｻﾌﾞﾓｼﾞｭｰﾙ名 | AJ2: =表紙!$AX$64 -> 販売Webシステム | AS2: =表紙!$BL$64 -> M7-US-1140 | AZ2: =表紙!$BU$64 -> 7.0.2 | BF2: =表紙!$CB$64 -> 1
K3: =RIGHT(CELL("filename",$A$1),LEN(CELL("filename",$A$1))-FIND("]",CELL("filename",$A$1))) -> #VALUE! | U3: 表題 | Z3: =表紙!$AJ$65 -> MSBBPA020 | AE3: =表紙!$AQ$65 -> Web見積計算書一覧照会
A5: 画面イメージ
B7: ≫凡例
Q8: ・・・ | S8: ボタン
C9: 見積計算書NO | Q9: ・・・ | S9: 検索項目(検索画面表示選択) | AJ9: 参照情報
C10: 品名 | Q10: ・・・ | S10: 入力項目
C11: 得意先 | Q11: ・・・ | S11: 表示項目(得意先名称、原紙名等) | AJ11: 担当者
C12: 操作種別 | I12: ●登録 | M12: ○訂正 | Q12: ・・・ | S12: 選択項目(一つのみ選択可能)
C13: 受注区分 | Q13: ・・・ | S13: 選択項目(一つのみ選択可能)
C14: 作業順 | I14: ☑AAA | M14: ☑BBB | Q14: ・・・ | S14: 選択項目(複数選択可能)
C16: 見積作成日 | Q16: ・・・ | S16: カレンダー形式 | CX16: MDSOL 野村 2022/10/25 修正しました(カレンダー形式 誤字対応) | DY16: 2022/10/27 落合 問題なし
CX17: MDSOL 野村 2022/10/25 修正しました(メーカ追加) | DY17: 2022/10/27 落合 問題なし
CX18: 【MSBBPA080】_画面設計書_アドオン(Web受注一覧照会)の横展開
CX19: CP指摘 2022/10/02 落合 検索条件が多すぎる為、レイアウトを右記のようにする→
DG20: 詳細検索は折りたたんだ状態で表示し、必要時のみ入力する
BX21: － | DG21: 見積検索も合わせてください
CY22: MDSOL 野村 2022/10/25 レイアウト修正→見積を合わせて修正します | DY22: 2022/10/27 落合 問題なし
D23: 拠点 | BR23: * | BS23: あいまい検索可能
D24: 得意先 | J24: (得意先名:オートフィルタ) | AC24: 見積担当者
D25: 案件No | J25: 9999999-999 | Q25: (案件No親/子)
D26: 顧客品名 | AB26: * | AU26: *
D27: 見積作成日 | P27: ~
D28: 見積計算書NO | P28: ~ | AC28: 受注区分 | AI28: 製品 | AO28: 製品区分 | AU28: 大 | BB28: 中 | BI28: 小
D29: 親子区分 | R29: FSC認証区分 | AC29: FSC材質区分
R31: 原紙 | AK31: 印刷 | AY31: エンボス | BJ31: メーカ
D32: 段 | J32: E | N32: 表構成 | BJ32: (メーカ名:ｵｰﾄﾌｨﾙﾀ)
D33: シート寸法 | J33: 巾 | P33: 流れ | AC33: 刃渡り（mm) | AI33: 巾 | AO33: 流れ
D35: 詳細検索 | BW35: ー
J36: 原紙 | AC36: 印刷 | AQ36: エンボス | BB36: メーカ
D37: 中構成 | BB37: (メーカ名:ｵｰﾄﾌｨﾙﾀ)
D38: 裏構成 | BB38: (メーカ名:ｵｰﾄﾌｨﾙﾀ)
D40: 製品形状 | R40: 物流区分
D42: 印刷備考 | J42: 40byte | AB42: * | AC42: 製造備考 | AI42: 40byte | BA42: *
D43: 伝票備考 | J43: 40byte | AB43: * | AC43: 納入備考 | AI43: 40byte | BA43: *
D44: 出荷備考１ | J44: 40byte | AB44: * | AC44: 出荷備考２ | AI44: 40byte | BA44: *
D47: 決定予想 | J47: ☑決定予想のみ
D48: 見積区分 | J48: ☑通常 | N48: ☑決定
D49: ステータス | J49: ☑未承認 | N49: ☑承認済 | R49: ☑マスタ採用済 | W49: ☑受注済
...

Sheet 旧レイアウト
A1: =表紙!A54 -> Webシステム | K1: 文書名 | U1: モジュールID | Z1: =表紙!$AJ$63 -> MS | AE1: モジュール名 | AJ1: =表紙!$AX$63 -> Webシステム | AS1: 文書番号 | AZ1: Version | BF1: Rev.
K2: =表紙!O64 -> アドオン設計書 | U2: ｻﾌﾞﾓｼﾞｭｰﾙID | Z2: =表紙!$AJ$64 -> MSBB | AE2: ｻﾌﾞﾓｼﾞｭｰﾙ名 | AJ2: =表紙!$AX$64 -> 販売Webシステム | AS2: =表紙!$BL$64 -> M7-US-1140 | AZ2: =表紙!$BU$64 -> 7.0.2 | BF2: =表紙!$CB$64 -> 1
K3: =RIGHT(CELL("filename",$A$1),LEN(CELL("filename",$A$1))-FIND("]",CELL("filename",$A$1))) -> #VALUE! | U3: 表題 | Z3: =表紙!$AJ$65 -> MSBBPA020 | AE3: =表紙!$AQ$65 -> Web見積計算書一覧照会
A5: 画面イメージ
B7: ≫凡例
Q8: ・・・ | S8: ボタン | AD8: 見積作成日 | AR8: ・・・ | AT8: カンレンダー形式
C9: 見積計算書№ | Q9: ・・・ | S9: 検索項目(検索画面表示選択)
C10: 品名 | Q10: ・・・ | S10: 入力項目
C11: 得意先 | Q11: ・・・ | S11: 表示項目(得意先名称、原紙名等)
C12: 操作種別 | I12: ●登録 | M12: ○訂正 | Q12: ・・・ | S12: 選択項目(一つのみ選択可能)
C13: 受注区分 | Q13: ・・・ | S13: 選択項目(一つのみ選択可能)
C14: 作業順 | I14: ☑AAA | M14: ☑BBB | Q14: ・・・ | S14: 選択項目(複数選択可能)
D20: 拠点 | BC20: * | BD20: あいまい検索可能
D21: 担当者
D23: 見積作成日 | P23: ~
D25: 見積計算書№
D26: 案件№ | J26: (案件名:オートフィルタ)
D27: 得意先 | J27: (得意先名:オートフィルタ)
D29: 刃渡り | P29: ~
D31: 品名 | AB31: * | AD31: FSC認証製品
D32: 受注区分 | R32: 製品区分
D33: 製品形状 | R33: 物流区分
D35: 印刷備考 | AB35: * | AD35: 製造備考 | BB35: *
D36: 横持備考 | AB36: * | AD36: 納入備考 | BB36: *
D37: 配車備考 | AB37: * | AD37: 伝票備考 | BB37: *
D39: ステータス | J39: □一時保存 | O39: □未受注 | T39: □受注済 | AD39: 並び順 | AJ39: 見積作成日 | AQ39: ○昇順 | AU39: ●降順
D44: № | F44: ステータス | I44: 案件№ | N44: 見積計算書№ | S44: 見積作成日 | W44: 得意先 | AB44: 製品区分 | AF44: 品名 | AK44: 見積り数 | AO44: 見積平米 | AS44: ㎡単価 | AW44: 金額 | BA44: 計算書
D45: 1 | AB45: 加工 | BA45: ☑
D46: 2 | F46: 受注済 | BA46: ☑
D47: 3 | BA47: ☑
D48: 4 | BA48: ☑
D49: 5 | F49: 受注済 | BA49: ☑
D50: 6 | BA50: □
D51: 7 | F51: 受注済 | BA51: □
D52: 8 | F52: 受注済 | BA52: □
D53: 9 | BA53: □
D54: 10 | F54: 受注済 | BA54: □
F62: ・・・ | H62: 参照モードで、「見積計算書」画面へ遷移
F65: ・・・ | H65: 訂正モードで、「見積計算書」画面へ遷移
F68: ・・・ | H68: 削除モードで、「見積計算書」画面へ遷移
...

Sheet 項目説明
A1: =表紙!A54 -> Webシステム | K1: 文書名 | U1: モジュールID | Z1: =表紙!$AJ$63 -> MS | AE1: モジュール名 | AJ1: =表紙!$AX$63 -> Webシステム | AS1: 文書番号 | AZ1: Version | BF1: Rev.
K2: =表紙!O64 -> アドオン設計書 | U2: ｻﾌﾞﾓｼﾞｭｰﾙID | Z2: =表紙!$AJ$64 -> MSBB | AE2: ｻﾌﾞﾓｼﾞｭｰﾙ名 | AJ2: =表紙!$AX$64 -> 販売Webシステム | AS2: =表紙!$BL$64 -> M7-US-1140 | AZ2: =表紙!$BU$64 -> 7.0.2 | BF2: =表紙!$CB$64 -> 1
K3: =RIGHT(CELL("filename",$A$1),LEN(CELL("filename",$A$1))-FIND("]",CELL("filename",$A$1))) -> #VALUE! | U3: 表題 | Z3: =表紙!$AJ$65 -> MSBBPA020 | AE3: =表紙!$AQ$65 -> Web見積計算書一覧照会
A5: 見積計算書一覧照会
B6: 抽出条件 | N6: 説明 | BE6: Ｗ | BF6: 型 | BG6: 参 | BH6: 必 | BI6: 入 | BJ6: 非 | BK6: 検
A7: 〇 | B7: 拠点 | M7: 【MSBBPACOM】_共通設計書_アドオン(共通ロジック)にて定義 | BE7: C | BF7: S
A8: 〇 | B8: 得意先 | M8: 【MSBBPACOM】_共通設計書_アドオン(共通ロジック)にて定義 | BE8: A | BF8: S | BK8: 検
A9: 〇 | B9: 見積担当者 | M9: 【MSBBPACOM】_共通設計書_アドオン(共通ロジック)にて定義 | BE9: C | BF9: S
A10: 〇 | B10: 案件No | M10: 【MSBBPACOM】_共通設計書_アドオン(共通ロジック)にて定義 | BE10: A | BF10: S | BK10: 検
A11: 〇 | B11: 顧客品名1 | M11: 抽出条件として、顧客品名1を入力する | AZ11: あいまい検索可 | BE11: T | BF11: S
A12: 〇 | B12: 顧客品名2 | M12: 抽出条件として、顧客品名2を入力する | AZ12: あいまい検索可 | BE12: T | BF12: S
A13: 〇 | B13: 見積作成日(From) | M13: 抽出条件として、見積作成日(From)を入力する | BE13: カ | BF13: D
A14: 〇 | B14: 見積作成日(To) | M14: 抽出条件として、見積作成日(To)を入力する | BE14: カ | BF14: D
A15: 〇 | B15: 見積計算書NO(From) | M15: 抽出条件として、見積計算書NO(From)を入力する | BE15: T | BF15: S
A16: 〇 | B16: 見積計算書NO(To) | M16: 抽出条件として、見積計算書NO(To)を入力する | BE16: T | BF16: S
A17: 〇 | B17: 受注区分 | M17: 【MSBBPACOM】_共通設計書_アドオン(共通ロジック)にて定義 | BE17: C | BF17: S
A18: 〇 | B18: 製品区分_大 | M18: 【MSBBPACOM】_共通設計書_アドオン(共通ロジック)にて定義 | BE18: C | BF18: S
A19: 〇 | B19: 製品区分_中 | M19: 【MSBBPACOM】_共通設計書_アドオン(共通ロジック)にて定義 | BE19: C | BF19: S
A20: 〇 | B20: 製品区分_小 | M20: 【MSBBPACOM】_共通設計書_アドオン(共通ロジック)にて定義 | BE20: C | BF20: S
A21: 〇 | B21: 親子区分 | M21: 【MSBBPACOM】_共通設計書_アドオン(共通ロジック)にて定義 | BE21: C | BF21: S
A22: 〇 | B22: FSC認証区分 | M22: 【MSBBPACOM】_共通設計書_アドオン(共通ロジック)にて定義 | BE22: C | BF22: S
A23: 〇 | B23: FSC材質区分 | M23: 【MSBBPACOM】_共通設計書_アドオン(共通ロジック)にて定義 | BE23: C | BF23: S
A24: 〇 | B24: シート段 | M24: 【MSBBPACOM】_共通設計書_アドオン(共通ロジック)にて定義 | BE24: C | BF24: S
A25: 〇 | B25: 原紙コード(表) | M25: 【MSBBPACOM】_共通設計書_アドオン(共通ロジック)にて定義 | BE25: A | BF25: S | BJ25: 検
A26: 〇 | B26: 印刷コード(表) | M26: 【MSBBPACOM】_共通設計書_アドオン(共通ロジック)にて定義 | BE26: A | BF26: S | BJ26: 検
A27: 〇 | B27: エンボスコード(表) | M27: 【MSBBPACOM】_共通設計書_アドオン(共通ロジック)にて定義 | BE27: A | BF27: S | BJ27: 検
A28: 〇 | B28: メーカコード(表) | M28: 【MSBBPACOM】_共通設計書_アドオン(共通ロジック)にて定義 | BE28: A | BF28: S | BJ28: 検
B30: 抽出条件 - 詳細検索 | N30: 説明 | BE30: Ｗ | BF30: 型 | BG30: 参 | BH30: 必 | BI30: 入 | BJ30: 非 | BK30: 検
A31: 〇 | B31: 詳細検索(+/-) | M31: 詳細検索領域を+時…開く、-時…閉じる | AA31: 原紙コード(中)～出荷備考2までの領域の表示/非表示 | AS31: ※初期は閉じた状態(折り畳み)とする
A32: 〇 | B32: 原紙コード(中) | M32: 【MSBBPACOM】_共通設計書_アドオン(共通ロジック)にて定義 | BE32: A | BF32: S | BJ32: 検
A33: 〇 | B33: 印刷コード(中) | M33: 【MSBBPACOM】_共通設計書_アドオン(共通ロジック)にて定義 | BE33: A | BF33: S | BJ33: 検
A34: 〇 | B34: エンボスコード(中) | M34: 【MSBBPACOM】_共通設計書_アドオン(共通ロジック)にて定義 | BE34: A | BF34: S | BJ34: 検
A35: 〇 | B35: メーカコード(中) | M35: 【MSBBPACOM】_共通設計書_アドオン(共通ロジック)にて定義 | BE35: A | BF35: S | BJ35: 検
A36: 〇 | B36: 原紙コード(裏) | M36: 【MSBBPACOM】_共通設計書_アドオン(共通ロジック)にて定義 | BE36: A | BF36: S | BJ36: 検
A37: 〇 | B37: 印刷コード(裏) | M37: 【MSBBPACOM】_共通設計書_アドオン(共通ロジック)にて定義 | BE37: A | BF37: S | BJ37: 検
A38: 〇 | B38: エンボスコード(裏) | M38: 【MSBBPACOM】_共通設計書_アドオン(共通ロジック)にて定義 | BE38: A | BF38: S | BJ38: 検
A39: 〇 | B39: メーカコード(裏) | M39: 【MSBBPACOM】_共通設計書_アドオン(共通ロジック)にて定義 | BE39: A | BF39: S | BJ39: 検
A40: 〇 | B40: 製品形状 | M40: 【MSBBPACOM】_共通設計書_アドオン(共通ロジック)にて定義 | BE40: C | BF40: S
A41: 〇 | B41: 物流区分 | M41: 【MSBBPACOM】_共通設計書_アドオン(共通ロジック)にて定義 | BE41: C | BF41: S
A42: 〇 | B42: 刃渡り_巾 | M42: 抽出条件として、刃渡り_巾を入力する | BE42: T | BF42: N
...

Sheet 引数説明
A1: =表紙!A54 -> Webシステム | K1: 文書名 | U1: モジュールID | Z1: =表紙!$AJ$63 -> MS | AE1: モジュール名 | AJ1: =表紙!$AX$63 -> Webシステム | AS1: 文書番号 | AZ1: Version | BF1: Rev.
K2: =表紙!O64 -> アドオン設計書 | U2: ｻﾌﾞﾓｼﾞｭｰﾙID | Z2: =表紙!$AJ$64 -> MSBB | AE2: ｻﾌﾞﾓｼﾞｭｰﾙ名 | AJ2: =表紙!$AX$64 -> 販売Webシステム | AS2: =表紙!$BL$64 -> M7-US-1140 | AZ2: =表紙!$BU$64 -> 7.0.2 | BF2: =表紙!$CB$64 -> 1
K3: =RIGHT(CELL("filename",$A$1),LEN(CELL("filename",$A$1))-FIND("]",CELL("filename",$A$1))) -> #VALUE! | U3: 表題 | Z3: =表紙!$AJ$65 -> MSBBPA020 | AE3: =表紙!$AQ$65 -> Web見積計算書一覧照会
B5: オペレーションＩＤ/名称：SloRecvIfImp_Upd01/取込
A6: 必 | B6: 項目名 | N6: 説明 | AS6: 未設定時の振る舞い

Sheet 処理概要
A1: =表紙!A54 -> Webシステム | K1: 文書名 | U1: モジュールID | Z1: =表紙!$AJ$63 -> MS | AE1: モジュール名 | AJ1: =表紙!$AX$63 -> Webシステム | AS1: 文書番号 | AZ1: Version | BF1: Rev.
K2: =表紙!O64 -> アドオン設計書 | U2: ｻﾌﾞﾓｼﾞｭｰﾙID | Z2: =表紙!$AJ$64 -> MSBB | AE2: ｻﾌﾞﾓｼﾞｭｰﾙ名 | AJ2: =表紙!$AX$64 -> 販売Webシステム | AS2: =表紙!$BL$64 -> M7-US-1140 | AZ2: =表紙!$BU$64 -> 7.0.2 | BF2: =表紙!$CB$64 -> 1
K3: =RIGHT(CELL("filename",$A$1),LEN(CELL("filename",$A$1))-FIND("]",CELL("filename",$A$1))) -> #VALUE! | U3: 表題 | Z3: =表紙!$AJ$65 -> MSBBPA020 | AE3: =表紙!$AQ$65 -> Web見積計算書一覧照会
A5: No | B5: 入力 | J5: 処理 | BD5: 出力
A6: 1 | B6: 初期表示
J7: 1.処理概要
K8: 初期表示
L9: 拠点 | Q9: ： | R9: ログインに紐づく拠点CDを表示する
R10: ログイン.管理者区分 = 0(一般ユーザー時)、変更不可とする
L11: 担当者 | Q11: ： | R11: ログイン担当者CDを表示する
L12: 見積作成日 | Q12: ： | R12: 見積作成日Fromに当日 - ログインマスタ.初期表示をセット、Toに当日をセットする
L13: 表示処理 | Q13: ： | R13: 抽出条件をもとに見積計算書一覧に結果を表示する | BD13: 検索入出力仕様.NO1
L15: フッターボタン表示・非表示切替
M16: メニューから呼び出された場合(照会画面モード) | AC16: ・・・ | AE16: 見積詳細ボタンを表示、選択ボタンを非表示とする
M17: 検索画面として呼び出された場合(検索画面モード) | AC17: ・・・ | AE17: 見積詳細ボタンを非表示、選択ボタンを表示とする
M18: 例)検索画面モード:Web見積計算書入力から検索画面として呼び出され、選択行を返す場合
A20: 2 | B20: 画面操作
J21: 1.処理概要
K22: ボタン処理
L23: クリアボタン押下 | U23: ： | V23: 画面を初期化する(起動時の状態とする)
L25: 表示ボタン押下 | U25: ： | V25: チェック処理にてエラーとなった場合、後続処理をキャンセルする
L26: (チェック処理) | W26: FROM～TOの整合性チェック | AH26: … | AI26: エラーメッセージ：FROM≦TOの関係で指定してください。 | BD26: メッセージID.001
W27: チェックボックスチェック有無 | AH27: … | AI27: エラーメッセージ：いずれかを選択してください。 | BD27: メッセージID.002
L29: 表示ボタン押下 | U29: ： | V29: 抽出条件をもとに見積計算書一覧に結果を表示する | BD29: 検索入出力仕様.NO1
W30: データ取得できなかった場合、下記メッセージを表示
W31: エラーメッセージ：検索結果がありません。 | BD31: メッセージID.003
L33: 見積計算書発行ボタン押下 | U33: ： | V33: 見積計算書一覧の発行にチェックされたデータを帳票「見積計算書」として出力する
W34: 発行☑が1行もチェックされていない場合、下記メッセージを表示
W35: エラーメッセージ：発行対象がありません。 | BD35: メッセージID.004
U36: ※帳票出力は、【MSBBRA010】_帳票設計書_アドオン(見積計算書)を参照
L38: CSV出力 | U38: ： | V38: 見積計算書一覧のデータをCSV出力する | BD38: ファイル入出力仕様.NO1
U39: ※1 CSV出力定義とファイル名は、【MSBBPACOM】_共通設計書_アドオン(共通ロジック)にて定義
U40: ※2 画面に表示されたデータがCSVとして出力される
BM41: 事前指摘
L42: 見積詳細ボタン押下 | U42: ： | V42: 見積計算書入力画面の「3ページ目：計算結果画面」に遷移する(操作種別:参照で遷移する)
W43: 一覧にデータが無いもしくは対象行が選択されてない場合、下記メッセージを表示 | BM43: CP指摘 2022/09/28 木﨑 選択した詳細画面へ遷移なら一覧にチェックボックス等の選択用項目が必要かと思います。(何を選択中か分からない。選択した行はハイライト表示ですか？)また[選択]→[詳細表示]ですと２ステップの操作になるので、各行の先頭に受注詳細ボタを設けた方が操作性は良いかと思います。(スクロール時は固定)
W44: エラーメッセージ：選択行がありません。 | BD44: メッセージID.005 | BN44: MDSOL 野村 2022/10/25 選択行となります。初期想定は、一覧にて選択ボタンを設けておりましたが、打合せによりフッターにボタンを集約することになりました。 | DI44: 2022/10/27 落合 問題なし
U45: → 選択行の見積計算書NOをキーに見積計算書のデータを参照する | BD45: 画面遷移.S01.NO1
L47: 選択 | U47: ： | V47: 検索モードで開いた場合に選択結果(1行)を遷移元画面に返す | BM47: CP指摘 2022/09/28 木﨑 選択ボタンは各行の先頭に設けた方が操作性は良くなると思います。
W48: 一覧にデータが無いもしくは対象行が選択されてない場合、下記メッセージを表示 | BN48: MDSOL 野村 2022/10/25 打合せにより、フッターにボタンを集めることになりました。 | CN48: 2022/10/27 落合 問題なし
...

Sheet 処理詳細
A1: =表紙!A54 -> Webシステム | K1: 文書名 | U1: モジュールID | Z1: =表紙!$AJ$63 -> MS | AE1: モジュール名 | AJ1: =表紙!$AX$63 -> Webシステム | AS1: 文書番号 | AZ1: Version | BF1: Rev.
K2: =表紙!O64 -> アドオン設計書 | U2: ｻﾌﾞﾓｼﾞｭｰﾙID | Z2: =表紙!$AJ$64 -> MSBB | AE2: ｻﾌﾞﾓｼﾞｭｰﾙ名 | AJ2: =表紙!$AX$64 -> 販売Webシステム | AS2: =表紙!$BL$64 -> M7-US-1140 | AZ2: =表紙!$BU$64 -> 7.0.2 | BF2: =表紙!$CB$64 -> 1
K3: =RIGHT(CELL("filename",$A$1),LEN(CELL("filename",$A$1))-FIND("]",CELL("filename",$A$1))) -> #VALUE! | U3: 表題 | Z3: =表紙!$AJ$65 -> MSBBPA020 | AE3: =表紙!$AQ$65 -> Web見積計算書一覧照会
A5: No | B5: 入力 | J5: 処理 | BD5: 出力
A6: 1 | B6: 初期表示
A12: 2 | B12: 画面操作
A18: 3 | B18: 検索【F1】

Sheet 処理・サービス関連図
A1: =表紙!A54 -> Webシステム | K1: 文書名 | U1: モジュールID | Z1: =表紙!$AJ$63 -> MS | AE1: モジュール名 | AJ1: =表紙!$AX$63 -> Webシステム | AS1: 文書番号 | AZ1: Version | BF1: Rev.
K2: =表紙!O64 -> アドオン設計書 | U2: ｻﾌﾞﾓｼﾞｭｰﾙID | Z2: =表紙!$AJ$64 -> MSBB | AE2: ｻﾌﾞﾓｼﾞｭｰﾙ名 | AJ2: =表紙!$AX$64 -> 販売Webシステム | AS2: =表紙!$BL$64 -> M7-US-1140 | AZ2: =表紙!$BU$64 -> 7.0.2 | BF2: =表紙!$CB$64 -> 1
K3: =RIGHT(CELL("filename",$A$1),LEN(CELL("filename",$A$1))-FIND("]",CELL("filename",$A$1))) -> #VALUE! | U3: 表題 | Z3: =表紙!$AJ$65 -> MSBBPA020 | AE3: =表紙!$AQ$65 -> Web見積計算書一覧照会
C7: 検索処理

Sheet 検索入出力仕様
A1: =表紙!A54 -> Webシステム | K1: 文書名 | U1: モジュールID | Z1: =表紙!$AJ$63 -> MS | AE1: モジュール名 | AJ1: =表紙!$AX$63 -> Webシステム | AS1: 文書番号 | AZ1: Version | BF1: Rev.
K2: =表紙!O64 -> アドオン設計書 | U2: ｻﾌﾞﾓｼﾞｭｰﾙID | Z2: =表紙!$AJ$64 -> MSBB | AE2: ｻﾌﾞﾓｼﾞｭｰﾙ名 | AJ2: =表紙!$AX$64 -> 販売Webシステム | AS2: =表紙!$BL$64 -> M7-US-1140 | AZ2: =表紙!$BU$64 -> 7.0.2 | BF2: =表紙!$CB$64 -> 1
K3: =RIGHT(CELL("filename",$A$1),LEN(CELL("filename",$A$1))-FIND("]",CELL("filename",$A$1))) -> #VALUE! | U3: 表題 | Z3: =表紙!$AJ$65 -> MSBBPA020 | AE3: =表紙!$AQ$65 -> Web見積計算書一覧照会
A5: No | G5: 1 | S5: ボタン | Z5: 表示 | AH5: 備考 | AK5: 表示ボタンクリック時処理
A6: 処理分類 | E6: 検索 | S6: ソート順 | Z6: 担当、得意先、案件NO、見積計算書NO
A7: No | C7: 転送先 | V7: 転送元 | AQ7: 説明
C8: 種 | D8: オブジェクト | K8: 項目名 | V8: 種 | W8: オブジェクト | AF8: 項目名
A9: 1 | C9: 画 | D9: 見積計算書一覧 | K9: NO | AF9: 行番
A10: 2 | C10: 画 | D10: 見積計算書一覧 | K10: 担当 | V10: T | W10: 見積計算書 | AF10: 担当
A11: 3 | C11: 画 | D11: 見積計算書一覧 | K11: 担当者名 | V11: T | W11: 担当 | AF11: 担当者名
A12: 4 | C12: 画 | D12: 見積計算書一覧 | K12: 得意先 | V12: T | W12: 見積計算書 | AF12: 得意先
A13: 5 | C13: 画 | D13: 見積計算書一覧 | K13: 得意先名 | V13: T | W13: 得意先 | AF13: 得意先名
A14: 6 | C14: 画 | D14: 見積計算書一覧 | K14: 案件NO | V14: T | W14: 見積計算書 | AF14: 案件NO
A15: 7 | C15: 画 | D15: 見積計算書一覧 | K15: 案件名 | V15: T | W15: 見積計算書 | AF15: 案件名
A16: 8 | C16: 画 | D16: 見積計算書一覧 | K16: 見積計算書NO | V16: T | W16: 見積計算書 | AF16: 見積計算書NO
A17: 9 | C17: 画 | D17: 見積計算書一覧 | K17: 見積作成日 | V17: T | W17: 見積計算書 | AF17: 見積作成日
A18: 10 | C18: 画 | D18: 見積計算書一覧 | K18: 顧客品名1 | V18: T | W18: 見積計算書 | AF18: 顧客品名1
A19: 11 | C19: 画 | D19: 見積計算書一覧 | K19: 顧客品名2 | V19: T | W19: 見積計算書 | AF19: 顧客品名2
A20: 12 | C20: 画 | D20: 見積計算書一覧 | K20: 見積数 | V20: T | W20: 見積計算書 | AF20: 見積数
A21: 13 | C21: 画 | D21: 見積計算書一覧 | K21: 決定予想 | V21: T | W21: 見積計算書 | AF21: 決定予想
... A26: 18 | C26: 画 | D26: 見積計算書一覧 | K26: ステータス | V26: T | W26: 見積計算書 | AF26: ステータス
A27: 19 | C27: 画 | D27: 見積計算書一覧 | K27: 発行 | AF27: [0:固定値] | AQ27: チェックOFF
A28: 20 | C28: 画 | D28: 見積計算書一覧 | K28: 製品コード | V28: T | W28: 見積計算書

Sheet 更新入出力仕様
A1: =表紙!A54 -> Webシステム | K1: 文書名 | U1: モジュールID | Z1: =表紙!$AJ$63 -> MS | AE1: モジュール名 | AJ1: =表紙!$AX$63 -> Webシステム | AS1: 文書番号 | AZ1: Version | BF1: Rev.
K2: =表紙!O64 -> アドオン設計書 | U2: ｻﾌﾞﾓｼﾞｭｰﾙID | Z2: =表紙!$AJ$64 -> MSBB | AE2: ｻﾌﾞﾓｼﾞｭｰﾙ名 | AJ2: =表紙!$AX$64 -> 販売Webシステム | AS2: =表紙!$BL$64 -> M7-US-1140 | AZ2: =表紙!$BU$64 -> 7.0.2 | BF2: =表紙!$CB$64 -> 1
K3: =RIGHT(CELL("filename",$A$1),LEN(CELL("filename",$A$1))-FIND("]",CELL("filename",$A$1))) -> #VALUE! | U3: 表題 | Z3: =表紙!$AJ$65 -> MSBBPA020 | AE3: =表紙!$AQ$65 -> Web見積計算書一覧照会
A5: No | G5: 1 | S5: ロジック名称 | AH5: 備考
A6: 処理分類 | E6: 更新
A7: No | C7: 転送先 | V7: 転送元 | AQ7: 説明
C8: 種 | D8: オブジェクト | K8: 項目名 | V8: 種 | W8: オブジェクト | AF8: 項目名

Sheet ファイル入出力仕様
A1: =表紙!A54 -> Webシステム | K1: 文書名 | U1: モジュールID | Z1: =表紙!$AJ$63 -> MS | AE1: モジュール名 | AJ1: =表紙!$AX$63 -> Webシステム | AS1: 文書番号 | AZ1: Version | BF1: Rev.
K2: =表紙!O64 -> アドオン設計書 | U2: ｻﾌﾞﾓｼﾞｭｰﾙID | Z2: =表紙!$AJ$64 -> MSBB | AE2: ｻﾌﾞﾓｼﾞｭｰﾙ名 | AJ2: =表紙!$AX$64 -> 販売Webシステム | AS2: =表紙!$BL$64 -> M7-US-1140 | AZ2: =表紙!$BU$64 -> 7.0.2 | BF2: =表紙!$CB$64 -> 1
K3: =RIGHT(CELL("filename",$A$1),LEN(CELL("filename",$A$1))-FIND("]",CELL("filename",$A$1))) -> #VALUE! | U3: 表題 | Z3: =表紙!$AJ$65 -> MSBBPA020 | AE3: =表紙!$AQ$65 -> Web見積計算書一覧照会
A5: No | G5: 1 | S5: ロジック名称 | Z5: ファイル出力 | AH5: 備考
A6: 処理分類 | E6: ファイル出力 | S6: ソート順
A7: No | C7: 転送先 | V7: 転送元 | AQ7: 説明
C8: 種 | D8: オブジェクト | K8: 項目名 | V8: 種 | W8: オブジェクト | AF8: 項目名
A9: 1 | C9: フ | D9: 見積計算書一覧 | K9: NO | V9: 画 | W9: 見積計算書一覧 | AF9: NO
A10: 2 | C10: フ | D10: 見積計算書一覧 | K10: 担当 | V10: 画 | W10: 見積計算書一覧 | AF10: 担当
A11: 3 | C11: フ | D11: 見積計算書一覧 | K11: 担当者名 | V11: 画 | W11: 見積計算書一覧 | AF11: 担当者名
A12: 4 | C12: フ | D12: 見積計算書一覧 | K12: 得意先 | V12: 画 | W12: 見積計算書一覧 | AF12: 得意先
A13: 5 | C13: フ | D13: 見積計算書一覧 | K13: 得意先名 | V13: 画 | W13: 見積計算書一覧 | AF13: 得意先名
A14: 6 | C14: フ | D14: 見積計算書一覧 | K14: 案件NO | V14: 画 | W14: 見積計算書一覧 | AF14: 案件NO
A15: 7 | C15: フ | D15: 見積計算書一覧 | K15: 案件名 | V15: 画 | W15: 見積計算書一覧 | AF15: 案件名
A16: 8 | C16: フ | D16: 見積計算書一覧 | K16: 見積計算書NO | V16: 画 | W16: 見積計算書一覧 | AF16: 見積計算書NO
A17: 9 | C17: フ | D17: 見積計算書一覧 | K17: 見積作成日 | V17: 画 | W17: 見積計算書一覧 | AF17: 見積作成日
A18: 10 | C18: フ | D18: 見積計算書一覧 | K18: 顧客品名1 | V18: 画 | W18: 見積計算書一覧 | AF18: 顧客品名1
A19: 11 | C19: フ | D19: 見積計算書一覧 | K19: 顧客品名2 | V19: 画 | W19: 見積計算書一覧 | AF19: 顧客品名2
A20: 12 | C20: フ | D20: 見積計算書一覧 | K20: 見積数 | V20: 画 | W20: 見積計算書一覧 | AF20: 見積数
... A27: 19 | C27: フ | D27: 見積計算書一覧 | K27: 製品コード | V27: 画 | W27: 見積計算書一覧 | AF27: 製品コード

Sheet 画面遷移
A1: =表紙!A54 -> Webシステム | K1: 文書名 | U1: モジュールID | Z1: =表紙!$AJ$63 -> MS | AE1: モジュール名 | AJ1: =表紙!$AX$63 -> Webシステム | AS1: 文書番号 | AZ1: Version | BF1: Rev.
K2: =表紙!O64 -> アドオン設計書 | U2: ｻﾌﾞﾓｼﾞｭｰﾙID | Z2: =表紙!$AJ$64 -> MSBB | AE2: ｻﾌﾞﾓｼﾞｭｰﾙ名 | AJ2: =表紙!$AX$64 -> 販売Webシステム | AS2: =表紙!$BL$64 -> M7-US-1140 | AZ2: =表紙!$BU$64 -> 7.0.2 | BF2: =表紙!$CB$64 -> 1
K3: =RIGHT(CELL("filename",$A$1),LEN(CELL("filename",$A$1))-FIND("]",CELL("filename",$A$1))) -> #VALUE! | U3: 表題 | Z3: =表紙!$AJ$65 -> MSBBPA020 | AE3: =表紙!$AQ$65 -> Web見積計算書一覧照会
A5: 画面遷移フロー図
A6: ＩＤ | C6: S01 | E6: Web見積計算書一覧照会から他画面の画面遷移
D9: NO2
D10: Web取引先一覧照会 | AI10: NO1
AI11: Web見積計算書入力
K12: 検索 | R12: Web見積計算書一覧照会 | AI12: 3ページ目：計算結果画面
X13: 見積詳細ボタン押下
D15: NO3 | K15: 検索
D16: Web汎用検索(共通検索)
A22: ID | D22: 処理名
A23: S01 | D23: Web見積計算書一覧照会から他画面の画面遷移
B25: NO | D25: 遷移元ＩＤ | H25: 遷移元画面名 | Q25: 遷移先ＩＤ | V25: 遷移先画面名 | AE25: 目的 | AJ25: 引継項目 | AS25: 遷移後のアクション(遷移先) | BC25: 戻り値 | BL25: 戻り値取得後のアクション(遷移元) | BV25: 備考
B26: 1 | D26: MSBBPA020 | H26: Web見積計算書一覧照会 | Q26: MSBBPA010 | V26: Web見積計算入力(計算結果) | AE26: 参照 | AJ26: 見積計算書NO | AS26: 検索 | BV26: 操作種別:参照、データ参照
B27: 2 | D27: MSBBPA020 | H27: Web見積計算書一覧照会 | Q27: MSBBPA120 | V27: Web取引先一覧照会 | AE27: 検索結果取得 | AJ27: 得意先ＦＬＧ=1 | AS27: 検索 | BC27: 取引先選択データ(1行) | BL27: 対象データに値セット | BV27: 得意先CD、得意先名に値セット
B28: 3 | D28: MSBBPA020 | H28: Web見積計算書一覧照会 | Q28: MSBBPA900 | V28: Web汎用検索(共通検索) | AE28: 検索結果取得 | AS28: 検索 | BC28: 各種検索画面の選択データ(1行) | BL28: 対象データに値セット | BV28: CD、名称に値セット
B29: 4
B30: 5
B31: 6
B32: 7
B33: 8

Sheet メッセージ一覧
A1: =表紙!A54 -> Webシステム | K1: 文書名 | U1: モジュールID | Z1: =表紙!$AJ$63 -> MS | AE1: モジュール名 | AJ1: =表紙!$AX$63 -> Webシステム | AS1: 文書番号 | AZ1: Version | BF1: Rev.
K2: =表紙!O64 -> アドオン設計書 | U2: ｻﾌﾞﾓｼﾞｭｰﾙID | Z2: =表紙!$AJ$64 -> MSBB | AE2: ｻﾌﾞﾓｼﾞｭｰﾙ名 | AJ2: =表紙!$AX$64 -> 販売Webシステム | AS2: =表紙!$BL$64 -> M7-US-1140 | AZ2: =表紙!$BU$64 -> 7.0.2 | BF2: =表紙!$CB$64 -> 1
K3: =RIGHT(CELL("filename",$A$1),LEN(CELL("filename",$A$1))-FIND("]",CELL("filename",$A$1))) -> #VALUE! | U3: 表題 | Z3: =表紙!$AJ$65 -> MSBBPA020 | AE3: =表紙!$AQ$65 -> Web見積計算書一覧照会
C4: ↓アドオン画面のため、基本全て[新]
A5: No | C5: 新/変 | E5: 種別 | G5: メッセージ内容 | AQ5: 備考（パラメータ等） | BG5: メッセージID
A6: 1 | C6: 新 | E6: W | G6: 「FROM≦TOの関係で指定してください。」 | AQ6: 見積作成日、見積計算書NO | BG6: メッセージID.001
A9: 2 | C9: 新 | E9: W | G9: 「いずれかを選択してください。」 | AQ9: 見積区分、ステータス | BG9: メッセージID.002
A10: 3 | C10: 新 | E10: W | G10: 「検索結果がありません。」 | BG10: メッセージID.003
A11: 4 | C11: 新 | E11: W | G11: 「発行対象がありません。」 | BG11: メッセージID.004
A12: 5 | C12: 新 | E12: W | G12: 「選択行がありません。」 | BG12: メッセージID.005

Sheet 補足説明資料
A1: =表紙!A54 -> Webシステム | O1: 文書名 | AC1: モジュールID | AJ1: =表紙!AJ64 -> MSBB | AQ1: モジュール名 | AX1: =表紙!AX64 -> 販売Webシステム | BL1: 文書番号 | BU1: Version | CB1: Rev.
O2: =表紙!O65 -> #VALUE! | AC2: サブモジュールID | AJ2: =表紙!AJ65 -> MSBBPA020 | AQ2: サブモジュール名 | AX2: =表紙!AX65 -> 0 | BL2: =表紙!BL65 -> 0 | BU2: =表紙!BU65 -> 0 | CB2: =表紙!CB65 -> 0
O3: =RIGHT(CELL("filename",$A$1),LEN(CELL("filename",$A$1))-FIND("]",CELL("filename",$A$1))) -> #VALUE! | AC3: 表題 | AJ3: =表紙!AJ66 -> 0 | AQ3: =表紙!AQ66 -> 0
AO5: 補足説明
