Workbook
Name _____________a1: {"'Sheet1'!$A$3:$I$11"}
Name ____________a1: {"'Sheet1'!$A$3:$I$11"}
Name ___________a1: {"'Sheet1'!$A$3:$I$11"}
Name _________a1: {"'Sheet1'!$A$3:$I$11"}
Name ________a1: {"'Sheet1'!$A$3:$I$11"}
Name ______a1: {"'Sheet1'!$A$3:$I$11"}
Name _____a1: {"'Sheet1'!$A$3:$I$11"}
Name ____a1: {"'Sheet1'!$A$3:$I$11"}
Name ___a1: {"'Sheet1'!$A$3:$I$11"}
Name __a1: {"'Sheet1'!$A$3:$I$11"}
Name _Table2_In1: [1]LIST!#REF!
Name A: #REF!
Name aa: {"'その他費用'!$B$3:$J$22"}
Name ADDON: {"'その他費用'!$B$3:$J$22"}
Name ADDON_2: {"'その他費用'!$B$3:$J$22"}
Name B: {"'その他費用'!$B$3:$J$22"}
Name cc: {"'その他費用'!$B$3:$J$22"}
Name dd: {"'その他費用'!$B$3:$J$22"}
Name ee: {"'その他費用'!$B$3:$J$22"}
Name f: {"'その他費用'!$B$3:$J$22"}
Name ffff: {"'その他費用'!$B$3:$J$22"}
Name HTML_Control: {"'その他費用'!$B$3:$J$22"}
Name HTML_Control1: {"'その他費用'!$B$3:$J$22"}
Name HTML_Control2: {"'その他費用'!$B$3:$J$22"}
Name HTML_Control3: {"'その他費用'!$B$3:$J$22"}
Name InterFace: {"'その他費用'!$B$3:$J$22"}
Name Rev.: 表紙!$U$22
Name RR: {"'その他費用'!$B$3:$J$22"}
Name Ver.: 表紙!$AE$26
Name ああ: {"'その他費用'!$B$3:$J$22"}
Name アドオン: {"'その他費用'!$B$3:$J$22"}
Name こ: {"'その他費用'!$B$3:$J$22"}
Name ご確認者: 表紙!$AG$40
Name ご確認日: 表紙!$AG$42
Name サブシステム名: 表紙!$U$28
Name システム名: 表紙!$U$26
Name プロジェクト名: 表紙!$U$18
Name 開発区分: 表紙!$U$36
Name 機能ＩＤ: 表紙!$U$32
Name 機能区分: 表紙!$U$34
Name 機能名称: 表紙!$U$30
Name 顧客名: 表紙!$U$16
Name 最終更新者: 表紙!$AB$40
Name 最終更新日: 表紙!$AB$42
Name 作成者: 表紙!$W$40
Name 作成日: 表紙!$W$42
Name 章: 表紙!$M$10
Name 文書名: 表紙!$M$10

Sheet 目次
A1: アドオン設計書作成ガイド
C3: ■アドオン設計と成果物について
D4: ・システム設計フェーズとソフトウェア設計フェーズでアドオンの処理仕様を定義する
D5: ・システム設計フェーズとソフトウェア設計フェーズの成果物がアドオン設計書であり、ソフトウェア製作フェーズのインプットとなる
C7: ■各設計フェーズ毎のアドオン設計書作成範囲
D8: ・システム設計フェーズ：他機能との関連を定義するとともに、画面や帳票、ファイル入出力を中心とした外部入出力の設計を行う
D9: ・ソフトウェア設計フェーズ：内部処理を中心とした設計を行う
U11: ◎ | W11: … | X11: システム設計フェーズで作成
U12: ○ | W12: … | X12: システム設計フェーズで基本仕様を定義して、ソフトウェア設計フェーズで詳細化する
U13: △ | W13: … | X13: 必要に応じて（例えば標準仕様から変更がない場合は不要）
U14: ‐ | W14: … | X14: 不要
W15: … | X15: ソフトウェア設計フェーズで作成
D17: 各設計書と作成対象シートのマトリックス | S17: ※カスタマイズ：標準機能に機能を追加する アドオン：新規で機能を開発する
D18: EXCELシート | N18: 画面設計書 | W18: バッチ設計書 | AF18: 帳票設計書 | AO18: ＢＩ設計書 | AT18: .Net設計書 | BB18: EXCELシート | BL18: WebDB設計書 | BR18: 帳票設計書 | BX18: 汎用申請設計書
N19: カスタマイズ | S19: アドオン | W19: カスタマイズ | AB19: アドオン | AF19: カスタマイズ | AK19: アドオン | AO19: アドオン | AT19: アドオン | BL19: アドオン | BR19: アドオン | BX19: アドオン
D20: 概要 | N20: ◎ | O20: ※1 | S20: ◎ | W20: ◎ | X20: ※1 | AB20: ◎ | AF20: ◎ | AG20: ※1 | AK20: ◎ | AO20: ◎ | AT20: ◎ | BB20: 機能概要 | BL20: ◎ | BR20: ◎ | BX20: ◎
D21: レイアウト | N21: ◎ | O21: ※2 | S21: ◎ | W21: ‐ | AB21: ‐ | AF21: ◎ | AG21: ※2 | AK21: ◎ | AO21: ◎ | AT21: ◎ | BB21: アプリケーションフロー | BL21: ◎ | BR21: ー | BX21: ◎
D22: 項目説明 | N22: △ | S22: ○ | W22: ‐ | AB22: ‐ | AF22: △ | AK22: ○ | AO22: ○ | AT22: ○ | BB22: データベース設定 | BL22: ◎ | BR22: ー | BX22: ◎
D23: 引数説明 | N23: ‐ | S23: ‐ | W23: △ | AB23: ◎ | AF23: ‐ | AK23: ‐ | AO23: ‐ | AT23: ◎ | BB23: フィールド設定 | BL23: ◎ | BR23: ー | BX23: ◎
D24: 処理概要 | N24: ◎ | S24: ◎ | W24: ◎ | AB24: ◎ | AF24: ◎ | AK24: ◎ | AO24: ◎ | AT24: ◎ | BB24: 一覧表示画面設定 | BL24: ◎ | BR24: ー | BX24: ◎
D25: 処理詳細 | BB25: 表示編集画面設定 | BL25: ◎ | BR25: ー | BX25: ◎
D26: 処理・サービス関連図 | N26: △ | S26: ◎ | W26: △ | AB26: ◎ | AF26: ‐ | AK26: ‐ | AO26: ‐ | AT26: ◎ | BB26: 明細画面設定 | BL26: △ | BN26: ※3 | BR26: ー | BX26: △ | BZ26: ※3
D27: 検索入出力仕様 | N27: △ | S27: ○ | W27: △ | AB27: ○ | AF27: ‐ | AK27: ‐ | AO27: ‐ | AT27: ○ | BB27: 集計表示設定 | BL27: △ | BN27: ※4 | BR27: ー | BX27: △ | BZ27: ※4
D28: 更新入出力仕様 | N28: △ | S28: ○ | W28: △ | AB28: ○ | AF28: ‐ | AK28: ‐ | AO28: ‐ | AT28: ○ | BB28: 絞り込み条件設定 | BL28: △ | BN28: ※5 | BR28: ー | BX28: △ | BZ28: ※5
D29: ファイル入出力仕様 | N29: △ | S29: △ | W29: ‐ | AB29: ‐ | AF29: ‐ | AK29: ‐ | AO29: ‐ | AT29: △ | BB29: その他設定 | BR29: ー
D30: 画面遷移 | N30: △ | S30: ◎ | W30: ‐ | AB30: ‐ | AF30: ‐ | AK30: ‐ | AO30: ‐ | AT30: ◎ | BB30: 帳票イメージ | BL30: ー | BR30: ◎ | BX30: ー
D31: メッセージ一覧 | N31: △ | S31: △ | W31: △ | AB31: △ | AF31: ‐ | AK31: ‐ | AO31: ‐ | AT31: △ | BB31: 項目設計 | BL31: ー | BR31: ◎ | BX31: ー
D32: 補足説明 | N32: △ | S32: △ | W32: △ | AB32: △ | AF32: △ | AK32: △ | AO32: △ | AT32: △ | BB32: 補足説明 | BL32: △ | BR32: △ | BX32: △
D33: サービス呼出編集仕様 | N33: - | S33: - | W33: - | AB33: - | AF33: - | AK33: - | AO33: - | AT33: - | BB33: 補足説明(詳細)
D35: ※1 | G35: 別シートでカスタマイズ内容を記載する | BB35: ※3 | BE35: 単票画面は記載しない
D36: ※2 | G36: 吹き出しでカスタマイズ内容を記載する | BB36: ※4 | BE36: 集計・グラフ機能を使用する場合に記載する
BB37: ※5 | BE37: 共通設定のみ記載する(個別設定は、記載しない)

Sheet 表紙
AW2: サブモジュール
AW3: MA_マスタ管理
AW4: MB_業務共通
AW5: MG_原価管理
AW6: MSBA_需給管理
M7: 基本設計 | AW7: MSBB_販売管理
AW8: MSBC_生産管理
AW9: MSBD_購買管理
M10: アドオン設計書 | AW10: MSBE_在庫物流管理
AW11: MSBF_品質管理
AW12: MSBG_債権管理
AW13: MSBH_債務管理
AW14: MSBI_締処理
AW15: MSUA_リスト・入力補助
M16: 顧客 | U16: 株式会社クラウン・パッケージ | AW16: PF_ESBアダプタ
M18: プロジェクト名 | U18: 基幹システム刷新PJ | AW18: 機能区分
AW19: 画面
M20: 文書番号 | AW20: 帳票
AW21: バッチ
M22: Ｒｅｖ． | U22: {=MAX(_xlfn.NUMBERVALUE(改訂!A7:E44))} -> 1 | AW22: マスタ
M24: 機密性区分 | U24: 取扱注意（Ｃ） | AW24: 開発区分
AW25: カスタマイズ
M26: システム名 | U26: mcframe7 | AC26: Ver. | AE26: 7.0.2 | AW26: アドオン
AW27: －
M28: サブモジュール | U28: MSBB_販売管理
M30: 機能名 | U30: =M50 -> シート単価マスタ
M32: 機能ID | U32: =G50 -> MSBBPA130
M34: 機能区分 | U34: 画面
M36: 開発区分 | U36: アドオン
W39: 作成 | AB39: 最終更新 | AG39: ご確認
W40: MDSOL
W42: 44824
A48: 文書番号 | G48: 画面ID | M48: 画面名 | V48: Version | AB48: Revision
A50: M7-US-1140 | G50: MSBBPA130 | M50: シート単価マスタ | V50: 1.0.0 | AB50: r01.00
A53: 共通（元データ）
A54: Webシステム | K54: 文書名 | U54: モジュールID | Z54: MS | AE54: モジュール名 | AJ54: Webシステム | AS54: 文書番号 | AZ54: Version | BF54: Rev.
K55: 画面説明書 | U55: ｻﾌﾞﾓｼﾞｭｰﾙID | Z55: MSBB | AE55: ｻﾌﾞﾓｼﾞｭｰﾙ名 | AJ55: 販売Webシステム | AS55: M7-US-1140 | AZ55: 1.0.0 | BF55: r00.00
K56: 表紙 | U56: 表題 | Z56: MSBBPA130 | AE56: Webシート単価マスタ
A57: 共通（リンク用）
A58: =A54 -> Webシステム | K58: 文書名 | U58: モジュールID | Z58: =Z54 -> MS | AE58: モジュール名 | AJ58: =AJ54 -> Webシステム | AS58: 文書番号 | AZ58: Version | BF58: Rev.
...

Sheet 改訂
A1: 第7章 | K1: 改訂 | AU1: 作成者 | AZ1: MDSOL | BE1: 作成日 | BJ1: =表紙!W42 -> 44824 | BP1: Rev.
AU2: 修正者 | BE2: 改訂日 | BP2: =表紙!CB64 -> 1
A5: Rev. | F5: 改定内容 | BC5: 頁 | BM5: 変更日 変更者 | BR5: 確認日 確認者
A7: 1 | F7: 新規作成

Sheet 概要
A1: =表紙!A54 -> Webシステム | O1: 文書名 | AC1: モジュールID | AJ1: =表紙!AJ63 -> MS | AQ1: モジュール名 | AX1: =表紙!AX63 -> Webシステム | BL1: 文書番号 | BU1: Version | CB1: Rev.
O2: =表紙!O64 -> アドオン設計書 | AC2: サブモジュールID | AJ2: =表紙!AJ64 -> MSBB | AQ2: サブモジュール名 | AX2: =表紙!AX64 -> 販売Webシステム | BL2: =表紙!BL64 -> M7-US-1140 | BU2: =表紙!BU64 -> 7.0.2 | CB2: =表紙!CB64 -> 1
O3: =RIGHT(CELL("filename",$A$1),LEN(CELL("filename",$A$1))-FIND("]",CELL("filename",$A$1))) -> 概要 | AC3: 表題 | AJ3: =表紙!AJ65 -> MSBBPA130 | AQ3: =表紙!AQ65 -> Webシート単価マスタ
AO5: 概要
B7: 【説明】
C8: シート品の標準単価表、得意先別単価表を取込しシート単価マスタに登録する
B10: 【前提条件】
C11: 取込可能なEXCELファイルは、[.xls、xlsx形式]とする
B13: 【目的】
C14: シート単価をEXCELで取込、画面にて確認し更新する
B16: 【処理関連図/サービス関連図】
C17: ※処理・サービス関連図シートに詳細記載
B19: 【オペレーション一覧】
C20: シート品の標準単価表、得意先別単価表を参照する
C21: シート品の標準単価表、得意先別単価表を取り込む
D22: 取込結果を確認する
D23: 単価を更新する
B25: 【SQLID一覧】
C26: なし
B28: 【ソート順】
C29: 登録時 | F29: EXCEL取込順
C30: 参照時 | F30: 拠点、得意先、段、
F31: 原紙CD(表)、印刷CD(表)、エンボスCD(表)
F32: 原紙CD(中)、印刷CD(中)、エンボスCD(中)
F33: 原紙CD(裏)、印刷CD(裏)、エンボスCD(裏)
F34: 改定日(降順)
B36: 【データアクセスコントロール】
C37: 拠点による制御
C38: ※詳細は、【MSBBPA000】_共通設計書_アドオン(Webシステム共通仕様)にて定義
B40: 【自由記述】
C41: なし

Sheet 画面イメージ
A1: =表紙!A54 -> Webシステム | K1: 文書名 | U1: モジュールID | Z1: =表紙!$AJ$63 -> MS | AE1: モジュール名 | AJ1: =表紙!$AX$63 -> Webシステム | AS1: 文書番号 | AZ1: Version | BF1: Rev.
K2: =表紙!O64 -> アドオン設計書 | U2: ｻﾌﾞﾓｼﾞｭｰﾙID | Z2: =表紙!$AJ$64 -> MSBB | AE2: ｻﾌﾞﾓｼﾞｭｰﾙ名 | AJ2: =表紙!$AX$64 -> 販売Webシステム | AS2: =表紙!$BL$64 -> M7-US-1140 | AZ2: =表紙!$BU$64 -> 7.0.2 | BF2: =表紙!$CB$64 -> 1
K3: =RIGHT(CELL("filename",$A$1),LEN(CELL("filename",$A$1))-FIND("]",CELL("filename",$A$1))) -> 画面イメージ | U3: 表題 | Z3: =表紙!$AJ$65 -> MSBBPA130 | AE3: =表紙!$AQ$65 -> Webシート単価マスタ
A5: 画面イメージ
B7: ≫凡例
Q8: ・・・ | S8: ボタン
C9: 見積計算書NO | Q9: ・・・ | S9: 検索項目(検索画面表示選択) | AJ9: 参照情報
C10: 品名 | Q10: ・・・ | S10: 入力項目
C11: 得意先 | Q11: ・・・ | S11: 表示項目(得意先名称、原紙名等) | AJ11: 担当者
C12: 操作種別 | I12: ●登録 | M12: ○訂正 | Q12: ・・・ | S12: 選択項目(一つのみ選択可能)
C13: 受注区分 | Q13: ・・・ | S13: 選択項目(一つのみ選択可能)
C14: 作業順 | I14: ☑AAA | M14: ☑BBB | Q14: ・・・ | S14: 選択項目(複数選択可能)
C16: 見積作成日 | Q16: ・・・ | S16: カレンダー形式
D21: 操作種別 | J21: ●登録 | N21: ○参照
D24: 基本情報
D25: 基準日(改定日)
D26: 拠点 | W26: ※標準単価は、拠点単位に異なる。
D27: 取込区分 | J27: ●シート単価 | P27: ○シート単価(見積用)
D29: 取込
D30: ファイルパス
D32: 表示条件
D33: 営業担当
D34: 得意先
D38: NO | F38: 選択 | H38: 拠点 | J38: 拠点名 | M38: 営業 | P38: 営業 | T38: 得意先 | W38: 得意先名 | AA38: 構成情報 | BG38: 単価 | BK38: 改定日
M39: 担当 | P39: 担当名 | AA39: 段 | AC39: 原紙表 | AG39: 印刷表 | AJ39: ｴﾝﾎﾞｽ表 | AM39: 原紙中 | AQ39: 印刷中 | AT39: ｴﾝﾎﾞｽ中 | AW39: 原紙裏 | BA39: 印刷裏 | BD39: ｴﾝﾎﾞｽ裏
D40: 1 | F40: ☑ | H40: 10 | J40: XXXXX6 | M40: XXXX | P40: XXXXXXX8 | T40: 12345 | W40: XXXXXXX8 | AA40: XX | AC40: XXXXXXX8 | AG40: XXXX | AJ40: XXXX | AM40: XXXXXXX8 | AQ40: XXXX | AT40: XXXX | AW40: XXXXXXX8 | BA40: XXXX | BD40: XXXX | BG40: 9999999 | BK40: 2022/9/01
D41: 2 | F41: ☑ | H41: 10 | J41: XXXXX6 | M41: XXXX | P41: XXXXXXX8 | T41: 12345 | W41: XXXXXXX8 | AA41: XX | AC41: XXXXXXX8 | AG41: XXXX | AJ41: XXXX | AM41: XXXXXXX8 | AQ41: XXXX | AT41: XXXX | AW41: XXXXXXX8 | BA41: XXXX | BD41: XXXX | BG41: 9999999 | BK41: 2022/9/01
D42: 3 | F42: ☑ | H42: 10 | J42: XXXXX6 | M42: XXXX | P42: XXXXXXX8 | T42: 12345 | W42: XXXXXXX8 | AA42: XX | AC42: XXXXXXX8 | AG42: XXXX | AJ42: XXXX | AM42: XXXXXXX8 | AQ42: XXXX | AT42: XXXX | AW42: XXXXXXX8 | BA42: XXXX | BD42: XXXX | BG42: 9999999 | BK42: 2022/9/01
D43: 4 | F43: □ | H43: 10 | J43: XXXXX6 | M43: XXXX | P43: XXXXXXX8 | T43: 12345 | W43: XXXXXXX8 | AA43: XX | AC43: XXXXXXX8 | AG43: XXXX | AJ43: XXXX | AM43: XXXXXXX8 | AQ43: XXXX | AT43: XXXX | AW43: XXXXXXX8 | BA43: XXXX | BD43: XXXX | BG43: 9999999 | BK43: 2022/9/01 | BW43: CP指摘 2022/10/20 本多 未来日で新単価と改定日を入力した場合、現単価はどのように表示されますか？
D44: 5 | F44: □ | H44: 10 | J44: XXXXX6 | M44: XXXX | P44: XXXXXXX8 | T44: 12345 | W44: XXXXXXX8 | AA44: XX | AC44: XXXXXXX8 | AG44: XXXX | AJ44: XXXX | AM44: XXXXXXX8 | AQ44: XXXX | AT44: XXXX | AW44: XXXXXXX8 | BA44: XXXX | BD44: XXXX | BG44: 9999999 | BK44: 2022/9/01
D45: 6 | F45: □ | H45: 10 | J45: XXXXX6 | M45: XXXX | P45: XXXXXXX8 | T45: 12345 | W45: XXXXXXX8 | AA45: XX | AC45: XXXXXXX8 | AG45: XXXX | AJ45: XXXX | AM45: XXXXXXX8 | AQ45: XXXX | AT45: XXXX | AW45: XXXXXXX8 | BA45: XXXX | BD45: XXXX | BG45: 9999999 | BK45: 2022/9/01 | CF45: MDSOL 野村 2022/10/25 | CU45: 2022/10/27 落合 問題なし
D46: 7 | F46: □ | H46: 10 | J46: XXXXX6 | M46: XXXX | P46: XXXXXXX8 | T46: 12345 | W46: XXXXXXX8 | AA46: XX | AC46: XXXXXXX8 | AG46: XXXX | AJ46: XXXX | AM46: XXXXXXX8 | AQ46: XXXX | AT46: XXXX | AW46: XXXXXXX8 | BA46: XXXX | BD46: XXXX | BG46: 9999999 | BK46: 2022/9/01 | CF46: 基準日以降のデータを表示します。
D47: 8 | F47: □ | H47: 10 | J47: XXXXX6 | M47: XXXX | P47: XXXXXXX8 | T47: 12345 | W47: XXXXXXX8 | AA47: XX | AC47: XXXXXXX8 | AG47: XXXX | AJ47: XXXX | AM47: XXXXXXX8 | AQ47: XXXX | AT47: XXXX | AW47: XXXXXXX8 | BA47: XXXX | BD47: XXXX | BG47: 9999999 | BK47: 2022/9/01 | CF47: 基準日(改定日)：2020/4/01で表示した場合
D48: 9 | F48: □ | H48: 10 | J48: XXXXX6 | M48: XXXX | P48: XXXXXXX8 | T48: 12345 | W48: XXXXXXX8 | AA48: XX | AC48: XXXXXXX8 | AG48: XXXX | AJ48: XXXX | AM48: XXXXXXX8 | AQ48: XXXX | AT48: XXXX | AW48: XXXXXXX8 | BA48: XXXX | BD48: XXXX | BG48: 9999999 | BK48: 2022/9/01
D49: 10 | F49: □ | H49: 10 | J49: XXXXX6 | M49: XXXX | P49: XXXXXXX8 | T49: 12345 | W49: XXXXXXX8 | AA49: XX | AC49: XXXXXXX8 | AG49: XXXX | AJ49: XXXX | AM49: XXXXXXX8 | AQ49: XXXX | AT49: XXXX | AW49: XXXXXXX8 | BA49: XXXX | BD49: XXXX | BG49: 9999999 | BK49: 2022/9/01 | CF49: NO | CH49: 選択 | CJ49: 拠点 | CL49: 拠点名 | CO49: 営業 | CR49: 営業 | CV49: 得意先 | CY49: 得意先名 | DC49: 構成情報 | EI49: 単価 | EM49: 改定日
D50: ◁ | BG50: ▷ | CO50: 担当 | CR50: 担当名 | DC50: 段 | DE50: 原紙表 | DI50: 印刷表 | DL50: ｴﾝﾎﾞｽ表 | DO50: 原紙中 | DS50: 印刷中 | DV50: ｴﾝﾎﾞｽ中 | DY50: 原紙裏 | EC50: 印刷裏 | EF50: ｴﾝﾎﾞｽ裏
CF51: 1 | CH51: ☑ | CJ51: 10 | CL51: XXXXX6 | CO51: XXXX | CR51: XXXXXXX8 | CV51: 12345 | CY51: XXXXXXX8 | DC51: E | DE51: AAA | DI51: BBB | DL51: CCC | DO51: AAA | DS51: BBB | DV51: CCC | DY51: AAA | EC51: BBB | EF51: CCC | EI51: 1000 | EM51: 2020/4/1
CF52: 2 | CH52: ☑ | CJ52: 10 | CL52: XXXXX6 | CO52: XXXX | CR52: XXXXXXX8 | CV52: 12345 | CY52: XXXXXXX8 | DC52: E | DE52: AAA | DI52: BBB | DL52: CCC | DO52: AAA | DS52: BBB | DV52: CCC | DY52: AAA | EC52: BBB | EF52: CCC | EI52: 1100 | EM52: 2020/5/1
CF55: 非表示 | CH55: ☑ | CJ55: 10 | CL55: XXXXX6 | CO55: XXXX | CR55: XXXXXXX8 | CV55: 12345 | CY55: XXXXXXX8 | DC55: E | DE55: AAA | DI55: BBB | DL55: CCC | DO55: AAA | DS55: BBB | DV55: CCC | DY55: AAA | EC55: BBB | EF55: CCC | EI55: 900 | EM55: 2020/1/1
CF57: 2020/1/1 ～ 2020/3/31 | CO57: … | CP57: 単価 900
...

Sheet レイアウト(変更前)
A1: =表紙!A54 -> Webシステム | K1: 文書名 | U1: モジュールID | Z1: =表紙!$AJ$63 -> MS | AE1: モジュール名 | AJ1: =表紙!$AX$63 -> Webシステム | AS1: 文書番号 | AZ1: Version | BF1: Rev.
K2: =表紙!O64 -> アドオン設計書 | U2: ｻﾌﾞﾓｼﾞｭｰﾙID | Z2: =表紙!$AJ$64 -> MSBB | AE2: ｻﾌﾞﾓｼﾞｭｰﾙ名 | AJ2: =表紙!$AX$64 -> 販売Webシステム | AS2: =表紙!$BL$64 -> M7-US-1140 | AZ2: =表紙!$BU$64 -> 7.0.2 | BF2: =表紙!$CB$64 -> 1
K3: =RIGHT(CELL("filename",$A$1),LEN(CELL("filename",$A$1))-FIND("]",CELL("filename",$A$1))) -> レイアウト(変更前) | U3: 表題 | Z3: =表紙!$AJ$65 -> MSBBPA130 | AE3: =表紙!$AQ$65 -> Webシート単価マスタ
A5: 画面イメージ
B7: ≫凡例
Q8: ・・・ | S8: ボタン
C9: 見積計算書№ | Q9: ・・・ | S9: 検索項目(検索画面表示選択)
C10: 品名 | Q10: ・・・ | S10: 入力項目
C11: 得意先 | Q11: ・・・ | S11: 表示項目(得意先名称、原紙名等)
C12: 操作種別 | I12: ●登録 | M12: ○訂正 | Q12: ・・・ | S12: 選択項目(一つのみ選択可能)
C13: 受注区分 | Q13: ・・・ | S13: 選択項目(一つのみ選択可能)
C14: 作業順 | I14: ☑AAA | M14: ☑BBB | Q14: ・・・ | S14: 選択項目(複数選択可能)
D20: 取込条件
D22: 取込区分 | J22: ●標準 | N22: 〇得意先別
O23: 得意先
D25: ファイルパス
D29: 取込内容
D32: № | G32: 選択 | I32: 得意先コード | N32: 得意先名 | T32: 段 | W32: 原紙表 | AA32: 印刷表 | AE32: エンボス表 | AI32: 原紙中 | AM32: 印刷中 | AQ32: エンボス | AU32: 原紙裏 | AY32: 印刷裏 | BC32: 印刷裏 | BG32: 単価
E33: 1 | G33: □
E34: 2 | G34: □
E35: 3 | G35: □
E36: 4 | G36: □
E37: 5 | G37: □
E38: 6 | G38: □
E39: 7 | G39: □
E40: 8 | G40: □
E41: 9 | G41: □
D42: 10 | G42: □

Sheet 現行画面
A1: =表紙!A54 -> Webシステム | K1: 文書名 | U1: モジュールID | Z1: =表紙!$AJ$63 -> MS | AE1: モジュール名 | AJ1: =表紙!$AX$63 -> Webシステム | AS1: 文書番号 | AZ1: Version | BF1: Rev.
K2: =表紙!O64 -> アドオン設計書 | U2: ｻﾌﾞﾓｼﾞｭｰﾙID | Z2: =表紙!$AJ$64 -> MSBB | AE2: ｻﾌﾞﾓｼﾞｭｰﾙ名 | AJ2: =表紙!$AX$64 -> 販売Webシステム | AS2: =表紙!$BL$64 -> M7-US-1140 | AZ2: =表紙!$BU$64 -> 7.0.2 | BF2: =表紙!$CB$64 -> 1
K3: =RIGHT(CELL("filename",$A$1),LEN(CELL("filename",$A$1))-FIND("]",CELL("filename",$A$1))) -> 現行画面 | U3: 表題 | Z3: =表紙!$AJ$65 -> MSBBPA130 | AE3: =表紙!$AQ$65 -> Webシート単価マスタ
A5: 画面イメージ

Sheet 項目説明
A1: =表紙!A54 -> Webシステム | K1: 文書名 | U1: モジュールID | Z1: =表紙!$AJ$63 -> MS | AE1: モジュール名 | AJ1: =表紙!$AX$63 -> Webシステム | AS1: 文書番号 | AZ1: Version | BF1: Rev.
K2: =表紙!O64 -> アドオン設計書 | U2: ｻﾌﾞﾓｼﾞｭｰﾙID | Z2: =表紙!$AJ$64 -> MSBB | AE2: ｻﾌﾞﾓｼﾞｭｰﾙ名 | AJ2: =表紙!$AX$64 -> 販売Webシステム | AS2: =表紙!$BL$64 -> M7-US-1140 | AZ2: =表紙!$BU$64 -> 7.0.2 | BF2: =表紙!$CB$64 -> 1
K3: =RIGHT(CELL("filename",$A$1),LEN(CELL("filename",$A$1))-FIND("]",CELL("filename",$A$1))) -> 項目説明 | U3: 表題 | Z3: =表紙!$AJ$65 -> MSBBPA130 | AE3: =表紙!$AQ$65 -> Webシート単価マスタ
A5: Webシート単価マスタ
B6: 操作種別 | N6: 説明 | BE6: Ｗ | BF6: 型 | BG6: 参 | BH6: 必 | BI6: 入 | BJ6: 非 | BK6: 検
A7: ● | B7: 登録 | M7: 【MSBBPA000】_共通設計書_アドオン(Webシステム共通仕様)にて定義 | BE7: R
A8: ● | B8: 参照 | M8: 【MSBBPA000】_共通設計書_アドオン(Webシステム共通仕様)にて定義 | BE8: R
B9: 基本情報 | N9: 説明 | BE9: Ｗ | BF9: 型 | BG9: 参 | BH9: 必 | BI9: 入 | BJ9: 非 | BK9: 検
A10: 〇 | B10: 基準日 | M10: 基準日を指定する | AJ10: ※初期値は本日日付とする | BE10: カ | BF10: D | BH10: 必
A11: 〇 | B11: 拠点 | M11: 【MSBBPACOM】_共通設計書_アドオン(共通ロジック)にて定義 | BE11: C | BF11: S | BH11: 必
A12: 〇 | B12: 取込区分 | M12: 取込区分を選択する(取込/表示するマスタを選択) | BE12: R | BF12: S
B13: 取込条件 | N13: 説明 | BE13: Ｗ | BF13: 型 | BG13: 参 | BH13: 必 | BI13: 入 | BJ13: 非 | BK13: 検
A14: 〇 | B14: ファイルパス | M14: ファイル選択のダイアログを表示する | AJ14: ※操作種別が登録の場合、有効 | BE14: T | BF14: S | BK14: 検
B15: 表示条件 | N15: 説明 | BE15: Ｗ | BF15: 型 | BG15: 参 | BH15: 必 | BI15: 入 | BJ15: 非 | BK15: 検
A16: 〇 | B16: 得意先 | M16: 【MSBBPACOM】_共通設計書_アドオン(共通ロジック)にて定義 | AJ16: ※操作種別が参照の場合、有効 | BE16: A | BF16: S | BK16: 検
A17: 〇 | B17: 営業担当 | M17: 【MSBBPACOM】_共通設計書_アドオン(共通ロジック)にて定義 | AJ17: ※操作種別が参照の場合、有効 | BE17: C | BF17: S | BK17: 検
B18: シート単価明細 | N18: 説明 | BE18: Ｗ | BF18: 型 | BG18: 参 | BH18: 必 | BI18: 入 | BJ18: 非 | BK18: 検
B19: NO | M19: 行番を表示 | BE19: T | BF19: N
A20: ● | B20: 選択 | M20: 更新対象とする行データに対して☑する | BE20: チ | BF20: N
B21: 拠点 | M21: 拠点を表示 | BE21: T | BF21: S
B22: 拠点名 | M22: 拠点名を表示 | BE22: T | BF22: S
B23: 営業担当 | M23: 営業担当を表示 | BE23: T | BF23: S
B24: 営業担当名 | M24: 営業担当名を表示 | BE24: T | BF24: S | BP24: CP指摘 2022/10/20 本多 現状では１レコードに現単価と現行単価適用日、新単価と新単価適用日を持っていますが、新基幹では新旧単価は別レコードとして存在するという認識ですか？
B25: 得意先 | M25: 得意先を表示 | BE25: T | BF25: S | BP25: MDSOL 野村 2022/10/25 はい。ご認識の通りです。 | CI25: 2022/10/27 落合 問題なし
B26: 得意先名 | M26: 得意先名を表示 | BE26: T | BF26: S
B27: 段 | M27: 段を表示 | BE27: T | BF27: S
B28: 原紙表 | M28: 原紙表を表示 | BE28: T | BF28: S
B29: 印刷表 | M29: 印刷表を表示 | BE29: T | BF29: S
B30: エンボス表 | M30: エンボス表を表示 | BE30: T | BF30: S
B31: 原紙中 | M31: 原紙中を表示 | BE31: T | BF31: S
B32: 印刷中 | M32: 印刷中を表示 | BE32: T | BF32: S
B33: エンボス中 | M33: エンボス中を表示 | BE33: T | BF33: S
B34: 原紙裏 | M34: 原紙裏を表示 | BE34: T | BF34: S
B35: 印刷裏 | M35: 印刷裏を表示 | BE35: T | BF35: S
B36: エンボス裏 | M36: エンボス裏を表示 | BE36: T | BF36: S
B37: 単価 | M37: 単価を表示 | BE37: T | BF37: N
B38: 改定日 | M38: 改定日を表示 | BE38: T | BF38: D
B40: 共通項目 | BE40: Ｗ | BF40: 型 | BG40: 参 | BH40: 必 | BI40: 入 | BJ40: 非 | BK40: 検
B41: 全選択 | M41: シート単価一覧の選択チェックを全てチェック=ONとする | BE41: チ | BF41: F
B42: 全解除 | M42: シート単価一覧の選択チェックを全てチェック=OFFとする | BE42: チ | BF42: F
...

Sheet 引数説明
A1: =表紙!A54 -> Webシステム | K1: 文書名 | U1: モジュールID | Z1: =表紙!$AJ$63 -> MS | AE1: モジュール名 | AJ1: =表紙!$AX$63 -> Webシステム | AS1: 文書番号 | AZ1: Version | BF1: Rev.
K2: =表紙!O64 -> アドオン設計書 | U2: ｻﾌﾞﾓｼﾞｭｰﾙID | Z2: =表紙!$AJ$64 -> MSBB | AE2: ｻﾌﾞﾓｼﾞｭｰﾙ名 | AJ2: =表紙!$AX$64 -> 販売Webシステム | AS2: =表紙!$BL$64 -> M7-US-1140 | AZ2: =表紙!$BU$64 -> 7.0.2 | BF2: =表紙!$CB$64 -> 1
K3: =RIGHT(CELL("filename",$A$1),LEN(CELL("filename",$A$1))-FIND("]",CELL("filename",$A$1))) -> 引数説明 | U3: 表題 | Z3: =表紙!$AJ$65 -> MSBBPA130 | AE3: =表紙!$AQ$65 -> Webシート単価マスタ
B5: オペレーションＩＤ/名称：SloRecvIfImp_Upd01/取込
A6: 必 | B6: 項目名 | N6: 説明 | AS6: 未設定時の振る舞い

Sheet 処理概要
A1: =表紙!A54 -> Webシステム | K1: 文書名 | U1: モジュールID | Z1: =表紙!$AJ$63 -> MS | AE1: モジュール名 | AJ1: =表紙!$AX$63 -> Webシステム | AS1: 文書番号 | AZ1: Version | BF1: Rev.
K2: =表紙!O64 -> アドオン設計書 | U2: ｻﾌﾞﾓｼﾞｭｰﾙID | Z2: =表紙!$AJ$64 -> MSBB | AE2: ｻﾌﾞﾓｼﾞｭｰﾙ名 | AJ2: =表紙!$AX$64 -> 販売Webシステム | AS2: =表紙!$BL$64 -> M7-US-1140 | AZ2: =表紙!$BU$64 -> 7.0.2 | BF2: =表紙!$CB$64 -> 1
K3: =RIGHT(CELL("filename",$A$1),LEN(CELL("filename",$A$1))-FIND("]",CELL("filename",$A$1))) -> 処理概要 | U3: 表題 | Z3: =表紙!$AJ$65 -> MSBBPA130 | AE3: =表紙!$AQ$65 -> Webシート単価マスタ
A5: No | B5: 入力 | J5: 処理 | BD5: 出力
A6: 1 | B6: 初期表示
J7: 1.初期設定
K8: 操作種別 | Q8: ： | R8: 登録をチェック
K9: 基準日 | Q9: ： | R9: 本日日付を表示する
K10: 拠点 | Q10: ： | R10: ログインに紐づく拠点CDを表示する
R11: ログイン.管理者区分 = 0(一般ユーザー時)、変更不可とする
K12: 取込区分 | Q12: ： | R12: シート単価をチェック
A14: 2 | B14: 操作種別選択処理 | J14: 操作種別変更時
K15: 操作種別：登録 選択時 | S15: … | U15: 表示ボタン非表示、更新ボタン表示
K16: 操作種別：参照 選択時 | S16: … | U16: 表示ボタン表示、更新ボタン非表示
A18: 3 | B18: ファイルパス | J18: ファイル選択後処理
J19: 1.既定のフォーマット(EXCEL)を読込み
K20: 読込みエラーの場合、メッセージ表示 | BD20: メッセージID.002
J21: 2.項目数のチェックを行う
K22: 既定のフォーマット(EXCEL)：13項目 | BD22: メッセージID.003
J23: 3.必須項目のチェックを行う
K24: 拠点、得意先、段、原紙表、印刷表、エンボス表、原紙中、印刷中、エンボス中、原紙裏、印刷裏、エンボス裏、単価 | BD24: メッセージID.004
J25: 4.項目型のチェックを行う
K26: 単価、改定日 | BD26: メッセージID.005
J27: 5.マスタ存在のチェックを行う
K28: 拠点、得意先、段、原紙表、印刷表、エンボス表、原紙中、印刷中、エンボス中、原紙裏、印刷裏、エンボス裏 | BD28: メッセージID.006
J29: 6.同一のデータチェックを行う
L30: 存在チェック | R30: 確認メッセージ：同じデータが登録されています。上書きしますか。(はい・いいえ) | BD30: メッセージID.007
S31: はい：処理を続行する
S32: いいえ：後続処理をキャンセルする
L33: 存在チェック仕様
N34: 取込データ内に下記をキーとした重複データが1件でも存在する場合、確認メッセージを表示
N35: 改定日、拠点、得意先CD、段、原紙CD(表)、印刷CD(表)、エンボスCD(表)、原紙CD(中)、印刷CD(中)、
N36: エンボスCD(中)、原紙CD(裏)、印刷CD(裏)、エンボスCD(裏)
J38: 7.一覧にデータセットする | BD38: 検索入出力仕様.NO1
A40: 4 | B40: クリア
J41: 1.画面を初期化する(起動時の状態とする)
A43: 5 | B43: 表示
J44: 1.チェック処理
K45: チェック処理にてエラーとなった場合、後続処理をキャンセルする
L46: 必須チェック | AA46: エラーメッセージ：必須項目に値が指定されていません。項目名：パラメータ | BD46: メッセージID.008
...

Sheet 処理詳細
A1: =表紙!A54 -> Webシステム | K1: 文書名 | U1: モジュールID | Z1: =表紙!$AJ$63 -> MS | AE1: モジュール名 | AJ1: =表紙!$AX$63 -> Webシステム | AS1: 文書番号 | AZ1: Version | BF1: Rev.
K2: =表紙!O64 -> アドオン設計書 | U2: ｻﾌﾞﾓｼﾞｭｰﾙID | Z2: =表紙!$AJ$64 -> MSBB | AE2: ｻﾌﾞﾓｼﾞｭｰﾙ名 | AJ2: =表紙!$AX$64 -> 販売Webシステム | AS2: =表紙!$BL$64 -> M7-US-1140 | AZ2: =表紙!$BU$64 -> 7.0.2 | BF2: =表紙!$CB$64 -> 1
K3: =RIGHT(CELL("filename",$A$1),LEN(CELL("filename",$A$1))-FIND("]",CELL("filename",$A$1))) -> 処理詳細 | U3: 表題 | Z3: =表紙!$AJ$65 -> MSBBPA130 | AE3: =表紙!$AQ$65 -> Webシート単価マスタ
A5: No | B5: 入力 | J5: 処理 | BD5: 出力
A6: 1 | B6: 初期表示
A12: 2 | B12: 画面操作
A18: 3 | B18: 検索【F1】

Sheet 処理・サービス関連図
A1: =表紙!A54 -> Webシステム | K1: 文書名 | U1: モジュールID | Z1: =表紙!$AJ$63 -> MS | AE1: モジュール名 | AJ1: =表紙!$AX$63 -> Webシステム | AS1: 文書番号 | AZ1: Version | BF1: Rev.
K2: =表紙!O64 -> アドオン設計書 | U2: ｻﾌﾞﾓｼﾞｭｰﾙID | Z2: =表紙!$AJ$64 -> MSBB | AE2: ｻﾌﾞﾓｼﾞｭｰﾙ名 | AJ2: =表紙!$AX$64 -> 販売Webシステム | AS2: =表紙!$BL$64 -> M7-US-1140 | AZ2: =表紙!$BU$64 -> 7.0.2 | BF2: =表紙!$CB$64 -> 1
K3: =RIGHT(CELL("filename",$A$1),LEN(CELL("filename",$A$1))-FIND("]",CELL("filename",$A$1))) -> 処理・サービス関連図 | U3: 表題 | Z3: =表紙!$AJ$65 -> MSBBPA130 | AE3: =表紙!$AQ$65 -> Webシート単価マスタ
C7: 検索処理
C26: ファイル入力処理
C36: 更新処理

Sheet 検索入出力仕様
A1: =表紙!A54 -> Webシステム | K1: 文書名 | U1: モジュールID | Z1: =表紙!$AJ$63 -> MS | AE1: モジュール名 | AJ1: =表紙!$AX$63 -> Webシステム | AS1: 文書番号 | AZ1: Version | BF1: Rev.
K2: =表紙!O64 -> アドオン設計書 | U2: ｻﾌﾞﾓｼﾞｭｰﾙID | Z2: =表紙!$AJ$64 -> MSBB | AE2: ｻﾌﾞﾓｼﾞｭｰﾙ名 | AJ2: =表紙!$AX$64 -> 販売Webシステム | AS2: =表紙!$BL$64 -> M7-US-1140 | AZ2: =表紙!$BU$64 -> 7.0.2 | BF2: =表紙!$CB$64 -> 1
K3: =RIGHT(CELL("filename",$A$1),LEN(CELL("filename",$A$1))-FIND("]",CELL("filename",$A$1))) -> 検索入出力仕様 | U3: 表題 | Z3: =表紙!$AJ$65 -> MSBBPA130 | AE3: =表紙!$AQ$65 -> Webシート単価マスタ
A5: No | G5: 1 | S5: ボタン | Z5: ファイルパス | AH5: 備考
A6: 処理分類 | E6: 取込 | S6: ソート順
A7: No | C7: 転送先 | V7: 転送元 | AQ7: 説明
C8: 種 | D8: オブジェクト | K8: 項目名 | V8: 種 | W8: オブジェクト | AF8: 項目名
A9: 1 | C9: 画 | D9: シート単価明細 | K9: NO | AF9: 行番
A10: 2 | C10: 画 | D10: シート単価明細 | K10: 拠点 | V10: 画 | W10: 基本情報 | AF10: 拠点
A11: 3 | C11: 画 | D11: シート単価明細 | K11: 拠点名 | V11: 画 | W11: 基本情報 | AF11: 拠点名
A12: 4 | C12: 画 | D12: シート単価明細 | K12: 営業担当 | V12: T | W12: 得意先担当 | AF12: 営業担当 | AQ12: 得意先CD(取込先CD)＆基準日で得意先担当マスタより
A13: 5 | C13: 画 | D13: シート単価明細 | K13: 営業担当名 | V13: T | W13: 担当マスタ | AF13: 営業担当名 | AQ13: データを参照する
A14: 6 | C14: 画 | D14: シート単価明細 | K14: 得意先CD | V14: フ | W14: シート単価EXCEL | AF14: 得意先CD
A15: 7 | C15: 画 | D15: シート単価明細 | K15: 得意先名 | V15: T | W15: WEB取引先マスタ | AF15: 取引先名
A16: 8 | C16: 画 | D16: シート単価明細 | K16: 段 | V16: フ | W16: シート単価EXCEL | AF16: 段
A17: 9 | C17: 画 | D17: シート単価明細 | K17: 原紙表 | V17: フ | W17: シート単価EXCEL | AF17: 原紙表
A18: 10 | C18: 画 | D18: シート単価明細 | K18: 印刷表 | V18: フ | W18: シート単価EXCEL | AF18: 印刷表
A19: 11 | C19: 画 | D19: シート単価明細 | K19: エンボス表 | V19: フ | W19: シート単価EXCEL | AF19: エンボス表
A20: 12 | C20: 画 | D20: シート単価明細 | K20: 原紙中 | V20: フ | W20: シート単価EXCEL | AF20: 原紙中
A21: 13 | C21: 画 | D21: シート単価明細 | K21: 印刷中 | V21: フ | W21: シート単価EXCEL | AF21: 印刷中
A22: 14 | C22: 画 | D22: シート単価明細 | K22: エンボス中 | V22: フ | W22: シート単価EXCEL | AF22: エンボス中
A23: 15 | C23: 画 | D23: シート単価明細 | K23: 原紙裏 | V23: フ | W23: シート単価EXCEL | AF23: 原紙裏
A24: 16 | C24: 画 | D24: シート単価明細 | K24: 印刷裏 | V24: フ | W24: シート単価EXCEL | AF24: 印刷裏
A25: 17 | C25: 画 | D25: シート単価明細 | K25: エンボス裏 | V25: フ | W25: シート単価EXCEL | AF25: エンボス裏
... A27: 19 | C27: 画 | D27: シート単価明細 | K27: 改定日 | V27: 画 | W27: 基本情報 | AF27: 基準日
A30: No | G30: 2 | S30: ボタン | Z30: 検索 | AH30: 備考 | AK30: 取込区分=シート単価選択時
A31: 処理分類 | E31: 検索 | S31: ソート順
A32: No | C32: 転送先 | V32: 転送元 | AQ32: 説明
C33: 種 | D33: オブジェクト | K33: 項目名 | V33: 種 | W33: オブジェクト | AF33: 項目名
A34: 1 | C34: 画 | D34: シート単価明細 | K34: NO | AF34: 行番
A35: 2 | C35: 画 | D35: シート単価明細 | K35: 拠点 | V35: T | W35: WEBシート単価マスタ | AF35: 拠点
A36: 3 | C36: 画 | D36: シート単価明細 | K36: 拠点名 | V36: T | W36: 拠点マスタ | AF36: 拠点名
A37: 4 | C37: 画 | D37: シート単価明細 | K37: 営業担当 | V37: T | W37: 得意先担当 | AF37: 営業担当 | AQ37: 得意先CD(取込先CD)＆基準日で得意先担当マスタより
A38: 5 | C38: 画 | D38: シート単価明細 | K38: 営業担当名 | V38: T | W38: 担当マスタ | AF38: 営業担当名 | AQ38: データを参照する
A39: 6 | C39: 画 | D39: シート単価明細 | K39: 得意先CD | V39: T | W39: WEBシート単価マスタ | AF39: 得意先CD
A40: 7 | C40: 画 | D40: シート単価明細 | K40: 得意先名 | V40: T | W40: 取引先マスタ | AF40: 取引先名
A41: 8 | C41: 画 | D41: シート単価明細 | K41: 段 | V41: T | W41: WEBシート単価マスタ | AF41: 段
A42: 9 | C42: 画 | D42: シート単価明細 | K42: 原紙表 | V42: T | W42: WEBシート単価マスタ | AF42: 原紙表
A43: 10 | C43: 画 | D43: シート単価明細 | K43: 印刷表 | V43: T | W43: WEBシート単価マスタ | AF43: 印刷表
A44: 11 | C44: 画 | D44: シート単価明細 | K44: エンボス表 | V44: T | W44: WEBシート単価マスタ | AF44: エンボス表
...

Sheet 更新入出力仕様
A1: =表紙!A54 -> Webシステム | K1: 文書名 | U1: モジュールID | Z1: =表紙!$AJ$63 -> MS | AE1: モジュール名 | AJ1: =表紙!$AX$63 -> Webシステム | AS1: 文書番号 | AZ1: Version | BF1: Rev.
K2: =表紙!O64 -> アドオン設計書 | U2: ｻﾌﾞﾓｼﾞｭｰﾙID | Z2: =表紙!$AJ$64 -> MSBB | AE2: ｻﾌﾞﾓｼﾞｭｰﾙ名 | AJ2: =表紙!$AX$64 -> 販売Webシステム | AS2: =表紙!$BL$64 -> M7-US-1140 | AZ2: =表紙!$BU$64 -> 7.0.2 | BF2: =表紙!$CB$64 -> 1
K3: =RIGHT(CELL("filename",$A$1),LEN(CELL("filename",$A$1))-FIND("]",CELL("filename",$A$1))) -> 更新入出力仕様 | U3: 表題 | Z3: =表紙!$AJ$65 -> MSBBPA130 | AE3: =表紙!$AQ$65 -> Webシート単価マスタ
A5: No | G5: 1 | S5: ロジック名称 | Z5: Upd01 | AH5: 備考 | AK5: 取込区分=シート単価選択時
A6: 処理分類 | E6: 更新
A7: No | C7: 転送先 | V7: 転送元 | AQ7: 説明
C8: 種 | D8: オブジェクト | K8: 項目名 | V8: 種 | W8: オブジェクト | AF8: 項目名
A9: 1 | C9: T | D9: WEBシート単価マスタ | K9: 拠点 | V9: 画 | W9: シート単価明細 | AF9: 拠点
A10: 2 | C10: T | D10: WEBシート単価マスタ | K10: 得意先CD | V10: 画 | W10: シート単価明細 | AF10: 得意先CD
A11: 3 | C11: T | D11: WEBシート単価マスタ | K11: 段 | V11: 画 | W11: シート単価明細 | AF11: 段
A12: 4 | C12: T | D12: WEBシート単価マスタ | K12: 原紙表 | V12: 画 | W12: シート単価明細 | AF12: 原紙表
A13: 5 | C13: T | D13: WEBシート単価マスタ | K13: 印刷表 | V13: 画 | W13: シート単価明細 | AF13: 印刷表
A14: 6 | C14: T | D14: WEBシート単価マスタ | K14: エンボス表 | V14: 画 | W14: シート単価明細 | AF14: エンボス表
A15: 7 | C15: T | D15: WEBシート単価マスタ | K15: 原紙中 | V15: 画 | W15: シート単価明細 | AF15: 原紙中
A16: 8 | C16: T | D16: WEBシート単価マスタ | K16: 印刷中 | V16: 画 | W16: シート単価明細 | AF16: 印刷中
A17: 9 | C17: T | D17: WEBシート単価マスタ | K17: エンボス中 | V17: 画 | W17: シート単価明細 | AF17: エンボス中
A18: 10 | C18: T | D18: WEBシート単価マスタ | K18: 原紙裏 | V18: 画 | W18: シート単価明細 | AF18: 原紙裏
A19: 11 | C19: T | D19: WEBシート単価マスタ | K19: 印刷裏 | V19: 画 | W19: シート単価明細 | AF19: 印刷裏
A20: 12 | C20: T | D20: WEBシート単価マスタ | K20: エンボス裏 | V20: 画 | W20: シート単価明細 | AF20: エンボス裏
... A22: 14 | C22: T | D22: WEBシート単価マスタ | K22: 改定日 | V22: 画 | W22: シート単価明細 | AF22: 改定日
A24: No | G24: 1’ | S24: ロジック名称 | Z24: Upd01 | AH24: 備考 | AK24: 取込区分=シート単価(見積用)選択時
A25: 処理分類 | E25: 更新
A26: No | C26: 転送先 | V26: 転送元 | AQ26: 説明
C27: 種 | D27: オブジェクト | K27: 項目名 | V27: 種 | W27: オブジェクト | AF27: 項目名
A28: 1 | C28: T | D28: WEBシート単価マスタ | K28: 拠点 | V28: 画 | W28: シート単価明細 | AF28: 拠点
A29: 2 | C29: T | D29: WEBシート単価マスタ | K29: 得意先CD | V29: 画 | W29: シート単価明細 | AF29: 得意先CD
A30: 3 | C30: T | D30: WEBシート単価マスタ | K30: 段 | V30: 画 | W30: シート単価明細 | AF30: 段
A31: 4 | C31: T | D31: WEBシート単価マスタ | K31: 原紙表 | V31: 画 | W31: シート単価明細 | AF31: 原紙表
A32: 5 | C32: T | D32: WEBシート単価マスタ | K32: 印刷表 | V32: 画 | W32: シート単価明細 | AF32: 印刷表
A33: 6 | C33: T | D33: WEBシート単価マスタ | K33: エンボス表 | V33: 画 | W33: シート単価明細 | AF33: エンボス表
A34: 7 | C34: T | D34: WEBシート単価マスタ | K34: 原紙中 | V34: 画 | W34: シート単価明細 | AF34: 原紙中
A35: 8 | C35: T | D35: WEBシート単価マスタ | K35: 印刷中 | V35: 画 | W35: シート単価明細 | AF35: 印刷中
A36: 9 | C36: T | D36: WEBシート単価マスタ | K36: エンボス中 | V36: 画 | W36: シート単価明細 | AF36: エンボス中
A37: 10 | C37: T | D37: WEBシート単価マスタ | K37: 原紙裏 | V37: 画 | W37: シート単価明細 | AF37: 原紙裏
A38: 11 | C38: T | D38: WEBシート単価マスタ | K38: 印刷裏 | V38: 画 | W38: シート単価明細 | AF38: 印刷裏
A39: 12 | C39: T | D39: WEBシート単価マスタ | K39: エンボス裏 | V39: 画 | W39: シート単価明細 | AF39: エンボス裏
... A41: 14 | C41: T | D41: WEBシート単価マスタ | K41: 改定日 | V41: 画 | W41: シート単価明細 | AF41: 改定日
D43: ※転送先オブジェクト | K43: 取込区分=シート単価時、WEBシート単価マスタ
K44: 取込区分=シート単価(見積用)、WEBシート単価(見積用)マスタ

Sheet 画面遷移
A1: =表紙!A54 -> Webシステム | K1: 文書名 | U1: モジュールID | Z1: =表紙!$AJ$63 -> MS | AE1: モジュール名 | AJ1: =表紙!$AX$63 -> Webシステム | AS1: 文書番号 | AZ1: Version | BF1: Rev.
K2: =表紙!O64 -> アドオン設計書 | U2: ｻﾌﾞﾓｼﾞｭｰﾙID | Z2: =表紙!$AJ$64 -> MSBB | AE2: ｻﾌﾞﾓｼﾞｭｰﾙ名 | AJ2: =表紙!$AX$64 -> 販売Webシステム | AS2: =表紙!$BL$64 -> M7-US-1140 | AZ2: =表紙!$BU$64 -> 7.0.2 | BF2: =表紙!$CB$64 -> 1
K3: =RIGHT(CELL("filename",$A$1),LEN(CELL("filename",$A$1))-FIND("]",CELL("filename",$A$1))) -> 画面遷移 | U3: 表題 | Z3: =表紙!$AJ$65 -> MSBBPA130 | AE3: =表紙!$AQ$65 -> Webシート単価マスタ
A5: 画面遷移フロー図
A6: ＩＤ | C6: S01 | E6: Webシート単価マスタから他画面の画面遷移
D9: NO1
D10: Web取引先一覧照会 | K10: 検索 | R10: Webシート単価マスタ
A16: ID | D16: 処理名
A17: S01 | D17: Webシート単価マスタから他画面の画面遷移
B19: NO | D19: 遷移元ＩＤ | H19: 遷移元画面名 | Q19: 遷移先ＩＤ | V19: 遷移先画面名 | AE19: 目的 | AJ19: 引継項目 | AS19: 遷移後のアクション(遷移先) | BC19: 戻り値 | BL19: 戻り値取得後のアクション(遷移元) | BV19: 備考
B20: 1 | D20: MSBBPA020 | H20: Webシート単価マスタ | Q20: MSBBPA120 | V20: Web取引先一覧照会 | AE20: 検索結果取得 | AJ20: 得意先ＦＬＧ=1 | AS20: 検索 | BC20: 取引先選択データ(1行) | BL20: 対象データに値セット | BV20: 得意先CD、得意先名に値セット
B21: 2
B22: 3
B23: 4
B24: 5
B25: 6
B26: 7
B27: 8

Sheet メッセージ一覧
A1: =表紙!A54 -> Webシステム | K1: 文書名 | U1: モジュールID | Z1: =表紙!$AJ$63 -> MS | AE1: モジュール名 | AJ1: =表紙!$AX$63 -> Webシステム | AS1: 文書番号 | AZ1: Version | BF1: Rev.
K2: =表紙!O64 -> アドオン設計書 | U2: ｻﾌﾞﾓｼﾞｭｰﾙID | Z2: =表紙!$AJ$64 -> MSBB | AE2: ｻﾌﾞﾓｼﾞｭｰﾙ名 | AJ2: =表紙!$AX$64 -> 販売Webシステム | AS2: =表紙!$BL$64 -> M7-US-1140 | AZ2: =表紙!$BU$64 -> 7.0.2 | BF2: =表紙!$CB$64 -> 1
K3: =RIGHT(CELL("filename",$A$1),LEN(CELL("filename",$A$1))-FIND("]",CELL("filename",$A$1))) -> メッセージ一覧 | U3: 表題 | Z3: =表紙!$AJ$65 -> MSBBPA130 | AE3: =表紙!$AQ$65 -> Webシート単価マスタ
C4: ↓アドオン画面のため、基本全て[新]
A5: No | C5: 新/変 | E5: 種別 | G5: メッセージ内容 | AQ5: 備考（パラメータ等） | BG5: メッセージID
A6: 1 | C6: 新 | E6: W | G6: 「検索結果がありませんでした。」 | BG6: メッセージID.001
A7: 2 | C7: 新 | E7: W | G7: 「ファイルの読み込みに失敗しました。ファイルのフォーマット(EXCEL)を確認してください。」 | BG7: メッセージID.002
A8: 3 | C8: 新 | E8: W | G8: 「読み込んだファイルのカラム数{1} が正しくありません。(正:14)」 | BG8: メッセージID.003
A9: 4 | C9: 新 | E9: W | G9: 「必須項目に値が指定されていません。行：{1} 列名：{2}」 | AQ9: {1}：対象明細行番号 | BG9: メッセージID.004
AQ10: {2}：対象明細行の項目名
A11: 5 | C11: 新 | E11: W | G11: 「{1}形式ではありません。行：{2} 列名：{3}」 | AQ11: {1}：数字 OR 日付 | BG11: メッセージID.005
AQ12: {2}：対象明細行番号
AQ13: {3}：対象明細行の項目名
A14: 6 | C14: 新 | E14: W | G14: 「指定された値はマスタに存在しません。行：{1} 列名：{2} 値：{3}」 | AQ14: {1}：対象明細行番号 | BG14: メッセージID.006
AQ15: {2}：対象明細行の項目名
AQ16: {3}：対象明細行の項目値
A17: 7 | C17: 新 | E17: W | G17: 「同じデータが登録されています。上書きしますか。(はい・いいえ)」 | BG17: メッセージID.007
A18: 8 | C18: 新 | E18: W | G18: 「必須項目に値が指定されていません。」 | AQ18: 基準日、拠点 | BG18: メッセージID.008

Sheet WEBシート単価マスタ
A1: =表紙!A54 -> Webシステム | K1: 文書名 | U1: モジュールID | Z1: =表紙!$AJ$63 -> MS | AE1: モジュール名 | AJ1: =表紙!$AX$63 -> Webシステム | AS1: 文書番号 | AZ1: Version | BF1: Rev.
K2: =表紙!O64 -> アドオン設計書 | U2: ｻﾌﾞﾓｼﾞｭｰﾙID | Z2: =表紙!$AJ$64 -> MSBB | AE2: ｻﾌﾞﾓｼﾞｭｰﾙ名 | AJ2: =表紙!$AX$64 -> 販売Webシステム | AS2: =表紙!$BL$64 -> M7-US-1140 | AZ2: =表紙!$BU$64 -> 7.0.2 | BF2: =表紙!$CB$64 -> 1
K3: =RIGHT(CELL("filename",$A$1),LEN(CELL("filename",$A$1))-FIND("]",CELL("filename",$A$1))) -> WEBシート単価マスタ | U3: 表題 | Z3: =表紙!$AJ$65 -> MSBBPA130 | AE3: =表紙!$AQ$65 -> Webシート単価マスタ
A5: テーブル名 | O5: 日本語名
O6: WEBシート単価マスタ(見積用)
A8: 主キー | D8: 項目名 | O8: 日本語名 | AE8: 型 | AG8: 桁 | AI8: Null | AK8: 説明 | BL8: 値の制限 | BM8: 設定仕様 | BN8: 未設定時の振る舞い | CZ8: 未設定時の振る舞い
A9: 〇 | O9: 改定日 | AE9: D | AK9: 基準日(改定日)
A10: 〇 | O10: 拠点 | AE10: C
A11: 〇 | O11: 得意先CD | AE11: C | BL11: 取引先マスタ(得意先FLG=1)
A12: 〇 | O12: 段 | AE12: C | BL12: 段マスタ
A13: 〇 | O13: 原紙CD(表) | AE13: C | BL13: 原紙マスタ
A14: 〇 | O14: 印刷CD(表) | AE14: C | BL14: 印刷マスタ
A15: 〇 | O15: エンボスCD(表) | AE15: C | BL15: エンボスマスタ
A16: 〇 | O16: 原紙CD(中) | AE16: C | BL16: 原紙マスタ
A17: 〇 | O17: 印刷CD(中) | AE17: C | BL17: 印刷マスタ
A18: 〇 | O18: エンボスCD(中) | AE18: C | BL18: エンボスマスタ
A19: 〇 | O19: 原紙CD(裏) | AE19: C | BL19: 原紙マスタ
A20: 〇 | O20: 印刷CD(裏) | AE20: C | BL20: 印刷マスタ
A21: 〇 | O21: エンボスCD(裏) | AE21: C | BL21: エンボスマスタ
O22: 単価 | AE22: N
D23: DEL_FLG | O23: 論理削除ＦＬＧ | AE23: F | AI23: N | AK23: 論理削除を示すフラグ
D24: DEL_USR_ID | O24: 論理削除ユーザＩＤ | AE24: C | AG24: 500 | AI24: Y
D25: DEL_USR_NM | O25: 論理削除ユーザ名 | AE25: C | AG25: 100 | AI25: Y
D26: DEL_TS | O26: 論理削除日時 | AE26: TS | AG26: 0 | AI26: Y
D27: INS_USR_ID | O27: 登録ユーザＩＤ | AE27: C | AG27: 500 | AI27: Y
D28: INS_USR_NM | O28: 登録ユーザ名 | AE28: C | AG28: 100 | AI28: Y
D29: INS_TS | O29: 登録日時 | AE29: TS | AG29: 0 | AI29: Y
D30: INS_FUNC_ID | O30: 登録機能ＩＤ | AE30: C | AG30: 50 | AI30: Y
D31: UPD_CNTR | O31: 更新カウンタ | AE31: N | AG31: 9,0 | AI31: Y
D32: UPD_USR_ID | O32: 更新ユーザＩＤ | AE32: C | AG32: 500 | AI32: Y
D33: UPD_USR_NM | O33: 更新ユーザ名 | AE33: C | AG33: 100 | AI33: Y
D34: UPD_TS | O34: 更新日時 | AE34: TS | AG34: 0 | AI34: Y

Sheet WEBシート単価マスタ(見積用)
A1: =表紙!A54 -> Webシステム | K1: 文書名 | U1: モジュールID | Z1: =表紙!$AJ$63 -> MS | AE1: モジュール名 | AJ1: =表紙!$AX$63 -> Webシステム | AS1: 文書番号 | AZ1: Version | BF1: Rev.
K2: =表紙!O64 -> アドオン設計書 | U2: ｻﾌﾞﾓｼﾞｭｰﾙID | Z2: =表紙!$AJ$64 -> MSBB | AE2: ｻﾌﾞﾓｼﾞｭｰﾙ名 | AJ2: =表紙!$AX$64 -> 販売Webシステム | AS2: =表紙!$BL$64 -> M7-US-1140 | AZ2: =表紙!$BU$64 -> 7.0.2 | BF2: =表紙!$CB$64 -> 1
K3: =RIGHT(CELL("filename",$A$1),LEN(CELL("filename",$A$1))-FIND("]",CELL("filename",$A$1))) -> WEBシート単価マスタ(見積用) | U3: 表題 | Z3: =表紙!$AJ$65 -> MSBBPA130 | AE3: =表紙!$AQ$65 -> Webシート単価マスタ
A5: テーブル名 | O5: 日本語名
O6: WEBシート単価マスタ(見積用)
A8: 主キー | D8: 項目名 | O8: 日本語名 | AE8: 型 | AG8: 桁 | AI8: Null | AK8: 説明 | BL8: 値の制限 | BM8: 設定仕様 | BN8: 未設定時の振る舞い | CZ8: 未設定時の振る舞い
A9: 〇 | O9: 改定日 | AE9: D | AK9: 基準日(改定日)
A10: 〇 | O10: 拠点 | AE10: C
A11: 〇 | O11: 得意先CD | AE11: C | BL11: 取引先マスタ(得意先FLG=1)
A12: 〇 | O12: 段 | AE12: C | BL12: 段マスタ
A13: 〇 | O13: 原紙CD(表) | AE13: C | BL13: 原紙マスタ
A14: 〇 | O14: 印刷CD(表) | AE14: C | BL14: 印刷マスタ
A15: 〇 | O15: エンボスCD(表) | AE15: C | BL15: エンボスマスタ
A16: 〇 | O16: 原紙CD(中) | AE16: C | BL16: 原紙マスタ
A17: 〇 | O17: 印刷CD(中) | AE17: C | BL17: 印刷マスタ
A18: 〇 | O18: エンボスCD(中) | AE18: C | BL18: エンボスマスタ
A19: 〇 | O19: 原紙CD(裏) | AE19: C | BL19: 原紙マスタ
A20: 〇 | O20: 印刷CD(裏) | AE20: C | BL20: 印刷マスタ
A21: 〇 | O21: エンボスCD(裏) | AE21: C | BL21: エンボスマスタ
O22: 単価 | AE22: N
D23: DEL_FLG | O23: 論理削除ＦＬＧ | AE23: F | AI23: N | AK23: 論理削除を示すフラグ
D24: DEL_USR_ID | O24: 論理削除ユーザＩＤ | AE24: C | AG24: 500 | AI24: Y
D25: DEL_USR_NM | O25: 論理削除ユーザ名 | AE25: C | AG25: 100 | AI25: Y
D26: DEL_TS | O26: 論理削除日時 | AE26: TS | AG26: 0 | AI26: Y
D27: INS_USR_ID | O27: 登録ユーザＩＤ | AE27: C | AG27: 500 | AI27: Y
D28: INS_USR_NM | O28: 登録ユーザ名 | AE28: C | AG28: 100 | AI28: Y
D29: INS_TS | O29: 登録日時 | AE29: TS | AG29: 0 | AI29: Y
D30: INS_FUNC_ID | O30: 登録機能ＩＤ | AE30: C | AG30: 50 | AI30: Y
D31: UPD_CNTR | O31: 更新カウンタ | AE31: N | AG31: 9,0 | AI31: Y
D32: UPD_USR_ID | O32: 更新ユーザＩＤ | AE32: C | AG32: 500 | AI32: Y
D33: UPD_USR_NM | O33: 更新ユーザ名 | AE33: C | AG33: 100 | AI33: Y
D34: UPD_TS | O34: 更新日時 | AE34: TS | AG34: 0 | AI34: Y

Sheet →補足シート

Sheet シート単価マスター(現行)
A1: テーブル情報
B2: システム名 | E2: 作成者 | F2: HW59
B3: サブシステム名 | E3: 作成日 | F3: 2018/12/05 | I3: SELECT*FROMCPBKD9.FBD14P
B4: スキーマ名 | C4: CPBKD9 | E4: 更新日
B5: 論理テーブル名 | C5: シート単価マスター | E5: RDBMS | F5: DB2forIBMi07.02.0000OS/400V7R2M0 | I5: FETCHFIRST50ROWSONLY
B6: 物理テーブル名 | C6: FBD14P
B7: 備考
B8: キー：得意先CD＋原紙CD(1～3)＋印刷CD(1～3)＋エンボスCD(1～3)＋段
A12: カラム情報 | I12: 活動区分 | J12: 得意先ｺｰﾄﾞ | K12: 原紙ｺｰﾄﾞ(表) | L12: 印刷ｺｰﾄﾞ(表) | M12: ｴﾝﾎﾞｽｺｰﾄﾞ(表) | N12: 原紙ｺｰﾄﾞ(中) | O12: 印刷ｺｰﾄﾞ(中) | P12: ｴﾝﾎﾞｽｺｰﾄﾞ(中) | Q12: 原紙ｺｰﾄﾞ(裏) | R12: 印刷ｺｰﾄﾞ(裏) | S12: ｴﾝﾎﾞｽｺｰﾄﾞ(裏) | T12: ｼｰﾄ単価Ａ通常 | U12: ｼｰﾄ単価Ｂ特値 | V12: 登録日付 | W12: 登録時間 | X12: 最終更新日付 | Y12: 最終更新時刻 | Z12: 受注NO(更新) | AA12: 配車指示回数 | AB12: ｼｰﾄ原価 | AC12: 最終更新日付(特値) | AD12: 最終更新時刻(特値) | AE12: 受注NO(特値) | AF12: 配車指示回数(特値) | AG12: ｼｰﾄ原価(特値) | AH12: 段 | AI12: ｼｰﾄ単価Ｃ旧 | AJ12: 最終更新日付(特値) | AK12: ｼｰﾄ単価新 | AL12: 新シート単価適用日
A13: No | B13: 論理名 | C13: 物理名 | D13: データ型 | E13: NotNull | F13: デフォルト | G13: 備考 | I13: DNKATU | J13: DNTKC | K13: DNGSC1 | L13: DNPRC1 | M13: DNEBC1 | N13: DNGSC2 | O13: DNPRC2 | P13: DNEBC2 | Q13: DNGSC3 | R13: DNPRC3 | S13: DNEBC3 | T13: DNSTTA | U13: DNSTTB | V13: DNTDT | W13: DNTTM | X13: DNLDT | Y13: DNLTM | Z13: DNJNOU | AA13: DNHSK | AB13: DNSTT | AC13: DNLDTN | AD13: DNLTMN | AE13: DNJNON | AF13: DNHSKN | AG13: DNSTTN | AH13: DNDAN | AI13: DNSTTC | AJ13: DNLDTC | AK13: DNSTTS | AL13: DNNDAT
A14: 1 | B14: 活動区分 | C14: DNKATU | D14: NUMERIC | E14: Yes | F14: 0 | I14: 0 | J14: 36093 | K14: 0000 | L14: 0000 | M14: 00 | N14: 0001 | O14: 0000 | P14: 00 | Q14: @E84 | R14: 0000 | S14: 00 | T14: 34.68 | U14: 0 | V14: 19890822 | W14: 100811 | X14: 19890830 | Y14: 133513 | Z14: 10000334 | AA14: 1 | AB14: 62.28 | AC14: 0 | AD14: 0 | AE14: 0 | AF14: 0 | AG14: 0 | AI14: 0 | AJ14: 0 | AK14: 0 | AL14: 0
A15: 2 | B15: 得意先ｺｰﾄﾞ | C15: DNTKC | D15: NUMERIC | E15: Yes | F15: 0 | I15: 0 | J15: 36093 | K15: 0000 | L15: 0000 | M15: 00 | N15: 0001 | O15: 0000 | P15: 00 | Q15: 0700 | R15: 0000 | S15: 00 | T15: 37.06 | U15: 0 | V15: 19890822 | W15: 101017 | X15: 19900202 | Y15: 90333 | Z15: 10007506 | AA15: 1 | AB15: 39.82 | AC15: 0 | AD15: 0 | AE15: 0 | AF15: 0 | AG15: 0 | AI15: 0 | AJ15: 0 | AK15: 0 | AL15: 0
A16: 3 | B16: 原紙ｺｰﾄﾞ(表) | C16: DNGSC1 | D16: CHAR(4) | E16: Yes | F16: '' | I16: 0 | J16: 37062 | K16: 0000 | L16: 0000 | M16: 00 | N16: C5 | O16: 0000 | P16: 00 | Q16: C5 | R16: 0000 | S16: 00 | T16: 40.12 | U16: 0 | V16: 19890822 | W16: 101238 | X16: 19890830 | Y16: 133603 | Z16: 10000332 | AA16: 1 | AB16: 61.95 | AC16: 0 | AD16: 0 | AE16: 0 | AF16: 0 | AG16: 0 | AI16: 0 | AJ16: 0 | AK16: 0 | AL16: 0
A17: 4 | B17: 印刷ｺｰﾄﾞ(表) | C17: DNPRC1 | D17: CHAR(4) | E17: Yes | F17: '' | I17: 0 | J17: 33843 | K17: 0000 | L17: 0000 | M17: 00 | N17: 0001 | O17: 0000 | P17: 00 | Q17: 0700 | R17: 0000 | S17: 00 | T17: 50 | U17: 44 | V17: 19890822 | W17: 101351 | X17: 20180920 | Y17: 90838 | Z17: 21104223 | AA17: 1 | AB17: 29.87 | AC17: 20170929 | AD17: 92854 | AE17: 20511049 | AF17: 1 | AG17: 29.87 | AI17: 49 | AJ17: 20170928 | AK17: 0 | AL17: 0
A18: 5 | B18: ｴﾝﾎﾞｽｺｰﾄﾞ(表) | C18: DNEBC1 | D18: CHAR(2) | E18: Yes | F18: '' | I18: 0 | J18: 33343 | K18: 0000 | L18: 0000 | M18: 00 | N18: 0001 | O18: 0000 | P18: 00 | Q18: C5 | R18: 0000 | S18: 00 | T18: 36 | U18: 28 | V18: 19890822 | W18: 101439 | X18: 20180907 | Y18: 90058 | Z18: 21087442 | AA18: 1 | AB18: 25.19 | AC18: 20100707 | AD18: 92356 | AE18: 13007647 | AF18: 3 | AG18: 27.88 | AI18: 32 | AJ18: 20170729 | AK18: 0 | AL18: 0
A19: 6 | B19: 原紙ｺｰﾄﾞ(中) | C19: DNGSC2 | D19: CHAR(4) | E19: Yes | F19: '' | I19: 0 | J19: 32443 | K19: 0000 | L19: 0000 | M19: 00 | N19: 0001 | O19: 0000 | P19: 00 | Q19: 0700 | R19: 0000 | S19: 00 | T19: 48 | U19: 46 | V19: 19890822 | W19: 101554 | X19: 20071215 | Y19: 84828 | Z19: 12703027 | AA19: 1 | AB19: 30.26 | AC19: 19930111 | AD19: 110625 | AE19: 10285707 | AF19: 1 | AG19: 37.32 | AI19: 0 | AJ19: 0 | AK19: 0 | AL19: 0
A20: 7 | B20: 印刷ｺｰﾄﾞ(中) | C20: DNPRC2 | D20: CHAR(4) | E20: Yes | F20: '' | I20: 0 | J20: 32203 | K20: RC90 | L20: 0000 | M20: 00 | N20: 0001 | O20: 0000 | P20: 00 | Q20: C5 | R20: 0000 | S20: 00 | T20: 149 | U20: 0 | V20: 19890822 | W20: 101630 | X20: 20150819 | Y20: 84026 | Z20: 13695170 | AA20: 1 | AB20: 81.79 | AC20: 0 | AD20: 0 | AE20: 0 | AF20: 0 | AG20: 0 | AI20: 0 | AJ20: 0 | AK20: 0 | AL20: 0
A21: 8 | B21: ｴﾝﾎﾞｽｺｰﾄﾞ(中) | C21: DNEBC2 | D21: CHAR(2) | E21: Yes | F21: '' | I21: 0 | J21: 39782 | K21: 0700 | L21: 0000 | M21: 00 | N21: 0001 | O21: 0000 | P21: 00 | Q21: D4 | R21: 0000 | S21: 00 | T21: 46 | U21: 46 | V21: 19890822 | W21: 101857 | X21: 20010511 | Y21: 134915 | Z21: 11198108 | AA21: 1 | AB21: 43.36 | AC21: 20021015 | AD21: 131941 | AE21: 12056922 | AF21: 1 | AG21: 42.4 | AI21: 0 | AJ21: 0 | AK21: 0 | AL21: 0
A22: 9 | B22: 原紙ｺｰﾄﾞ(裏) | C22: DNGSC3 | D22: CHAR(4) | E22: Yes | F22: '' | I22: 0 | J22: 39682 | K22: 0700 | L22: 0000 | M22: 00 | N22: 0001 | O22: 0000 | P22: 00 | Q22: 0700 | R22: 0000 | S22: 00 | T22: 56 | U22: 0 | V22: 19890822 | W22: 101924 | X22: 20180516 | Y22: 92823 | Z22: 20892056 | AA22: 1 | AB22: 52.87 | AC22: 20180501 | AD22: 91526 | AE22: 20871584 | AF22: 1 | AG22: 52.87 | AI22: 56 | AJ22: 20170704 | AK22: 0 | AL22: 0
A23: 10 | B23: 印刷ｺｰﾄﾞ(裏) | C23: DNPRC3 | D23: CHAR(4) | E23: Yes | F23: '' | I23: 0 | J23: 39722 | K23: C5 | L23: 0000 | M23: 00 | N23: 0001 | O23: 0000 | P23: 00 | Q23: C5 | R23: 0000 | S23: 00 | T23: 40 | U23: 45 | V23: 19890822 | W23: 101950 | X23: 20110727 | Y23: 112022 | Z23: 13144746 | AA23: 1 | AB23: 48.17 | AC23: 19900726 | AD23: 95815 | AE23: 10053743 | AF23: 1 | AG23: 51.04 | AI23: 0 | AJ23: 0 | AK23: 0 | AL23: 0
A24: 11 | B24: ｴﾝﾎﾞｽｺｰﾄﾞ(裏) | C24: DNEBC3 | D24: CHAR(2) | E24: Yes | F24: '' | I24: 0 | J24: 31793 | K24: 0000 | L24: 0000 | M24: 00 | N24: 0001 | O24: 0000 | P24: 00 | Q24: D4 | R24: 0000 | S24: 00 | T24: 31 | U24: 40 | V24: 19890822 | W24: 102115 | X24: 20051025 | Y24: 92804 | Z24: 12439561 | AA24: 1 | AB24: 20.36 | AC24: 19941014 | AD24: 94602 | AE24: 10448666 | AF24: 1 | AG24: 32.51 | AI24: 0 | AJ24: 0 | AK24: 0 | AL24: 0
A25: 12 | B25: ｼｰﾄ単価Ａ通常 | C25: DNSTTA | D25: NUMERIC | E25: Yes | F25: 0 | I25: 0 | J25: 31073 | K25: 0000 | L25: 0000 | M25: 00 | N25: 0001 | O25: 0000 | P25: 00 | Q25: C5 | R25: 0000 | S25: 00 | T25: 41 | U25: 0 | V25: 19890822 | W25: 102135 | X25: 20180727 | Y25: 93424 | Z25: 20994084 | AA25: 1 | AB25: 25.19 | AC25: 20100708 | AD25: 110325 | AE25: 13009294 | AF25: 1 | AG25: 27.88 | AI25: 38 | AJ25: 20170721 | AK25: 0 | AL25: 0
... A39: 26 | B39: 段 | C39: DNDAN | D39: CHAR(1) | E39: Yes | F39: '' | I39: 0 | J39: 39322 | K39: RC11 | L39: 0000 | M39: AS | N39: 0001 | O39: 0000 | P39: 00 | Q39: D4 | R39: 0000 | S39: 00 | T39: 109 | U39: 0 | V39: 19890822 | W39: 103118 | X39: 19900226 | Y39: 95112 | Z39: 10008495 | AA39: 1 | AB39: 73.52 | AC39: 0 | AD39: 0 | AE39: 0 | AF39: 0 | AG39: 0 | AI39: 0 | AJ39: 0 | AK39: 0 | AL39: 0
A40: 27 | B40: ｼｰﾄ単価Ｃ旧 | C40: DNSTTC | D40: NUMERIC | E40: Yes | F40: 0 | G40: ｷｭｳｳﾘｱｹﾞﾀﾝｶ | I40: 0 | J40: 39252 | K40: 0700 | L40: 0000 | M40: 00 | N40: 0001 | O40: 0000 | P40: 00 | Q40: D4 | R40: 0000 | S40: 00 | T40: 55 | U40: 52 | V40: 19890822 | W40: 103139 | X40: 19930114 | Y40: 95644 | Z40: 10286360 | AA40: 1 | AB40: 50.36 | AC40: 19901207 | AD40: 103701 | AE40: 10093438 | AF40: 1 | AG40: 55.93 | AI40: 0 | AJ40: 0 | AK40: 0 | AL40: 0
A41: 28 | B41: 最終更新日付(特値) | C41: DNLDTC | D41: NUMERIC | E41: Yes | F41: 0 | G41: ｷｭｳｳﾘｱｹﾞﾋﾞ | I41: 0 | J41: 39212 | K41: C5 | L41: 0000 | M41: 00 | N41: 0001 | O41: 0000 | P41: 00 | Q41: C5 | R41: 0000 | S41: 00 | T41: 43 | U41: 38 | V41: 19890822 | W41: 103206 | X41: 20051102 | Y41: 103826 | Z41: 12438274 | AA41: 1 | AB41: 40.34 | AC41: 20041117 | AD41: 140623 | AE41: 12325887 | AF41: 1 | AG41: 40.34 | AI41: 0 | AJ41: 0 | AK41: 0 | AL41: 0
A42: 29 | B42: ｼｰﾄ単価新 | C42: DNSTTS | D42: NUMERIC | E42: Yes | F42: 0 | I42: 0 | J42: 37013 | K42: 0000 | L42: 0000 | M42: 00 | N42: 0001 | O42: 0000 | P42: 00 | Q42: C5 | R42: 0000 | S42: 00 | T42: 26 | U42: 24 | V42: 19890822 | W42: 103221 | X42: 20161219 | Y42: 90632 | Z42: 20062060 | AA42: 1 | AB42: 25.45 | AC42: 20151226 | AD42: 83857 | AE42: 13749615 | AF42: 1 | AG42: 25.45 | AI42: 0 | AJ42: 0 | AK42: 0 | AL42: 0
A43: 30 | B43: 新シート単価適用日 | C43: DNNDAT | D43: NUMERIC | E43: Yes | F43: 0 | I43: 0 | J43: 36093 | K43: 0000 | L43: 0000 | M43: 00 | N43: 0001 | O43: 0000 | P43: 00 | Q43: C6 | R43: 0000 | S43: 00 | T43: 31.58 | U43: 0 | V43: 19890822 | W43: 103246 | X43: 19890830 | Y43: 135430 | Z43: 10000360 | AA43: 1 | AB43: 58.56 | AC43: 0 | AD43: 0 | AE43: 0 | AF43: 0 | AG43: 0 | AI43: 0 | AJ43: 0 | AK43: 0 | AL43: 0
I44: 0 | J44: 39342 | K44: C6 | L44: 0000 | M44: 00 | N44: 0001 | O44: 0000 | P44: 00 | Q44: C6 | R44: 0000 | S44: 00 | T44: 55 | U44: 59 | V44: 19890822 | W44: 103319 | X44: 20090727 | Y44: 93503 | Z44: 12889579 | AA44: 1 | AB44: 52.76 | AC44: 20090114 | AD44: 90414 | AE44: 12830206 | AF44: 1 | AG44: 56.21 | AI44: 0 | AJ44: 0 | AK44: 0 | AL44: 0
A45: インデックス情報 | I45: 0 | J45: 39342 | K45: 0905 | L45: 0000 | M45: 00 | N45: 0001 | O45: 0000 | P45: 00 | Q45: C5 | R45: 0000 | S45: 00 | T45: 76 | U45: 71 | V45: 19890822 | W45: 103346 | X45: 20161012 | Y45: 95804 | Z45: 20021707 | AA45: 1 | AB45: 52.87 | AC45: 20110908 | AD45: 95238 | AE45: 13156265 | AF45: 1 | AG45: 55.93 | AI45: 0 | AJ45: 0 | AK45: 0 | AL45: 0
A46: No | B46: インデックス名 | C46: カラムリスト | E46: 主キー | F46: ユニーク | G46: 備考 | I46: 0 | J46: 39212 | K46: BB01 | L46: 0000 | M46: 00 | N46: 0001 | O46: 0000 | P46: 00 | Q46: 0700 | R46: 0000 | S46: 00 | T46: 96.69 | U46: 0 | V46: 19890822 | W46: 103442 | X46: 19890830 | Y46: 135608 | Z46: 10000368 | AA46: 1 | AB46: 102.12 | AC46: 0 | AD46: 0 | AE46: 0 | AF46: 0 | AG46: 0 | AI46: 0 | AJ46: 0 | AK46: 0 | AL46: 0
I47: 0 | J47: 37013 | K47: PL04 | L47: 0000 | M47: 00 | N47: 0001 | O47: 0000 | P47: 00 | Q47: 0700 | R47: 0000 | S47: 00 | T47: 126 | U47: 0 | V47: 19890822 | W47: 103519 | X47: 19890830 | Y47: 135642 | Z47: 10000363 | AA47: 1 | AB47: 133.27 | AC47: 0 | AD47: 0 | AE47: 0 | AF47: 0 | AG47: 0 | AI47: 0 | AJ47: 0 | AK47: 0 | AL47: 0
A48: 制約情報 | I48: 0 | J48: 35533 | K48: 0000 | L48: 0000 | M48: 00 | N48: 0001 | O48: 0000 | P48: 00 | Q48: D4 | R48: 0000 | S48: 00 | T48: 24 | U48: 23 | V48: 19890822 | W48: 103547 | X48: 20011011 | Y48: 90714 | Z48: 11243528 | AA48: 1 | AB48: 18.49 | AC48: 19960909 | AD48: 101041 | AE48: 10682504 | AF48: 1 | AG48: 22.5 | AI48: 0 | AJ48: 0 | AK48: 0 | AL48: 0
A49: No | B49: 制約名 | C49: 種類 | D49: 制約定義 | I49: 0 | J49: 39442 | K49: 0600 | L49: 3255 | M49: 00 | N49: 0001 | O49: 0000 | P49: 00 | Q49: C5 | R49: 0000 | S49: 00 | T49: 110 | U49: 113 | V49: 19890822 | W49: 103605 | X49: 19940418 | Y49: 110657 | Z49: 10396582 | AA49: 1 | AB49: 83.41 | AC49: 19931008 | AD49: 104414 | AE49: 10350117 | AF49: 1 | AG49: 86.19 | AI49: 0 | AJ49: 0 | AK49: 0 | AL49: 0
I50: 0 | J50: 39582 | K50: 0700 | L50: 0000 | M50: 00 | N50: 0001 | O50: 0000 | P50: 00 | Q50: C5 | R50: 0000 | S50: 00 | T50: 56 | U50: 0 | V50: 19890822 | W50: 103627 | X50: 19950928 | Y50: 100732 | Z50: 10565732 | AA50: 1 | AB50: 52.58 | AC50: 0 | AD50: 0 | AE50: 0 | AF50: 0 | AG50: 0 | AI50: 0 | AJ50: 0 | AK50: 0 | AL50: 0
A51: 外部キー情報 | I51: 0 | J51: 39342 | K51: 0700 | L51: 0000 | M51: 00 | N51: 0001 | O51: 0000 | P51: 00 | Q51: D4 | R51: 0000 | S51: 00 | T51: 54 | U51: 0 | V51: 19890822 | W51: 103706 | X51: 20111214 | Y51: 104344 | Z51: 13199124 | AA51: 1 | AB51: 46.97 | AC51: 20090709 | AD51: 164122 | AE51: 12883273 | AF51: 1 | AG51: 47.48 | AI51: 0 | AJ51: 0 | AK51: 0 | AL51: 0
A52: No | B52: 外部キー名 | C52: カラムリスト | E52: 参照先テーブル名 | G52: 参照先カラムリスト | I52: 0 | J52: 39442 | K52: 0925 | L52: 0000 | M52: 00 | N52: 0001 | O52: 0000 | P52: 00 | Q52: C5 | R52: 0000 | S52: 00 | T52: 70 | U52: 70 | V52: 19890822 | W52: 103812 | X52: 20011129 | Y52: 150125 | Z52: 11260900 | AA52: 2 | AB52: 48.83 | AC52: 19981214 | AD52: 84238 | AE52: 10930485 | AF52: 1 | AG52: 56.49 | AI52: 0 | AJ52: 0 | AK52: 0 | AL52: 0
I53: 0 | J53: 33843 | K53: 0000 | L53: 0000 | M53: 00 | N53: 0001 | O53: 0000 | P53: 00 | Q53: D4 | R53: 0000 | S53: 00 | T53: 31 | U53: 0 | V53: 19890822 | W53: 103852 | X53: 20040412 | Y53: 90220 | Z53: 12248260 | AA53: 1 | AB53: 20.67 | AC53: 0 | AD53: 0 | AE53: 0 | AF53: 0 | AG53: 0 | AI53: 0 | AJ53: 0 | AK53: 0 | AL53: 0
A54: 外部キー情報(PK側) | I54: 0 | J54: 33773 | K54: 0000 | L54: 0000 | M54: 00 | N54: 0001 | O54: 0000 | P54: 00 | Q54: C5 | R54: 0000 | S54: 00 | T54: 34 | U54: 30 | V54: 19890822 | W54: 104044 | X54: 20070903 | Y54: 84216 | Z54: 12662907 | AA54: 1 | AB54: 24.58 | AC54: 19951109 | AD54: 94629 | AE54: 10581674 | AF54: 1 | AG54: 26.78 | AI54: 0 | AJ54: 0 | AK54: 0 | AL54: 0
A55: No | B55: 外部キー名 | C55: カラムリスト | E55: 参照元テーブル名 | G55: 参照元カラムリスト | I55: 0 | J55: 36093 | K55: 0000 | L55: 0000 | M55: 00 | N55: 0001 | O55: 0000 | P55: 00 | Q55: C5 | R55: 0000 | S55: 00 | T55: 29.26 | U55: 0 | V55: 19890823 | W55: 92355 | X55: 19900214 | Y55: 100508 | Z55: 10007810 | AA55: 1 | AB55: 32.64 | AC55: 0 | AD55: 0 | AE55: 0 | AF55: 0 | AG55: 0 | AI55: 0 | AJ55: 0 | AK55: 0 | AL55: 0
I56: 0 | J56: 34523 | K56: 0000 | L56: 0000 | M56: 00 | N56: 0001 | O56: 0000 | P56: 00 | Q56: C5 | R56: 0000 | S56: 00 | T56: 41 | U56: 39 | V56: 19890823 | W56: 92557 | X56: 20130410 | Y56: 112143 | Z56: 13371216 | AA56: 1 | AB56: 25.19 | AC56: 19960919 | AD56: 90441 | AE56: 10684969 | AF56: 1 | AG56: 25.6 | AI56: 0 | AJ56: 0 | AK56: 0 | AL56: 0
...

Sheet 見積もり用シート単価マスター（標準売価）
A1: テーブル情報
B2: システム名 | E2: 作成者 | F2: HW59
B3: サブシステム名 | E3: 作成日 | F3: 2018/12/05
B4: スキーマ名 | C4: CPBKD9 | E4: 更新日
B5: 論理テーブル名 | C5: 見積もり用シート単価マスター（標準売価） | E5: RDBMS | F5: DB2forIBMi07.02.0000OS/400V7R2M0
B6: 物理テーブル名 | C6: FBD25P
B7: 備考
A12: カラム情報
A13: No | B13: 論理名 | C13: 物理名 | D13: データ型 | E13: NotNull | F13: デフォルト | G13: 備考
A14: 1 | B14: 活動区分 | C14: DYKATU | D14: NUMERIC | E14: Yes | F14: 0
A15: 2 | B15: 得意先ｺｰﾄﾞ | C15: DYTKC | D15: NUMERIC | E15: Yes | F15: 0
A16: 3 | B16: 原紙ｺｰﾄﾞ(表) | C16: DYGSC1 | D16: CHAR(4) | E16: Yes | F16: ''
A17: 4 | B17: 印刷ｺｰﾄﾞ(表) | C17: DYPRC1 | D17: CHAR(4) | E17: Yes | F17: ''
A18: 5 | B18: ｴﾝﾎﾞｽｺｰﾄﾞ(表) | C18: DYEBC1 | D18: CHAR(2) | E18: Yes | F18: ''
A19: 6 | B19: 原紙ｺｰﾄﾞ(中) | C19: DYGSC2 | D19: CHAR(4) | E19: Yes | F19: ''
A20: 7 | B20: 印刷ｺｰﾄﾞ(中) | C20: DYPRC2 | D20: CHAR(4) | E20: Yes | F20: ''
A21: 8 | B21: ｴﾝﾎﾞｽｺｰﾄﾞ(中) | C21: DYEBC2 | D21: CHAR(2) | E21: Yes | F21: ''
A22: 9 | B22: 原紙ｺｰﾄﾞ(裏) | C22: DYGSC3 | D22: CHAR(4) | E22: Yes | F22: ''
A23: 10 | B23: 印刷ｺｰﾄﾞ(裏) | C23: DYPRC3 | D23: CHAR(4) | E23: Yes | F23: ''
A24: 11 | B24: ｴﾝﾎﾞｽｺｰﾄﾞ(裏) | C24: DYEBC3 | D24: CHAR(2) | E24: Yes | F24: ''
A25: 12 | B25: シート大区分 | C25: DYSLK | D25: CHAR(1) | E25: Yes | F25: ''
... A37: 24 | B37: 見本帳小区分 | C37: DYMSK | D37: NUMERIC | E37: Yes | F37: 0
A39: インデックス情報
A40: No | B40: インデックス名 | C40: カラムリスト | E40: 主キー | F40: ユニーク | G40: 備考
A42: 制約情報
A43: No | B43: 制約名 | C43: 種類 | D43: 制約定義
A45: 外部キー情報
A46: No | B46: 外部キー名 | C46: カラムリスト | E46: 参照先テーブル名 | G46: 参照先カラムリスト
A48: 外部キー情報(PK側)
A49: No | B49: 外部キー名 | C49: カラムリスト | E49: 参照元テーブル名 | G49: 参照元カラムリスト
A51: RDBMS固有の情報
A52: No | B52: プロパティ名 | D52: プロパティ値
A53: 1 | B53: TABLE_NAME | D53: FBD25P
A54: 2 | B54: TABLE_OWNER | D54: QPGMR
A55: 3 | B55: TABLE_TYPE | D55: P
A56: 4 | B56: COLUMN_COUNT | D56: 24
A57: 5 | B57: ROW_LENGTH | D57: 101
A58: 6 | B58: TABLE_TEXT | D58: 見積もり用シート単価マスター（標準売価）
A59: 7 | B59: LONG_COMMENT
A60: 8 | B60: TABLE_SCHEMA | D60: CPBKD9
...
