Workbook
Name Rev.: 表紙!$U$22
Name Ver.: 表紙!$AE$26
Name ご確認者: 表紙!$AG$40
Name ご確認日: 表紙!$AG$42
Name サブシステム名: 表紙!$U$28
Name システム名: 表紙!$U$26
Name プロジェクト名: 表紙!$U$18
Name 開発区分: 表紙!$U$36
Name 機能ＩＤ: 表紙!$U$32
Name 機能区分: 表紙!$U$34
Name 機能名称: 表紙!$U$30
Name 顧客名: 表紙!$U$16
Name 最終更新者: 表紙!$AB$40
Name 最終更新日: 表紙!$AB$42
Name 作成者: 表紙!$W$40
Name 作成日: 表紙!$W$42
Name 章: 表紙!$M$10
Name 文書名: 表紙!$M$10

Sheet 目次
A1: アドオン設計書作成ガイド
C3: ■アドオン設計と成果物について
D4: ・システム設計フェーズとソフトウェア設計フェーズでアドオンの処理仕様を定義する
D5: ・システム設計フェーズとソフトウェア設計フェーズの成果物がアドオン設計書であり、ソフトウェア製作フェーズのインプットとなる
C7: ■各設計フェーズ毎のアドオン設計書作成範囲
D8: ・システム設計フェーズ：他機能との関連を定義するとともに、画面や帳票、ファイル入出力を中心とした外部入出力の設計を行う
D9: ・ソフトウェア設計フェーズ：内部処理を中心とした設計を行う
U11: ◎ | W11: … | X11: システム設計フェーズで作成
U12: ○ | W12: … | X12: システム設計フェーズで基本仕様を定義して、ソフトウェア設計フェーズで詳細化する
U13: △ | W13: … | X13: 必要に応じて（例えば標準仕様から変更がない場合は不要）
U14: ‐ | W14: … | X14: 不要
W15: … | X15: ソフトウェア設計フェーズで作成
D17: 各設計書と作成対象シートのマトリックス | S17: ※カスタマイズ：標準機能に機能を追加する アドオン：新規で機能を開発する
D18: EXCELシート | N18: 画面設計書 | W18: バッチ設計書 | AF18: 帳票設計書 | AO18: ＢＩ設計書 | AT18: .Net設計書 | BB18: EXCELシート | BL18: WebDB設計書 | BR18: 帳票設計書 | BX18: 汎用申請設計書
N19: カスタマイズ | S19: アドオン | W19: カスタマイズ | AB19: アドオン | AF19: カスタマイズ | AK19: アドオン | AO19: アドオン | AT19: アドオン | BL19: アドオン | BR19: アドオン | BX19: アドオン
D20: 概要 | N20: ◎ | O20: ※1 | S20: ◎ | W20: ◎ | X20: ※1 | AB20: ◎ | AF20: ◎ | AG20: ※1 | AK20: ◎ | AO20: ◎ | AT20: ◎ | BB20: 機能概要 | BL20: ◎ | BR20: ◎ | BX20: ◎
D21: レイアウト | N21: ◎ | O21: ※2 | S21: ◎ | W21: ‐ | AB21: ‐ | AF21: ◎ | AG21: ※2 | AK21: ◎ | AO21: ◎ | AT21: ◎ | BB21: アプリケーションフロー | BL21: ◎ | BR21: ー | BX21: ◎
D22: 項目説明 | N22: △ | S22: ○ | W22: ‐ | AB22: ‐ | AF22: △ | AK22: ○ | AO22: ○ | AT22: ○ | BB22: データベース設定 | BL22: ◎ | BR22: ー | BX22: ◎
D23: 引数説明 | N23: ‐ | S23: ‐ | W23: △ | AB23: ◎ | AF23: ‐ | AK23: ‐ | AO23: ‐ | AT23: ◎ | BB23: フィールド設定 | BL23: ◎ | BR23: ー | BX23: ◎
D24: 処理概要 | N24: ◎ | S24: ◎ | W24: ◎ | AB24: ◎ | AF24: ◎ | AK24: ◎ | AO24: ◎ | AT24: ◎ | BB24: 一覧表示画面設定 | BL24: ◎ | BR24: ー | BX24: ◎
D25: 処理詳細 | BB25: 表示編集画面設定 | BL25: ◎ | BR25: ー | BX25: ◎
D26: 処理・サービス関連図 | N26: △ | S26: ◎ | W26: △ | AB26: ◎ | AF26: ‐ | AK26: ‐ | AO26: ‐ | AT26: ◎ | BB26: 明細画面設定 | BL26: △ | BN26: ※3 | BR26: ー | BX26: △ | BZ26: ※3
D27: 検索入出力仕様 | N27: △ | S27: ○ | W27: △ | AB27: ○ | AF27: ‐ | AK27: ‐ | AO27: ‐ | AT27: ○ | BB27: 集計表示設定 | BL27: △ | BN27: ※4 | BR27: ー | BX27: △ | BZ27: ※4
D28: 更新入出力仕様 | N28: △ | S28: ○ | W28: △ | AB28: ○ | AF28: ‐ | AK28: ‐ | AO28: ‐ | AT28: ○ | BB28: 絞り込み条件設定 | BL28: △ | BN28: ※5 | BR28: ー | BX28: △ | BZ28: ※5
D29: ファイル入出力仕様 | N29: △ | S29: △ | W29: ‐ | AB29: ‐ | AF29: ‐ | AK29: ‐ | AO29: ‐ | AT29: △ | BB29: その他設定 | BR29: ー
D30: 画面遷移 | N30: △ | S30: ◎ | W30: ‐ | AB30: ‐ | AF30: ‐ | AK30: ‐ | AO30: ‐ | AT30: ◎ | BB30: 帳票イメージ | BL30: ー | BR30: ◎ | BX30: ー
D31: メッセージ一覧 | N31: △ | S31: △ | W31: △ | AB31: △ | AF31: ‐ | AK31: ‐ | AO31: ‐ | AT31: △ | BB31: 項目設計 | BL31: ー | BR31: ◎ | BX31: ー
D32: 補足説明 | N32: △ | S32: △ | W32: △ | AB32: △ | AF32: △ | AK32: △ | AO32: △ | AT32: △ | BB32: 補足説明 | BL32: △ | BR32: △ | BX32: △
D33: サービス呼出編集仕様 | N33: - | S33: - | W33: - | AB33: - | AF33: - | AK33: - | AO33: - | AT33: - | BB33: 補足説明(詳細)
D35: ※1 | G35: 別シートでカスタマイズ内容を記載する | BB35: ※3 | BE35: 単票画面は記載しない
D36: ※2 | G36: 吹き出しでカスタマイズ内容を記載する | BB36: ※4 | BE36: 集計・グラフ機能を使用する場合に記載する
BB37: ※5 | BE37: 共通設定のみ記載する(個別設定は、記載しない)

Sheet 表紙
AW2: サブモジュール
AW3: MA_マスタ管理
AW4: MB_業務共通
AW5: MG_原価管理
AW6: MSBA_需給管理
M7: 基本設計 | AW7: MSBB_販売管理
AW8: MSBC_生産管理
AW9: MSBD_購買管理
M10: アドオン設計書 | AW10: MSBE_在庫物流管理
AW11: MSBF_品質管理
AW12: MSBG_債権管理
AW13: MSBH_債務管理
AW14: MSBI_締処理
AW15: MSUA_リスト・入力補助
M16: 顧客 | U16: 株式会社クラウン・パッケージ | AW16: PF_ESBアダプタ
M18: プロジェクト名 | U18: 基幹システム刷新PJ | AW18: 機能区分
AW19: 画面
M20: 文書番号 | AW20: 帳票
AW21: バッチ
M22: Ｒｅｖ． | U22: {=MAX(_xlfn.NUMBERVALUE(改訂!A7:E48))} -> 1 | AW22: マスタ
M24: 機密性区分 | U24: 取扱注意（Ｃ） | AW24: 開発区分
AW25: カスタマイズ
M26: システム名 | U26: Webシステム | AC26: Ver. | AE26: 7.0.2 | AW26: アドオン
AW27: －
M28: サブモジュール | U28: MSBB_販売管理
M30: 機能名 | U30: =M50 -> Web版型・木型マスタ一覧照会
M32: 機能ID | U32: =G50 -> MSBBPA150
M34: 機能区分 | U34: 画面
M36: 開発区分 | U36: アドオン
W39: 作成 | AB39: 最終更新 | AG39: ご確認
W40: MDSOL
W42: 44805
A48: 文書番号 | G48: 画面ID | M48: 画面名 | V48: Version | AB48: Revision
A50: M7-US-1140 | G50: MSBBPA150 | M50: Web版型・木型マスタ一覧照会 | V50: 1.0.0 | AB50: r01.00
A53: 共通（元データ）
A54: Webシステム | K54: 文書名 | U54: モジュールID | Z54: MS | AE54: モジュール名 | AJ54: Webシステム | AS54: 文書番号 | AZ54: Version | BF54: Rev.
K55: 画面説明書 | U55: ｻﾌﾞﾓｼﾞｭｰﾙID | Z55: MSBB | AE55: ｻﾌﾞﾓｼﾞｭｰﾙ名 | AJ55: 販売Webシステム | AS55: M7-US-1140 | AZ55: 1.0.0 | BF55: r00.00
K56: 表紙 | U56: 表題 | Z56: MSBBPA150 | AE56: Web版型・木型マスタ一覧照会
A57: 共通（リンク用）
A58: =A54 -> Webシステム | K58: 文書名 | U58: モジュールID | Z58: =Z54 -> MS | AE58: モジュール名 | AJ58: =AJ54 -> Webシステム | AS58: 文書番号 | AZ58: Version | BF58: Rev.
...

Sheet 改訂
K1: 改訂 | AU1: 作成者 | AZ1: MDSOL | BE1: 作成日 | BJ1: =表紙!W42 -> 44805 | BP1: Rev.
AU2: 修正者 | BE2: 改訂日 | BP2: =表紙!CB64 -> 1
A5: Rev. | F5: 改定内容 | BC5: 頁 | BM5: 変更日 変更者 | BR5: 確認日 確認者
A7: 1 | F7: 新規作成

Sheet 概要
A1: =表紙!A54 -> Webシステム | O1: 文書名 | AC1: モジュールID | AJ1: =表紙!AJ63 -> MS | AQ1: モジュール名 | AX1: =表紙!AX63 -> Webシステム | BL1: 文書番号 | BU1: Version | CB1: Rev.
O2: =表紙!O64 -> アドオン設計書 | AC2: サブモジュールID | AJ2: =表紙!AJ64 -> MSBB | AQ2: サブモジュール名 | AX2: =表紙!AX64 -> 販売Webシステム | BL2: =表紙!BL64 -> M7-US-1140 | BU2: =表紙!BU64 -> 1.0.0 | CB2: =表紙!CB64 -> 1
O3: =RIGHT(CELL("filename",$A$1),LEN(CELL("filename",$A$1))-FIND("]",CELL("filename",$A$1))) -> #VALUE! | AC3: 表題 | AJ3: =表紙!AJ65 -> MSBBPA150 | AQ3: =表紙!AQ65 -> Web版型・木型マスタ一覧照会
AO5: 概要
B7: 【説明】
C8: 版型・木型マスタ一覧照会画面
B10: 【目的】
C11: 版型・木型マスタを一覧照会する
B13: 【処理関連図/サービス関連図】
C14: ※処理・サービス関連図シートに詳細記載
B16: 【オペレーション一覧】
C17: 版型・木型マスタの検索・照会処理を行う
C18: 版型・木型ラベルの帳票発行(ラベル発行)を行う
C19: 版型・木型マスタのCSV出力を行う
B21: 【SQLID一覧】
C22: なし
B24: 【ソート順】
C25: 版型・木型NO、Rev
B27: 【データアクセスコントロール】
C28: 拠点による制御
C29: ※詳細は、【MSBBPA000】_共通設計書_アドオン(Webシステム共通仕様)にて定義
B31: 【自由記述】
C32: なし

Sheet 画面イメージ
A1: =表紙!A54 -> Webシステム | K1: 文書名 | U1: モジュールID | Z1: =表紙!$AJ$63 -> MS | AE1: モジュール名 | AJ1: =表紙!$AX$63 -> Webシステム | AS1: 文書番号 | AZ1: Version | BF1: Rev.
K2: =表紙!O64 -> アドオン設計書 | U2: ｻﾌﾞﾓｼﾞｭｰﾙID | Z2: =表紙!$AJ$64 -> MSBB | AE2: ｻﾌﾞﾓｼﾞｭｰﾙ名 | AJ2: =表紙!$AX$64 -> 販売Webシステム | AS2: =表紙!$BL$64 -> M7-US-1140 | AZ2: =表紙!$BU$64 -> 1.0.0 | BF2: =表紙!$CB$64 -> 1
K3: =RIGHT(CELL("filename",$A$1),LEN(CELL("filename",$A$1))-FIND("]",CELL("filename",$A$1))) -> #VALUE! | U3: 表題 | Z3: =表紙!$AJ$65 -> MSBBPA150 | AE3: =表紙!$AQ$65 -> Web版型・木型マスタ一覧照会
A5: 画面イメージ
B7: ≫凡例
Q8: ・・・ | S8: ボタン
C9: 見積計算書NO | Q9: ・・・ | S9: 検索項目(検索画面表示選択) | AJ9: 参照情報
C10: 品名 | Q10: ・・・ | S10: 入力項目
C11: 得意先 | Q11: ・・・ | S11: 表示項目(得意先名称、原紙名等) | AJ11: 担当者
C12: 操作種別 | I12: ●登録 | M12: ○訂正 | Q12: ・・・ | S12: 選択項目(一つのみ選択可能)
C13: 受注区分 | Q13: ・・・ | S13: 選択項目(一つのみ選択可能)
C14: 作業順 | I14: ☑AAA | M14: ☑BBB | Q14: ・・・ | S14: 選択項目(複数選択可能)
C16: 見積作成日 | Q16: ・・・ | S16: カレンダー形式
BO21: －
BW22: CP指摘事項 2022/09/21 土屋 案件Noで検索出来ると良いお思います | DT22: MDSOL 野村 2022/10/25 見積計算書NOに紐づく案件NOを抽出条件として、追加します。 | EU22: 2022/10/27 落合 問題なし
D23: 拠点 | AC23: 担当者 | BB23: * | BC23: あいまい検索可能
BW24: CP指摘事項 2022/09/22 三宅 検索条件が多すぎて一覧表示画面が小さくなるのである程度絞っても良いかも またはよく使うものを表示して細かい条件は折り畳み表示が必要かも | DT24: MDSOL 野村 2022/10/25 あいまい検索は、部分一致の検索となります。(文字の全角と半角、大文字と小文字は区別されます。スペース区切りの複数指定はできません。)
D25: 適用開始日 | O25: ~ | AC25: 手配NO | AN25: * | BX25: この「* あいまい検索可能」とはどういう意味でしょうか | EB25: 版型名と手配NOがあいまい検索対象です
D26: 版型NO | O26: ~ | AC26: 版型名称 | AN26: * | BX26: 一般的な用法の、文字列の全角と半角、大文字と小文字などの表記ゆれを区別せずに検索できるという理解で正しいでしょうか？ | EB26: 対象は、項目説明に「あいまい検索可」をつけるようにしています。 | EU26: CP指摘 2022/10/27 落合 大文字・小文字は区別せず検索できないか？ その他は問題なし
D27: 版型分類 | AC27: 新版区分 | BX27: Elasticsearch等全文検索エンジンを使用？Oracleの機能プラス形態素解析やN-gram併用？ | EV27: MDSOL 野村 2022/10/31 WEBだけの変更であれば可能です。ただし、mcframe7でも大文字と小文字は区別されます。挙動をmcframe7と合わせたいと思いますが、いかがでしょうか。
D28: 得意先 | BX28: 実装方法は不明ですが追加の仕様策定が必要ではないでしょうか？
D29: 代表製品CD | BX29: そもそも検索対象に版型名や備考欄が無いのであいまい検索を適用する箇所が無いのでは | FE29: mcframe7：メニュー検索等の一部を除いて基本大文字と小文字は区別されます。
FF30: 2022/11/01 落合 webだけでもやってください
D31: 工程 | AC31: 通し数 | AN31: ~ | BW31: CP指摘事項 2022/09/22 三宅 | FG31: MDSOL 野村 2022/11/02 承知しました。 | FX31: 2022/11/04 落合 問題なし
D32: 発注先 | AC32: 限界通し数 | AN32: ~ | BX32: ものすごい幅の長いテーブルになりそうだと心配しましたが、ComponentOneを使うらしいので、コンポーネントの一種 FlexGrid のデモを見たところ列の表示非表示の切替えや折り畳み表示列が作れるので適宜調整可能で見づらい問題はなさそうです | FO32: 共通仕様に明記します。
D33: 場所 | AC33: 棚・ライン | BX33: https://demo.grapecity.com/c1/aspnet/MvcExplorer/FlexGrid/ShowCase
BX34: FlexGrid はかなり高度なことが出来るので、機能のどこまでを実装するかについては版型一覧画面に限らず決めておく必要がありそうです | DT34: MDSOL 野村 2022/10/25
D35: 入荷日 | O35: ~ | AC35: 廃棄予定日 | AN35: ~ | BX35: 可能なら列の表示非表示切替・ソート・フィルター・エクスポートはどの一覧画面にも実装してほしいです | DU35: 現行想定は、一覧照会はMultiRowを使用する想定です。 | EU35: CP指摘 2022/10/27 落合 Multirowの標準機能でソート・エクスポートは可能と思います。
D36: 返却予定日 | O36: ~ | AC36: 返却日 | AN36: ~ | DU36: 基本は全項目ソート可能としたいですが、開発時、レスポンスなどを加味したうえで相談させてください。 | EW36: MDSOL 野村 2022/10/31 エクスポート追加します。
FE37: CSV出力と機能重複しますが、両方必要でしょうか。
D38: 対象 | J38: ☑最新Revのみ表示 | DU38: 列の表示非表示の切替えや折り畳み表示列の機能に関して | EX38: 2022/11/01 csv出力のみで結構です。
DV39: 現行は、実装を想定していないです。 | EY39: MDSOL 野村 2022/11/02 承知しました。
DV40: プラスで条件の保存機能が必要になるのではと考えます。 | EY40: 2022/11/04 落合 問題なし
D41: NO | F41: 発行 | H41: 版型NO | M41: 版型名 | T41: Rev | V41: 版型分類 | Y41: 得意先 | AB41: 得意先名 | AF41: 製品コード | AK41: 製品名 | AQ41: 通し数 | AU41: 限界通し数 | AY41: 発注先 | BB41: 発注先名 | BF41: 入荷日 | BK41: 廃棄予定日 | BP41: 返却予定日 | BU41: 返却日 | BZ41: 返却理由
D43: 1 | F43: ☑ | H43: X/999991 | M43: XXXXXXX8XXXXXXX8 | U43: 1 | V43: 木型 | Y43: 12345 | AB43: XXXXXXX8 | AF43: 99999999-01 | AK43: 品名１＋品名２ | AQ43: 1000 | AU43: 1000 | AY43: 12345 | BB43: XXXXXXX8 | BF43: 2022/07/01 | BK43: 2022/07/01 | BP43: 2022/07/01 | BU43: 2022/07/01 | DJ43: CP指摘 2022/10/27 落合 版型名までを固定表示し、以降の項目をスクロールにして欲しい
D44: 2 | F44: ☑ | H44: X/999992 | M44: XXXXXXX8XXXXXXX8 | U44: 2 | V44: 木型 | Y44: 12345 | AB44: XXXXXXX8 | AF44: 99999999-02 | AK44: 品名１＋品名２ | AQ44: 1000 | AU44: 1000 | AY44: 12345 | BB44: XXXXXXX8 | BF44: 2022/07/01 | BK44: 2022/07/01 | BP44: 2022/07/01 | BU44: 2022/07/01 | DK44: MDSOL 野村 2022/10/31 セル固定をレイアウトに明記しました。
D45: 3 | F45: ☑ | H45: X/999993 | M45: XXXXXXX8XXXXXXX8 | U45: 3 | V45: 木型 | Y45: 12345 | AB45: XXXXXXX8 | AF45: 99999999-03 | AK45: 品名１＋品名２ | AQ45: 1000 | AU45: 1000 | AY45: 12345 | BB45: XXXXXXX8 | BF45: 2022/07/01 | BK45: 2022/07/01 | BP45: 2022/07/01 | BU45: 2022/07/01 | DL45: 2022/11/01 csv出力のみで結構です。
D46: 4 | F46: □ | H46: X/999994 | M46: XXXXXXX8XXXXXXX8 | U46: 4 | V46: 木型 | Y46: 12345 | AB46: XXXXXXX8 | AF46: 99999999-04 | AK46: 品名１＋品名２ | AQ46: 2000 | AU46: 2000 | AY46: 12345 | BB46: XXXXXXX8 | BF46: 2022/07/01 | BK46: 2022/07/01 | BP46: 2022/07/01 | BU46: 2022/07/01
D47: 5 | F47: □ | H47: X/999995 | M47: XXXXXXX8XXXXXXX8 | U47: 5 | V47: 木型 | Y47: 12345 | AB47: XXXXXXX8 | AF47: 99999999-05 | AK47: 品名１＋品名２ | AQ47: 2000 | AU47: 2000 | AY47: 12345 | BB47: XXXXXXX8 | BF47: 2022/07/01 | BK47: 2022/07/01 | BP47: 2022/07/01 | BU47: 2022/07/01
D48: 6 | F48: □ | H48: X/999996 | M48: XXXXXXX8XXXXXXX8 | U48: 6 | V48: 木型 | Y48: 12345 | AB48: XXXXXXX8 | AF48: 99999999-06 | AK48: 品名１＋品名２ | AQ48: 2000 | AU48: 2000 | AY48: 12345 | BB48: XXXXXXX8 | BF48: 2022/07/01 | BK48: 2022/07/01 | BP48: 2022/07/01 | BU48: 2022/07/01
...

Sheet 項目説明
A1: =表紙!A54 -> Webシステム | K1: 文書名 | U1: モジュールID | Z1: =表紙!$AJ$63 -> MS | AE1: モジュール名 | AJ1: =表紙!$AX$63 -> Webシステム | AS1: 文書番号 | AZ1: Version | BF1: Rev.
K2: =表紙!O64 -> アドオン設計書 | U2: ｻﾌﾞﾓｼﾞｭｰﾙID | Z2: =表紙!$AJ$64 -> MSBB | AE2: ｻﾌﾞﾓｼﾞｭｰﾙ名 | AJ2: =表紙!$AX$64 -> 販売Webシステム | AS2: =表紙!$BL$64 -> M7-US-1140 | AZ2: =表紙!$BU$64 -> 1.0.0 | BF2: =表紙!$CB$64 -> 1
K3: =RIGHT(CELL("filename",$A$1),LEN(CELL("filename",$A$1))-FIND("]",CELL("filename",$A$1))) -> #VALUE! | U3: 表題 | Z3: =表紙!$AJ$65 -> MSBBPA150 | AE3: =表紙!$AQ$65 -> Web版型・木型マスタ一覧照会
A5: Web版型・木型マスタ一覧照会
B6: 抽出条件 | N6: 説明 | BE6: Ｗ | BF6: 型 | BG6: 参 | BH6: 必 | BI6: 入 | BJ6: 非 | BK6: 検
A7: 〇 | B7: 拠点 | M7: 【MSBBPACOM】_共通設計書_アドオン(共通ロジック)にて定義 | BE7: C | BF7: S
A8: 〇 | B8: 担当者 | M8: 【MSBBPACOM】_共通設計書_アドオン(共通ロジック)にて定義 | BE8: C | BF8: S
A9: 〇 | B9: 適用開始日(From) | M9: 抽出条件として、適用開始日(From)を入力する | BE9: カ | BF9: D
A10: 〇 | B10: 適用開始日(To) | M10: 抽出条件として、適用開始日(To)を入力する | BE10: カ | BF10: D
A11: 〇 | B11: 手配NO | M11: 抽出条件として、手配NOを入力する | AZ11: あいまい検索可 | BE11: T | BF11: S
A12: 〇 | B12: 版型NO(From) | M12: 抽出条件として、版型NO(From)を入力する | BE12: T | BF12: S
A13: 〇 | B13: 版型NO(To) | M13: 抽出条件として、版型NO(To)を入力する | BE13: T | BF13: S
A14: 〇 | B14: 版型名称 | M14: 抽出条件として、版型名称を入力する | AZ14: あいまい検索可 | BE14: T | BF14: S
A15: 〇 | B15: 版型分類 | M15: 【MSBBPACOM】_共通設計書_アドオン(共通ロジック)にて定義 | BF15: S
A16: 〇 | B16: 新版区分 | M16: 【MSBBPACOM】_共通設計書_アドオン(共通ロジック)にて定義 | BF16: S
A17: 〇 | B17: 得意先 | M17: 【MSBBPACOM】_共通設計書_アドオン(共通ロジック)にて定義 | BE17: A | BF17: S | BK17: 検
A18: 〇 | B18: 代表製品CD | M18: 【MSBBPACOM】_共通設計書_アドオン(共通ロジック)にて定義 | BF18: S | BK18: 検
A19: 〇 | B19: 工程 | M19: 【MSBBPACOM】_共通設計書_アドオン(共通ロジック)にて定義 | BE19: C | BF19: S
A20: 〇 | B20: 通し数(From) | M20: 抽出条件として、通し数(From)を入力する | BE20: T | BF20: N
A21: 〇 | B21: 通し数(To) | M21: 抽出条件として、通し数(To)を入力する | BE21: T | BF21: N
A22: 〇 | B22: 発注先 | M22: 【MSBBPACOM】_共通設計書_アドオン(共通ロジック)にて定義 | BF22: S | BK22: 検
A23: 〇 | B23: 限界通し数(From) | M23: 抽出条件として、限界通し数(From)を入力する | BE23: T | BF23: N
A24: 〇 | B24: 限界通し数(To) | M24: 抽出条件として、限界通し数(To)を入力する | BE24: T | BF24: N
A25: 〇 | B25: 場所 | M25: 【MSBBPACOM】_共通設計書_アドオン(共通ロジック)にて定義 | BF25: S | BK25: 検
A26: 〇 | B26: 棚・ライン | M26: 【MSBBPACOM】_共通設計書_アドオン(共通ロジック)にて定義 | BF26: S | BK26: 検
A27: 〇 | B27: 入荷日(From) | M27: 抽出条件として、入荷日(From)を入力する | BE27: カ | BF27: D
A28: 〇 | B28: 入荷日(To) | M28: 抽出条件として、入荷日(To)を入力する | BE28: カ | BF28: D
A29: 〇 | B29: 廃棄予定日(From) | M29: 抽出条件として、廃棄予定日(From)を入力する | BE29: カ | BF29: D
A30: 〇 | B30: 廃棄予定日(To) | M30: 抽出条件として、廃棄予定日(To)を入力する | BE30: カ | BF30: D
A31: 〇 | B31: 返却予定日(From) | M31: 抽出条件として、返却予定日(From)を入力する | BE31: カ | BF31: D
A32: 〇 | B32: 返却予定日(To) | M32: 抽出条件として、返却予定日(To)を入力する | BE32: カ | BF32: D
A33: 〇 | B33: 返却日(From) | M33: 抽出条件として、返却日(From)を入力する | BE33: カ | BF33: D
A34: 〇 | B34: 返却日(To) | M34: 抽出条件として、返却日(To)を入力する | BE34: カ | BF34: D
A35: 〇 | B35: 最新Revのみ表示 | M35: 最新Revのみ抽出条件とする場合に、チェックする | AS35: 初期値☑有 | BE35: チ | BF35: F
B37: Web版型・木型マスタ一覧 | N37: 説明 | BE37: Ｗ | BF37: 型 | BG37: 参 | BH37: 必 | BI37: 入 | BJ37: 非 | BK37: 検
B38: NO | M38: 行番を表示 | BE38: T | BF38: N
A39: ● | B39: 発行 | M39: 発行を表示 | BE39: チ | BF39: F
B40: 版型NO | M40: 版型NOを表示 | BE40: T | BF40: S
B41: 版型名 | M41: 版型名を表示 | AS41: 発行～版型名までセル固定 | BE41: T | BF41: S
B42: Rev | M42: Revを表示 | BE42: T | BF42: N
...

Sheet 引数説明
A1: =表紙!A54 -> Webシステム | K1: 文書名 | U1: モジュールID | Z1: =表紙!$AJ$63 -> MS | AE1: モジュール名 | AJ1: =表紙!$AX$63 -> Webシステム | AS1: 文書番号 | AZ1: Version | BF1: Rev.
K2: =表紙!O64 -> アドオン設計書 | U2: ｻﾌﾞﾓｼﾞｭｰﾙID | Z2: =表紙!$AJ$64 -> MSBB | AE2: ｻﾌﾞﾓｼﾞｭｰﾙ名 | AJ2: =表紙!$AX$64 -> 販売Webシステム | AS2: =表紙!$BL$64 -> M7-US-1140 | AZ2: =表紙!$BU$64 -> 1.0.0 | BF2: =表紙!$CB$64 -> 1
K3: =RIGHT(CELL("filename",$A$1),LEN(CELL("filename",$A$1))-FIND("]",CELL("filename",$A$1))) -> #VALUE! | U3: 表題 | Z3: =表紙!$AJ$65 -> MSBBPA150 | AE3: =表紙!$AQ$65 -> Web版型・木型マスタ一覧照会
B5: オペレーションＩＤ/名称：SloRecvIfImp_Upd01/取込
A6: 必 | B6: 項目名 | N6: 説明 | AS6: 未設定時の振る舞い

Sheet 処理概要
A1: =表紙!A54 -> Webシステム | K1: 文書名 | U1: モジュールID | Z1: =表紙!$AJ$63 -> MS | AE1: モジュール名 | AJ1: =表紙!$AX$63 -> Webシステム | AS1: 文書番号 | AZ1: Version | BF1: Rev.
K2: =表紙!O64 -> アドオン設計書 | U2: ｻﾌﾞﾓｼﾞｭｰﾙID | Z2: =表紙!$AJ$64 -> MSBB | AE2: ｻﾌﾞﾓｼﾞｭｰﾙ名 | AJ2: =表紙!$AX$64 -> 販売Webシステム | AS2: =表紙!$BL$64 -> M7-US-1140 | AZ2: =表紙!$BU$64 -> 1.0.0 | BF2: =表紙!$CB$64 -> 1
K3: =RIGHT(CELL("filename",$A$1),LEN(CELL("filename",$A$1))-FIND("]",CELL("filename",$A$1))) -> #VALUE! | U3: 表題 | Z3: =表紙!$AJ$65 -> MSBBPA150 | AE3: =表紙!$AQ$65 -> Web版型・木型マスタ一覧照会
A5: NO | B5: 入力 | J5: 処理 | BD5: 出力
A6: 1 | B6: 初期表示
J7: 1.処理概要
K8: 初期表示
L9: 拠点 | Q9: ： | R9: ログインに紐づく拠点CDを表示する
R10: ログイン.管理者区分 = 0(一般ユーザー時)、変更不可とする
L11: 担当者 | Q11: ： | R11: ログイン担当者CDを表示する
L12: 適用開始日 | Q12: ： | R12: 適用開始日Fromに当日 - ログインマスタ.初期表示をセット、Toに当日をセットする
L13: 表示処理 | Q13: ： | R13: 抽出条件をもとにWeb版型・木型マスタ一覧に結果を表示する | BD13: 検索入出力仕様.NO1
L15: フッターボタン表示・非表示切替
M16: メニューから呼び出された場合(照会画面モード) | AC16: ・・・ | AE16: 発行ラベルを表示する、選択ボタンを非表示する
M17: 検索画面として呼び出された場合(検索画面モード) | AC17: ・・・ | AE17: 発行ラベルを非表示する、選択ボタンを表示する
M18: 例)検索画面モード:Web版型・木型マスタから検索画面として呼び出され、選択行を返す場合
A20: 2 | B20: 画面操作
J21: 1.処理概要
K22: ボタン処理
L23: クリアボタン押下 | U23: ： | V23: 画面を初期化する(起動時の状態とする)
L24: 表示ボタン押下 | U24: ： | V24: チェック処理にてエラーとなった場合、後続処理をキャンセルする
L25: (チェック処理) | W25: FROM～TOの整合性チェック | AH25: … | AI25: エラーメッセージ：FROM≦TOの関係で指定してください。 | BD25: メッセージID.001
L26: 表示 | U26: ： | V26: 抽出条件をもとにWeb版型・木型マスタ一覧に結果を表示する | BD26: 検索入出力仕様.NO1
W27: データ取得できなかった場合、下記メッセージを表示
W28: エラーメッセージ：検索結果がありません。 | BD28: メッセージID.002
L29: ラベル発行 | U29: ： | V29: 一覧の発行にチェックされたデータを「版型ラベル」として出力する
W30: 発行☑が1行もチェックされていない場合、下記メッセージを表示
W31: エラーメッセージ：発行対象がありません。 | BD31: メッセージID.003
V32: →発行☑された行のラベル発行用のCSVファイルを出力する | BD32: ファイル入出力仕様.NO2
W33: ※1回の操作での複数行指定時は、1ファイルに出力する
W34: 複数回ラベル発行をクリックすると、クリック分ファイル出力されます
L35: CSV出力 | U35: ： | V35: Web版型・木型マスタ一覧のデータをCSV出力する | BD35: ファイル入出力仕様.NO1
U36: ※1 CSV出力定義とファイル名は、【MSBBPACOM】_共通設計書_アドオン(共通ロジック)にて定義
U37: ※2 画面に表示されたデータがCSVとして出力される
L38: 選択 | U38: ： | V38: 検索モードで開いた場合に選択結果(1行)を遷移元画面に返す
W39: 一覧にデータが無いもしくは対象行が選択されてない場合、下記メッセージを表示
W40: エラーメッセージ：選択行がありません。 | BD40: メッセージID.004
U41: ※1 選択された版型・木型マスタの1レコードを呼出元に返す
U42: ※2 複数選択は許可しない

Sheet 処理詳細
A1: =表紙!A54 -> Webシステム | K1: 文書名 | U1: モジュールID | Z1: =表紙!$AJ$63 -> MS | AE1: モジュール名 | AJ1: =表紙!$AX$63 -> Webシステム | AS1: 文書番号 | AZ1: Version | BF1: Rev.
K2: =表紙!O64 -> アドオン設計書 | U2: ｻﾌﾞﾓｼﾞｭｰﾙID | Z2: =表紙!$AJ$64 -> MSBB | AE2: ｻﾌﾞﾓｼﾞｭｰﾙ名 | AJ2: =表紙!$AX$64 -> 販売Webシステム | AS2: =表紙!$BL$64 -> M7-US-1140 | AZ2: =表紙!$BU$64 -> 1.0.0 | BF2: =表紙!$CB$64 -> 1
K3: =RIGHT(CELL("filename",$A$1),LEN(CELL("filename",$A$1))-FIND("]",CELL("filename",$A$1))) -> #VALUE! | U3: 表題 | Z3: =表紙!$AJ$65 -> MSBBPA150 | AE3: =表紙!$AQ$65 -> Web版型・木型マスタ一覧照会
A5: No | B5: 入力 | J5: 処理 | BD5: 出力
A6: 1 | B6: 初期表示
A12: 2 | B12: 画面操作
A18: 3 | B18: 検索【F1】

Sheet 処理・サービス関連図
A1: =表紙!A54 -> Webシステム | K1: 文書名 | U1: モジュールID | Z1: =表紙!$AJ$63 -> MS | AE1: モジュール名 | AJ1: =表紙!$AX$63 -> Webシステム | AS1: 文書番号 | AZ1: Version | BF1: Rev.
K2: =表紙!O64 -> アドオン設計書 | U2: ｻﾌﾞﾓｼﾞｭｰﾙID | Z2: =表紙!$AJ$64 -> MSBB | AE2: ｻﾌﾞﾓｼﾞｭｰﾙ名 | AJ2: =表紙!$AX$64 -> 販売Webシステム | AS2: =表紙!$BL$64 -> M7-US-1140 | AZ2: =表紙!$BU$64 -> 1.0.0 | BF2: =表紙!$CB$64 -> 1
K3: =RIGHT(CELL("filename",$A$1),LEN(CELL("filename",$A$1))-FIND("]",CELL("filename",$A$1))) -> #VALUE! | U3: 表題 | Z3: =表紙!$AJ$65 -> MSBBPA150 | AE3: =表紙!$AQ$65 -> Web版型・木型マスタ一覧照会
C7: 検索処理

Sheet 検索入出力仕様
A1: =表紙!A54 -> Webシステム | K1: 文書名 | U1: モジュールID | Z1: =表紙!$AJ$63 -> MS | AE1: モジュール名 | AJ1: =表紙!$AX$63 -> Webシステム | AS1: 文書番号 | AZ1: Version | BF1: Rev.
K2: =表紙!O64 -> アドオン設計書 | U2: ｻﾌﾞﾓｼﾞｭｰﾙID | Z2: =表紙!$AJ$64 -> MSBB | AE2: ｻﾌﾞﾓｼﾞｭｰﾙ名 | AJ2: =表紙!$AX$64 -> 販売Webシステム | AS2: =表紙!$BL$64 -> M7-US-1140 | AZ2: =表紙!$BU$64 -> 1.0.0 | BF2: =表紙!$CB$64 -> 1
K3: =RIGHT(CELL("filename",$A$1),LEN(CELL("filename",$A$1))-FIND("]",CELL("filename",$A$1))) -> #VALUE! | U3: 表題 | Z3: =表紙!$AJ$65 -> MSBBPA150 | AE3: =表紙!$AQ$65 -> Web版型・木型マスタ一覧照会
A5: NO | G5: 1 | S5: ボタン | Z5: 表示 | AH5: 備考 | AK5: 表示ボタンクリック時処理
A6: 処理分類 | E6: 検索 | S6: ソート順 | Z6: 版型NO、Rev
A7: NO | C7: 転送先 | V7: 転送元 | AQ7: 説明
C8: 種 | D8: オブジェクト | K8: 項目名 | V8: 種 | W8: オブジェクト | AF8: 項目名
A9: 1 | C9: 画 | D9: Web版型・木型マスタ一覧 | K9: NO | AF9: 行番
A10: 2 | C10: 画 | D10: Web版型・木型マスタ一覧 | K10: 発行 | AF10: [固定値:0] ※チェック無し
A11: 3 | C11: 画 | D11: Web版型・木型マスタ一覧 | K11: 版型NO | V11: T | W11: 版型・木型管理マスタ | AF11: 版型NO
A12: 4 | C12: 画 | D12: Web版型・木型マスタ一覧 | K12: 版型名 | V12: T | W12: 版型・木型管理マスタ | AF12: 版型名
A13: 5 | C13: 画 | D13: Web版型・木型マスタ一覧 | K13: Rev | V13: T | W13: 版型・木型管理マスタ | AF13: Rev
A14: 6 | C14: 画 | D14: Web版型・木型マスタ一覧 | K14: 版型分類 | V14: T | W14: 版型・木型管理マスタ | AF14: 版型分類
A15: 7 | C15: 画 | D15: Web版型・木型マスタ一覧 | K15: 得意先 | V15: T | W15: 版型・木型管理マスタ | AF15: 得意先
A16: 8 | C16: 画 | D16: Web版型・木型マスタ一覧 | K16: 得意先名 | V16: T | W16: 得意先 | AF16: 得意先名
A17: 9 | C17: 画 | D17: Web版型・木型マスタ一覧 | K17: 製品コード | V17: T | W17: 版型・木型管理マスタ | AF17: 製品コード
A18: 10 | C18: 画 | D18: Web版型・木型マスタ一覧 | K18: 製品名 | V18: T | W18: 製品マスタ | AF18: 品名1 + 品名2
A19: 11 | C19: 画 | D19: Web版型・木型マスタ一覧 | K19: 通し数 | V19: T | W19: 版型・木型管理マスタ | AF19: 通し数
A20: 12 | C20: 画 | D20: Web版型・木型マスタ一覧 | K20: 限界通し数 | V20: T | W20: 版型・木型管理マスタ | AF20: 限界通し数
A21: 13 | C21: 画 | D21: Web版型・木型マスタ一覧 | K21: 発注先 | V21: T | W21: 版型・木型管理マスタ | AF21: 発注先
A22: 14 | C22: 画 | D22: Web版型・木型マスタ一覧 | K22: 発注先名 | V22: T | W22: 発注先 | AF22: 発注先名
... A46: 38 | C46: 画 | D46: Web版型・木型マスタ一覧 | K46: 備考 | V46: T | W46: 版型・木型管理マスタ | AF46: 備考

Sheet 更新入出力仕様
A1: =表紙!A54 -> Webシステム | K1: 文書名 | U1: モジュールID | Z1: =表紙!$AJ$63 -> MS | AE1: モジュール名 | AJ1: =表紙!$AX$63 -> Webシステム | AS1: 文書番号 | AZ1: Version | BF1: Rev.
K2: =表紙!O64 -> アドオン設計書 | U2: ｻﾌﾞﾓｼﾞｭｰﾙID | Z2: =表紙!$AJ$64 -> MSBB | AE2: ｻﾌﾞﾓｼﾞｭｰﾙ名 | AJ2: =表紙!$AX$64 -> 販売Webシステム | AS2: =表紙!$BL$64 -> M7-US-1140 | AZ2: =表紙!$BU$64 -> 1.0.0 | BF2: =表紙!$CB$64 -> 1
K3: =RIGHT(CELL("filename",$A$1),LEN(CELL("filename",$A$1))-FIND("]",CELL("filename",$A$1))) -> #VALUE! | U3: 表題 | Z3: =表紙!$AJ$65 -> MSBBPA150 | AE3: =表紙!$AQ$65 -> Web版型・木型マスタ一覧照会
A5: No | G5: 1 | S5: ロジック名称 | AH5: 備考
A6: 処理分類 | E6: 更新
A7: No | C7: 転送先 | V7: 転送元 | AQ7: 説明
C8: 種 | D8: オブジェクト | K8: 項目名 | V8: 種 | W8: オブジェクト | AF8: 項目名

Sheet ファイル入出力仕様
A1: =表紙!A54 -> Webシステム | K1: 文書名 | U1: モジュールID | Z1: =表紙!$AJ$63 -> MS | AE1: モジュール名 | AJ1: =表紙!$AX$63 -> Webシステム | AS1: 文書番号 | AZ1: Version | BF1: Rev.
K2: =表紙!O64 -> アドオン設計書 | U2: ｻﾌﾞﾓｼﾞｭｰﾙID | Z2: =表紙!$AJ$64 -> MSBB | AE2: ｻﾌﾞﾓｼﾞｭｰﾙ名 | AJ2: =表紙!$AX$64 -> 販売Webシステム | AS2: =表紙!$BL$64 -> M7-US-1140 | AZ2: =表紙!$BU$64 -> 1.0.0 | BF2: =表紙!$CB$64 -> 1
K3: =RIGHT(CELL("filename",$A$1),LEN(CELL("filename",$A$1))-FIND("]",CELL("filename",$A$1))) -> #VALUE! | U3: 表題 | Z3: =表紙!$AJ$65 -> MSBBPA150 | AE3: =表紙!$AQ$65 -> Web版型・木型マスタ一覧照会
A5: NO | G5: 1 | S5: ロジック名称 | Z5: ファイル出力 | AH5: 備考
A6: 処理分類 | E6: ファイル出力 | S6: ソート順 | Z6: 版型NO、Rev
A7: NO | C7: 転送先 | X7: 転送元 | AS7: 説明
C8: 種 | D8: オブジェクト | M8: 項目名 | X8: 種 | Y8: オブジェクト | AH8: 項目名
A9: 1 | C9: フ | D9: Web版型・木型マスタ一覧 | M9: NO | X9: 画 | Y9: Web版型・木型マスタ一覧 | AH9: 行番
A10: 2 | C10: フ | D10: Web版型・木型マスタ一覧 | M10: 版型NO | X10: 画 | Y10: Web版型・木型マスタ一覧 | AH10: 版型NO
A11: 3 | C11: フ | D11: Web版型・木型マスタ一覧 | M11: 版型名 | X11: 画 | Y11: Web版型・木型マスタ一覧 | AH11: 版型名
A12: 4 | C12: フ | D12: Web版型・木型マスタ一覧 | M12: Rev | X12: 画 | Y12: Web版型・木型マスタ一覧 | AH12: Rev
A13: 5 | C13: フ | D13: Web版型・木型マスタ一覧 | M13: 版型分類 | X13: 画 | Y13: Web版型・木型マスタ一覧 | AH13: 版型分類
A14: 6 | C14: フ | D14: Web版型・木型マスタ一覧 | M14: 得意先 | X14: 画 | Y14: Web版型・木型マスタ一覧 | AH14: 得意先
A15: 7 | C15: フ | D15: Web版型・木型マスタ一覧 | M15: 得意先名 | X15: 画 | Y15: Web版型・木型マスタ一覧 | AH15: 得意先名
A16: 8 | C16: フ | D16: Web版型・木型マスタ一覧 | M16: 製品コード | X16: 画 | Y16: Web版型・木型マスタ一覧 | AH16: 製品コード
A17: 9 | C17: フ | D17: Web版型・木型マスタ一覧 | M17: 製品名 | X17: 画 | Y17: Web版型・木型マスタ一覧 | AH17: 製品名
A18: 10 | C18: フ | D18: Web版型・木型マスタ一覧 | M18: 通し数 | X18: 画 | Y18: Web版型・木型マスタ一覧 | AH18: 通し数
A19: 11 | C19: フ | D19: Web版型・木型マスタ一覧 | M19: 限界通し数 | X19: 画 | Y19: Web版型・木型マスタ一覧 | AH19: 限界通し数
A20: 12 | C20: フ | D20: Web版型・木型マスタ一覧 | M20: 発注先 | X20: 画 | Y20: Web版型・木型マスタ一覧 | AH20: 発注先
... A45: 37 | C45: フ | D45: Web版型・木型マスタ一覧 | M45: 備考 | X45: 画 | Y45: Web版型・木型マスタ一覧 | AH45: 備考
A47: NO | G47: 2 | V47: ロジック名称 | AC47: ラベル発行 | AK47: 備考 | AN47: 版・型管理ラベル発行用のCSVファイルの出力
A48: 処理分類 | E48: ファイル出力 | V48: ソート順 | AC48: 版型NO、Rev
A49: NO | C49: 転送先 | X49: 転送元 | AS49: 説明
C50: 種 | D50: オブジェクト | O50: 項目名 | X50: 種 | Y50: オブジェクト | AH50: 項目名
A51: 1 | C51: フ | D51: 版・型管理ラベル出力用CSVファイル | O51: 版型NO | X51: 画 | Y51: Web版型・木型マスタ一覧 | AH51: 版型NO
A52: 2 | C52: フ | D52: 版・型管理ラベル出力用CSVファイル | O52: 版型名 | X52: 画 | Y52: Web版型・木型マスタ一覧 | AH52: 版型名
A53: 3 | C53: フ | D53: 版・型管理ラベル出力用CSVファイル | O53: Rev | X53: 画 | Y53: Web版型・木型マスタ一覧 | AH53: Rev
A54: 4 | C54: フ | D54: 版・型管理ラベル出力用CSVファイル | O54: 版型分類 | X54: 画 | Y54: Web版型・木型マスタ一覧 | AH54: 版型分類
A55: 5 | C55: フ | D55: 版・型管理ラベル出力用CSVファイル | O55: 得意先 | X55: 画 | Y55: Web版型・木型マスタ一覧 | AH55: 得意先
A56: 6 | C56: フ | D56: 版・型管理ラベル出力用CSVファイル | O56: 得意先名 | X56: 画 | Y56: Web版型・木型マスタ一覧 | AH56: 得意先名
A57: 7 | C57: フ | D57: 版・型管理ラベル出力用CSVファイル | O57: 製品コード | X57: 画 | Y57: Web版型・木型マスタ一覧 | AH57: 製品コード
A58: 8 | C58: フ | D58: 版・型管理ラベル出力用CSVファイル | O58: 製品名 | X58: 画 | Y58: Web版型・木型マスタ一覧 | AH58: 製品名
A59: 9 | C59: フ | D59: 版・型管理ラベル出力用CSVファイル | O59: 通し数 | X59: 画 | Y59: Web版型・木型マスタ一覧 | AH59: 通し数
A60: 10 | C60: フ | D60: 版・型管理ラベル出力用CSVファイル | O60: 限界通し数 | X60: 画 | Y60: Web版型・木型マスタ一覧 | AH60: 限界通し数
A61: 11 | C61: フ | D61: 版・型管理ラベル出力用CSVファイル | O61: 発注先 | X61: 画 | Y61: Web版型・木型マスタ一覧 | AH61: 発注先
A62: 12 | C62: フ | D62: 版・型管理ラベル出力用CSVファイル | O62: 発注先名 | X62: 画 | Y62: Web版型・木型マスタ一覧 | AH62: 発注先名
... A86: 36 | C86: フ | D86: 版・型管理ラベル出力用CSVファイル | O86: 備考 | X86: 画 | Y86: Web版型・木型マスタ一覧 | AH86: 備考
A87: 37 | C87: フ | D87: 版・型管理ラベル出力用CSVファイル | O87: 手配NO | X87: T | Y87: 版型・木型管理マスタ | AH87: 手配NO | AS87: 手配NO追加

Sheet 画面遷移
A1: =表紙!A54 -> Webシステム | K1: 文書名 | U1: モジュールID | Z1: =表紙!$AJ$63 -> MS | AE1: モジュール名 | AJ1: =表紙!$AX$63 -> Webシステム | AS1: 文書番号 | AZ1: Version | BF1: Rev.
K2: =表紙!O64 -> アドオン設計書 | U2: ｻﾌﾞﾓｼﾞｭｰﾙID | Z2: =表紙!$AJ$64 -> MSBB | AE2: ｻﾌﾞﾓｼﾞｭｰﾙ名 | AJ2: =表紙!$AX$64 -> 販売Webシステム | AS2: =表紙!$BL$64 -> M7-US-1140 | AZ2: =表紙!$BU$64 -> 1.0.0 | BF2: =表紙!$CB$64 -> 1
K3: =RIGHT(CELL("filename",$A$1),LEN(CELL("filename",$A$1))-FIND("]",CELL("filename",$A$1))) -> #VALUE! | U3: 表題 | Z3: =表紙!$AJ$65 -> MSBBPA150 | AE3: =表紙!$AQ$65 -> Web版型・木型マスタ一覧照会
A5: 画面遷移フロー図
A6: ＩＤ | C6: S01 | E6: Web版型・木型マスタ一覧照会から他画面の画面遷移
D9: NO1
D10: Web取引先一覧照会
R12: Web版型・木型マスタ一覧照会
D15: NO2
D16: Web製品マスタ一覧照会
AI18: ※Web版型・木型マスタ側で記述
AI19: Web版型・木型マスタ(検索)
D20: NO3
D21: Web汎用検索(共通検索)
A27: ID | D27: 処理名
A28: S01 | D28: Web版型・木型マスタ一覧照会から他画面の画面遷移
B30: NO | D30: 遷移元ＩＤ | H30: 遷移元画面名 | Q30: 遷移先ＩＤ | V30: 遷移先画面名 | AE30: 目的 | AJ30: 引継項目 | AS30: 遷移後のアクション(遷移先) | BC30: 戻り値 | BL30: 戻り値取得後のアクション(遷移元) | BV30: 備考
B31: 1 | D31: MSBBPA150 | H31: Web版型・木型マスタ一覧照会 | Q31: MSBBPA120 | V31: Web取引先一覧照会 | AE31: 検索結果取得 | AJ31: 得意先ＦＬＧ=1 | AS31: 検索 | BC31: 取引先選択データ(1行) | BL31: 対象データに値セット | BV31: 得意先CD、得意先名に値セット
B32: 2 | D32: MSBBPA150 | H32: Web版型・木型マスタ一覧照会 | Q32: MSBBPA060 | V32: Web製品マスタ一覧照会 | AE32: 検索結果取得 | AS32: 検索 | BC32: 製品マスタ選択データ(1行) | BL32: 対象データに値セット | BV32: 製品CD、製品名(CP品名1+2)に値セット
B33: 3 | D33: MSBBPA150 | H33: Web版型・木型マスタ一覧照会 | Q33: MSBBPA900 | V33: Web汎用検索(共通検索) | AE33: 検索結果取得 | AS33: 検索 | BC33: 各種検索画面の選択データ(1行) | BL33: 対象データに値セット | BV33: CD、名称に値セット
B34: 4
B35: 5
B36: 6
B37: 7
B38: 8

Sheet メッセージ一覧
A1: =表紙!A54 -> Webシステム | K1: 文書名 | U1: モジュールID | Z1: =表紙!$AJ$63 -> MS | AE1: モジュール名 | AJ1: =表紙!$AX$63 -> Webシステム | AS1: 文書番号 | AZ1: Version | BF1: Rev.
K2: =表紙!O64 -> アドオン設計書 | U2: ｻﾌﾞﾓｼﾞｭｰﾙID | Z2: =表紙!$AJ$64 -> MSBB | AE2: ｻﾌﾞﾓｼﾞｭｰﾙ名 | AJ2: =表紙!$AX$64 -> 販売Webシステム | AS2: =表紙!$BL$64 -> M7-US-1140 | AZ2: =表紙!$BU$64 -> 1.0.0 | BF2: =表紙!$CB$64 -> 1
K3: =RIGHT(CELL("filename",$A$1),LEN(CELL("filename",$A$1))-FIND("]",CELL("filename",$A$1))) -> #VALUE! | U3: 表題 | Z3: =表紙!$AJ$65 -> MSBBPA150 | AE3: =表紙!$AQ$65 -> Web版型・木型マスタ一覧照会
C4: ↓アドオン画面のため、基本全て[新]
A5: NO | C5: 新/変 | E5: 種別 | G5: メッセージ内容 | AQ5: 備考（パラメータ等） | BG5: メッセージID
A6: 1 | C6: 新 | E6: W | G6: 「FROM≦TOの関係で指定してください。」 | AQ6: 適用開始日、版型NO、通し数、限界通し数 | BG6: メッセージID.001
AQ7: 入荷日、廃棄予定日、返却予定日、返却日
A9: 2 | C9: 新 | E9: W | G9: 「検索結果がありません。」 | BG9: メッセージID.002
A10: 3 | C10: 新 | E10: W | G10: 「発行対象がありません。」 | BG10: メッセージID.003
A11: 4 | C11: 新 | E11: W | G11: 「選択行がありません。」 | BG11: メッセージID.004

Sheet 補足説明資料
A1: =表紙!A54 -> Webシステム | O1: 文書名 | AC1: モジュールID | AJ1: =表紙!$AJ$63 -> MS | AQ1: モジュール名 | AX1: =表紙!$AX$63 -> Webシステム | BL1: 文書番号 | BU1: Version | CB1: Rev.
O2: =表紙!O64 -> アドオン設計書 | AC2: サブモジュールID | AJ2: =表紙!$AJ$64 -> MSBB | AQ2: サブモジュール名 | AX2: =表紙!$AX$64 -> 販売Webシステム | BL2: =表紙!$BL$64 -> M7-US-1140 | BU2: =表紙!$BU$64 -> 1.0.0 | CB2: =表紙!$CB$64 -> 1
O3: =RIGHT(CELL("filename",$A$1),LEN(CELL("filename",$A$1))-FIND("]",CELL("filename",$A$1))) -> #VALUE! | AC3: 表題 | AJ3: =表紙!$AJ$65 -> MSBBPA150 | AQ3: =表紙!$AQ$65 -> Web版型・木型マスタ一覧照会
AO5: 補足説明
