Workbook
Name Rev.: 表紙!$U$22
Name Revision: [2]表紙!$AP$5
Name Ver.: 表紙!$AE$26
Name Version: [2]表紙!$AJ$5
Name ご確認者: 表紙!$AG$40
Name ご確認日: 表紙!$AG$42
Name サブシステム名: 表紙!$U$28
Name システム名: 表紙!$U$26
Name プロジェクト名: 表紙!$U$18
Name 開発区分: 表紙!$U$36
Name 機能ＩＤ: 表紙!$U$32
Name 機能区分: 表紙!$U$34
Name 機能名称: 表紙!$U$30
Name 顧客名: 表紙!$U$16
Name 最終更新者: 表紙!$AB$40
Name 最終更新日: 表紙!$AB$42
Name 作成者: 表紙!$W$40
Name 作成日: 表紙!$W$42
Name 章: 表紙!$M$10
Name 文書番号: [2]表紙!$O$5
Name 文書名: 表紙!$M$10
Name 文書名: [2]表紙!$M$15

Sheet 目次
A1: アドオン設計書作成ガイド
C3: ■アドオン設計と成果物について
D4: ・システム設計フェーズとソフトウェア設計フェーズでアドオンの処理仕様を定義する
D5: ・システム設計フェーズとソフトウェア設計フェーズの成果物がアドオン設計書であり、ソフトウェア製作フェーズのインプットとなる
C7: ■各設計フェーズ毎のアドオン設計書作成範囲
D8: ・システム設計フェーズ：他機能との関連を定義するとともに、画面や帳票、ファイル入出力を中心とした外部入出力の設計を行う
D9: ・ソフトウェア設計フェーズ：内部処理を中心とした設計を行う
U11: ◎ | W11: … | X11: システム設計フェーズで作成
U12: ○ | W12: … | X12: システム設計フェーズで基本仕様を定義して、ソフトウェア設計フェーズで詳細化する
U13: △ | W13: … | X13: 必要に応じて（例えば標準仕様から変更がない場合は不要）
U14: ‐ | W14: … | X14: 不要
W15: … | X15: ソフトウェア設計フェーズで作成
D17: 各設計書と作成対象シートのマトリックス | S17: ※カスタマイズ：標準機能に機能を追加する アドオン：新規で機能を開発する
D18: EXCELシート | N18: 画面設計書 | W18: バッチ設計書 | AF18: 帳票設計書 | AO18: ＢＩ設計書 | AT18: .Net設計書 | BB18: EXCELシート | BL18: WebDB設計書 | BR18: 帳票設計書 | BX18: 汎用申請設計書
N19: カスタマイズ | S19: アドオン | W19: カスタマイズ | AB19: アドオン | AF19: カスタマイズ | AK19: アドオン | AO19: アドオン | AT19: アドオン | BL19: アドオン | BR19: アドオン | BX19: アドオン
D20: 概要 | N20: ◎ | O20: ※1 | S20: ◎ | W20: ◎ | X20: ※1 | AB20: ◎ | AF20: ◎ | AG20: ※1 | AK20: ◎ | AO20: ◎ | AT20: ◎ | BB20: 機能概要 | BL20: ◎ | BR20: ◎ | BX20: ◎
D21: レイアウト | N21: ◎ | O21: ※2 | S21: ◎ | W21: ‐ | AB21: ‐ | AF21: ◎ | AG21: ※2 | AK21: ◎ | AO21: ◎ | AT21: ◎ | BB21: アプリケーションフロー | BL21: ◎ | BR21: ー | BX21: ◎
D22: 項目説明 | N22: △ | S22: ○ | W22: ‐ | AB22: ‐ | AF22: △ | AK22: ○ | AO22: ○ | AT22: ○ | BB22: データベース設定 | BL22: ◎ | BR22: ー | BX22: ◎
D23: 引数説明 | N23: ‐ | S23: ‐ | W23: △ | AB23: ◎ | AF23: ‐ | AK23: ‐ | AO23: ‐ | AT23: ◎ | BB23: フィールド設定 | BL23: ◎ | BR23: ー | BX23: ◎
D24: 処理概要 | N24: ◎ | S24: ◎ | W24: ◎ | AB24: ◎ | AF24: ◎ | AK24: ◎ | AO24: ◎ | AT24: ◎ | BB24: 一覧表示画面設定 | BL24: ◎ | BR24: ー | BX24: ◎
D25: 処理詳細 | BB25: 表示編集画面設定 | BL25: ◎ | BR25: ー | BX25: ◎
D26: 処理・サービス関連図 | N26: △ | S26: ◎ | W26: △ | AB26: ◎ | AF26: ‐ | AK26: ‐ | AO26: ‐ | AT26: ◎ | BB26: 明細画面設定 | BL26: △ | BN26: ※3 | BR26: ー | BX26: △ | BZ26: ※3
D27: 検索入出力仕様 | N27: △ | S27: ○ | W27: △ | AB27: ○ | AF27: ‐ | AK27: ‐ | AO27: ‐ | AT27: ○ | BB27: 集計表示設定 | BL27: △ | BN27: ※4 | BR27: ー | BX27: △ | BZ27: ※4
D28: 更新入出力仕様 | N28: △ | S28: ○ | W28: △ | AB28: ○ | AF28: ‐ | AK28: ‐ | AO28: ‐ | AT28: ○ | BB28: 絞り込み条件設定 | BL28: △ | BN28: ※5 | BR28: ー | BX28: △ | BZ28: ※5
D29: ファイル入出力仕様 | N29: △ | S29: △ | W29: ‐ | AB29: ‐ | AF29: ‐ | AK29: ‐ | AO29: ‐ | AT29: △ | BB29: その他設定 | BR29: ー
D30: 画面遷移 | N30: △ | S30: ◎ | W30: ‐ | AB30: ‐ | AF30: ‐ | AK30: ‐ | AO30: ‐ | AT30: ◎ | BB30: 帳票イメージ | BL30: ー | BR30: ◎ | BX30: ー
D31: メッセージ一覧 | N31: △ | S31: △ | W31: △ | AB31: △ | AF31: ‐ | AK31: ‐ | AO31: ‐ | AT31: △ | BB31: 項目設計 | BL31: ー | BR31: ◎ | BX31: ー
D32: 補足説明 | N32: △ | S32: △ | W32: △ | AB32: △ | AF32: △ | AK32: △ | AO32: △ | AT32: △ | BB32: 補足説明 | BL32: △ | BR32: △ | BX32: △
D33: サービス呼出編集仕様 | N33: - | S33: - | W33: - | AB33: - | AF33: - | AK33: - | AO33: - | AT33: - | BB33: 補足説明(詳細)
D35: ※1 | G35: 別シートでカスタマイズ内容を記載する | BB35: ※3 | BE35: 単票画面は記載しない
D36: ※2 | G36: 吹き出しでカスタマイズ内容を記載する | BB36: ※4 | BE36: 集計・グラフ機能を使用する場合に記載する
BB37: ※5 | BE37: 共通設定のみ記載する(個別設定は、記載しない)

Sheet 表紙
AW2: サブモジュール
AW3: MA_マスタ管理
AW4: MB_業務共通
AW5: MG_原価管理
AW6: MSBA_需給管理
M7: 基本設計 | AW7: MSBB_販売管理
AW8: MSBC_生産管理
AW9: MSBD_購買管理
M10: アドオン設計書 | AW10: MSBE_在庫物流管理
AW11: MSBF_品質管理
AW12: MSBG_債権管理
AW13: MSBH_債務管理
AW14: MSBI_締処理
AW15: MSUA_リスト・入力補助
M16: 顧客 | U16: 株式会社クラウン・パッケージ | AW16: PF_ESBアダプタ
M18: プロジェクト名 | U18: 基幹システム刷新PJ | AW18: 機能区分
AW19: 画面
M20: 文書番号 | AW20: 帳票
AW21: バッチ
M22: Ｒｅｖ． | U22: {=MAX(_xlfn.NUMBERVALUE(改訂!A7:E44))} -> 1 | AW22: マスタ
M24: 機密性区分 | U24: 取扱注意（Ｃ） | AW24: 開発区分
AW25: カスタマイズ
M26: システム名 | U26: Webシステム | AC26: Ver. | AE26: 7.0.2 | AW26: アドオン
AW27: －
M28: サブモジュール | U28: MSBB_販売管理
M30: 機能名 | U30: =M50 -> Web見積計算書入力
M32: 機能ID | U32: =G50 -> MSBBPA010
M34: 機能区分 | U34: 画面
M36: 開発区分 | U36: アドオン
W39: 作成 | AB39: 最終更新 | AG39: ご確認
W40: MDSOL
W42: 44824
A48: 文書番号 | G48: 画面ID | M48: 画面名 | V48: Version | AB48: Revision
A50: M7-US-1140 | G50: MSBBPA010 | M50: Web見積計算書入力 | V50: 1.0.0 | AB50: r01.00
A53: 共通（元データ）
A54: Webシステム | K54: 文書名 | U54: モジュールID | Z54: MS | AE54: モジュール名 | AJ54: 見積管理 | AS54: 文書番号 | AZ54: Version | BF54: Rev.
K55: 画面説明書 | U55: ｻﾌﾞﾓｼﾞｭｰﾙID | Z55: MSBB | AE55: ｻﾌﾞﾓｼﾞｭｰﾙ名 | AJ55: Webシステム | AS55: M7-US-1140 | AZ55: 1.0.0 | BF55: r00.00
K56: 表紙 | U56: 表題 | Z56: MSBBPA010 | AE56: Web見積計算書入力
A57: 共通（リンク用）
A58: =A54 -> Webシステム | K58: 文書名 | U58: モジュールID | Z58: =Z54 -> MS | AE58: モジュール名 | AJ58: =AJ54 -> 見積管理 | AS58: 文書番号 | AZ58: Version | BF58: Rev.
...

Sheet 改訂
A1: 第7章 | K1: 改訂 | AU1: 作成者 | AZ1: MDSOL | BE1: 作成日 | BJ1: =表紙!W42 -> 44824 | BP1: Rev.
AU2: 修正者 | BE2: 改訂日 | BP2: =表紙!CB64 -> 1
A5: Rev. | F5: 改定内容 | BC5: 頁 | BM5: 変更日 変更者 | BR5: 確認日 確認者
A7: 1 | F7: 新規作成

Sheet 概要
A1: =表紙!A54 -> Webシステム | O1: 文書名 | AC1: モジュールID | AJ1: =表紙!AJ63 -> MS | AQ1: モジュール名 | AX1: =表紙!AX63 -> 見積管理 | BL1: 文書番号 | BU1: Version | CB1: Rev.
O2: =表紙!O64 -> アドオン設計書 | AC2: サブモジュールID | AJ2: =表紙!AJ64 -> MSBB | AQ2: サブモジュール名 | AX2: =表紙!AX64 -> Webシステム | BL2: =表紙!BL64 -> M7-US-1140 | BU2: =表紙!BU64 -> 7.0.2 | CB2: =表紙!CB64 -> 1
O3: =RIGHT(CELL("filename",$A$1),LEN(CELL("filename",$A$1))-FIND("]",CELL("filename",$A$1))) -> #VALUE! | AC3: 表題 | AJ3: =表紙!AJ65 -> MSBBPA010 | AQ3: =表紙!AQ65 -> Web見積計算書入力
AO5: 概要
B7: 【業務要件】
C8: カスタマイズ | G8: 内容
C9: No. | G9: アドオン件名 | Y9: アドオン機能
C10: 3 | G10: 見積管理：見積入力画面 | Y10: ■定型の見積もりフォームに数量と単価などを入力し、見積もりを行う | AT10: システム設計フェーズ変更点
Y11: ■見積結果は蓄積され、再活用できること | AU11: 見積計算書(価格印字無※見積計算書とレイアウトは同じ)の出力帳票を追加
Y12: ・定型見積フォーム入力
Y13: ・見積計算書の発行
Y14: ■見積マスターを用いて、見積額を算出する
Y15: ■製品仕様ごとの原価・粗利を見れるようにする
Y16: ■標準LTが分かるようにする（将来課題）
C17: 4 | G17: 見積Webシステム | Y17: 見積Webシステム：主要機能
C18: 146 | H18: 見積業務は、機能要求レベルが高く、 | Y18: ①見積(見積計算書)入力・発行②御見積書入力・発行③見積確定④受注入力⑤受注一覧(単価訂正)⑥製品マスタ⑦得意先マスタ⑧シート単価マスタ
H19: UIに機能制限があるPOWER EGGでの実現が難しく、 | Y19: ※詳細機能は、「機能要件一覧」に記載
H20: 見積Webシステム(スクラッチ開発)を新規に構築する。 | Z20: システム設計フェーズ変更点
AA21: ④受注入力(TOP画面、基本情報、工程情報)
AB22: 当初想定は、1画面で明細形式での画面構成を想定していたが、製品マスタと同等のテーブル構造を持ち、
AB23: 受注入力でも工程仕様画面を表示(仕様の変更可はシート受注のみ)するように変更
B25: 【機能概要】
C26: ・顧客要求より、製品の仕様を登録し、見積計算処理を行う。
B28: 【前提条件】
C29: ・WEB見積計算書入力、見積計算は、WEBシステムの機能とする。(WEBシステムに機能構築する。)
B31: 【説明】
C32: ・見積計算書の登録(新規登録・訂正登録・削除)及び参照を行う画面、見積計算書を発行する
B34: 【目的】
C35: ・見積計算書を登録・訂正する。
C36: ・見積計算書を発行する。
C37: ・見積計算書の決定入力する。（見積提出後、決定した場合、補足情報を追加入力する。）
B39: 【処理関連図/サービス関連図】
C40: ※処理・サービス関連図シートに詳細記載
B42: 【オペレーション一覧】
C43: ID | L43: 処理名 | Y43: 処理概要
C44: Srch01 | L44: 検索 | Y44: 見積計算書の検索処理を行う。
C45: Upd01 | L45: 登録 | Y45: 見積計算書の登録処理を行う。
C46: Del01 | L46: 削除 | Y46: 見積計算書の削除処理を行う。
B48: 【SQLID一覧】
C49: なし
...

Sheet レイアウト
A1: =表紙!A54 -> Webシステム | K1: 文書名 | U1: モジュールID | Z1: =表紙!$AJ$63 -> MS | AE1: モジュール名 | AJ1: =表紙!$AX$63 -> 見積管理 | AS1: 文書番号 | AZ1: Version | BF1: Rev.
K2: =表紙!O64 -> アドオン設計書 | U2: ｻﾌﾞﾓｼﾞｭｰﾙID | Z2: =表紙!$AJ$64 -> MSBB | AE2: ｻﾌﾞﾓｼﾞｭｰﾙ名 | AJ2: =表紙!$AX$64 -> Webシステム | AS2: =表紙!$BL$64 -> M7-US-1140 | AZ2: =表紙!$BU$64 -> 7.0.2 | BF2: =表紙!$CB$64 -> 1
K3: =RIGHT(CELL("filename",$A$1),LEN(CELL("filename",$A$1))-FIND("]",CELL("filename",$A$1))) -> #VALUE! | U3: 表題 | Z3: =表紙!$AJ$65 -> MSBBPA010 | AE3: =表紙!$AQ$65 -> Web見積計算書入力
A5: 画面イメージ
B7: ≫凡例
Q8: ・・・ | S8: ボタン | AH8: 参照情報
C9: 見積計算書NO | Q9: ・・・ | S9: 検索項目(検索画面表示選択)
C10: 品名 | Q10: ・・・ | S10: 入力項目 | AH10: 担当者
C11: 得意先 | Q11: ・・・ | S11: 表示項目(得意先名称、原紙名等)
C12: 操作種別 | I12: ●登録 | M12: ○訂正 | Q12: ・・・ | S12: 選択項目(一つのみ選択可能)
C13: 受注区分 | Q13: ・・・ | S13: 選択項目(一つのみ選択可能)
C14: 作業順 | I14: ☑AAA | M14: ☑BBB | Q14: ・・・ | S14: 選択項目(複数選択可能)
AF15: CP指摘 2022/10/18 本多 見積計算書№からと同様にして、製品マスタからの参照入力も可能でしょうか？ | BM15: MDSOL 野村 2022/10/28 現想定では、過去見積やテンプレート見積からの参照を想定しています。追加必要でしょうか。
C18: 1ページ目：基本情報画面 | BO18: ポップアップ | BS18: ※モーダレス表示
D20: 操作種別 | J20: ●登録 | N20: ○訂正 | R20: ○削除 | V20: ○参照 | Z20: ○コピー
N22: 見積計算書NO
BQ24: 注意メッセージ
D25: 見積計算書NO | J25: 自動採番
D26: 見積拠点 | W26: 受注拠点 | AP26: 担当者 | BS26: 82 | BU26: ・フレキソ印刷有り + 表ライナーの濃い色は裏移り注意
BU27: <<改善方法>> 裏ライナーにフレ輪、ニス引き
D29: 基本情報 | BS29: 83 | BU29: ・両面で、中芯エフカラー黒の使用は、貼合不可の拠点も有ります。要確認
D30: 得意先 | AC30: 案件No | AI30: (件名:オートフィルタ) | AP30: (案件No親/子、サンプル依頼ID) | BS30: 84 | BU30: ・表面加工、PP、マットPPは、グルアが可能か要確認
D31: 受注区分 | J31: 製品 | P31: 製品区分(大) | BS31: 85 | BU31: ・グルアのある表面加工PPは、S648を指示する(東京製造)
BS32: 86 | BU32: ・グルアのある表面加工マットPPは、YMS1を指示する。
D33: 顧客品名 | J33: 48byte7890XXXXXXXXX2XXXXXXXXX3XXXXXXXXX4XXXXXXX8 | AI33: 20byte7890XXXXXXXXX2 | BS33: 87 | BU33: ・Gプリ両面印刷P5仕様は、どちらかをOPニス、どちらかを水性ニスにする。
D34: 受注総数 | O34: 受注年月 | T34: YYYY/MM | AB34: 親子区分 | AO34: FSC認証区分 | BA34: FSC材質区分 | BS34: 88 | BU34: ・ベース原紙ヤシに印刷工程が有ります。製造備考に(改良品)の文言を挿入します。
BS35: 89 | BU35: ・UVクリア版は印刷 +1.5ﾐﾘのﾇﾘﾀｼが必要。⇒樹脂版作成時に版発注者へ連絡してください。
D36: 構成情報 | BS36: 90 | BU36: ・顔料系の箔を使用するとプレスマークが目立つ可能性あり。⇒仕上がりを事前確認してください。
D37: シート 段 | J37: E | O37: 原紙 | X37: 印刷 | AI37: エンボス | AT37: メーカ | BE37: G7で印刷 | BS37: 91 | BU37: ・Gプリ印刷は、クラフト３層でK判以上は印刷不可、シート構成の変更を検討。
F38: 表 | BE38: 柄数 | BS38: 92 | BU38: ・裏にグラビア・フレマル・オフセット・フレキソ等、印刷有の"抜きまでの製品で"梱包のみ"は、荷崩れの可能
F39: 中 | BU39: 性大、包装工程追加を検討
F40: 裏 | BE40: 柄数
D41: 枚葉印刷 | J41: オフセット
D42: 刃渡り（mm) | J42: 巾 | P42: 流れ | V42: 咥え | Z42: 前後 | AF42: 左右 | BQ42: 改善形状メッセージ
D43: シート寸法 | J43: 巾 | P43: 流れ | U43: ※(抜き無し見積もり：刃渡り寸法が無いので、シート寸法を入力する。) | BS43: ※基本情報の形状で、003 041 120 160 をしていした場合
D44: 最終機械工程 | J44: グルア
D46: 製品形状 | X46: 物流区分 | AI46: 容リ支払 | AU46: 識別表示 | BQ46: 難作業メッセージ
BS47: 81 | BU47: ・難作業!! 包装は、"胴巻" 又は"カートン入れ"を推奨 | CO47: 完全包装をしていした場合
D48: AD（形状） | BS48: 82 | BU48: ・難作業!! カートンのテープ貼りは、"I貼り" を推奨 | CO48: H貼りを指定した場合
D49: 戦略商品区分 | J49: □ | K49: FSC | N49: □ | O49: TKP | R49: □ | S49: スマパピ | V49: □ | W49: バリット | Z49: □ | AA49: マイクロ | AD49: □ | AE49: カラフルウィッシュ
...

Sheet 旧レイアウトイメージ
A1: =表紙!A54 -> Webシステム | K1: 文書名 | U1: モジュールID | Z1: =表紙!$AJ$63 -> MS | AE1: モジュール名 | AJ1: =表紙!$AX$63 -> 見積管理 | AS1: 文書番号 | AZ1: Version | BF1: Rev.
K2: =表紙!O64 -> アドオン設計書 | U2: ｻﾌﾞﾓｼﾞｭｰﾙID | Z2: =表紙!$AJ$64 -> MSBB | AE2: ｻﾌﾞﾓｼﾞｭｰﾙ名 | AJ2: =表紙!$AX$64 -> Webシステム | AS2: =表紙!$BL$64 -> M7-US-1140 | AZ2: =表紙!$BU$64 -> 7.0.2 | BF2: =表紙!$CB$64 -> 1
K3: =RIGHT(CELL("filename",$A$1),LEN(CELL("filename",$A$1))-FIND("]",CELL("filename",$A$1))) -> #VALUE! | U3: 表題 | Z3: =表紙!$AJ$65 -> MSBBPA010 | AE3: =表紙!$AQ$65 -> Web見積計算書入力
A5: 画面イメージ
B7: ≫凡例 | AG7: 全体画面構成
Q8: ・・・ | S8: ボタン | AG8: ボタン | AP8: … | AQ8: ボタン処理
C9: 見積計算書№ | Q9: ・・・ | S9: 検索項目(検索画面表示選択) | AG9: 見積ヘッダー情報
C10: 品名 | Q10: ・・・ | S10: 入力項目
C11: 得意先 | Q11: ・・・ | S11: 表示項目(得意先名称、原紙名等)
C12: 操作種別 | I12: ●登録 | M12: ○訂正 | Q12: ・・・ | S12: 選択項目(一つのみ選択可能) | AG12: 決定見積情報 | AP12: … | AQ12: 見積区分「決定」時、表示
C13: 受注区分 | Q13: ・・・ | S13: 選択項目(一つのみ選択可能) | AG13: 工程選択ボタン
C14: 作業順 | I14: ☑AAA | M14: ☑BBB | Q14: ・・・ | S14: 選択項目(複数選択可能) | AG14: 工程仕様
C32: １ページ目
D37: 操作種別 | J37: ●登録 | N37: ○訂正 | R37: ○削除 | V37: ○参照
D39: 見積区分 | J39: ●通常 | N39: ○決定
D40: 見積計算書№ | AB40: 参照見積計算書№
D41: 案件№
D42: 得意先
D44: トムソン工程 | J44: ○抜有 | N44: ○抜無
D46: 品名 | J46: 100文字 | AD46: FSC認証製品 | AQ46: 受注年月 | AU46: YYMM
D47: 受注区分 | R47: 製品区分 | AD47: アイテム | AI47: 1:親、2:子
D48: 製品形状 | R48: 物流区分 | AD48: 容リ支払 | AQ48: 識別表示
D50: シート 段 | V50: メーカー | AD50: G7で印刷 | AQ50: 受注総数
D51: 構成 | F51: 表 | AD51: 柄数
F52: 中
F53: 裏 | AD53: 柄数
D54: シート寸法 | N54: × | S54: ※(抜き無し見積もり：刃渡り寸法が無いので、シート寸法を入力する。)
D56: 印刷備考 | AD56: 製造備考
D57: 横持備考 | AD57: 納入備考
D58: 配車備考 | AD58: 伝票備考
AX60: 単位
D61: 見積り数
D62: (決定予想) | J62: ○ | O62: ○ | T62: ○ | Y62: ○ | AD62: ○ | AI62: ○ | AN62: ○ | AS62: ○
D64: 工程パターン | P64: (選択補助機能)
D65: 最低工賃
N71: □ | O71: ----- | T71: □ | U71: ----- | Z71: □ | AA71: ----- | AF71: □ | AG71: -----
N72: □ | O72: ----- | T72: □ | U72: ----- | Z72: □ | AA72: ----- | AF72: □ | AG72: -----
N73: ☑ | O73: フレキソ印刷 | T73: □ | U73: ----- | Z73: □ | AA73: ----- | AF73: □ | AG73: -----
N74: □ | O74: ----- | T74: □ | U74: ----- | Z74: □ | AA74: ----- | AF74: □ | AG74: -----
N75: □ | O75: ----- | T75: □ | U75: ----- | Z75: ☑ | AA75: トムソン | AF75: ☑ | AG75: 穴あけ
...

Sheet 項目説明
A1: =表紙!A54 -> Webシステム | K1: 文書名 | U1: モジュールID | Z1: =表紙!$AJ$63 -> MS | AE1: モジュール名 | AJ1: =表紙!$AX$63 -> 見積管理 | AS1: 文書番号 | AZ1: Version | BF1: Rev. | BM1: =表紙!BM54 -> 0 | BW1: 文書名 | CG1: モジュールID | CL1: =表紙!$AJ$63 -> MS | CQ1: モジュール名 | CV1: =表紙!$AX$63 -> 見積管理 | DE1: 文書番号 | DL1: Version | DR1: Rev.
K2: =表紙!O64 -> アドオン設計書 | U2: ｻﾌﾞﾓｼﾞｭｰﾙID | Z2: =表紙!$AJ$64 -> MSBB | AE2: ｻﾌﾞﾓｼﾞｭｰﾙ名 | AJ2: =表紙!$AX$64 -> Webシステム | AS2: =表紙!$BL$64 -> M7-US-1140 | AZ2: =表紙!$BU$64 -> 7.0.2 | BF2: =表紙!$CB$64 -> 1 | BW2: =表紙!CA64 -> 0 | CG2: ｻﾌﾞﾓｼﾞｭｰﾙID | CL2: =表紙!$AJ$64 -> MSBB | CQ2: ｻﾌﾞﾓｼﾞｭｰﾙ名 | CV2: =表紙!$AX$64 -> Webシステム | DE2: =表紙!$BL$64 -> M7-US-1140 | DL2: =表紙!$BU$64 -> 7.0.2 | DR2: =表紙!$CB$64 -> 1
K3: =RIGHT(CELL("filename",$A$1),LEN(CELL("filename",$A$1))-FIND("]",CELL("filename",$A$1))) -> #VALUE! | U3: 表題 | Z3: =表紙!$AJ$65 -> MSBBPA010 | AE3: =表紙!$AQ$65 -> Web見積計算書入力 | BW3: =RIGHT(CELL("filename",$A$1),LEN(CELL("filename",$A$1))-FIND("]",CELL("filename",$A$1))) -> #VALUE! | CG3: 表題 | CL3: =表紙!$AJ$65 -> MSBBPA010 | CQ3: =表紙!$AQ$65 -> Web見積計算書入力
A5: 第1画面(基本情報画面) | BM5: 第1画面(基本情報画面)
B6: 操作種別 | N6: 説明 | BE6: Ｗ | BF6: 型 | BG6: 参 | BH6: 必 | BI6: 入 | BJ6: 非 | BK6: 検 | BN6: 操作種別 | BY6: 最大入力文字数 | CK6: DB文字数 | CS6: mcframe項目名 | DB6: mcframeDB文字数
A7: ● | B7: 登録 | M7: 【MSBBPA000】_共通設計書_アドオン(Webシステム共通仕様)にて定義 | BE7: R | BN7: 登録
A8: ● | B8: 訂正 | M8: 【MSBBPA000】_共通設計書_アドオン(Webシステム共通仕様)にて定義 | BE8: R | BN8: 訂正
A9: ● | B9: 削除 | M9: 【MSBBPA000】_共通設計書_アドオン(Webシステム共通仕様)にて定義 | BE9: R | BN9: 削除
A10: ● | B10: 参照 | M10: 【MSBBPA000】_共通設計書_アドオン(Webシステム共通仕様)にて定義 | BE10: R | BN10: 参照
A11: ● | B11: コピー | M11: 【MSBBPA000】_共通設計書_アドオン(Webシステム共通仕様)にて定義 | BE11: R | BN11: コピー
B12: 検索 | N12: 説明 | BE12: Ｗ | BF12: 型 | BG12: 参 | BH12: 必 | BI12: 入 | BJ12: 非 | BK12: 検 | BN12: 検索
A13: ○ | B13: 見積計算書NO | M13: 【MSBBPACOM】_共通設計書_アドオン(共通ロジック)にて定義 | BE13: A | BF13: S | BK13: 検 | BN13: 見積計算書NO | BY13: 10文字 | CK13: 10文字 | DY13: CP指摘 2022/10/18 本多 製品コードから参照入力を可能とするのであれば、製品コードのフィールドが必要と思われます。
B14: 基本情報 | N14: 説明 | BE14: Ｗ | BF14: 型 | BG14: 参 | BH14: 必 | BI14: 入 | BJ14: 非 | BK14: 検 | BN14: 基本情報 | DZ14: MDSOL 野村 2022/10/28 現想定では、過去見積やテンプレート見積からの参照を想定しています。追加必要でしょうか。
B15: 見積計算書NO | M15: 自動採番項目(登録時は、空白)、訂正・削除・参照時に見積計算書NOを表示する | BE15: T | BF15: S | BH15: 必 | BN15: 見積計算書NO | BY15: 10文字 | CK15: 10文字
A16: ● | B16: 見積拠点 | M16: 【MSBBPACOM】_共通設計書_アドオン(共通ロジック)にて定義 | BE16: C | BF16: S | BH16: 必 | BN16: 見積拠点
A17: ● | B17: 受注拠点 | M17: 【MSBBPACOM】_共通設計書_アドオン(共通ロジック)にて定義 | BE17: C | BF17: S | BH17: 必 | BN17: 受注拠点
A18: ● | B18: 担当者 | M18: 【MSBBPACOM】_共通設計書_アドオン(共通ロジック)にて定義 | BE18: C | BF18: S | BH18: 必 | BN18: 担当者
A19: ● | B19: 得意先 | M19: 【MSBBPACOM】_共通設計書_アドオン(共通ロジック)にて定義 | BE19: A | BF19: S | BG19: 参 | BN19: 得意先
A20: ● | B20: 案件No | M20: 入力・表示形式は、[9999999-999] ※案件№（親）＋’－’＋案件№（子）でセットする(親7桁、子3桁) | BE20: A | BF20: S | BG20: 参 | BK20: 検 | BN20: 案件No | BY20: 11文字 | CK20: 15文字 | CS20: 手配NO3 | DB20: 15文字
M21: 【MSBBPACOM】_共通設計書_アドオン(共通ロジック)にて定義
A22: ● | B22: 受注区分 | M22: 【MSBBPACOM】_共通設計書_アドオン(共通ロジック)にて定義 | BE22: C | BF22: S | BG22: 参 | BN22: 受注区分
A23: ● | B23: 製品区分(大) | M23: 【MSBBPACOM】_共通設計書_アドオン(共通ロジック)にて定義 | BE23: C | BF23: S | BG23: 参 | BH23: 必 | BN23: 製品区分(大)
A24: ● | B24: 顧客品名1 | M24: 顧客品名1を入力する | BE24: T | BF24: S | BG24: 参 | BN24: 顧客品名 | BY24: 32文字 | CK24: 100文字 | CS24: 品目マスタ.品目別名３ | DB24: 100文字
A25: ● | B25: 顧客品名2 | M25: 顧客品名2を入力する | BE25: T | BF25: S | BG25: 参 | BY25: 12文字 | CK25: 100文字 | CS25: 品目マスタ.品目別名4 | DB25: 100文字
A26: ● | B26: 受注総数 | M26: 受注総数を入力する | BE26: T | BF26: N | BG26: 参 | BH26: 必 | BN26: 受注総数 | BY26: 10,2 | CK26: 10,2
A27: ● | B27: 受注年月 | M27: 入力・表示形式は、[YYYY/MM] | BE27: T | BF27: D | BH27: 必 | BN27: 受注年月
A28: ● | B28: 親子区分 | M28: 【MSBBPACOM】_共通設計書_アドオン(共通ロジック)にて定義 | BE28: C | BF28: S | BG28: 参 | BN28: 親子区分
A29: ● | B29: FSC認証区分 | M29: 【MSBBPACOM】_共通設計書_アドオン(共通ロジック)にて定義 | BE29: C | BF29: S | BG29: 参 | BN29: FSC認証区分
B30: FSC材質区分 | M30: 【MSBBPACOM】_共通設計書_アドオン(共通ロジック)にて定義 | BE30: C | BF30: S | BG30: 参 | BN30: FSC材質区分
B31: 構成情報 | N31: 説明 | BE31: Ｗ | BF31: 型 | BG31: 参 | BH31: 必 | BI31: 入 | BJ31: 非 | BK31: 検 | BN31: 構成情報
A32: ● | B32: シート段 | M32: 【MSBBPACOM】_共通設計書_アドオン(共通ロジック)にて定義 | BE32: C | BF32: S | BG32: 参 | BK32: 検 | BN32: シート段
A33: ● | B33: 原紙CD(表) | M33: 【MSBBPACOM】_共通設計書_アドオン(共通ロジック)にて定義 | BE33: A | BF33: S | BG33: 参 | BK33: 検 | BN33: 原紙CD(表)
A34: ● | B34: 印刷CD(表) | M34: 【MSBBPACOM】_共通設計書_アドオン(共通ロジック)にて定義 | BE34: A | BF34: S | BG34: 参 | BK34: 検 | BN34: 印刷CD(表)
A35: ● | B35: エンボスCD(表) | M35: 【MSBBPACOM】_共通設計書_アドオン(共通ロジック)にて定義 | BE35: A | BF35: S | BG35: 参 | BK35: 検 | BN35: エンボスCD(表)
A36: ● | B36: メーカCD(表) | M36: 【MSBBPACOM】_共通設計書_アドオン(共通ロジック)にて定義 | BE36: A | BF36: S | BG36: 参 | BK36: 検 | BN36: メーカCD(表)
A37: ● | B37: 柄数(表) | M37: 柄数(表)を入力する | BE37: T | BF37: S | BG37: 参 | BN37: 柄数(表) | BY37: 10,2 | CK37: 10,2
A38: ● | B38: 原紙CD(中) | M38: 【MSBBPACOM】_共通設計書_アドオン(共通ロジック)にて定義 | BE38: A | BF38: S | BG38: 参 | BK38: 検 | BN38: 原紙CD(中)
A39: ● | B39: 印刷CD(中) | M39: 【MSBBPACOM】_共通設計書_アドオン(共通ロジック)にて定義 | BE39: A | BF39: S | BG39: 参 | BK39: 検 | BN39: 印刷CD(中)
A40: ● | B40: エンボスCD(中) | M40: 【MSBBPACOM】_共通設計書_アドオン(共通ロジック)にて定義 | BE40: A | BF40: S | BG40: 参 | BK40: 検 | BN40: エンボスCD(中)
A41: ● | B41: メーカCD(中) | M41: 【MSBBPACOM】_共通設計書_アドオン(共通ロジック)にて定義 | BE41: A | BF41: S | BG41: 参 | BK41: 検 | BN41: メーカCD(中)
...

Sheet 引数説明
A1: =表紙!A54 -> Webシステム | K1: 文書名 | U1: モジュールID | Z1: =表紙!$AJ$63 -> MS | AE1: モジュール名 | AJ1: =表紙!$AX$63 -> 見積管理 | AS1: 文書番号 | AZ1: Version | BF1: Rev.
K2: =表紙!O64 -> アドオン設計書 | U2: ｻﾌﾞﾓｼﾞｭｰﾙID | Z2: =表紙!$AJ$64 -> MSBB | AE2: ｻﾌﾞﾓｼﾞｭｰﾙ名 | AJ2: =表紙!$AX$64 -> Webシステム | AS2: =表紙!$BL$64 -> M7-US-1140 | AZ2: =表紙!$BU$64 -> 7.0.2 | BF2: =表紙!$CB$64 -> 1
K3: =RIGHT(CELL("filename",$A$1),LEN(CELL("filename",$A$1))-FIND("]",CELL("filename",$A$1))) -> #VALUE! | U3: 表題 | Z3: =表紙!$AJ$65 -> MSBBPA010 | AE3: =表紙!$AQ$65 -> Web見積計算書入力
B5: オペレーションＩＤ/名称：SloRecvIfImp_Upd01/取込
A6: 必 | B6: 項目名 | N6: 説明 | AS6: 未設定時の振る舞い

Sheet 項目説明 (入力値)
A1: =表紙!A54 -> Webシステム | K1: 文書名 | U1: モジュールID | Z1: =表紙!$AJ$63 -> MS | AE1: モジュール名 | AJ1: =表紙!$AX$63 -> 見積管理 | AS1: 文書番号 | AZ1: Version | BF1: Rev.
K2: =表紙!O64 -> アドオン設計書 | U2: ｻﾌﾞﾓｼﾞｭｰﾙID | Z2: =表紙!$AJ$64 -> MSBB | AE2: ｻﾌﾞﾓｼﾞｭｰﾙ名 | AJ2: =表紙!$AX$64 -> Webシステム | AS2: =表紙!$BL$64 -> M7-US-1140 | AZ2: =表紙!$BU$64 -> 7.0.2 | BF2: =表紙!$CB$64 -> 1
K3: =RIGHT(CELL("filename",$A$1),LEN(CELL("filename",$A$1))-FIND("]",CELL("filename",$A$1))) -> #VALUE! | U3: 表題 | Z3: =表紙!$AJ$65 -> MSBBPA010 | AE3: =表紙!$AQ$65 -> Web見積計算書入力
A5: 第1画面(基本情報画面)
B6: 操作種別 | M6: 最大入力文字数 | Y6: DB文字数 | AG6: mcframe項目名 | AP6: mcframeDB文字数 | BE6: リ | BF6: 型 | BG6: 参 | BH6: コ | BI6: 入 | BJ6: 非 | BK6: Ｏ
A7: ● | B7: 登録する | BF7: R
A8: ● | B8: 訂正する | BF8: R
A9: ● | B9: 取り消す | BF9: R
A10: ● | B10: 参照する | BF10: R
A11: ● | B11: コピー | BF11: R
B12: 検索 | BE12: リ | BF12: 型 | BG12: 参 | BH12: コ | BI12: 入 | BJ12: 非 | BK12: Ｏ
A13: ○ | B13: 見積計算書No | M13: 10文字 | Y13: 10文字 | BF13: S
B14: 基本情報 | BE14: リ | BF14: 型 | BG14: 参 | BH14: コ | BI14: 入 | BJ14: 非 | BK14: Ｏ
A15: ● | B15: 見積計算書No | M15: 10文字 | Y15: 10文字 | BF15: S
A16: ● | B16: 拠点 | BF16: S
A17: ● | B17: 担当者 | BF17: S
A18: ● | B18: 得意先 | BE18: C | BF18: S | BG18: 参
A19: ● | B19: 案件No | M19: 7文字 | Y19: 15文字 | AG19: 手配NO3 | AP19: 15文字 | BE19: C | BF19: S | BG19: 参
A20: ● | B20: 顧客品名 | M20: 32文字 | Y20: 100文字 | AG20: 品目マスタ.品目別名３ | AP20: 100文字 | BF20: S | BG20: 参
M21: 12文字 | Y21: 100文字 | AG21: 品目マスタ.品目別名4 | AP21: 100文字
A22: ● | B22: 受注総数 | M22: 10,2 | Y22: 10,2 | BF22: N | BG22: 参
A23: ● | B23: 受注年月 | BF23: D
A24: ● | B24: 親子区分 | BE24: CI | BF24: S | BG24: 参
A25: ● | B25: FSC認証区分 | BE25: C | BF25: S | BG25: 参
A26: ● | B26: FSC材質区分 | BE26: C | BF26: S | BG26: 参
B27: 構成情報 | BE27: リ | BF27: 型 | BG27: 参 | BH27: コ | BI27: 入 | BJ27: 非 | BK27: Ｏ
A28: ● | B28: 受注区分 | BE28: CI | BF28: S | BG28: 参
A29: ● | B29: シート段 | BE29: CI | BF29: S | BG29: 参
A30: ● | B30: 原紙コード(表) | BE30: C | BF30: S | BG30: 参
A31: ● | B31: 印刷コード(表) | BE31: C | BF31: S | BG31: 参
A32: ● | B32: エンボスコード(表) | BE32: C | BF32: S | BG32: 参
A33: ● | B33: 柄数(表) | M33: 10,2 | Y33: 10,2 | BE33: C | BF33: S | BG33: 参
A34: ● | B34: 原紙コード(中) | BE34: C | BF34: S | BG34: 参
A35: ● | B35: 印刷コード(中) | BE35: C | BF35: S | BG35: 参
A36: ● | B36: エンボスコード(中) | BE36: C | BF36: S | BG36: 参
A37: ● | B37: 原紙コード(裏) | BE37: C | BF37: S | BG37: 参
A38: ● | B38: 印刷コード(裏) | BE38: C | BF38: S | BG38: 参
A39: ● | B39: エンボスコード(裏) | BE39: C | BF39: S | BG39: 参
A40: ● | B40: 柄数(裏) | M40: 10,2 | Y40: 10,2 | BE40: C | BF40: S | BG40: 参
A41: ● | B41: 枚葉印刷 | BE41: C | BF41: S | BG41: 参
...

Sheet 処理概要
A1: =表紙!A54 -> Webシステム | K1: 文書名 | U1: モジュールID | Z1: =表紙!$AJ$63 -> MS | AE1: モジュール名 | AJ1: =表紙!$AX$63 -> 見積管理 | AS1: 文書番号 | AZ1: Version | BF1: Rev.
K2: =表紙!O64 -> アドオン設計書 | U2: ｻﾌﾞﾓｼﾞｭｰﾙID | Z2: =表紙!$AJ$64 -> MSBB | AE2: ｻﾌﾞﾓｼﾞｭｰﾙ名 | AJ2: =表紙!$AX$64 -> Webシステム | AS2: =表紙!$BL$64 -> M7-US-1140 | AZ2: =表紙!$BU$64 -> 7.0.2 | BF2: =表紙!$CB$64 -> 1
K3: =RIGHT(CELL("filename",$A$1),LEN(CELL("filename",$A$1))-FIND("]",CELL("filename",$A$1))) -> #VALUE! | U3: 表題 | Z3: =表紙!$AJ$65 -> MSBBPA010 | AE3: =表紙!$AQ$65 -> Web見積計算書入力
A5: 第1画面(基本情報画面)
A6: No | B6: 入力 | J6: 処理 | BD6: 出力
A7: 1 | B7: 初期表示
J8: 1.処理概要
K9: 初期表示
L10: 見積拠点 | P10: ： | Q10: ログインに紐づく拠点CDを表示する | AD10: ※ | AE10: 見積拠点：管理者・岐阜事業所が変更可能(見積計算の拠点となる) | BM10: CP指摘 2022/09/28 木﨑 シート[レイアウト]では「拠点に紐づく担当者を表示」と記載があります。こちらが正でしょうか？
L11: 受注拠点 | P11: ： | Q11: ログインに紐づく拠点CDを表示する | AD11: ※ | AE11: 受注拠点：管理者のみ変更可能 | BN11: MDSOL 野村 2022/10/28 左記は初期表示の仕様となります。
L12: 担当者 | P12: ： | Q12: ログイン担当者CDを表示する | BO12: 拠点に紐づく担当者を表示は、選択値のことになります。
BO13: 受注拠点が変更になった場合に、担当者の選択値が「拠点に紐づく担当者」になることを指します。
A14: 2 | B14: 画面操作
J15: 1.処理概要
K16: 操作種別
L17: 登録 | U17: ・・・ | X17: 検索.見積計算書NO 入力不可
X18: 構成情報：枚葉印刷～最終機械工程の表示
L19: 訂正、削除、参照 | U19: ・・・ | X19: 検索.見積計算書NO 入力可
L20: コピー | X20: 構成情報：枚葉印刷～最終機械工程の非表示
K22: 見積計算書NO
L23: 訂正、削除、参照 | U23: ・・・ | X23: 更新入出力仕様を参考に各項目に値をセットする | BD23: 検索入出力仕様.検索No1
L24: コピー | X24: 検索入出力仕様(見積計算書NO)の仕様に沿い、各項目に値をセットする
K26: 案件 | U26: ・・・ | X26: 検索入出力仕様(案件)の仕様に沿い、各項目に値をセットする | BD26: 検索入出力仕様.検索No2
K28: ボタン処理
L29: クリアボタン押下 | U29: ・・・ | X29: 画面を初期化する
L30: 溶リ判定押下 | U30: ・・・ | X30: 溶リ判定画面を表示する
A32: 3 | B32: 次画面処理
J33: 1.処理概要
K34: チェック処理 | BD34: 処理概要(チェック仕様)
L35: 処理概要(チェック仕様)のチェック処理を行う | BD35: 第1画面(基本情報画面)
L36: ※チェック処理でエラーメッセージがある場合は、後続処理をキャンセルし、エラーポップアップ表示する
K37: 容リ法対象ポップアップ表示
L38: 得意先マスタ：容リ法対象=1:該当時、容リ法対象ポップアップ表示する、容リ法対象≠1時は、第2画面へ遷移する
L40: 容器包装リサイクル法判定を行い、ポップアップA、B、Cに遷移する | BM40: (設計書添付資料：【MSBBPA010_添付資料】見積計算仕様__20220719_V01.xlsx)
M41: 遷移画面 | AD41: 判定条件
M42: A.特定容器包装(紙製品) | AA42: ・・・ | AD42: 紙の重量が重い
M43: B.ダンボール容器 | AA43: ・・・ | AD43: 段ボール原紙の重量が重い
M44: C.商品(購買品) | AA44: ・・・ | AD44: 受注区分が商品
M46: 概要
M47: ①原紙は、段ボール原紙、ダンボール原紙以外(以後 : 紙)で区分されている。
...

Sheet 処理詳細
A1: =表紙!A54 -> Webシステム | K1: 文書名 | U1: モジュールID | Z1: =表紙!$AJ$63 -> MS | AE1: モジュール名 | AJ1: =表紙!$AX$63 -> 見積管理 | AS1: 文書番号 | AZ1: Version | BF1: Rev.
K2: =表紙!O64 -> アドオン設計書 | U2: ｻﾌﾞﾓｼﾞｭｰﾙID | Z2: =表紙!$AJ$64 -> MSBB | AE2: ｻﾌﾞﾓｼﾞｭｰﾙ名 | AJ2: =表紙!$AX$64 -> Webシステム | AS2: =表紙!$BL$64 -> M7-US-1140 | AZ2: =表紙!$BU$64 -> 7.0.2 | BF2: =表紙!$CB$64 -> 1
K3: =RIGHT(CELL("filename",$A$1),LEN(CELL("filename",$A$1))-FIND("]",CELL("filename",$A$1))) -> #VALUE! | U3: 表題 | Z3: =表紙!$AJ$65 -> MSBBPA010 | AE3: =表紙!$AQ$65 -> Web見積計算書入力
A5: No | B5: 入力 | J5: 処理 | BD5: 出力
A6: 1 | B6: 初期表示
A12: 2 | B12: 画面操作
A18: 3 | B18: 検索【F1】

Sheet 処理概要(チェック仕様)
A1: =表紙!A54 -> Webシステム | K1: 文書名 | U1: モジュールID | Z1: =表紙!$AJ$63 -> MS | AE1: モジュール名 | AJ1: =表紙!$AX$63 -> 見積管理 | AS1: 文書番号 | AZ1: Version | BF1: Rev.
K2: =表紙!O64 -> アドオン設計書 | U2: ｻﾌﾞﾓｼﾞｭｰﾙID | Z2: =表紙!$AJ$64 -> MSBB | AE2: ｻﾌﾞﾓｼﾞｭｰﾙ名 | AJ2: =表紙!$AX$64 -> Webシステム | AS2: =表紙!$BL$64 -> M7-US-1140 | AZ2: =表紙!$BU$64 -> 7.0.2 | BF2: =表紙!$CB$64 -> 1
K3: =RIGHT(CELL("filename",$A$1),LEN(CELL("filename",$A$1))-FIND("]",CELL("filename",$A$1))) -> #VALUE! | U3: 表題 | Z3: =表紙!$AJ$65 -> MSBBPA010 | AE3: =表紙!$AQ$65 -> Web見積計算書入力
A5: 第1画面(基本情報画面)
A6: No | B6: 入力 | J6: 1ページ目：基本情報画面 | BD6: 出力
A7: 1 | B7: ヘッダー見積計算書 | J7: 見積計算書NO選択/検索
J8: 1.処理概要
K9: チェック処理
L10: 見積計算書NO
N11: 必須チェック | U11: 「見積計算書NOが未入力です。」 | BD11: メッセージID.101
N12: ＤＢチェック | U12: 「見積計算書NOが未登録です。」 | BD12: メッセージID.102
A14: 2 | B14: 次へチェック | J14: 次へチェック処理
J15: 1.処理概要
K16: チェック処理
L17: 見積拠点CD
N18: 必須チェック | U18: 「見積拠点CDが未入力です。」 | BD18: メッセージID.111
L19: 受注拠点CD
N20: 必須チェック | U20: 「受注拠点CDが未入力です。」 | BD20: メッセージID.112
L21: 担当者CD
N22: 必須チェック | U22: 「担当者CDが未入力です。」 | BD22: メッセージID.113
L23: 得意先
N24: 必須チェック | U24: 「得意先が未入力です。」 | BD24: メッセージID.114
L25: 案件NO
N26: 必須チェック | U26: 「案件NOが未入力です。」 | BD26: メッセージID.115
L27: 顧客品名
N28: 必須チェック | U28: 「顧客品名が未入力です。」 | BD28: メッセージID.116
L29: 受注総数
N30: 必須チェック | U30: 「受注総数が未入力です。」 | BD30: メッセージID.117
L31: 受注年月
N32: 必須チェック | U32: 「受注年月が未入力です。」 | BD32: メッセージID.118
L33: 親子区分
N34: 必須チェック | U34: 「親子区分が未入力です。」 | BD34: メッセージID.119
L35: FSC認証区分
N36: FSC認証製品>=1以上、 | BN36: CP指摘 2022/10/18 本多 製品区分 入力必須チェック 「製品区分が未入力です」 表示されますか？
N37: 原紙CDから原紙マスタを参照し、FSC区分が「0:非認証」の場合、「原紙が非認証です。」 | BD37: メッセージID.120
L38: 受注区分
N39: 必須チェック | U39: 「受注区分が未入力です。」 | BD39: メッセージID.121
L40: 製品区分_大
N41: 必須チェック | U41: 「製品区分が未入力です。」 | BD41: メッセージID.129 | BN41: MDSOL 野村 2022/10/28 製品区分を必須に変更し、チェック追加しました。
L42: シート 段
...

Sheet 処理・サービス関連図
A1: =表紙!A54 -> Webシステム | K1: 文書名 | U1: モジュールID | Z1: =表紙!$AJ$63 -> MS | AE1: モジュール名 | AJ1: =表紙!$AX$63 -> 見積管理 | AS1: 文書番号 | AZ1: Version | BF1: Rev.
K2: =表紙!O64 -> アドオン設計書 | U2: ｻﾌﾞﾓｼﾞｭｰﾙID | Z2: =表紙!$AJ$64 -> MSBB | AE2: ｻﾌﾞﾓｼﾞｭｰﾙ名 | AJ2: =表紙!$AX$64 -> Webシステム | AS2: =表紙!$BL$64 -> M7-US-1140 | AZ2: =表紙!$BU$64 -> 7.0.2 | BF2: =表紙!$CB$64 -> 1
K3: =RIGHT(CELL("filename",$A$1),LEN(CELL("filename",$A$1))-FIND("]",CELL("filename",$A$1))) -> #VALUE! | U3: 表題 | Z3: =表紙!$AJ$65 -> MSBBPA010 | AE3: =表紙!$AQ$65 -> Web見積計算書入力
C7: 検索処理
C19: 更新処理

Sheet 検索入出力仕様
A1: =表紙!A54 -> Webシステム | K1: 文書名 | U1: モジュールID | Z1: =表紙!$AJ$63 -> MS | AE1: モジュール名 | AJ1: =表紙!$AX$63 -> 見積管理 | AS1: 文書番号 | AZ1: Version | BF1: Rev.
K2: =表紙!O64 -> アドオン設計書 | U2: ｻﾌﾞﾓｼﾞｭｰﾙID | Z2: =表紙!$AJ$64 -> MSBB | AE2: ｻﾌﾞﾓｼﾞｭｰﾙ名 | AJ2: =表紙!$AX$64 -> Webシステム | AS2: =表紙!$BL$64 -> M7-US-1140 | AZ2: =表紙!$BU$64 -> 7.0.2 | BF2: =表紙!$CB$64 -> 1
K3: =RIGHT(CELL("filename",$A$1),LEN(CELL("filename",$A$1))-FIND("]",CELL("filename",$A$1))) -> #VALUE! | U3: 表題 | Z3: =表紙!$AJ$65 -> MSBBPA010 | AE3: =表紙!$AQ$65 -> Web見積計算書入力
A5: No | G5: 1 | S5: ボタン | Z5: 見積計算書NO | AH5: 備考 | AK5: 見積計算書NOからのコピー登録
A6: 処理分類 | E6: 検索 | S6: ソート順
A7: No | C7: 転送先 | V7: 転送元 | AQ7: 説明
C8: 種 | D8: オブジェクト | K8: 項目名 | V8: 種 | W8: オブジェクト | AF8: 項目名
A9: 1 | C9: 画 | D9: 第1画面(基本情報画面) | K9: 得意先 | V9: T | W9: 見積計算書 | AF9: 得意先
A10: 2 | C10: 画 | D10: 第1画面(基本情報画面) | K10: 案件No | V10: T | W10: 見積計算書 | AF10: 案件No
A11: 3 | C11: 画 | D11: 第1画面(基本情報画面) | K11: 案件名 | V11: T | W11: ヒアリングシート | AF11: 案件名
A12: 4 | C12: 画 | D12: 第1画面(基本情報画面) | K12: 受注区分 | V12: T | W12: 見積計算書 | AF12: 受注区分
A13: 5 | C13: 画 | D13: 第1画面(基本情報画面) | K13: 製品区分(大) | V13: T | W13: 見積計算書 | AF13: 製品区分_大
A14: 6 | C14: 画 | D14: 第1画面(基本情報画面) | K14: 顧客品名 | V14: T | W14: 見積計算書 | AF14: 顧客品名
A15: 7 | C15: 画 | D15: 第1画面(基本情報画面) | K15: 受注総数 | V15: T | W15: 見積計算書 | AF15: 受注総数
A16: 8 | C16: 画 | D16: 第1画面(基本情報画面) | K16: 受注年月 | V16: T | W16: 見積計算書 | AF16: 受注年月
A17: 9 | C17: 画 | D17: 第1画面(基本情報画面) | K17: 親子区分 | V17: T | W17: 見積計算書 | AF17: 親子区分
A18: 10 | C18: 画 | D18: 第1画面(基本情報画面) | K18: FSC認証区分 | V18: T | W18: 見積計算書 | AF18: FSC認証区分
A19: 11 | C19: 画 | D19: 第1画面(基本情報画面) | K19: FSC材質区分 | V19: T | W19: 見積計算書 | AF19: FSC材質区分
A20: 12 | C20: 画 | D20: 第1画面(基本情報画面) | K20: シート段 | V20: T | W20: 見積計算書 | AF20: シート段
... A45: 37 | C45: 画 | D45: 第1画面(基本情報画面) | K45: AD（形状） | V45: T | W45: 見積計算書 | AF45: AD（形状）
A46: 38 | C46: 画 | D46: 第1画面(基本情報画面) | K46: 戦略商品区分_01 | V46: T | W46: 見積計算書 | AF46: 戦略商品区分_01 | AQ46: FSC
A47: 39 | C47: 画 | D47: 第1画面(基本情報画面) | K47: 戦略商品区分_02 | V47: T | W47: 見積計算書 | AF47: 戦略商品区分_02 | AQ47: TKP
A48: 40 | C48: 画 | D48: 第1画面(基本情報画面) | K48: 戦略商品区分_03 | V48: T | W48: 見積計算書 | AF48: 戦略商品区分_03 | AQ48: スマパピ
A49: 41 | C49: 画 | D49: 第1画面(基本情報画面) | K49: 戦略商品区分_04 | V49: T | W49: 見積計算書 | AF49: 戦略商品区分_04 | AQ49: バリット
A50: 42 | C50: 画 | D50: 第1画面(基本情報画面) | K50: 戦略商品区分_05 | V50: T | W50: 見積計算書 | AF50: 戦略商品区分_05 | AQ50: マイクロ
A51: 43 | C51: 画 | D51: 第1画面(基本情報画面) | K51: 戦略商品区分_06 | V51: T | W51: 見積計算書 | AF51: 戦略商品区分_06 | AQ51: カラフルウィッシュ
A52: 44 | C52: 画 | D52: 第1画面(基本情報画面) | V52: T | W52: 見積計算書 | AF52: 戦略商品区分_07 | AQ52: 空き項目:マスタ値により、不可視設定
A53: 45 | C53: 画 | D53: 第1画面(基本情報画面) | V53: T | W53: 見積計算書 | AF53: 戦略商品区分_08 | AQ53: 空き項目:マスタ値により、不可視設定
A54: 46 | C54: 画 | D54: 第1画面(基本情報画面) | V54: T | W54: 見積計算書 | AF54: 戦略商品区分_09 | AQ54: 空き項目:マスタ値により、不可視設定
A55: 47 | C55: 画 | D55: 第1画面(基本情報画面) | V55: T | W55: 見積計算書 | AF55: 戦略商品区分_10 | AQ55: 空き項目:マスタ値により、不可視設定
A56: 48 | C56: 画 | D56: 第1画面(基本情報画面) | K56: 印刷備考 | V56: T | W56: 見積計算書 | AF56: 印刷備考
A57: 49 | C57: 画 | D57: 第1画面(基本情報画面) | K57: 製造備考 | V57: T | W57: 見積計算書 | AF57: 製造備考
A58: 50 | C58: 画 | D58: 第1画面(基本情報画面) | K58: 伝票備考 | V58: T | W58: 見積計算書 | AF58: 伝票備考
A59: 51 | C59: 画 | D59: 第1画面(基本情報画面) | K59: 納入備考 | V59: T | W59: 見積計算書 | AF59: 納入備考
A60: 52 | C60: 画 | D60: 第1画面(基本情報画面) | K60: 出荷備考１ | V60: T | W60: 見積計算書 | AF60: 出荷備考１
A61: 53 | C61: 画 | D61: 第1画面(基本情報画面) | K61: 出荷備考２ | V61: T | W61: 見積計算書 | AF61: 出荷備考２
A62: 54 | C62: 画 | D62: 第1画面(基本情報画面) | K62: 見積り数01 | V62: T | W62: 見積計算書 | AF62: 見積数 | AQ62: 見積書計算書の枝番データ分、01～08にデータセットする
A63: 55 | C63: 画 | D63: 第1画面(基本情報画面) | K63: 見積り数02 | V63: T | W63: 見積計算書 | AF63: 見積数
A64: 56 | C64: 画 | D64: 第1画面(基本情報画面) | K64: 見積り数03 | V64: T | W64: 見積計算書 | AF64: 見積数
A65: 57 | C65: 画 | D65: 第1画面(基本情報画面) | K65: 見積り数04 | V65: T | W65: 見積計算書 | AF65: 見積数
...

Sheet 更新入出力仕様
A1: =表紙!A54 -> Webシステム | K1: 文書名 | U1: モジュールID | Z1: =表紙!$AJ$63 -> MS | AE1: モジュール名 | AJ1: =表紙!$AX$63 -> 見積管理 | AS1: 文書番号 | AZ1: Version | BF1: Rev.
K2: =表紙!O64 -> アドオン設計書 | U2: ｻﾌﾞﾓｼﾞｭｰﾙID | Z2: =表紙!$AJ$64 -> MSBB | AE2: ｻﾌﾞﾓｼﾞｭｰﾙ名 | AJ2: =表紙!$AX$64 -> Webシステム | AS2: =表紙!$BL$64 -> M7-US-1140 | AZ2: =表紙!$BU$64 -> 7.0.2 | BF2: =表紙!$CB$64 -> 1
K3: =RIGHT(CELL("filename",$A$1),LEN(CELL("filename",$A$1))-FIND("]",CELL("filename",$A$1))) -> #VALUE! | U3: 表題 | Z3: =表紙!$AJ$65 -> MSBBPA010 | AE3: =表紙!$AQ$65 -> Web見積計算書入力
A5: No | G5: 1 | S5: ロジック名称 | Z5: 見積計算書 | AH5: 備考
A6: 処理分類 | E6: 更新
A7: No | C7: 転送先 | V7: 転送元 | AQ7: 説明
C8: 種 | D8: オブジェクト | K8: 項目名 | V8: 種 | W8: オブジェクト | AF8: 項目名
A9: 1 | C9: T | D9: 見積計算書 | K9: 見積計算書NO | V9: 画 | W9: 第1画面(基本情報画面) | AF9: 見積計算書NO | BN9: CP指摘 2022/10/18 本多 製品コードから参照入力を可能とするのであれば、製品コードのフィールドが必要と思われます。
A10: 2 | C10: T | D10: 見積計算書 | K10: 参照元_見積計算書NO | V10: 画 | W10: 第1画面(基本情報画面) | AF10: 参照元_見積計算書NO | BO10: MDSOL 野村 2022/10/28 現想定では、過去見積やテンプレート見積からの参照を想定しています。追加必要でしょうか。
A11: 3 | C11: T | D11: 見積計算書 | K11: 見積日 | AQ11: 登録日
A12: 4 | C12: T | D12: 見積計算書 | K12: 見積拠点CD | V12: 画 | W12: 第1画面(基本情報画面) | AF12: 見積拠点CD
A13: 5 | C13: T | D13: 見積計算書 | K13: 受注拠点CD | V13: 画 | W13: 第1画面(基本情報画面) | AF13: 受注拠点CD
A14: 6 | C14: T | D14: 見積計算書 | K14: 担当者CD | V14: 画 | W14: 第1画面(基本情報画面) | AF14: 担当者CD
A15: 7 | C15: T | D15: 見積計算書 | K15: 得意先CD | V15: 画 | W15: 第1画面(基本情報画面) | AF15: 得意先CD
A16: 8 | C16: T | D16: 見積計算書 | K16: 案件No | V16: 画 | W16: 第1画面(基本情報画面) | AF16: 案件No
A17: 9 | C17: T | D17: 見積計算書 | K17: 案件No(親・子) | V17: 画 | W17: 第1画面(基本情報画面) | AF17: 案件No(親・子)
A18: 10 | C18: T | D18: 見積計算書 | K18: 案件No(子) | V18: 画 | W18: 第1画面(基本情報画面) | AF18: 案件No(子)
A19: 11 | C19: T | D19: 見積計算書 | K19: サンプル依頼ID | V19: 画 | W19: 第1画面(基本情報画面) | AF19: サンプル依頼ID
A20: 12 | C20: T | D20: 見積計算書 | K20: 受注区分 | V20: 画 | W20: 第1画面(基本情報画面) | AF20: 受注区分
A21: 13 | C21: T | D21: 見積計算書 | K21: 顧客品名 | V21: 画 | W21: 第1画面(基本情報画面) | AF21: 顧客品名
A22: 14 | C22: T | D22: 見積計算書 | K22: 受注総数 | V22: 画 | W22: 第1画面(基本情報画面) | AF22: 受注総数
A23: 15 | C23: T | D23: 見積計算書 | K23: 受注年月 | V23: 画 | W23: 第1画面(基本情報画面) | AF23: 受注年月
... A52: 44 | C52: T | D52: 見積計算書 | K52: AD（形状） | V52: 画 | W52: 第1画面(基本情報画面) | AF52: AD（形状）
A53: 45 | C53: T | D53: 見積計算書 | K53: 戦略商品区分_01 | V53: 画 | W53: 第1画面(基本情報画面) | AF53: 戦略商品区分_01 | AQ53: FSC
A54: 46 | C54: T | D54: 見積計算書 | K54: 戦略商品区分_02 | V54: 画 | W54: 第1画面(基本情報画面) | AF54: 戦略商品区分_02 | AQ54: TKP
A55: 47 | C55: T | D55: 見積計算書 | K55: 戦略商品区分_03 | V55: 画 | W55: 第1画面(基本情報画面) | AF55: 戦略商品区分_03 | AQ55: スマパピ
A56: 48 | C56: T | D56: 見積計算書 | K56: 戦略商品区分_04 | V56: 画 | W56: 第1画面(基本情報画面) | AF56: 戦略商品区分_04 | AQ56: バリット
A57: 49 | C57: T | D57: 見積計算書 | K57: 戦略商品区分_05 | V57: 画 | W57: 第1画面(基本情報画面) | AF57: 戦略商品区分_05 | AQ57: マイクロ
A58: 50 | C58: T | D58: 見積計算書 | K58: 戦略商品区分_06 | V58: 画 | W58: 第1画面(基本情報画面) | AF58: 戦略商品区分_06 | AQ58: カラフルウィッシュ
A59: 51 | C59: T | D59: 見積計算書 | K59: 戦略商品区分_07 | V59: 画 | W59: 第1画面(基本情報画面) | AQ59: 空き項目:マスタ値により、不可視設定
A60: 52 | C60: T | D60: 見積計算書 | K60: 戦略商品区分_08 | V60: 画 | W60: 第1画面(基本情報画面) | AQ60: 空き項目:マスタ値により、不可視設定
A61: 53 | C61: T | D61: 見積計算書 | K61: 戦略商品区分_09 | V61: 画 | W61: 第1画面(基本情報画面) | AQ61: 空き項目:マスタ値により、不可視設定
A62: 54 | C62: T | D62: 見積計算書 | K62: 戦略商品区分_10 | V62: 画 | W62: 第1画面(基本情報画面) | AQ62: 空き項目:マスタ値により、不可視設定
A63: 55 | C63: T | D63: 見積計算書 | K63: 印刷備考 | V63: 画 | W63: 第1画面(基本情報画面) | AF63: 印刷備考
A64: 56 | C64: T | D64: 見積計算書 | K64: 製造備考 | V64: 画 | W64: 第1画面(基本情報画面) | AF64: 製造備考
A65: 57 | C65: T | D65: 見積計算書 | K65: 伝票備考 | V65: 画 | W65: 第1画面(基本情報画面) | AF65: 伝票備考
A66: 58 | C66: T | D66: 見積計算書 | K66: 納入備考 | V66: 画 | W66: 第1画面(基本情報画面) | AF66: 納入備考
A67: 59 | C67: T | D67: 見積計算書 | K67: 出荷備考１ | V67: 画 | W67: 第1画面(基本情報画面) | AF67: 出荷備考１
A68: 60 | C68: T | D68: 見積計算書 | K68: 出荷備考２ | V68: 画 | W68: 第1画面(基本情報画面) | AF68: 出荷備考２
A69: 61 | C69: T | D69: 見積計算書 | K69: 見積数 | V69: 画 | W69: 第1画面(基本情報画面) | AF69: 見積り数01 | AQ69: 見積り数01～08分の枝番として、見積書計算書のデータを生成する
...

Sheet ファイル入出力仕様
A1: =表紙!A54 -> Webシステム | K1: 文書名 | U1: モジュールID | Z1: =表紙!$AJ$63 -> MS | AE1: モジュール名 | AJ1: =表紙!$AX$63 -> 見積管理 | AS1: 文書番号 | AZ1: Version | BF1: Rev.
K2: =表紙!O64 -> アドオン設計書 | U2: ｻﾌﾞﾓｼﾞｭｰﾙID | Z2: =表紙!$AJ$64 -> MSBB | AE2: ｻﾌﾞﾓｼﾞｭｰﾙ名 | AJ2: =表紙!$AX$64 -> Webシステム | AS2: =表紙!$BL$64 -> M7-US-1140 | AZ2: =表紙!$BU$64 -> 7.0.2 | BF2: =表紙!$CB$64 -> 1
K3: =RIGHT(CELL("filename",$A$1),LEN(CELL("filename",$A$1))-FIND("]",CELL("filename",$A$1))) -> #VALUE! | U3: 表題 | Z3: =表紙!$AJ$65 -> MSBBPA010 | AE3: =表紙!$AQ$65 -> Web見積計算書入力
A5: No | G5: 1 | S5: ロジック名称 | AH5: 備考
A6: 処理分類 | E6: 更新
A7: No | C7: 転送先 | V7: 転送元 | AQ7: 説明
C8: 種 | D8: オブジェクト | K8: 項目名 | V8: 種 | W8: オブジェクト | AF8: 項目名

Sheet 画面遷移
A1: =表紙!A54 -> Webシステム | K1: 文書名 | U1: モジュールID | Z1: =表紙!$AJ$63 -> MS | AE1: モジュール名 | AJ1: =表紙!$AX$63 -> 見積管理 | AS1: 文書番号 | AZ1: Version | BF1: Rev.
K2: =表紙!O64 -> アドオン設計書 | U2: ｻﾌﾞﾓｼﾞｭｰﾙID | Z2: =表紙!$AJ$64 -> MSBB | AE2: ｻﾌﾞﾓｼﾞｭｰﾙ名 | AJ2: =表紙!$AX$64 -> Webシステム | AS2: =表紙!$BL$64 -> M7-US-1140 | AZ2: =表紙!$BU$64 -> 7.0.2 | BF2: =表紙!$CB$64 -> 1
K3: =RIGHT(CELL("filename",$A$1),LEN(CELL("filename",$A$1))-FIND("]",CELL("filename",$A$1))) -> #VALUE! | U3: 表題 | Z3: =表紙!$AJ$65 -> MSBBPA010 | AE3: =表紙!$AQ$65 -> Web見積計算書入力
A5: 画面遷移フロー図
C7: 前提条件
D8: 見積計算書・製品マスタ・受注入力画面は、複数画面を遷移して項目を選択・入力し、登録する画面となる
J10: 次画面 | U10: 最初・最終画面以外は、基本「次画面・前画面」のボタンが用意されている
V11: 次画面：現在のページを記憶する
V12: 前画面：前のページに戻る、次画面を押した時に情報をセットし前画面を呼び出す
V13: ※次画面を押した時と同じ情報となる(次画面で途中まで入力して、前画面をクリックすると入力キャンセル扱いとなる)
J14: 前画面
A17: ＩＤ | C17: S01 | E17: 見積計算書機能の画面遷移
C19: ≫操作種別：登録、訂正、コピー
D20: 1ページ目：基本情報画面 | O20: 2ページ目：工程情報画面 | AH20: 3ページ目：計算結果画面
J21: 次画面 | U21: 次画面
J23: 戻る | U23: 戻る
D25: 溶リ判定必要時
D26: (取引先.容器リ法対象=該当)
E27: 戻る
I30: 溶リ判定ポップアップ | R30: 工程選択ポップアップ
I31: ※得意先マスタ：容リ法対象=1:該当時
C33: ≫操作種別：削除、参照
D34: 1ページ目：基本情報画面 | O34: 3ページ目：計算結果画面
J37: 戻る | V37: ※削除時
C43: ≫コピー登録
D44: 3ページ目：計算結果画面 | U44: 3ページ目：計算結果画面
A51: ＩＤ | C51: S02 | E51: 見積計算書、他画面の画面遷移
D53: NO1 | AG53: ※Web御見積書登録・発行側で記述
D54: Web見積計算書一覧照会(検索モード) | AG54: Web御見積書登録・発行
K60: Web見積計算書入力 | V60: Web見積計算書入力 | AG60: Web見積計算書入力
K61: 1ページ目：基本情報画面 | V61: 2ページ目：工程情報画面 | AG61: 3ページ目：計算結果画面
Q62: 次画面 | AB62: 次画面
Q64: 戻る | AB64: 戻る
D67: NO2 | Q67: NO4
D68: 簡易検索 | I68: NO3 | Q68: 簡易検索
D69: ヒアリングシート | I69: Web取引先一覧照会 | Q69: その他
A74: ID | D74: 処理名
A75: S02 | D75: 見積計算書から他画面の画面遷移
B77: NO | D77: 遷移元ＩＤ | H77: 遷移元画面名 | P77: 遷移先ＩＤ | U77: 遷移先画面名 | AC77: 目的 | AH77: 引継項目 | AQ77: 遷移後のアクション(遷移先) | BA77: 戻り値 | BJ77: 戻り値取得後のアクション(遷移元) | BT77: 備考
B78: 1 | D78: MSBBPA010 | H78: Web見積計算書入力(基本) | P78: MSBBPA020 | U78: Web見積計算書一覧照会 | AC78: 検索結果取得 | AQ78: 検索 | BA78: 見積計算書選択データ(1行) | BJ78: 検索入出力仕様.NO1
...

Sheet メッセージ一覧
A1: =表紙!A54 -> Webシステム | K1: 文書名 | U1: モジュールID | Z1: =表紙!$AJ$63 -> MS | AE1: モジュール名 | AJ1: =表紙!$AX$63 -> 見積管理 | AS1: 文書番号 | AZ1: Version | BF1: Rev.
K2: =表紙!O64 -> アドオン設計書 | U2: ｻﾌﾞﾓｼﾞｭｰﾙID | Z2: =表紙!$AJ$64 -> MSBB | AE2: ｻﾌﾞﾓｼﾞｭｰﾙ名 | AJ2: =表紙!$AX$64 -> Webシステム | AS2: =表紙!$BL$64 -> M7-US-1140 | AZ2: =表紙!$BU$64 -> 7.0.2 | BF2: =表紙!$CB$64 -> 1
K3: =RIGHT(CELL("filename",$A$1),LEN(CELL("filename",$A$1))-FIND("]",CELL("filename",$A$1))) -> #VALUE! | U3: 表題 | Z3: =表紙!$AJ$65 -> MSBBPA010 | AE3: =表紙!$AQ$65 -> Web見積計算書入力
C4: ↓アドオン画面のため、基本全て[新]
A5: No | C5: 新/変 | E5: 種別 | G5: メッセージ内容 | AQ5: 備考（パラメータ等） | BG5: メッセージID
A6: 1 | C6: 新 | E6: W | G6: 「見積計算書NOが未入力です。」 | BG6: メッセージID.101
A7: 2 | C7: 新 | E7: W | G7: 「見積計算書NOが未登録です。」 | BG7: メッセージID.102
A8: 3 | C8: 新 | E8: W | G8: 「見積拠点CDが未入力です。」 | BG8: メッセージID.111
A9: 4 | C9: 新 | E9: W | G9: 「受注拠点CDが未入力です。」 | BG9: メッセージID.112
A10: 5 | C10: 新 | E10: W | G10: 「担当者CDが未入力です。」 | BG10: メッセージID.113
A11: 6 | C11: 新 | E11: W | G11: 「得意先が未入力です。」 | BG11: メッセージID.114
A12: 7 | C12: 新 | E12: W | G12: 「案件NOが未入力です。」 | BG12: メッセージID.115
A13: 8 | C13: 新 | E13: W | G13: 「顧客品名が未入力です。」 | BG13: メッセージID.116
A14: 9 | C14: 新 | E14: W | G14: 「受注総数が未入力です。」 | BG14: メッセージID.117
A15: 10 | C15: 新 | E15: W | G15: 「受注年月が未入力です。」 | BG15: メッセージID.118
A16: 11 | C16: 新 | E16: W | G16: 「親子区分が未入力です。」 | BG16: メッセージID.119
A17: 12 | C17: 新 | E17: W | G17: 「原紙が非認証です。」 | BG17: メッセージID.120
... A91: 86 | C91: 新 | E91: W | G91: 「シート単価を入力」 | BG91: メッセージID.310

Sheet テーブル項目_見積計算書
A1: =表紙!A54 -> Webシステム | K1: 文書名 | U1: モジュールID | Z1: =表紙!$AJ$63 -> MS | AE1: モジュール名 | AJ1: =表紙!$AX$63 -> 見積管理 | AS1: 文書番号 | AZ1: Version | BF1: Rev.
K2: =表紙!O64 -> アドオン設計書 | U2: ｻﾌﾞﾓｼﾞｭｰﾙID | Z2: =表紙!$AJ$64 -> MSBB | AE2: ｻﾌﾞﾓｼﾞｭｰﾙ名 | AJ2: =表紙!$AX$64 -> Webシステム | AS2: =表紙!$BL$64 -> M7-US-1140 | AZ2: =表紙!$BU$64 -> 7.0.2 | BF2: =表紙!$CB$64 -> 1
K3: =RIGHT(CELL("filename",$A$1),LEN(CELL("filename",$A$1))-FIND("]",CELL("filename",$A$1))) -> #VALUE! | U3: 表題 | Z3: =表紙!$AJ$65 -> MSBBPA010 | AE3: =表紙!$AQ$65 -> Web見積計算書入力
A5: テーブル名 | O5: 日本語名 | AE5: 種別
O6: 見積計算書 | AE6: アドオン(新規) | BP6: CP指摘 2022/10/18 本多 現状、見積から製品コードが作成された場合、見積テーブルへ製品コードを記録しています。これにより見積決定率の算出等をしております。
BQ7: MDSOL 野村 2022/10/28 製品CD追加しました。
A8: 主キー | D8: 項目名 | O8: 日本語名 | AE8: 型 | AG8: 桁 | AI8: Null | AK8: 説明 | BL8: 値の制限 | BM8: 設定仕様 | BN8: 未設定時の振る舞い | BO8: 見積計算書 画面
A9: 〇 | O9: 見積計算書NO | AE9: C | AI9: N | AK9: 枝番含む | BO9: 第1画面(基本情報画面) | BP9: CP指摘 2022/09/30 三宅 見積計算書№は「枝番を含む」となっているので「123456」と「1」のように持つのではなく「123456-1」のように一つのカラムで持つのでしょうか？分けずに持つその場合、参照時にロット別表示やロット別見積一覧の箇所は「ハイフン区切りの前の部分が一致するレコード」として取得しないといけないので効率が悪く処理も遅くならないでしょうか？
D10: QTN_CALC_NO_M | O10: 見積計算書NO_主番 | AE10: N | AI10: N | AK10: 見積計算書NOの内訳(99999999-01) 99999999部分 | BO10: 第1画面(基本情報画面) | BQ10: MDSOL 野村 2022/10/28 内訳項目として追加しました。
D11: QTN_CALC_NO_B | O11: 見積計算書NO_枝番 | AE11: N | AI11: N | AK11: 見積計算書NOの内訳(99999999-01) 1部分 | BO11: 第1画面(基本情報画面)
O12: 参照元_見積計算書NO | AE12: C | AI12: Y | AK12: 操作種別：コピー時、保存 | BL12: 見積計算書トラン | BO12: 第1画面(基本情報画面)
D13: PRO_CD | O13: 製品コード | AE13: C | AI13: N | AK13: 品目コード+枝番
O14: 見積日 | AE14: D | AI14: N | AK14: 見積作成日
O15: 見積拠点CD | AE15: C | AI15: N | BL15: 拠点マスタ | BO15: 第1画面(基本情報画面)
O16: 受注拠点CD | AE16: C | AI16: N | BL16: 拠点マスタ | BO16: 第1画面(基本情報画面)
O17: 担当者CD | AE17: C | AI17: N | BL17: 担当者マスタ | BO17: 第1画面(基本情報画面)
O18: 得意先CD | AE18: C | AI18: N | BL18: 得意先マスタ | BO18: 第1画面(基本情報画面)
O19: 案件No | AE19: C | AI19: N | AK19: 案件No(親) | BL19: ヒアリングシート | BO19: 第1画面(基本情報画面)
O20: サンプル依頼ID | AE20: C | AI20: N | BL20: ヒアリングシート | BO20: 第1画面(基本情報画面)
O21: 受注区分 | AE21: C | AI21: N | BO21: 第1画面(基本情報画面)
O22: 顧客品名 | AE22: C | AI22: N | BO22: 第1画面(基本情報画面)
O23: 受注総数 | AE23: N | AI23: N | BO23: 第1画面(基本情報画面)
O24: 受注年月 | AE24: C | AI24: N | BO24: 第1画面(基本情報画面)
O25: 親子区分 | AE25: C | AI25: N | BO25: 第1画面(基本情報画面)
O26: FSC認証区分 | AE26: C | AI26: N | BO26: 第1画面(基本情報画面)
O27: FSC材質区分 | AE27: C | AI27: N | BO27: 第1画面(基本情報画面)
O28: シート段 | AE28: C | AI28: N | BO28: 第1画面(基本情報画面)
O29: 原紙CD(表) | AE29: C | AI29: N | BL29: 原紙マスタ | BO29: 第1画面(基本情報画面)
O30: 印刷CD(表) | AE30: C | AI30: N | BL30: 汎用マスタ(印刷マスタ) | BO30: 第1画面(基本情報画面)
O31: エンボスCD(表) | AE31: C | AI31: N | BL31: 汎用マスタ(エンボスマスタ) | BO31: 第1画面(基本情報画面)
O32: 柄数(表) | AE32: C | AI32: N | BO32: 第1画面(基本情報画面)
O33: 原紙CD(中) | AE33: C | AI33: N | BL33: 原紙マスタ | BO33: 第1画面(基本情報画面)
O34: 印刷CD(中) | AE34: C | AI34: N | BL34: 汎用マスタ(印刷マスタ) | BO34: 第1画面(基本情報画面)
O35: エンボスCD(中) | AE35: C | AI35: N | BL35: 汎用マスタ(エンボスマスタ) | BO35: 第1画面(基本情報画面)
O36: 原紙CD(裏) | AE36: C | AI36: N | BL36: 原紙マスタ | BO36: 第1画面(基本情報画面)
O37: 印刷CD(裏) | AE37: C | AI37: N | BL37: 汎用マスタ(印刷マスタ) | BO37: 第1画面(基本情報画面)
O38: エンボスCD(裏) | AE38: C | AI38: N | BL38: 汎用マスタ(エンボスマスタ) | BO38: 第1画面(基本情報画面)
O39: 柄数(裏) | AE39: C | AI39: N | BO39: 第1画面(基本情報画面)
O40: 枚葉印刷 | AE40: C | AI40: N | BO40: 第1画面(基本情報画面)
O41: 刃渡り_巾 | AE41: N | AI41: N | BO41: 第1画面(基本情報画面)
...

Sheet テーブル項目_見積加工工程
A1: =表紙!A54 -> Webシステム | K1: 文書名 | U1: モジュールID | Z1: =表紙!$AJ$63 -> MS | AE1: モジュール名 | AJ1: =表紙!$AX$63 -> 見積管理 | AS1: 文書番号 | AZ1: Version | BF1: Rev.
K2: =表紙!O64 -> アドオン設計書 | U2: ｻﾌﾞﾓｼﾞｭｰﾙID | Z2: =表紙!$AJ$64 -> MSBB | AE2: ｻﾌﾞﾓｼﾞｭｰﾙ名 | AJ2: =表紙!$AX$64 -> Webシステム | AS2: =表紙!$BL$64 -> M7-US-1140 | AZ2: =表紙!$BU$64 -> 7.0.2 | BF2: =表紙!$CB$64 -> 1
K3: =RIGHT(CELL("filename",$A$1),LEN(CELL("filename",$A$1))-FIND("]",CELL("filename",$A$1))) -> #VALUE! | U3: 表題 | Z3: =表紙!$AJ$65 -> MSBBPA010 | AE3: =表紙!$AQ$65 -> Web見積計算書入力
A5: テーブル名 | O5: 日本語名 | AE5: 種別
O6: 見積加工工程 | AE6: アドオン(新規)
A8: 主キー | D8: 項目名 | O8: 日本語名 | AE8: 型 | AG8: 桁 | AI8: Null | AK8: 説明 | BL8: 値の制限 | BM8: 設定仕様 | BN8: 未設定時の振る舞い | BO8: 見積計算書 画面
A9: 〇 | O9: 見積計算書NO | AE9: C | AI9: N | AK9: 枝番含む | BO9: 1ページ目：メンテ対象選択画面
A10: 〇 | O10: 作業CD | AE10: C | AI10: N | BL10: 作業マスタ(条件=作業CD) | BO10: 第2画面(工程情報画面)
O11: 工程CD | AE11: C | AI11: N | BL11: 工程マスタ | BO11: 第2画面(工程情報画面)
O12: 作業順 | AE12: N | AI12: N | AK12: 工程毎の作業順、システム自動採番 | BO12: 第2画面(工程情報画面)
O13: ワーキンググループＣＤ | AE13: C | AG13: 10 | AI13: Y | AK13: 製造場所に紐づくワーキンググループCD | BO13: 第2画面(工程情報画面)
O14: 製造場所 | AE14: C | AI14: Y | BL14: 汎用マスタ(拠点・外注) | BO14: 第2画面(工程情報画面)
O15: 工程仕様01 | AE15: N | AI15: Y | BL15: 汎用マスタ(工程仕様) | BO15: 第2画面(工程情報画面)
O16: 工程仕様02 | AE16: N | AI16: Y | BL16: 汎用マスタ(工程仕様) | BO16: 第2画面(工程情報画面)
O17: 工程仕様03 | AE17: N | AI17: Y | BL17: 汎用マスタ(工程仕様) | BO17: 第2画面(工程情報画面)
O18: 工程仕様04 | AE18: N | AI18: Y | BL18: 汎用マスタ(工程仕様) | BO18: 第2画面(工程情報画面)
O19: 工程仕様05 | AE19: N | AI19: Y | BL19: 汎用マスタ(工程仕様) | BO19: 第2画面(工程情報画面)
O20: 工程仕様06 | AE20: N | AI20: Y | BL20: 汎用マスタ(工程仕様) | BO20: 第2画面(工程情報画面)
O21: 工程仕様07 | AE21: N | AI21: Y | BL21: 汎用マスタ(工程仕様) | BO21: 第2画面(工程情報画面)
O22: 工程仕様08 | AE22: N | AI22: Y | BL22: 汎用マスタ(工程仕様)
O23: 工程仕様09 | AE23: N | AI23: Y | BL23: 汎用マスタ(工程仕様)
O24: 工程仕様10 | AE24: N | AI24: Y | BL24: 汎用マスタ(工程仕様)
O25: 版NO | AE25: C | AI25: Y | BO25: 第2画面(工程情報画面)
O26: 工程備考１ | AE26: C | AI26: Y | BO26: 第2画面(工程情報画面)
O27: 工程備考２ | AE27: C | AI27: Y | BO27: 第2画面(工程情報画面)
O28: 指示数 | AE28: N | BO28: 第3画面(計算結果画面)
O29: 見積単価 | AE29: N | BO29: 第3画面(計算結果画面)
O30: 見積工賃 | AE30: N | BO30: 第3画面(計算結果画面)
O31: 外注単価 | AE31: N | BO31: 第3画面(計算結果画面)
O32: 外注金額 | AE32: N | BO32: 第3画面(計算結果画面)
O33: 版型仕入 | AE33: N | BO33: 第3画面(計算結果画面)
O34: 版型金額 | AE34: N | BO34: 第3画面(計算結果画面)
O35: 並び順 | AE35: N | AI35: N | AK35: 画面の並び順、システム自動採番
D36: MEMO1 | O36: メモ１ | AE36: C | AG36: 100 | AI36: Y
D37: MEMO2 | O37: メモ２ | AE37: C | AG37: 100 | AI37: Y
D38: MEMO3 | O38: メモ３ | AE38: C | AG38: 100 | AI38: Y
D39: DEL_FLG | O39: 論理削除ＦＬＧ | AE39: F | AI39: N | AK39: 論理削除を示すフラグ
D40: DEL_USR_ID | O40: 論理削除ユーザＩＤ | AE40: C | AG40: 500 | AI40: Y
D41: DEL_USR_NM | O41: 論理削除ユーザ名 | AE41: C | AG41: 100 | AI41: Y
D42: DEL_TS | O42: 論理削除日時 | AE42: TS | AG42: 0 | AI42: Y
...

Sheet |→補足シート

Sheet 現行画面
A1: =表紙!A54 -> Webシステム | K1: 文書名 | U1: モジュールID | Z1: =表紙!$AJ$63 -> MS | AE1: モジュール名 | AJ1: =表紙!$AX$63 -> 見積管理 | AS1: 文書番号 | AY1: Version | BE1: Rev.
K2: =表紙!O64 -> アドオン設計書 | U2: ｻﾌﾞﾓｼﾞｭｰﾙID | Z2: =表紙!$AJ$64 -> MSBB | AE2: ｻﾌﾞﾓｼﾞｭｰﾙ名 | AJ2: =表紙!$AX$64 -> Webシステム | AS2: =表紙!$BL$64 -> M7-US-1140 | AY2: =表紙!$BU$64 -> 7.0.2 | BE2: =表紙!$CB$64 -> 1
K3: =RIGHT(CELL("filename",$A$1),LEN(CELL("filename",$A$1))-FIND("]",CELL("filename",$A$1))) -> #VALUE! | U3: 表題 | Z3: =表紙!$AJ$65 -> MSBBPA010 | AE3: =表紙!$AQ$65 -> Web見積計算書入力
A5: 画面イメージ
C7: 第1画面
C46: 第2画面 | AZ46: 第3画面
C82: 第4画面
C118: 第5画面
