Workbook
Name Rev.: 表紙!$U$22
Name Revision: [2]表紙!$AP$5
Name Revision: [5]表紙!$AP$5
Name Revision: [3]表紙!$AP$5
Name Ver.: 表紙!$AE$26
Name Version: [2]表紙!$AJ$5
Name Version: [5]表紙!$AJ$5
Name Version: [3]表紙!$AJ$5
Name ご確認者: 表紙!$AG$40
Name ご確認日: 表紙!$AG$42
Name サブシステム名: 表紙!$U$28
Name システム名: 表紙!$U$26
Name プロジェクト名: 表紙!$U$18
Name 開発区分: 表紙!$U$36
Name 機能ＩＤ: 表紙!$U$32
Name 機能区分: 表紙!$U$34
Name 機能名称: 表紙!$U$30
Name 顧客名: 表紙!$U$16
Name 最終更新者: 表紙!$AB$40
Name 最終更新日: 表紙!$AB$42
Name 作成者: 表紙!$W$40
Name 作成日: 表紙!$W$42
Name 章: 表紙!$M$10
Name 文書番号: [2]表紙!$O$5
Name 文書番号: [5]表紙!$O$5
Name 文書番号: [3]表紙!$O$5
Name 文書番号_カスタマイズ: '[5]表紙（カスタマイズ）'!$U$20
Name 文書番号_カスタマイズ: '[3]表紙（カスタマイズ）'!$U$20
Name 文書名: [2]表紙!$M$15
Name 文書名: [5]表紙!$M$15
Name 文書名: 表紙!$M$10
Name 文書名: [3]表紙!$M$15
Name 文書名_カスタマイズ: '[5]表紙（カスタマイズ）'!$M$10
Name 文書名_カスタマイズ: '[3]表紙（カスタマイズ）'!$M$10

Sheet 目次
A1: アドオン設計書作成ガイド
C3: ■アドオン設計と成果物について
D4: ・システム設計フェーズとソフトウェア設計フェーズでアドオンの処理仕様を定義する
D5: ・システム設計フェーズとソフトウェア設計フェーズの成果物がアドオン設計書であり、ソフトウェア製作フェーズのインプットとなる
C7: ■各設計フェーズ毎のアドオン設計書作成範囲
D8: ・システム設計フェーズ：他機能との関連を定義するとともに、画面や帳票、ファイル入出力を中心とした外部入出力の設計を行う
D9: ・ソフトウェア設計フェーズ：内部処理を中心とした設計を行う
U11: ◎ | W11: … | X11: システム設計フェーズで作成
U12: ○ | W12: … | X12: システム設計フェーズで基本仕様を定義して、ソフトウェア設計フェーズで詳細化する
U13: △ | W13: … | X13: 必要に応じて（例えば標準仕様から変更がない場合は不要）
U14: ‐ | W14: … | X14: 不要
W15: … | X15: ソフトウェア設計フェーズで作成
D17: 各設計書と作成対象シートのマトリックス | S17: ※カスタマイズ：標準機能に機能を追加する アドオン：新規で機能を開発する
D18: EXCELシート | N18: 画面設計書 | W18: バッチ設計書 | AF18: 帳票設計書 | AO18: ＢＩ設計書 | AT18: .Net設計書 | BB18: EXCELシート | BL18: WebDB設計書 | BR18: 帳票設計書 | BX18: 汎用申請設計書
N19: カスタマイズ | S19: アドオン | W19: カスタマイズ | AB19: アドオン | AF19: カスタマイズ | AK19: アドオン | AO19: アドオン | AT19: アドオン | BL19: アドオン | BR19: アドオン | BX19: アドオン
D20: 概要 | N20: ◎ | O20: ※1 | S20: ◎ | W20: ◎ | X20: ※1 | AB20: ◎ | AF20: ◎ | AG20: ※1 | AK20: ◎ | AO20: ◎ | AT20: ◎ | BB20: 機能概要 | BL20: ◎ | BR20: ◎ | BX20: ◎
D21: レイアウト | N21: ◎ | O21: ※2 | S21: ◎ | W21: ‐ | AB21: ‐ | AF21: ◎ | AG21: ※2 | AK21: ◎ | AO21: ◎ | AT21: ◎ | BB21: アプリケーションフロー | BL21: ◎ | BR21: ー | BX21: ◎
D22: 項目説明 | N22: △ | S22: ○ | W22: ‐ | AB22: ‐ | AF22: △ | AK22: ○ | AO22: ○ | AT22: ○ | BB22: データベース設定 | BL22: ◎ | BR22: ー | BX22: ◎
D23: 引数説明 | N23: ‐ | S23: ‐ | W23: △ | AB23: ◎ | AF23: ‐ | AK23: ‐ | AO23: ‐ | AT23: ◎ | BB23: フィールド設定 | BL23: ◎ | BR23: ー | BX23: ◎
D24: 処理概要 | N24: ◎ | S24: ◎ | W24: ◎ | AB24: ◎ | AF24: ◎ | AK24: ◎ | AO24: ◎ | AT24: ◎ | BB24: 一覧表示画面設定 | BL24: ◎ | BR24: ー | BX24: ◎
D25: 処理詳細 | BB25: 表示編集画面設定 | BL25: ◎ | BR25: ー | BX25: ◎
D26: 処理・サービス関連図 | N26: △ | S26: ◎ | W26: △ | AB26: ◎ | AF26: ‐ | AK26: ‐ | AO26: ‐ | AT26: ◎ | BB26: 明細画面設定 | BL26: △ | BN26: ※3 | BR26: ー | BX26: △ | BZ26: ※3
D27: 検索入出力仕様 | N27: △ | S27: ○ | W27: △ | AB27: ○ | AF27: ‐ | AK27: ‐ | AO27: ‐ | AT27: ○ | BB27: 集計表示設定 | BL27: △ | BN27: ※4 | BR27: ー | BX27: △ | BZ27: ※4
D28: 更新入出力仕様 | N28: △ | S28: ○ | W28: △ | AB28: ○ | AF28: ‐ | AK28: ‐ | AO28: ‐ | AT28: ○ | BB28: 絞り込み条件設定 | BL28: △ | BN28: ※5 | BR28: ー | BX28: △ | BZ28: ※5
D29: ファイル入出力仕様 | N29: △ | S29: △ | W29: ‐ | AB29: ‐ | AF29: ‐ | AK29: ‐ | AO29: ‐ | AT29: △ | BB29: その他設定 | BR29: ー
D30: 画面遷移 | N30: △ | S30: ◎ | W30: ‐ | AB30: ‐ | AF30: ‐ | AK30: ‐ | AO30: ‐ | AT30: ◎ | BB30: 帳票イメージ | BL30: ー | BR30: ◎ | BX30: ー
D31: メッセージ一覧 | N31: △ | S31: △ | W31: △ | AB31: △ | AF31: ‐ | AK31: ‐ | AO31: ‐ | AT31: △ | BB31: 項目設計 | BL31: ー | BR31: ◎ | BX31: ー
D32: 補足説明 | N32: △ | S32: △ | W32: △ | AB32: △ | AF32: △ | AK32: △ | AO32: △ | AT32: △ | BB32: 補足説明 | BL32: △ | BR32: △ | BX32: △
D33: サービス呼出編集仕様 | N33: - | S33: - | W33: - | AB33: - | AF33: - | AK33: - | AO33: - | AT33: - | BB33: 補足説明(詳細)
D35: ※1 | G35: 別シートでカスタマイズ内容を記載する | BB35: ※3 | BE35: 単票画面は記載しない
D36: ※2 | G36: 吹き出しでカスタマイズ内容を記載する | BB36: ※4 | BE36: 集計・グラフ機能を使用する場合に記載する
BB37: ※5 | BE37: 共通設定のみ記載する(個別設定は、記載しない)

Sheet 表紙
AW2: サブモジュール
AW3: MA_マスタ管理
AW4: MB_業務共通
AW5: MG_原価管理
AW6: MSBA_需給管理
M7: 基本設計 | AW7: MSBB_販売管理
AW8: MSBC_生産管理
AW9: MSBD_購買管理
M10: アドオン設計書 | AW10: MSBE_在庫物流管理
AW11: MSBF_品質管理
AW12: MSBG_債権管理
AW13: MSBH_債務管理
AW14: MSBI_締処理
AW15: MSUA_リスト・入力補助
M16: 顧客 | U16: 株式会社クラウン・パッケージ | AW16: PF_ESBアダプタ
M18: プロジェクト名 | U18: 基幹システム刷新PJ | AW18: 機能区分
AW19: 画面
M20: 文書番号 | AW20: 帳票
AW21: バッチ
M22: Ｒｅｖ． | U22: {=MAX(_xlfn.NUMBERVALUE(改訂!A7:E50))} -> 2 | AW22: マスタ
M24: 機密性区分 | U24: 取扱注意（Ｃ） | AW24: 開発区分
AW25: カスタマイズ
M26: システム名 | U26: Webシステム | AC26: Ver. | AE26: 7.0.2 | AW26: アドオン
AW27: －
M28: サブモジュール | U28: MSBB_販売管理
M30: 機能名 | U30: =M50 -> Web取引先マスタ一覧照会
M32: 機能ID | U32: =G50 -> MSBBPA120
M34: 機能区分 | U34: 画面
M36: 開発区分 | U36: アドオン
W39: 作成 | AB39: 最終更新 | AG39: ご確認
W40: MDSOL | AB40: =改訂!AZ2 -> MDSOL 野村
W42: 44805 | AB42: =改訂!BJ2 -> 44910
A48: 文書番号 | G48: 画面ID | M48: 画面名 | V48: Version | AB48: Revision
A50: M7-US-1140 | G50: MSBBPA120 | M50: Web取引先マスタ一覧照会 | V50: 1.0.0 | AB50: r01.00
A53: 共通（元データ）
A54: Webシステム | K54: 文書名 | U54: モジュールID | Z54: MS | AE54: モジュール名 | AJ54: Webシステム | AS54: 文書番号 | AZ54: Version | BF54: Rev.
K55: 画面説明書 | U55: ｻﾌﾞﾓｼﾞｭｰﾙID | Z55: MSBB | AE55: ｻﾌﾞﾓｼﾞｭｰﾙ名 | AJ55: 販売Webシステム | AS55: M7-US-1140 | AZ55: 1.0.0 | BF55: r00.00
K56: 表紙 | U56: 表題 | Z56: MSBBPA120 | AE56: Web取引先マスタ一覧照会
A57: 共通（リンク用）
A58: =A54 -> Webシステム | K58: 文書名 | U58: モジュールID | Z58: =Z54 -> MS | AE58: モジュール名 | AJ58: =AJ54 -> Webシステム | AS58: 文書番号 | AZ58: Version | BF58: Rev.
...

Sheet 改訂
A1: 第7章 | K1: 改訂 | AU1: 作成者 | AZ1: MDSOL | BE1: 作成日 | BJ1: =表紙!W42 -> 44805 | BP1: Rev.
AU2: 修正者 | AZ2: =BM10 -> MDSOL 野村 | BE2: 改訂日 | BJ2: =BM9 -> 44910 | BP2: =表紙!CB64 -> 2
A5: Rev. | F5: 改定内容 | BC5: 頁 | BM5: 変更日 変更者 | BR5: 確認日 確認者
A7: 1 | F7: 新規作成
A9: 2 | F9: 仕様連絡書：RCS-1091に伴う下記改定を実施 条件と一覧項目にWGを追加(営業担当/業務担当)、営業担当と営業WGの左右を入れ替え（業務も同様）、拠点＞部門＞担当者 | BC9: 画面イメージ、項目説明、検索入出力仕様、ファイル入出力仕様 | BM9: 44910 | BR9: 44911
BM10: MDSOL 野村 | BR10: MDSOL 奥本
A11: 2 | F11: 詳細設計の追加 | BC11: 処理詳細 画面遷移 | BM11: 44917
BM12: TBK 華
A13: 2 | F13: メッセージIDの採番 | BC13: メッセージ一覧 | BM13: 44931
BM14: TBK 華

Sheet 概要
A1: =表紙!A54 -> Webシステム | O1: 文書名 | AC1: モジュールID | AJ1: =表紙!AJ63 -> MS | AQ1: モジュール名 | AX1: =表紙!AX63 -> Webシステム | BL1: 文書番号 | BU1: Version | CB1: Rev.
O2: =表紙!O64 -> アドオン設計書 | AC2: サブモジュールID | AJ2: =表紙!AJ64 -> MSBB | AQ2: サブモジュール名 | AX2: =表紙!AX64 -> 販売Webシステム | BL2: =表紙!BL64 -> M7-US-1140 | BU2: =表紙!BU64 -> 7.0.2 | CB2: =表紙!CB64 -> 2
O3: =RIGHT(CELL("filename",$A$1),LEN(CELL("filename",$A$1))-FIND("]",CELL("filename",$A$1))) -> 概要 | AC3: 表題 | AJ3: =表紙!AJ65 -> MSBBPA120 | AQ3: =表紙!AQ65 -> Web取引先マスタ一覧照会
AO5: 概要
B7: 【説明】
C8: 取引先マスタの一覧照会画面
B10: 【目的】
C11: 取引先マスタを一覧照会する。取引先マスタ画面へ遷移する。(参照・訂正)
B13: 【処理関連図/サービス関連図】
C14: ※処理・サービス関連図シートに詳細記載
B16: 【オペレーション一覧】
C17: 取引先マスタの検索・照会処理を行う
C18: 取引先マスタのCSV出力を行う
B20: 【SQLID一覧】
C21: なし
B23: 【ソート順】
C24: 取引先CD
B26: 【データアクセスコントロール】
C27: 拠点による制御
C28: ※詳細は、【MSBBPA000】_共通設計書_アドオン(Webシステム共通仕様)にて定義
B30: 【自由記述】
C31: なし

Sheet 画面イメージ
A1: =表紙!A54 -> Webシステム | K1: 文書名 | U1: モジュールID | Z1: =表紙!$AJ$63 -> MS | AE1: モジュール名 | AJ1: =表紙!$AX$63 -> Webシステム | AS1: 文書番号 | AZ1: Version | BF1: Rev.
K2: =表紙!O64 -> アドオン設計書 | U2: ｻﾌﾞﾓｼﾞｭｰﾙID | Z2: =表紙!$AJ$64 -> MSBB | AE2: ｻﾌﾞﾓｼﾞｭｰﾙ名 | AJ2: =表紙!$AX$64 -> 販売Webシステム | AS2: =表紙!$BL$64 -> M7-US-1140 | AZ2: =表紙!$BU$64 -> 7.0.2 | BF2: =表紙!$CB$64 -> 2
K3: =RIGHT(CELL("filename",$A$1),LEN(CELL("filename",$A$1))-FIND("]",CELL("filename",$A$1))) -> 画面イメージ | U3: 表題 | Z3: =表紙!$AJ$65 -> MSBBPA120 | AE3: =表紙!$AQ$65 -> Web取引先マスタ一覧照会
A5: 画面イメージ
B7: ≫凡例
Q8: ・・・ | S8: ボタン
C9: 見積計算書№ | Q9: ・・・ | S9: 検索項目(検索画面表示選択) | AJ9: 参照情報
C10: 品名 | Q10: ・・・ | S10: 入力項目
C11: 取引先 | Q11: ・・・ | S11: 表示項目(取引先名称、原紙名等) | AJ11: 担当者
C12: 操作種別 | I12: ●登録 | M12: ○訂正 | Q12: ・・・ | S12: 選択項目(一つのみ選択可能)
C13: 受注区分 | Q13: ・・・ | S13: 選択項目(一つのみ選択可能)
C14: 作業順 | I14: ☑AAA | M14: ☑BBB | Q14: ・・・ | S14: 選択項目(複数選択可能)
C16: 見積作成日 | Q16: ・・・ | S16: カレンダー形式
BX21: －
D23: ■得意先 | H23: ■売掛先 | L23: ■請求先 | P23: ■入金先 | T23: ■納品先 | X23: ■与信管理先 | BR23: * | BS23: あいまい検索可能
D24: ■発注先 | H24: ■買掛先 | L24: ■支払予定管理先 | T24: ■支払先 | X24: ■メーカ
D27: 登録日 | O27: ~
D28: 取引先 | O28: *
D29: 取引先名 | U29: * | X29: 標準企業コード | AL29: *
D30: 法人番号 | U30: * | X30: 法人番号区分 | AD30: 0:法人,1:個人
D31: 郵便番号 | U31: * | CC31: CP指摘 2022/10/20 本多 法人区分（0：法人 1：個人）での区分けにて検索を可能としてください。
D32: 住所 | U32: * | CC32: MDSOL 野村 2022/10/25 条件追加しました
D33: ＴＥＬ | U33: * | X33: ＦＡＸ | AL33: *
D34: 地域CD
D36: 営業担当WG | X36: 営業担当 | DD36: Rev2.0 営業担当WG 追加
D37: 業務担当WG | X37: 業務担当 | DD37: Rev2.0 業務担当WG 追加
D39: 取引先分類1 | I39: 取引先区分 | X39: 取引先分類2 | AD39: ユーザ・コンバータ
D40: 取引先分類3 | I40: 業種 | X40: 取引先分類4 | AD40: 顧客ランク
D41: 取引先分類5 | I41: 債権区分 | X41: 取引先分類6 | AD41: 締め日
D42: 取引先分類7 | X42: 取引先分類8
D43: 取引先分類9 | X43: 取引先分類10
D45: ステータス | J45: ■事前登録 | N45: ■本登録
D48: № | F48: ステータス | I48: 取引先 | L48: 取引先名 | S48: 取引先別名１ | W48: 営業担当 | AG48: 業務担当 | AQ48: 法人番号 | AU48: 標準企業コード | AZ48: 住所(１～４) | BS48: 得意先 | BU48: 売掛先 | BW48: 請求先 | BY48: 入金先 | CA48: 納品先 | CC48: 与信 管理先 | CE48: 発注先 | CG48: 買掛先 | CI48: 支払予定 管理先 | CK48: 支払先 | CM48: メーカ | CO48: 登録日 | CS48: 登録 | DD48: Rev2.0 営業/業務担当WG 追加
W49: WG | Y49: WG名 | AB49: 担当 | AD49: 担当者名 | AG49: WG | AI49: WG名 | AL49: 担当 | AN49: 担当者名 | CS49: 担当 | CU49: 担当者名
D50: 1 | F50: 事前 | I50: 12345 | L50: XXXXXXXXX1XXXXX6 | S50: XXXXXXX8 | W50: 12 | Y50: XXXXX6 | AB50: 1234 | AD50: XXXXX6 | AG50: 12 | AI50: XXXXX6 | AL50: 1234 | AN50: XXXXX6 | AZ50: XXXXXXXXX1XXXXX6 | BG50: XXXXXXX8 | BK50: XXXXXXX8 | BO50: XXXXXXX8 | BS50: ☑ | BU50: ☑ | BW50: ☑ | BY50: ☑ | CA50: ☑ | CC50: ☑ | CO50: 2022/7/1 | CS50: 1234 | CU50: XXXXX6
D51: 2 | F51: 事前 | I51: 12345 | L51: XXXXXXXXX1XXXXX6 | S51: XXXXXXX8 | W51: 12 | Y51: XXXXX6 | AB51: 1234 | AD51: XXXXX6 | AG51: 12 | AI51: XXXXX6 | AL51: 1234 | AN51: XXXXX6 | AZ51: XXXXXXXXX1XXXXX6 | BG51: XXXXXXX8 | BK51: XXXXXXX8 | BO51: XXXXXXX8 | BS51: ☑ | BU51: ☑ | BW51: ☑ | BY51: ☑ | CA51: ☑ | CC51: ☑ | CO51: 2022/7/1 | CS51: 1234 | CU51: XXXXX6
D52: 3 | F52: 事前 | I52: 12345 | L52: XXXXXXXXX1XXXXX6 | S52: XXXXXXX8 | W52: 12 | Y52: XXXXX6 | AB52: 1234 | AD52: XXXXX6 | AG52: 12 | AI52: XXXXX6 | AL52: 1234 | AN52: XXXXX6 | AZ52: XXXXXXXXX1XXXXX6 | BG52: XXXXXXX8 | BK52: XXXXXXX8 | BO52: XXXXXXX8 | BS52: ☑ | BU52: ☑ | BW52: ☑ | BY52: ☑ | CA52: ☑ | CC52: ☑ | CE52: ☑ | CG52: ☑ | CI52: ☑ | CK52: ☑ | CM52: ☑ | CO52: 2022/7/1 | CS52: 1234 | CU52: XXXXX6
D53: 4 | F53: 事前 | I53: 12345 | L53: XXXXXXXXX1XXXXX6 | S53: XXXXXXX8 | W53: 12 | Y53: XXXXX6 | AB53: 1234 | AD53: XXXXX6 | AG53: 12 | AI53: XXXXX6 | AL53: 1234 | AN53: XXXXX6 | AZ53: XXXXXXXXX1XXXXX6 | BG53: XXXXXXX8 | BK53: XXXXXXX8 | BO53: XXXXXXX8 | CE53: ☑ | CG53: ☑ | CI53: ☑ | CK53: ☑ | CM53: ☑ | CO53: 2022/7/1 | CS53: 1234 | CU53: XXXXX6
D54: 5 | F54: 事前 | I54: 12345 | L54: XXXXXXXXX1XXXXX6 | S54: XXXXXXX8 | W54: 12 | Y54: XXXXX6 | AB54: 1234 | AD54: XXXXX6 | AG54: 12 | AI54: XXXXX6 | AL54: 1234 | AN54: XXXXX6 | AZ54: XXXXXXXXX1XXXXX6 | BG54: XXXXXXX8 | BK54: XXXXXXX8 | BO54: XXXXXXX8 | CE54: ☑ | CG54: ☑ | CI54: ☑ | CK54: ☑ | CM54: ☑ | CO54: 2022/7/1 | CS54: 1234 | CU54: XXXXX6
D55: 6 | F55: 本登録 | I55: 12345 | L55: YYYYYYYYY1XXXXX6 | S55: XXXXXXX8 | W55: 12 | Y55: XXXXX6 | AB55: 1234 | AD55: XXXXX6 | AG55: 12 | AI55: XXXXX6 | AL55: 1234 | AN55: XXXXX6 | AZ55: YYYYYYYYY1XXXXX6 | BG55: XXXXXX01 | BK55: XXXXXX01 | BO55: XXXXXX01 | CE55: ☑ | CG55: ☑ | CI55: ☑ | CK55: ☑ | CM55: ☑ | CO55: 2022/7/1 | CS55: 1234 | CU55: XXXXX6
...

Sheet 項目説明
A1: =表紙!A54 -> Webシステム | K1: 文書名 | U1: モジュールID | Z1: =表紙!$AJ$63 -> MS | AE1: モジュール名 | AJ1: =表紙!$AX$63 -> Webシステム | AS1: 文書番号 | AZ1: Version | BF1: Rev.
K2: =表紙!O64 -> アドオン設計書 | U2: ｻﾌﾞﾓｼﾞｭｰﾙID | Z2: =表紙!$AJ$64 -> MSBB | AE2: ｻﾌﾞﾓｼﾞｭｰﾙ名 | AJ2: =表紙!$AX$64 -> 販売Webシステム | AS2: =表紙!$BL$64 -> M7-US-1140 | AZ2: =表紙!$BU$64 -> 7.0.2 | BF2: =表紙!$CB$64 -> 2
K3: =RIGHT(CELL("filename",$A$1),LEN(CELL("filename",$A$1))-FIND("]",CELL("filename",$A$1))) -> 項目説明 | U3: 表題 | Z3: =表紙!$AJ$65 -> MSBBPA120 | AE3: =表紙!$AQ$65 -> Web取引先マスタ一覧照会
A5: 取引先マスタ一覧照会
B6: 抽出条件 | N6: 説明 | BE6: Ｗ | BF6: 型 | BG6: 参 | BH6: 必 | BI6: 入 | BJ6: 非 | BK6: 検
A7: 〇 | B7: 得意先 | M7: 抽出条件として、取引先が[得意先]の属性を持つ場合にチェックします | AS7: 初期値☑有 | BE7: チ | BF7: F
A8: 〇 | B8: 売掛先 | M8: 抽出条件として、取引先が[売掛先]の属性を持つ場合にチェックします | AS8: 初期値☑有 | BE8: チ | BF8: F
A9: 〇 | B9: 請求先 | M9: 抽出条件として、取引先が[請求先]の属性を持つ場合にチェックします | AS9: 初期値☑有 | BE9: チ | BF9: F
A10: 〇 | B10: 入金先 | M10: 抽出条件として、取引先が[入金先]の属性を持つ場合にチェックします | AS10: 初期値☑有 | BE10: チ | BF10: F
A11: 〇 | B11: 納品先 | M11: 抽出条件として、取引先が[納品先]の属性を持つ場合にチェックします | AS11: 初期値☑有 | BE11: チ | BF11: F
A12: 〇 | B12: 与信管理先 | M12: 抽出条件として、取引先が[与信管理先]の属性を持つ場合にチェックします | AS12: 初期値☑有 | BE12: チ | BF12: F
A13: 〇 | B13: 発注先 | M13: 抽出条件として、取引先が[発注先]の属性を持つ場合にチェックします | AS13: 初期値☑有 | BE13: チ | BF13: F
A14: 〇 | B14: 買掛先 | M14: 抽出条件として、取引先が[買掛先]の属性を持つ場合にチェックします | AS14: 初期値☑有 | BE14: チ | BF14: F
A15: 〇 | B15: 支払予定管理先 | M15: 抽出条件として、取引先が[支払予定管理先]の属性を持つ場合にチェックします | AS15: 初期値☑有 | BE15: チ | BF15: F
A16: 〇 | B16: 支払先 | M16: 抽出条件として、取引先が[支払先]の属性を持つ場合にチェックします | AS16: 初期値☑有 | BE16: チ | BF16: F
A17: 〇 | B17: メーカ | M17: 抽出条件として、取引先が[メーカ]の属性を持つ場合にチェックします | AS17: 初期値☑有 | BE17: チ | BF17: F
A18: 〇 | B18: 登録日(From) | M18: 抽出条件として、登録日(From)を入力する | BE18: カ | BF18: D
A19: 〇 | B19: 登録日(To) | M19: 抽出条件として、登録日(To)を入力する | BE19: カ | BF19: D
A20: 〇 | B20: 取引先 | M20: 抽出条件として、取引先を入力する | AZ20: あいまい検索可 | BE20: T | BF20: S
A21: 〇 | B21: 取引先名 | M21: 抽出条件として、取引先名を入力する | AZ21: あいまい検索可 | BE21: T | BF21: S
A22: 〇 | B22: 法人番号 | M22: 抽出条件として、法人番号を入力する | AZ22: あいまい検索可 | BE22: T | BF22: S | BM22: CP指摘 2022/10/20 本多 法人区分（0：法人 1：個人）にて区分けされた表示が必要です。現状、国税庁の法人番号を持たない取引先についてはCP独自で法人マスタへ採番しているためです。
A23: 〇 | B23: 法人番号区分 | M23: 抽出条件として、法人番号区分を入力する | AE23: 【MSBBPACOM】_共通設計書_アドオン(共通ロジック)にて定義 | BE23: C | BF23: S | BM23: MDSOL 野村 2022/10/25 条件追加しました
A24: 〇 | B24: 標準企業コード | M24: 抽出条件として、標準企業コードを入力する | AZ24: あいまい検索可 | BE24: T | BF24: S
A25: 〇 | B25: 郵便番号 | M25: 抽出条件として、郵便番号を入力する | AZ25: あいまい検索可 | BE25: T | BF25: S
A26: 〇 | B26: 住所 | M26: 抽出条件として、住所を入力する | AZ26: あいまい検索可 | BE26: T | BF26: S
A27: 〇 | B27: ＴＥＬ | M27: 抽出条件として、ＴＥＬを入力する | AZ27: あいまい検索可 | BE27: T | BF27: S
A28: 〇 | B28: ＦＡＸ | M28: 抽出条件として、ＦＡＸを入力する | AZ28: あいまい検索可 | BE28: T | BF28: S
A29: 〇 | B29: 地域CD | M29: 【MSBBPACOM】_共通設計書_アドオン(共通ロジック)にて定義 | BE29: C | BF29: S
A30: 〇 | B30: 営業担当WG | M30: 【MSBBPACOM】_共通設計書_アドオン(共通ロジック)にて定義 | BE30: C | BF30: S | BM30: Rev2.0 営業/業務担当WG 追加
B31: 営業担当WG名 | M31: 営業担当選択後に営業担当WG名がセットされる | BE31: T | BF31: S | BM31: Rev2.0 営業/業務担当WG 追加
A32: 〇 | B32: 営業担当 | M32: 【MSBBPACOM】_共通設計書_アドオン(共通ロジック)にて定義 | BE32: C | BF32: S | BK32: 検
B33: 営業担当名 | M33: 営業担当選択後に営業担当名がセットされる | BE33: T | BF33: S
A34: 〇 | B34: 業務担当WG | M34: 【MSBBPACOM】_共通設計書_アドオン(共通ロジック)にて定義 | BE34: C | BF34: S | BM34: Rev2.0 営業/業務担当WG 追加
B35: 業務担当WG名 | M35: 業務担当選択後に業務担当WG名がセットされる | BE35: T | BF35: S | BM35: Rev2.0 営業/業務担当WG 追加
A36: 〇 | B36: 業務担当 | M36: 【MSBBPACOM】_共通設計書_アドオン(共通ロジック)にて定義 | BE36: C | BF36: S | BK36: 検
B37: 業務担当名 | M37: 業務担当選択後に業務担当名がセットされる | BE37: T | BF37: S
A38: 〇 | B38: 取引先分類1 | M38: 【MSBBPACOM】_共通設計書_アドオン(共通ロジック)にて定義 | BE38: C | BF38: S
B39: 取引先分類名1 | M39: 取引先分類1選択後に取引先分類名1がセットされる | BE39: T | BF39: S
A40: 〇 | B40: 取引先分類2 | M40: 【MSBBPACOM】_共通設計書_アドオン(共通ロジック)にて定義 | BE40: C | BF40: S
B41: 取引先分類名2 | M41: 取引先分類2選択後に取引先分類名2がセットされる | BE41: T | BF41: S
...

Sheet 引数説明
A1: =表紙!A54 -> Webシステム | K1: 文書名 | U1: モジュールID | Z1: =表紙!$AJ$63 -> MS | AE1: モジュール名 | AJ1: =表紙!$AX$63 -> Webシステム | AS1: 文書番号 | AZ1: Version | BF1: Rev.
K2: =表紙!O64 -> アドオン設計書 | U2: ｻﾌﾞﾓｼﾞｭｰﾙID | Z2: =表紙!$AJ$64 -> MSBB | AE2: ｻﾌﾞﾓｼﾞｭｰﾙ名 | AJ2: =表紙!$AX$64 -> 販売Webシステム | AS2: =表紙!$BL$64 -> M7-US-1140 | AZ2: =表紙!$BU$64 -> 7.0.2 | BF2: =表紙!$CB$64 -> 2
K3: =RIGHT(CELL("filename",$A$1),LEN(CELL("filename",$A$1))-FIND("]",CELL("filename",$A$1))) -> 引数説明 | U3: 表題 | Z3: =表紙!$AJ$65 -> MSBBPA120 | AE3: =表紙!$AQ$65 -> Web取引先マスタ一覧照会
B5: オペレーションＩＤ/名称：SloRecvIfImp_Upd01/取込
A6: 必 | B6: 項目名 | N6: 説明 | AS6: 未設定時の振る舞い

Sheet 画面遷移
A1: =表紙!A54 -> Webシステム | K1: 文書名 | U1: モジュールID | Z1: =表紙!$AJ$63 -> MS | AE1: モジュール名 | AJ1: =表紙!$AX$63 -> Webシステム | AS1: 文書番号 | AZ1: Version | BF1: Rev.
K2: =表紙!O64 -> アドオン設計書 | U2: ｻﾌﾞﾓｼﾞｭｰﾙID | Z2: =表紙!$AJ$64 -> MSBB | AE2: ｻﾌﾞﾓｼﾞｭｰﾙ名 | AJ2: =表紙!$AX$64 -> 販売Webシステム | AS2: =表紙!$BL$64 -> M7-US-1140 | AZ2: =表紙!$BU$64 -> 7.0.2 | BF2: =表紙!$CB$64 -> 2
K3: =RIGHT(CELL("filename",$A$1),LEN(CELL("filename",$A$1))-FIND("]",CELL("filename",$A$1))) -> 画面遷移 | U3: 表題 | Z3: =表紙!$AJ$65 -> MSBBPA120 | AE3: =表紙!$AQ$65 -> Web取引先マスタ一覧照会
A5: 画面遷移フロー図
A6: ＩＤ | C6: S01 | E6: Web取引先マスタ一覧照会から他画面の画面遷移
D10: NO1
D11: Web汎用検索(共通検索) | R11: Web取引先マスタ一覧照会
AD14: ※Web取引先マスタ側で記述
AD15: Web取引先マスタ(検索)
A20: ID | D20: 処理名
A21: S01 | D21: メニューから本画面遷移
B23: 遷移処理
B24: 遷移元画面ＩＤ | I24: なし
B25: 遷移元画面名 | I25: メニュー
B26: 遷移先画面ＩＤ | I26: MSBBPA120
B27: 遷移先画面名 | I27: Web取引先マスタ一覧照会
B28: 遷移条件
B29: 引継項目・種別 | I29: 遷移元画面項目 | AJ29: 遷移先画面項目
I30: なし | AK30: なし
B33: 遷移後のアクション | I33: 検索
B34: 備考

Sheet 処理概要
A1: =表紙!A54 -> Webシステム | K1: 文書名 | U1: モジュールID | Z1: =表紙!$AJ$63 -> MS | AE1: モジュール名 | AJ1: =表紙!$AX$63 -> Webシステム | AS1: 文書番号 | AZ1: Version | BF1: Rev.
K2: =表紙!O64 -> アドオン設計書 | U2: ｻﾌﾞﾓｼﾞｭｰﾙID | Z2: =表紙!$AJ$64 -> MSBB | AE2: ｻﾌﾞﾓｼﾞｭｰﾙ名 | AJ2: =表紙!$AX$64 -> 販売Webシステム | AS2: =表紙!$BL$64 -> M7-US-1140 | AZ2: =表紙!$BU$64 -> 7.0.2 | BF2: =表紙!$CB$64 -> 2
K3: =RIGHT(CELL("filename",$A$1),LEN(CELL("filename",$A$1))-FIND("]",CELL("filename",$A$1))) -> 処理概要 | U3: 表題 | Z3: =表紙!$AJ$65 -> MSBBPA120 | AE3: =表紙!$AQ$65 -> Web取引先マスタ一覧照会
A5: No | B5: 入力 | J5: 処理 | BD5: 出力
A6: 1 | B6: 初期表示
J7: 1.処理概要
K8: 初期表示
L9: 得意先～メーカ | R9: ： | S9: 初期は全チェック
L10: 登録日 | R10: ： | S10: 登録日Fromに当日 - ログインマスタ.初期表示をセット、Toに当日をセットする
L11: ステータス | R11: ： | S11: 初期は全チェック
L12: 表示処理 | R12: ： | S12: 抽出条件をもとに取引先マスタ一覧に結果を表示する | BD12: 検索入出力仕様.NO1
L14: フッターボタン表示・非表示切替
M15: メニューから呼び出された場合(照会画面モード) | AC15: ・・・ | AE15: 選択ボタンを非表示とする
M16: 検索画面として呼び出された場合(検索画面モード) | AC16: ・・・ | AE16: 選択ボタンを表示とする
M17: 例)検索画面モード:Web取引先マスタから検索画面として呼び出され、選択行を返す場合
A19: 2 | B19: 画面操作
J20: 1.処理概要
K21: ボタン処理
L22: クリアボタン押下 | U22: ： | V22: 画面を初期化する(起動時の状態とする)
L24: 表示ボタン押下 | U24: ： | V24: チェック処理にてエラーとなった場合、後続処理をキャンセルする
L25: (チェック処理) | W25: FROM～TOの整合性チェック | AH25: … | AI25: エラーメッセージ：FROM≦TOの関係で指定してください。 | BD25: メッセージID.001
W26: チェックボックスチェック有無 | AH26: … | AI26: エラーメッセージ：いずれかを選択してください。 | BD26: メッセージID.002
L28: 表示ボタン押下 | U28: ： | V28: 抽出条件をもとに取引先マスタ一覧に結果を表示する | BD28: 検索入出力仕様.NO1
W29: データ取得できなかった場合、下記メッセージを表示
W30: エラーメッセージ：検索結果がありません。 | BD30: メッセージID.003
L32: CSV出力 | U32: ： | V32: 取引先マスタ一覧のデータをCSV出力する | BD32: ファイル入出力仕様.NO1
U33: ※1 CSV出力定義とファイル名は、【MSBBPACOM】_共通設計書_アドオン(共通ロジック)にて定義
U34: ※2 画面に表示されたデータがCSVとして出力される
L36: 選択 | U36: ： | V36: 検索モードで開いた場合に選択結果(1行)を遷移元画面に返す
W37: 一覧にデータが無いもしくは対象行が選択されてない場合、下記メッセージを表示
W38: エラーメッセージ：選択行がありません。 | BD38: メッセージID.004
U39: ※1 選択された取引先マスタの1レコードを呼出元に返す
U40: ※2 複数選択は許可しない

Sheet 処理詳細
A1: =表紙!A54 -> Webシステム | K1: 文書名 | U1: モジュールID | Z1: =表紙!$AJ$63 -> MS | AE1: モジュール名 | AJ1: =表紙!$AX$63 -> Webシステム | AS1: 文書番号 | AZ1: Version | BF1: Rev.
K2: =表紙!O64 -> アドオン設計書 | U2: ｻﾌﾞﾓｼﾞｭｰﾙID | Z2: =表紙!$AJ$64 -> MSBB | AE2: ｻﾌﾞﾓｼﾞｭｰﾙ名 | AJ2: =表紙!$AX$64 -> 販売Webシステム | AS2: =表紙!$BL$64 -> M7-US-1140 | AZ2: =表紙!$BU$64 -> 7.0.2 | BF2: =表紙!$CB$64 -> 2
K3: =RIGHT(CELL("filename",$A$1),LEN(CELL("filename",$A$1))-FIND("]",CELL("filename",$A$1))) -> 処理詳細 | U3: 表題 | Z3: =表紙!$AJ$65 -> MSBBPA120 | AE3: =表紙!$AQ$65 -> Web取引先マスタ一覧照会
A5: No | B5: 入力 | J5: 処理 | BD5: 出力
A6: 1 | B6: 初期表示
J7: 1.1 | L7: 処理概要参照
A10: ２ | B10: 画面操作
J11: 2.1 | L11: 処理概要参照
A14: 3 | B14: 検索
J15: 3.1 | L15: コンボボックスの初期化
L16: 営業担当WGコンボボックスの初期化
M17: ※ | N17: 営業担当WG検索_SQLリソースの検索仕様
N18: 【MSBBPACOM】_共通設計書_アドオン(Web共通ロジック)の「処理詳細(共通検索)」シート」を参照する。
L20: 業務担当WGコンボボックスの初期化
M21: ※ | N21: 業務担当WG検索_SQLリソースの検索仕様
N22: 【MSBBPACOM】_共通設計書_アドオン(Web共通ロジック)の「処理詳細(共通検索)」シート」を参照する。
L24: 営業担当者コンボボックスの初期化
M25: ※ | N25: 営業担当者検索_SQLリソースの検索仕様
N26: 【MSBBPACOM】_共通設計書_アドオン(Web共通ロジック)の「処理詳細(共通検索)」シート」を参照する。
L28: 業務担当者コンボボックスの初期化
M29: ※ | N29: 業務担当者検索_SQLリソースの検索仕様
N30: 【MSBBPACOM】_共通設計書_アドオン(Web共通ロジック)の「処理詳細(共通検索)」シート」を参照する。
L32: 取引先分類1～10コンボボックスの初期化
M33: ※ | N33: 取引先分類1～10検索_SQLリソースの検索仕様
N34: 【MSBBPACOM】_共通設計書_アドオン(Web共通ロジック)の「処理詳細(共通検索)」シート」を参照する。
L36: 法人番号区分コンボボックスの初期化
M37: ※ | N37: 法人番号区分検索_SQLリソースの検索仕様
N38: 【MSBBPACOM】_共通設計書_アドオン(Web共通ロジック)の「処理詳細(共通検索)」シート」を参照する。
L40: 地域コードコンボボックスの初期化
M41: ※ | N41: 地域コード検索_SQLリソースの検索仕様
N42: 【MSBBPACOM】_共通設計書_アドオン(Web共通ロジック)の「処理詳細(共通検索)」シート」を参照する。
J44: 3.2 | L44: 表示の検索ボタン処理
L45: 3.2.1 | N45: 入力チェック
N46: FROM～TOの整合性チェック：チェックエラーの場合 メッセージを表示する | BD46: メッセージNo.001
N47: チェックボックスチェック有無：チェックエラーの場合 メッセージを表示する | BD47: メッセージNo.002
L49: 3.2.2 | N49: 抽出条件をもとにWeb取引先マスタ一覧照会に結果を表示する | BD49: 検索入出力仕様.No1
N50: 検索結果が0件の場合、メッセージを表示する | BD50: メッセージNo.003
N51: 検索結果が0件の以外の場合、
N53: Web取引先マスタ一覧照会検索_SQLリソースの検索仕様
P54: 【対象テーブル】
...

Sheet 処理・サービス関連図
A1: =表紙!A54 -> Webシステム | K1: 文書名 | U1: モジュールID | Z1: =表紙!$AJ$63 -> MS | AE1: モジュール名 | AJ1: =表紙!$AX$63 -> Webシステム | AS1: 文書番号 | AZ1: Version | BF1: Rev.
K2: =表紙!O64 -> アドオン設計書 | U2: ｻﾌﾞﾓｼﾞｭｰﾙID | Z2: =表紙!$AJ$64 -> MSBB | AE2: ｻﾌﾞﾓｼﾞｭｰﾙ名 | AJ2: =表紙!$AX$64 -> 販売Webシステム | AS2: =表紙!$BL$64 -> M7-US-1140 | AZ2: =表紙!$BU$64 -> 7.0.2 | BF2: =表紙!$CB$64 -> 2
K3: =RIGHT(CELL("filename",$A$1),LEN(CELL("filename",$A$1))-FIND("]",CELL("filename",$A$1))) -> 処理・サービス関連図 | U3: 表題 | Z3: =表紙!$AJ$65 -> MSBBPA120 | AE3: =表紙!$AQ$65 -> Web取引先マスタ一覧照会
C7: 検索処理

Sheet 検索入出力仕様
A1: =表紙!A54 -> Webシステム | K1: 文書名 | U1: モジュールID | Z1: =表紙!$AJ$63 -> MS | AE1: モジュール名 | AJ1: =表紙!$AX$63 -> Webシステム | AS1: 文書番号 | AZ1: Version | BF1: Rev.
K2: =表紙!O64 -> アドオン設計書 | U2: ｻﾌﾞﾓｼﾞｭｰﾙID | Z2: =表紙!$AJ$64 -> MSBB | AE2: ｻﾌﾞﾓｼﾞｭｰﾙ名 | AJ2: =表紙!$AX$64 -> 販売Webシステム | AS2: =表紙!$BL$64 -> M7-US-1140 | AZ2: =表紙!$BU$64 -> 7.0.2 | BF2: =表紙!$CB$64 -> 2
K3: =RIGHT(CELL("filename",$A$1),LEN(CELL("filename",$A$1))-FIND("]",CELL("filename",$A$1))) -> 検索入出力仕様 | U3: 表題 | Z3: =表紙!$AJ$65 -> MSBBPA120 | AE3: =表紙!$AQ$65 -> Web取引先マスタ一覧照会
A5: No | G5: 1 | S5: ボタン | Z5: 表示 | AH5: 備考 | AK5: 表示ボタンクリック時処理
A6: 処理分類 | E6: 検索 | S6: ソート順 | Z6: 取引先コード
A7: No | C7: 転送先 | V7: 転送元 | AQ7: 説明
C8: 種 | D8: オブジェクト | K8: 項目名 | V8: 種 | W8: オブジェクト | AF8: 項目名
A9: 1 | C9: 画 | D9: 取引先マスタ一覧 | K9: № | AF9: 行番
A10: 2 | C10: 画 | D10: 取引先マスタ一覧 | K10: ステータス | V10: T | W10: 取引先マスタ | AF10: ステータス
A11: 3 | C11: 画 | D11: 取引先マスタ一覧 | K11: 取引先 | V11: T | W11: 取引先マスタ | AF11: 取引先
A12: 4 | C12: 画 | D12: 取引先マスタ一覧 | K12: 取引先名 | V12: T | W12: 取引先マスタ | AF12: 取引先名
A13: 5 | C13: 画 | D13: 取引先マスタ一覧 | K13: 取引先別名１ | V13: T | W13: 取引先マスタ | AF13: 取引先別名１
A14: 6 | C14: 画 | D14: 取引先マスタ一覧 | K14: 法人番号 | V14: T | W14: 取引先マスタ | AF14: 法人番号
A15: 7 | C15: 画 | D15: 取引先マスタ一覧 | K15: 標準企業コード | V15: T | W15: 取引先マスタ | AF15: 標準企業コード
A16: 8 | C16: 画 | D16: 取引先マスタ一覧 | K16: 営業担当WG | V16: T | W16: 担当者権限/部門 | AF16: 営業担当WG | AQ16: 現時点での営業担当の主部門のWG | BM16: Rev2.0 営業/業務担当WG 追加
A17: 9 | C17: 画 | D17: 取引先マスタ一覧 | K17: 営業担当WG名 | V17: T | W17: WGマスタ | AF17: WG名 | BM17: Rev2.0 営業/業務担当WG 追加
A18: 10 | C18: 画 | D18: 取引先マスタ一覧 | K18: 営業担当 | V18: T | W18: 得意先担当マスタ | AF18: 担当者コード | AQ18: 現時点での営業担当：得意先担当マスタを参照
A19: 11 | C19: 画 | D19: 取引先マスタ一覧 | K19: 営業担当者名 | V19: T | W19: 担当者 | AF19: 担当者名
A20: 12 | C20: 画 | D20: 取引先マスタ一覧 | K20: 業務担当WG | V20: T | W20: 担当者権限/部門 | AF20: 業務担当WG | AQ20: 現時点での業務担当の主部門のWG | BM20: Rev2.0 営業/業務担当WG 追加
A21: 13 | C21: 画 | D21: 取引先マスタ一覧 | K21: 業務担当WG名 | V21: T | W21: WGマスタ | AF21: WG名 | BM21: Rev2.0 営業/業務担当WG 追加
A22: 14 | C22: 画 | D22: 取引先マスタ一覧 | K22: 業務担当 | V22: T | W22: 取引先マスタ | AF22: 業務担当
A23: 15 | C23: 画 | D23: 取引先マスタ一覧 | K23: 業務担当者名 | V23: T | W23: 担当者 | AF23: 担当者名
A24: 16 | C24: 画 | D24: 取引先マスタ一覧 | K24: 住所１ | V24: T | W24: 取引先マスタ | AF24: 住所１
A25: 17 | C25: 画 | D25: 取引先マスタ一覧 | K25: 住所２ | V25: T | W25: 取引先マスタ | AF25: 住所２
A26: 18 | C26: 画 | D26: 取引先マスタ一覧 | K26: 住所３ | V26: T | W26: 取引先マスタ | AF26: 住所３
A27: 19 | C27: 画 | D27: 取引先マスタ一覧 | K27: 住所４ | V27: T | W27: 取引先マスタ | AF27: 住所４
A28: 20 | C28: 画 | D28: 取引先マスタ一覧 | K28: 得意先 | V28: T | W28: 取引先マスタ | AF28: 得意先有効ＦＬＧ
A29: 21 | C29: 画 | D29: 取引先マスタ一覧 | K29: 売掛先 | V29: T | W29: 取引先マスタ | AF29: 売掛先有効ＦＬＧ
A30: 22 | C30: 画 | D30: 取引先マスタ一覧 | K30: 請求先 | V30: T | W30: 取引先マスタ | AF30: 請求先有効ＦＬＧ
A31: 23 | C31: 画 | D31: 取引先マスタ一覧 | K31: 入金先 | V31: T | W31: 取引先マスタ | AF31: 入金先有効ＦＬＧ
A32: 24 | C32: 画 | D32: 取引先マスタ一覧 | K32: 納品先 | V32: T | W32: 取引先マスタ | AF32: 納品先有効ＦＬＧ
A33: 25 | C33: 画 | D33: 取引先マスタ一覧 | K33: 与信管理先 | V33: T | W33: 取引先マスタ | AF33: 与信管理先
... A41: 33 | C41: 画 | D41: 取引先マスタ一覧 | K41: 登録担当者名 | V41: T | W41: 担当者 | AF41: 担当者名

Sheet 更新入出力仕様
A1: =表紙!A54 -> Webシステム | K1: 文書名 | U1: モジュールID | Z1: =表紙!$AJ$63 -> MS | AE1: モジュール名 | AJ1: =表紙!$AX$63 -> Webシステム | AS1: 文書番号 | AZ1: Version | BF1: Rev.
K2: =表紙!O64 -> アドオン設計書 | U2: ｻﾌﾞﾓｼﾞｭｰﾙID | Z2: =表紙!$AJ$64 -> MSBB | AE2: ｻﾌﾞﾓｼﾞｭｰﾙ名 | AJ2: =表紙!$AX$64 -> 販売Webシステム | AS2: =表紙!$BL$64 -> M7-US-1140 | AZ2: =表紙!$BU$64 -> 7.0.2 | BF2: =表紙!$CB$64 -> 2
K3: =RIGHT(CELL("filename",$A$1),LEN(CELL("filename",$A$1))-FIND("]",CELL("filename",$A$1))) -> 更新入出力仕様 | U3: 表題 | Z3: =表紙!$AJ$65 -> MSBBPA120 | AE3: =表紙!$AQ$65 -> Web取引先マスタ一覧照会
A5: No | G5: 1 | S5: ロジック名称 | AH5: 備考
A6: 処理分類 | E6: 更新
A7: No | C7: 転送先 | V7: 転送元 | AQ7: 説明
C8: 種 | D8: オブジェクト | K8: 項目名 | V8: 種 | W8: オブジェクト | AF8: 項目名

Sheet ファイル入出力仕様
A1: =表紙!A54 -> Webシステム | K1: 文書名 | U1: モジュールID | Z1: =表紙!$AJ$63 -> MS | AE1: モジュール名 | AJ1: =表紙!$AX$63 -> Webシステム | AS1: 文書番号 | AZ1: Version | BF1: Rev.
K2: =表紙!O64 -> アドオン設計書 | U2: ｻﾌﾞﾓｼﾞｭｰﾙID | Z2: =表紙!$AJ$64 -> MSBB | AE2: ｻﾌﾞﾓｼﾞｭｰﾙ名 | AJ2: =表紙!$AX$64 -> 販売Webシステム | AS2: =表紙!$BL$64 -> M7-US-1140 | AZ2: =表紙!$BU$64 -> 7.0.2 | BF2: =表紙!$CB$64 -> 2
K3: =RIGHT(CELL("filename",$A$1),LEN(CELL("filename",$A$1))-FIND("]",CELL("filename",$A$1))) -> ファイル入出力仕様 | U3: 表題 | Z3: =表紙!$AJ$65 -> MSBBPA120 | AE3: =表紙!$AQ$65 -> Web取引先マスタ一覧照会
A5: No | G5: 1 | S5: ロジック名称 | Z5: ファイル出力 | AH5: 備考
A6: 処理分類 | E6: ファイル出力 | S6: ソート順
A7: No | C7: 転送先 | V7: 転送元 | AQ7: 説明
C8: 種 | D8: オブジェクト | K8: 項目名 | V8: 種 | W8: オブジェクト | AF8: 項目名
A9: 1 | C9: フ | D9: 取引先マスタ一覧 | K9: № | V9: 画 | W9: 取引先マスタ一覧 | AF9: №
A10: 2 | C10: フ | D10: 取引先マスタ一覧 | K10: ステータス | V10: 画 | W10: 取引先マスタ一覧 | AF10: ステータス
A11: 3 | C11: フ | D11: 取引先マスタ一覧 | K11: 取引先 | V11: 画 | W11: 取引先マスタ一覧 | AF11: 取引先
A12: 4 | C12: フ | D12: 取引先マスタ一覧 | K12: 取引先名 | V12: 画 | W12: 取引先マスタ一覧 | AF12: 取引先名
A13: 5 | C13: フ | D13: 取引先マスタ一覧 | K13: 取引先別名１ | V13: 画 | W13: 取引先マスタ一覧 | AF13: 取引先別名１
A14: 6 | C14: フ | D14: 取引先マスタ一覧 | K14: 法人番号 | V14: 画 | W14: 取引先マスタ一覧 | AF14: 法人番号
A15: 7 | C15: フ | D15: 取引先マスタ一覧 | K15: 標準企業コード | V15: 画 | W15: 取引先マスタ一覧 | AF15: 標準企業コード
A16: 8 | C16: フ | D16: 取引先マスタ一覧 | K16: 営業担当WG | V16: 画 | W16: 取引先マスタ一覧 | AF16: 営業担当WG | BM16: Rev2.0 営業/業務担当WG 追加
A17: 9 | C17: フ | D17: 取引先マスタ一覧 | K17: 営業担当WG名 | V17: 画 | W17: 取引先マスタ一覧 | AF17: WG名 | BM17: Rev2.0 営業/業務担当WG 追加
A18: 10 | C18: フ | D18: 取引先マスタ一覧 | K18: 営業担当 | V18: 画 | W18: 取引先マスタ一覧 | AF18: 営業担当
A19: 11 | C19: フ | D19: 取引先マスタ一覧 | K19: 営業担当者名 | V19: 画 | W19: 取引先マスタ一覧 | AF19: 営業担当者名
A20: 12 | C20: フ | D20: 取引先マスタ一覧 | K20: 業務担当WG | V20: 画 | W20: 取引先マスタ一覧 | AF20: 業務担当WG | BM20: Rev2.0 営業/業務担当WG 追加
A21: 13 | C21: フ | D21: 取引先マスタ一覧 | K21: 業務担当WG名 | V21: 画 | W21: 取引先マスタ一覧 | AF21: WG名 | BM21: Rev2.0 営業/業務担当WG 追加
A22: 14 | C22: フ | D22: 取引先マスタ一覧 | K22: 業務担当 | V22: 画 | W22: 取引先マスタ一覧 | AF22: 業務担当
A23: 15 | C23: フ | D23: 取引先マスタ一覧 | K23: 業務担当者名 | V23: 画 | W23: 取引先マスタ一覧 | AF23: 業務担当者名
A24: 16 | C24: フ | D24: 取引先マスタ一覧 | K24: 住所１ | V24: 画 | W24: 取引先マスタ一覧 | AF24: 住所１
A25: 17 | C25: フ | D25: 取引先マスタ一覧 | K25: 住所２ | V25: 画 | W25: 取引先マスタ一覧 | AF25: 住所２
A26: 18 | C26: フ | D26: 取引先マスタ一覧 | K26: 住所３ | V26: 画 | W26: 取引先マスタ一覧 | AF26: 住所３
A27: 19 | C27: フ | D27: 取引先マスタ一覧 | K27: 住所４ | V27: 画 | W27: 取引先マスタ一覧 | AF27: 住所４
A28: 20 | C28: フ | D28: 取引先マスタ一覧 | K28: 得意先 | V28: 画 | W28: 取引先マスタ一覧 | AF28: 得意先
A29: 21 | C29: フ | D29: 取引先マスタ一覧 | K29: 売掛先 | V29: 画 | W29: 取引先マスタ一覧 | AF29: 売掛先
A30: 22 | C30: フ | D30: 取引先マスタ一覧 | K30: 請求先 | V30: 画 | W30: 取引先マスタ一覧 | AF30: 請求先
A31: 23 | C31: フ | D31: 取引先マスタ一覧 | K31: 入金先 | V31: 画 | W31: 取引先マスタ一覧 | AF31: 入金先
A32: 24 | C32: フ | D32: 取引先マスタ一覧 | K32: 納品先 | V32: 画 | W32: 取引先マスタ一覧 | AF32: 納品先
A33: 25 | C33: フ | D33: 取引先マスタ一覧 | K33: 与信管理先 | V33: 画 | W33: 取引先マスタ一覧 | AF33: 与信管理先
... A41: 33 | C41: フ | D41: 取引先マスタ一覧 | K41: 登録担当者名 | V41: 画 | W41: 取引先マスタ一覧 | AF41: 登録担当者名

Sheet メッセージ一覧
A1: =表紙!A54 -> Webシステム | K1: 文書名 | U1: モジュールID | Z1: =表紙!$AJ$63 -> MS | AE1: モジュール名 | AJ1: =表紙!$AX$63 -> Webシステム | AS1: 文書番号 | AZ1: Version | BF1: Rev.
K2: =表紙!O64 -> アドオン設計書 | U2: ｻﾌﾞﾓｼﾞｭｰﾙID | Z2: =表紙!$AJ$64 -> MSBB | AE2: ｻﾌﾞﾓｼﾞｭｰﾙ名 | AJ2: =表紙!$AX$64 -> 販売Webシステム | AS2: =表紙!$BL$64 -> M7-US-1140 | AZ2: =表紙!$BU$64 -> 7.0.2 | BF2: =表紙!$CB$64 -> 2
K3: =RIGHT(CELL("filename",$A$1),LEN(CELL("filename",$A$1))-FIND("]",CELL("filename",$A$1))) -> メッセージ一覧 | U3: 表題 | Z3: =表紙!$AJ$65 -> MSBBPA120 | AE3: =表紙!$AQ$65 -> Web取引先マスタ一覧照会
C4: ↓アドオン画面のため、基本全て[新]
A5: No | C5: 新/変 | E5: 種別 | G5: メッセージ内容 | AQ5: 備考（パラメータ等） | BG5: メッセージID
A6: 1 | C6: 新 | E6: W | G6: 「FROM≦TOの関係で指定してください。項目名：{1} 」 | AQ6: 登録日 | BG6: E10036 | BM6: メッセージID.001
A7: 2 | C7: 新 | E7: W | G7: 「いずれかを選択してください。項目名：{1} 」 | AQ7: 取引先属性(得意先、売掛先等) | BG7: E10030 | BM7: メッセージID.002
A8: 3 | C8: 新 | E8: W | G8: 「検索結果がありません。」 | BG8: E10008 | BM8: メッセージID.003
A9: 4 | C9: 新 | E9: W | G9: 「選択行がありません。」 | BG9: E10009 | BM9: メッセージID.004

Sheet 補足説明資料
A1: =表紙!A54 -> Webシステム | O1: 文書名 | AC1: モジュールID | AJ1: =表紙!AJ64 -> MSBB | AQ1: モジュール名 | AX1: =表紙!AX64 -> 販売Webシステム | BL1: 文書番号 | BU1: Version | CB1: Rev.
O2: =表紙!O65 -> 表紙 | AC2: サブモジュールID | AJ2: =表紙!AJ65 -> MSBBPA120 | AQ2: サブモジュール名 | AX2: =表紙!AX65 -> 0 | BL2: =表紙!BL65 -> 0 | BU2: =表紙!BU65 -> 0 | CB2: =表紙!CB65 -> 0
O3: =RIGHT(CELL("filename",$A$1),LEN(CELL("filename",$A$1))-FIND("]",CELL("filename",$A$1))) -> 補足説明資料 | AC3: 表題 | AJ3: =表紙!AJ66 -> 0 | AQ3: =表紙!AQ66 -> 0
AO5: 補足説明
