Workbook
Name 工程: 説明書!$J$3:$J$11
Name 工程: レビューシート!$J$3:$J$11

Sheet 改訂履歴
A1: 査読レビューシート （改訂履歴）
A3: 改定日 | C3: 番号 | D3: 改訂内容/理由
A4: 41165 | B4: Ver. 1.0 | C4: 1 | D4: 新規制定
A6: 41198 | B6: Ver. 1.1 | C6: 1 | D6: レビュー日、レビューアの項目を見出し部から明細部へ移動。
C7: 2 | D7: 顧客名を追加。
D8: 作込工程を社規40100システム開発規定に合せて見直し。
A10: 41302 | B10: Ver. 1.2 | C10: 1 | D10: Excel2010保存時の互換性チェックエラーの対応。
D11: ・入力規則のリストを名前定義での参照に変更。
D12: （対象項目：作込工程）
A14: 41333 | B14: Ver. 1.3 | C14: 1 | D14: 結合列の廃止。
D15: ・複数列での結合を止めて、単列での項目としセル高の
D16: Excel自動調整可とする。
D17: （対象項目：指摘事項、回答）
A19: 41346 | B19: Ver. 1.4 | C19: 1 | D19: 書式設定（行の高さの自動調整）再定義。
D20: ・明細行の書式を再定義。
D21: （指摘事項の初期値を空改行２行とする）
A23: 41369 | B23: Ver. 1.5 | C23: 1 | D23: 作込工程への集計不具合を修正。
A25: 41883 | B25: Ver. 1.6 | C25: 1 | D25: Excel拡張子変更の対応（.xls→.xlsx）
A27: 42445 | B27: Ver. 1.7 | C27: 1 | D27: レビュー回答工数を追加。
C28: 2 | D28: 実施日、回答日の表示形式「yy/m/d」指定
A30: 42825 | B30: Ver. 1.8 | C30: 1 | D30: 作込工程を変更。
D31: ・項目見出しを以下のように変更
E32: [変更後] | G32: [変更前]
E33: プロ計画 | G33: プロ計画
E34: 要件定義 | G34: 要件定義
E35: 基本設計 | G35: 基本設計
E36: 詳細設計 | G36: 詳細設計
E37: プロ設計 | G37: プロ設計
E38: 製作 | G38: 製作
E39: 試験 | G39: 導入運用
E40: その他 | G40: 移行
D41: ※ | E41: 運用移行保守 | G41: 保守
D43: ※インストールマニュアル、操作説明書、移行手順書、保守マニュアル等の
D44: ドキュメントをレビュー時に用いる。
A46: 42916 | B46: Ver. 1.9 | C46: 1 | D46: ドキュメント頁数の追加。
D47: ・レビュー対象ドキュメントの頁数を記入する欄を追加。
A49: 43217 | B49: Ver. 2.0 | C49: 1 | D49: 確認欄の見出し変更。
D50: ・[変更後]確認日、確認者
D51: [変更前]確認
A53: 43236 | B53: Ver. 2.1 | C53: 1 | D53: 2018年度アクションプラン「ＩSMSに準じた社規・様式の機密等級表示変更」にて
...

Sheet レビューシート
F1: レビューシート | J1: 43677 | K1: Ver.2.3
C3: 顧客名 | D3: 株式会社クラウン・パッケージ | I3: 作込工程 | J3: プロ計画 | K3: =SUMPRODUCT(($J$15:$J$40=$J3)*($I$15:$I$40="")) -> 0
C4: プロジェクト名 | D4: 新基幹システム導入 | J4: 要件定義 | K4: =SUMPRODUCT(($J$15:$J$40=$J4)*($I$15:$I$40="")) -> 0
C5: ドキュメント名 | J5: 基本設計 | K5: =SUMPRODUCT(($J$15:$J$40=$J5)*($I$15:$I$40="")) -> 0
C6: ドキュメント頁数 | J6: 詳細設計 | K6: =SUMPRODUCT(($J$15:$J$40=$J6)*($I$15:$I$40="")) -> 0
J7: プロ設計 | K7: =SUMPRODUCT(($J$15:$J$40=$J7)*($I$15:$I$40="")) -> 0
C8: レビュー指摘工数 | J8: 製作 | K8: =SUMPRODUCT(($J$15:$J$40=$J8)*($I$15:$I$40="")) -> 0
C9: レビュー回答工数 | J9: 試験要領 | K9: =SUMPRODUCT(($J$15:$J$40=$J9)*($I$15:$I$40="")) -> 0
C10: レビュー確認工数 | J10: その他 | K10: =SUMPRODUCT(($J$15:$J$40=$J10)*($I$15:$I$40="")) -> 0
C11: 実施工数(Hr) | D11: =SUM(D8:D10) -> 0 | J11: 運用移行保守 | K11: =SUMPRODUCT(($J$15:$J$40=$J11)*($I$15:$I$40="")) -> 0
J12: 計 | K12: =SUM(K3:K11) -> 0
A14: No | B14: 頁 | C14: 指摘事項 | D14: 実施日 (ﾚﾋﾞｭｰ日) | E14: 実施者 (ﾚﾋﾞｭｰｱ) | F14: 回 答 | G14: 回答日 | H14: 回答者 | I14: 対象外 | J14: 作込工程 | K14: 確認日 確認者
A15: 1 | C15: MSBBPA090.xmlに、 １．ROWNUM代わって、ROW_NUMBER()を利用ください。 | D15: 44963 | E15: 韓 | F15: ご対応しました。 | G15: 44992 | H15: 王
A16: 2 | C16: MSBBPA090Serviceにトランザクション処理を追加ください。 | D16: 44963 | E16: 韓 | F16: ご対応しました。 | G16: 44992 | H16: 王
A17: 3 | C17: Id=>RowIdにしてください。 | D17: 44963 | E17: 韓 | F17: ご対応しました。 | G17: 44992 | H17: 王
A18: 4 | C18: if (dto.Model.Amt_On == true) ＝＞if (dto.Model.Amt_On)にしてください。 | D18: 44963 | E18: 韓 | F18: ご対応しました。 | G18: 44992 | H18: 王
A19: 5
A20: 6
A21: 7
A22: 8
A23: 9
A24: 10
A25: 11
A26: 12
A27: 13
A28: 14
A29: 15
A30: 16
... A39: 25
A40: ※
A41: 明細の追加は、※行をコピーして、※行より上に挿入して下さい。

Sheet 説明書
F1: レビューシート | J1: =レビューシート!J1 -> 43677 | K1: =レビューシート!K1 -> Ver.2.3
C3: 顧客名 | I3: 作込工程 | J3: =レビューシート!J3 -> プロ計画 | K3: =SUMPRODUCT(($J$15:$J$40=$J3)*($I$15:$I$40="")) -> 0
C4: プロジェクト名 | J4: =レビューシート!J4 -> 要件定義 | K4: =SUMPRODUCT(($J$15:$J$40=$J4)*($I$15:$I$40="")) -> 0
C5: ドキュメント名 | J5: =レビューシート!J5 -> 基本設計 | K5: =SUMPRODUCT(($J$15:$J$40=$J5)*($I$15:$I$40="")) -> 0
C6: ドキュメント頁数 | J6: =レビューシート!J6 -> 詳細設計 | K6: =SUMPRODUCT(($J$15:$J$40=$J6)*($I$15:$I$40="")) -> 0
J7: =レビューシート!J7 -> プロ設計 | K7: =SUMPRODUCT(($J$15:$J$40=$J7)*($I$15:$I$40="")) -> 0
C8: レビュー指摘工数 | J8: =レビューシート!J8 -> 製作 | K8: =SUMPRODUCT(($J$15:$J$40=$J8)*($I$15:$I$40="")) -> 0
C9: レビュー回答工数 | J9: =レビューシート!J9 -> 試験要領 | K9: =SUMPRODUCT(($J$15:$J$40=$J9)*($I$15:$I$40="")) -> 0
C10: レビュー確認工数 | J10: =レビューシート!J10 -> その他 | K10: =SUMPRODUCT(($J$15:$J$40=$J10)*($I$15:$I$40="")) -> 0
C11: 実施工数(Hr) | D11: =SUM(D8:D10) -> 0 | J11: =レビューシート!J11 -> 運用移行保守 | K11: =SUMPRODUCT(($J$15:$J$40=$J11)*($I$15:$I$40="")) -> 0
J12: 計 | K12: =SUM(K3:K11) -> 0
A14: No | B14: 頁 | C14: 指摘事項 | D14: 実施日 (ﾚﾋﾞｭｰ日) | E14: 実施者 (ﾚﾋﾞｭｰｱ) | F14: 回 答 | G14: 回答日 | H14: 回答者 | I14: 対象外 | J14: 作込工程 | K14: 確認日 確認者
A15: 1
A16: 2
A17: 3
A18: 4
A19: 5
A20: 6
A21: 7
A22: 8
A23: 9
A24: 10
A25: 11
A26: 12
... A39: 25
A40: ※
A41: 明細の追加は、※行をコピーして、※行より上に挿入して下さい。
